Workbook

Sheet Instructions
B2: “Construction Estimate Template Excel | Contractor Bid & Job Costing Spreadsheet, Markup Margin Calculator, Proposal Generator Google Sheets”
B3: Template Author: novality store | Formula Protection Password: premium | Excel & Google Sheets Compatible
B5: TEMPLATE OVERVIEW & KEY SELLING POINTS
B6: Welcome to the novality store Construction Estimate & Contractor Bid Template! This commercial-grade spreadsheet is engineered for general contractors, remodelers, builders, electricians, plumbers, roofers, painters, and specialty trades. It features automatic cost calculations, itemized trade breakdown sheets, an advanced markup & margin calculator, job costing variance tracking, and a printable client proposal generator.
B8: CELL COLOR & INPUT LEGEND
B9: White Cells with Border | C9: Editable User Input Cells (Data entry, quantities, prices, notes)
B10: Soft Blue / Gray Cells | C10: Locked Formula & Read-Only Cells (Protected with password: premium)
B11: Navy / Slate / Gold Banners | C11: Section Headers, Table Banners & Accounting Grand Totals
B13: STEP-BY-STEP USER WORKFLOW
B15: Step 1: Project Info & Global Rates
B16: Go to the 'Project Info' tab. Enter client details, contractor company info, and global rates (Sales Tax %, Discount %, Overhead %, Contingency %, and default trade Markups). These rates link automatically across the entire workbook.
B17: Step 2: Enter Itemized Costs
B18: Use the 'Materials', 'Labor', 'Equipment', and 'Subcontractors' tabs to enter detailed line items for each trade. Quantities, unit costs, and hours will automatically calculate line totals and sheet subtotals.
B19: Step 3: Build & Review Estimate
B20: Open the 'Estimate' tab. This master sheet compiles your itemized trade costs, applies Overhead and Contingency allowances, adds your calculated Markup, and computes the final Contract Bid Price.
B21: Step 4: Configure Markup & Margin
B22: Visit the 'Markup & Margin Calculator' tab to fine-tune separate markup percentages for Materials, Labor, Equipment, and Subcontractors. Check the comparison table to see equivalent profit margins or use the Target Margin Reverse Calculator.
B23: Step 5: Generate Client Proposal
B24: Switch to the 'Client Proposal' tab. Your project scope, contractor details, and pricing summary are auto-populated into a clean, print-ready, invoice-style proposal page ready for client signature.
B25: Step 6: Track Actual Job Costs
B26: During construction, log your actual field costs on the 'Job Costing & Actuals' tab. Track budget variances in real time and view profitability performance on the executive 'Summary Dashboard'.

Sheet Project Info
B2: PROJECT, CLIENT & CONTRACTOR SETUP (GLOBAL PARAMETERS)
B4: 1. PROJECT & CLIENT DETAILS | E4: 3. FINANCIAL, TAX & CONTINGENCY SETTINGS
B5: Project Name | C5: Luxury Kitchen & Living Area Remodel | E5: Sales Tax Rate (%) | F5: 0.0825
B6: Client / Owner Name | C6: Robert Sterling / Apex Properties | E6: Preferred Client Discount Rate (%) | F6: 0.025
B7: Jobsite Location | C7: 742 Evergreen Terrace, Suite 300 | E7: Contingency Allowance Rate (%) | F7: 0.05
B8: Estimate Number | C8: EST-2026-042 | E8: General Overhead Rate (%) | F8: 0.1
B9: Estimate Date | C9: 2026-07-31 | E9: Target Profit Margin (%) | F9: 0.225
B10: Proposal Expiration Date | C10: 2026-08-30 | E10: Default Material Markup (%) | F10: 0.2
B11: Scope of Work Summary | C11: Full kitchen demolition, custom cabinetry, quartz countertops, electrical & plumbing relocation, hardwood flooring, and ambient LED lighting. | E11: Default Labor Markup (%) | F11: 0.35
E12: Default Subcontractor Markup (%) | F12: 0.15
B13: 2. CONTRACTOR & COMPANY DETAILS | E13: Default Equipment Markup (%) | F13: 0.25
B14: Contractor / Company Name | C14: Novality Construction & Design LLC
B15: Primary Contact / Estimator | C15: David Novality, Master Contractor | E15: GLOBAL RATE SUMMARY NOTE
B16: Company Business Address | C16: 100 Professional Way, Suite 400 | E16: These global percentages feed directly into the master Estimate and Markup Calculator sheets. Overhead (E8) and Contingency (E7) allowances are applied to Total Direct Costs before Markup. Sales Tax (E5) is applied after preferred discount deductions.
B17: Phone Number | C17: (555) 382-9100
B18: Email Address | C18: estimating@novalitystore.com
B19: Contractor License # | C19: LIC-GEN-884210
B20: Tax ID / EIN # | C20: XX-XXX8842

Sheet Materials
A2: ITEMIZED MATERIALS COST SHEET (DIRECT MATERIAL QUANTITY & PRICE BREAKDOWN)
A3: Enter material SKUs, supplier vendors, quantities, and unit prices. Line totals calculate automatically.
A5: Item SKU | B5: Material Description & Specification | C5: Trade Category | D5: Supplier / Vendor | E5: Quantity | F5: Unit | G5: Unit Cost ($) | H5: Tax / Freight ($) | I5: Total Cost ($)
A6: MAT-101 | B6: Custom Shaker Shading Shaker Base Cabinets | C6: Cabinetry | D6: Craftsman Cabinet Co. | E6: 12 | F6: Set | G6: 700 | H6: 140 | I6: =E6*G6+H6 -> 0
A7: MAT-102 | B7: Custom Shaker Wall & Pantry Cabinets | C7: Cabinetry | D7: Craftsman Cabinet Co. | E7: 8 | F7: Set | G7: 350 | H7: 70 | I7: =E7*G7+H7 -> 0
A8: MAT-103 | B8: Calacatta Gold White Quartz Countertop Slab | C8: Countertops | D8: Apex Stone & Tile | E8: 60 | F8: SqFt | G8: 75 | H8: 300 | I8: =E8*G8+H8 -> 0
A9: MAT-104 | B9: Engineered Oak Wide Plank Hardwood Flooring | C9: Flooring | D9: Prime Flooring Dist. | E9: 450 | F9: SqFt | G9: 6.5 | H9: 225 | I9: =E9*G9+H9 -> 0
A10: MAT-105 | B10: Hardwood Underlayment & Moisture Barrier | C10: Flooring | D10: Prime Flooring Dist. | E10: 450 | F10: SqFt | G10: 0.65 | H10: 7.5 | I10: =E10*G10+H10 -> 0
A11: MAT-106 | B11: Recessed 6-inch LED Dimmable Fixture Bundle | C11: Electrical | D11: Lumens Direct Wholesale | E11: 16 | F11: Unit | G11: 45 | H11: 30 | I11: =E11*G11+H11 -> 0
A12: MAT-107 | B12: Decorative Kitchen Pendant Lighting Array | C12: Electrical | D12: Lumens Direct Wholesale | E12: 3 | F12: Unit | G12: 220 | H12: 20 | I12: =E12*G12+H12 -> 0
A13: MAT-108 | B13: Architectural Interior Primer (5-Gal Pail) | C13: Paint | D13: Sherwin-Williams Pro | E13: 4 | F13: Pail | G13: 45 | H13: 20 | I13: =E13*G13+H13 -> 0
A14: MAT-109 | B14: Premium Satin Enamel Paint (5-Gal Pail) | C14: Paint | D14: Sherwin-Williams Pro | E14: 6 | F14: Pail | G14: 65 | H14: 30 | I14: =E14*G14+H14 -> 0
A15: MAT-110 | B15: High-End Kitchen Sink & Commercial Faucet | C15: Plumbing | D15: Ferguson Plumbing Sup. | E15: 1 | F15: Set | G15: 950 | H15: 50 | I15: =E15*G15+H15 -> 0
A16: MAT-111 | B16: Ceramic Subway Tile Backsplash Bundle | C16: Tile | D16: Apex Stone & Tile | E16: 80 | F16: SqFt | G16: 8.5 | H16: 40 | I16: =E16*G16+H16 -> 0
A17: MAT-112 | B17: Drywall, Compound & Trim Lumber Package | C17: Lumber / Prep | D17: Home Depot Pro | E17: 1 | F17: Lot | G17: 650 | H17: 50 | I17: =E17*G17+H17 -> 0
A18: TOTAL DIRECT MATERIAL COST ($) | I18: =SUM(I6:I17) -> 0

Sheet Labor
A2: ITEMIZED LABOR COST SHEET (CRAFT HOURS, REGULAR WAGES & OVERTIME)
A3: Enter craft roles, crew size, standard hours, and hourly billing rates. Overtime is tracked separately.
A5: Task Code | B5: Craft Role & Task Description | C5: Crew Size | D5: Reg. Hours | E5: Reg. Rate ($/hr) | F5: OT Hours | G5: OT Rate ($/hr) | H5: Total Labor Cost ($)
A6: LAB-201 | B6: Selective Kitchen Demolition & Haul Prep | C6: 2 | D6: 32 | E6: 40 | F6: 0 | G6: 60 | H6: =(C6*D6*E6)+(C6*F6*G6) -> 0
A7: LAB-202 | B7: Structural Header & Framing Modification | C7: 2 | D7: 24 | E7: 55 | F7: 4 | G7: 82.5 | H7: =(C7*D7*E7)+(C7*F7*G7) -> 0
A8: LAB-203 | B8: Custom Cabinetry & Island Box Installation | C8: 2 | D8: 40 | E8: 65 | F8: 0 | G8: 97.5 | H8: =(C8*D8*E8)+(C8*F8*G8) -> 0
A9: LAB-204 | B9: Finish Carpentry, Crown Molding & Trim | C9: 1 | D9: 32 | E9: 60 | F9: 0 | G9: 90 | H9: =(C9*D9*E9)+(C9*F9*G9) -> 0
A10: LAB-205 | B10: Drywall Hanging, Taping & Sanding Prep | C10: 2 | D10: 28 | E10: 45 | F10: 0 | G10: 67.5 | H10: =(C10*D10*E10)+(C10*F10*G10) -> 0
A11: LAB-206 | B11: Engineered Hardwood Floor Installation | C11: 2 | D11: 24 | E11: 50 | F11: 0 | G11: 75 | H11: =(C11*D11*E11)+(C11*F11*G11) -> 0
A12: LAB-207 | B12: Ceramic Tile Backsplash Layout & Setting | C12: 1 | D12: 16 | E12: 55 | F12: 0 | G12: 82.5 | H12: =(C12*D12*E12)+(C12*F12*G12) -> 0
A13: LAB-208 | B13: Interior Spray Primer & Architectural Paint | C13: 2 | D13: 36 | E13: 45 | F13: 0 | G13: 67.5 | H13: =(C13*D13*E13)+(C13*F13*G13) -> 0
A14: LAB-209 | B14: Project Supervisor & Quality Control Audit | C14: 1 | D14: 24 | E14: 75 | F14: 0 | G14: 112.5 | H14: =(C14*D14*E14)+(C14*F14*G14) -> 0
A15: LAB-210 | B15: Jobsite Cleanup, Dust Control & Sanitizing | C15: 1 | D15: 16 | E15: 35 | F15: 0 | G15: 52.5 | H15: =(C15*D15*E15)+(C15*F15*G15) -> 0
A16: TOTAL DIRECT LABOR COST ($) | H16: =SUM(H6:H15) -> 0

Sheet Equipment
A2: EQUIPMENT RENTAL & SPECIAL TOOLING COST SHEET
A3: Track equipment rentals, daily/weekly rates, delivery fees, and owned tool allowances.
A5: Equip. ID | B5: Equipment Name & Specification | C5: Ownership Type | D5: Rate Period | E5: Rate ($) | F5: Qty / Days | G5: Delivery Fee ($) | H5: Total Cost ($)
A6: EQP-301 | B6: 20-Yard Roll-Off Waste Dumpster Rental | C6: Rental | D6: Flat Rate | E6: 650 | F6: 1 | G6: 200 | H6: =E6*F6+G6 -> 0
A7: EQP-302 | B7: HEPA Commercial Air Scrubber & Filtration | C7: Owned / Allowance | D7: Daily Rate | E7: 45 | F7: 10 | G7: 50 | H7: =E7*F7+G7 -> 0
A8: EQP-303 | B8: Commercial Wet Tile Saw & Diamond Blade | C8: Owned / Allowance | D8: Daily Rate | E8: 35 | F8: 4 | G8: 0 | H8: =E8*F8+G8 -> 0
A9: EQP-304 | B9: Hardwood Floor Drum Sander & Edger Kit | C9: Rental | D9: Daily Rate | E9: 85 | F9: 3 | G9: 50 | H9: =E9*F9+G9 -> 0
A10: EQP-305 | B10: Interior Aluminum Scaffolding & Work Lift | C10: Rental | D10: Weekly Rate | E10: 250 | F10: 2 | G10: 75 | H10: =E10*F10+G10 -> 0
A11: EQP-306 | B11: Temporary Site Distribution Electrical Box | C11: Owned / Allowance | D11: Flat Rate | E11: 120 | F11: 1 | G11: 0 | H11: =E11*F11+G11 -> 0
A12: EQP-307 | B12: High-Capacity Dehumidifier & Blower Array | C12: Rental | D12: Daily Rate | E12: 40 | F12: 5 | G12: 25 | H12: =E12*F12+G12 -> 0
A13: EQP-308 | B13: Material Hoist & Cabinet Dolly Package | C13: Owned / Allowance | D13: Flat Rate | E13: 150 | F13: 1 | G13: 0 | H13: =E13*F13+G13 -> 0
A14: TOTAL DIRECT EQUIPMENT & RENTAL COST ($) | H14: =SUM(H6:H13) -> 0

Sheet Subcontractors
A2: LICENSED SUBCONTRACTOR PACKAGE & QUOTE SHEET
A3: Manage subcontractor bids, verify license/insurance, and calculate markup amounts per package.
A5: Sub. Code | B5: Subcontractor Company | C5: Scope of Work & Package Description | D5: Quoted Cost ($) | E5: Markup % | F5: Markup Amt ($) | G5: Billed Amount ($) | H5: License Verified
A6: SUB-401 | B6: Spark Systems Electric LLC | C6: 200A Service Panel Upgrade & LED Wiring Rough/Finish | D6: 4200 | E6: 0.15 | F6: =D6*E6 -> 0 | G6: =D6+F6 -> 0 | H6: Yes - Verified
A7: SUB-402 | B7: Apex Mechanical Plumbing Co. | C7: Kitchen Sink Reroute, Gas Line Extension & Appliance Hookup | D7: 3800 | E7: 0.15 | F7: =D7*E7 -> 0 | G7: =D7+F7 -> 0 | H7: Yes - Verified
A8: SUB-403 | B8: Breeze Comfort HVAC LLC | C8: Range Hood Duct Reroute & Supply Register Diffusers | D8: 1750 | E8: 0.15 | F8: =D8*E8 -> 0 | G8: =D8+F8 -> 0 | H8: Yes - Verified
A9: TOTAL SUBCONTRACTOR PACKAGE COSTS ($) | D9: =SUM(D6:D8) -> 0 | E9: 0 | F9: =SUM(F6:F8) -> 0 | G9: =SUM(G6:G8) -> 0

Sheet Estimate
A2: CONSTRUCTION ESTIMATE & CONTRACTOR BID TEMPLATE
A3: Dynamic bid sheet compiling itemized costs, overhead, contingency, and markup.
A5: PROJECT & CLIENT INFORMATION | E5: BID ESTIMATE & CONTRACTOR DETAILS
A6: Project Name: | B6: ='Project Info'!B4 -> 0 | E6: Estimate Number: | F6: ='Project Info'!B7 -> 0
A7: Client / Owner: | B7: ='Project Info'!B5 -> 0 | E7: Estimate Date: | F7: ='Project Info'!B8 -> 0
A8: Job Location: | B8: ='Project Info'!B6 -> 0 | E8: Contractor: | F8: ='Project Info'!B13 -> 0
A9: Scope Summary: | B9: ='Project Info'!B10 -> 0
A12: Item # | B12: Cost Category & Item Specification | C12: Quantity | D12: Unit | E12: Unit Cost ($) | F12: Total Cost ($) | G12: Trade Source
A13: 1. DIRECT MATERIALS & FIXTURE PACKAGES
A14: 1.01 | B14: Custom Cabinetry & Millwork Package | C14: 1 | D14: Lot | E14: 11200 | F14: =C14*E14 -> 0 | G14: Materials Sheet
A15: 1.02 | B15: Calacatta Gold Quartz Countertops & Backsplash | C15: 1 | D15: Lot | E15: 4800 | F15: =C15*E15 -> 0 | G15: Materials Sheet
A16: 1.03 | B16: Engineered Hardwood Flooring & Moisture Barrier | C16: 1 | D16: Lot | E16: 3450 | F16: =C16*E16 -> 0 | G16: Materials Sheet
A17: 1.04 | B17: Recessed & Decorative LED Lighting Bundle | C17: 1 | D17: Lot | E17: 1400 | F17: =C17*E17 -> 0 | G17: Materials Sheet
A18: 1.05 | B18: Architectural Interior Primers & Enamel Paints | C18: 1 | D18: Lot | E18: 800 | F18: =C18*E18 -> 0 | G18: Materials Sheet
A19: SUBTOTAL DIRECT MATERIALS ($) | F19: =SUM(F14:F18) -> 0 | G19: ='Materials'!I18 -> 0
A21: 2. DIRECT LABOR & CRAFTSMANSHIP HOURS
A22: 2.01 | B22: Selective Kitchen Demolition, Haul & Structural Prep | C22: 1 | D22: Lot | E22: 3200 | F22: =C22*E22 -> 0 | G22: Labor Sheet
A23: 2.02 | B23: Master Cabinetry, Millwork & Island Installation | C23: 1 | D23: Lot | E23: 6400 | F23: =C23*E23 -> 0 | G23: Labor Sheet
A24: 2.03 | B24: Drywall Framing, Hanging, Taping & Sanding | C24: 1 | D24: Lot | E24: 3600 | F24: =C24*E24 -> 0 | G24: Labor Sheet
A25: 2.04 | B25: Precision Interior Spray Painting & Enamel Trim Finish | C25: 1 | D25: Lot | E25: 3600 | F25: =C25*E25 -> 0 | G25: Labor Sheet
A26: SUBTOTAL DIRECT LABOR ($) | F26: =SUM(F22:F25) -> 0 | G26: ='Labor'!H16 -> 0
A28: 3. LICENSED SUBCONTRACTOR SPECIALTY SERVICES
A29: 3.01 | B29: Licensed Electrical Wiring & Service Panel Upgrade | C29: 1 | D29: Pkg | E29: 4200 | F29: =C29*E29 -> 0 | G29: Subcontractors
A30: 3.02 | B30: Licensed Plumbing Gas/Water Reroute & Fixtures | C30: 1 | D30: Pkg | E30: 3800 | F30: =C30*E30 -> 0 | G30: Subcontractors
A31: 3.03 | B31: Licensed HVAC Duct Modification & Range Hood Exhaust | C31: 1 | D31: Pkg | E31: 1750 | F31: =C31*E31 -> 0 | G31: Subcontractors
A32: SUBTOTAL SUBCONTRACTORS ($) | F32: =SUM(F29:F31) -> 0 | G32: ='Subcontractors'!D9 -> 0
A34: 4. EQUIPMENT RENTALS & SPECIAL TOOLING ALLOWANCE
A35: 4.01 | B35: 20-Yard Roll-Off Waste Dumpster Rental & Removal | C35: 1 | D35: Lot | E35: 850 | F35: =C35*E35 -> 0 | G35: Equipment Sheet
A36: 4.02 | B36: HEPA Air Scrubber, Dust Containment & Dehumidifiers | C36: 1 | D36: Lot | E36: 750 | F36: =C36*E36 -> 0 | G36: Equipment Sheet
A37: 4.03 | B37: Scaffolding Towers, Lifts & Specialty Flooring Sanders | C37: 1 | D37: Lot | E37: 1250 | F37: =C37*E37 -> 0 | G37: Equipment Sheet
A38: SUBTOTAL EQUIPMENT & RENTALS ($) | F38: =SUM(F35:F37) -> 0 | G38: ='Equipment'!H14 -> 0
A40: 5. PERMITS, FEES & SITE PROTECTION ALLOWANCE
A41: 5.01 | B41: Municipal Building, Trade & Electrical Permit Fees | C41: 1 | D41: Lot | E41: 950 | F41: =C41*E41 -> 0 | G41: Municipal
A42: 5.02 | B42: Site Floor Protection, Dust Barriers & Sanitization | C42: 1 | D42: Lot | E42: 500 | F42: =C42*E42 -> 0 | G42: Jobsite Prep
A43: SUBTOTAL PERMITS & OTHER COSTS ($) | F43: =SUM(F41:F42) -> 0 | G43: -
A45: 6. CONTRACTOR BID PRICING SUMMARY & CONTRACT BID TOTALS
A46: Total Direct Job Costs (Sum of Sections 1 to 5) | F46: =F19+F26+F32+F38+F43 -> 0
A47: General Overhead Allowance (10.00% of Direct Costs) | F47: ='Project Info'!F7*F46 -> 0
A48: Contingency Allowance (5.00% of Direct Costs) | F48: ='Project Info'!F6*F46 -> 0
A49: Subtotal Total Estimated Job Cost (Before Markup) | F49: =F46+F47+F48 -> 0
...

Sheet Markup & Margin Calculator
A2: ADVANCED MARKUP & PROFIT MARGIN CALCULATOR
A3: Separate category markups, Markup vs. Margin comparison table, and Target Profit Margin reverse calculator.
A5: 1. CATEGORY-SPECIFIC MARKUP & PROFIT MARGIN CALCULATOR
A6: Cost Category | B6: Base Cost ($) | C6: Markup % | D6: Markup Amt ($) | E6: Selling Price ($) | F6: Category Share | G6: Profit Margin %
A7: Direct Materials | B7: ='Estimate'!F19 -> 0 | C7: ='Project Info'!F9 -> 0 | D7: =B7*C7 -> 0 | E7: =B7+D7 -> 0 | F7: =E7/$E$13 -> 0 | G7: =IFERROR(D7/E7, 0) -> 0
A8: Direct Labor | B8: ='Estimate'!F26 -> 0 | C8: ='Project Info'!F10 -> 0 | D8: =B8*C8 -> 0 | E8: =B8+D8 -> 0 | F8: =E8/$E$13 -> 0 | G8: =IFERROR(D8/E8, 0) -> 0
A9: Equipment & Rentals | B9: ='Estimate'!F38 -> 0 | C9: ='Project Info'!F12 -> 0 | D9: =B9*C9 -> 0 | E9: =B9+D9 -> 0 | F9: =E9/$E$13 -> 0 | G9: =IFERROR(D9/E9, 0) -> 0
A10: Subcontractors | B10: ='Estimate'!F32 -> 0 | C10: ='Project Info'!F11 -> 0 | D10: =B10*C10 -> 0 | E10: =B10+D10 -> 0 | F10: =E10/$E$13 -> 0 | G10: =IFERROR(D10/E10, 0) -> 0
A11: Permits & Other Costs | B11: ='Estimate'!F43 -> 0 | C11: 0.15 | D11: =B11*C11 -> 0 | E11: =B11+D11 -> 0 | F11: =E11/$E$13 -> 0 | G11: =IFERROR(D11/E11, 0) -> 0
A12: Overhead & Contingency | B12: ='Estimate'!F47+'Estimate'!F48 -> 0 | C12: 0.2 | D12: =B12*C12 -> 0 | E12: =B12+D12 -> 0 | F12: =E12/$E$13 -> 0 | G12: =IFERROR(D12/E12, 0) -> 0
A13: TOTAL JOB MARKUP & MARGIN | B13: =SUM(B7:B12) -> 0 | C13: =D13/B13 -> 0 | D13: =SUM(D7:D12) -> 0 | E13: =SUM(E7:E12) -> 0 | F13: =SUM(F7:F12) -> 0 | G13: =IFERROR(D13/E13, 0) -> 0
A15: 2. MARKUP VS. PROFIT MARGIN COMPARISON TABLE | E15: 3. TARGET MARGIN REVERSE CALCULATOR
A16: Markup % | B16: Equivalent Margin % | C16: Price on $1,000 Cost ($) | D16: Gross Profit ($)
A17: 0.1 | B17: =A17/(1+A17) -> 0 | C17: =1000*(1+A17) -> 0 | D17: =C17-1000 -> 0 | E17: Input Total Job Cost ($): | F17: =B13 -> 0 | G17: Cost to price
A18: 0.15 | B18: =A18/(1+A18) -> 0 | C18: =1000*(1+A18) -> 0 | D18: =C18-1000 -> 0 | E18: Desired Profit Margin (%): | F18: ='Project Info'!F8 -> 0 | G18: Target %
A19: 0.2 | B19: =A19/(1+A19) -> 0 | C19: =1000*(1+A19) -> 0 | D19: =C19-1000 -> 0 | E19: Required Selling Price ($): | F19: =F17/(1-F18) -> 0 | G19: Formula
A20: 0.25 | B20: =A20/(1+A20) -> 0 | C20: =1000*(1+A20) -> 0 | D20: =C20-1000 -> 0 | E20: Required Gross Profit ($): | F20: =F19-F17 -> 0 | G20: Profit $
A21: 0.3 | B21: =A21/(1+A21) -> 0 | C21: =1000*(1+A21) -> 0 | D21: =C21-1000 -> 0 | E21: Equivalent Markup % Needed: | F21: =IFERROR(F20/F17, 0) -> 0 | G21: Equivalent
A22: 0.35 | B22: =A22/(1+A22) -> 0 | C22: =1000*(1+A22) -> 0 | D22: =C22-1000 -> 0
A23: 0.4 | B23: =A23/(1+A23) -> 0 | C23: =1000*(1+A23) -> 0 | D23: =C23-1000 -> 0
A24: 0.5 | B24: =A24/(1+A24) -> 0 | C24: =1000*(1+A24) -> 0 | D24: =C24-1000 -> 0
A25: 0.75 | B25: =A25/(1+A25) -> 0 | C25: =1000*(1+A25) -> 0 | D25: =C25-1000 -> 0
A26: 1 | B26: =A26/(1+A26) -> 0 | C26: =1000*(1+A26) -> 0 | D26: =C26-1000 -> 0

Sheet Job Costing & Actuals
A2: ESTIMATED VS. ACTUAL JOB COSTING TRACKER & VARIANCE ANALYSIS
A3: Track field expenditures against estimated budget. Automatic budget variance and status indicator.
A5: Category Code | B5: Cost Category Description | C5: Estimated Budget ($) | D5: Actual Cost Incurred ($) | E5: Dollar Variance ($) | F5: Budget Variance % | G5: Cost Performance Status
A6: CAT-100 | B6: Direct Materials & Fixtures | C6: ='Estimate'!F19 -> 0 | D6: 20950 | E6: =C6-D6 -> 0 | F6: =IFERROR(E6/C6, 0) -> 0 | G6: =IF(E6>=0, "UNDER BUDGET", "OVER BUDGET") -> 0
A7: CAT-200 | B7: Direct Labor & Craft Hours | C7: ='Estimate'!F26 -> 0 | D7: 17200 | E7: =C7-D7 -> 0 | F7: =IFERROR(E7/C7, 0) -> 0 | G7: =IF(E7>=0, "UNDER BUDGET", "OVER BUDGET") -> 0
A8: CAT-300 | B8: Licensed Subcontractors | C8: ='Estimate'!F32 -> 0 | D8: 9750 | E8: =C8-D8 -> 0 | F8: =IFERROR(E8/C8, 0) -> 0 | G8: =IF(E8>=0, "UNDER BUDGET", "OVER BUDGET") -> 0
A9: CAT-400 | B9: Equipment Rentals & Special Tools | C9: ='Estimate'!F38 -> 0 | D9: 2650 | E9: =C9-D9 -> 0 | F9: =IFERROR(E9/C9, 0) -> 0 | G9: =IF(E9>=0, "UNDER BUDGET", "OVER BUDGET") -> 0
A10: CAT-500 | B10: Permits, Fees & Site Protection | C10: ='Estimate'!F43 -> 0 | D10: 1450 | E10: =C10-D10 -> 0 | F10: =IFERROR(E10/C10, 0) -> 0 | G10: =IF(E10>=0, "UNDER BUDGET", "OVER BUDGET") -> 0
A11: CAT-600 | B11: General Overhead & Contingency Allowance | C11: ='Estimate'!F47+'Estimate'!F48 -> 0 | D11: 7500 | E11: =C11-D11 -> 0 | F11: =IFERROR(E11/C11, 0) -> 0 | G11: =IF(E11>=0, "UNDER BUDGET", "OVER BUDGET") -> 0
A12: TOTAL CONSTRUCTION JOB COST ($) | C12: =SUM(C6:C11) -> 0 | D12: =SUM(D6:D11) -> 0 | E12: =C12-D12 -> 0 | F12: =IFERROR(E12/C12, 0) -> 0 | G12: =IF(E12>=0, "UNDER BUDGET", "OVER BUDGET") -> 0
B14: EXECUTIVE JOB PROFITABILITY & MARGIN VARIANCE SUMMARY
B15: Contract Bid Selling Price ($) | C15: ='Estimate'!F51 -> 0
B16: Actual Total Job Cost Incurred ($) | C16: =D12 -> 0
B17: Actual Job Gross Profit ($) | C17: =C15-C16 -> 0
B18: Actual Realized Profit Margin (%) | C18: =IFERROR(C17/C15, 0) -> 0
B19: Estimated Profit Margin (%) | C19: ='Markup & Margin Calculator'!G13 -> 0
B20: Profit Margin Variance (%) | C20: =C18-C19 -> 0

Sheet Summary Dashboard
B2: EXECUTIVE CONSTRUCTION SUMMARY DASHBOARD & KPI OVERVIEW
B4: TOTAL ESTIMATED JOB COST | D4: TOTAL CONTRACT BID PRICE | F4: TOTAL MARKUP & GROSS PROFIT | H4: ESTIMATED PROFIT MARGIN %
B5: ='Estimate'!F49 -> 0 | D5: ='Estimate'!F55 -> 0 | F5: ='Markup & Margin Calculator'!D13 -> 0 | H5: ='Markup & Margin Calculator'!G13 -> 0
B8: COST PERFORMANCE BY CATEGORY ($) | H8: CONTRACT BID & PROFIT BREAKDOWN
B9: Cost Category | C9: Estimated ($) | D9: Actual ($) | E9: Variance ($) | F9: Status
B10: Direct Materials | C10: ='Job Costing & Actuals'!C6 -> 0 | D10: ='Job Costing & Actuals'!D6 -> 0 | E10: =C10-D10 -> 0 | F10: =IF(E10>=0, "UNDER BUDGET", "OVER BUDGET") -> 0 | H10: Subtotal Direct Costs | J10: ='Estimate'!F46 -> 0
B11: Direct Labor | C11: ='Job Costing & Actuals'!C7 -> 0 | D11: ='Job Costing & Actuals'!D7 -> 0 | E11: =C11-D11 -> 0 | F11: =IF(E11>=0, "UNDER BUDGET", "OVER BUDGET") -> 0 | H11: Overhead Allowance | J11: ='Estimate'!F47 -> 0
B12: Subcontractors | C12: ='Job Costing & Actuals'!C8 -> 0 | D12: ='Job Costing & Actuals'!D8 -> 0 | E12: =C12-D12 -> 0 | F12: =IF(E12>=0, "UNDER BUDGET", "OVER BUDGET") -> 0 | H12: Contingency Allowance | J12: ='Estimate'!F48 -> 0
B13: Equipment & Rentals | C13: ='Job Costing & Actuals'!C9 -> 0 | D13: ='Job Costing & Actuals'!D9 -> 0 | E13: =C13-D13 -> 0 | F13: =IF(E13>=0, "UNDER BUDGET", "OVER BUDGET") -> 0 | H13: Total Professional Markup | J13: ='Estimate'!F50 -> 0
B14: Permits & Other | C14: ='Job Costing & Actuals'!C10 -> 0 | D14: ='Job Costing & Actuals'!D10 -> 0 | E14: =C14-D14 -> 0 | F14: =IF(E14>=0, "UNDER BUDGET", "OVER BUDGET") -> 0 | H14: Subtotal Bid Selling Price | J14: ='Estimate'!F51 -> 0
B15: Overhead & Contingency | C15: ='Job Costing & Actuals'!C11 -> 0 | D15: ='Job Costing & Actuals'!D11 -> 0 | E15: =C15-D15 -> 0 | F15: =IF(E15>=0, "UNDER BUDGET", "OVER BUDGET") -> 0 | H15: Preferred Client Discount | J15: ='Estimate'!F52 -> 0
B16: TOTAL JOB COSTS | C16: =SUM(C10:C15) -> 0 | D16: =SUM(D10:D15) -> 0 | E16: =C16-D16 -> 0 | F16: =IF(E16>=0, "UNDER BUDGET", "OVER BUDGET") -> 0 | H16: Sales Tax (8.25%) | J16: ='Estimate'!F54 -> 0
H17: GRAND TOTAL BID PRICE ($) | J17: ='Estimate'!F55 -> 0
B18: COST PERFORMANCE VISUAL SNAPSHOT (EXCEL-SAFE CELL-BASED DASHBOARD)
B19: Cost Category | C19: Estimated ($) | D19: Actual ($) | E19: Variance ($) | F19: Budget Perf. | G19: Visual Bar (Est.) | H19: Visual Bar (Act.)
B20: Direct Materials | C20: ='Job Costing & Actuals'!C6 -> 0 | D20: ='Job Costing & Actuals'!D6 -> 0 | E20: =C20-D20 -> 0 | F20: =IF(E20>=0, "ON BUDGET", "OVER BUDGET") -> 0 | G20: =REPT("█", MAX(1, MIN(50, ROUND(C20/500, 0)))) -> 0 | H20: =REPT("█", MAX(1, MIN(50, ROUND(D20/500, 0)))) -> 0
B21: Direct Labor | C21: ='Job Costing & Actuals'!C7 -> 0 | D21: ='Job Costing & Actuals'!D7 -> 0 | E21: =C21-D21 -> 0 | F21: =IF(E21>=0, "ON BUDGET", "OVER BUDGET") -> 0 | G21: =REPT("█", MAX(1, MIN(50, ROUND(C21/500, 0)))) -> 0 | H21: =REPT("█", MAX(1, MIN(50, ROUND(D21/500, 0)))) -> 0
B22: Subcontractors | C22: ='Job Costing & Actuals'!C8 -> 0 | D22: ='Job Costing & Actuals'!D8 -> 0 | E22: =C22-D22 -> 0 | F22: =IF(E22>=0, "ON BUDGET", "OVER BUDGET") -> 0 | G22: =REPT("█", MAX(1, MIN(50, ROUND(C22/500, 0)))) -> 0 | H22: =REPT("█", MAX(1, MIN(50, ROUND(D22/500, 0)))) -> 0
B23: Equipment & Rentals | C23: ='Job Costing & Actuals'!C9 -> 0 | D23: ='Job Costing & Actuals'!D9 -> 0 | E23: =C23-D23 -> 0 | F23: =IF(E23>=0, "ON BUDGET", "OVER BUDGET") -> 0 | G23: =REPT("█", MAX(1, MIN(50, ROUND(C23/500, 0)))) -> 0 | H23: =REPT("█", MAX(1, MIN(50, ROUND(D23/500, 0)))) -> 0
B24: Permits & Other | C24: ='Job Costing & Actuals'!C10 -> 0 | D24: ='Job Costing & Actuals'!D10 -> 0 | E24: =C24-D24 -> 0 | F24: =IF(E24>=0, "ON BUDGET", "OVER BUDGET") -> 0 | G24: =REPT("█", MAX(1, MIN(50, ROUND(C24/500, 0)))) -> 0 | H24: =REPT("█", MAX(1, MIN(50, ROUND(D24/500, 0)))) -> 0
B25: Overhead & Contingency | C25: ='Job Costing & Actuals'!C11 -> 0 | D25: ='Job Costing & Actuals'!D11 -> 0 | E25: =C25-D25 -> 0 | F25: =IF(E25>=0, "ON BUDGET", "OVER BUDGET") -> 0 | G25: =REPT("█", MAX(1, MIN(50, ROUND(C25/500, 0)))) -> 0 | H25: =REPT("█", MAX(1, MIN(50, ROUND(D25/500, 0)))) -> 0
B26: TOTAL JOB COSTS | C26: =SUM(C20:C25) -> 0 | D26: =SUM(D20:D25) -> 0 | E26: =C26-D26 -> 0 | F26: =IF(E26>=0, "ON BUDGET", "OVER BUDGET") -> 0 | G26: =REPT("█", MAX(1, MIN(50, ROUND(C26/500, 0)))) -> 0 | H26: =REPT("█", MAX(1, MIN(50, ROUND(D26/500, 0)))) -> 0
B27: NOTE: Native embedded chart removed to ensure 100% Excel compatibility with zero repair errors. The REPT()-based visual bars above provide a drawing-free alternative.

Sheet Client Proposal
B2: CONSTRUCTION PROJECT PROPOSAL & BID ACCEPTANCE
B3: Professional Contractor Bid & Scope Specification
B5: CONTRACTOR / COMPANY INFO | E5: CLIENT / PROJECT INFO
B6: Company Name: | C6: ='Project Info'!B13 -> 0 | E6: Client Name: | F6: ='Project Info'!B5 -> 0
B7: Contact Person: | C7: ='Project Info'!B14 -> 0 | E7: Project Name: | F7: ='Project Info'!B4 -> 0
B8: Phone Number: | C8: ='Project Info'!B16 -> 0 | E8: Job Location: | F8: ='Project Info'!B6 -> 0
B9: Email Address: | C9: ='Project Info'!B17 -> 0 | E9: Estimate Number: | F9: ='Project Info'!B7 -> 0
B11: SCOPE OF WORK SPECIFICATION
B12: ='Project Info'!B10 -> 0
B14: PROJECT PRICING SUMMARY BY TRADE & SERVICE
B15: Cost Category / Trade Description | F15: Contract Price ($)
B16: Direct Materials & Custom Architectural Fixtures | F16: ='Estimate'!F19 -> 0
B17: Direct Labor & Skilled Craftsmanship Hours | F17: ='Estimate'!F26 -> 0
B18: Licensed Specialty Subcontractor Packages | F18: ='Estimate'!F32 -> 0
B19: Equipment Rentals, Waste Removal & Specialty Tooling | F19: ='Estimate'!F38 -> 0
B20: Municipal Building & Trade Permits, Site Protection & Cleanup | F20: ='Estimate'!F43 -> 0
B21: Contractor Overhead, Management & Contingency Allowance | F21: ='Estimate'!F47+'Estimate'!F48 -> 0
B22: Professional Contractor Markup & Value Engineering | F22: ='Estimate'!F50 -> 0
B23: SUBTOTAL CONTRACT BID PRICE | F23: ='Estimate'!F51 -> 0
B24: Preferred Client Discount (-2.50%) | F24: ='Estimate'!F52 -> 0
B25: Net Taxable Contract Bid Amount | F25: ='Estimate'!F53 -> 0
B26: Applicable Sales Tax (8.25%) | F26: ='Estimate'!F54 -> 0
B27: GRAND TOTAL CONTRACT BID PRICE ($) | F27: ='Estimate'!F55 -> 0
B28: EXCLUSIONS, CLARIFICATIONS & PAYMENT TERMS
B29: EXCLUSIONS: Excludes hazardous material abatement, unforeseen subterranean repairs, and utility company connection fees. PAYMENT SCHEDULE: 20% deposit upon contract signing, 50% upon progress milestones, and 30% upon substantial completion. PROPOSAL VALIDITY: 30 days from date of issue.
B31: CLIENT ACCEPTANCE & AUTHORIZATION SIGNATURE AREA
B32: Client Signature: | E32: Date Signed:
B33: Printed Name: | C33: Robert Sterling, Apex Properties | E33: Contractor Sign-off: | F33: David Novality, Master Contractor

Sheet Terms & Conditions
B2: STANDARD CONTRACTOR TERMS, CONDITIONS & WORKMANSHIP WARRANTY
B3: Legal Agreement & Operational Policies for Construction Contracts
B6: 1. SCOPE OF WORK & PROPOSAL VALIDITY
B7: The contractor agrees to perform the scope of work specified in the Client Proposal. The pricing stated in this document is valid for 30 calendar days from the date of issuance. Any work not explicitly listed is excluded.
B9: 2. PAYMENT SCHEDULE & INVOICING
B10: Payments shall be made according to the agreed milestone payment schedule: 20% mobilization deposit upon signing, milestone progress invoices during construction, and final payment upon completion of punchlist items.
B12: 3. CHANGE ORDERS & MODIFICATIONS
B13: Any alteration or deviation from the original specifications involving extra costs or schedule extensions will be executed only upon a written Change Order signed by both Owner and Contractor.
B15: 4. SITE ACCESS, WORKING HOURS & UTILITIES
B16: The owner agrees to provide reasonable access to the property during standard working hours (7:00 AM - 5:00 PM) and make water and electricity available for construction purposes without charge.
B18: 5. WORKMANSHIP WARRANTY & MATERIAL GUARANTEE
B19: Novality Construction & Design LLC provides a 1-year limited workmanship warranty on all installations. Standard manufacturer warranties apply to all installed equipment and material fixtures.
... B25: The contractor is not responsible for project delays caused by severe weather, material vendor backorders, strikes, or municipal permitting delays beyond contractor control.

Sheet Material Price DB
A2: MATERIAL PRICE DATABASE (MASTER INVENTORY & UNIT PRICE REFERENCE)
A3: Reference table of standard construction materials, default suppliers, and current market unit costs.
A5: SKU Code | B5: Material Description & Specification | C5: Trade Category | D5: Default Supplier | E5: Unit | F5: Standard Price ($) | G5: Lead Time (Days)
A6: MAT-101 | B6: Custom Shaker Base Cabinet Box | C6: Cabinetry | D6: Craftsman Cabinet Co. | E6: Set | F6: 700 | G6: 14
A7: MAT-102 | B7: Custom Shaker Wall Cabinet Box | C7: Cabinetry | D7: Craftsman Cabinet Co. | E7: Set | F7: 350 | G7: 14
A8: MAT-103 | B8: Calacatta Gold Quartz Slab (3cm) | C8: Countertops | D8: Apex Stone & Tile | E8: SqFt | F8: 75 | G8: 7
A9: MAT-104 | B9: Engineered Oak Hardwood Plank | C9: Flooring | D9: Prime Flooring Dist. | E9: SqFt | F9: 6.5 | G9: 5
A10: MAT-105 | B10: Hardwood Acoustic Underlayment | C10: Flooring | D10: Prime Flooring Dist. | E10: SqFt | F10: 0.65 | G10: 3
A11: MAT-106 | B11: Recessed 6-inch LED Dimmable Fixture | C11: Electrical | D11: Lumens Direct | E11: Unit | F11: 45 | G11: 2
A12: MAT-107 | B12: Decorative Pendant Light Fixture | C12: Electrical | D12: Lumens Direct | E12: Unit | F12: 220 | G12: 5
A13: MAT-108 | B13: Architectural Primer (5-Gal Pail) | C13: Paint | D13: Sherwin-Williams Pro | E13: Pail | F13: 45 | G13: 1
A14: MAT-109 | B14: Premium Satin Enamel (5-Gal Pail) | C14: Paint | D14: Sherwin-Williams Pro | E14: Pail | F14: 65 | G14: 1
A15: MAT-110 | B15: Commercial Stainless Sink & Faucet | C15: Plumbing | D15: Ferguson Plumbing | E15: Set | F15: 950 | G15: 7
A16: MAT-111 | B16: Ceramic Subway Backsplash Tile | C16: Tile | D16: Apex Stone & Tile | E16: SqFt | F16: 8.5 | G16: 4
A17: MAT-112 | B17: Drywall Sheet 1/2-inch x 8ft | C17: Drywall | D17: Home Depot Pro | E17: Sheet | F17: 14.5 | G17: 1
... A20: MAT-115 | B20: Interior Mold-Resistant Silicone Caulk | C20: Finish | D20: Home Depot Pro | E20: Tube | F20: 8.5 | G20: 1

Sheet Labor Rate DB
A2: LABOR RATE DATABASE (STANDARD HOURLY WAGES, BURDEN & BILLING RATES)
A3: Master labor rate table with base wage, payroll burden, fully burdened cost, and standard billing rates.
A5: Trade Code | B5: Craft Role / Trade Description | C5: Base Wage ($/hr) | D5: Burden & Ins. % | E5: Burdened Cost ($/hr) | F5: Billing Rate ($/hr) | G5: OT Billing Rate ($/hr)
A6: TRD-01 | B6: General Construction Laborer | C6: 25 | D6: 0.25 | E6: =C6*(1+D6) -> 0 | F6: 40 | G6: 60
A7: TRD-02 | B7: Skilled Carpenter & Framing Lead | C7: 35 | D7: 0.28 | E7: =C7*(1+D7) -> 0 | F7: 55 | G7: 82.5
A8: TRD-03 | B8: Master Millwork & Cabinet Specialist | C8: 42 | D8: 0.28 | E8: =C8*(1+D8) -> 0 | F8: 65 | G8: 97.5
A9: TRD-04 | B9: Drywall Hanger & Finisher | C9: 30 | D9: 0.25 | E9: =C9*(1+D9) -> 0 | F9: 45 | G9: 67.5
A10: TRD-05 | B10: Interior Painter & Trim Finisher | C10: 28 | D10: 0.25 | E10: =C10*(1+D10) -> 0 | F10: 45 | G10: 67.5
A11: TRD-06 | B11: Licensed Electrician (Master) | C11: 48 | D11: 0.3 | E11: =C11*(1+D11) -> 0 | F11: 75 | G11: 112.5
A12: TRD-07 | B12: Licensed Plumber & Gas Fitter | C12: 48 | D12: 0.3 | E12: =C12*(1+D12) -> 0 | F12: 75 | G12: 112.5
A13: TRD-08 | B13: HVAC Duct & Mechanical Technician | C13: 42 | D13: 0.3 | E13: =C13*(1+D13) -> 0 | F13: 70 | G13: 105
A14: TRD-09 | B14: Ceramic & Stone Tile Setter | C14: 35 | D14: 0.26 | E14: =C14*(1+D14) -> 0 | F14: 55 | G14: 82.5
A15: TRD-10 | B15: Hardwood Flooring Installer | C15: 32 | D15: 0.26 | E15: =C15*(1+D15) -> 0 | F15: 50 | G15: 75
A16: TRD-11 | B16: Project Supervisor / QC Manager | C16: 50 | D16: 0.32 | E16: =C16*(1+D16) -> 0 | F16: 75 | G16: 112.5
A17: TRD-12 | B17: Site Safety & Sanitization Tech | C17: 22 | D17: 0.25 | E17: =C17*(1+D17) -> 0 | F17: 35 | G17: 52.5

Sheet Estimate Versions
A2: MULTIPLE ESTIMATE VERSIONS COMPARISON (GOOD / BETTER / BEST)
A3: Side-by-side comparison of 3 client proposal packages to facilitate upselling and option analysis.
A5: Cost Category / Metric | B5: Option 1: Standard / Base | C5: Option 2: Upgraded / Preferred | D5: Option 3: Premium / Luxury
A6: Direct Materials & Fixture Packages ($) | B6: 16500 | C6: 21650 | D6: 29800
A7: Direct Labor & Craft Hours ($) | B7: 14200 | C7: 16800 | D7: 21500
A8: Licensed Subcontractor Services ($) | B8: 8500 | C8: 9750 | D8: 12400
A9: Equipment Rentals & Tool Allowance ($) | B9: 2200 | C9: 2850 | D9: 3600
A10: Permits, Fees & Site Protection ($) | B10: 1450 | C10: 1450 | D10: 1850
A11: TOTAL DIRECT JOB COSTS ($) | B11: =SUM(B6:B10) -> 0 | C11: =SUM(C6:C10) -> 0 | D11: =SUM(D6:D10) -> 0
A12: Overhead Allowance (10.0%) | B12: =B11*'Project Info'!F7 -> 0 | C12: =C11*'Project Info'!F7 -> 0 | D12: =D11*'Project Info'!F7 -> 0
A13: Contingency Allowance (5.0%) | B13: =B11*'Project Info'!F6 -> 0 | C13: =C11*'Project Info'!F6 -> 0 | D13: =D11*'Project Info'!F6 -> 0
A14: SUBTOTAL JOB COST (Before Markup) | B14: =B11+B12+B13 -> 0 | C14: =C11+C12+C13 -> 0 | D14: =D11+D12+D13 -> 0
A15: Contractor Markup % Applied | B15: 0.22 | C15: 0.2348 | D15: 0.25
A16: Total Markup Amount ($) | B16: =B14*B15 -> 0 | C16: =C14*C15 -> 0 | D16: =D14*D15 -> 0
A17: ESTIMATED CONTRACT SELLING PRICE ($) | B17: =B14+B16 -> 0 | C17: =C14+C16 -> 0 | D17: =D14+D16 -> 0
A18: Equivalent Profit Margin % | B18: =IFERROR(B16/B17, 0) -> 0 | C18: =IFERROR(C16/C17, 0) -> 0 | D18: =IFERROR(D16/D17, 0) -> 0

Sheet Change Order Tracker
A2: PROJECT CHANGE ORDER TRACKER & BID MODIFICATION LOG
A3: Log scope changes, calculate change order markups, and track client approval status.
A5: CO Number | B5: Date Req. | C5: Description of Scope Modification | D5: Requested By | E5: Direct Cost ($) | F5: Markup % | G5: CO Total Price ($) | H5: Schedule Add | I5: Approval Status | J5: Date Approved
A6: CO-001 | B6: 2026-08-05 | C6: Upgrade Quartz Island Countertop to Waterfall Edge | D6: Robert Sterling | E6: 1200 | F6: 0.2 | G6: =E6*(1+F6) -> 0 | H6: 2 Days | I6: Approved | J6: 2026-08-06
A7: CO-002 | B7: 2026-08-10 | C7: Add 4 Additional Dimmable Recessed LED Lights | D7: Robert Sterling | E7: 450 | F7: 0.25 | G7: =E7*(1+F7) -> 0 | H7: 1 Day | I7: Approved | J7: 2026-08-11
A8: CO-003 | B8: 2026-08-15 | C8: Relocate Secondary Laundry Plumbing Drain Line | D8: Robert Sterling | E8: 850 | F8: 0.2 | G8: =E8*(1+F8) -> 0 | H8: 1 Day | I8: Pending | J8: -
A9: TOTAL CHANGE ORDER LOG ($) | E9: =SUM(E6:E8) -> 0 | G9: =SUM(G6:G8) -> 0
B12: CHANGE ORDER CONTRACT PRICE IMPACT
B13: Original Contract Bid Price ($) | D13: ='Estimate'!F55 -> 0
B14: Total Approved Change Orders ($) | D14: =SUMIF(I6:I8, "Approved", G6:G8) -> 0
B15: REVISED GRAND TOTAL CONTRACT PRICE ($) | D15: =D13+D14 -> 0

Sheet Payment Schedule
A2: MILESTONE PAYMENT SCHEDULE & PROGRESS BILLING TRACKER
A3: Schedule progress payments based on contract milestones and track amounts received.
A5: Milestone # | B5: Milestone Phase Description | C5: % of Contract | D5: Scheduled Amount ($) | E5: Target Due Date | F5: Payment Status | G5: Date Received | H5: Check / Ref #
A6: PAY-01 | B6: Initial Mobilization & Deposit (Upon Contract Signing) | C6: 0.2 | D6: ='Estimate'!$F$55*C6 -> 0 | E6: 2026-08-01 | F6: Paid | G6: 2026-08-01 | H6: CHK-9921
A7: PAY-02 | B7: Rough-In Completion (Electrical, Plumbing & HVAC) | C7: 0.25 | D7: ='Estimate'!$F$55*C7 -> 0 | E7: 2026-08-15 | F7: Paid | G7: 2026-08-16 | H7: CHK-9945
A8: PAY-03 | B8: Drywall, Flooring & Cabinet Installation Completion | C8: 0.25 | D8: ='Estimate'!$F$55*C8 -> 0 | E8: 2026-08-30 | F8: Pending | G8: - | H8: -
A9: PAY-04 | B9: Countertops, Backsplash Tile & Fixture Completion | C9: 0.2 | D9: ='Estimate'!$F$55*C9 -> 0 | E9: 2026-09-10 | F9: Pending | G9: - | H9: -
A10: PAY-05 | B10: Final Inspection & Punchlist Sign-Off | C10: 0.1 | D10: ='Estimate'!$F$55*C10 -> 0 | E10: 2026-09-20 | F10: Pending | G10: - | H10: -
A11: TOTAL CONTRACT PAYMENT SCHEDULE | C11: =SUM(C6:C10) -> 0 | D11: =SUM(D6:D10) -> 0

Sheet Invoice Summary
B2: PROGRESS INVOICE & CONTRACT BILLING SUMMARY
B3: Standard AIA-Style Progress Billing Summary for Construction Contractors
B5: CONTRACTOR / PAYEE DETAILS | E5: INVOICE & CONTRACT METRICS
B6: Company Name: | C6: ='Project Info'!B13 -> 0 | E6: Invoice Number: | F6: INV-2026-001
B7: Client / Owner: | C7: ='Project Info'!B5 -> 0 | E7: Billing Period: | F7: 2026-08-01 to 2026-08-16
B10: PROGRESS BILLING FINANCIAL BREAKDOWN
B11: 1. Original Contract Bid Price ($) | E11: ='Estimate'!F55 -> 0
B12: 2. Net Addition from Approved Change Orders ($) | E12: ='Change Order Tracker'!D14 -> 0
B13: 3. REVISED TOTAL CONTRACT PRICE ($) | E13: =E11+E12 -> 0
B14: 4. Total Value of Work Completed to Date ($) | E14: =E13*0.45 -> 0
B15: 5. Retainage Withheld (5.00% of Completed Work) | E15: =E14*0.05 -> 0
B16: 6. Total Earned Less Retainage ($) | E16: =E14-E15 -> 0
B17: 7. Less Previous Payments Received ($) | E17: ='Payment Schedule'!D6 -> 0
B18: 8. CURRENT PROGRESS INVOICE AMOUNT DUE ($) | E18: =E16-E17 -> 0
B19: 9. Balance to Finish Including Retainage ($) | E19: =E13-E16 -> 0

Sheet Project Timeline
A2: CONSTRUCTION PROJECT TIMELINE & GANTT SCHEDULE TRACKER (12 WEEKS)
A3: High-level schedule tracker by phase. Visual bar indicators highlight planned week duration.
A5: Phase # | B5: Construction Phase & Task | C5: Lead Trade | D5: Status | E5: Start Wk | F5: Duration | G5: End Wk | H5: W1 | I5: W2 | J5: W3 | K5: W4 | L5: W5 | M5: W6 | N5: W7 | O5: W8 | P5: W9 | Q5: W10 | R5: W11 | S5: W12
A6: PH-01 | B6: Permitting & Material Procurement | C6: Management | D6: Completed | E6: 1 | F6: 2 | G6: =E6+F6-1 -> 0
A7: PH-02 | B7: Selective Kitchen Demolition & Site Prep | C7: Demolition | D7: Completed | E7: 2 | F7: 1 | G7: =E7+F7-1 -> 0
A8: PH-03 | B8: Structural Framing & Wall Header Reroute | C8: Carpentry | D8: Completed | E8: 3 | F8: 1 | G8: =E8+F8-1 -> 0
A9: PH-04 | B9: Electrical & Plumbing Rough-In Wiring/Pipes | C9: MEP Subs | D9: Completed | E9: 3 | F9: 2 | G9: =E9+F9-1 -> 0
A10: PH-05 | B10: Municipal Inspection (Rough MEP & Frame) | C10: Municipal | D10: Completed | E10: 5 | F10: 1 | G10: =E10+F10-1 -> 0
A11: PH-06 | B11: Drywall Hanging, Taping & Plaster Sanding | C11: Drywall | D11: In Progress | E11: 5 | F11: 2 | G11: =E11+F11-1 -> 0
A12: PH-07 | B12: Engineered Hardwood Floor Installation | C12: Flooring | D12: Scheduled | E12: 7 | F12: 1 | G12: =E12+F12-1 -> 0
A13: PH-08 | B13: Custom Cabinetry & Kitchen Island Box Install | C13: Carpentry | D13: Scheduled | E13: 8 | F13: 2 | G13: =E13+F13-1 -> 0
A14: PH-09 | B14: Quartz Countertop Slab & Tile Backsplash | C14: Stone / Tile | D14: Scheduled | E14: 9 | F14: 2 | G14: =E14+F14-1 -> 0
A15: PH-10 | B15: Interior Paint, Trim Molding & Enamel Finish | C15: Painting | D15: Scheduled | E15: 10 | F15: 2 | G15: =E15+F15-1 -> 0
A16: PH-11 | B16: MEP Fixtures, Faucet & LED Trim Finish | C16: MEP Subs | D16: Scheduled | E16: 11 | F16: 1 | G16: =E16+F16-1 -> 0
A17: PH-12 | B17: Final Cleanup, Punchlist & Owner Sign-Off | C17: Management | D17: Scheduled | E17: 12 | F17: 1 | G17: =E17+F17-1 -> 0
