Workbook
Name BusinessName: '⚙️ Setup'!$C$6
Name CalMonth: '⚙️ Setup'!$C$18
Name CalYear: '⚙️ Setup'!$C$19
Name ClientsList: OFFSET('👥 Clients'!$C$8,0,0,MAX(1,COUNTA('👥 Clients'!$C$8:$C$47)),1)
Name Currency: '⚙️ Setup'!$C$10
Name DefaultMargin: '⚙️ Setup'!$C$12
Name DepositPct: '⚙️ Setup'!$C$13
Name DueSoonDays: '⚙️ Setup'!$C$14
Name EventList: OFFSET('📅 Events'!$C$8,0,0,MAX(1,COUNTA('📅 Events'!$C$8:$C$47)),1)
Name EventStatuses: '⚙️ Setup'!$C$47:$C$52
Name EventTypes: OFFSET('⚙️ Setup'!$B$23,0,0,MAX(1,COUNTA('⚙️ Setup'!$B$23:$B$42)),1)
Name ExpenseCategories: OFFSET('⚙️ Setup'!$C$23,0,0,MAX(1,COUNTA('⚙️ Setup'!$C$23:$C$42)),1)
Name IngredientCategories: OFFSET('⚙️ Setup'!$G$23,0,0,MAX(1,COUNTA('⚙️ Setup'!$G$23:$G$42)),1)
Name MenuCategories: OFFSET('⚙️ Setup'!$F$23,0,0,MAX(1,COUNTA('⚙️ Setup'!$F$23:$F$42)),1)
Name MenuItems: OFFSET('🍽️ Menu Costing'!$C$8,0,0,MAX(1,COUNTA('🍽️ Menu Costing'!$C$8:$C$37)),1)
Name PaymentMethods: OFFSET('⚙️ Setup'!$D$23,0,0,MAX(1,COUNTA('⚙️ Setup'!$D$23:$D$42)),1)
Name PaymentStatuses: '⚙️ Setup'!$D$47:$D$49
Name ReportYear: '⚙️ Setup'!$C$15
Name StaffRoles: OFFSET('⚙️ Setup'!$E$23,0,0,MAX(1,COUNTA('⚙️ Setup'!$E$23:$E$42)),1)
Name SuppliersList: OFFSET('🚚 Suppliers'!$C$8,0,0,MAX(1,COUNTA('🚚 Suppliers'!$C$8:$C$37)),1)
Name TaxRate: '⚙️ Setup'!$C$11
Name Tick: '⚙️ Setup'!$E$47:$E$48

Sheet _Data
H1: Month | I1: Cash in | J1: Expenses | K1: Profit | L1: Events | N1: Expense category | O1: Spend | AA1: Date | AB1: Event | AC1: Stage | AE1: KPI | AF1: Value
H2: Jan | I2: =SUMIFS('💰 Payments'!$J$8:$J$67,'💰 Payments'!$E$8:$E$67,">="&DATE(ReportYear,1,1),'💰 Payments'!$E$8:$E$67,"<"&DATE(ReportYear,2,1)) -> 0 | J2: =SUMIFS('💸 Expenses'!$G$8:$G$67,'💸 Expenses'!$C$8:$C$67,">="&DATE(ReportYear,1,1),'💸 Expenses'!$C$8:$C$67,"<"&DATE(ReportYear,2,1)) -> 0 | K2: =I2-J2 -> 0 | L2: =COUNTIFS('📅 Events'!$E$8:$E$47,">="&DATE(ReportYear,1,1),'📅 Events'!$E$8:$E$47,"<"&DATE(ReportYear,2,1),'📅 Events'!$C$8:$C$47,"<>") -> 0 | N2: Ingredients | O2: =SUMIF('💸 Expenses'!$E$8:$E$67,$N2,'💸 Expenses'!$G$8:$G$67) -> 0 | AA2: =IF(AND('📅 Events'!$E$8<>"",'📅 Events'!$E$8>=TODAY(),'📅 Events'!$Q$8<>"❌ Cancelled",'📅 Events'!$Q$8<>"🎉 Completed"),'📅 Events'!$E$8,"") | AB2: =IF($AA2="","",'📅 Events'!$D$8&" • "&'📅 Events'!$F$8) | AC2: =IF($AA2="","",'📅 Events'!$Q$8) | AE2: Cash received (deposits + payments) | AF2: =SUM('💰 Payments'!$J$8:$J$67) -> 0
H3: Feb | I3: =SUMIFS('💰 Payments'!$J$8:$J$67,'💰 Payments'!$E$8:$E$67,">="&DATE(ReportYear,2,1),'💰 Payments'!$E$8:$E$67,"<"&DATE(ReportYear,3,1)) -> 0 | J3: =SUMIFS('💸 Expenses'!$G$8:$G$67,'💸 Expenses'!$C$8:$C$67,">="&DATE(ReportYear,2,1),'💸 Expenses'!$C$8:$C$67,"<"&DATE(ReportYear,3,1)) -> 0 | K3: =I3-J3 -> 0 | L3: =COUNTIFS('📅 Events'!$E$8:$E$47,">="&DATE(ReportYear,2,1),'📅 Events'!$E$8:$E$47,"<"&DATE(ReportYear,3,1),'📅 Events'!$C$8:$C$47,"<>") -> 0 | N3: Packaging | O3: =SUMIF('💸 Expenses'!$E$8:$E$67,$N3,'💸 Expenses'!$G$8:$G$67) -> 0 | AA3: =IF(AND('📅 Events'!$E$9<>"",'📅 Events'!$E$9>=TODAY(),'📅 Events'!$Q$9<>"❌ Cancelled",'📅 Events'!$Q$9<>"🎉 Completed"),'📅 Events'!$E$9,"") | AB3: =IF($AA3="","",'📅 Events'!$D$9&" • "&'📅 Events'!$F$9) | AC3: =IF($AA3="","",'📅 Events'!$Q$9) | AE3: Total expenses | AF3: =SUM('💸 Expenses'!$G$8:$G$67) -> 0
H4: Mar | I4: =SUMIFS('💰 Payments'!$J$8:$J$67,'💰 Payments'!$E$8:$E$67,">="&DATE(ReportYear,3,1),'💰 Payments'!$E$8:$E$67,"<"&DATE(ReportYear,4,1)) -> 0 | J4: =SUMIFS('💸 Expenses'!$G$8:$G$67,'💸 Expenses'!$C$8:$C$67,">="&DATE(ReportYear,3,1),'💸 Expenses'!$C$8:$C$67,"<"&DATE(ReportYear,4,1)) -> 0 | K4: =I4-J4 -> 0 | L4: =COUNTIFS('📅 Events'!$E$8:$E$47,">="&DATE(ReportYear,3,1),'📅 Events'!$E$8:$E$47,"<"&DATE(ReportYear,4,1),'📅 Events'!$C$8:$C$47,"<>") -> 0 | N4: Staff / Labor | O4: =SUMIF('💸 Expenses'!$E$8:$E$67,$N4,'💸 Expenses'!$G$8:$G$67) -> 0 | AA4: =IF(AND('📅 Events'!$E$10<>"",'📅 Events'!$E$10>=TODAY(),'📅 Events'!$Q$10<>"❌ Cancelled",'📅 Events'!$Q$10<>"🎉 Completed"),'📅 Events'!$E$10,"") | AB4: =IF($AA4="","",'📅 Events'!$D$10&" • "&'📅 Events'!$F$10) | AC4: =IF($AA4="","",'📅 Events'!$Q$10) | AE4: Net profit | AF4: =$AF$2-$AF$3 -> 0
H5: Apr | I5: =SUMIFS('💰 Payments'!$J$8:$J$67,'💰 Payments'!$E$8:$E$67,">="&DATE(ReportYear,4,1),'💰 Payments'!$E$8:$E$67,"<"&DATE(ReportYear,5,1)) -> 0 | J5: =SUMIFS('💸 Expenses'!$G$8:$G$67,'💸 Expenses'!$C$8:$C$67,">="&DATE(ReportYear,4,1),'💸 Expenses'!$C$8:$C$67,"<"&DATE(ReportYear,5,1)) -> 0 | K5: =I5-J5 -> 0 | L5: =COUNTIFS('📅 Events'!$E$8:$E$47,">="&DATE(ReportYear,4,1),'📅 Events'!$E$8:$E$47,"<"&DATE(ReportYear,5,1),'📅 Events'!$C$8:$C$47,"<>") -> 0 | N5: Transportation | O5: =SUMIF('💸 Expenses'!$E$8:$E$67,$N5,'💸 Expenses'!$G$8:$G$67) -> 0 | AA5: =IF(AND('📅 Events'!$E$11<>"",'📅 Events'!$E$11>=TODAY(),'📅 Events'!$Q$11<>"❌ Cancelled",'📅 Events'!$Q$11<>"🎉 Completed"),'📅 Events'!$E$11,"") | AB5: =IF($AA5="","",'📅 Events'!$D$11&" • "&'📅 Events'!$F$11) | AC5: =IF($AA5="","",'📅 Events'!$Q$11) | AE5: Net profit margin | AF5: =IFERROR($AF$4/$AF$2,0) -> 0
H6: May | I6: =SUMIFS('💰 Payments'!$J$8:$J$67,'💰 Payments'!$E$8:$E$67,">="&DATE(ReportYear,5,1),'💰 Payments'!$E$8:$E$67,"<"&DATE(ReportYear,6,1)) -> 0 | J6: =SUMIFS('💸 Expenses'!$G$8:$G$67,'💸 Expenses'!$C$8:$C$67,">="&DATE(ReportYear,5,1),'💸 Expenses'!$C$8:$C$67,"<"&DATE(ReportYear,6,1)) -> 0 | K6: =I6-J6 -> 0 | L6: =COUNTIFS('📅 Events'!$E$8:$E$47,">="&DATE(ReportYear,5,1),'📅 Events'!$E$8:$E$47,"<"&DATE(ReportYear,6,1),'📅 Events'!$C$8:$C$47,"<>") -> 0 | N6: Equipment | O6: =SUMIF('💸 Expenses'!$E$8:$E$67,$N6,'💸 Expenses'!$G$8:$G$67) -> 0 | AA6: =IF(AND('📅 Events'!$E$12<>"",'📅 Events'!$E$12>=TODAY(),'📅 Events'!$Q$12<>"❌ Cancelled",'📅 Events'!$Q$12<>"🎉 Completed"),'📅 Events'!$E$12,"") | AB6: =IF($AA6="","",'📅 Events'!$D$12&" • "&'📅 Events'!$F$12) | AC6: =IF($AA6="","",'📅 Events'!$Q$12) | AE6: Events on the books | AF6: =COUNTA('📅 Events'!$C$8:$C$47) -> 0
H7: Jun | I7: =SUMIFS('💰 Payments'!$J$8:$J$67,'💰 Payments'!$E$8:$E$67,">="&DATE(ReportYear,6,1),'💰 Payments'!$E$8:$E$67,"<"&DATE(ReportYear,7,1)) -> 0 | J7: =SUMIFS('💸 Expenses'!$G$8:$G$67,'💸 Expenses'!$C$8:$C$67,">="&DATE(ReportYear,6,1),'💸 Expenses'!$C$8:$C$67,"<"&DATE(ReportYear,7,1)) -> 0 | K7: =I7-J7 -> 0 | L7: =COUNTIFS('📅 Events'!$E$8:$E$47,">="&DATE(ReportYear,6,1),'📅 Events'!$E$8:$E$47,"<"&DATE(ReportYear,7,1),'📅 Events'!$C$8:$C$47,"<>") -> 0 | N7: Kitchen Rental | O7: =SUMIF('💸 Expenses'!$E$8:$E$67,$N7,'💸 Expenses'!$G$8:$G$67) -> 0 | AA7: =IF(AND('📅 Events'!$E$13<>"",'📅 Events'!$E$13>=TODAY(),'📅 Events'!$Q$13<>"❌ Cancelled",'📅 Events'!$Q$13<>"🎉 Completed"),'📅 Events'!$E$13,"") | AB7: =IF($AA7="","",'📅 Events'!$D$13&" • "&'📅 Events'!$F$13) | AC7: =IF($AA7="","",'📅 Events'!$Q$13) | AE7: Events completed | AF7: =COUNTIF('📅 Events'!$Q$8:$Q$47,"🎉 Completed") -> 0
H8: Jul | I8: =SUMIFS('💰 Payments'!$J$8:$J$67,'💰 Payments'!$E$8:$E$67,">="&DATE(ReportYear,7,1),'💰 Payments'!$E$8:$E$67,"<"&DATE(ReportYear,8,1)) -> 0 | J8: =SUMIFS('💸 Expenses'!$G$8:$G$67,'💸 Expenses'!$C$8:$C$67,">="&DATE(ReportYear,7,1),'💸 Expenses'!$C$8:$C$67,"<"&DATE(ReportYear,8,1)) -> 0 | K8: =I8-J8 -> 0 | L8: =COUNTIFS('📅 Events'!$E$8:$E$47,">="&DATE(ReportYear,7,1),'📅 Events'!$E$8:$E$47,"<"&DATE(ReportYear,8,1),'📅 Events'!$C$8:$C$47,"<>") -> 0 | N8: Marketing | O8: =SUMIF('💸 Expenses'!$E$8:$E$67,$N8,'💸 Expenses'!$G$8:$G$67) -> 0 | AA8: =IF(AND('📅 Events'!$E$14<>"",'📅 Events'!$E$14>=TODAY(),'📅 Events'!$Q$14<>"❌ Cancelled",'📅 Events'!$Q$14<>"🎉 Completed"),'📅 Events'!$E$14,"") | AB8: =IF($AA8="","",'📅 Events'!$D$14&" • "&'📅 Events'!$F$14) | AC8: =IF($AA8="","",'📅 Events'!$Q$14) | AE8: Events confirmed (upcoming) | AF8: =COUNTIF('📅 Events'!$Q$8:$Q$47,"💰 Deposit Paid")+COUNTIF('📅 Events'!$Q$8:$Q$47,"✅ Confirmed") -> 0
H9: Aug | I9: =SUMIFS('💰 Payments'!$J$8:$J$67,'💰 Payments'!$E$8:$E$67,">="&DATE(ReportYear,8,1),'💰 Payments'!$E$8:$E$67,"<"&DATE(ReportYear,9,1)) -> 0 | J9: =SUMIFS('💸 Expenses'!$G$8:$G$67,'💸 Expenses'!$C$8:$C$67,">="&DATE(ReportYear,8,1),'💸 Expenses'!$C$8:$C$67,"<"&DATE(ReportYear,9,1)) -> 0 | K9: =I9-J9 -> 0 | L9: =COUNTIFS('📅 Events'!$E$8:$E$47,">="&DATE(ReportYear,8,1),'📅 Events'!$E$8:$E$47,"<"&DATE(ReportYear,9,1),'📅 Events'!$C$8:$C$47,"<>") -> 0 | N9: Insurance | O9: =SUMIF('💸 Expenses'!$E$8:$E$67,$N9,'💸 Expenses'!$G$8:$G$67) -> 0 | AA9: =IF(AND('📅 Events'!$E$15<>"",'📅 Events'!$E$15>=TODAY(),'📅 Events'!$Q$15<>"❌ Cancelled",'📅 Events'!$Q$15<>"🎉 Completed"),'📅 Events'!$E$15,"") | AB9: =IF($AA9="","",'📅 Events'!$D$15&" • "&'📅 Events'!$F$15) | AC9: =IF($AA9="","",'📅 Events'!$Q$15) | AE9: Events cancelled | AF9: =COUNTIF('📅 Events'!$Q$8:$Q$47,"❌ Cancelled") -> 0
H10: Sep | I10: =SUMIFS('💰 Payments'!$J$8:$J$67,'💰 Payments'!$E$8:$E$67,">="&DATE(ReportYear,9,1),'💰 Payments'!$E$8:$E$67,"<"&DATE(ReportYear,10,1)) -> 0 | J10: =SUMIFS('💸 Expenses'!$G$8:$G$67,'💸 Expenses'!$C$8:$C$67,">="&DATE(ReportYear,9,1),'💸 Expenses'!$C$8:$C$67,"<"&DATE(ReportYear,10,1)) -> 0 | K10: =I10-J10 -> 0 | L10: =COUNTIFS('📅 Events'!$E$8:$E$47,">="&DATE(ReportYear,9,1),'📅 Events'!$E$8:$E$47,"<"&DATE(ReportYear,10,1),'📅 Events'!$C$8:$C$47,"<>") -> 0 | N10: Utilities | O10: =SUMIF('💸 Expenses'!$E$8:$E$67,$N10,'💸 Expenses'!$G$8:$G$67) -> 0 | AA10: =IF(AND('📅 Events'!$E$16<>"",'📅 Events'!$E$16>=TODAY(),'📅 Events'!$Q$16<>"❌ Cancelled",'📅 Events'!$Q$16<>"🎉 Completed"),'📅 Events'!$E$16,"") | AB10: =IF($AA10="","",'📅 Events'!$D$16&" • "&'📅 Events'!$F$16) | AC10: =IF($AA10="","",'📅 Events'!$Q$16) | AE10: Average order value | AF10: =IFERROR(AVERAGEIF('📅 Events'!$Q$8:$Q$47,"<>❌ Cancelled",'📅 Events'!$L$8:$L$47),0) -> 0
H11: Oct | I11: =SUMIFS('💰 Payments'!$J$8:$J$67,'💰 Payments'!$E$8:$E$67,">="&DATE(ReportYear,10,1),'💰 Payments'!$E$8:$E$67,"<"&DATE(ReportYear,11,1)) -> 0 | J11: =SUMIFS('💸 Expenses'!$G$8:$G$67,'💸 Expenses'!$C$8:$C$67,">="&DATE(ReportYear,10,1),'💸 Expenses'!$C$8:$C$67,"<"&DATE(ReportYear,11,1)) -> 0 | K11: =I11-J11 -> 0 | L11: =COUNTIFS('📅 Events'!$E$8:$E$47,">="&DATE(ReportYear,10,1),'📅 Events'!$E$8:$E$47,"<"&DATE(ReportYear,11,1),'📅 Events'!$C$8:$C$47,"<>") -> 0 | N11: Software | O11: =SUMIF('💸 Expenses'!$E$8:$E$67,$N11,'💸 Expenses'!$G$8:$G$67) -> 0 | AA11: =IF(AND('📅 Events'!$E$17<>"",'📅 Events'!$E$17>=TODAY(),'📅 Events'!$Q$17<>"❌ Cancelled",'📅 Events'!$Q$17<>"🎉 Completed"),'📅 Events'!$E$17,"") | AB11: =IF($AA11="","",'📅 Events'!$D$17&" • "&'📅 Events'!$F$17) | AC11: =IF($AA11="","",'📅 Events'!$Q$17) | AE11: Average guests per event | AF11: =IFERROR(AVERAGEIF('📅 Events'!$Q$8:$Q$47,"<>❌ Cancelled",'📅 Events'!$G$8:$G$47),0) -> 0
H12: Nov | I12: =SUMIFS('💰 Payments'!$J$8:$J$67,'💰 Payments'!$E$8:$E$67,">="&DATE(ReportYear,11,1),'💰 Payments'!$E$8:$E$67,"<"&DATE(ReportYear,12,1)) -> 0 | J12: =SUMIFS('💸 Expenses'!$G$8:$G$67,'💸 Expenses'!$C$8:$C$67,">="&DATE(ReportYear,11,1),'💸 Expenses'!$C$8:$C$67,"<"&DATE(ReportYear,12,1)) -> 0 | K12: =I12-J12 -> 0 | L12: =COUNTIFS('📅 Events'!$E$8:$E$47,">="&DATE(ReportYear,11,1),'📅 Events'!$E$8:$E$47,"<"&DATE(ReportYear,12,1),'📅 Events'!$C$8:$C$47,"<>") -> 0 | N12: Miscellaneous | O12: =SUMIF('💸 Expenses'!$E$8:$E$67,$N12,'💸 Expenses'!$G$8:$G$67) -> 0 | AA12: =IF(AND('📅 Events'!$E$18<>"",'📅 Events'!$E$18>=TODAY(),'📅 Events'!$Q$18<>"❌ Cancelled",'📅 Events'!$Q$18<>"🎉 Completed"),'📅 Events'!$E$18,"") | AB12: =IF($AA12="","",'📅 Events'!$D$18&" • "&'📅 Events'!$F$18) | AC12: =IF($AA12="","",'📅 Events'!$Q$18) | AE12: Average profit per event | AF12: =IFERROR(AVERAGEIFS('📅 Events'!$M$8:$M$47,'📅 Events'!$Q$8:$Q$47,"<>❌ Cancelled"),0) -> 0
H13: Dec | I13: =SUMIFS('💰 Payments'!$J$8:$J$67,'💰 Payments'!$E$8:$E$67,">="&DATE(ReportYear,12,1),'💰 Payments'!$E$8:$E$67,"<"&DATE(ReportYear+1,1,1)) -> 0 | J13: =SUMIFS('💸 Expenses'!$G$8:$G$67,'💸 Expenses'!$C$8:$C$67,">="&DATE(ReportYear,12,1),'💸 Expenses'!$C$8:$C$67,"<"&DATE(ReportYear+1,1,1)) -> 0 | K13: =I13-J13 -> 0 | L13: =COUNTIFS('📅 Events'!$E$8:$E$47,">="&DATE(ReportYear,12,1),'📅 Events'!$E$8:$E$47,"<"&DATE(ReportYear+1,1,1),'📅 Events'!$C$8:$C$47,"<>") -> 0 | AA13: =IF(AND('📅 Events'!$E$19<>"",'📅 Events'!$E$19>=TODAY(),'📅 Events'!$Q$19<>"❌ Cancelled",'📅 Events'!$Q$19<>"🎉 Completed"),'📅 Events'!$E$19,"") | AB13: =IF($AA13="","",'📅 Events'!$D$19&" • "&'📅 Events'!$F$19) | AC13: =IF($AA13="","",'📅 Events'!$Q$19) | AE13: Guests catered (completed) | AF13: =SUMIF('📅 Events'!$Q$8:$Q$47,"🎉 Completed",'📅 Events'!$G$8:$G$47) -> 0
AA14: =IF(AND('📅 Events'!$E$20<>"",'📅 Events'!$E$20>=TODAY(),'📅 Events'!$Q$20<>"❌ Cancelled",'📅 Events'!$Q$20<>"🎉 Completed"),'📅 Events'!$E$20,"") | AB14: =IF($AA14="","",'📅 Events'!$D$20&" • "&'📅 Events'!$F$20) | AC14: =IF($AA14="","",'📅 Events'!$Q$20) | AE14: Outstanding receivables | AF14: =SUMIF('💰 Payments'!$K$8:$K$67,">0") -> 0
N15: Event type | O15: Booked value | AA15: =IF(AND('📅 Events'!$E$21<>"",'📅 Events'!$E$21>=TODAY(),'📅 Events'!$Q$21<>"❌ Cancelled",'📅 Events'!$Q$21<>"🎉 Completed"),'📅 Events'!$E$21,"") | AB15: =IF($AA15="","",'📅 Events'!$D$21&" • "&'📅 Events'!$F$21) | AC15: =IF($AA15="","",'📅 Events'!$Q$21) | AE15: Overdue invoices | AF15: =SUMPRODUCT(('💰 Payments'!$K$8:$K$67>0)*('💰 Payments'!$L$8:$L$67<>"")*('💰 Payments'!$L$8:$L$67<TODAY())) -> 0
N16: Wedding | O16: =SUMIFS('📅 Events'!$L$8:$L$47,'📅 Events'!$F$8:$F$47,$N16,'📅 Events'!$Q$8:$Q$47,"<>❌ Cancelled") -> 0 | AA16: =IF(AND('📅 Events'!$E$22<>"",'📅 Events'!$E$22>=TODAY(),'📅 Events'!$Q$22<>"❌ Cancelled",'📅 Events'!$Q$22<>"🎉 Completed"),'📅 Events'!$E$22,"") | AB16: =IF($AA16="","",'📅 Events'!$D$22&" • "&'📅 Events'!$F$22) | AC16: =IF($AA16="","",'📅 Events'!$Q$22) | AE16: Invoices still open | AF16: =COUNTIF('💰 Payments'!$K$8:$K$67,">0") -> 0
N17: Corporate | O17: =SUMIFS('📅 Events'!$L$8:$L$47,'📅 Events'!$F$8:$F$47,$N17,'📅 Events'!$Q$8:$Q$47,"<>❌ Cancelled") -> 0 | AA17: =IF(AND('📅 Events'!$E$23<>"",'📅 Events'!$E$23>=TODAY(),'📅 Events'!$Q$23<>"❌ Cancelled",'📅 Events'!$Q$23<>"🎉 Completed"),'📅 Events'!$E$23,"") | AB17: =IF($AA17="","",'📅 Events'!$D$23&" • "&'📅 Events'!$F$23) | AC17: =IF($AA17="","",'📅 Events'!$Q$23) | AE17: Ingredient & packaging spend | AF17: =SUMIF('💸 Expenses'!$E$8:$E$67,"Ingredients",'💸 Expenses'!$G$8:$G$67)+SUMIF('💸 Expenses'!$E$8:$E$67,"Packaging",'💸 Expenses'!$G$8:$G$67) -> 0
N18: Birthday | O18: =SUMIFS('📅 Events'!$L$8:$L$47,'📅 Events'!$F$8:$F$47,$N18,'📅 Events'!$Q$8:$Q$47,"<>❌ Cancelled") -> 0 | AA18: =IF(AND('📅 Events'!$E$24<>"",'📅 Events'!$E$24>=TODAY(),'📅 Events'!$Q$24<>"❌ Cancelled",'📅 Events'!$Q$24<>"🎉 Completed"),'📅 Events'!$E$24,"") | AB18: =IF($AA18="","",'📅 Events'!$D$24&" • "&'📅 Events'!$F$24) | AC18: =IF($AA18="","",'📅 Events'!$Q$24) | AE18: Staff / labor spend | AF18: =SUMIF('💸 Expenses'!$E$8:$E$67,"Staff / Labor",'💸 Expenses'!$G$8:$G$67) -> 0
N19: Private Party | O19: =SUMIFS('📅 Events'!$L$8:$L$47,'📅 Events'!$F$8:$F$47,$N19,'📅 Events'!$Q$8:$Q$47,"<>❌ Cancelled") -> 0 | AA19: =IF(AND('📅 Events'!$E$25<>"",'📅 Events'!$E$25>=TODAY(),'📅 Events'!$Q$25<>"❌ Cancelled",'📅 Events'!$Q$25<>"🎉 Completed"),'📅 Events'!$E$25,"") | AB19: =IF($AA19="","",'📅 Events'!$D$25&" • "&'📅 Events'!$F$25) | AC19: =IF($AA19="","",'📅 Events'!$Q$25) | AE19: Food cost % of revenue | AF19: =IFERROR($AF$17/$AF$2,0) -> 0
N20: Buffet | O20: =SUMIFS('📅 Events'!$L$8:$L$47,'📅 Events'!$F$8:$F$47,$N20,'📅 Events'!$Q$8:$Q$47,"<>❌ Cancelled") -> 0 | AA20: =IF(AND('📅 Events'!$E$26<>"",'📅 Events'!$E$26>=TODAY(),'📅 Events'!$Q$26<>"❌ Cancelled",'📅 Events'!$Q$26<>"🎉 Completed"),'📅 Events'!$E$26,"") | AB20: =IF($AA20="","",'📅 Events'!$D$26&" • "&'📅 Events'!$F$26) | AC20: =IF($AA20="","",'📅 Events'!$Q$26) | AE20: Labor cost % of revenue | AF20: =IFERROR($AF$18/$AF$2,0) -> 0
N21: Cocktail | O21: =SUMIFS('📅 Events'!$L$8:$L$47,'📅 Events'!$F$8:$F$47,$N21,'📅 Events'!$Q$8:$Q$47,"<>❌ Cancelled") -> 0 | AA21: =IF(AND('📅 Events'!$E$27<>"",'📅 Events'!$E$27>=TODAY(),'📅 Events'!$Q$27<>"❌ Cancelled",'📅 Events'!$Q$27<>"🎉 Completed"),'📅 Events'!$E$27,"") | AB21: =IF($AA21="","",'📅 Events'!$D$27&" • "&'📅 Events'!$F$27) | AC21: =IF($AA21="","",'📅 Events'!$Q$27) | AE21: Repeat customer % | AF21: =IFERROR(SUMPRODUCT(('👥 Clients'!$C$8:$C$47<>"")*(COUNTIF('📅 Events'!$D$8:$D$47,'👥 Clients'!$C$8:$C$47)>1))/COUNTIF('👥 Clients'!$C$8:$C$47,"?*"),0) -> 0
N22: Conference | O22: =SUMIFS('📅 Events'!$L$8:$L$47,'📅 Events'!$F$8:$F$47,$N22,'📅 Events'!$Q$8:$Q$47,"<>❌ Cancelled") -> 0 | AA22: =IF(AND('📅 Events'!$E$28<>"",'📅 Events'!$E$28>=TODAY(),'📅 Events'!$Q$28<>"❌ Cancelled",'📅 Events'!$Q$28<>"🎉 Completed"),'📅 Events'!$E$28,"") | AB22: =IF($AA22="","",'📅 Events'!$D$28&" • "&'📅 Events'!$F$28) | AC22: =IF($AA22="","",'📅 Events'!$Q$28) | AE22: Inventory value | AF22: =SUM('📦 Inventory'!$I$8:$I$47) -> 0
N23: Festival | O23: =SUMIFS('📅 Events'!$L$8:$L$47,'📅 Events'!$F$8:$F$47,$N23,'📅 Events'!$Q$8:$Q$47,"<>❌ Cancelled") -> 0 | AA23: =IF(AND('📅 Events'!$E$29<>"",'📅 Events'!$E$29>=TODAY(),'📅 Events'!$Q$29<>"❌ Cancelled",'📅 Events'!$Q$29<>"🎉 Completed"),'📅 Events'!$E$29,"") | AB23: =IF($AA23="","",'📅 Events'!$D$29&" • "&'📅 Events'!$F$29) | AC23: =IF($AA23="","",'📅 Events'!$Q$29) | AE23: Ingredients below minimum | AF23: =COUNTIF('📦 Inventory'!$K$8:$K$47,"🔴 Reorder") -> 0
N24: Other | O24: =SUMIFS('📅 Events'!$L$8:$L$47,'📅 Events'!$F$8:$F$47,$N24,'📅 Events'!$Q$8:$Q$47,"<>❌ Cancelled") -> 0 | AA24: =IF(AND('📅 Events'!$E$30<>"",'📅 Events'!$E$30>=TODAY(),'📅 Events'!$Q$30<>"❌ Cancelled",'📅 Events'!$Q$30<>"🎉 Completed"),'📅 Events'!$E$30,"") | AB24: =IF($AA24="","",'📅 Events'!$D$30&" • "&'📅 Events'!$F$30) | AC24: =IF($AA24="","",'📅 Events'!$Q$30) | AE24: Shopping lines open | AF24: =COUNTIFS('🛒 Shopping List'!$G$8:$G$47,">0",'🛒 Shopping List'!$J$8:$J$47,"<>✓") -> 0
Q25: Client | R25: Cash received | T25: Menu item | U25: Booked | AA25: =IF(AND('📅 Events'!$E$31<>"",'📅 Events'!$E$31>=TODAY(),'📅 Events'!$Q$31<>"❌ Cancelled",'📅 Events'!$Q$31<>"🎉 Completed"),'📅 Events'!$E$31,"") | AB25: =IF($AA25="","",'📅 Events'!$D$31&" • "&'📅 Events'!$F$31) | AC25: =IF($AA25="","",'📅 Events'!$Q$31) | AE25: Shopping list estimated cost | AF25: =SUMIF('🛒 Shopping List'!$J$8:$J$47,"<>✓",'🛒 Shopping List'!$I$8:$I$47) -> 0
Q26: =IF('👥 Clients'!$C$8="","",'👥 Clients'!$C$8) | R26: =IF($Q26="",0,SUMIF('💰 Payments'!$D$8:$D$67,$Q26,'💰 Payments'!$J$8:$J$67)) -> 0 | T26: =IF('🍽️ Menu Costing'!$C$8="","",'🍽️ Menu Costing'!$C$8) | U26: =IF($T26="",0,COUNTIF('📅 Events'!$H$8:$H$47,"*"&$T26&"*")) -> 0 | AA26: =IF(AND('📅 Events'!$E$32<>"",'📅 Events'!$E$32>=TODAY(),'📅 Events'!$Q$32<>"❌ Cancelled",'📅 Events'!$Q$32<>"🎉 Completed"),'📅 Events'!$E$32,"") | AB26: =IF($AA26="","",'📅 Events'!$D$32&" • "&'📅 Events'!$F$32) | AC26: =IF($AA26="","",'📅 Events'!$Q$32) | AE26: Unpaid staff shifts | AF26: =SUMPRODUCT(('👷 Staff & Labor'!$C$8:$C$57<>"")*('👷 Staff & Labor'!$J$8:$J$57<>"✓")) -> 0
N27: Pipeline stage | O27: Events | Q27: =IF('👥 Clients'!$C$9="","",'👥 Clients'!$C$9) | R27: =IF($Q27="",0,SUMIF('💰 Payments'!$D$8:$D$67,$Q27,'💰 Payments'!$J$8:$J$67)) -> 0 | T27: =IF('🍽️ Menu Costing'!$C$9="","",'🍽️ Menu Costing'!$C$9) | U27: =IF($T27="",0,COUNTIF('📅 Events'!$H$8:$H$47,"*"&$T27&"*")) -> 0 | AA27: =IF(AND('📅 Events'!$E$33<>"",'📅 Events'!$E$33>=TODAY(),'📅 Events'!$Q$33<>"❌ Cancelled",'📅 Events'!$Q$33<>"🎉 Completed"),'📅 Events'!$E$33,"") | AB27: =IF($AA27="","",'📅 Events'!$D$33&" • "&'📅 Events'!$F$33) | AC27: =IF($AA27="","",'📅 Events'!$Q$33) | AE27: Equipment value | AF27: =SUM('🍳 Equipment'!$J$8:$J$42) -> 0
N28: 💬 Inquiry | O28: =COUNTIF('📅 Events'!$Q$8:$Q$47,$N28) -> 0 | Q28: =IF('👥 Clients'!$C$10="","",'👥 Clients'!$C$10) | R28: =IF($Q28="",0,SUMIF('💰 Payments'!$D$8:$D$67,$Q28,'💰 Payments'!$J$8:$J$67)) -> 0 | T28: =IF('🍽️ Menu Costing'!$C$10="","",'🍽️ Menu Costing'!$C$10) | U28: =IF($T28="",0,COUNTIF('📅 Events'!$H$8:$H$47,"*"&$T28&"*")) -> 0 | AA28: =IF(AND('📅 Events'!$E$34<>"",'📅 Events'!$E$34>=TODAY(),'📅 Events'!$Q$34<>"❌ Cancelled",'📅 Events'!$Q$34<>"🎉 Completed"),'📅 Events'!$E$34,"") | AB28: =IF($AA28="","",'📅 Events'!$D$34&" • "&'📅 Events'!$F$34) | AC28: =IF($AA28="","",'📅 Events'!$Q$34) | AE28: Equipment needing service | AF28: =COUNTIF('🍳 Equipment'!$L$8:$L$42,"🔧 Service")+COUNTIF('🍳 Equipment'!$L$8:$L$42,"🟡 Soon") -> 0
N29: 📝 Quote Sent | O29: =COUNTIF('📅 Events'!$Q$8:$Q$47,$N29) -> 0 | Q29: =IF('👥 Clients'!$C$11="","",'👥 Clients'!$C$11) | R29: =IF($Q29="",0,SUMIF('💰 Payments'!$D$8:$D$67,$Q29,'💰 Payments'!$J$8:$J$67)) -> 0 | T29: =IF('🍽️ Menu Costing'!$C$11="","",'🍽️ Menu Costing'!$C$11) | U29: =IF($T29="",0,COUNTIF('📅 Events'!$H$8:$H$47,"*"&$T29&"*")) -> 0 | AA29: =IF(AND('📅 Events'!$E$35<>"",'📅 Events'!$E$35>=TODAY(),'📅 Events'!$Q$35<>"❌ Cancelled",'📅 Events'!$Q$35<>"🎉 Completed"),'📅 Events'!$E$35,"") | AB29: =IF($AA29="","",'📅 Events'!$D$35&" • "&'📅 Events'!$F$35) | AC29: =IF($AA29="","",'📅 Events'!$Q$35) | AE29: Tax collected on sales | AF29: =ROUND(SUM('💰 Payments'!$F$8:$F$67)*TaxRate,2) -> 0
N30: 💰 Deposit Paid | O30: =COUNTIF('📅 Events'!$Q$8:$Q$47,$N30) -> 0 | Q30: =IF('👥 Clients'!$C$12="","",'👥 Clients'!$C$12) | R30: =IF($Q30="",0,SUMIF('💰 Payments'!$D$8:$D$67,$Q30,'💰 Payments'!$J$8:$J$67)) -> 0 | T30: =IF('🍽️ Menu Costing'!$C$12="","",'🍽️ Menu Costing'!$C$12) | U30: =IF($T30="",0,COUNTIF('📅 Events'!$H$8:$H$47,"*"&$T30&"*")) -> 0 | AA30: =IF(AND('📅 Events'!$E$36<>"",'📅 Events'!$E$36>=TODAY(),'📅 Events'!$Q$36<>"❌ Cancelled",'📅 Events'!$Q$36<>"🎉 Completed"),'📅 Events'!$E$36,"") | AB30: =IF($AA30="","",'📅 Events'!$D$36&" • "&'📅 Events'!$F$36) | AC30: =IF($AA30="","",'📅 Events'!$Q$36) | AE30: Estimated tax still due | AF30: ='🧾 Tax Tracker'!$G$13 -> 0
N31: ✅ Confirmed | O31: =COUNTIF('📅 Events'!$Q$8:$Q$47,$N31) -> 0 | Q31: =IF('👥 Clients'!$C$13="","",'👥 Clients'!$C$13) | R31: =IF($Q31="",0,SUMIF('💰 Payments'!$D$8:$D$67,$Q31,'💰 Payments'!$J$8:$J$67)) -> 0 | T31: =IF('🍽️ Menu Costing'!$C$13="","",'🍽️ Menu Costing'!$C$13) | U31: =IF($T31="",0,COUNTIF('📅 Events'!$H$8:$H$47,"*"&$T31&"*")) -> 0 | AA31: =IF(AND('📅 Events'!$E$37<>"",'📅 Events'!$E$37>=TODAY(),'📅 Events'!$Q$37<>"❌ Cancelled",'📅 Events'!$Q$37<>"🎉 Completed"),'📅 Events'!$E$37,"") | AB31: =IF($AA31="","",'📅 Events'!$D$37&" • "&'📅 Events'!$F$37) | AC31: =IF($AA31="","",'📅 Events'!$Q$37) | AE31: Quote calculator: recommended price | AF31: ='🧮 Quote Calculator'!$J$16
N32: 🎉 Completed | O32: =COUNTIF('📅 Events'!$Q$8:$Q$47,$N32) -> 0 | Q32: =IF('👥 Clients'!$C$14="","",'👥 Clients'!$C$14) | R32: =IF($Q32="",0,SUMIF('💰 Payments'!$D$8:$D$67,$Q32,'💰 Payments'!$J$8:$J$67)) -> 0 | T32: =IF('🍽️ Menu Costing'!$C$14="","",'🍽️ Menu Costing'!$C$14) | U32: =IF($T32="",0,COUNTIF('📅 Events'!$H$8:$H$47,"*"&$T32&"*")) -> 0 | AA32: =IF(AND('📅 Events'!$E$38<>"",'📅 Events'!$E$38>=TODAY(),'📅 Events'!$Q$38<>"❌ Cancelled",'📅 Events'!$Q$38<>"🎉 Completed"),'📅 Events'!$E$38,"") | AB32: =IF($AA32="","",'📅 Events'!$D$38&" • "&'📅 Events'!$F$38) | AC32: =IF($AA32="","",'📅 Events'!$Q$38) | AE32: Quote calculator: price per guest | AF32: ='🧮 Quote Calculator'!$J$17
N33: ❌ Cancelled | O33: =COUNTIF('📅 Events'!$Q$8:$Q$47,$N33) -> 0 | Q33: =IF('👥 Clients'!$C$15="","",'👥 Clients'!$C$15) | R33: =IF($Q33="",0,SUMIF('💰 Payments'!$D$8:$D$67,$Q33,'💰 Payments'!$J$8:$J$67)) -> 0 | T33: =IF('🍽️ Menu Costing'!$C$15="","",'🍽️ Menu Costing'!$C$15) | U33: =IF($T33="",0,COUNTIF('📅 Events'!$H$8:$H$47,"*"&$T33&"*")) -> 0 | AA33: =IF(AND('📅 Events'!$E$39<>"",'📅 Events'!$E$39>=TODAY(),'📅 Events'!$Q$39<>"❌ Cancelled",'📅 Events'!$Q$39<>"🎉 Completed"),'📅 Events'!$E$39,"") | AB33: =IF($AA33="","",'📅 Events'!$D$39&" • "&'📅 Events'!$F$39) | AC33: =IF($AA33="","",'📅 Events'!$Q$39) | AE33: Menu items priced | AF33: =COUNTA('🍽️ Menu Costing'!$C$8:$C$37) -> 0
Q34: =IF('👥 Clients'!$C$16="","",'👥 Clients'!$C$16) | R34: =IF($Q34="",0,SUMIF('💰 Payments'!$D$8:$D$67,$Q34,'💰 Payments'!$J$8:$J$67)) -> 0 | T34: =IF('🍽️ Menu Costing'!$C$16="","",'🍽️ Menu Costing'!$C$16) | U34: =IF($T34="",0,COUNTIF('📅 Events'!$H$8:$H$47,"*"&$T34&"*")) -> 0 | AA34: =IF(AND('📅 Events'!$E$40<>"",'📅 Events'!$E$40>=TODAY(),'📅 Events'!$Q$40<>"❌ Cancelled",'📅 Events'!$Q$40<>"🎉 Completed"),'📅 Events'!$E$40,"") | AB34: =IF($AA34="","",'📅 Events'!$D$40&" • "&'📅 Events'!$F$40) | AC34: =IF($AA34="","",'📅 Events'!$Q$40) | AE34: Average menu margin | AF34: =IFERROR(AVERAGE('🍽️ Menu Costing'!$J$8:$J$37),0) -> 0
Q35: =IF('👥 Clients'!$C$17="","",'👥 Clients'!$C$17) | R35: =IF($Q35="",0,SUMIF('💰 Payments'!$D$8:$D$67,$Q35,'💰 Payments'!$J$8:$J$67)) -> 0 | T35: =IF('🍽️ Menu Costing'!$C$17="","",'🍽️ Menu Costing'!$C$17) | U35: =IF($T35="",0,COUNTIF('📅 Events'!$H$8:$H$47,"*"&$T35&"*")) -> 0 | AA35: =IF(AND('📅 Events'!$E$41<>"",'📅 Events'!$E$41>=TODAY(),'📅 Events'!$Q$41<>"❌ Cancelled",'📅 Events'!$Q$41<>"🎉 Completed"),'📅 Events'!$E$41,"") | AB35: =IF($AA35="","",'📅 Events'!$D$41&" • "&'📅 Events'!$F$41) | AC35: =IF($AA35="","",'📅 Events'!$Q$41) | AE35: Best earning event type | AF35: =IF(MAX($O$16:$O$24)<=0,"-",INDEX($N$16:$N$24,MATCH(MAX($O$16:$O$24),$O$16:$O$24,0))) -> -
Q36: =IF('👥 Clients'!$C$18="","",'👥 Clients'!$C$18) | R36: =IF($Q36="",0,SUMIF('💰 Payments'!$D$8:$D$67,$Q36,'💰 Payments'!$J$8:$J$67)) -> 0 | T36: =IF('🍽️ Menu Costing'!$C$18="","",'🍽️ Menu Costing'!$C$18) | U36: =IF($T36="",0,COUNTIF('📅 Events'!$H$8:$H$47,"*"&$T36&"*")) -> 0 | AA36: =IF(AND('📅 Events'!$E$42<>"",'📅 Events'!$E$42>=TODAY(),'📅 Events'!$Q$42<>"❌ Cancelled",'📅 Events'!$Q$42<>"🎉 Completed"),'📅 Events'!$E$42,"") | AB36: =IF($AA36="","",'📅 Events'!$D$42&" • "&'📅 Events'!$F$42) | AC36: =IF($AA36="","",'📅 Events'!$Q$42) | AE36: Highest value client | AF36: =IF(MAX($R$26:$R$45)<=0,"-",INDEX($Q$26:$Q$45,MATCH(MAX($R$26:$R$45),$R$26:$R$45,0))) -> -
Q37: =IF('👥 Clients'!$C$19="","",'👥 Clients'!$C$19) | R37: =IF($Q37="",0,SUMIF('💰 Payments'!$D$8:$D$67,$Q37,'💰 Payments'!$J$8:$J$67)) -> 0 | T37: =IF('🍽️ Menu Costing'!$C$19="","",'🍽️ Menu Costing'!$C$19) | U37: =IF($T37="",0,COUNTIF('📅 Events'!$H$8:$H$47,"*"&$T37&"*")) -> 0 | AA37: =IF(AND('📅 Events'!$E$43<>"",'📅 Events'!$E$43>=TODAY(),'📅 Events'!$Q$43<>"❌ Cancelled",'📅 Events'!$Q$43<>"🎉 Completed"),'📅 Events'!$E$43,"") | AB37: =IF($AA37="","",'📅 Events'!$D$43&" • "&'📅 Events'!$F$43) | AC37: =IF($AA37="","",'📅 Events'!$Q$43)
Q38: =IF('👥 Clients'!$C$20="","",'👥 Clients'!$C$20) | R38: =IF($Q38="",0,SUMIF('💰 Payments'!$D$8:$D$67,$Q38,'💰 Payments'!$J$8:$J$67)) -> 0 | T38: =IF('🍽️ Menu Costing'!$C$20="","",'🍽️ Menu Costing'!$C$20) | U38: =IF($T38="",0,COUNTIF('📅 Events'!$H$8:$H$47,"*"&$T38&"*")) -> 0 | AA38: =IF(AND('📅 Events'!$E$44<>"",'📅 Events'!$E$44>=TODAY(),'📅 Events'!$Q$44<>"❌ Cancelled",'📅 Events'!$Q$44<>"🎉 Completed"),'📅 Events'!$E$44,"") | AB38: =IF($AA38="","",'📅 Events'!$D$44&" • "&'📅 Events'!$F$44) | AC38: =IF($AA38="","",'📅 Events'!$Q$44)
Q39: =IF('👥 Clients'!$C$21="","",'👥 Clients'!$C$21) | R39: =IF($Q39="",0,SUMIF('💰 Payments'!$D$8:$D$67,$Q39,'💰 Payments'!$J$8:$J$67)) -> 0 | T39: =IF('🍽️ Menu Costing'!$C$21="","",'🍽️ Menu Costing'!$C$21) | U39: =IF($T39="",0,COUNTIF('📅 Events'!$H$8:$H$47,"*"&$T39&"*")) -> 0 | AA39: =IF(AND('📅 Events'!$E$45<>"",'📅 Events'!$E$45>=TODAY(),'📅 Events'!$Q$45<>"❌ Cancelled",'📅 Events'!$Q$45<>"🎉 Completed"),'📅 Events'!$E$45,"") | AB39: =IF($AA39="","",'📅 Events'!$D$45&" • "&'📅 Events'!$F$45) | AC39: =IF($AA39="","",'📅 Events'!$Q$45)
Q40: =IF('👥 Clients'!$C$22="","",'👥 Clients'!$C$22) | R40: =IF($Q40="",0,SUMIF('💰 Payments'!$D$8:$D$67,$Q40,'💰 Payments'!$J$8:$J$67)) -> 0 | T40: =IF('🍽️ Menu Costing'!$C$22="","",'🍽️ Menu Costing'!$C$22) | U40: =IF($T40="",0,COUNTIF('📅 Events'!$H$8:$H$47,"*"&$T40&"*")) -> 0 | AA40: =IF(AND('📅 Events'!$E$46<>"",'📅 Events'!$E$46>=TODAY(),'📅 Events'!$Q$46<>"❌ Cancelled",'📅 Events'!$Q$46<>"🎉 Completed"),'📅 Events'!$E$46,"") | AB40: =IF($AA40="","",'📅 Events'!$D$46&" • "&'📅 Events'!$F$46) | AC40: =IF($AA40="","",'📅 Events'!$Q$46)
...

Sheet ⚙️ Setup
B2: ⚙️ Setup — make it your business
B3: Set these once and every tab, quote, alert and dropdown follows automatically. | H3: 🏠 Back to Dashboard
B5: 👨‍🍳 YOUR BUSINESS
B6: Business name | D6: Shown on the dashboard hero and on the printable invoice.
B7: Dashboard message / focus | D7: One line under the dashboard title: this week's priority, a reminder, or a little motivation.
B9: 💰 MONEY DEFAULTS
B10: Currency symbol | C10: $ | D10: Every summary readout prefixes amounts with this. To show it inside the tables too: select the money columns → Home → Number format → Currency.
B11: Tax rate (sales tax / GST) | C11: 0 | D11: Applied on the 🧾 Tax tab and the printable invoice. Use 0% if you are not tax registered.
B12: Default target margin | C12: 0.35 | D12: The 🧮 Quote Calculator starts from this. A 35% margin means price = total cost ÷ 0.65.
B13: Default deposit % | C13: 0.4 | D13: Suggested deposit on quotes and invoices.
B14: “Due soon” window (days) | C14: 7 | D14: Payment due dates inside this many days turn orange; past-due turns red everywhere.
B15: Reporting year | C15: 2026 | D15: The 📈 P&L tab and the monthly charts report on this year.
B17: 📆 EVENT CALENDAR MONTH
B18: Calendar month (1-12) | C18: 9 | D18: Which month the 📆 Event Calendar tab displays (9 = September).
B19: Calendar year | C19: 2026
B21: 📋 YOUR LISTS — edit any time; every dropdown in the workbook updates itself
B22: Event types | C22: Expense categories | D22: Payment methods | E22: Staff roles | F22: Menu categories | G22: Ingredient categories
B23: Wedding | C23: Ingredients | D23: Cash | E23: Head Chef | F23: Starter | G23: Produce
B24: Corporate | C24: Packaging | D24: Bank Transfer | E24: Chef | F24: Main | G24: Meat & Fish
B25: Birthday | C25: Staff / Labor | D25: Card | E25: Sous Chef | F25: Dessert | G25: Dairy
B26: Private Party | C26: Transportation | D26: Cheque | E26: Server | F26: Sides | G26: Pantry
B27: Buffet | C27: Equipment | D27: Mobile Wallet | E27: Bartender | F27: Beverage | G27: Bakery
B28: Cocktail | C28: Kitchen Rental | D28: Other | E28: Driver | F28: Canapé | G28: Beverages
B29: Conference | C29: Marketing | E29: Setup Crew | F29: Other | G29: Packaging
B30: Festival | C30: Insurance | E30: Cleaner | G30: Other
B31: Other | C31: Utilities | E31: Manager
C32: Software | E32: Other
C33: Miscellaneous
B43: • Type over the defaults with your own words — add as many as you like (20 rows each). • Don't leave a blank row in the middle of a list: the dropdown stops at the first gap. • Deleting a word here does NOT delete your events or expenses — it only removes it from the dropdown.
B45: 🔒 FIXED LISTS — colours, counts and dashboard maths depend on this exact wording, so they are locked
C46: Event pipeline | D46: Payment status | E46: Tick box
C47: 💬 Inquiry | D47: 🔴 Unpaid | E47: ✓
C48: 📝 Quote Sent | D48: 🟠 Partial
C49: 💰 Deposit Paid | D49: 🟢 Paid in full
C50: ✅ Confirmed
C51: 🎉 Completed
C52: ❌ Cancelled
B54: 💡 Everything else is formula-driven: you never have to touch a formula, only these settings and the white input cells on each tab.
B56: ▶ Setup | D56: 🏠 Home | F56: Clients | H56: Events
B57: Quote | D57: Menu | F57: Stock | H57: Shop
...

Sheet 📊 Dashboard
B2: =IF(BusinessName="","🍽️ Catering Command Center","🍽️ "&BusinessName&" • Catering Command Center") -> 🍽️ Catering Command Center
B3: =IF(IFERROR(SMALL('_Data'!$AA$2:$AA$41,1),"")="","🌴 No upcoming events — add one on the 📅 Events tab!","🔥 Next event: "&IFERROR(INDEX('_Data'!$AB$2:$AB$41,MATCH(IFERROR(SMALL('_Data'!$AA$2:$AA$41,1),""),'_Data'!$AA$2:$AA$41,0)),"")&" — in "&(IFERROR(SMALL('_Data'!$AA$2:$AA$41,1),"")-TODAY())&" day(s)") -> 🌴 No upcoming events — add one on the 📅 Events tab!
B4: =TEXT(TODAY(),"dddd, dd mmmm yyyy")&" • "&'_Data'!$AF$6&" events on the books • "&Currency&TEXT('_Data'!$AF$2,"#,##0")&" cash received • "&Currency&TEXT('_Data'!$AF$14,"#,##0")&" still outstanding" -> Saturday, 12 September 2026 • 0 events on the books • $0 cash received • $0 still outstanding
B5: =IF('⚙️ Setup'!$C$7="","","📣 "&'⚙️ Setup'!$C$7)
B7: 💰 BUSINESS AT A GLANCE
B8: CASH RECEIVED | D8: TOTAL EXPENSES | F8: NET PROFIT | H8: NET MARGIN | J8: EVENTS ON BOOKS | L8: AVG ORDER VALUE
B9: =Currency&TEXT('_Data'!$AF$2,"#,##0") -> $0 | D9: =Currency&TEXT('_Data'!$AF$3,"#,##0") -> $0 | F9: =Currency&TEXT('_Data'!$AF$4,"#,##0") -> $0 | H9: ='_Data'!$AF$5 -> 0 | J9: ='_Data'!$AF$6 -> 0 | L9: =Currency&TEXT('_Data'!$AF$10,"#,##0") -> $0
B10: UPCOMING BOOKED | D10: OUTSTANDING | F10: OVERDUE INVOICES | H10: LOW-STOCK ITEMS | J10: UNPAID SHIFTS | L10: INVENTORY VALUE
B11: ='_Data'!$AF$8 -> 0 | D11: =Currency&TEXT('_Data'!$AF$14,"#,##0") -> $0 | F11: ='_Data'!$AF$15 -> 0 | H11: ='_Data'!$AF$23 -> 0 | J11: ='_Data'!$AF$26 -> 0 | L11: =Currency&TEXT('_Data'!$AF$22,"#,##0") -> $0
B12: Net margin | D12: =IFERROR(REPT("█",ROUND(MIN(1,IFERROR(('_Data'!$AF$4)/('_Data'!$AF$2),0))*34,0))&REPT("░",34-ROUND(MIN(1,IFERROR(('_Data'!$AF$4)/('_Data'!$AF$2),0))*34,0)),"░░░░░░░░░░░░░░░░░░░░░░░░░░░░░░░░░░") -> ░░░░░░░░░░░░░░░░░░░░░░░░░░░░░░░░░░ | K12: =TEXT('_Data'!$AF$5,"0.0%") -> 0.0%
B13: Food cost % of cash in | D13: =IFERROR(REPT("█",ROUND(MIN(1,IFERROR(('_Data'!$AF$17)/('_Data'!$AF$2),0))*34,0))&REPT("░",34-ROUND(MIN(1,IFERROR(('_Data'!$AF$17)/('_Data'!$AF$2),0))*34,0)),"░░░░░░░░░░░░░░░░░░░░░░░░░░░░░░░░░░") -> ░░░░░░░░░░░░░░░░░░░░░░░░░░░░░░░░░░ | K13: =TEXT('_Data'!$AF$19,"0.0%") -> 0.0%
B15: 📅 THE PIPELINE
B16: ="💬 Inquiry: "&COUNTIF('📅 Events'!$Q$8:$Q$47,"💬 Inquiry") -> 💬 Inquiry: 0 | D16: ="📝 Quote Sent: "&COUNTIF('📅 Events'!$Q$8:$Q$47,"📝 Quote Sent") -> 📝 Quote Sent: 0 | F16: ="💰 Deposit Paid: "&COUNTIF('📅 Events'!$Q$8:$Q$47,"💰 Deposit Paid") -> 💰 Deposit Paid: 0 | H16: ="✅ Confirmed: "&COUNTIF('📅 Events'!$Q$8:$Q$47,"✅ Confirmed") -> ✅ Confirmed: 0 | J16: ="🎉 Completed: "&COUNTIF('📅 Events'!$Q$8:$Q$47,"🎉 Completed") -> 🎉 Completed: 0 | L16: ="❌ Cancelled: "&COUNTIF('📅 Events'!$Q$8:$Q$47,"❌ Cancelled") -> ❌ Cancelled: 0
B50: 📅 NEXT EVENTS | G50: 💵 MONEY COMING IN
B51: =IF('_Data'!$AA$2="","—",TEXT('_Data'!$AA$2,"ddd dd mmm")) -> — | C51: =IF('_Data'!$AB$2="","(nothing booked yet)",'_Data'!$AB$2) -> (nothing booked yet) | E51: =IF('_Data'!$AC$2="","",'_Data'!$AC$2) | G51: =IF('_Data'!$AA$42="","—",TEXT('_Data'!$AA$42,"dd mmm")) -> — | H51: =IF('_Data'!$AB$42="","(all square — nothing owed)",'_Data'!$AB$42) -> (all square — nothing owed) | K51: =IF('_Data'!$AA$42="","",'_Data'!$AC$42)
B52: =IF('_Data'!$AA$3="","—",TEXT('_Data'!$AA$3,"ddd dd mmm")) -> — | C52: =IF('_Data'!$AB$3="","(nothing booked yet)",'_Data'!$AB$3) -> (nothing booked yet) | E52: =IF('_Data'!$AC$3="","",'_Data'!$AC$3) | G52: =IF('_Data'!$AA$43="","—",TEXT('_Data'!$AA$43,"dd mmm")) -> — | H52: =IF('_Data'!$AB$43="","(all square — nothing owed)",'_Data'!$AB$43) -> (all square — nothing owed) | K52: =IF('_Data'!$AA$43="","",'_Data'!$AC$43)
B53: =IF('_Data'!$AA$4="","—",TEXT('_Data'!$AA$4,"ddd dd mmm")) -> — | C53: =IF('_Data'!$AB$4="","(nothing booked yet)",'_Data'!$AB$4) -> (nothing booked yet) | E53: =IF('_Data'!$AC$4="","",'_Data'!$AC$4) | G53: =IF('_Data'!$AA$44="","—",TEXT('_Data'!$AA$44,"dd mmm")) -> — | H53: =IF('_Data'!$AB$44="","(all square — nothing owed)",'_Data'!$AB$44) -> (all square — nothing owed) | K53: =IF('_Data'!$AA$44="","",'_Data'!$AC$44)
B54: =IF('_Data'!$AA$5="","—",TEXT('_Data'!$AA$5,"ddd dd mmm")) -> — | C54: =IF('_Data'!$AB$5="","(nothing booked yet)",'_Data'!$AB$5) -> (nothing booked yet) | E54: =IF('_Data'!$AC$5="","",'_Data'!$AC$5) | G54: =IF('_Data'!$AA$45="","—",TEXT('_Data'!$AA$45,"dd mmm")) -> — | H54: =IF('_Data'!$AB$45="","(all square — nothing owed)",'_Data'!$AB$45) -> (all square — nothing owed) | K54: =IF('_Data'!$AA$45="","",'_Data'!$AC$45)
B55: =IF('_Data'!$AA$6="","—",TEXT('_Data'!$AA$6,"ddd dd mmm")) -> — | C55: =IF('_Data'!$AB$6="","(nothing booked yet)",'_Data'!$AB$6) -> (nothing booked yet) | E55: =IF('_Data'!$AC$6="","",'_Data'!$AC$6) | G55: =IF('_Data'!$AA$46="","—",TEXT('_Data'!$AA$46,"dd mmm")) -> — | H55: =IF('_Data'!$AB$46="","(all square — nothing owed)",'_Data'!$AB$46) -> (all square — nothing owed) | K55: =IF('_Data'!$AA$46="","",'_Data'!$AC$46)
B56: =IF('_Data'!$AA$7="","—",TEXT('_Data'!$AA$7,"ddd dd mmm")) -> — | C56: =IF('_Data'!$AB$7="","(nothing booked yet)",'_Data'!$AB$7) -> (nothing booked yet) | E56: =IF('_Data'!$AC$7="","",'_Data'!$AC$7) | G56: =IF('_Data'!$AA$47="","—",TEXT('_Data'!$AA$47,"dd mmm")) -> — | H56: =IF('_Data'!$AB$47="","(all square — nothing owed)",'_Data'!$AB$47) -> (all square — nothing owed) | K56: =IF('_Data'!$AA$47="","",'_Data'!$AC$47)
B59: 💡 Everything on this page is calculated — type your business into the tabs and watch it update. Start with the 📖 Start Here guide, set up ⚙️ Setup, then log 📅 Events and 💰 Payments.
B61: Setup | D61: ▶ 🏠 Home | F61: Clients | H61: Events | J61: Quote | L61: Menu
B62: Stock | D62: Shop | F62: Expenses | H62: Payments | J62: Staff | L62: Equip
B63: Suppliers | D63: Calendar | F63: P&L | H63: Tax | J63: Checks | L63: Invoice
B64: Help

Sheet 👥 Clients
B2: 👥 Client Tracker
B3: One row per client: contacts, their next (or latest) event and the money picture. Repeat clients are gold for your business — the dashboard counts them. | M3: 🏠 Back to Dashboard
B5: ="👥 Clients: "&COUNTIF('👥 Clients'!$C$8:$C$47,"?*") -> Clients: 0 | E5: ="🔁 Repeat customers: "&TEXT('_Data'!$AF$21,"0%") -> Repeat customers: 0% | H5: ="💰 Total quoted: "&Currency&TEXT(SUM('👥 Clients'!$K$8:$K$47),"#,##0") -> Total quoted: $0 | K5: ="💵 Deposits held: "&Currency&TEXT(SUM('👥 Clients'!$L$8:$L$47),"#,##0") -> Deposits held: $0
B7: # | C7: Client name | D7: Phone | E7: Email | F7: Next / last event | G7: Event type | H7: Guests | I7: Venue | J7: Package | K7: Quote value | L7: Deposit held | M7: Balance | N7: Payment status | O7: Notes
B8: 1 | M8: =IF($K8="","",$K8-$L8)
B9: 2 | M9: =IF($K9="","",$K9-$L9)
B10: 3 | M10: =IF($K10="","",$K10-$L10)
B11: 4 | M11: =IF($K11="","",$K11-$L11)
B12: 5 | M12: =IF($K12="","",$K12-$L12)
B13: 6 | M13: =IF($K13="","",$K13-$L13)
B14: 7 | M14: =IF($K14="","",$K14-$L14)
B15: 8 | M15: =IF($K15="","",$K15-$L15)
B16: 9 | M16: =IF($K16="","",$K16-$L16)
B17: 10 | M17: =IF($K17="","",$K17-$L17)
B18: 11 | M18: =IF($K18="","",$K18-$L18)
B19: 12 | M19: =IF($K19="","",$K19-$L19)
... B47: 40 | M47: =IF($K47="","",$K47-$L47)
B49: TOTALS → | H49: =SUM($H$8:$H$47) -> 0 | K49: =SUM($K$8:$K$47) -> 0 | L49: =SUM($L$8:$L$47) -> 0 | M49: =SUM($M$8:$M$47) -> 0
B51: 💡 How to use this tab
B52: Names typed here feed the Client dropdown on the Events, Payments and Invoice tabs. A golden name means the client appears on more than one event - repeat business! Quote / Deposit are inputs; Balance calculates itself. For the full payment schedule use the 💰 Payments tab.
B57: Setup | D57: 🏠 Home | F57: ▶ Clients | H57: Events | J57: Quote | L57: Menu | N57: Stock
B58: Shop | D58: Expenses | F58: Payments | H58: Staff | J58: Equip | L58: Suppliers | N58: Calendar
B59: P&L | D59: Tax | F59: Checks | H59: Invoice | J59: Help

Sheet 📅 Events
B2: 📅 Event & Order Tracker
B3: The pipeline: 💬 Inquiry → 📝 Quote Sent → 💰 Deposit Paid → ✅ Confirmed → 🎉 Completed. White cells are yours; tinted cells calculate. | P3: 🏠 Back to Dashboard
B5: ="📅 Events: "&'_Data'!$AF$6 -> Events: 0 | E5: ="✅ Confirmed + deposit: "&'_Data'!$AF$8 -> Confirmed + deposit: 0 | H5: ="🎉 Completed: "&'_Data'!$AF$7&" ❌ Cancelled: "&'_Data'!$AF$9 -> Completed: 0 Cancelled: 0 | K5: ="💰 Booked value: "&Currency&TEXT(SUMIF('📅 Events'!$Q$8:$Q$47,"<>❌ Cancelled",'📅 Events'!$L$8:$L$47),"#,##0") -> Booked value: $0 | N5: ="📈 Projected profit: "&Currency&TEXT(SUMIF('📅 Events'!$Q$8:$Q$47,"<>❌ Cancelled",'📅 Events'!$M$8:$M$47),"#,##0") -> Projected profit: $0
B7: # | C7: Event ID | D7: Client | E7: Event date | F7: Type | G7: Guests | H7: Menu / package | I7: Staff req. | J7: Equipment req. | K7: Total cost | L7: Price quoted | M7: Profit | N7: Margin | O7: Deposit held | P7: Balance | Q7: Pipeline status | R7: Notes
B8: 1 | M8: =IF(OR($K8="",$L8=""),"",$L8-$K8) | N8: =IF(OR($L8="",$L8=0),"",$M8/$L8) | P8: =IF($L8="","",$L8-$O8)
B9: 2 | M9: =IF(OR($K9="",$L9=""),"",$L9-$K9) | N9: =IF(OR($L9="",$L9=0),"",$M9/$L9) | P9: =IF($L9="","",$L9-$O9)
B10: 3 | M10: =IF(OR($K10="",$L10=""),"",$L10-$K10) | N10: =IF(OR($L10="",$L10=0),"",$M10/$L10) | P10: =IF($L10="","",$L10-$O10)
B11: 4 | M11: =IF(OR($K11="",$L11=""),"",$L11-$K11) | N11: =IF(OR($L11="",$L11=0),"",$M11/$L11) | P11: =IF($L11="","",$L11-$O11)
B12: 5 | M12: =IF(OR($K12="",$L12=""),"",$L12-$K12) | N12: =IF(OR($L12="",$L12=0),"",$M12/$L12) | P12: =IF($L12="","",$L12-$O12)
B13: 6 | M13: =IF(OR($K13="",$L13=""),"",$L13-$K13) | N13: =IF(OR($L13="",$L13=0),"",$M13/$L13) | P13: =IF($L13="","",$L13-$O13)
B14: 7 | M14: =IF(OR($K14="",$L14=""),"",$L14-$K14) | N14: =IF(OR($L14="",$L14=0),"",$M14/$L14) | P14: =IF($L14="","",$L14-$O14)
B15: 8 | M15: =IF(OR($K15="",$L15=""),"",$L15-$K15) | N15: =IF(OR($L15="",$L15=0),"",$M15/$L15) | P15: =IF($L15="","",$L15-$O15)
B16: 9 | M16: =IF(OR($K16="",$L16=""),"",$L16-$K16) | N16: =IF(OR($L16="",$L16=0),"",$M16/$L16) | P16: =IF($L16="","",$L16-$O16)
B17: 10 | M17: =IF(OR($K17="",$L17=""),"",$L17-$K17) | N17: =IF(OR($L17="",$L17=0),"",$M17/$L17) | P17: =IF($L17="","",$L17-$O17)
B18: 11 | M18: =IF(OR($K18="",$L18=""),"",$L18-$K18) | N18: =IF(OR($L18="",$L18=0),"",$M18/$L18) | P18: =IF($L18="","",$L18-$O18)
B19: 12 | M19: =IF(OR($K19="",$L19=""),"",$L19-$K19) | N19: =IF(OR($L19="",$L19=0),"",$M19/$L19) | P19: =IF($L19="","",$L19-$O19)
... B47: 40 | M47: =IF(OR($K47="",$L47=""),"",$L47-$K47) | N47: =IF(OR($L47="",$L47=0),"",$M47/$L47) | P47: =IF($L47="","",$L47-$O47)
B49: TOTALS (all events incl. cancelled) → | G49: =SUM($G$8:$G$47) -> 0 | K49: =SUM($K$8:$K$47) -> 0 | L49: =SUM($L$8:$L$47) -> 0 | M49: =SUM($M$8:$M$47) -> 0 | O49: =SUM($O$8:$O$47) -> 0
B51: 💡 How to use this tab
B52: Fill the white cells - the tinted Profit / Margin / Balance columns do the maths. Need a price? Build it on the 🧮 Quote Calculator first, then copy the recommended price into 'Price quoted'. Cancelled events stay in the list (greyed + struck through) so your history is complete - they are excluded from every total and average.
B57: Setup | D57: 🏠 Home | F57: Clients | H57: ▶ Events | J57: Quote | L57: Menu | N57: Stock | P57: Shop
B58: Expenses | D58: Payments | F58: Staff | H58: Equip | J58: Suppliers | L58: Calendar | N58: P&L | P58: Tax
B59: Checks | D59: Invoice | F59: Help

Sheet 🧮 Quote Calculator
B2: 🧮 Quote & Pricing Calculator
B3: Never guess a price again: costs in → recommended quote out, at the margin YOU decide. | H3: 🏠 Back to Dashboard
B9: 1 · THE EVENT
B10: Client / enquiry
B11: Event date
B12: Guest count
B13: 2 · YOUR COSTS
B14: Food cost per guest | G14: Food cost (guests x per guest) | J14: =IF(OR($E$12="",$E$14=""),"",$E$12*$E$14)
B15: Labor total | G15: TOTAL COST | J15: =IF($J$14="","",SUM($E$15:$E$18)+$J$14)
B16: Equipment / rental | G16: RECOMMENDED PRICE | J16: =IF(OR($J$15="",$E$12="",1-$E$20<=0),"",ROUND($J$15/(1-$E$20),2))
B17: Transport | G17: Price per guest | J17: =IF(OR($J$16="",$E$12=""),"",$J$16/$E$12)
B18: Other costs | G18: Your profit | J18: =IF($J$16="","",$J$16-$J$15)
B19: 3 · PRICING POLICY | G19: Effective margin | J19: =IF($J$16="","",$J$18/$J$16)
B20: Target margin % | E20: =DefaultMargin -> 0.35 | G20: Deposit to collect | J20: =IF($J$16="","",ROUND($J$16*$E$21,2))
B21: Deposit % | E21: =DepositPct -> 0.4 | G21: Balance due later | J21: =IF($J$16="","",$J$16-$J$20)
G22: True cost per guest | J22: =IF(OR($J$15="",$E$12=""),"",$J$15/$E$12)
B25: HOW TO PRICE LIKE A PRO 1. Food cost per guest = what one plate costs you (use the Recipe Calculator on 🍽️ Menu Costing). 2. Labor / equipment / transport / other = the event's share of everything else. 3. Recommended price covers ALL of it and still pays you your target margin. Rule of thumb: food should stay under ~30% of the final price.
B29: Setup | D29: 🏠 Home | F29: Clients | H29: Events
B30: ▶ Quote | D30: Menu | F30: Stock | H30: Shop
B31: Expenses | D31: Payments | F31: Staff | H31: Equip
B32: Suppliers | D32: Calendar | F32: P&L | H32: Tax
B33: Checks | D33: Invoice | F33: Help

Sheet 🍽️ Menu Costing
B2: 🍽️ Menu & Recipe Costing
B3: Know the true cost of every dish. Margins under 30% light up red — reprice them or retire them. | I3: 🏠 Back to Dashboard
B5: ="🍽️ Items priced: "&'_Data'!$AF$33 -> Items priced: 0 | E5: ="📈 Average margin: "&TEXT('_Data'!$AF$34,"0%") -> Average margin: 0% | H5: ="⚠️ Under 30% margin: "&TEXT(COUNTIF('🍽️ Menu Costing'!$J$8:$J$37,">0")-COUNTIF('🍽️ Menu Costing'!$J$8:$J$37,">=0.3"),"0") -> Under 30% margin: 0
B7: # | C7: Menu item | D7: Category | E7: Main ingredients | F7: Portion | G7: Cost / portion | H7: Price / portion | I7: Profit | J7: Margin | K7: Notes
B8: 1 | I8: =IF(OR($C8="",$H8=""),"",$H8-$G8) | J8: =IF(OR($C8="",$H8="",$H8=0),"",$I8/$H8)
B9: 2 | I9: =IF(OR($C9="",$H9=""),"",$H9-$G9) | J9: =IF(OR($C9="",$H9="",$H9=0),"",$I9/$H9)
B10: 3 | I10: =IF(OR($C10="",$H10=""),"",$H10-$G10) | J10: =IF(OR($C10="",$H10="",$H10=0),"",$I10/$H10)
B11: 4 | I11: =IF(OR($C11="",$H11=""),"",$H11-$G11) | J11: =IF(OR($C11="",$H11="",$H11=0),"",$I11/$H11)
B12: 5 | I12: =IF(OR($C12="",$H12=""),"",$H12-$G12) | J12: =IF(OR($C12="",$H12="",$H12=0),"",$I12/$H12)
B13: 6 | I13: =IF(OR($C13="",$H13=""),"",$H13-$G13) | J13: =IF(OR($C13="",$H13="",$H13=0),"",$I13/$H13)
B14: 7 | I14: =IF(OR($C14="",$H14=""),"",$H14-$G14) | J14: =IF(OR($C14="",$H14="",$H14=0),"",$I14/$H14)
B15: 8 | I15: =IF(OR($C15="",$H15=""),"",$H15-$G15) | J15: =IF(OR($C15="",$H15="",$H15=0),"",$I15/$H15)
B16: 9 | I16: =IF(OR($C16="",$H16=""),"",$H16-$G16) | J16: =IF(OR($C16="",$H16="",$H16=0),"",$I16/$H16)
B17: 10 | I17: =IF(OR($C17="",$H17=""),"",$H17-$G17) | J17: =IF(OR($C17="",$H17="",$H17=0),"",$I17/$H17)
B18: 11 | I18: =IF(OR($C18="",$H18=""),"",$H18-$G18) | J18: =IF(OR($C18="",$H18="",$H18=0),"",$I18/$H18)
B19: 12 | I19: =IF(OR($C19="",$H19=""),"",$H19-$G19) | J19: =IF(OR($C19="",$H19="",$H19=0),"",$I19/$H19)
... B37: 30 | I37: =IF(OR($C37="",$H37=""),"",$H37-$G37) | J37: =IF(OR($C37="",$H37="",$H37=0),"",$I37/$H37)
B39: AVERAGES → | G39: =IFERROR(AVERAGE($G$8:$G$37),0) -> 0 | H39: =IFERROR(AVERAGE($H$8:$H$37),0) -> 0 | J39: =IFERROR(AVERAGE($J$8:$J$37),0) -> 0
B48: 🧮 RECIPE COST CALCULATOR — price a new dish before it goes on the menu
B49: Dish being costed | H49: Unit prices below are looked up from 📦 Inventory - add the ingredient there first.
B50: # | C50: Ingredient | E50: Qty per portion | G50: Unit | I50: Unit cost (auto) | K50: Line cost
B51: 1 | I51: =IF($C51="","",IFERROR(SUMIF('📦 Inventory'!$C$8:$C$47,$C51,'📦 Inventory'!$H$8:$H$47),0)) | K51: =IF(OR($C51="",$E51=""),"",$E51*$I51)
B52: 2 | I52: =IF($C52="","",IFERROR(SUMIF('📦 Inventory'!$C$8:$C$47,$C52,'📦 Inventory'!$H$8:$H$47),0)) | K52: =IF(OR($C52="",$E52=""),"",$E52*$I52)
B53: 3 | I53: =IF($C53="","",IFERROR(SUMIF('📦 Inventory'!$C$8:$C$47,$C53,'📦 Inventory'!$H$8:$H$47),0)) | K53: =IF(OR($C53="",$E53=""),"",$E53*$I53)
B54: 4 | I54: =IF($C54="","",IFERROR(SUMIF('📦 Inventory'!$C$8:$C$47,$C54,'📦 Inventory'!$H$8:$H$47),0)) | K54: =IF(OR($C54="",$E54=""),"",$E54*$I54)
B55: 5 | I55: =IF($C55="","",IFERROR(SUMIF('📦 Inventory'!$C$8:$C$47,$C55,'📦 Inventory'!$H$8:$H$47),0)) | K55: =IF(OR($C55="",$E55=""),"",$E55*$I55)
B56: 6 | I56: =IF($C56="","",IFERROR(SUMIF('📦 Inventory'!$C$8:$C$47,$C56,'📦 Inventory'!$H$8:$H$47),0)) | K56: =IF(OR($C56="",$E56=""),"",$E56*$I56)
B57: Cost per portion | D57: =SUM($K$51:$K$56) -> 0 | F57: Add the finished dish to the menu table above when you're happy with the numbers.
B58: Suggested price at your default margin | D58: =IFERROR($D$57/(1-DefaultMargin),"") -> 0 | F58: DefaultMargin comes from ⚙️ Setup - change it once, every suggested price follows.
B59: Profit per portion at that price | D59: =IFERROR($D$58-$D$57,"") -> 0 | F59: Ingredient names must match the 📦 Inventory spelling for the unit-cost lookup to work.
B61: Setup | D61: 🏠 Home | F61: Clients | H61: Events | J61: Quote
B62: ▶ Menu | D62: Stock | F62: Shop | H62: Expenses | J62: Payments
B63: Staff | D63: Equip | F63: Suppliers | H63: Calendar | J63: P&L
B64: Tax | D64: Checks | F64: Invoice | H64: Help

Sheet 📦 Inventory
B2: 📦 Ingredient Inventory
B3: What's on the shelf right now. Stock below its minimum lights up 🔴 red - the shopping list and recipe calculator read these prices. | J3: 🏠 Back to Dashboard
B5: ="📦 Ingredients: "&COUNTIF('📦 Inventory'!$C$8:$C$47,"?*") -> Ingredients: 0 | D5: ="💰 Stock value: "&Currency&TEXT('_Data'!$AF$22,"#,##0.00") -> Stock value: $0.00 | F5: ="🔴 Reorder now: "&COUNTIF('📦 Inventory'!$K$8:$K$47,"🔴 Reorder") -> Reorder now: 0 | H5: ="🟡 Running low: "&COUNTIF('📦 Inventory'!$K$8:$K$47,"🟡 Low") -> Running low: 0 | J5: ="🟢 Well stocked: "&COUNTIF('📦 Inventory'!$K$8:$K$47,"🟢 OK") -> Well stocked: 0
B7: # | C7: Ingredient | D7: Category | E7: Unit | F7: Qty on hand | G7: Minimum level | H7: Unit cost | I7: Stock value | J7: Supplier | K7: Reorder status | L7: Notes
B8: 1 | I8: =IF(OR($C8="",$F8=""),"",$F8*$H8) | K8: =IF($C8="","",IF($F8<$G8,"🔴 Reorder",IF($F8<$G8*1.5,"🟡 Low","🟢 OK")))
B9: 2 | I9: =IF(OR($C9="",$F9=""),"",$F9*$H9) | K9: =IF($C9="","",IF($F9<$G9,"🔴 Reorder",IF($F9<$G9*1.5,"🟡 Low","🟢 OK")))
B10: 3 | I10: =IF(OR($C10="",$F10=""),"",$F10*$H10) | K10: =IF($C10="","",IF($F10<$G10,"🔴 Reorder",IF($F10<$G10*1.5,"🟡 Low","🟢 OK")))
B11: 4 | I11: =IF(OR($C11="",$F11=""),"",$F11*$H11) | K11: =IF($C11="","",IF($F11<$G11,"🔴 Reorder",IF($F11<$G11*1.5,"🟡 Low","🟢 OK")))
B12: 5 | I12: =IF(OR($C12="",$F12=""),"",$F12*$H12) | K12: =IF($C12="","",IF($F12<$G12,"🔴 Reorder",IF($F12<$G12*1.5,"🟡 Low","🟢 OK")))
B13: 6 | I13: =IF(OR($C13="",$F13=""),"",$F13*$H13) | K13: =IF($C13="","",IF($F13<$G13,"🔴 Reorder",IF($F13<$G13*1.5,"🟡 Low","🟢 OK")))
B14: 7 | I14: =IF(OR($C14="",$F14=""),"",$F14*$H14) | K14: =IF($C14="","",IF($F14<$G14,"🔴 Reorder",IF($F14<$G14*1.5,"🟡 Low","🟢 OK")))
B15: 8 | I15: =IF(OR($C15="",$F15=""),"",$F15*$H15) | K15: =IF($C15="","",IF($F15<$G15,"🔴 Reorder",IF($F15<$G15*1.5,"🟡 Low","🟢 OK")))
B16: 9 | I16: =IF(OR($C16="",$F16=""),"",$F16*$H16) | K16: =IF($C16="","",IF($F16<$G16,"🔴 Reorder",IF($F16<$G16*1.5,"🟡 Low","🟢 OK")))
B17: 10 | I17: =IF(OR($C17="",$F17=""),"",$F17*$H17) | K17: =IF($C17="","",IF($F17<$G17,"🔴 Reorder",IF($F17<$G17*1.5,"🟡 Low","🟢 OK")))
B18: 11 | I18: =IF(OR($C18="",$F18=""),"",$F18*$H18) | K18: =IF($C18="","",IF($F18<$G18,"🔴 Reorder",IF($F18<$G18*1.5,"🟡 Low","🟢 OK")))
B19: 12 | I19: =IF(OR($C19="",$F19=""),"",$F19*$H19) | K19: =IF($C19="","",IF($F19<$G19,"🔴 Reorder",IF($F19<$G19*1.5,"🟡 Low","🟢 OK")))
... B47: 40 | I47: =IF(OR($C47="",$F47=""),"",$F47*$H47) | K47: =IF($C47="","",IF($F47<$G47,"🔴 Reorder",IF($F47<$G47*1.5,"🟡 Low","🟢 OK")))
B49: TOTAL STOCK VALUE → | I49: =SUM($I$8:$I$47) -> 0
B51: 💡 How to use this tab
B52: 🔴 Reorder = below minimum. 🟡 Low = below 1.5x the minimum. 🟢 OK = comfortable. Unit costs typed here power the 🍽️ Recipe Calculator and the 🛒 Shopping List estimates. Do a quick shelf count before every big event - ten minutes now saves an emergency run later.
B57: Setup | D57: 🏠 Home | F57: Clients | H57: Events | J57: Quote
B58: Menu | D58: ▶ Stock | F58: Shop | H58: Expenses | J58: Payments
B59: Staff | D59: Equip | F59: Suppliers | H59: Calendar | J59: P&L
B60: Tax | D60: Checks | F60: Invoice | H60: Help

Sheet 🛒 Shopping List
B2: 🛒 Shopping List
B3: What each event needs vs what the shelf holds — To buy and Est. cost fill themselves in from the 📦 Inventory. | J3: 🏠 Back to Dashboard
B5: ="🛒 Lines: "&COUNTIF('🛒 Shopping List'!$D$8:$D$47,"?*") -> Lines: 0 | D5: ="💰 Still to buy: "&'_Data'!$AF$24&" line(s)" -> Still to buy: 0 line(s) | F5: ="💵 Estimated cost to buy: "&Currency&TEXT('_Data'!$AF$25,"#,##0.00") -> Estimated cost to buy: $0.00 | H5: ="✅ Purchased: "&COUNTIF('🛒 Shopping List'!$J$8:$J$47,"✓")&" line(s)" -> Purchased: 0 line(s) | J5: ="🧾 Spent on this list: "&Currency&TEXT(SUMIF('🛒 Shopping List'!$J$8:$J$47,"✓",'🛒 Shopping List'!$I$8:$I$47),"#,##0.00") -> Spent on this list: $0.00
B7: # | C7: Event ID | D7: Ingredient | E7: Qty needed | F7: In stock | G7: To buy | H7: Supplier | I7: Est. cost | J7: 🛒 Got it | K7: Bought on | L7: Notes
B8: 1 | F8: =IF($D8="",0,SUMIF('📦 Inventory'!$C$8:$C$47,$D8,'📦 Inventory'!$F$8:$F$47)) -> 0 | G8: =IF($D8="","",MAX(0,$E8-$F8)) | I8: =IF($G8="","",ROUND($G8*SUMIF('📦 Inventory'!$C$8:$C$47,$D8,'📦 Inventory'!$H$8:$H$47),2))
B9: 2 | F9: =IF($D9="",0,SUMIF('📦 Inventory'!$C$8:$C$47,$D9,'📦 Inventory'!$F$8:$F$47)) -> 0 | G9: =IF($D9="","",MAX(0,$E9-$F9)) | I9: =IF($G9="","",ROUND($G9*SUMIF('📦 Inventory'!$C$8:$C$47,$D9,'📦 Inventory'!$H$8:$H$47),2))
B10: 3 | F10: =IF($D10="",0,SUMIF('📦 Inventory'!$C$8:$C$47,$D10,'📦 Inventory'!$F$8:$F$47)) -> 0 | G10: =IF($D10="","",MAX(0,$E10-$F10)) | I10: =IF($G10="","",ROUND($G10*SUMIF('📦 Inventory'!$C$8:$C$47,$D10,'📦 Inventory'!$H$8:$H$47),2))
B11: 4 | F11: =IF($D11="",0,SUMIF('📦 Inventory'!$C$8:$C$47,$D11,'📦 Inventory'!$F$8:$F$47)) -> 0 | G11: =IF($D11="","",MAX(0,$E11-$F11)) | I11: =IF($G11="","",ROUND($G11*SUMIF('📦 Inventory'!$C$8:$C$47,$D11,'📦 Inventory'!$H$8:$H$47),2))
B12: 5 | F12: =IF($D12="",0,SUMIF('📦 Inventory'!$C$8:$C$47,$D12,'📦 Inventory'!$F$8:$F$47)) -> 0 | G12: =IF($D12="","",MAX(0,$E12-$F12)) | I12: =IF($G12="","",ROUND($G12*SUMIF('📦 Inventory'!$C$8:$C$47,$D12,'📦 Inventory'!$H$8:$H$47),2))
B13: 6 | F13: =IF($D13="",0,SUMIF('📦 Inventory'!$C$8:$C$47,$D13,'📦 Inventory'!$F$8:$F$47)) -> 0 | G13: =IF($D13="","",MAX(0,$E13-$F13)) | I13: =IF($G13="","",ROUND($G13*SUMIF('📦 Inventory'!$C$8:$C$47,$D13,'📦 Inventory'!$H$8:$H$47),2))
B14: 7 | F14: =IF($D14="",0,SUMIF('📦 Inventory'!$C$8:$C$47,$D14,'📦 Inventory'!$F$8:$F$47)) -> 0 | G14: =IF($D14="","",MAX(0,$E14-$F14)) | I14: =IF($G14="","",ROUND($G14*SUMIF('📦 Inventory'!$C$8:$C$47,$D14,'📦 Inventory'!$H$8:$H$47),2))
B15: 8 | F15: =IF($D15="",0,SUMIF('📦 Inventory'!$C$8:$C$47,$D15,'📦 Inventory'!$F$8:$F$47)) -> 0 | G15: =IF($D15="","",MAX(0,$E15-$F15)) | I15: =IF($G15="","",ROUND($G15*SUMIF('📦 Inventory'!$C$8:$C$47,$D15,'📦 Inventory'!$H$8:$H$47),2))
B16: 9 | F16: =IF($D16="",0,SUMIF('📦 Inventory'!$C$8:$C$47,$D16,'📦 Inventory'!$F$8:$F$47)) -> 0 | G16: =IF($D16="","",MAX(0,$E16-$F16)) | I16: =IF($G16="","",ROUND($G16*SUMIF('📦 Inventory'!$C$8:$C$47,$D16,'📦 Inventory'!$H$8:$H$47),2))
B17: 10 | F17: =IF($D17="",0,SUMIF('📦 Inventory'!$C$8:$C$47,$D17,'📦 Inventory'!$F$8:$F$47)) -> 0 | G17: =IF($D17="","",MAX(0,$E17-$F17)) | I17: =IF($G17="","",ROUND($G17*SUMIF('📦 Inventory'!$C$8:$C$47,$D17,'📦 Inventory'!$H$8:$H$47),2))
B18: 11 | F18: =IF($D18="",0,SUMIF('📦 Inventory'!$C$8:$C$47,$D18,'📦 Inventory'!$F$8:$F$47)) -> 0 | G18: =IF($D18="","",MAX(0,$E18-$F18)) | I18: =IF($G18="","",ROUND($G18*SUMIF('📦 Inventory'!$C$8:$C$47,$D18,'📦 Inventory'!$H$8:$H$47),2))
B19: 12 | F19: =IF($D19="",0,SUMIF('📦 Inventory'!$C$8:$C$47,$D19,'📦 Inventory'!$F$8:$F$47)) -> 0 | G19: =IF($D19="","",MAX(0,$E19-$F19)) | I19: =IF($G19="","",ROUND($G19*SUMIF('📦 Inventory'!$C$8:$C$47,$D19,'📦 Inventory'!$H$8:$H$47),2))
... B47: 40 | F47: =IF($D47="",0,SUMIF('📦 Inventory'!$C$8:$C$47,$D47,'📦 Inventory'!$F$8:$F$47)) -> 0 | G47: =IF($D47="","",MAX(0,$E47-$F47)) | I47: =IF($G47="","",ROUND($G47*SUMIF('📦 Inventory'!$C$8:$C$47,$D47,'📦 Inventory'!$H$8:$H$47),2))
B49: TOTALS → | E49: =SUM($E$8:$E$47) -> 0 | G49: =SUM($G$8:$G$47) -> 0 | I49: =SUM($I$8:$I$47) -> 0
B51: 💡 How to use this tab
B52: Add one line per ingredient per event - In stock, To buy and Est. cost fill themselves in. Red 'To buy' = still needs purchasing. Green = the shelf already covers it. Struck-through = bought and done. When you buy, log the real spend on 💸 Expenses (category Ingredients) so the P&L stays true.
B57: Setup | D57: 🏠 Home | F57: Clients | H57: Events | J57: Quote
B58: Menu | D58: Stock | F58: ▶ Shop | H58: Expenses | J58: Payments
B59: Staff | D59: Equip | F59: Suppliers | H59: Calendar | J59: P&L
B60: Tax | D60: Checks | F60: Invoice | H60: Help

Sheet 💸 Expenses
B2: 💸 Expense Tracker
B3: Log every business cost as it happens — the P&L, tax summary and dashboard pie all read this table. | H3: 🏠 Back to Dashboard
B5: ="💸 Total expenses: "&Currency&TEXT('_Data'!$AF$3,"#,##0") -> Total expenses: $0 | D5: ="📅 This month: "&Currency&TEXT(SUMIFS('💸 Expenses'!$G$8:$G$67,'💸 Expenses'!$C$8:$C$67,">="&DATE(YEAR(TODAY()),MONTH(TODAY()),1),'💸 Expenses'!$C$8:$C$67,"<"&EDATE(DATE(YEAR(TODAY()),MONTH(TODAY()),1),1)),"#,##0") -> This month: $0 | F5: ="🍳 Food + packaging: "&Currency&TEXT('_Data'!$AF$17,"#,##0") -> Food + packaging: $0 | H5: ="👷 Staff / labor: "&Currency&TEXT('_Data'!$AF$18,"#,##0") -> Staff / labor: $0
B7: # | C7: Date | D7: Vendor / payee | E7: Category | F7: Description | G7: Amount | H7: Paid by | I7: Event ID | J7: 🧾 Receipt filed
B8: 1
B9: 2
B10: 3
B11: 4
B12: 5
B13: 6
B14: 7
B15: 8
B16: 9
B17: 10
B18: 11
B19: 12
... B67: 60
B69: TOTAL SPENT → | G69: =SUM($G$8:$G$67) -> 0
B71: 💡 How to use this tab
B72: Log the expense the day it happens - future-you doing tax season will say thanks. The Event ID column is optional, but tagging event purchases makes each event's true cost visible. Red tick column = money spent with no receipt filed yet.
B77: Setup | D77: 🏠 Home | F77: Clients | H77: Events
B78: Quote | D78: Menu | F78: Stock | H78: Shop
B79: ▶ Expenses | D79: Payments | F79: Staff | H79: Equip
B80: Suppliers | D80: Calendar | F80: P&L | H80: Tax
B81: Checks | D81: Invoice | F81: Help

Sheet 💰 Payments
B2: 💰 Income & Payments
B3: One row per invoice. Log deposits and payments as they arrive — Received, Balance and Status calculate themselves, and overdue money turns red. | K3: 🏠 Back to Dashboard
B5: ="💰 Cash received: "&Currency&TEXT('_Data'!$AF$2,"#,##0") -> Cash received: $0 | D5: ="🧾 Invoiced: "&Currency&TEXT(SUM('💰 Payments'!$F$8:$F$67),"#,##0") -> Invoiced: $0 | F5: ="⏳ Outstanding: "&Currency&TEXT(SUM('💰 Payments'!$K$8:$K$67),"#,##0") -> Outstanding: $0 | H5: ="🔴 Overdue: "&'_Data'!$AF$15&" invoice(s)" -> Overdue: 0 invoice(s) | J5: ="📂 Open invoices: "&'_Data'!$AF$16 -> Open invoices: 0
B7: # | C7: Invoice # | D7: Client | E7: Event date | F7: Invoice total | G7: Deposit | H7: Payment 1 | I7: Payment 2 | J7: Received | K7: Balance due | L7: Due date | M7: Status
B8: 1 | J8: =IF($F8="","",SUM($G8:$I8)) | K8: =IF($F8="","",$F8-$J8) | M8: =IF($F8="","",IF($J8>=$F8,"🟢 Paid in full",IF($J8>0,"🟠 Partial","🔴 Unpaid")))
B9: 2 | J9: =IF($F9="","",SUM($G9:$I9)) | K9: =IF($F9="","",$F9-$J9) | M9: =IF($F9="","",IF($J9>=$F9,"🟢 Paid in full",IF($J9>0,"🟠 Partial","🔴 Unpaid")))
B10: 3 | J10: =IF($F10="","",SUM($G10:$I10)) | K10: =IF($F10="","",$F10-$J10) | M10: =IF($F10="","",IF($J10>=$F10,"🟢 Paid in full",IF($J10>0,"🟠 Partial","🔴 Unpaid")))
B11: 4 | J11: =IF($F11="","",SUM($G11:$I11)) | K11: =IF($F11="","",$F11-$J11) | M11: =IF($F11="","",IF($J11>=$F11,"🟢 Paid in full",IF($J11>0,"🟠 Partial","🔴 Unpaid")))
B12: 5 | J12: =IF($F12="","",SUM($G12:$I12)) | K12: =IF($F12="","",$F12-$J12) | M12: =IF($F12="","",IF($J12>=$F12,"🟢 Paid in full",IF($J12>0,"🟠 Partial","🔴 Unpaid")))
B13: 6 | J13: =IF($F13="","",SUM($G13:$I13)) | K13: =IF($F13="","",$F13-$J13) | M13: =IF($F13="","",IF($J13>=$F13,"🟢 Paid in full",IF($J13>0,"🟠 Partial","🔴 Unpaid")))
B14: 7 | J14: =IF($F14="","",SUM($G14:$I14)) | K14: =IF($F14="","",$F14-$J14) | M14: =IF($F14="","",IF($J14>=$F14,"🟢 Paid in full",IF($J14>0,"🟠 Partial","🔴 Unpaid")))
B15: 8 | J15: =IF($F15="","",SUM($G15:$I15)) | K15: =IF($F15="","",$F15-$J15) | M15: =IF($F15="","",IF($J15>=$F15,"🟢 Paid in full",IF($J15>0,"🟠 Partial","🔴 Unpaid")))
B16: 9 | J16: =IF($F16="","",SUM($G16:$I16)) | K16: =IF($F16="","",$F16-$J16) | M16: =IF($F16="","",IF($J16>=$F16,"🟢 Paid in full",IF($J16>0,"🟠 Partial","🔴 Unpaid")))
B17: 10 | J17: =IF($F17="","",SUM($G17:$I17)) | K17: =IF($F17="","",$F17-$J17) | M17: =IF($F17="","",IF($J17>=$F17,"🟢 Paid in full",IF($J17>0,"🟠 Partial","🔴 Unpaid")))
B18: 11 | J18: =IF($F18="","",SUM($G18:$I18)) | K18: =IF($F18="","",$F18-$J18) | M18: =IF($F18="","",IF($J18>=$F18,"🟢 Paid in full",IF($J18>0,"🟠 Partial","🔴 Unpaid")))
B19: 12 | J19: =IF($F19="","",SUM($G19:$I19)) | K19: =IF($F19="","",$F19-$J19) | M19: =IF($F19="","",IF($J19>=$F19,"🟢 Paid in full",IF($J19>0,"🟠 Partial","🔴 Unpaid")))
... B67: 60 | J67: =IF($F67="","",SUM($G67:$I67)) | K67: =IF($F67="","",$F67-$J67) | M67: =IF($F67="","",IF($J67>=$F67,"🟢 Paid in full",IF($J67>0,"🟠 Partial","🔴 Unpaid")))
B69: TOTALS → | F69: =SUM($F$8:$F$67) -> 0 | G69: =SUM($G$8:$G$67) -> 0 | H69: =SUM($H$8:$H$67) -> 0 | I69: =SUM($I$8:$I$67) -> 0 | J69: =SUM($J$8:$J$67) -> 0 | K69: =SUM($K$8:$K$67) -> 0
B71: 💡 How to use this tab
