Workbook
Name AlertAt: '⚙️ Setup'!$C$23
Name CountOrdered: '⚙️ Setup'!$C$26
Name Currency: '⚙️ Setup'!$C$21
Name DueSoonDays: '⚙️ Setup'!$C$24
Name EventDate: '⚙️ Setup'!$C$7
Name EventName: '⚙️ Setup'!$C$6
Name GiftCategories: OFFSET('⚙️ Setup'!$D$30,0,0,MAX(1,COUNTA('⚙️ Setup'!$D$30:$D$49)),1)
Name HidingSpots: OFFSET('⚙️ Setup'!$G$30,0,0,MAX(1,COUNTA('⚙️ Setup'!$G$30:$G$49)),1)
Name Occasions: OFFSET('_Data'!$A$2,0,0,COUNTA('_Data'!$A$2:$A$19),1)
Name OrderStatuses: '⚙️ Setup'!$C$54:$C$59
Name Priorities: '⚙️ Setup'!$D$54:$D$56
Name Recipients: OFFSET('⚙️ Setup'!$B$30,0,0,MAX(1,COUNTA('⚙️ Setup'!$B$30:$B$49)),1)
Name Relationships: OFFSET('⚙️ Setup'!$C$30,0,0,MAX(1,COUNTA('⚙️ Setup'!$C$30:$C$49)),1)
Name SecretMode: '⚙️ Setup'!$C$25
Name ShopCategories: OFFSET('⚙️ Setup'!$F$30,0,0,MAX(1,COUNTA('⚙️ Setup'!$F$30:$F$49)),1)
Name Statuses: '⚙️ Setup'!$B$54:$B$59
Name StockingItems: OFFSET('⚙️ Setup'!$J$30,0,0,MAX(1,COUNTA('⚙️ Setup'!$J$30:$J$49)),1)
Name StockingOwners: OFFSET('⚙️ Setup'!$I$30,0,0,MAX(1,COUNTA('⚙️ Setup'!$I$30:$I$49)),1)
Name Stores: OFFSET('⚙️ Setup'!$E$30,0,0,MAX(1,COUNTA('⚙️ Setup'!$E$30:$E$49)),1)
Name Tick: '⚙️ Setup'!$E$54:$E$55
Name TodoCategories: OFFSET('⚙️ Setup'!$H$30,0,0,MAX(1,COUNTA('⚙️ Setup'!$H$30:$H$49)),1)
Name TotalBudget: '⚙️ Setup'!$C$22

Sheet 🎄 Dashboard
B2: ="🎄 "&EventName&" "&TEXT(EventDate,"yyyy")&" • Gift Command Center" -> 🎄 Christmas 2026 • Gift Command Center
B3: =IF('_Data'!$AF$2>1,"⏳ "&'_Data'!$AF$2&" Days Until "&EventName&" 🎁",IF('_Data'!$AF$2=1,"⏳ Tomorrow is "&EventName&"! 🎁",IF('_Data'!$AF$2=0,"🎉 It's "&EventName&" today! 🎄","🎄 "&EventName&" "&TEXT(EventDate,"yyyy")&" has been and gone — set a new date in ⚙️ Setup"))) -> ⏳ 104 Days Until Christmas 🎁
B4: =TEXT(TODAY(),"dddd d mmmm yyyy")&" • "&EventName&" falls on "&TEXT(EventDate,"dddd d mmmm yyyy")&" • "&'_Data'!$AF$5&" of "&'_Data'!$AF$4&" gifts bought • "&'_Data'!$AF$6&" wrapped • "&'_Data'!$AF$7&" handed over" -> Saturday 12 September 2026 • Christmas falls on Friday 25 December 2026 • 18 of 25 gifts bought • 13 wrapped • 6 handed over
B6: 💰 BUDGET AT A GLANCE
B7: TOTAL CHRISTMAS BUDGET | E7: SPENT SO FAR | H7: STILL TO SPEND | K7: BUDGET USED
B8: =Currency&TEXT('_Data'!$AF$17,"#,##0") -> $1,500 | E8: =Currency&TEXT('_Data'!$AF$18,"#,##0") -> $1,206 | H8: =Currency&TEXT('_Data'!$AF$19,"#,##0") -> $294 | K8: ='_Data'!$AF$20 -> 0.80382667
B9: Budget progress | D9: =IFERROR(REPT("█",ROUND(MIN(1,IFERROR(('_Data'!$AF$18)/('_Data'!$AF$17),0))*40,0))&REPT("░",40-ROUND(MIN(1,IFERROR(('_Data'!$AF$18)/('_Data'!$AF$17),0))*40,0)),"░░░░░░░░░░░░░░░░░░░░░░░░░░░░░░░░░░░░░░░░") -> ████████████████████████████████░░░░░░░░ | L9: =TEXT('_Data'!$AF$20,"0%")&" used" -> 80% used
B11: 🎁 GIFT PROGRESS
B12: 🎁 GIFTS PLANNED | E12: ✅ PURCHASED | H12: 🎀 WRAPPED | K12: 📦 DELIVERED / GIVEN
B13: ='_Data'!$AF$4 -> 25 | E13: ='_Data'!$AF$5&" / "&'_Data'!$AF$4 -> 18 / 25 | H13: ='_Data'!$AF$6 -> 13 | K13: ='_Data'!$AF$7 -> 6
B14: 🛒 STILL TO BUY | E14: 🛍️ ON ORDER | H14: 📈 COMPLETION | K14: 👥 AVG SPEND PER PERSON
B15: ='_Data'!$AF$8 -> 4 | E15: ='_Data'!$AF$9 -> 3 | H15: ='_Data'!$AF$12 -> 0.72 | K15: =Currency&TEXT('_Data'!$AF$14,"#,##0") -> $77
B16: Gift progress | D16: =IFERROR(REPT("█",ROUND(MIN(1,IFERROR(('_Data'!$AF$5)/('_Data'!$AF$4),0))*40,0))&REPT("░",40-ROUND(MIN(1,IFERROR(('_Data'!$AF$5)/('_Data'!$AF$4),0))*40,0)),"░░░░░░░░░░░░░░░░░░░░░░░░░░░░░░░░░░░░░░░░") -> █████████████████████████████░░░░░░░░░░░ | L16: ='_Data'!$AF$5&" / "&'_Data'!$AF$4&" gifts" -> 18 / 25 gifts
B18: 📊 WHERE THE MONEY GOES
B49: 🎯 WHAT'S LEFT TO DO | H49: ⏰ UPCOMING DEADLINES
B50: =IF('_Data'!$AF$8=0,"✅ Every gift is bought — nice work!","🛒 "&'_Data'!$AF$8&" gift(s) still to buy"&IF('_Data'!$AF$9>0," ("&'_Data'!$AF$9&" already on order)","")) -> 🛒 4 gift(s) still to buy (3 already on order) | H50: =IFERROR(SMALL('_Data'!$AA$2:$AA$61,1),"") -> 46346 | I50: =IF($H50="","— nothing scheduled —",IFERROR(INDEX('_Data'!$AB$2:$AB$61,MATCH(SMALL('_Data'!$AA$2:$AA$61,1),'_Data'!$AA$2:$AA$61,0)),"")) -> ✅ Address & write all cards | L50: =IF($H50="","",$H50-TODAY()) -> 69
B51: =IF('_Data'!$AF$10=0,"✅ Everything is wrapped","🎀 "&'_Data'!$AF$10&" present(s) still to wrap") -> 🎀 5 present(s) still to wrap | H51: =IFERROR(SMALL('_Data'!$AA$2:$AA$61,2),"") -> 46356 | I51: =IF($H51="","— nothing scheduled —",IFERROR(INDEX('_Data'!$AB$2:$AB$61,MATCH(SMALL('_Data'!$AA$2:$AA$61,2),'_Data'!$AA$2:$AA$61,0)),"")) -> ✅ Post the cards | L51: =IF($H51="","",$H51-TODAY()) -> 79
B52: =IF('_Data'!$AF$11=0,"✅ All wrapped gifts handed over","📦 "&'_Data'!$AF$11&" wrapped gift(s) not given yet") -> 📦 7 wrapped gift(s) not given yet | H52: =IFERROR(SMALL('_Data'!$AA$2:$AA$61,3),"") -> 46360 | I52: =IF($H52="","— nothing scheduled —",IFERROR(INDEX('_Data'!$AB$2:$AB$61,MATCH(SMALL('_Data'!$AA$2:$AA$61,3),'_Data'!$AA$2:$AA$61,0)),"")) -> ✅ Book travel / check the car | L52: =IF($H52="","",$H52-TODAY()) -> 83
B53: =IF('_Data'!$AF$17=0,"📝 Set your category budgets on the 💰 Budget tab",IF('_Data'!$AF$19<0,"🔴 Over budget by "&Currency&TEXT(-'_Data'!$AF$19,"#,##0"),IF('_Data'!$AF$20>=AlertAt,"⚠️ "&TEXT('_Data'!$AF$20,"0%")&" of the budget used — "&Currency&TEXT('_Data'!$AF$19,"#,##0")&" left to play with","💰 "&Currency&TEXT('_Data'!$AF$19,"#,##0")&" left to spend ("&TEXT('_Data'!$AF$20,"0%")&" used)"))) -> 💰 $294 left to spend (80% used) | H53: =IFERROR(SMALL('_Data'!$AA$2:$AA$61,4),"") -> 46363 | I53: =IF($H53="","— nothing scheduled —",IFERROR(INDEX('_Data'!$AB$2:$AB$61,MATCH(SMALL('_Data'!$AA$2:$AA$61,4),'_Data'!$AA$2:$AA$61,0)),"")) -> ✅ Prepare the stockings | L53: =IF($H53="","",$H53-TODAY()) -> 86
B54: =IF('_Data'!$AF$21=0,"🛍️ Your shopping list is empty",IF('_Data'!$AF$21='_Data'!$AF$22,"✅ Shopping list complete ("&'_Data'!$AF$21&" items)","🛍️ "&('_Data'!$AF$21-'_Data'!$AF$22)&" of "&'_Data'!$AF$21&" shopping items still to buy")) -> 🛍️ 11 of 24 shopping items still to buy | H54: =IFERROR(SMALL('_Data'!$AA$2:$AA$61,5),"") -> 46367 | I54: =IF($H54="","— nothing scheduled —",IFERROR(INDEX('_Data'!$AB$2:$AB$61,MATCH(SMALL('_Data'!$AA$2:$AA$61,5),'_Data'!$AA$2:$AA$61,0)),"")) -> ✅ Plan the Christmas dinner menu | L54: =IF($H54="","",$H54-TODAY()) -> 90
B55: ="💡 Tip: sort the 🎁 Gift Tracker by “Store” and you shop the whole list in one trip." -> 💡 Tip: sort the 🎁 Gift Tracker by “Store” and you shop the whole list in one trip. | H55: 🗓️ KEY DATES (calculated from your event date)
B56: ="💡 Tip: the 🎀 Wrapping tab remembers where every present is hiding." -> 💡 Tip: the 🎀 Wrapping tab remembers where every present is hiding. | H56: =EventDate-10 -> 46371 | I56: 📮 Last online order date | L56: =IF($H56-TODAY()<0,"✓ passed",$H56-TODAY()) -> 94
B57: ="💡 Tip: change the event date in ⚙️ Setup and every deadline re-dates itself." -> 💡 Tip: change the event date in ⚙️ Setup and every deadline re-dates itself. | H57: =EventDate-14 -> 46367 | I57: 💌 Cards in the post by | L57: =IF($H57-TODAY()<0,"✓ passed",$H57-TODAY()) -> 90
B58: ="💡 Tip: use this file for birthdays too — pick an occasion in ⚙️ Setup." -> 💡 Tip: use this file for birthdays too — pick an occasion in ⚙️ Setup. | H58: =EventDate-2 -> 46379 | I58: 🎀 Wrapping day | L58: =IF($H58-TODAY()<0,"✓ passed",$H58-TODAY()) -> 102
B59: ="💡 Tip: 🙈 Secret Mode hides the hiding spots when somebody is watching." -> 💡 Tip: 🙈 Secret Mode hides the hiding spots when somebody is watching. | H59: =EventDate -> 46381 | I59: 🎄 The big day | L59: =IF($H59-TODAY()<0,"✓ passed",$H59-TODAY()) -> 104
B61: 🎅 PER-RECIPIENT SUMMARY (automatic)
B62: Recipient | D62: Budget | E62: Spent | F62: Remaining | G62: Gifts | H62: Bought | I62: Wrapped | J62: Given | K62: To buy | L62: Done % | M62: Progress
B63: ='_Data'!$H$2 -> Mum | D63: =IF($B63="","",'_Data'!$I$2) -> 105 | E63: =IF($B63="","",'_Data'!$J$2) -> 97.99 | F63: =IF(OR($B63="",'_Data'!$H$2=""),"",$D63-$E63) -> 7.01 | G63: =IF($B63="","",'_Data'!$K$2) -> 2 | H63: =IF($B63="","",'_Data'!$L$2) -> 2 | I63: =IF($B63="","",'_Data'!$M$2) -> 2 | J63: =IF($B63="","",'_Data'!$N$2) -> 0 | K63: =IF($B63="","",'_Data'!$O$2) -> 0 | L63: =IF($B63="","",'_Data'!$P$2) -> 1 | M63: =IF($B63="","",REPT("█",ROUND(IFERROR($L63,0)*10,0))&REPT("░",10-ROUND(IFERROR($L63,0)*10,0))) -> ██████████
B64: ='_Data'!$H$3 -> Dad | D64: =IF($B64="","",'_Data'!$I$3) -> 95 | E64: =IF($B64="","",'_Data'!$J$3) -> 93.5 | F64: =IF(OR($B64="",'_Data'!$H$3=""),"",$D64-$E64) -> 1.5 | G64: =IF($B64="","",'_Data'!$K$3) -> 2 | H64: =IF($B64="","",'_Data'!$L$3) -> 2 | I64: =IF($B64="","",'_Data'!$M$3) -> 2 | J64: =IF($B64="","",'_Data'!$N$3) -> 1 | K64: =IF($B64="","",'_Data'!$O$3) -> 0 | L64: =IF($B64="","",'_Data'!$P$3) -> 1 | M64: =IF($B64="","",REPT("█",ROUND(IFERROR($L64,0)*10,0))&REPT("░",10-ROUND(IFERROR($L64,0)*10,0))) -> ██████████
B65: ='_Data'!$H$4 -> Grandma Rose | D65: =IF($B65="","",'_Data'!$I$4) -> 135 | E65: =IF($B65="","",'_Data'!$J$4) -> 129.99 | F65: =IF(OR($B65="",'_Data'!$H$4=""),"",$D65-$E65) -> 5.01 | G65: =IF($B65="","",'_Data'!$K$4) -> 2 | H65: =IF($B65="","",'_Data'!$L$4) -> 1 | I65: =IF($B65="","",'_Data'!$M$4) -> 1 | J65: =IF($B65="","",'_Data'!$N$4) -> 0 | K65: =IF($B65="","",'_Data'!$O$4) -> 1 | L65: =IF($B65="","",'_Data'!$P$4) -> 0.5 | M65: =IF($B65="","",REPT("█",ROUND(IFERROR($L65,0)*10,0))&REPT("░",10-ROUND(IFERROR($L65,0)*10,0))) -> █████░░░░░
B66: ='_Data'!$H$5 -> Grandpa Joe | D66: =IF($B66="","",'_Data'!$I$5) -> 55 | E66: =IF($B66="","",'_Data'!$J$5) -> 49.5 | F66: =IF(OR($B66="",'_Data'!$H$5=""),"",$D66-$E66) -> 5.5 | G66: =IF($B66="","",'_Data'!$K$5) -> 2 | H66: =IF($B66="","",'_Data'!$L$5) -> 2 | I66: =IF($B66="","",'_Data'!$M$5) -> 2 | J66: =IF($B66="","",'_Data'!$N$5) -> 2 | K66: =IF($B66="","",'_Data'!$O$5) -> 0 | L66: =IF($B66="","",'_Data'!$P$5) -> 1 | M66: =IF($B66="","",REPT("█",ROUND(IFERROR($L66,0)*10,0))&REPT("░",10-ROUND(IFERROR($L66,0)*10,0))) -> ██████████
B67: ='_Data'!$H$6 -> Sister Emily | D67: =IF($B67="","",'_Data'!$I$6) -> 75 | E67: =IF($B67="","",'_Data'!$J$6) -> 48 | F67: =IF(OR($B67="",'_Data'!$H$6=""),"",$D67-$E67) -> 27 | G67: =IF($B67="","",'_Data'!$K$6) -> 2 | H67: =IF($B67="","",'_Data'!$L$6) -> 1 | I67: =IF($B67="","",'_Data'!$M$6) -> 1 | J67: =IF($B67="","",'_Data'!$N$6) -> 0 | K67: =IF($B67="","",'_Data'!$O$6) -> 1 | L67: =IF($B67="","",'_Data'!$P$6) -> 0.5 | M67: =IF($B67="","",REPT("█",ROUND(IFERROR($L67,0)*10,0))&REPT("░",10-ROUND(IFERROR($L67,0)*10,0))) -> █████░░░░░
B68: ='_Data'!$H$7 -> Brother Jack | D68: =IF($B68="","",'_Data'!$I$7) -> 115 | E68: =IF($B68="","",'_Data'!$J$7) -> 107.99 | F68: =IF(OR($B68="",'_Data'!$H$7=""),"",$D68-$E68) -> 7.01 | G68: =IF($B68="","",'_Data'!$K$7) -> 2 | H68: =IF($B68="","",'_Data'!$L$7) -> 1 | I68: =IF($B68="","",'_Data'!$M$7) -> 0 | J68: =IF($B68="","",'_Data'!$N$7) -> 0 | K68: =IF($B68="","",'_Data'!$O$7) -> 1 | L68: =IF($B68="","",'_Data'!$P$7) -> 0.5 | M68: =IF($B68="","",REPT("█",ROUND(IFERROR($L68,0)*10,0))&REPT("░",10-ROUND(IFERROR($L68,0)*10,0))) -> █████░░░░░
B69: ='_Data'!$H$8 -> Niece Sophie | D69: =IF($B69="","",'_Data'!$I$8) -> 67 | E69: =IF($B69="","",'_Data'!$J$8) -> 59.99 | F69: =IF(OR($B69="",'_Data'!$H$8=""),"",$D69-$E69) -> 7.01 | G69: =IF($B69="","",'_Data'!$K$8) -> 2 | H69: =IF($B69="","",'_Data'!$L$8) -> 2 | I69: =IF($B69="","",'_Data'!$M$8) -> 2 | J69: =IF($B69="","",'_Data'!$N$8) -> 1 | K69: =IF($B69="","",'_Data'!$O$8) -> 0 | L69: =IF($B69="","",'_Data'!$P$8) -> 1 | M69: =IF($B69="","",REPT("█",ROUND(IFERROR($L69,0)*10,0))&REPT("░",10-ROUND(IFERROR($L69,0)*10,0))) -> ██████████
B70: ='_Data'!$H$9 -> Nephew Leo | D70: =IF($B70="","",'_Data'!$I$9) -> 65 | E70: =IF($B70="","",'_Data'!$J$9) -> 36 | F70: =IF(OR($B70="",'_Data'!$H$9=""),"",$D70-$E70) -> 29 | G70: =IF($B70="","",'_Data'!$K$9) -> 2 | H70: =IF($B70="","",'_Data'!$L$9) -> 1 | I70: =IF($B70="","",'_Data'!$M$9) -> 0 | J70: =IF($B70="","",'_Data'!$N$9) -> 0 | K70: =IF($B70="","",'_Data'!$O$9) -> 1 | L70: =IF($B70="","",'_Data'!$P$9) -> 0.5 | M70: =IF($B70="","",REPT("█",ROUND(IFERROR($L70,0)*10,0))&REPT("░",10-ROUND(IFERROR($L70,0)*10,0))) -> █████░░░░░
B71: ='_Data'!$H$10 -> Alex (partner) | D71: =IF($B71="","",'_Data'!$I$10) -> 275 | E71: =IF($B71="","",'_Data'!$J$10) -> 254 | F71: =IF(OR($B71="",'_Data'!$H$10=""),"",$D71-$E71) -> 21 | G71: =IF($B71="","",'_Data'!$K$10) -> 2 | H71: =IF($B71="","",'_Data'!$L$10) -> 1 | I71: =IF($B71="","",'_Data'!$M$10) -> 0 | J71: =IF($B71="","",'_Data'!$N$10) -> 0 | K71: =IF($B71="","",'_Data'!$O$10) -> 1 | L71: =IF($B71="","",'_Data'!$P$10) -> 0.5 | M71: =IF($B71="","",REPT("█",ROUND(IFERROR($L71,0)*10,0))&REPT("░",10-ROUND(IFERROR($L71,0)*10,0))) -> █████░░░░░
B72: ='_Data'!$H$11 -> Maya (best friend) | D72: =IF($B72="","",'_Data'!$I$11) -> 52 | E72: =IF($B72="","",'_Data'!$J$11) -> 28.5 | F72: =IF(OR($B72="",'_Data'!$H$11=""),"",$D72-$E72) -> 23.5 | G72: =IF($B72="","",'_Data'!$K$11) -> 2 | H72: =IF($B72="","",'_Data'!$L$11) -> 1 | I72: =IF($B72="","",'_Data'!$M$11) -> 1 | J72: =IF($B72="","",'_Data'!$N$11) -> 1 | K72: =IF($B72="","",'_Data'!$O$11) -> 1 | L72: =IF($B72="","",'_Data'!$P$11) -> 0.5 | M72: =IF($B72="","",REPT("█",ROUND(IFERROR($L72,0)*10,0))&REPT("░",10-ROUND(IFERROR($L72,0)*10,0))) -> █████░░░░░
B73: ='_Data'!$H$12 -> Cousin Dan | D73: =IF($B73="","",'_Data'!$I$12) -> 65 | E73: =IF($B73="","",'_Data'!$J$12) -> 32 | F73: =IF(OR($B73="",'_Data'!$H$12=""),"",$D73-$E73) -> 33 | G73: =IF($B73="","",'_Data'!$K$12) -> 2 | H73: =IF($B73="","",'_Data'!$L$12) -> 1 | I73: =IF($B73="","",'_Data'!$M$12) -> 0 | J73: =IF($B73="","",'_Data'!$N$12) -> 0 | K73: =IF($B73="","",'_Data'!$O$12) -> 1 | L73: =IF($B73="","",'_Data'!$P$12) -> 0.5 | M73: =IF($B73="","",REPT("█",ROUND(IFERROR($L73,0)*10,0))&REPT("░",10-ROUND(IFERROR($L73,0)*10,0))) -> █████░░░░░
B74: ='_Data'!$H$13 -> Aunt Carol | D74: =IF($B74="","",'_Data'!$I$13) -> 58 | E74: =IF($B74="","",'_Data'!$J$13) -> 53.5 | F74: =IF(OR($B74="",'_Data'!$H$13=""),"",$D74-$E74) -> 4.5 | G74: =IF($B74="","",'_Data'!$K$13) -> 2 | H74: =IF($B74="","",'_Data'!$L$13) -> 2 | I74: =IF($B74="","",'_Data'!$M$13) -> 2 | J74: =IF($B74="","",'_Data'!$N$13) -> 1 | K74: =IF($B74="","",'_Data'!$O$13) -> 0 | L74: =IF($B74="","",'_Data'!$P$13) -> 1 | M74: =IF($B74="","",REPT("█",ROUND(IFERROR($L74,0)*10,0))&REPT("░",10-ROUND(IFERROR($L74,0)*10,0))) -> ██████████
B75: ='_Data'!$H$14 -> Uncle Bill | D75: =IF($B75="","",'_Data'!$I$14) -> 0 | E75: =IF($B75="","",'_Data'!$J$14) -> 0 | F75: =IF(OR($B75="",'_Data'!$H$14=""),"",$D75-$E75) -> 0 | G75: =IF($B75="","",'_Data'!$K$14) -> 0 | H75: =IF($B75="","",'_Data'!$L$14) -> 0 | I75: =IF($B75="","",'_Data'!$M$14) -> 0 | J75: =IF($B75="","",'_Data'!$N$14) -> 0 | K75: =IF($B75="","",'_Data'!$O$14) -> 0 | L75: =IF($B75="","",'_Data'!$P$14) | M75: =IF($B75="","",REPT("█",ROUND(IFERROR($L75,0)*10,0))&REPT("░",10-ROUND(IFERROR($L75,0)*10,0))) -> ░░░░░░░░░░
...

Sheet 🎁 Gift Tracker
B2: 🎁 Gift Tracker
B3: Every present in one place — type in the white cells, the tinted cells do the maths. | R3: 🏠 Back to Dashboard
B5: ="🎁 Planned: "&'_Data'!$AF$4 -> 🎁 Planned: 25 | E5: ="✅ Purchased: "&'_Data'!$AF$5 -> ✅ Purchased: 18 | H5: ="🎀 Wrapped: "&'_Data'!$AF$6 -> 🎀 Wrapped: 13 | K5: ="📦 Given: "&'_Data'!$AF$7 -> 📦 Given: 6 | N5: ="🛒 Still to buy: "&'_Data'!$AF$8 -> 🛒 Still to buy: 4 | Q5: ="💰 Spent on gifts: "&Currency&TEXT('_Data'!$AF$16,"#,##0") -> 💰 Spent on gifts: $1,004
B7: # | C7: Recipient | D7: Relationship | E7: Gift idea | F7: Category | G7: Store / where from | H7: Link | I7: 🔗 | J7: Budget | K7: Actual cost | L7: Under / over | M7: % of budget | N7: Status | O7: 🎀 Wrapped | P7: 📦 Given | Q7: Buy-by date | R7: Days left | S7: Deadline alert | T7: Notes
B8: =IF($C8="","",ROW()-7) -> 1 | C8: Mum | D8: Mum | E8: Cashmere scarf | F8: Clothing | G8: John Lewis | H8: https://www.johnlewis.com | I8: =IF($H8="","",HYPERLINK($H8,"🔗")) -> 🔗 | J8: 60 | K8: 55 | L8: =IF($K8="","",IF($J8="",0,$J8)-$K8) -> 5 | M8: =IF(OR($K8="",$J8="",$J8=0),"",$K8/$J8) -> 0.91666667 | N8: ✅ Purchased | O8: ✓ | Q8: 46371 | R8: =IF($Q8="","",$Q8-TODAY()) -> 94 | S8: =IF($C8="","",IF(OR($N8="📦 Delivered",$P8="✓"),"✅ Done",IF($Q8="","",IF($Q8<TODAY(),"🔴 Overdue",IF($Q8-TODAY()<=DueSoonDays,"🟠 Due soon","🟢 On track"))))) -> 🟢 On track | T8: Wanted burgundy or cream
B9: =IF($C9="","",ROW()-7) -> 2 | C9: Mum | D9: Mum | E9: Spa gift set | F9: Beauty | G9: Sephora | H9: https://www.sephora.com | I9: =IF($H9="","",HYPERLINK($H9,"🔗")) -> 🔗 | J9: 45 | K9: 42.99 | L9: =IF($K9="","",IF($J9="",0,$J9)-$K9) -> 2.01 | M9: =IF(OR($K9="",$J9="",$J9=0),"",$K9/$J9) -> 0.95533333 | N9: 🎀 Wrapped | O9: ✓ | Q9: 46371 | R9: =IF($Q9="","",$Q9-TODAY()) -> 94 | S9: =IF($C9="","",IF(OR($N9="📦 Delivered",$P9="✓"),"✅ Done",IF($Q9="","",IF($Q9<TODAY(),"🔴 Overdue",IF($Q9-TODAY()<=DueSoonDays,"🟠 Due soon","🟢 On track"))))) -> 🟢 On track
B10: =IF($C10="","",ROW()-7) -> 3 | C10: Dad | D10: Dad | E10: Leather wallet | F10: Clothing | G10: Amazon | H10: https://www.amazon.com | I10: =IF($H10="","",HYPERLINK($H10,"🔗")) -> 🔗 | J10: 40 | K10: 38.5 | L10: =IF($K10="","",IF($J10="",0,$J10)-$K10) -> 1.5 | M10: =IF(OR($K10="",$J10="",$J10=0),"",$K10/$J10) -> 0.9625 | N10: 📦 Delivered | O10: ✓ | P10: ✓ | Q10: 46367 | R10: =IF($Q10="","",$Q10-TODAY()) -> 90 | S10: =IF($C10="","",IF(OR($N10="📦 Delivered",$P10="✓"),"✅ Done",IF($Q10="","",IF($Q10<TODAY(),"🔴 Overdue",IF($Q10-TODAY()<=DueSoonDays,"🟠 Due soon","🟢 On track"))))) -> ✅ Done | T10: Engraved initials
B11: =IF($C11="","",ROW()-7) -> 4 | C11: Dad | D11: Dad | E11: Whisky tasting set | F11: Food & Drink | G11: Not On The High Street | H11: https://www.notonthehighstreet.com | I11: =IF($H11="","",HYPERLINK($H11,"🔗")) -> 🔗 | J11: 55 | K11: 55 | L11: =IF($K11="","",IF($J11="",0,$J11)-$K11) -> 0 | M11: =IF(OR($K11="",$J11="",$J11=0),"",$K11/$J11) -> 1 | N11: ✅ Purchased | O11: ✓ | Q11: 46373 | R11: =IF($Q11="","",$Q11-TODAY()) -> 96 | S11: =IF($C11="","",IF(OR($N11="📦 Delivered",$P11="✓"),"✅ Done",IF($Q11="","",IF($Q11<TODAY(),"🔴 Overdue",IF($Q11-TODAY()<=DueSoonDays,"🟠 Due soon","🟢 On track"))))) -> 🟢 On track
B12: =IF($C12="","",ROW()-7) -> 5 | C12: Grandma Rose | D12: Grandma | E12: Digital photo frame | F12: Electronics | G12: Amazon | H12: https://www.amazon.com | I12: =IF($H12="","",HYPERLINK($H12,"🔗")) -> 🔗 | J12: 90 | K12: 84.99 | L12: =IF($K12="","",IF($J12="",0,$J12)-$K12) -> 5.01 | M12: =IF(OR($K12="",$J12="",$J12=0),"",$K12/$J12) -> 0.94433333 | N12: 🛍️ Ordered | Q12: 46376 | R12: =IF($Q12="","",$Q12-TODAY()) -> 99 | S12: =IF($C12="","",IF(OR($N12="📦 Delivered",$P12="✓"),"✅ Done",IF($Q12="","",IF($Q12<TODAY(),"🔴 Overdue",IF($Q12-TODAY()<=DueSoonDays,"🟠 Due soon","🟢 On track"))))) -> 🟢 On track | T12: Pre-load family photos
B13: =IF($C13="","",ROW()-7) -> 6 | C13: Grandma Rose | D13: Grandma | E13: Chunky knitted blanket | F13: Handmade | G13: Etsy | H13: https://www.etsy.com | I13: =IF($H13="","",HYPERLINK($H13,"🔗")) -> 🔗 | J13: 45 | K13: 45 | L13: =IF($K13="","",IF($J13="",0,$J13)-$K13) -> 0 | M13: =IF(OR($K13="",$J13="",$J13=0),"",$K13/$J13) -> 1 | N13: 🎀 Wrapped | O13: ✓ | Q13: 46369 | R13: =IF($Q13="","",$Q13-TODAY()) -> 92 | S13: =IF($C13="","",IF(OR($N13="📦 Delivered",$P13="✓"),"✅ Done",IF($Q13="","",IF($Q13<TODAY(),"🔴 Overdue",IF($Q13-TODAY()<=DueSoonDays,"🟠 Due soon","🟢 On track"))))) -> 🟢 On track
B14: =IF($C14="","",ROW()-7) -> 7 | C14: Grandpa Joe | D14: Grandpa | E14: Crossword book bundle | F14: Books | G14: Local Bookshop | I14: =IF($H14="","",HYPERLINK($H14,"🔗")) | J14: 25 | K14: 22 | L14: =IF($K14="","",IF($J14="",0,$J14)-$K14) -> 3 | M14: =IF(OR($K14="",$J14="",$J14=0),"",$K14/$J14) -> 0.88 | N14: 📦 Delivered | O14: ✓ | P14: ✓ | Q14: 46365 | R14: =IF($Q14="","",$Q14-TODAY()) -> 88 | S14: =IF($C14="","",IF(OR($N14="📦 Delivered",$P14="✓"),"✅ Done",IF($Q14="","",IF($Q14<TODAY(),"🔴 Overdue",IF($Q14-TODAY()<=DueSoonDays,"🟠 Due soon","🟢 On track"))))) -> ✅ Done
B15: =IF($C15="","",ROW()-7) -> 8 | C15: Grandpa Joe | D15: Grandpa | E15: Heated slippers | F15: Clothing | G15: Amazon | H15: https://www.amazon.com | I15: =IF($H15="","",HYPERLINK($H15,"🔗")) -> 🔗 | J15: 30 | K15: 27.5 | L15: =IF($K15="","",IF($J15="",0,$J15)-$K15) -> 2.5 | M15: =IF(OR($K15="",$J15="",$J15=0),"",$K15/$J15) -> 0.91666667 | N15: 📦 Delivered | O15: ✓ | P15: ✓ | Q15: 46365 | R15: =IF($Q15="","",$Q15-TODAY()) -> 88 | S15: =IF($C15="","",IF(OR($N15="📦 Delivered",$P15="✓"),"✅ Done",IF($Q15="","",IF($Q15<TODAY(),"🔴 Overdue",IF($Q15-TODAY()<=DueSoonDays,"🟠 Due soon","🟢 On track"))))) -> ✅ Done
B16: =IF($C16="","",ROW()-7) -> 9 | C16: Sister Emily | D16: Sister | E16: Gold hoop earrings | F16: Jewellery | G16: Etsy | H16: https://www.etsy.com | I16: =IF($H16="","",HYPERLINK($H16,"🔗")) -> 🔗 | J16: 50 | K16: 48 | L16: =IF($K16="","",IF($J16="",0,$J16)-$K16) -> 2 | M16: =IF(OR($K16="",$J16="",$J16=0),"",$K16/$J16) -> 0.96 | N16: 🎀 Wrapped | O16: ✓ | Q16: 46375 | R16: =IF($Q16="","",$Q16-TODAY()) -> 98 | S16: =IF($C16="","",IF(OR($N16="📦 Delivered",$P16="✓"),"✅ Done",IF($Q16="","",IF($Q16<TODAY(),"🔴 Overdue",IF($Q16-TODAY()<=DueSoonDays,"🟠 Due soon","🟢 On track"))))) -> 🟢 On track
B17: =IF($C17="","",ROW()-7) -> 10 | C17: Sister Emily | D17: Sister | E17: Bath bomb gift box | F17: Beauty | G17: Sephora | H17: https://www.sephora.com | I17: =IF($H17="","",HYPERLINK($H17,"🔗")) -> 🔗 | J17: 25 | L17: =IF($K17="","",IF($J17="",0,$J17)-$K17) | M17: =IF(OR($K17="",$J17="",$J17=0),"",$K17/$J17) | N17: 🛒 Need to Buy | Q17: 46375 | R17: =IF($Q17="","",$Q17-TODAY()) -> 98 | S17: =IF($C17="","",IF(OR($N17="📦 Delivered",$P17="✓"),"✅ Done",IF($Q17="","",IF($Q17<TODAY(),"🔴 Overdue",IF($Q17-TODAY()<=DueSoonDays,"🟠 Due soon","🟢 On track"))))) -> 🟢 On track | T17: Check the winter collection
B18: =IF($C18="","",ROW()-7) -> 11 | C18: Brother Jack | D18: Brother | E18: Wireless earbuds | F18: Electronics | G18: Best Buy | H18: https://www.bestbuy.com | I18: =IF($H18="","",HYPERLINK($H18,"🔗")) -> 🔗 | J18: 80 | K18: 74.99 | L18: =IF($K18="","",IF($J18="",0,$J18)-$K18) -> 5.01 | M18: =IF(OR($K18="",$J18="",$J18=0),"",$K18/$J18) -> 0.937375 | N18: 🛍️ Ordered | Q18: 46377 | R18: =IF($Q18="","",$Q18-TODAY()) -> 100 | S18: =IF($C18="","",IF(OR($N18="📦 Delivered",$P18="✓"),"✅ Done",IF($Q18="","",IF($Q18<TODAY(),"🔴 Overdue",IF($Q18-TODAY()<=DueSoonDays,"🟠 Due soon","🟢 On track"))))) -> 🟢 On track | T18: Express delivery paid
B19: =IF($C19="","",ROW()-7) -> 12 | C19: Brother Jack | D19: Brother | E19: Craft beer hamper | F19: Food & Drink | G19: Tesco | I19: =IF($H19="","",HYPERLINK($H19,"🔗")) | J19: 35 | K19: 33 | L19: =IF($K19="","",IF($J19="",0,$J19)-$K19) -> 2 | M19: =IF(OR($K19="",$J19="",$J19=0),"",$K19/$J19) -> 0.94285714 | N19: ✅ Purchased | Q19: 46372 | R19: =IF($Q19="","",$Q19-TODAY()) -> 95 | S19: =IF($C19="","",IF(OR($N19="📦 Delivered",$P19="✓"),"✅ Done",IF($Q19="","",IF($Q19<TODAY(),"🔴 Overdue",IF($Q19-TODAY()<=DueSoonDays,"🟠 Due soon","🟢 On track"))))) -> 🟢 On track
B20: =IF($C20="","",ROW()-7) -> 13 | C20: Niece Sophie | D20: Niece | E20: LEGO Friends set | F20: Toys | G20: Amazon | H20: https://www.amazon.com | I20: =IF($H20="","",HYPERLINK($H20,"🔗")) -> 🔗 | J20: 45 | K20: 39.99 | L20: =IF($K20="","",IF($J20="",0,$J20)-$K20) -> 5.01 | M20: =IF(OR($K20="",$J20="",$J20=0),"",$K20/$J20) -> 0.88866667 | N20: 📦 Delivered | O20: ✓ | P20: ✓ | Q20: 46363 | R20: =IF($Q20="","",$Q20-TODAY()) -> 86 | S20: =IF($C20="","",IF(OR($N20="📦 Delivered",$P20="✓"),"✅ Done",IF($Q20="","",IF($Q20<TODAY(),"🔴 Overdue",IF($Q20-TODAY()<=DueSoonDays,"🟠 Due soon","🟢 On track"))))) -> ✅ Done | T20: Age 8 - checked the age guide
B21: =IF($C21="","",ROW()-7) -> 14 | C21: Niece Sophie | D21: Niece | E21: Art supplies case | F21: Kids | G21: Etsy | H21: https://www.etsy.com | I21: =IF($H21="","",HYPERLINK($H21,"🔗")) -> 🔗 | J21: 22 | K21: 20 | L21: =IF($K21="","",IF($J21="",0,$J21)-$K21) -> 2 | M21: =IF(OR($K21="",$J21="",$J21=0),"",$K21/$J21) -> 0.90909091 | N21: 🎀 Wrapped | O21: ✓ | Q21: 46374 | R21: =IF($Q21="","",$Q21-TODAY()) -> 97 | S21: =IF($C21="","",IF(OR($N21="📦 Delivered",$P21="✓"),"✅ Done",IF($Q21="","",IF($Q21<TODAY(),"🔴 Overdue",IF($Q21-TODAY()<=DueSoonDays,"🟠 Due soon","🟢 On track"))))) -> 🟢 On track
B22: =IF($C22="","",ROW()-7) -> 15 | C22: Nephew Leo | D22: Nephew | E22: Dinosaur museum tickets | F22: Experience | G22: Other | I22: =IF($H22="","",HYPERLINK($H22,"🔗")) | J22: 40 | K22: 36 | L22: =IF($K22="","",IF($J22="",0,$J22)-$K22) -> 4 | M22: =IF(OR($K22="",$J22="",$J22=0),"",$K22/$J22) -> 0.9 | N22: ✅ Purchased | Q22: 46378 | R22: =IF($Q22="","",$Q22-TODAY()) -> 101 | S22: =IF($C22="","",IF(OR($N22="📦 Delivered",$P22="✓"),"✅ Done",IF($Q22="","",IF($Q22<TODAY(),"🔴 Overdue",IF($Q22-TODAY()<=DueSoonDays,"🟠 Due soon","🟢 On track"))))) -> 🟢 On track | T22: Print the voucher
B23: =IF($C23="","",ROW()-7) -> 16 | C23: Nephew Leo | D23: Nephew | E23: Graphic novel bundle | F23: Books | G23: Local Bookshop | I23: =IF($H23="","",HYPERLINK($H23,"🔗")) | J23: 25 | L23: =IF($K23="","",IF($J23="",0,$J23)-$K23) | M23: =IF(OR($K23="",$J23="",$J23=0),"",$K23/$J23) | N23: 💡 Idea | Q23: 46378 | R23: =IF($Q23="","",$Q23-TODAY()) -> 101 | S23: =IF($C23="","",IF(OR($N23="📦 Delivered",$P23="✓"),"✅ Done",IF($Q23="","",IF($Q23<TODAY(),"🔴 Overdue",IF($Q23-TODAY()<=DueSoonDays,"🟠 Due soon","🟢 On track"))))) -> 🟢 On track | T23: Ask Emily what he is reading
B24: =IF($C24="","",ROW()-7) -> 17 | C24: Alex (partner) | D24: Partner | E24: Weekend getaway | F24: Experience | G24: Other | I24: =IF($H24="","",HYPERLINK($H24,"🔗")) | J24: 180 | K24: 165 | L24: =IF($K24="","",IF($J24="",0,$J24)-$K24) -> 15 | M24: =IF(OR($K24="",$J24="",$J24=0),"",$K24/$J24) -> 0.91666667 | N24: ✅ Purchased | Q24: 46379 | R24: =IF($Q24="","",$Q24-TODAY()) -> 102 | S24: =IF($C24="","",IF(OR($N24="📦 Delivered",$P24="✓"),"✅ Done",IF($Q24="","",IF($Q24<TODAY(),"🔴 Overdue",IF($Q24-TODAY()<=DueSoonDays,"🟠 Due soon","🟢 On track"))))) -> 🟢 On track | T24: Booked, no wrapping!
B25: =IF($C25="","",ROW()-7) -> 18 | C25: Alex (partner) | D25: Partner | E25: Engraved watch | F25: Jewellery | G25: Etsy | H25: https://www.etsy.com | I25: =IF($H25="","",HYPERLINK($H25,"🔗")) -> 🔗 | J25: 95 | K25: 89 | L25: =IF($K25="","",IF($J25="",0,$J25)-$K25) -> 6 | M25: =IF(OR($K25="",$J25="",$J25=0),"",$K25/$J25) -> 0.93684211 | N25: 🛍️ Ordered | Q25: 46376 | R25: =IF($Q25="","",$Q25-TODAY()) -> 99 | S25: =IF($C25="","",IF(OR($N25="📦 Delivered",$P25="✓"),"✅ Done",IF($Q25="","",IF($Q25<TODAY(),"🔴 Overdue",IF($Q25-TODAY()<=DueSoonDays,"🟠 Due soon","🟢 On track"))))) -> 🟢 On track
B26: =IF($C26="","",ROW()-7) -> 19 | C26: Maya (best friend) | D26: Friend | E26: Scented candle trio | F26: Home | G26: Not On The High Street | H26: https://www.notonthehighstreet.com | I26: =IF($H26="","",HYPERLINK($H26,"🔗")) -> 🔗 | J26: 30 | K26: 28.5 | L26: =IF($K26="","",IF($J26="",0,$J26)-$K26) -> 1.5 | M26: =IF(OR($K26="",$J26="",$J26=0),"",$K26/$J26) -> 0.95 | N26: 📦 Delivered | O26: ✓ | P26: ✓ | Q26: 46361 | R26: =IF($Q26="","",$Q26-TODAY()) -> 84 | S26: =IF($C26="","",IF(OR($N26="📦 Delivered",$P26="✓"),"✅ Done",IF($Q26="","",IF($Q26<TODAY(),"🔴 Overdue",IF($Q26-TODAY()<=DueSoonDays,"🟠 Due soon","🟢 On track"))))) -> ✅ Done
B27: =IF($C27="","",ROW()-7) -> 20 | C27: Maya (best friend) | D27: Friend | E27: Baking cookbook | F27: Books | G27: Amazon | H27: https://www.amazon.com | I27: =IF($H27="","",HYPERLINK($H27,"🔗")) -> 🔗 | J27: 22 | L27: =IF($K27="","",IF($J27="",0,$J27)-$K27) | M27: =IF(OR($K27="",$J27="",$J27=0),"",$K27/$J27) | N27: 🛒 Need to Buy | Q27: 46375 | R27: =IF($Q27="","",$Q27-TODAY()) -> 98 | S27: =IF($C27="","",IF(OR($N27="📦 Delivered",$P27="✓"),"✅ Done",IF($Q27="","",IF($Q27<TODAY(),"🔴 Overdue",IF($Q27-TODAY()<=DueSoonDays,"🟠 Due soon","🟢 On track"))))) -> 🟢 On track
B28: =IF($C28="","",ROW()-7) -> 21 | C28: Cousin Dan | D28: Cousin | E28: Strategy board game | F28: Games | G28: Target | H28: https://www.target.com | I28: =IF($H28="","",HYPERLINK($H28,"🔗")) -> 🔗 | J28: 35 | K28: 32 | L28: =IF($K28="","",IF($J28="",0,$J28)-$K28) -> 3 | M28: =IF(OR($K28="",$J28="",$J28=0),"",$K28/$J28) -> 0.91428571 | N28: ✅ Purchased | Q28: 46373 | R28: =IF($Q28="","",$Q28-TODAY()) -> 96 | S28: =IF($C28="","",IF(OR($N28="📦 Delivered",$P28="✓"),"✅ Done",IF($Q28="","",IF($Q28<TODAY(),"🔴 Overdue",IF($Q28-TODAY()<=DueSoonDays,"🟠 Due soon","🟢 On track"))))) -> 🟢 On track
B29: =IF($C29="","",ROW()-7) -> 22 | C29: Cousin Dan | D29: Cousin | E29: Coffee bean subscription | F29: Food & Drink | G29: Etsy | H29: https://www.etsy.com | I29: =IF($H29="","",HYPERLINK($H29,"🔗")) -> 🔗 | J29: 30 | L29: =IF($K29="","",IF($J29="",0,$J29)-$K29) | M29: =IF(OR($K29="",$J29="",$J29=0),"",$K29/$J29) | N29: 🛒 Need to Buy | Q29: 46373 | R29: =IF($Q29="","",$Q29-TODAY()) -> 96 | S29: =IF($C29="","",IF(OR($N29="📦 Delivered",$P29="✓"),"✅ Done",IF($Q29="","",IF($Q29<TODAY(),"🔴 Overdue",IF($Q29-TODAY()<=DueSoonDays,"🟠 Due soon","🟢 On track"))))) -> 🟢 On track | T29: 3-month subscription
B30: =IF($C30="","",ROW()-7) -> 23 | C30: Aunt Carol | D30: Aunt | E30: Silk scarf | F30: Clothing | G30: M&S | H30: https://www.marksandspencer.com | I30: =IF($H30="","",HYPERLINK($H30,"🔗")) -> 🔗 | J30: 40 | K30: 37.5 | L30: =IF($K30="","",IF($J30="",0,$J30)-$K30) -> 2.5 | M30: =IF(OR($K30="",$J30="",$J30=0),"",$K30/$J30) -> 0.9375 | N30: 📦 Delivered | O30: ✓ | P30: ✓ | Q30: 46360 | R30: =IF($Q30="","",$Q30-TODAY()) -> 83 | S30: =IF($C30="","",IF(OR($N30="📦 Delivered",$P30="✓"),"✅ Done",IF($Q30="","",IF($Q30<TODAY(),"🔴 Overdue",IF($Q30-TODAY()<=DueSoonDays,"🟠 Due soon","🟢 On track"))))) -> ✅ Done
B31: =IF($C31="","",ROW()-7) -> 24 | C31: Aunt Carol | D31: Aunt | E31: Garden gloves & tool set | F31: Home | G31: Amazon | H31: https://www.amazon.com | I31: =IF($H31="","",HYPERLINK($H31,"🔗")) -> 🔗 | J31: 18 | K31: 16 | L31: =IF($K31="","",IF($J31="",0,$J31)-$K31) -> 2 | M31: =IF(OR($K31="",$J31="",$J31=0),"",$K31/$J31) -> 0.88888889 | N31: 🎀 Wrapped | O31: ✓ | Q31: 46374 | R31: =IF($Q31="","",$Q31-TODAY()) -> 97 | S31: =IF($C31="","",IF(OR($N31="📦 Delivered",$P31="✓"),"✅ Done",IF($Q31="","",IF($Q31<TODAY(),"🔴 Overdue",IF($Q31-TODAY()<=DueSoonDays,"🟠 Due soon","🟢 On track"))))) -> 🟢 On track
B32: =IF($C32="","",ROW()-7) -> 25 | C32: Secret Santa | D32: Secret Santa | E32: Novelty reindeer mug | F32: Other | G32: Target | H32: https://www.target.com | I32: =IF($H32="","",HYPERLINK($H32,"🔗")) -> 🔗 | J32: 15 | K32: 12.99 | L32: =IF($K32="","",IF($J32="",0,$J32)-$K32) -> 2.01 | M32: =IF(OR($K32="",$J32="",$J32=0),"",$K32/$J32) -> 0.866 | N32: ✅ Purchased | Q32: 46377 | R32: =IF($Q32="","",$Q32-TODAY()) -> 100 | S32: =IF($C32="","",IF(OR($N32="📦 Delivered",$P32="✓"),"✅ Done",IF($Q32="","",IF($Q32<TODAY(),"🔴 Overdue",IF($Q32-TODAY()<=DueSoonDays,"🟠 Due soon","🟢 On track"))))) -> 🟢 On track | T32: Office Secret Santa - $15 limit
B33: =IF($C33="","",ROW()-7) | I33: =IF($H33="","",HYPERLINK($H33,"🔗")) | L33: =IF($K33="","",IF($J33="",0,$J33)-$K33) | M33: =IF(OR($K33="",$J33="",$J33=0),"",$K33/$J33) | R33: =IF($Q33="","",$Q33-TODAY()) | S33: =IF($C33="","",IF(OR($N33="📦 Delivered",$P33="✓"),"✅ Done",IF($Q33="","",IF($Q33<TODAY(),"🔴 Overdue",IF($Q33-TODAY()<=DueSoonDays,"🟠 Due soon","🟢 On track")))))
B34: =IF($C34="","",ROW()-7) | I34: =IF($H34="","",HYPERLINK($H34,"🔗")) | L34: =IF($K34="","",IF($J34="",0,$J34)-$K34) | M34: =IF(OR($K34="",$J34="",$J34=0),"",$K34/$J34) | R34: =IF($Q34="","",$Q34-TODAY()) | S34: =IF($C34="","",IF(OR($N34="📦 Delivered",$P34="✓"),"✅ Done",IF($Q34="","",IF($Q34<TODAY(),"🔴 Overdue",IF($Q34-TODAY()<=DueSoonDays,"🟠 Due soon","🟢 On track")))))
B35: =IF($C35="","",ROW()-7) | I35: =IF($H35="","",HYPERLINK($H35,"🔗")) | L35: =IF($K35="","",IF($J35="",0,$J35)-$K35) | M35: =IF(OR($K35="",$J35="",$J35=0),"",$K35/$J35) | R35: =IF($Q35="","",$Q35-TODAY()) | S35: =IF($C35="","",IF(OR($N35="📦 Delivered",$P35="✓"),"✅ Done",IF($Q35="","",IF($Q35<TODAY(),"🔴 Overdue",IF($Q35-TODAY()<=DueSoonDays,"🟠 Due soon","🟢 On track")))))
B36: =IF($C36="","",ROW()-7) | I36: =IF($H36="","",HYPERLINK($H36,"🔗")) | L36: =IF($K36="","",IF($J36="",0,$J36)-$K36) | M36: =IF(OR($K36="",$J36="",$J36=0),"",$K36/$J36) | R36: =IF($Q36="","",$Q36-TODAY()) | S36: =IF($C36="","",IF(OR($N36="📦 Delivered",$P36="✓"),"✅ Done",IF($Q36="","",IF($Q36<TODAY(),"🔴 Overdue",IF($Q36-TODAY()<=DueSoonDays,"🟠 Due soon","🟢 On track")))))
B37: =IF($C37="","",ROW()-7) | I37: =IF($H37="","",HYPERLINK($H37,"🔗")) | L37: =IF($K37="","",IF($J37="",0,$J37)-$K37) | M37: =IF(OR($K37="",$J37="",$J37=0),"",$K37/$J37) | R37: =IF($Q37="","",$Q37-TODAY()) | S37: =IF($C37="","",IF(OR($N37="📦 Delivered",$P37="✓"),"✅ Done",IF($Q37="","",IF($Q37<TODAY(),"🔴 Overdue",IF($Q37-TODAY()<=DueSoonDays,"🟠 Due soon","🟢 On track")))))
B38: =IF($C38="","",ROW()-7) | I38: =IF($H38="","",HYPERLINK($H38,"🔗")) | L38: =IF($K38="","",IF($J38="",0,$J38)-$K38) | M38: =IF(OR($K38="",$J38="",$J38=0),"",$K38/$J38) | R38: =IF($Q38="","",$Q38-TODAY()) | S38: =IF($C38="","",IF(OR($N38="📦 Delivered",$P38="✓"),"✅ Done",IF($Q38="","",IF($Q38<TODAY(),"🔴 Overdue",IF($Q38-TODAY()<=DueSoonDays,"🟠 Due soon","🟢 On track")))))
B39: =IF($C39="","",ROW()-7) | I39: =IF($H39="","",HYPERLINK($H39,"🔗")) | L39: =IF($K39="","",IF($J39="",0,$J39)-$K39) | M39: =IF(OR($K39="",$J39="",$J39=0),"",$K39/$J39) | R39: =IF($Q39="","",$Q39-TODAY()) | S39: =IF($C39="","",IF(OR($N39="📦 Delivered",$P39="✓"),"✅ Done",IF($Q39="","",IF($Q39<TODAY(),"🔴 Overdue",IF($Q39-TODAY()<=DueSoonDays,"🟠 Due soon","🟢 On track")))))
B40: =IF($C40="","",ROW()-7) | I40: =IF($H40="","",HYPERLINK($H40,"🔗")) | L40: =IF($K40="","",IF($J40="",0,$J40)-$K40) | M40: =IF(OR($K40="",$J40="",$J40=0),"",$K40/$J40) | R40: =IF($Q40="","",$Q40-TODAY()) | S40: =IF($C40="","",IF(OR($N40="📦 Delivered",$P40="✓"),"✅ Done",IF($Q40="","",IF($Q40<TODAY(),"🔴 Overdue",IF($Q40-TODAY()<=DueSoonDays,"🟠 Due soon","🟢 On track")))))
B41: =IF($C41="","",ROW()-7) | I41: =IF($H41="","",HYPERLINK($H41,"🔗")) | L41: =IF($K41="","",IF($J41="",0,$J41)-$K41) | M41: =IF(OR($K41="",$J41="",$J41=0),"",$K41/$J41) | R41: =IF($Q41="","",$Q41-TODAY()) | S41: =IF($C41="","",IF(OR($N41="📦 Delivered",$P41="✓"),"✅ Done",IF($Q41="","",IF($Q41<TODAY(),"🔴 Overdue",IF($Q41-TODAY()<=DueSoonDays,"🟠 Due soon","🟢 On track")))))
B42: =IF($C42="","",ROW()-7) | I42: =IF($H42="","",HYPERLINK($H42,"🔗")) | L42: =IF($K42="","",IF($J42="",0,$J42)-$K42) | M42: =IF(OR($K42="",$J42="",$J42=0),"",$K42/$J42) | R42: =IF($Q42="","",$Q42-TODAY()) | S42: =IF($C42="","",IF(OR($N42="📦 Delivered",$P42="✓"),"✅ Done",IF($Q42="","",IF($Q42<TODAY(),"🔴 Overdue",IF($Q42-TODAY()<=DueSoonDays,"🟠 Due soon","🟢 On track")))))
B43: =IF($C43="","",ROW()-7) | I43: =IF($H43="","",HYPERLINK($H43,"🔗")) | L43: =IF($K43="","",IF($J43="",0,$J43)-$K43) | M43: =IF(OR($K43="",$J43="",$J43=0),"",$K43/$J43) | R43: =IF($Q43="","",$Q43-TODAY()) | S43: =IF($C43="","",IF(OR($N43="📦 Delivered",$P43="✓"),"✅ Done",IF($Q43="","",IF($Q43<TODAY(),"🔴 Overdue",IF($Q43-TODAY()<=DueSoonDays,"🟠 Due soon","🟢 On track")))))
...

Sheet 💰 Budget
B2: 💰 Christmas Budget
B3: Plan it, watch it, and get told the moment you are about to overspend. | I3: 🏠 Back to Dashboard
B7: 💰 MONEY OVERVIEW
B8: TOTAL PLANNED BUDGET | D8: SPENT SO FAR | F8: STILL TO SPEND | H8: BUDGET USED | J8: ⚠️ BUDGET ALERT
B9: =Currency&TEXT(SUM($C$15:$C$24),"#,##0") -> $1,500 | D9: =Currency&TEXT(SUM($F$15:$F$24),"#,##0") -> $1,206 | F9: =Currency&TEXT(SUM($C$15:$C$24)-SUM($F$15:$F$24),"#,##0") -> $294 | H9: =IFERROR(SUM($F$15:$F$24)/SUM($C$15:$C$24),0) -> 0.80382667 | J9: =IF(SUM($C$15:$C$24)<=0,"📝 Add your planned budgets below to switch on the alerts.",IF(SUM($F$15:$F$24)>SUM($C$15:$C$24),"🔴 Over budget by "&Currency&TEXT(SUM($F$15:$F$24)-SUM($C$15:$C$24),"#,##0.00")&" — pause the non-essentials.",IF(SUM($F$15:$F$24)/SUM($C$15:$C$24)>=AlertAt,"⚠️ You've spent "&TEXT(SUM($F$15:$F$24)/SUM($C$15:$C$24),"0%")&" of your "&EventName&" budget — "&Currency&TEXT(SUM($C$15:$C$24)-SUM($F$15:$F$24),"#,##0.00")&" left to play with.","🟢 On track — "&TEXT(SUM($F$15:$F$24)/SUM($C$15:$C$24),"0%")&" used, "&Currency&TEXT(SUM($C$15:$C$24)-SUM($F$15:$F$24),"#,##0.00")&" still to spend."))) -> 🟢 On track — 80% of the budget used, $294.26 still to spend.
B10: Budget progress | D10: =IFERROR(REPT("█",ROUND(MIN(1,SUM($F$15:$F$24)/SUM($C$15:$C$24))*34,0))&REPT("░",34-ROUND(MIN(1,SUM($F$15:$F$24)/SUM($C$15:$C$24))*34,0))&" "&TEXT(SUM($F$15:$F$24)/SUM($C$15:$C$24),"0%"),"░░░") -> ██████████████░░░░ 80%
B11: ="🎁 Gifts are "&TEXT(IFERROR($F15/SUM($F$15:$F$24),0),"0%")&" of everything" -> 🎁 Gifts are 83% of everything | D11: ="📈 Biggest spend: "&IFERROR(INDEX($B$15:$B$24,MATCH(MAX($F$15:$F$24),$F$15:$F$24,0)),"—") -> 📈 Biggest spend: 🎁 Gifts | G11: =COUNTIF($G$15:$G$24,"<0")&" over budget" -> 1 over budget | I11: ="🎯 Target "&Currency&TEXT(TotalBudget,"#,##0")&" • planned "&Currency&TEXT(SUM($C$15:$C$24),"#,##0") -> 🎯 Target $1,500 • planned $1,500
B13: 📋 BUDGET BY CATEGORY (white = you type, tinted = automatic)
B14: Category | C14: Planned budget | D14: Extra spend (type here) | E14: Pulled in automatically | F14: Total spent | G14: Remaining | H14: % used | I14: Status | J14: Progress | K14: Notes
B15: 🎁 Gifts | C15: 850 | E15: =SUM('🎁 Gift Tracker'!$K$8:$K$67)+SUMIFS('🛍️ Shopping List'!$K$8:$K$52,'🛍️ Shopping List'!$D$8:$D$52,"Gifts") -> 1003.95 | F15: =$D15+$E15 -> 1003.95 | G15: =$C15-$F15 -> 46.05 | H15: =IF($C15=0,"",$F15/$C15) -> 0.95614286 | I15: =IF($C15=0,"⚪ Set a plan",IF($F15>$C15,"🔴 Over budget",IF($F15/$C15>=AlertAt,"🟠 Nearly there",IF($F15=0,"⚪ Not started","🟢 On track")))) -> 🟠 Nearly there | J15: =IF($C15=0,"—",REPT("█",ROUND(MIN(1,IFERROR($F15/$C15,0))*12,0))&REPT("░",12-ROUND(MIN(1,IFERROR($F15/$C15,0))*12,0))&" "&TEXT(IFERROR($F15/$C15,0),"0%")) -> ███████████░ 96%
B16: 🧦 Stocking stuffers | C16: 140 | E16: =SUMIFS('🛍️ Shopping List'!$K$8:$K$52,'🛍️ Shopping List'!$D$8:$D$52,"Stockings") -> 15.8 | F16: =$D16+$E16 -> 15.8 | G16: =$C16-$F16 -> 104.2 | H16: =IF($C16=0,"",$F16/$C16) -> 0.13166667 | I16: =IF($C16=0,"⚪ Set a plan",IF($F16>$C16,"🔴 Over budget",IF($F16/$C16>=AlertAt,"🟠 Nearly there",IF($F16=0,"⚪ Not started","🟢 On track")))) -> 🟢 On track | J16: =IF($C16=0,"—",REPT("█",ROUND(MIN(1,IFERROR($F16/$C16,0))*12,0))&REPT("░",12-ROUND(MIN(1,IFERROR($F16/$C16,0))*12,0))&" "&TEXT(IFERROR($F16/$C16,0),"0%")) -> ██░░░░░░░░░░ 13%
B17: 🎀 Wrapping & packaging | C17: 55 | E17: =SUMIFS('🛍️ Shopping List'!$K$8:$K$52,'🛍️ Shopping List'!$D$8:$D$52,"Wrapping") -> 24.3 | F17: =$D17+$E17 -> 24.3 | G17: =$C17-$F17 -> 25.7 | H17: =IF($C17=0,"",$F17/$C17) -> 0.486 | I17: =IF($C17=0,"⚪ Set a plan",IF($F17>$C17,"🔴 Over budget",IF($F17/$C17>=AlertAt,"🟠 Nearly there",IF($F17=0,"⚪ Not started","🟢 On track")))) -> 🟢 On track | J17: =IF($C17=0,"—",REPT("█",ROUND(MIN(1,IFERROR($F17/$C17,0))*12,0))&REPT("░",12-ROUND(MIN(1,IFERROR($F17/$C17,0))*12,0))&" "&TEXT(IFERROR($F17/$C17,0),"0%")) -> ██████░░░░░░ 49%
B18: 💌 Cards & postage | C18: 40 | E18: =SUMIFS('🛍️ Shopping List'!$K$8:$K$52,'🛍️ Shopping List'!$D$8:$D$52,"Cards")+SUMIFS('🛍️ Shopping List'!$K$8:$K$52,'🛍️ Shopping List'!$D$8:$D$52,"Postage") -> 33.9 | F18: =$D18+$E18 -> 33.9 | G18: =$C18-$F18 -> 1.1 | H18: =IF($C18=0,"",$F18/$C18) -> 0.96857143 | I18: =IF($C18=0,"⚪ Set a plan",IF($F18>$C18,"🔴 Over budget",IF($F18/$C18>=AlertAt,"🟠 Nearly there",IF($F18=0,"⚪ Not started","🟢 On track")))) -> 🟠 Nearly there | J18: =IF($C18=0,"—",REPT("█",ROUND(MIN(1,IFERROR($F18/$C18,0))*12,0))&REPT("░",12-ROUND(MIN(1,IFERROR($F18/$C18,0))*12,0))&" "&TEXT(IFERROR($F18/$C18,0),"0%")) -> ████████████ 97%
B19: 🍝 Food & drink | C19: 200 | E19: =SUMIFS('🛍️ Shopping List'!$K$8:$K$52,'🛍️ Shopping List'!$D$8:$D$52,"Food") -> 22.5 | F19: =$D19+$E19 -> 22.5 | G19: =$C19-$F19 -> 107.5 | H19: =IF($C19=0,"",$F19/$C19) -> 0.17307692 | I19: =IF($C19=0,"⚪ Set a plan",IF($F19>$C19,"🔴 Over budget",IF($F19/$C19>=AlertAt,"🟠 Nearly there",IF($F19=0,"⚪ Not started","🟢 On track")))) -> 🟢 On track | J19: =IF($C19=0,"—",REPT("█",ROUND(MIN(1,IFERROR($F19/$C19,0))*12,0))&REPT("░",12-ROUND(MIN(1,IFERROR($F19/$C19,0))*12,0))&" "&TEXT(IFERROR($F19/$C19,0),"0%")) -> ██░░░░░░░░░░ 17%
B20: 🍪 Baking & treats | C20: 35 | E20: =SUMIFS('🛍️ Shopping List'!$K$8:$K$52,'🛍️ Shopping List'!$D$8:$D$52,"Baking") -> 10.9 | F20: =$D20+$E20 -> 10.9 | G20: =$C20-$F20 -> 14.1 | H20: =IF($C20=0,"",$F20/$C20) -> 0.436 | I20: =IF($C20=0,"⚪ Set a plan",IF($F20>$C20,"🔴 Over budget",IF($F20/$C20>=AlertAt,"🟠 Nearly there",IF($F20=0,"⚪ Not started","🟢 On track")))) -> 🟢 On track | J20: =IF($C20=0,"—",REPT("█",ROUND(MIN(1,IFERROR($F20/$C20,0))*12,0))&REPT("░",12-ROUND(MIN(1,IFERROR($F20/$C20,0))*12,0))&" "&TEXT(IFERROR($F20/$C20,0),"0%")) -> █████░░░░░░░ 44%
B21: 🎄 Decorations & tree | C21: 60 | E21: =SUMIFS('🛍️ Shopping List'!$K$8:$K$52,'🛍️ Shopping List'!$D$8:$D$52,"Decorations") -> 30.99 | F21: =$D21+$E21 -> 30.99 | G21: =$C21-$F21 -> 9.01 | H21: =IF($C21=0,"",$F21/$C21) -> 0.77475 | I21: =IF($C21=0,"⚪ Set a plan",IF($F21>$C21,"🔴 Over budget",IF($F21/$C21>=AlertAt,"🟠 Nearly there",IF($F21=0,"⚪ Not started","🟢 On track")))) -> 🟢 On track | J21: =IF($C21=0,"—",REPT("█",ROUND(MIN(1,IFERROR($F21/$C21,0))*12,0))&REPT("░",12-ROUND(MIN(1,IFERROR($F21/$C21,0))*12,0))&" "&TEXT(IFERROR($F21/$C21,0),"0%")) -> █████████░░░ 77%
B22: 🎉 Party & entertaining | C22: 45 | E22: =SUMIFS('🛍️ Shopping List'!$K$8:$K$52,'🛍️ Shopping List'!$D$8:$D$52,"Party Supplies") -> 0 | F22: =$D22+$E22 -> 0 | G22: =$C22-$F22 -> 25 | H22: =IF($C22=0,"",$F22/$C22) -> 0 | I22: =IF($C22=0,"⚪ Set a plan",IF($F22>$C22,"🔴 Over budget",IF($F22/$C22>=AlertAt,"🟠 Nearly there",IF($F22=0,"⚪ Not started","🟢 On track")))) -> ⚪ Not started | J22: =IF($C22=0,"—",REPT("█",ROUND(MIN(1,IFERROR($F22/$C22,0))*12,0))&REPT("░",12-ROUND(MIN(1,IFERROR($F22/$C22,0))*12,0))&" "&TEXT(IFERROR($F22/$C22,0),"0%")) -> ░░░░░░░░░░░░ 0%
B23: 🚗 Travel | C23: 35 | D23: 38.4 | E23: =SUMIFS('🛍️ Shopping List'!$K$8:$K$52,'🛍️ Shopping List'!$D$8:$D$52,"Travel") -> 0 | F23: =$D23+$E23 -> 38.4 | G23: =$C23-$F23 -> -38.4 | H23: =IF($C23=0,"",$F23/$C23) | I23: =IF($C23=0,"⚪ Set a plan",IF($F23>$C23,"🔴 Over budget",IF($F23/$C23>=AlertAt,"🟠 Nearly there",IF($F23=0,"⚪ Not started","🟢 On track")))) -> ⚪ Set a plan | J23: =IF($C23=0,"—",REPT("█",ROUND(MIN(1,IFERROR($F23/$C23,0))*12,0))&REPT("░",12-ROUND(MIN(1,IFERROR($F23/$C23,0))*12,0))&" "&TEXT(IFERROR($F23/$C23,0),"0%")) -> —
B24: ❤ Charity & other | C24: 40 | E24: =SUMIFS('🛍️ Shopping List'!$K$8:$K$52,'🛍️ Shopping List'!$D$8:$D$52,"Charity")+SUMIFS('🛍️ Shopping List'!$K$8:$K$52,'🛍️ Shopping List'!$D$8:$D$52,"Other") -> 25 | F24: =$D24+$E24 -> 25 | G24: =$C24-$F24 -> 0 | H24: =IF($C24=0,"",$F24/$C24) -> 1 | I24: =IF($C24=0,"⚪ Set a plan",IF($F24>$C24,"🔴 Over budget",IF($F24/$C24>=AlertAt,"🟠 Nearly there",IF($F24=0,"⚪ Not started","🟢 On track")))) -> 🟠 Nearly there | J24: =IF($C24=0,"—",REPT("█",ROUND(MIN(1,IFERROR($F24/$C24,0))*12,0))&REPT("░",12-ROUND(MIN(1,IFERROR($F24/$C24,0))*12,0))&" "&TEXT(IFERROR($F24/$C24,0),"0%")) -> ████████████ 100%
B25: TOTAL | C25: =SUM($C$15:$C$24) -> 1500 | D25: =SUM($D$15:$D$24) -> 38.4 | E25: =SUM($E$15:$E$24) -> 1167.34 | F25: =SUM($F$15:$F$24) -> 1205.74 | G25: =SUM($G$15:$G$24) -> 294.26 | H25: =IFERROR(SUM($F$15:$F$24)/SUM($C$15:$C$24),"") -> 0.80382667 | I25: =IF(SUM($C$15:$C$24)=0,"—","Budget "&TEXT(SUM($F$15:$F$24)/SUM($C$15:$C$24),"0%")&" used • "&Currency&TEXT(SUM($C$15:$C$24)-SUM($F$15:$F$24),"#,##0")&" left") -> Budget 80% used • $294 left
B27: 📊 BUDGET vs ACTUAL
B44: 💡 How this tab works
B45: • “Planned budget” and “Extra spend” are the only two columns you type in. • “Pulled in automatically” adds up the money from the 🎁 Gift Tracker, 🛍️ Shopping List, 🧦 Stockings and 💌 Card postage — so this total is always honest. • Set the warning level in ⚙️ Setup (“Warn me when spending reaches”). At that point the alert card, the status column and the dashboard all change colour. • Add your own category? Insert a row above the TOTAL row and everything (including the charts) picks it up.
B47: 🏠 Home | D47: 🎁 Gifts | F47: ▶ 💰 Budget | H47: 🛍️ Shop | J47: ⚙️ Setup
B48: 📖 Help
B50: Ultimate Christmas Gift Tracker v1.0 • Christmas • Birthdays • Holidays • Every Special Occasion

Sheet 🛍️ Shopping List
B2: 🛍️ Shopping List
B3: Wrapping, cards, baking, decorations, party bits — the stuff that quietly eats the budget. | K3: 🏠 Back to Dashboard
B5: ="📝 Items: "&'_Data'!$AF$21 -> 📝 Items: 24 | E5: ="✅ Bought: "&'_Data'!$AF$22 -> ✅ Bought: 13 | G5: ="💰 Spent: "&Currency&TEXT('_Data'!$AF$23,"#,##0") -> 💰 Spent: $163 | I5: ="💵 Estimated: "&Currency&TEXT(SUM('🛍️ Shopping List'!$H$8:$H$52),"#,##0") -> 💵 Estimated: $351 | K5: ="📊 Progress: "&TEXT(IFERROR('_Data'!$AF$22/'_Data'!$AF$21,0),"0%") -> 📊 Progress: 54%
B7: # | C7: Item | D7: Category | E7: Store | F7: Qty | G7: Unit cost | H7: Total (auto) | I7: Bought | J7: Actual cost | K7: In budget (auto) | L7: Link | M7: Notes
B8: =IF($C8="","",ROW()-7) -> 1 | C8: Wrapping paper - 3 roll pack | D8: Wrapping | E8: Target | F8: 3 | G8: 4 | H8: =IF($G8="","",IF($F8="",1,$F8)*$G8) -> 12 | I8: ✓ | J8: 11.5 | K8: =IF($I8="✓",IF($J8<>"",$J8,IF($H8<>"",$H8,0)),0) -> 11.5 | M8: Gold foil design
B9: =IF($C9="","",ROW()-7) -> 2 | C9: Ribbon - red & gold | D9: Wrapping | E9: Amazon | F9: 2 | G9: 3.5 | H9: =IF($G9="","",IF($F9="",1,$F9)*$G9) -> 7 | I9: ✓ | J9: 6.8 | K9: =IF($I9="✓",IF($J9<>"",$J9,IF($H9<>"",$H9,0)),0) -> 6.8
B10: =IF($C10="","",ROW()-7) -> 3 | C10: Gift tags (pack of 50) | D10: Wrapping | E10: Etsy | F10: 1 | G10: 6 | H10: =IF($G10="","",IF($F10="",1,$F10)*$G10) -> 6 | I10: ✓ | J10: 6 | K10: =IF($I10="✓",IF($J10<>"",$J10,IF($H10<>"",$H10,0)),0) -> 6 | M10: Hand-lettered
B11: =IF($C11="","",ROW()-7) -> 4 | C11: Sticky tape & scissors | D11: Wrapping | E11: Target | F11: 1 | G11: 5 | H11: =IF($G11="","",IF($F11="",1,$F11)*$G11) -> 5 | K11: =IF($I11="✓",IF($J11<>"",$J11,IF($H11<>"",$H11,0)),0) -> 0
B12: =IF($C12="","",ROW()-7) -> 5 | C12: Tissue paper bundle | D12: Wrapping | E12: Target | F12: 1 | G12: 3 | H12: =IF($G12="","",IF($F12="",1,$F12)*$G12) -> 3 | K12: =IF($I12="✓",IF($J12<>"",$J12,IF($H12<>"",$H12,0)),0) -> 0
B13: =IF($C13="","",ROW()-7) -> 6 | C13: Christmas cards (box of 30) | D13: Cards | E13: Amazon | F13: 1 | G13: 14 | H13: =IF($G13="","",IF($F13="",1,$F13)*$G13) -> 14 | I13: ✓ | J13: 13.5 | K13: =IF($I13="✓",IF($J13<>"",$J13,IF($H13<>"",$H13,0)),0) -> 13.5
B14: =IF($C14="","",ROW()-7) -> 7 | C14: Stamps - book of 30 | D14: Postage | E14: Post office | F14: 1 | G14: 20.4 | H14: =IF($G14="","",IF($F14="",1,$F14)*$G14) -> 20.4 | I14: ✓ | J14: 20.4 | K14: =IF($I14="✓",IF($J14<>"",$J14,IF($H14<>"",$H14,0)),0) -> 20.4
B15: =IF($C15="","",ROW()-7) -> 8 | C15: Thank-you notes | D15: Cards | E15: Etsy | F15: 1 | G15: 8 | H15: =IF($G15="","",IF($F15="",1,$F15)*$G15) -> 8 | K15: =IF($I15="✓",IF($J15<>"",$J15,IF($H15<>"",$H15,0)),0) -> 0 | M15: For January
B16: =IF($C16="","",ROW()-7) -> 9 | C16: Plain flour | D16: Baking | E16: Grocery store | F16: 2 | G16: 1.8 | H16: =IF($G16="","",IF($F16="",1,$F16)*$G16) -> 3.6 | I16: ✓ | J16: 3.4 | K16: =IF($I16="✓",IF($J16<>"",$J16,IF($H16<>"",$H16,0)),0) -> 3.4
B17: =IF($C17="","",ROW()-7) -> 10 | C17: Cookie cutters set | D17: Baking | E17: Amazon | F17: 1 | G17: 8 | H17: =IF($G17="","",IF($F17="",1,$F17)*$G17) -> 8 | I17: ✓ | J17: 7.5 | K17: =IF($I17="✓",IF($J17<>"",$J17,IF($H17<>"",$H17,0)),0) -> 7.5
B18: =IF($C18="","",ROW()-7) -> 11 | C18: Cake decorating sprinkles | D18: Baking | E18: Grocery store | F18: 1 | G18: 4.5 | H18: =IF($G18="","",IF($F18="",1,$F18)*$G18) -> 4.5 | K18: =IF($I18="✓",IF($J18<>"",$J18,IF($H18<>"",$H18,0)),0) -> 0
B19: =IF($C19="","",ROW()-7) -> 12 | C19: Chocolate for stockings | D19: Stockings | E19: Grocery store | F19: 4 | G19: 3.2 | H19: =IF($G19="","",IF($F19="",1,$F19)*$G19) -> 12.8 | I19: ✓ | J19: 12 | K19: =IF($I19="✓",IF($J19<>"",$J19,IF($H19<>"",$H19,0)),0) -> 12
B20: =IF($C20="","",ROW()-7) -> 13 | C20: Candy canes | D20: Stockings | E20: Grocery store | F20: 2 | G20: 2 | H20: =IF($G20="","",IF($F20="",1,$F20)*$G20) -> 4 | I20: ✓ | J20: 3.8 | K20: =IF($I20="✓",IF($J20<>"",$J20,IF($H20<>"",$H20,0)),0) -> 3.8
B21: =IF($C21="","",ROW()-7) -> 14 | C21: Christmas crackers | D21: Party Supplies | E21: Target | F21: 2 | G21: 5.5 | H21: =IF($G21="","",IF($F21="",1,$F21)*$G21) -> 11 | K21: =IF($I21="✓",IF($J21<>"",$J21,IF($H21<>"",$H21,0)),0) -> 0
B22: =IF($C22="","",ROW()-7) -> 15 | C22: Napkins & party plates | D22: Party Supplies | E22: Target | F22: 1 | G22: 7 | H22: =IF($G22="","",IF($F22="",1,$F22)*$G22) -> 7 | K22: =IF($I22="✓",IF($J22<>"",$J22,IF($H22<>"",$H22,0)),0) -> 0
B23: =IF($C23="","",ROW()-7) -> 16 | C23: Tree baubles - gold | D23: Decorations | E23: IKEA | F23: 2 | G23: 9 | H23: =IF($G23="","",IF($F23="",1,$F23)*$G23) -> 18 | I23: ✓ | J23: 16 | K23: =IF($I23="✓",IF($J23<>"",$J23,IF($H23<>"",$H23,0)),0) -> 16
B24: =IF($C24="","",ROW()-7) -> 17 | C24: Fairy lights (warm white) | D24: Decorations | E24: Amazon | F24: 1 | G24: 15 | H24: =IF($G24="","",IF($F24="",1,$F24)*$G24) -> 15 | I24: ✓ | J24: 14.99 | K24: =IF($I24="✓",IF($J24<>"",$J24,IF($H24<>"",$H24,0)),0) -> 14.99
B25: =IF($C25="","",ROW()-7) -> 18 | C25: Wreath for the front door | D25: Decorations | E25: Local market | F25: 1 | G25: 22 | H25: =IF($G25="","",IF($F25="",1,$F25)*$G25) -> 22 | K25: =IF($I25="✓",IF($J25<>"",$J25,IF($H25<>"",$H25,0)),0) -> 0
B26: =IF($C26="","",ROW()-7) -> 19 | C26: Turkey & trimmings | D26: Food | E26: Grocery store | F26: 1 | G26: 65 | H26: =IF($G26="","",IF($F26="",1,$F26)*$G26) -> 65 | K26: =IF($I26="✓",IF($J26<>"",$J26,IF($H26<>"",$H26,0)),0) -> 0 | M26: Order by 18 Dec
B27: =IF($C27="","",ROW()-7) -> 20 | C27: Sparkling cider | D27: Food | E27: Grocery store | F27: 2 | G27: 6.5 | H27: =IF($G27="","",IF($F27="",1,$F27)*$G27) -> 13 | K27: =IF($I27="✓",IF($J27<>"",$J27,IF($H27<>"",$H27,0)),0) -> 0
B28: =IF($C28="","",ROW()-7) -> 21 | C28: Chocolate selection boxes | D28: Food | E28: Grocery store | F28: 3 | G28: 8 | H28: =IF($G28="","",IF($F28="",1,$F28)*$G28) -> 24 | I28: ✓ | J28: 22.5 | K28: =IF($I28="✓",IF($J28<>"",$J28,IF($H28<>"",$H28,0)),0) -> 22.5 | M28: For neighbours & teachers
B29: =IF($C29="","",ROW()-7) -> 22 | C29: Petrol / parking for the trip | D29: Travel | E29: Shell | F29: 1 | G29: 38.4 | H29: =IF($G29="","",IF($F29="",1,$F29)*$G29) -> 38.4 | K29: =IF($I29="✓",IF($J29<>"",$J29,IF($H29<>"",$H29,0)),0) -> 0
B30: =IF($C30="","",ROW()-7) -> 23 | C30: Food bank donation | D30: Charity | E30: Local charity | F30: 1 | G30: 25 | H30: =IF($G30="","",IF($F30="",1,$F30)*$G30) -> 25 | I30: ✓ | J30: 25 | K30: =IF($I30="✓",IF($J30<>"",$J30,IF($H30<>"",$H30,0)),0) -> 25
B31: =IF($C31="","",ROW()-7) -> 24 | C31: Gift bags (spares) | D31: Other | E31: Target | F31: 1 | G31: 4 | H31: =IF($G31="","",IF($F31="",1,$F31)*$G31) -> 4 | K31: =IF($I31="✓",IF($J31<>"",$J31,IF($H31<>"",$H31,0)),0) -> 0
B32: =IF($C32="","",ROW()-7) | H32: =IF($G32="","",IF($F32="",1,$F32)*$G32) | K32: =IF($I32="✓",IF($J32<>"",$J32,IF($H32<>"",$H32,0)),0) -> 0
B33: =IF($C33="","",ROW()-7) | H33: =IF($G33="","",IF($F33="",1,$F33)*$G33) | K33: =IF($I33="✓",IF($J33<>"",$J33,IF($H33<>"",$H33,0)),0) -> 0
B34: =IF($C34="","",ROW()-7) | H34: =IF($G34="","",IF($F34="",1,$F34)*$G34) | K34: =IF($I34="✓",IF($J34<>"",$J34,IF($H34<>"",$H34,0)),0) -> 0
B35: =IF($C35="","",ROW()-7) | H35: =IF($G35="","",IF($F35="",1,$F35)*$G35) | K35: =IF($I35="✓",IF($J35<>"",$J35,IF($H35<>"",$H35,0)),0) -> 0
B36: =IF($C36="","",ROW()-7) | H36: =IF($G36="","",IF($F36="",1,$F36)*$G36) | K36: =IF($I36="✓",IF($J36<>"",$J36,IF($H36<>"",$H36,0)),0) -> 0
B37: =IF($C37="","",ROW()-7) | H37: =IF($G37="","",IF($F37="",1,$F37)*$G37) | K37: =IF($I37="✓",IF($J37<>"",$J37,IF($H37<>"",$H37,0)),0) -> 0
B38: =IF($C38="","",ROW()-7) | H38: =IF($G38="","",IF($F38="",1,$F38)*$G38) | K38: =IF($I38="✓",IF($J38<>"",$J38,IF($H38<>"",$H38,0)),0) -> 0
B39: =IF($C39="","",ROW()-7) | H39: =IF($G39="","",IF($F39="",1,$F39)*$G39) | K39: =IF($I39="✓",IF($J39<>"",$J39,IF($H39<>"",$H39,0)),0) -> 0
B40: =IF($C40="","",ROW()-7) | H40: =IF($G40="","",IF($F40="",1,$F40)*$G40) | K40: =IF($I40="✓",IF($J40<>"",$J40,IF($H40<>"",$H40,0)),0) -> 0
B41: =IF($C41="","",ROW()-7) | H41: =IF($G41="","",IF($F41="",1,$F41)*$G41) | K41: =IF($I41="✓",IF($J41<>"",$J41,IF($H41<>"",$H41,0)),0) -> 0
B42: =IF($C42="","",ROW()-7) | H42: =IF($G42="","",IF($F42="",1,$F42)*$G42) | K42: =IF($I42="✓",IF($J42<>"",$J42,IF($H42<>"",$H42,0)),0) -> 0
B43: =IF($C43="","",ROW()-7) | H43: =IF($G43="","",IF($F43="",1,$F43)*$G43) | K43: =IF($I43="✓",IF($J43<>"",$J43,IF($H43<>"",$H43,0)),0) -> 0
...

Sheet ⚙️ Setup
B2: ⚙️ Setup — make it yours
B3: Change these settings once and every tab, countdown, alert and dropdown follows automatically. | H3: 🏠 Back to Dashboard
B5: 🎄 YOUR EVENT
B6: Event name | C6: Christmas | D6: Christmas, 40th Birthday, Baby Shower… it appears on the dashboard and in every message.
B7: Event date | C7: 46381 | D7: The countdown, the deadline alerts and the to-do dates all work from this one cell.
B8: Days to go (auto) | C8: =IF($C$7="","",$C$7-TODAY()) -> 104 | D8: Recalculates every day by itself.
B9: Event year (auto) | C9: =IF($C$7="","",YEAR($C$7)) -> 2026
B10: Weeks to go (auto) | C10: =IF($C$7="","",MAX(0,ROUNDUP(($C$7-TODAY())/7,0))) -> 15 | D10: Rough planning guide: gifts by week 4, cards by week 3, wrapping by week 1.
B11: Countdown message (auto) | C11: =IF($C$7="","👉 Enter your event date to start the countdown",IF($C$7-TODAY()>1,"⏳ "&($C$7-TODAY())&" days until "&$C$6&" • "&TEXT($C$7,"dddd d mmmm yyyy"),IF($C$7-TODAY()=1,"⏳ Tomorrow is "&$C$6&"! 🎁",IF($C$7=TODAY(),"🎉 It's "&$C$6&" today! 🎄","🎄 "&$C$6&" "&TEXT($C$7,"yyyy")&" has been and gone — change the date above to plan the next one.")))) -> ⏳ 104 Days Until Christmas 🎁
B13: ♻️ REUSE IT FOR ANY OCCASION (birthdays, Valentine's, Mother's Day, weddings, Secret Santa…)
B14: Pick an occasion | C14: Christmas | D14: Just a helper — it suggests a name and a date for you.
B15: Suggested event name (auto) | C15: =IF($C$14="","",$C$14) -> Christmas
B16: Suggested date (auto) | C16: =IF('_Data'!$E$2="","",DATE(YEAR(TODAY())+IF(DATE(YEAR(TODAY()),'_Data'!$E$2,'_Data'!$F$2)<TODAY(),1,0),'_Data'!$E$2,'_Data'!$F$2)) -> 46381 | D16: Copy the two suggestions above into Event name / Event date and the whole workbook switches occasion.
B17: 💡 The workbook is date-driven, not year-driven: nothing is hard-coded to 2026, so you can keep using it every year (and for every other gift-giving occasion) just by changing the event date.
B20: 💰 MONEY, ALERTS & PRIVACY
B21: Currency symbol | C21: $ | D21: Used by every dashboard and summary readout. To show it inside the tables too: select the money columns → Home → Number format → Currency.
B22: Total budget target | C22: 1500 | D22: Your headline number for the whole event (the 💰 Budget tab breaks it down by category).
B23: Warn me when spending reaches | C23: 0.85 | D23: e.g. 85% — the dashboard and the Budget tab start shouting at this point.
B24: “Due soon” window (days) | C24: 7 | D24: Deadlines inside this many days turn orange everywhere.
B25: 🙈 Secret Mode | C25: No | D25: Yes = hiding spots on the 🎀 Wrapping and 🧦 Stockings tabs go invisible (white on white) so nobody can spoil the surprise over your shoulder.
B26: Count “Ordered” as purchased? | C26: No | D26: Yes = gifts that are ordered but not yet delivered still count as bought on the dashboard.
B28: 📋 YOUR LISTS — edit any time, every dropdown in the workbook updates itself
B29: 👪 Recipients | C29: 👥 Relationships | D29: 🏷️ Gift categories | E29: 🏬 Stores | F29: 🛒 Shopping categories | G29: 🙈 Hiding spots | H29: 📋 To-do categories | I29: 🧦 Stocking owners | J29: 🍬 Stocking items
B30: Mum | C30: Mum | D30: Clothing | E30: Amazon | F30: Gifts | G30: Top shelf in closet | H30: Gifts | I30: Emma | J30: Candy
B31: Dad | C31: Dad | D31: Beauty | E31: Etsy | F31: Stockings | G31: Under the bed | H31: Wrapping | I31: Oliver | J31: Chocolate
B32: Grandma Rose | C32: Grandma | D32: Electronics | E32: Target | F32: Wrapping | G32: Garage shelf | H32: Cards | I32: Mum | J32: Socks
B33: Grandpa Joe | C33: Grandpa | D33: Toys | E33: Walmart | F33: Food | G33: Suitcase in the attic | H33: Food | I33: Dad | J33: Beauty
B34: Sister Emily | C34: Sister | D34: Books | E34: John Lewis | F34: Baking | G34: Back of the pantry | H34: Decorations | J34: Hair clips
B35: Brother Jack | C35: Brother | D35: Home | E35: Tesco | F35: Decorations | G35: Linen closet | H35: Travel | J35: Stationery
B36: Niece Sophie | C36: Partner | D36: Food & Drink | E36: Argos | F36: Cards | G36: Shoe box in wardrobe | H36: Party | J36: Small toy
B37: Nephew Leo | C37: Son | D37: Gift Card | E37: ASOS | F37: Postage | G37: Behind the books | H37: Family | J37: Gift card
B38: Alex (partner) | C38: Daughter | D38: Handmade | E38: Sephora | F38: Party Supplies | G38: Under the stairs box | H38: Admin | J38: Snacks
B39: Maya (best friend) | C39: Niece | D39: Jewellery | E39: Best Buy | F39: Travel | G39: Car boot / trunk | H39: Other | J39: Novelty
B40: Cousin Dan | C40: Nephew | D40: Games | E40: IKEA | F40: Charity | G40: Decoration box | J40: Other
B41: Aunt Carol | C41: Cousin | D41: Sports | E41: M&S | F41: Other | G41: At work / office
B42: Uncle Bill | C42: Aunt | D42: Music | E42: Local Bookshop | G42: Friend's house
B43: Secret Santa | C43: Uncle | D43: Kids | E43: Not On The High Street
C44: Friend | D44: Pets | E44: Handmade by me
C45: Colleague | D45: Experience | E45: Other
C46: Neighbour | D46: Other
...

Sheet 📖 Start Here
C10: 📖 START HERE
C11: your 3-minute tour of the Christmas Gift Tracker
B22: ⚡ THREE-MINUTE QUICK START
B24: 1 | C24: Set your event.
C25: ⚙️ Setup → Event name and Event date. Every countdown, deadline and key date in the workbook is calculated from that one date, so nothing is locked to a year.
B26: 2 | C26: Make the money yours.
C27: On the same tab pick your currency symbol, your total budget target, the % that triggers the budget warning, and how many days counts as “due soon”.
B28: 3 | C28: Type your people.
C29: ⚙️ Setup → Your lists: recipients, relationships, stores, categories, hiding spots. Every dropdown in every tab reads from these lists and updates instantly.
B30: 4 | C30: Add your gifts.
C31: 🎁 Gift Tracker: one row per present. Use the Status dropdown as your pipeline (💡 idea → 📦 delivered). The tinted columns (difference, % of budget, days left, alert) fill themselves in.
B32: 5 | C32: Plan the money.
C33: 💰 Budget: type a planned amount per category. The “pulled in automatically” column adds up the real money from the gift, shopping, stocking and postage columns.
B34: 6 | C34: Enjoy the dashboard.
C35: 🎄 Dashboard needs no typing at all. It recalculates the moment you change anything anywhere else.
B37: 🗂️ WHAT EVERY TAB DOES
C39: Tab | F39: What it's for | I39: You type | K39: Automatic
C40: 🎄 Dashboard | F40: The command centre: countdown, money, gift progress, bars, 4 charts, deadlines. | I40: nothing | K40: everything
C41: 🎁 Gift Tracker | F41: One row per present — the heart of the workbook. | I41: the gift | K41: difference, %, alerts
C42: 💰 Budget | F42: Planned vs actual per category with a warning level you choose. | I42: planned amounts | K42: actuals + charts
C43: ⚙️ Setup | F43: Event, money settings, and every editable list in the workbook. | I43: settings + lists | K43: suggestions
C44: 📖 Start Here | F44: This page: tour, legend, automation list, Google Sheets help, FAQ. | I44: — | K44: —
C45: _Data (hidden) | F45: The engine room: every dashboard number, chart series and deadline is computed here. | I45: never | K45: all the maths
B47: 🎨 COLOUR & SYMBOL LEGEND
C49: Looks like | E49: Means | H49: Where you'll see it
C50: 🔴 red | E50: Overdue, over budget, or running late | H50: deadline columns, budget status, order alerts, to-do status
C51: 🟠 amber | E51: Due soon (inside your Setup window) or nearly at the budget limit | H51: deadlines, % used, budget status
C52: 🟢 green | E52: On track / complete / ticked off | H52: tick boxes, statuses, to-do list, wrapped rows
C53: 🔵 blue | E53: Ordered / on the way | H53: gift status, order status
C54: 🎀 gold | E54: Wrapped, or a priority must-have | H54: gift status, wrapping tab, wish list
