Workbook
Name BusinessName: '⚙️ Lists & Settings'!$C$6
Name Categories: OFFSET('⚙️ Lists & Settings'!$C$23,0,0,MAX(1,COUNTA('⚙️ Lists & Settings'!$C$23:$C$42)),1)
Name Currency: '⚙️ Lists & Settings'!$C$10
Name EventList: OFFSET('🏪 Craft Fairs'!$B$8,0,0,MAX(1,COUNTA('🏪 Craft Fairs'!$B$8:$B$31)),1)
Name HourlyWage: '⚙️ Lists & Settings'!$C$12
Name Message: '⚙️ Lists & Settings'!$C$7
Name OverheadPct: '⚙️ Lists & Settings'!$C$13
Name PaymentMethods: OFFSET('⚙️ Lists & Settings'!$D$23,0,0,MAX(1,COUNTA('⚙️ Lists & Settings'!$D$23:$D$42)),1)
Name ProductsList: OFFSET('🧶 Product Catalog'!$C$8,0,0,MAX(1,COUNTA('🧶 Product Catalog'!$C$8:$C$31)),1)
Name ReportYear: '⚙️ Lists & Settings'!$C$11
Name Suppliers: OFFSET('⚙️ Lists & Settings'!$G$23,0,0,MAX(1,COUNTA('⚙️ Lists & Settings'!$G$23:$G$42)),1)
Name TargetMargin: '⚙️ Lists & Settings'!$C$14
Name Tick: '⚙️ Lists & Settings'!$C$47:$C$48
Name Units: OFFSET('⚙️ Lists & Settings'!$F$23,0,0,MAX(1,COUNTA('⚙️ Lists & Settings'!$F$23:$F$42)),1)
Name YarnWeights: OFFSET('⚙️ Lists & Settings'!$E$23,0,0,MAX(1,COUNTA('⚙️ Lists & Settings'!$E$23:$E$42)),1)

Sheet _Data
H1: Month | I1: Revenue | J1: COGS | K1: Event fees | L1: Net | M1: Units | N1: Markets | O1: Sales lines | P1: Method | Q1: Taken | S1: Category | T1: Spent | V1: Product | W1: Units | X1: Revenue | Y1: In stock | Z1: Margin adj | AA1: Slow adj | AB1: Profit | AC1: Event | AD1: Sales | AE1: Net | AF1: Units | AG1: Upcoming | AH1: KPI | AI1: Value | AK1: Prod seq | AL1: Prod row | AN1: Mat seq | AO1: Mat row
H2: January | I2: =SUMIFS('💰 Sales Log'!$H$8:$H$67,'💰 Sales Log'!$B$8:$B$67,">="&DATE(ReportYear,1,1),'💰 Sales Log'!$B$8:$B$67,"<"&EDATE(DATE(ReportYear,1,1),1)) -> 0 | J2: =SUMIFS('💰 Sales Log'!$M$8:$M$67,'💰 Sales Log'!$B$8:$B$67,">="&DATE(ReportYear,1,1),'💰 Sales Log'!$B$8:$B$67,"<"&EDATE(DATE(ReportYear,1,1),1)) -> 0 | K2: =SUMIFS('🏪 Craft Fairs'!$K$8:$K$31,'🏪 Craft Fairs'!$C$8:$C$31,">="&DATE(ReportYear,1,1),'🏪 Craft Fairs'!$C$8:$C$31,"<"&EDATE(DATE(ReportYear,1,1),1)) -> 0 | L2: =$I2-$J2-$K2 -> 0 | M2: =SUMIFS('💰 Sales Log'!$E$8:$E$67,'💰 Sales Log'!$B$8:$B$67,">="&DATE(ReportYear,1,1),'💰 Sales Log'!$B$8:$B$67,"<"&EDATE(DATE(ReportYear,1,1),1)) -> 0 | N2: =COUNTIFS('🏪 Craft Fairs'!$C$8:$C$31,">="&DATE(ReportYear,1,1),'🏪 Craft Fairs'!$C$8:$C$31,"<"&EDATE(DATE(ReportYear,1,1),1)) -> 0 | O2: =COUNTIFS('💰 Sales Log'!$B$8:$B$67,">="&DATE(ReportYear,1,1),'💰 Sales Log'!$B$8:$B$67,"<"&EDATE(DATE(ReportYear,1,1),1)) -> 0 | P2: Cash | Q2: =SUMIFS('💰 Sales Log'!$H$8:$H$67,'💰 Sales Log'!$I$8:$I$67,$P2) -> 0 | S2: Booth fees | T2: =SUM('🏪 Craft Fairs'!$F$8:$F$31) -> 0 | V2: =IF('🧶 Product Catalog'!$C$8="","",'🧶 Product Catalog'!$C$8) | W2: =IF($V2="",0,SUMIFS('💰 Sales Log'!$E$8:$E$67,'💰 Sales Log'!$D$8:$D$67,$V2)) -> 0 | X2: =IF($V2="",0,SUMIFS('💰 Sales Log'!$H$8:$H$67,'💰 Sales Log'!$D$8:$D$67,$V2)) -> 0 | Y2: =IF($V2="","",'🧶 Product Catalog'!$M$8) | Z2: =IF($W2>0,'🧶 Product Catalog'!$K$8,0) -> 0 | AA2: =IF($V2="","",$W2) | AB2: =IFERROR(ROUND($W2*'🧶 Product Catalog'!$J$8,2),0) -> 0 | AC2: =IF('🏪 Craft Fairs'!$B$8="","",'🏪 Craft Fairs'!$B$8) | AD2: =IF($AC2="","",'🏪 Craft Fairs'!$N$8) | AE2: =IF($AC2="","",'🏪 Craft Fairs'!$P$8) | AF2: =IF($AC2="","",'🏪 Craft Fairs'!$M$8) | AG2: =IF(AND('🏪 Craft Fairs'!$C$8<>"",'🏪 Craft Fairs'!$C$8>=TODAY()),'🏪 Craft Fairs'!$C$8,"") | AH2: Gross sales (all time) | AI2: =SUM($I$2:$I$13) -> 0 | AK2: =IF(OR('🧶 Product Catalog'!$O$8="🟠 Low stock",'🧶 Product Catalog'!$O$8="🔴 Out of stock"),1,"") | AL2: 8
H3: February | I3: =SUMIFS('💰 Sales Log'!$H$8:$H$67,'💰 Sales Log'!$B$8:$B$67,">="&DATE(ReportYear,2,1),'💰 Sales Log'!$B$8:$B$67,"<"&EDATE(DATE(ReportYear,2,1),1)) -> 0 | J3: =SUMIFS('💰 Sales Log'!$M$8:$M$67,'💰 Sales Log'!$B$8:$B$67,">="&DATE(ReportYear,2,1),'💰 Sales Log'!$B$8:$B$67,"<"&EDATE(DATE(ReportYear,2,1),1)) -> 0 | K3: =SUMIFS('🏪 Craft Fairs'!$K$8:$K$31,'🏪 Craft Fairs'!$C$8:$C$31,">="&DATE(ReportYear,2,1),'🏪 Craft Fairs'!$C$8:$C$31,"<"&EDATE(DATE(ReportYear,2,1),1)) -> 0 | L3: =$I3-$J3-$K3 -> 0 | M3: =SUMIFS('💰 Sales Log'!$E$8:$E$67,'💰 Sales Log'!$B$8:$B$67,">="&DATE(ReportYear,2,1),'💰 Sales Log'!$B$8:$B$67,"<"&EDATE(DATE(ReportYear,2,1),1)) -> 0 | N3: =COUNTIFS('🏪 Craft Fairs'!$C$8:$C$31,">="&DATE(ReportYear,2,1),'🏪 Craft Fairs'!$C$8:$C$31,"<"&EDATE(DATE(ReportYear,2,1),1)) -> 0 | O3: =COUNTIFS('💰 Sales Log'!$B$8:$B$67,">="&DATE(ReportYear,2,1),'💰 Sales Log'!$B$8:$B$67,"<"&EDATE(DATE(ReportYear,2,1),1)) -> 0 | P3: Card | Q3: =SUMIFS('💰 Sales Log'!$H$8:$H$67,'💰 Sales Log'!$I$8:$I$67,$P3) -> 0 | S3: Travel | T3: =SUM('🏪 Craft Fairs'!$G$8:$G$31) -> 0 | V3: =IF('🧶 Product Catalog'!$C$9="","",'🧶 Product Catalog'!$C$9) | W3: =IF($V3="",0,SUMIFS('💰 Sales Log'!$E$8:$E$67,'💰 Sales Log'!$D$8:$D$67,$V3)) -> 0 | X3: =IF($V3="",0,SUMIFS('💰 Sales Log'!$H$8:$H$67,'💰 Sales Log'!$D$8:$D$67,$V3)) -> 0 | Y3: =IF($V3="","",'🧶 Product Catalog'!$M$9) | Z3: =IF($W3>0,'🧶 Product Catalog'!$K$9,0) -> 0 | AA3: =IF($V3="","",$W3) | AB3: =IFERROR(ROUND($W3*'🧶 Product Catalog'!$J$9,2),0) -> 0 | AC3: =IF('🏪 Craft Fairs'!$B$9="","",'🏪 Craft Fairs'!$B$9) | AD3: =IF($AC3="","",'🏪 Craft Fairs'!$N$9) | AE3: =IF($AC3="","",'🏪 Craft Fairs'!$P$9) | AF3: =IF($AC3="","",'🏪 Craft Fairs'!$M$9) | AG3: =IF(AND('🏪 Craft Fairs'!$C$9<>"",'🏪 Craft Fairs'!$C$9>=TODAY()),'🏪 Craft Fairs'!$C$9,"") | AH3: Discounts given | AI3: =SUM('💰 Sales Log'!$G$8:$G$67) -> 0 | AK3: =IF(OR('🧶 Product Catalog'!$O$9="🟠 Low stock",'🧶 Product Catalog'!$O$9="🔴 Out of stock"),1+SUMPRODUCT(('🧶 Product Catalog'!$O$8:$O$8="🟠 Low stock")+('🧶 Product Catalog'!$O$8:$O$8="🔴 Out of stock")),"") | AL3: 9
H4: March | I4: =SUMIFS('💰 Sales Log'!$H$8:$H$67,'💰 Sales Log'!$B$8:$B$67,">="&DATE(ReportYear,3,1),'💰 Sales Log'!$B$8:$B$67,"<"&EDATE(DATE(ReportYear,3,1),1)) -> 0 | J4: =SUMIFS('💰 Sales Log'!$M$8:$M$67,'💰 Sales Log'!$B$8:$B$67,">="&DATE(ReportYear,3,1),'💰 Sales Log'!$B$8:$B$67,"<"&EDATE(DATE(ReportYear,3,1),1)) -> 0 | K4: =SUMIFS('🏪 Craft Fairs'!$K$8:$K$31,'🏪 Craft Fairs'!$C$8:$C$31,">="&DATE(ReportYear,3,1),'🏪 Craft Fairs'!$C$8:$C$31,"<"&EDATE(DATE(ReportYear,3,1),1)) -> 0 | L4: =$I4-$J4-$K4 -> 0 | M4: =SUMIFS('💰 Sales Log'!$E$8:$E$67,'💰 Sales Log'!$B$8:$B$67,">="&DATE(ReportYear,3,1),'💰 Sales Log'!$B$8:$B$67,"<"&EDATE(DATE(ReportYear,3,1),1)) -> 0 | N4: =COUNTIFS('🏪 Craft Fairs'!$C$8:$C$31,">="&DATE(ReportYear,3,1),'🏪 Craft Fairs'!$C$8:$C$31,"<"&EDATE(DATE(ReportYear,3,1),1)) -> 0 | O4: =COUNTIFS('💰 Sales Log'!$B$8:$B$67,">="&DATE(ReportYear,3,1),'💰 Sales Log'!$B$8:$B$67,"<"&EDATE(DATE(ReportYear,3,1),1)) -> 0 | P4: Bank transfer | Q4: =SUMIFS('💰 Sales Log'!$H$8:$H$67,'💰 Sales Log'!$I$8:$I$67,$P4) -> 0 | S4: Parking | T4: =SUM('🏪 Craft Fairs'!$H$8:$H$31) -> 0 | V4: =IF('🧶 Product Catalog'!$C$10="","",'🧶 Product Catalog'!$C$10) | W4: =IF($V4="",0,SUMIFS('💰 Sales Log'!$E$8:$E$67,'💰 Sales Log'!$D$8:$D$67,$V4)) -> 0 | X4: =IF($V4="",0,SUMIFS('💰 Sales Log'!$H$8:$H$67,'💰 Sales Log'!$D$8:$D$67,$V4)) -> 0 | Y4: =IF($V4="","",'🧶 Product Catalog'!$M$10) | Z4: =IF($W4>0,'🧶 Product Catalog'!$K$10,0) -> 0 | AA4: =IF($V4="","",$W4) | AB4: =IFERROR(ROUND($W4*'🧶 Product Catalog'!$J$10,2),0) -> 0 | AC4: =IF('🏪 Craft Fairs'!$B$10="","",'🏪 Craft Fairs'!$B$10) | AD4: =IF($AC4="","",'🏪 Craft Fairs'!$N$10) | AE4: =IF($AC4="","",'🏪 Craft Fairs'!$P$10) | AF4: =IF($AC4="","",'🏪 Craft Fairs'!$M$10) | AG4: =IF(AND('🏪 Craft Fairs'!$C$10<>"",'🏪 Craft Fairs'!$C$10>=TODAY()),'🏪 Craft Fairs'!$C$10,"") | AH4: Cost of products sold | AI4: =SUMPRODUCT(IFERROR('💰 Sales Log'!$M$8:$M$67*1,0)) -> 0 | AK4: =IF(OR('🧶 Product Catalog'!$O$10="🟠 Low stock",'🧶 Product Catalog'!$O$10="🔴 Out of stock"),1+SUMPRODUCT(('🧶 Product Catalog'!$O$8:$O$9="🟠 Low stock")+('🧶 Product Catalog'!$O$8:$O$9="🔴 Out of stock")),"") | AL4: 10
H5: April | I5: =SUMIFS('💰 Sales Log'!$H$8:$H$67,'💰 Sales Log'!$B$8:$B$67,">="&DATE(ReportYear,4,1),'💰 Sales Log'!$B$8:$B$67,"<"&EDATE(DATE(ReportYear,4,1),1)) -> 0 | J5: =SUMIFS('💰 Sales Log'!$M$8:$M$67,'💰 Sales Log'!$B$8:$B$67,">="&DATE(ReportYear,4,1),'💰 Sales Log'!$B$8:$B$67,"<"&EDATE(DATE(ReportYear,4,1),1)) -> 0 | K5: =SUMIFS('🏪 Craft Fairs'!$K$8:$K$31,'🏪 Craft Fairs'!$C$8:$C$31,">="&DATE(ReportYear,4,1),'🏪 Craft Fairs'!$C$8:$C$31,"<"&EDATE(DATE(ReportYear,4,1),1)) -> 0 | L5: =$I5-$J5-$K5 -> 0 | M5: =SUMIFS('💰 Sales Log'!$E$8:$E$67,'💰 Sales Log'!$B$8:$B$67,">="&DATE(ReportYear,4,1),'💰 Sales Log'!$B$8:$B$67,"<"&EDATE(DATE(ReportYear,4,1),1)) -> 0 | N5: =COUNTIFS('🏪 Craft Fairs'!$C$8:$C$31,">="&DATE(ReportYear,4,1),'🏪 Craft Fairs'!$C$8:$C$31,"<"&EDATE(DATE(ReportYear,4,1),1)) -> 0 | O5: =COUNTIFS('💰 Sales Log'!$B$8:$B$67,">="&DATE(ReportYear,4,1),'💰 Sales Log'!$B$8:$B$67,"<"&EDATE(DATE(ReportYear,4,1),1)) -> 0 | P5: Mobile wallet | Q5: =SUMIFS('💰 Sales Log'!$H$8:$H$67,'💰 Sales Log'!$I$8:$I$67,$P5) -> 0 | S5: Food & drinks | T5: =SUM('🏪 Craft Fairs'!$I$8:$I$31) -> 0 | V5: =IF('🧶 Product Catalog'!$C$11="","",'🧶 Product Catalog'!$C$11) | W5: =IF($V5="",0,SUMIFS('💰 Sales Log'!$E$8:$E$67,'💰 Sales Log'!$D$8:$D$67,$V5)) -> 0 | X5: =IF($V5="",0,SUMIFS('💰 Sales Log'!$H$8:$H$67,'💰 Sales Log'!$D$8:$D$67,$V5)) -> 0 | Y5: =IF($V5="","",'🧶 Product Catalog'!$M$11) | Z5: =IF($W5>0,'🧶 Product Catalog'!$K$11,0) -> 0 | AA5: =IF($V5="","",$W5) | AB5: =IFERROR(ROUND($W5*'🧶 Product Catalog'!$J$11,2),0) -> 0 | AC5: =IF('🏪 Craft Fairs'!$B$11="","",'🏪 Craft Fairs'!$B$11) | AD5: =IF($AC5="","",'🏪 Craft Fairs'!$N$11) | AE5: =IF($AC5="","",'🏪 Craft Fairs'!$P$11) | AF5: =IF($AC5="","",'🏪 Craft Fairs'!$M$11) | AG5: =IF(AND('🏪 Craft Fairs'!$C$11<>"",'🏪 Craft Fairs'!$C$11>=TODAY()),'🏪 Craft Fairs'!$C$11,"") | AH5: Event expenses (all fairs) | AI5: =SUMIFS('🏪 Craft Fairs'!$K$8:$K$31,'🏪 Craft Fairs'!$C$8:$C$31,"<="&TODAY()) -> 0 | AK5: =IF(OR('🧶 Product Catalog'!$O$11="🟠 Low stock",'🧶 Product Catalog'!$O$11="🔴 Out of stock"),1+SUMPRODUCT(('🧶 Product Catalog'!$O$8:$O$10="🟠 Low stock")+('🧶 Product Catalog'!$O$8:$O$10="🔴 Out of stock")),"") | AL5: 11
H6: May | I6: =SUMIFS('💰 Sales Log'!$H$8:$H$67,'💰 Sales Log'!$B$8:$B$67,">="&DATE(ReportYear,5,1),'💰 Sales Log'!$B$8:$B$67,"<"&EDATE(DATE(ReportYear,5,1),1)) -> 0 | J6: =SUMIFS('💰 Sales Log'!$M$8:$M$67,'💰 Sales Log'!$B$8:$B$67,">="&DATE(ReportYear,5,1),'💰 Sales Log'!$B$8:$B$67,"<"&EDATE(DATE(ReportYear,5,1),1)) -> 0 | K6: =SUMIFS('🏪 Craft Fairs'!$K$8:$K$31,'🏪 Craft Fairs'!$C$8:$C$31,">="&DATE(ReportYear,5,1),'🏪 Craft Fairs'!$C$8:$C$31,"<"&EDATE(DATE(ReportYear,5,1),1)) -> 0 | L6: =$I6-$J6-$K6 -> 0 | M6: =SUMIFS('💰 Sales Log'!$E$8:$E$67,'💰 Sales Log'!$B$8:$B$67,">="&DATE(ReportYear,5,1),'💰 Sales Log'!$B$8:$B$67,"<"&EDATE(DATE(ReportYear,5,1),1)) -> 0 | N6: =COUNTIFS('🏪 Craft Fairs'!$C$8:$C$31,">="&DATE(ReportYear,5,1),'🏪 Craft Fairs'!$C$8:$C$31,"<"&EDATE(DATE(ReportYear,5,1),1)) -> 0 | O6: =COUNTIFS('💰 Sales Log'!$B$8:$B$67,">="&DATE(ReportYear,5,1),'💰 Sales Log'!$B$8:$B$67,"<"&EDATE(DATE(ReportYear,5,1),1)) -> 0 | P6: Online order | Q6: =SUMIFS('💰 Sales Log'!$H$8:$H$67,'💰 Sales Log'!$I$8:$I$67,$P6) -> 0 | S6: Display & decor | T6: =SUM('🏪 Craft Fairs'!$J$8:$J$31) -> 0 | V6: =IF('🧶 Product Catalog'!$C$12="","",'🧶 Product Catalog'!$C$12) | W6: =IF($V6="",0,SUMIFS('💰 Sales Log'!$E$8:$E$67,'💰 Sales Log'!$D$8:$D$67,$V6)) -> 0 | X6: =IF($V6="",0,SUMIFS('💰 Sales Log'!$H$8:$H$67,'💰 Sales Log'!$D$8:$D$67,$V6)) -> 0 | Y6: =IF($V6="","",'🧶 Product Catalog'!$M$12) | Z6: =IF($W6>0,'🧶 Product Catalog'!$K$12,0) -> 0 | AA6: =IF($V6="","",$W6) | AB6: =IFERROR(ROUND($W6*'🧶 Product Catalog'!$J$12,2),0) -> 0 | AC6: =IF('🏪 Craft Fairs'!$B$12="","",'🏪 Craft Fairs'!$B$12) | AD6: =IF($AC6="","",'🏪 Craft Fairs'!$N$12) | AE6: =IF($AC6="","",'🏪 Craft Fairs'!$P$12) | AF6: =IF($AC6="","",'🏪 Craft Fairs'!$M$12) | AG6: =IF(AND('🏪 Craft Fairs'!$C$12<>"",'🏪 Craft Fairs'!$C$12>=TODAY()),'🏪 Craft Fairs'!$C$12,"") | AH6: Net profit | AI6: =$AI$2-$AI$4-$AI$5 -> 0 | AK6: =IF(OR('🧶 Product Catalog'!$O$12="🟠 Low stock",'🧶 Product Catalog'!$O$12="🔴 Out of stock"),1+SUMPRODUCT(('🧶 Product Catalog'!$O$8:$O$11="🟠 Low stock")+('🧶 Product Catalog'!$O$8:$O$11="🔴 Out of stock")),"") | AL6: 12
H7: June | I7: =SUMIFS('💰 Sales Log'!$H$8:$H$67,'💰 Sales Log'!$B$8:$B$67,">="&DATE(ReportYear,6,1),'💰 Sales Log'!$B$8:$B$67,"<"&EDATE(DATE(ReportYear,6,1),1)) -> 0 | J7: =SUMIFS('💰 Sales Log'!$M$8:$M$67,'💰 Sales Log'!$B$8:$B$67,">="&DATE(ReportYear,6,1),'💰 Sales Log'!$B$8:$B$67,"<"&EDATE(DATE(ReportYear,6,1),1)) -> 0 | K7: =SUMIFS('🏪 Craft Fairs'!$K$8:$K$31,'🏪 Craft Fairs'!$C$8:$C$31,">="&DATE(ReportYear,6,1),'🏪 Craft Fairs'!$C$8:$C$31,"<"&EDATE(DATE(ReportYear,6,1),1)) -> 0 | L7: =$I7-$J7-$K7 -> 0 | M7: =SUMIFS('💰 Sales Log'!$E$8:$E$67,'💰 Sales Log'!$B$8:$B$67,">="&DATE(ReportYear,6,1),'💰 Sales Log'!$B$8:$B$67,"<"&EDATE(DATE(ReportYear,6,1),1)) -> 0 | N7: =COUNTIFS('🏪 Craft Fairs'!$C$8:$C$31,">="&DATE(ReportYear,6,1),'🏪 Craft Fairs'!$C$8:$C$31,"<"&EDATE(DATE(ReportYear,6,1),1)) -> 0 | O7: =COUNTIFS('💰 Sales Log'!$B$8:$B$67,">="&DATE(ReportYear,6,1),'💰 Sales Log'!$B$8:$B$67,"<"&EDATE(DATE(ReportYear,6,1),1)) -> 0 | P7: Other | Q7: =SUMIFS('💰 Sales Log'!$H$8:$H$67,'💰 Sales Log'!$I$8:$I$67,$P7) -> 0 | V7: =IF('🧶 Product Catalog'!$C$13="","",'🧶 Product Catalog'!$C$13) | W7: =IF($V7="",0,SUMIFS('💰 Sales Log'!$E$8:$E$67,'💰 Sales Log'!$D$8:$D$67,$V7)) -> 0 | X7: =IF($V7="",0,SUMIFS('💰 Sales Log'!$H$8:$H$67,'💰 Sales Log'!$D$8:$D$67,$V7)) -> 0 | Y7: =IF($V7="","",'🧶 Product Catalog'!$M$13) | Z7: =IF($W7>0,'🧶 Product Catalog'!$K$13,0) -> 0 | AA7: =IF($V7="","",$W7) | AB7: =IFERROR(ROUND($W7*'🧶 Product Catalog'!$J$13,2),0) -> 0 | AC7: =IF('🏪 Craft Fairs'!$B$13="","",'🏪 Craft Fairs'!$B$13) | AD7: =IF($AC7="","",'🏪 Craft Fairs'!$N$13) | AE7: =IF($AC7="","",'🏪 Craft Fairs'!$P$13) | AF7: =IF($AC7="","",'🏪 Craft Fairs'!$M$13) | AG7: =IF(AND('🏪 Craft Fairs'!$C$13<>"",'🏪 Craft Fairs'!$C$13>=TODAY()),'🏪 Craft Fairs'!$C$13,"") | AH7: Profit margin | AI7: =IFERROR($AI$6/$AI$2,0) -> 0 | AK7: =IF(OR('🧶 Product Catalog'!$O$13="🟠 Low stock",'🧶 Product Catalog'!$O$13="🔴 Out of stock"),1+SUMPRODUCT(('🧶 Product Catalog'!$O$8:$O$12="🟠 Low stock")+('🧶 Product Catalog'!$O$8:$O$12="🔴 Out of stock")),"") | AL7: 13
H8: July | I8: =SUMIFS('💰 Sales Log'!$H$8:$H$67,'💰 Sales Log'!$B$8:$B$67,">="&DATE(ReportYear,7,1),'💰 Sales Log'!$B$8:$B$67,"<"&EDATE(DATE(ReportYear,7,1),1)) -> 0 | J8: =SUMIFS('💰 Sales Log'!$M$8:$M$67,'💰 Sales Log'!$B$8:$B$67,">="&DATE(ReportYear,7,1),'💰 Sales Log'!$B$8:$B$67,"<"&EDATE(DATE(ReportYear,7,1),1)) -> 0 | K8: =SUMIFS('🏪 Craft Fairs'!$K$8:$K$31,'🏪 Craft Fairs'!$C$8:$C$31,">="&DATE(ReportYear,7,1),'🏪 Craft Fairs'!$C$8:$C$31,"<"&EDATE(DATE(ReportYear,7,1),1)) -> 0 | L8: =$I8-$J8-$K8 -> 0 | M8: =SUMIFS('💰 Sales Log'!$E$8:$E$67,'💰 Sales Log'!$B$8:$B$67,">="&DATE(ReportYear,7,1),'💰 Sales Log'!$B$8:$B$67,"<"&EDATE(DATE(ReportYear,7,1),1)) -> 0 | N8: =COUNTIFS('🏪 Craft Fairs'!$C$8:$C$31,">="&DATE(ReportYear,7,1),'🏪 Craft Fairs'!$C$8:$C$31,"<"&EDATE(DATE(ReportYear,7,1),1)) -> 0 | O8: =COUNTIFS('💰 Sales Log'!$B$8:$B$67,">="&DATE(ReportYear,7,1),'💰 Sales Log'!$B$8:$B$67,"<"&EDATE(DATE(ReportYear,7,1),1)) -> 0 | V8: =IF('🧶 Product Catalog'!$C$14="","",'🧶 Product Catalog'!$C$14) | W8: =IF($V8="",0,SUMIFS('💰 Sales Log'!$E$8:$E$67,'💰 Sales Log'!$D$8:$D$67,$V8)) -> 0 | X8: =IF($V8="",0,SUMIFS('💰 Sales Log'!$H$8:$H$67,'💰 Sales Log'!$D$8:$D$67,$V8)) -> 0 | Y8: =IF($V8="","",'🧶 Product Catalog'!$M$14) | Z8: =IF($W8>0,'🧶 Product Catalog'!$K$14,0) -> 0 | AA8: =IF($V8="","",$W8) | AB8: =IFERROR(ROUND($W8*'🧶 Product Catalog'!$J$14,2),0) -> 0 | AC8: =IF('🏪 Craft Fairs'!$B$14="","",'🏪 Craft Fairs'!$B$14) | AD8: =IF($AC8="","",'🏪 Craft Fairs'!$N$14) | AE8: =IF($AC8="","",'🏪 Craft Fairs'!$P$14) | AF8: =IF($AC8="","",'🏪 Craft Fairs'!$M$14) | AG8: =IF(AND('🏪 Craft Fairs'!$C$14<>"",'🏪 Craft Fairs'!$C$14>=TODAY()),'🏪 Craft Fairs'!$C$14,"") | AH8: Units sold | AI8: =SUM('💰 Sales Log'!$E$8:$E$67) -> 0 | AK8: =IF(OR('🧶 Product Catalog'!$O$14="🟠 Low stock",'🧶 Product Catalog'!$O$14="🔴 Out of stock"),1+SUMPRODUCT(('🧶 Product Catalog'!$O$8:$O$13="🟠 Low stock")+('🧶 Product Catalog'!$O$8:$O$13="🔴 Out of stock")),"") | AL8: 14
H9: August | I9: =SUMIFS('💰 Sales Log'!$H$8:$H$67,'💰 Sales Log'!$B$8:$B$67,">="&DATE(ReportYear,8,1),'💰 Sales Log'!$B$8:$B$67,"<"&EDATE(DATE(ReportYear,8,1),1)) -> 0 | J9: =SUMIFS('💰 Sales Log'!$M$8:$M$67,'💰 Sales Log'!$B$8:$B$67,">="&DATE(ReportYear,8,1),'💰 Sales Log'!$B$8:$B$67,"<"&EDATE(DATE(ReportYear,8,1),1)) -> 0 | K9: =SUMIFS('🏪 Craft Fairs'!$K$8:$K$31,'🏪 Craft Fairs'!$C$8:$C$31,">="&DATE(ReportYear,8,1),'🏪 Craft Fairs'!$C$8:$C$31,"<"&EDATE(DATE(ReportYear,8,1),1)) -> 0 | L9: =$I9-$J9-$K9 -> 0 | M9: =SUMIFS('💰 Sales Log'!$E$8:$E$67,'💰 Sales Log'!$B$8:$B$67,">="&DATE(ReportYear,8,1),'💰 Sales Log'!$B$8:$B$67,"<"&EDATE(DATE(ReportYear,8,1),1)) -> 0 | N9: =COUNTIFS('🏪 Craft Fairs'!$C$8:$C$31,">="&DATE(ReportYear,8,1),'🏪 Craft Fairs'!$C$8:$C$31,"<"&EDATE(DATE(ReportYear,8,1),1)) -> 0 | O9: =COUNTIFS('💰 Sales Log'!$B$8:$B$67,">="&DATE(ReportYear,8,1),'💰 Sales Log'!$B$8:$B$67,"<"&EDATE(DATE(ReportYear,8,1),1)) -> 0 | V9: =IF('🧶 Product Catalog'!$C$15="","",'🧶 Product Catalog'!$C$15) | W9: =IF($V9="",0,SUMIFS('💰 Sales Log'!$E$8:$E$67,'💰 Sales Log'!$D$8:$D$67,$V9)) -> 0 | X9: =IF($V9="",0,SUMIFS('💰 Sales Log'!$H$8:$H$67,'💰 Sales Log'!$D$8:$D$67,$V9)) -> 0 | Y9: =IF($V9="","",'🧶 Product Catalog'!$M$15) | Z9: =IF($W9>0,'🧶 Product Catalog'!$K$15,0) -> 0 | AA9: =IF($V9="","",$W9) | AB9: =IFERROR(ROUND($W9*'🧶 Product Catalog'!$J$15,2),0) -> 0 | AC9: =IF('🏪 Craft Fairs'!$B$15="","",'🏪 Craft Fairs'!$B$15) | AD9: =IF($AC9="","",'🏪 Craft Fairs'!$N$15) | AE9: =IF($AC9="","",'🏪 Craft Fairs'!$P$15) | AF9: =IF($AC9="","",'🏪 Craft Fairs'!$M$15) | AG9: =IF(AND('🏪 Craft Fairs'!$C$15<>"",'🏪 Craft Fairs'!$C$15>=TODAY()),'🏪 Craft Fairs'!$C$15,"") | AH9: Sales log entries | AI9: =COUNT('💰 Sales Log'!$H$8:$H$67) -> 0 | AK9: =IF(OR('🧶 Product Catalog'!$O$15="🟠 Low stock",'🧶 Product Catalog'!$O$15="🔴 Out of stock"),1+SUMPRODUCT(('🧶 Product Catalog'!$O$8:$O$14="🟠 Low stock")+('🧶 Product Catalog'!$O$8:$O$14="🔴 Out of stock")),"") | AL9: 15
H10: September | I10: =SUMIFS('💰 Sales Log'!$H$8:$H$67,'💰 Sales Log'!$B$8:$B$67,">="&DATE(ReportYear,9,1),'💰 Sales Log'!$B$8:$B$67,"<"&EDATE(DATE(ReportYear,9,1),1)) -> 0 | J10: =SUMIFS('💰 Sales Log'!$M$8:$M$67,'💰 Sales Log'!$B$8:$B$67,">="&DATE(ReportYear,9,1),'💰 Sales Log'!$B$8:$B$67,"<"&EDATE(DATE(ReportYear,9,1),1)) -> 0 | K10: =SUMIFS('🏪 Craft Fairs'!$K$8:$K$31,'🏪 Craft Fairs'!$C$8:$C$31,">="&DATE(ReportYear,9,1),'🏪 Craft Fairs'!$C$8:$C$31,"<"&EDATE(DATE(ReportYear,9,1),1)) -> 0 | L10: =$I10-$J10-$K10 -> 0 | M10: =SUMIFS('💰 Sales Log'!$E$8:$E$67,'💰 Sales Log'!$B$8:$B$67,">="&DATE(ReportYear,9,1),'💰 Sales Log'!$B$8:$B$67,"<"&EDATE(DATE(ReportYear,9,1),1)) -> 0 | N10: =COUNTIFS('🏪 Craft Fairs'!$C$8:$C$31,">="&DATE(ReportYear,9,1),'🏪 Craft Fairs'!$C$8:$C$31,"<"&EDATE(DATE(ReportYear,9,1),1)) -> 0 | O10: =COUNTIFS('💰 Sales Log'!$B$8:$B$67,">="&DATE(ReportYear,9,1),'💰 Sales Log'!$B$8:$B$67,"<"&EDATE(DATE(ReportYear,9,1),1)) -> 0 | V10: =IF('🧶 Product Catalog'!$C$16="","",'🧶 Product Catalog'!$C$16) | W10: =IF($V10="",0,SUMIFS('💰 Sales Log'!$E$8:$E$67,'💰 Sales Log'!$D$8:$D$67,$V10)) -> 0 | X10: =IF($V10="",0,SUMIFS('💰 Sales Log'!$H$8:$H$67,'💰 Sales Log'!$D$8:$D$67,$V10)) -> 0 | Y10: =IF($V10="","",'🧶 Product Catalog'!$M$16) | Z10: =IF($W10>0,'🧶 Product Catalog'!$K$16,0) -> 0 | AA10: =IF($V10="","",$W10) | AB10: =IFERROR(ROUND($W10*'🧶 Product Catalog'!$J$16,2),0) -> 0 | AC10: =IF('🏪 Craft Fairs'!$B$16="","",'🏪 Craft Fairs'!$B$16) | AD10: =IF($AC10="","",'🏪 Craft Fairs'!$N$16) | AE10: =IF($AC10="","",'🏪 Craft Fairs'!$P$16) | AF10: =IF($AC10="","",'🏪 Craft Fairs'!$M$16) | AG10: =IF(AND('🏪 Craft Fairs'!$C$16<>"",'🏪 Craft Fairs'!$C$16>=TODAY()),'🏪 Craft Fairs'!$C$16,"") | AH10: Average sale value | AI10: =IFERROR($AI$2/$AI$9,0) -> 0 | AK10: =IF(OR('🧶 Product Catalog'!$O$16="🟠 Low stock",'🧶 Product Catalog'!$O$16="🔴 Out of stock"),1+SUMPRODUCT(('🧶 Product Catalog'!$O$8:$O$15="🟠 Low stock")+('🧶 Product Catalog'!$O$8:$O$15="🔴 Out of stock")),"") | AL10: 16
H11: October | I11: =SUMIFS('💰 Sales Log'!$H$8:$H$67,'💰 Sales Log'!$B$8:$B$67,">="&DATE(ReportYear,10,1),'💰 Sales Log'!$B$8:$B$67,"<"&EDATE(DATE(ReportYear,10,1),1)) -> 0 | J11: =SUMIFS('💰 Sales Log'!$M$8:$M$67,'💰 Sales Log'!$B$8:$B$67,">="&DATE(ReportYear,10,1),'💰 Sales Log'!$B$8:$B$67,"<"&EDATE(DATE(ReportYear,10,1),1)) -> 0 | K11: =SUMIFS('🏪 Craft Fairs'!$K$8:$K$31,'🏪 Craft Fairs'!$C$8:$C$31,">="&DATE(ReportYear,10,1),'🏪 Craft Fairs'!$C$8:$C$31,"<"&EDATE(DATE(ReportYear,10,1),1)) -> 0 | L11: =$I11-$J11-$K11 -> 0 | M11: =SUMIFS('💰 Sales Log'!$E$8:$E$67,'💰 Sales Log'!$B$8:$B$67,">="&DATE(ReportYear,10,1),'💰 Sales Log'!$B$8:$B$67,"<"&EDATE(DATE(ReportYear,10,1),1)) -> 0 | N11: =COUNTIFS('🏪 Craft Fairs'!$C$8:$C$31,">="&DATE(ReportYear,10,1),'🏪 Craft Fairs'!$C$8:$C$31,"<"&EDATE(DATE(ReportYear,10,1),1)) -> 0 | O11: =COUNTIFS('💰 Sales Log'!$B$8:$B$67,">="&DATE(ReportYear,10,1),'💰 Sales Log'!$B$8:$B$67,"<"&EDATE(DATE(ReportYear,10,1),1)) -> 0 | V11: =IF('🧶 Product Catalog'!$C$17="","",'🧶 Product Catalog'!$C$17) | W11: =IF($V11="",0,SUMIFS('💰 Sales Log'!$E$8:$E$67,'💰 Sales Log'!$D$8:$D$67,$V11)) -> 0 | X11: =IF($V11="",0,SUMIFS('💰 Sales Log'!$H$8:$H$67,'💰 Sales Log'!$D$8:$D$67,$V11)) -> 0 | Y11: =IF($V11="","",'🧶 Product Catalog'!$M$17) | Z11: =IF($W11>0,'🧶 Product Catalog'!$K$17,0) -> 0 | AA11: =IF($V11="","",$W11) | AB11: =IFERROR(ROUND($W11*'🧶 Product Catalog'!$J$17,2),0) -> 0 | AC11: =IF('🏪 Craft Fairs'!$B$17="","",'🏪 Craft Fairs'!$B$17) | AD11: =IF($AC11="","",'🏪 Craft Fairs'!$N$17) | AE11: =IF($AC11="","",'🏪 Craft Fairs'!$P$17) | AF11: =IF($AC11="","",'🏪 Craft Fairs'!$M$17) | AG11: =IF(AND('🏪 Craft Fairs'!$C$17<>"",'🏪 Craft Fairs'!$C$17>=TODAY()),'🏪 Craft Fairs'!$C$17,"") | AH11: Average profit per item | AI11: =IFERROR($AI$6/$AI$8,0) -> 0 | AK11: =IF(OR('🧶 Product Catalog'!$O$17="🟠 Low stock",'🧶 Product Catalog'!$O$17="🔴 Out of stock"),1+SUMPRODUCT(('🧶 Product Catalog'!$O$8:$O$16="🟠 Low stock")+('🧶 Product Catalog'!$O$8:$O$16="🔴 Out of stock")),"") | AL11: 17
H12: November | I12: =SUMIFS('💰 Sales Log'!$H$8:$H$67,'💰 Sales Log'!$B$8:$B$67,">="&DATE(ReportYear,11,1),'💰 Sales Log'!$B$8:$B$67,"<"&EDATE(DATE(ReportYear,11,1),1)) -> 0 | J12: =SUMIFS('💰 Sales Log'!$M$8:$M$67,'💰 Sales Log'!$B$8:$B$67,">="&DATE(ReportYear,11,1),'💰 Sales Log'!$B$8:$B$67,"<"&EDATE(DATE(ReportYear,11,1),1)) -> 0 | K12: =SUMIFS('🏪 Craft Fairs'!$K$8:$K$31,'🏪 Craft Fairs'!$C$8:$C$31,">="&DATE(ReportYear,11,1),'🏪 Craft Fairs'!$C$8:$C$31,"<"&EDATE(DATE(ReportYear,11,1),1)) -> 0 | L12: =$I12-$J12-$K12 -> 0 | M12: =SUMIFS('💰 Sales Log'!$E$8:$E$67,'💰 Sales Log'!$B$8:$B$67,">="&DATE(ReportYear,11,1),'💰 Sales Log'!$B$8:$B$67,"<"&EDATE(DATE(ReportYear,11,1),1)) -> 0 | N12: =COUNTIFS('🏪 Craft Fairs'!$C$8:$C$31,">="&DATE(ReportYear,11,1),'🏪 Craft Fairs'!$C$8:$C$31,"<"&EDATE(DATE(ReportYear,11,1),1)) -> 0 | O12: =COUNTIFS('💰 Sales Log'!$B$8:$B$67,">="&DATE(ReportYear,11,1),'💰 Sales Log'!$B$8:$B$67,"<"&EDATE(DATE(ReportYear,11,1),1)) -> 0 | V12: =IF('🧶 Product Catalog'!$C$18="","",'🧶 Product Catalog'!$C$18) | W12: =IF($V12="",0,SUMIFS('💰 Sales Log'!$E$8:$E$67,'💰 Sales Log'!$D$8:$D$67,$V12)) -> 0 | X12: =IF($V12="",0,SUMIFS('💰 Sales Log'!$H$8:$H$67,'💰 Sales Log'!$D$8:$D$67,$V12)) -> 0 | Y12: =IF($V12="","",'🧶 Product Catalog'!$M$18) | Z12: =IF($W12>0,'🧶 Product Catalog'!$K$18,0) -> 0 | AA12: =IF($V12="","",$W12) | AB12: =IFERROR(ROUND($W12*'🧶 Product Catalog'!$J$18,2),0) -> 0 | AC12: =IF('🏪 Craft Fairs'!$B$18="","",'🏪 Craft Fairs'!$B$18) | AD12: =IF($AC12="","",'🏪 Craft Fairs'!$N$18) | AE12: =IF($AC12="","",'🏪 Craft Fairs'!$P$18) | AF12: =IF($AC12="","",'🏪 Craft Fairs'!$M$18) | AG12: =IF(AND('🏪 Craft Fairs'!$C$18<>"",'🏪 Craft Fairs'!$C$18>=TODAY()),'🏪 Craft Fairs'!$C$18,"") | AH12: Fairs on the books | AI12: =COUNTA('🏪 Craft Fairs'!$B$8:$B$31) -> 0 | AK12: =IF(OR('🧶 Product Catalog'!$O$18="🟠 Low stock",'🧶 Product Catalog'!$O$18="🔴 Out of stock"),1+SUMPRODUCT(('🧶 Product Catalog'!$O$8:$O$17="🟠 Low stock")+('🧶 Product Catalog'!$O$8:$O$17="🔴 Out of stock")),"") | AL12: 18
H13: December | I13: =SUMIFS('💰 Sales Log'!$H$8:$H$67,'💰 Sales Log'!$B$8:$B$67,">="&DATE(ReportYear,12,1),'💰 Sales Log'!$B$8:$B$67,"<"&EDATE(DATE(ReportYear,12,1),1)) -> 0 | J13: =SUMIFS('💰 Sales Log'!$M$8:$M$67,'💰 Sales Log'!$B$8:$B$67,">="&DATE(ReportYear,12,1),'💰 Sales Log'!$B$8:$B$67,"<"&EDATE(DATE(ReportYear,12,1),1)) -> 0 | K13: =SUMIFS('🏪 Craft Fairs'!$K$8:$K$31,'🏪 Craft Fairs'!$C$8:$C$31,">="&DATE(ReportYear,12,1),'🏪 Craft Fairs'!$C$8:$C$31,"<"&EDATE(DATE(ReportYear,12,1),1)) -> 0 | L13: =$I13-$J13-$K13 -> 0 | M13: =SUMIFS('💰 Sales Log'!$E$8:$E$67,'💰 Sales Log'!$B$8:$B$67,">="&DATE(ReportYear,12,1),'💰 Sales Log'!$B$8:$B$67,"<"&EDATE(DATE(ReportYear,12,1),1)) -> 0 | N13: =COUNTIFS('🏪 Craft Fairs'!$C$8:$C$31,">="&DATE(ReportYear,12,1),'🏪 Craft Fairs'!$C$8:$C$31,"<"&EDATE(DATE(ReportYear,12,1),1)) -> 0 | O13: =COUNTIFS('💰 Sales Log'!$B$8:$B$67,">="&DATE(ReportYear,12,1),'💰 Sales Log'!$B$8:$B$67,"<"&EDATE(DATE(ReportYear,12,1),1)) -> 0 | V13: =IF('🧶 Product Catalog'!$C$19="","",'🧶 Product Catalog'!$C$19) | W13: =IF($V13="",0,SUMIFS('💰 Sales Log'!$E$8:$E$67,'💰 Sales Log'!$D$8:$D$67,$V13)) -> 0 | X13: =IF($V13="",0,SUMIFS('💰 Sales Log'!$H$8:$H$67,'💰 Sales Log'!$D$8:$D$67,$V13)) -> 0 | Y13: =IF($V13="","",'🧶 Product Catalog'!$M$19) | Z13: =IF($W13>0,'🧶 Product Catalog'!$K$19,0) -> 0 | AA13: =IF($V13="","",$W13) | AB13: =IFERROR(ROUND($W13*'🧶 Product Catalog'!$J$19,2),0) -> 0 | AC13: =IF('🏪 Craft Fairs'!$B$19="","",'🏪 Craft Fairs'!$B$19) | AD13: =IF($AC13="","",'🏪 Craft Fairs'!$N$19) | AE13: =IF($AC13="","",'🏪 Craft Fairs'!$P$19) | AF13: =IF($AC13="","",'🏪 Craft Fairs'!$M$19) | AG13: =IF(AND('🏪 Craft Fairs'!$C$19<>"",'🏪 Craft Fairs'!$C$19>=TODAY()),'🏪 Craft Fairs'!$C$19,"") | AH13: Fairs worked | AI13: =COUNTIFS('🏪 Craft Fairs'!$C$8:$C$31,"<="&TODAY(),'🏪 Craft Fairs'!$N$8:$N$31,">0") -> 0 | AK13: =IF(OR('🧶 Product Catalog'!$O$19="🟠 Low stock",'🧶 Product Catalog'!$O$19="🔴 Out of stock"),1+SUMPRODUCT(('🧶 Product Catalog'!$O$8:$O$18="🟠 Low stock")+('🧶 Product Catalog'!$O$8:$O$18="🔴 Out of stock")),"") | AL13: 19
V14: =IF('🧶 Product Catalog'!$C$20="","",'🧶 Product Catalog'!$C$20) | W14: =IF($V14="",0,SUMIFS('💰 Sales Log'!$E$8:$E$67,'💰 Sales Log'!$D$8:$D$67,$V14)) -> 0 | X14: =IF($V14="",0,SUMIFS('💰 Sales Log'!$H$8:$H$67,'💰 Sales Log'!$D$8:$D$67,$V14)) -> 0 | Y14: =IF($V14="","",'🧶 Product Catalog'!$M$20) | Z14: =IF($W14>0,'🧶 Product Catalog'!$K$20,0) -> 0 | AA14: =IF($V14="","",$W14) | AB14: =IFERROR(ROUND($W14*'🧶 Product Catalog'!$J$20,2),0) -> 0 | AC14: =IF('🏪 Craft Fairs'!$B$20="","",'🏪 Craft Fairs'!$B$20) | AD14: =IF($AC14="","",'🏪 Craft Fairs'!$N$20) | AE14: =IF($AC14="","",'🏪 Craft Fairs'!$P$20) | AF14: =IF($AC14="","",'🏪 Craft Fairs'!$M$20) | AG14: =IF(AND('🏪 Craft Fairs'!$C$20<>"",'🏪 Craft Fairs'!$C$20>=TODAY()),'🏪 Craft Fairs'!$C$20,"") | AH14: Inventory value (at unit cost) | AI14: =0 -> 0 | AK14: =IF(OR('🧶 Product Catalog'!$O$20="🟠 Low stock",'🧶 Product Catalog'!$O$20="🔴 Out of stock"),1+SUMPRODUCT(('🧶 Product Catalog'!$O$8:$O$19="🟠 Low stock")+('🧶 Product Catalog'!$O$8:$O$19="🔴 Out of stock")),"") | AL14: 20
V15: =IF('🧶 Product Catalog'!$C$21="","",'🧶 Product Catalog'!$C$21) | W15: =IF($V15="",0,SUMIFS('💰 Sales Log'!$E$8:$E$67,'💰 Sales Log'!$D$8:$D$67,$V15)) -> 0 | X15: =IF($V15="",0,SUMIFS('💰 Sales Log'!$H$8:$H$67,'💰 Sales Log'!$D$8:$D$67,$V15)) -> 0 | Y15: =IF($V15="","",'🧶 Product Catalog'!$M$21) | Z15: =IF($W15>0,'🧶 Product Catalog'!$K$21,0) -> 0 | AA15: =IF($V15="","",$W15) | AB15: =IFERROR(ROUND($W15*'🧶 Product Catalog'!$J$21,2),0) -> 0 | AC15: =IF('🏪 Craft Fairs'!$B$21="","",'🏪 Craft Fairs'!$B$21) | AD15: =IF($AC15="","",'🏪 Craft Fairs'!$N$21) | AE15: =IF($AC15="","",'🏪 Craft Fairs'!$P$21) | AF15: =IF($AC15="","",'🏪 Craft Fairs'!$M$21) | AG15: =IF(AND('🏪 Craft Fairs'!$C$21<>"",'🏪 Craft Fairs'!$C$21>=TODAY()),'🏪 Craft Fairs'!$C$21,"") | AH15: Products below minimum | AI15: =COUNTIF('🧶 Product Catalog'!$O$8:$O$31,"🟠 Low stock")+COUNTIF('🧶 Product Catalog'!$O$8:$O$31,"🔴 Out of stock") -> 0 | AK15: =IF(OR('🧶 Product Catalog'!$O$21="🟠 Low stock",'🧶 Product Catalog'!$O$21="🔴 Out of stock"),1+SUMPRODUCT(('🧶 Product Catalog'!$O$8:$O$20="🟠 Low stock")+('🧶 Product Catalog'!$O$8:$O$20="🔴 Out of stock")),"") | AL15: 21
V16: =IF('🧶 Product Catalog'!$C$22="","",'🧶 Product Catalog'!$C$22) | W16: =IF($V16="",0,SUMIFS('💰 Sales Log'!$E$8:$E$67,'💰 Sales Log'!$D$8:$D$67,$V16)) -> 0 | X16: =IF($V16="",0,SUMIFS('💰 Sales Log'!$H$8:$H$67,'💰 Sales Log'!$D$8:$D$67,$V16)) -> 0 | Y16: =IF($V16="","",'🧶 Product Catalog'!$M$22) | Z16: =IF($W16>0,'🧶 Product Catalog'!$K$22,0) -> 0 | AA16: =IF($V16="","",$W16) | AB16: =IFERROR(ROUND($W16*'🧶 Product Catalog'!$J$22,2),0) -> 0 | AC16: =IF('🏪 Craft Fairs'!$B$22="","",'🏪 Craft Fairs'!$B$22) | AD16: =IF($AC16="","",'🏪 Craft Fairs'!$N$22) | AE16: =IF($AC16="","",'🏪 Craft Fairs'!$P$22) | AF16: =IF($AC16="","",'🏪 Craft Fairs'!$M$22) | AG16: =IF(AND('🏪 Craft Fairs'!$C$22<>"",'🏪 Craft Fairs'!$C$22>=TODAY()),'🏪 Craft Fairs'!$C$22,"") | AH16: Materials below threshold | AI16: =0 -> 0 | AK16: =IF(OR('🧶 Product Catalog'!$O$22="🟠 Low stock",'🧶 Product Catalog'!$O$22="🔴 Out of stock"),1+SUMPRODUCT(('🧶 Product Catalog'!$O$8:$O$21="🟠 Low stock")+('🧶 Product Catalog'!$O$8:$O$21="🔴 Out of stock")),"") | AL16: 22
V17: =IF('🧶 Product Catalog'!$C$23="","",'🧶 Product Catalog'!$C$23) | W17: =IF($V17="",0,SUMIFS('💰 Sales Log'!$E$8:$E$67,'💰 Sales Log'!$D$8:$D$67,$V17)) -> 0 | X17: =IF($V17="",0,SUMIFS('💰 Sales Log'!$H$8:$H$67,'💰 Sales Log'!$D$8:$D$67,$V17)) -> 0 | Y17: =IF($V17="","",'🧶 Product Catalog'!$M$23) | Z17: =IF($W17>0,'🧶 Product Catalog'!$K$23,0) -> 0 | AA17: =IF($V17="","",$W17) | AB17: =IFERROR(ROUND($W17*'🧶 Product Catalog'!$J$23,2),0) -> 0 | AC17: =IF('🏪 Craft Fairs'!$B$23="","",'🏪 Craft Fairs'!$B$23) | AD17: =IF($AC17="","",'🏪 Craft Fairs'!$N$23) | AE17: =IF($AC17="","",'🏪 Craft Fairs'!$P$23) | AF17: =IF($AC17="","",'🏪 Craft Fairs'!$M$23) | AG17: =IF(AND('🏪 Craft Fairs'!$C$23<>"",'🏪 Craft Fairs'!$C$23>=TODAY()),'🏪 Craft Fairs'!$C$23,"") | AH17: Estimated reorder cost | AI17: =SUMPRODUCT(('🧶 Product Catalog'!$M$8:$M$31<='🧶 Product Catalog'!$N$8:$N$31)*IFERROR(('🧶 Product Catalog'!$N$8:$N$31*2-'🧶 Product Catalog'!$M$8:$M$31)*'🧶 Product Catalog'!$I$8:$I$31,0)) -> 0 | AK17: =IF(OR('🧶 Product Catalog'!$O$23="🟠 Low stock",'🧶 Product Catalog'!$O$23="🔴 Out of stock"),1+SUMPRODUCT(('🧶 Product Catalog'!$O$8:$O$22="🟠 Low stock")+('🧶 Product Catalog'!$O$8:$O$22="🔴 Out of stock")),"") | AL17: 23
V18: =IF('🧶 Product Catalog'!$C$24="","",'🧶 Product Catalog'!$C$24) | W18: =IF($V18="",0,SUMIFS('💰 Sales Log'!$E$8:$E$67,'💰 Sales Log'!$D$8:$D$67,$V18)) -> 0 | X18: =IF($V18="",0,SUMIFS('💰 Sales Log'!$H$8:$H$67,'💰 Sales Log'!$D$8:$D$67,$V18)) -> 0 | Y18: =IF($V18="","",'🧶 Product Catalog'!$M$24) | Z18: =IF($W18>0,'🧶 Product Catalog'!$K$24,0) -> 0 | AA18: =IF($V18="","",$W18) | AB18: =IFERROR(ROUND($W18*'🧶 Product Catalog'!$J$24,2),0) -> 0 | AC18: =IF('🏪 Craft Fairs'!$B$24="","",'🏪 Craft Fairs'!$B$24) | AD18: =IF($AC18="","",'🏪 Craft Fairs'!$N$24) | AE18: =IF($AC18="","",'🏪 Craft Fairs'!$P$24) | AF18: =IF($AC18="","",'🏪 Craft Fairs'!$M$24) | AG18: =IF(AND('🏪 Craft Fairs'!$C$24<>"",'🏪 Craft Fairs'!$C$24>=TODAY()),'🏪 Craft Fairs'!$C$24,"") | AH18: Sell-through rate | AI18: =0 -> 0 | AK18: =IF(OR('🧶 Product Catalog'!$O$24="🟠 Low stock",'🧶 Product Catalog'!$O$24="🔴 Out of stock"),1+SUMPRODUCT(('🧶 Product Catalog'!$O$8:$O$23="🟠 Low stock")+('🧶 Product Catalog'!$O$8:$O$23="🔴 Out of stock")),"") | AL18: 24
V19: =IF('🧶 Product Catalog'!$C$25="","",'🧶 Product Catalog'!$C$25) | W19: =IF($V19="",0,SUMIFS('💰 Sales Log'!$E$8:$E$67,'💰 Sales Log'!$D$8:$D$67,$V19)) -> 0 | X19: =IF($V19="",0,SUMIFS('💰 Sales Log'!$H$8:$H$67,'💰 Sales Log'!$D$8:$D$67,$V19)) -> 0 | Y19: =IF($V19="","",'🧶 Product Catalog'!$M$25) | Z19: =IF($W19>0,'🧶 Product Catalog'!$K$25,0) -> 0 | AA19: =IF($V19="","",$W19) | AB19: =IFERROR(ROUND($W19*'🧶 Product Catalog'!$J$25,2),0) -> 0 | AC19: =IF('🏪 Craft Fairs'!$B$25="","",'🏪 Craft Fairs'!$B$25) | AD19: =IF($AC19="","",'🏪 Craft Fairs'!$N$25) | AE19: =IF($AC19="","",'🏪 Craft Fairs'!$P$25) | AF19: =IF($AC19="","",'🏪 Craft Fairs'!$M$25) | AG19: =IF(AND('🏪 Craft Fairs'!$C$25<>"",'🏪 Craft Fairs'!$C$25>=TODAY()),'🏪 Craft Fairs'!$C$25,"") | AH19: Units made (all batches) | AI19: =0 -> 0 | AK19: =IF(OR('🧶 Product Catalog'!$O$25="🟠 Low stock",'🧶 Product Catalog'!$O$25="🔴 Out of stock"),1+SUMPRODUCT(('🧶 Product Catalog'!$O$8:$O$24="🟠 Low stock")+('🧶 Product Catalog'!$O$8:$O$24="🔴 Out of stock")),"") | AL19: 25
V20: =IF('🧶 Product Catalog'!$C$26="","",'🧶 Product Catalog'!$C$26) | W20: =IF($V20="",0,SUMIFS('💰 Sales Log'!$E$8:$E$67,'💰 Sales Log'!$D$8:$D$67,$V20)) -> 0 | X20: =IF($V20="",0,SUMIFS('💰 Sales Log'!$H$8:$H$67,'💰 Sales Log'!$D$8:$D$67,$V20)) -> 0 | Y20: =IF($V20="","",'🧶 Product Catalog'!$M$26) | Z20: =IF($W20>0,'🧶 Product Catalog'!$K$26,0) -> 0 | AA20: =IF($V20="","",$W20) | AB20: =IFERROR(ROUND($W20*'🧶 Product Catalog'!$J$26,2),0) -> 0 | AC20: =IF('🏪 Craft Fairs'!$B$26="","",'🏪 Craft Fairs'!$B$26) | AD20: =IF($AC20="","",'🏪 Craft Fairs'!$N$26) | AE20: =IF($AC20="","",'🏪 Craft Fairs'!$P$26) | AF20: =IF($AC20="","",'🏪 Craft Fairs'!$M$26) | AG20: =IF(AND('🏪 Craft Fairs'!$C$26<>"",'🏪 Craft Fairs'!$C$26>=TODAY()),'🏪 Craft Fairs'!$C$26,"") | AH20: Best-selling product | AI20: =IFERROR(INDEX($V$2:$V$25,MATCH(MAX($X$2:$X$25),$X$2:$X$25,0)),"") | AK20: =IF(OR('🧶 Product Catalog'!$O$26="🟠 Low stock",'🧶 Product Catalog'!$O$26="🔴 Out of stock"),1+SUMPRODUCT(('🧶 Product Catalog'!$O$8:$O$25="🟠 Low stock")+('🧶 Product Catalog'!$O$8:$O$25="🔴 Out of stock")),"") | AL20: 26
V21: =IF('🧶 Product Catalog'!$C$27="","",'🧶 Product Catalog'!$C$27) | W21: =IF($V21="",0,SUMIFS('💰 Sales Log'!$E$8:$E$67,'💰 Sales Log'!$D$8:$D$67,$V21)) -> 0 | X21: =IF($V21="",0,SUMIFS('💰 Sales Log'!$H$8:$H$67,'💰 Sales Log'!$D$8:$D$67,$V21)) -> 0 | Y21: =IF($V21="","",'🧶 Product Catalog'!$M$27) | Z21: =IF($W21>0,'🧶 Product Catalog'!$K$27,0) -> 0 | AA21: =IF($V21="","",$W21) | AB21: =IFERROR(ROUND($W21*'🧶 Product Catalog'!$J$27,2),0) -> 0 | AC21: =IF('🏪 Craft Fairs'!$B$27="","",'🏪 Craft Fairs'!$B$27) | AD21: =IF($AC21="","",'🏪 Craft Fairs'!$N$27) | AE21: =IF($AC21="","",'🏪 Craft Fairs'!$P$27) | AF21: =IF($AC21="","",'🏪 Craft Fairs'!$M$27) | AG21: =IF(AND('🏪 Craft Fairs'!$C$27<>"",'🏪 Craft Fairs'!$C$27>=TODAY()),'🏪 Craft Fairs'!$C$27,"") | AH21: Best craft fair | AI21: =IFERROR(INDEX($AC$2:$AC$25,MATCH(MAX($AE$2:$AE$25),$AE$2:$AE$25,0)),"") | AK21: =IF(OR('🧶 Product Catalog'!$O$27="🟠 Low stock",'🧶 Product Catalog'!$O$27="🔴 Out of stock"),1+SUMPRODUCT(('🧶 Product Catalog'!$O$8:$O$26="🟠 Low stock")+('🧶 Product Catalog'!$O$8:$O$26="🔴 Out of stock")),"") | AL21: 27
V22: =IF('🧶 Product Catalog'!$C$28="","",'🧶 Product Catalog'!$C$28) | W22: =IF($V22="",0,SUMIFS('💰 Sales Log'!$E$8:$E$67,'💰 Sales Log'!$D$8:$D$67,$V22)) -> 0 | X22: =IF($V22="",0,SUMIFS('💰 Sales Log'!$H$8:$H$67,'💰 Sales Log'!$D$8:$D$67,$V22)) -> 0 | Y22: =IF($V22="","",'🧶 Product Catalog'!$M$28) | Z22: =IF($W22>0,'🧶 Product Catalog'!$K$28,0) -> 0 | AA22: =IF($V22="","",$W22) | AB22: =IFERROR(ROUND($W22*'🧶 Product Catalog'!$J$28,2),0) -> 0 | AC22: =IF('🏪 Craft Fairs'!$B$28="","",'🏪 Craft Fairs'!$B$28) | AD22: =IF($AC22="","",'🏪 Craft Fairs'!$N$28) | AE22: =IF($AC22="","",'🏪 Craft Fairs'!$P$28) | AF22: =IF($AC22="","",'🏪 Craft Fairs'!$M$28) | AG22: =IF(AND('🏪 Craft Fairs'!$C$28<>"",'🏪 Craft Fairs'!$C$28>=TODAY()),'🏪 Craft Fairs'!$C$28,"") | AH22: Most units sold | AI22: =IFERROR(INDEX($V$2:$V$25,MATCH(MAX($W$2:$W$25),$W$2:$W$25,0)),"") | AK22: =IF(OR('🧶 Product Catalog'!$O$28="🟠 Low stock",'🧶 Product Catalog'!$O$28="🔴 Out of stock"),1+SUMPRODUCT(('🧶 Product Catalog'!$O$8:$O$27="🟠 Low stock")+('🧶 Product Catalog'!$O$8:$O$27="🔴 Out of stock")),"") | AL22: 28
V23: =IF('🧶 Product Catalog'!$C$29="","",'🧶 Product Catalog'!$C$29) | W23: =IF($V23="",0,SUMIFS('💰 Sales Log'!$E$8:$E$67,'💰 Sales Log'!$D$8:$D$67,$V23)) -> 0 | X23: =IF($V23="",0,SUMIFS('💰 Sales Log'!$H$8:$H$67,'💰 Sales Log'!$D$8:$D$67,$V23)) -> 0 | Y23: =IF($V23="","",'🧶 Product Catalog'!$M$29) | Z23: =IF($W23>0,'🧶 Product Catalog'!$K$29,0) -> 0 | AA23: =IF($V23="","",$W23) | AB23: =IFERROR(ROUND($W23*'🧶 Product Catalog'!$J$29,2),0) -> 0 | AC23: =IF('🏪 Craft Fairs'!$B$29="","",'🏪 Craft Fairs'!$B$29) | AD23: =IF($AC23="","",'🏪 Craft Fairs'!$N$29) | AE23: =IF($AC23="","",'🏪 Craft Fairs'!$P$29) | AF23: =IF($AC23="","",'🏪 Craft Fairs'!$M$29) | AG23: =IF(AND('🏪 Craft Fairs'!$C$29<>"",'🏪 Craft Fairs'!$C$29>=TODAY()),'🏪 Craft Fairs'!$C$29,"") | AH23: Highest revenue product | AI23: =IFERROR(INDEX($V$2:$V$25,MATCH(MAX($X$2:$X$25),$X$2:$X$25,0)),"") | AK23: =IF(OR('🧶 Product Catalog'!$O$29="🟠 Low stock",'🧶 Product Catalog'!$O$29="🔴 Out of stock"),1+SUMPRODUCT(('🧶 Product Catalog'!$O$8:$O$28="🟠 Low stock")+('🧶 Product Catalog'!$O$8:$O$28="🔴 Out of stock")),"") | AL23: 29
V24: =IF('🧶 Product Catalog'!$C$30="","",'🧶 Product Catalog'!$C$30) | W24: =IF($V24="",0,SUMIFS('💰 Sales Log'!$E$8:$E$67,'💰 Sales Log'!$D$8:$D$67,$V24)) -> 0 | X24: =IF($V24="",0,SUMIFS('💰 Sales Log'!$H$8:$H$67,'💰 Sales Log'!$D$8:$D$67,$V24)) -> 0 | Y24: =IF($V24="","",'🧶 Product Catalog'!$M$30) | Z24: =IF($W24>0,'🧶 Product Catalog'!$K$30,0) -> 0 | AA24: =IF($V24="","",$W24) | AB24: =IFERROR(ROUND($W24*'🧶 Product Catalog'!$J$30,2),0) -> 0 | AC24: =IF('🏪 Craft Fairs'!$B$30="","",'🏪 Craft Fairs'!$B$30) | AD24: =IF($AC24="","",'🏪 Craft Fairs'!$N$30) | AE24: =IF($AC24="","",'🏪 Craft Fairs'!$P$30) | AF24: =IF($AC24="","",'🏪 Craft Fairs'!$M$30) | AG24: =IF(AND('🏪 Craft Fairs'!$C$30<>"",'🏪 Craft Fairs'!$C$30>=TODAY()),'🏪 Craft Fairs'!$C$30,"") | AH24: Highest profit product | AI24: =IFERROR(INDEX($V$2:$V$25,MATCH(MAX($AB$2:$AB$25),$AB$2:$AB$25,0)),"") | AK24: =IF(OR('🧶 Product Catalog'!$O$30="🟠 Low stock",'🧶 Product Catalog'!$O$30="🔴 Out of stock"),1+SUMPRODUCT(('🧶 Product Catalog'!$O$8:$O$29="🟠 Low stock")+('🧶 Product Catalog'!$O$8:$O$29="🔴 Out of stock")),"") | AL24: 30
V25: =IF('🧶 Product Catalog'!$C$31="","",'🧶 Product Catalog'!$C$31) | W25: =IF($V25="",0,SUMIFS('💰 Sales Log'!$E$8:$E$67,'💰 Sales Log'!$D$8:$D$67,$V25)) -> 0 | X25: =IF($V25="",0,SUMIFS('💰 Sales Log'!$H$8:$H$67,'💰 Sales Log'!$D$8:$D$67,$V25)) -> 0 | Y25: =IF($V25="","",'🧶 Product Catalog'!$M$31) | Z25: =IF($W25>0,'🧶 Product Catalog'!$K$31,0) -> 0 | AA25: =IF($V25="","",$W25) | AB25: =IFERROR(ROUND($W25*'🧶 Product Catalog'!$J$31,2),0) -> 0 | AC25: =IF('🏪 Craft Fairs'!$B$31="","",'🏪 Craft Fairs'!$B$31) | AD25: =IF($AC25="","",'🏪 Craft Fairs'!$N$31) | AE25: =IF($AC25="","",'🏪 Craft Fairs'!$P$31) | AF25: =IF($AC25="","",'🏪 Craft Fairs'!$M$31) | AG25: =IF(AND('🏪 Craft Fairs'!$C$31<>"",'🏪 Craft Fairs'!$C$31>=TODAY()),'🏪 Craft Fairs'!$C$31,"") | AH25: Highest margin product | AI25: =IFERROR(INDEX($V$2:$V$25,MATCH(MAX($Z$2:$Z$25),$Z$2:$Z$25,0)),"") | AK25: =IF(OR('🧶 Product Catalog'!$O$31="🟠 Low stock",'🧶 Product Catalog'!$O$31="🔴 Out of stock"),1+SUMPRODUCT(('🧶 Product Catalog'!$O$8:$O$30="🟠 Low stock")+('🧶 Product Catalog'!$O$8:$O$30="🔴 Out of stock")),"") | AL25: 31
AH26: Slowest mover | AI26: =IFERROR(INDEX($V$2:$V$25,MATCH(MIN($AA$2:$AA$25),$AA$2:$AA$25,0)),"")
AH27: Pricing calculator: suggested price | AI27: ='💵 Pricing Calculator'!$J$17 -> 0

Sheet ⚙️ Lists & Settings
B2: ⚙️ Lists & Settings — make it yours
B3: Set these once and every tab, calculator, alert and dropdown follows automatically. | H3: 🏠 Back to Dashboard
B5: 🏷️ BUSINESS PROFILE
B6: Business name (dashboard header)
B7: Dashboard message of the day
B9: 💵 MONEY & SEASON DEFAULTS
B10: Currency symbol | C10: $
B11: Report year (monthly summary) | C11: 2026
B12: Your hourly wage (pricing calculator) | C12: 14
B13: Overhead % on top of direct costs | C13: 0.1
B14: Default target profit margin | C14: 0.45
B21: 📝 YOUR DROPDOWN LISTS (edit freely)
C22: Product categories | D22: Payment methods | E22: Yarn weights | F22: Units | G22: Suppliers
C23: Toys & Amigurumi | D23: Cash | E23: Lace | F23: balls | G23: Local yarn shop
C24: Wearables | D24: Card | E24: Sock / 4-ply | F24: metres | G24: Online yarn store
C25: Home & Decor | D25: Bank transfer | E25: DK / light | F25: grams | G25: Wholesale craft
C26: Accessories | D26: Mobile wallet | E26: Worsted / aran | F26: skeins | G26: Market stall
C27: Baby & Kids | D27: Online order | E27: Chunky | F27: cones | G27: Second-hand / stash
C28: Seasonal | D28: Other | E28: Super chunky | F28: pieces | G28: Other
E29: Mixed / other
B43: These five columns feed every dropdown in the workbook. Add, rename or delete entries and the catalog, sales log and reorder list update instantly.
B45: 🔒 FIXED LIST (do not edit)
C46: Tick box
C47: ✓
B52: 💡 Cream cells are inputs everywhere in this workbook; white cells are formulas. Sheets are protected (no password) so nothing breaks by accident.
B54: ▶ Settings | D54: 🏠 Home | F54: Products | H54: Fairs
B55: Sales | D55: Pricing | F55: Help

Sheet 📊 Dashboard
B2: =IF(BusinessName="","🧶 Craft Fair Command Center","🧶 "&BusinessName&" • Craft Fair Command Center") -> 🧶 Craft Fair Command Center
B3: =IFERROR(TEXT(MIN('_Data'!$AG$2:$AG$25),"dd mmm")&" — "&INDEX('🏪 Craft Fairs'!$B$8:$B$31,MATCH(MIN('_Data'!$AG$2:$AG$25),'🏪 Craft Fairs'!$C$8:$C$31,0))&" is next — pack the van!","🌴 No upcoming fairs logged — add one on the 🏪 Craft Fairs tab!")
B4: =TEXT(TODAY(),"dddd, dd mmmm yyyy")&" • "&'_Data'!$AI$12&" fairs on the books • "&Currency&TEXT('_Data'!$AI$2,"#,##0")&" taken at the till • "&Currency&TEXT('_Data'!$AI$6,"#,##0")&" net profit so far"
B5: =IF('⚙️ Lists & Settings'!$C$7="","","📣 "&'⚙️ Lists & Settings'!$C$7)
B7: 🧶 BUSINESS AT A GLANCE
B8: TOTAL SALES | D8: NET PROFIT | F8: PROFIT MARGIN | H8: UNITS SOLD | J8: FAIRS WORKED | L8: AVERAGE SALE
B9: =Currency&TEXT('_Data'!$AI$2,"#,##0") -> 0 | D9: =Currency&TEXT('_Data'!$AI$6,"#,##0") -> 0 | F9: =TEXT('_Data'!$AI$7,"0%") -> 0% | H9: ='_Data'!$AI$8 -> 0 | J9: ='_Data'!$AI$13 -> 0 | L9: =Currency&TEXT('_Data'!$AI$10,"#,##0.00") -> 0
B10: INVENTORY VALUE | D10: LOW-STOCK ITEMS | F10: SELL-THROUGH | H10: BEST-SELLER | J10: TOP FAIR | L10: REORDER BUDGET
B11: =Currency&TEXT('_Data'!$AI$14,"#,##0.00") -> 0 | D11: ='_Data'!$AI$15+'_Data'!$AI$16 -> 0 | F11: =TEXT('_Data'!$AI$18,"0%") -> 0% | H11: ='_Data'!$AI$22 | J11: ='_Data'!$AI$21 | L11: =Currency&TEXT('_Data'!$AI$17,"#,##0.00") -> 0
B12: Net margin | D12: =IFERROR(REPT("█",ROUND(MIN(1,IFERROR(('_Data'!$AI$6)/('_Data'!$AI$2),0))*34,0))&REPT("░",34-ROUND(MIN(1,IFERROR(('_Data'!$AI$6)/('_Data'!$AI$2),0))*34,0)),"░░░░░░░░░░░░░░░░░░░░░░░░░░░░░░░░░░") -> ░░░░░░░░░░░░░░░░░░░░░░░░░░░░░░░░░░ | K12: =TEXT(IFERROR('_Data'!$AI$6/'_Data'!$AI$2,0),"0.0%") -> 0.0%
B13: Sell-through (sold ÷ made) | D13: =IFERROR(REPT("█",ROUND(MIN(1,IFERROR(('_Data'!$AI$8)/('_Data'!$AI$19),0))*34,0))&REPT("░",34-ROUND(MIN(1,IFERROR(('_Data'!$AI$8)/('_Data'!$AI$19),0))*34,0)),"░░░░░░░░░░░░░░░░░░░░░░░░░░░░░░░░░░") -> ░░░░░░░░░░░░░░░░░░░░░░░░░░░░░░░░░░ | K13: =TEXT(IFERROR('_Data'!$AI$8/'_Data'!$AI$19,0),"0.0%") -> 0.0%
B65: 🏆 BEST-SELLERS | H65: 🔴 LOW STOCK RIGHT NOW
B66: Most units sold | D66: ='_Data'!$AI$22 | H66: =IFERROR(INDEX('🧶 Product Catalog'!$C$8:$C$31,MATCH(1,'_Data'!$AK$2:$AK$25,0)),"") | L66: =IFERROR(INDEX('🧶 Product Catalog'!$M$8:$M$31,MATCH(1,'_Data'!$AK$2:$AK$25,0))&" left (min "&INDEX('🧶 Product Catalog'!$N$8:$N$31,MATCH(1,'_Data'!$AK$2:$AK$25,0))&")","")
B67: Highest revenue | D67: ='_Data'!$AI$23 | H67: =IFERROR(INDEX('🧶 Product Catalog'!$C$8:$C$31,MATCH(2,'_Data'!$AK$2:$AK$25,0)),"") | L67: =IFERROR(INDEX('🧶 Product Catalog'!$M$8:$M$31,MATCH(2,'_Data'!$AK$2:$AK$25,0))&" left (min "&INDEX('🧶 Product Catalog'!$N$8:$N$31,MATCH(2,'_Data'!$AK$2:$AK$25,0))&")","")
B68: Highest profit | D68: ='_Data'!$AI$24 | H68: =IFERROR(INDEX('🧶 Product Catalog'!$C$8:$C$31,MATCH(3,'_Data'!$AK$2:$AK$25,0)),"") | L68: =IFERROR(INDEX('🧶 Product Catalog'!$M$8:$M$31,MATCH(3,'_Data'!$AK$2:$AK$25,0))&" left (min "&INDEX('🧶 Product Catalog'!$N$8:$N$31,MATCH(3,'_Data'!$AK$2:$AK$25,0))&")","")
B69: Highest margin | D69: ='_Data'!$AI$25 | H69: =IFERROR(INDEX('🧶 Product Catalog'!$C$8:$C$31,MATCH(4,'_Data'!$AK$2:$AK$25,0)),"") | L69: =IFERROR(INDEX('🧶 Product Catalog'!$M$8:$M$31,MATCH(4,'_Data'!$AK$2:$AK$25,0))&" left (min "&INDEX('🧶 Product Catalog'!$N$8:$N$31,MATCH(4,'_Data'!$AK$2:$AK$25,0))&")","")
B70: Slowest mover | D70: ='_Data'!$AI$26 | H70: =IFERROR(INDEX('🧶 Product Catalog'!$C$8:$C$31,MATCH(5,'_Data'!$AK$2:$AK$25,0)),"") | L70: =IFERROR(INDEX('🧶 Product Catalog'!$M$8:$M$31,MATCH(5,'_Data'!$AK$2:$AK$25,0))&" left (min "&INDEX('🧶 Product Catalog'!$N$8:$N$31,MATCH(5,'_Data'!$AK$2:$AK$25,0))&")","")
B73: 💡 Everything on this page is calculated — type your makes and sales into the tabs and watch it update. Start with the 📖 Start Here guide and ⚙️ Lists & Settings.
B75: Settings | D75: ▶ 🏠 Home | F75: Products | H75: Fairs | J75: Sales | L75: Pricing
B76: Help

Sheet 🧶 Product Catalog
B2: 🧶 Product Catalog
B3: Everything you make, what it costs you and what it earns you - stock counts flow in from 📦 Made & Stocked. | N3: 🏠 Dashboard
B5: ="🧶 Products: "&COUNTA('🧶 Product Catalog'!$C$8:$C$31) -> Products: 0 | E5: ="💰 Stock value: "&Currency&TEXT(SUMPRODUCT(IFERROR('🧶 Product Catalog'!$M$8:$M$31*1,0)*IFERROR('🧶 Product Catalog'!$I$8:$I$31*1,0)),"#,##0.00") -> Stock value: $0.00 | I5: ="🔴 Below minimum: "&'_Data'!$AI$15 -> Below minimum: 0 | M5: ="📈 Avg margin: "&TEXT(IFERROR(AVERAGE('🧶 Product Catalog'!$K$8:$K$31),0),"0%") -> Avg margin: 0%
A7: # | B7: SKU | C7: Product name | D7: Category | E7: Description | F7: Selling price | G7: Yarn / material | H7: Packaging | I7: Unit cost | J7: Profit / item | K7: Margin % | L7: Hours | M7: In stock | N7: Min level | O7: Reorder status | P7: Photo / link
A8: 1 | I8: =IF($C8="","",$G8+$H8) -> 0 | J8: =IF($F8="","",$F8-$I8) -> 0 | K8: =IF($F8="","",$J8/$F8) -> 0 | O8: =IF($C8="","",IF($M8<=0,"🔴 Out of stock",IF($M8<$N8,"🟠 Low stock","🟢 In stock"))) -> 0
A9: 2 | I9: =IF($C9="","",$G9+$H9) -> 0 | J9: =IF($F9="","",$F9-$I9) -> 0 | K9: =IF($F9="","",$J9/$F9) -> 0 | O9: =IF($C9="","",IF($M9<=0,"🔴 Out of stock",IF($M9<$N9,"🟠 Low stock","🟢 In stock"))) -> 0
A10: 3 | I10: =IF($C10="","",$G10+$H10) -> 0 | J10: =IF($F10="","",$F10-$I10) -> 0 | K10: =IF($F10="","",$J10/$F10) -> 0 | O10: =IF($C10="","",IF($M10<=0,"🔴 Out of stock",IF($M10<$N10,"🟠 Low stock","🟢 In stock"))) -> 0
A11: 4 | I11: =IF($C11="","",$G11+$H11) -> 0 | J11: =IF($F11="","",$F11-$I11) -> 0 | K11: =IF($F11="","",$J11/$F11) -> 0 | O11: =IF($C11="","",IF($M11<=0,"🔴 Out of stock",IF($M11<$N11,"🟠 Low stock","🟢 In stock"))) -> 0
A12: 5 | I12: =IF($C12="","",$G12+$H12) -> 0 | J12: =IF($F12="","",$F12-$I12) -> 0 | K12: =IF($F12="","",$J12/$F12) -> 0 | O12: =IF($C12="","",IF($M12<=0,"🔴 Out of stock",IF($M12<$N12,"🟠 Low stock","🟢 In stock"))) -> 0
A13: 6 | I13: =IF($C13="","",$G13+$H13) -> 0 | J13: =IF($F13="","",$F13-$I13) -> 0 | K13: =IF($F13="","",$J13/$F13) -> 0 | O13: =IF($C13="","",IF($M13<=0,"🔴 Out of stock",IF($M13<$N13,"🟠 Low stock","🟢 In stock"))) -> 0
A14: 7 | I14: =IF($C14="","",$G14+$H14) -> 0 | J14: =IF($F14="","",$F14-$I14) -> 0 | K14: =IF($F14="","",$J14/$F14) -> 0 | O14: =IF($C14="","",IF($M14<=0,"🔴 Out of stock",IF($M14<$N14,"🟠 Low stock","🟢 In stock"))) -> 0
A15: 8 | I15: =IF($C15="","",$G15+$H15) -> 0 | J15: =IF($F15="","",$F15-$I15) -> 0 | K15: =IF($F15="","",$J15/$F15) -> 0 | O15: =IF($C15="","",IF($M15<=0,"🔴 Out of stock",IF($M15<$N15,"🟠 Low stock","🟢 In stock"))) -> 0
A16: 9 | I16: =IF($C16="","",$G16+$H16) -> 0 | J16: =IF($F16="","",$F16-$I16) -> 0 | K16: =IF($F16="","",$J16/$F16) -> 0 | O16: =IF($C16="","",IF($M16<=0,"🔴 Out of stock",IF($M16<$N16,"🟠 Low stock","🟢 In stock"))) -> 0
A17: 10 | I17: =IF($C17="","",$G17+$H17) -> 0 | J17: =IF($F17="","",$F17-$I17) -> 0 | K17: =IF($F17="","",$J17/$F17) -> 0 | O17: =IF($C17="","",IF($M17<=0,"🔴 Out of stock",IF($M17<$N17,"🟠 Low stock","🟢 In stock"))) -> 0
A18: 11 | I18: =IF($C18="","",$G18+$H18) -> 0 | J18: =IF($F18="","",$F18-$I18) -> 0 | K18: =IF($F18="","",$J18/$F18) -> 0 | O18: =IF($C18="","",IF($M18<=0,"🔴 Out of stock",IF($M18<$N18,"🟠 Low stock","🟢 In stock"))) -> 0
A19: 12 | I19: =IF($C19="","",$G19+$H19) -> 0 | J19: =IF($F19="","",$F19-$I19) -> 0 | K19: =IF($F19="","",$J19/$F19) -> 0 | O19: =IF($C19="","",IF($M19<=0,"🔴 Out of stock",IF($M19<$N19,"🟠 Low stock","🟢 In stock"))) -> 0
... A31: 24 | I31: =IF($C31="","",$G31+$H31) -> 0 | J31: =IF($F31="","",$F31-$I31) -> 0 | K31: =IF($F31="","",$J31/$F31) -> 0 | O31: =IF($C31="","",IF($M31<=0,"🔴 Out of stock",IF($M31<$N31,"🟠 Low stock","🟢 In stock"))) -> 0
B34: 💡 Cream cells are yours to type in; white cells calculate. Dropdowns keep every column honest.
B36: Settings | D36: 🏠 Home | F36: ▶ Products | H36: Fairs | J36: Sales | L36: Pricing | N36: Help

Sheet 🏪 Craft Fairs
B2: 🏪 Craft Fairs
B3: Every market you work - sales, costs and best seller pull straight from the 💰 Sales Log. | P3: 🏠 Dashboard
B5: ="🏪 Fairs logged: "&COUNTA('🏪 Craft Fairs'!$B$8:$B$31) -> Fairs logged: 0 | E5: ="✅ Worked: "&'_Data'!$AI$13 -> Worked: 0 | H5: ="💰 Takings: "&Currency&TEXT(SUM('🏪 Craft Fairs'!$N$8:$N$31),"#,##0") -> Takings: $0 | K5: ="🏆 Best fair: "&'_Data'!$AI$21 -> Best fair:
A7: # | B7: Fair / event | C7: Date | D7: Location | E7: Organizer | F7: Booth fee | G7: Travel | H7: Parking | I7: Food / other | J7: Display | K7: Total expenses | L7: Items taken | M7: Items sold | N7: Total sales | O7: Product cost | P7: Net profit | Q7: Margin | R7: Best seller
A8: 1 | K8: =IF($B8="","",SUM($F8:$J8)) -> 0 | M8: =IF($B8="","",SUMIFS('💰 Sales Log'!$E$8:$E$67,'💰 Sales Log'!$C$8:$C$67,$B8)) -> 0 | N8: =IF($B8="","",SUMIFS('💰 Sales Log'!$H$8:$H$67,'💰 Sales Log'!$C$8:$C$67,$B8)) -> 0 | O8: =IF($B8="","",SUMIFS('💰 Sales Log'!$M$8:$M$67,'💰 Sales Log'!$C$8:$C$67,$B8)) -> 0 | P8: =IF($N8="","",$N8-$K8-$O8) -> 0 | Q8: =IF($N8="","",IF($N8=0,"",$P8/$N8)) -> 0 | R8: =IF($B8="","",IFERROR(INDEX('💰 Sales Log'!$D$8:$D$67,MATCH(1,INDEX(('💰 Sales Log'!$C$8:$C$67=$B8)*('💰 Sales Log'!$L$8:$L$67=SUMPRODUCT(MAX(('💰 Sales Log'!$C$8:$C$67=$B8)*'💰 Sales Log'!$L$8:$L$67))),0),0)),"")) -> 0
A9: 2 | K9: =IF($B9="","",SUM($F9:$J9)) -> 0 | M9: =IF($B9="","",SUMIFS('💰 Sales Log'!$E$8:$E$67,'💰 Sales Log'!$C$8:$C$67,$B9)) -> 0 | N9: =IF($B9="","",SUMIFS('💰 Sales Log'!$H$8:$H$67,'💰 Sales Log'!$C$8:$C$67,$B9)) -> 0 | O9: =IF($B9="","",SUMIFS('💰 Sales Log'!$M$8:$M$67,'💰 Sales Log'!$C$8:$C$67,$B9)) -> 0 | P9: =IF($N9="","",$N9-$K9-$O9) -> 0 | Q9: =IF($N9="","",IF($N9=0,"",$P9/$N9)) -> 0 | R9: =IF($B9="","",IFERROR(INDEX('💰 Sales Log'!$D$8:$D$67,MATCH(1,INDEX(('💰 Sales Log'!$C$8:$C$67=$B9)*('💰 Sales Log'!$L$8:$L$67=SUMPRODUCT(MAX(('💰 Sales Log'!$C$8:$C$67=$B9)*'💰 Sales Log'!$L$8:$L$67))),0),0)),"")) -> 0
A10: 3 | K10: =IF($B10="","",SUM($F10:$J10)) -> 0 | M10: =IF($B10="","",SUMIFS('💰 Sales Log'!$E$8:$E$67,'💰 Sales Log'!$C$8:$C$67,$B10)) -> 0 | N10: =IF($B10="","",SUMIFS('💰 Sales Log'!$H$8:$H$67,'💰 Sales Log'!$C$8:$C$67,$B10)) -> 0 | O10: =IF($B10="","",SUMIFS('💰 Sales Log'!$M$8:$M$67,'💰 Sales Log'!$C$8:$C$67,$B10)) -> 0 | P10: =IF($N10="","",$N10-$K10-$O10) -> 0 | Q10: =IF($N10="","",IF($N10=0,"",$P10/$N10)) -> 0 | R10: =IF($B10="","",IFERROR(INDEX('💰 Sales Log'!$D$8:$D$67,MATCH(1,INDEX(('💰 Sales Log'!$C$8:$C$67=$B10)*('💰 Sales Log'!$L$8:$L$67=SUMPRODUCT(MAX(('💰 Sales Log'!$C$8:$C$67=$B10)*'💰 Sales Log'!$L$8:$L$67))),0),0)),"")) -> 0
A11: 4 | K11: =IF($B11="","",SUM($F11:$J11)) -> 0 | M11: =IF($B11="","",SUMIFS('💰 Sales Log'!$E$8:$E$67,'💰 Sales Log'!$C$8:$C$67,$B11)) -> 0 | N11: =IF($B11="","",SUMIFS('💰 Sales Log'!$H$8:$H$67,'💰 Sales Log'!$C$8:$C$67,$B11)) -> 0 | O11: =IF($B11="","",SUMIFS('💰 Sales Log'!$M$8:$M$67,'💰 Sales Log'!$C$8:$C$67,$B11)) -> 0 | P11: =IF($N11="","",$N11-$K11-$O11) -> 0 | Q11: =IF($N11="","",IF($N11=0,"",$P11/$N11)) -> 0 | R11: =IF($B11="","",IFERROR(INDEX('💰 Sales Log'!$D$8:$D$67,MATCH(1,INDEX(('💰 Sales Log'!$C$8:$C$67=$B11)*('💰 Sales Log'!$L$8:$L$67=SUMPRODUCT(MAX(('💰 Sales Log'!$C$8:$C$67=$B11)*'💰 Sales Log'!$L$8:$L$67))),0),0)),"")) -> 0
A12: 5 | K12: =IF($B12="","",SUM($F12:$J12)) -> 0 | M12: =IF($B12="","",SUMIFS('💰 Sales Log'!$E$8:$E$67,'💰 Sales Log'!$C$8:$C$67,$B12)) -> 0 | N12: =IF($B12="","",SUMIFS('💰 Sales Log'!$H$8:$H$67,'💰 Sales Log'!$C$8:$C$67,$B12)) -> 0 | O12: =IF($B12="","",SUMIFS('💰 Sales Log'!$M$8:$M$67,'💰 Sales Log'!$C$8:$C$67,$B12)) -> 0 | P12: =IF($N12="","",$N12-$K12-$O12) -> 0 | Q12: =IF($N12="","",IF($N12=0,"",$P12/$N12)) -> 0 | R12: =IF($B12="","",IFERROR(INDEX('💰 Sales Log'!$D$8:$D$67,MATCH(1,INDEX(('💰 Sales Log'!$C$8:$C$67=$B12)*('💰 Sales Log'!$L$8:$L$67=SUMPRODUCT(MAX(('💰 Sales Log'!$C$8:$C$67=$B12)*'💰 Sales Log'!$L$8:$L$67))),0),0)),"")) -> 0
A13: 6 | K13: =IF($B13="","",SUM($F13:$J13)) -> 0 | M13: =IF($B13="","",SUMIFS('💰 Sales Log'!$E$8:$E$67,'💰 Sales Log'!$C$8:$C$67,$B13)) -> 0 | N13: =IF($B13="","",SUMIFS('💰 Sales Log'!$H$8:$H$67,'💰 Sales Log'!$C$8:$C$67,$B13)) -> 0 | O13: =IF($B13="","",SUMIFS('💰 Sales Log'!$M$8:$M$67,'💰 Sales Log'!$C$8:$C$67,$B13)) -> 0 | P13: =IF($N13="","",$N13-$K13-$O13) -> 0 | Q13: =IF($N13="","",IF($N13=0,"",$P13/$N13)) -> 0 | R13: =IF($B13="","",IFERROR(INDEX('💰 Sales Log'!$D$8:$D$67,MATCH(1,INDEX(('💰 Sales Log'!$C$8:$C$67=$B13)*('💰 Sales Log'!$L$8:$L$67=SUMPRODUCT(MAX(('💰 Sales Log'!$C$8:$C$67=$B13)*'💰 Sales Log'!$L$8:$L$67))),0),0)),"")) -> 0
A14: 7 | K14: =IF($B14="","",SUM($F14:$J14)) -> 0 | M14: =IF($B14="","",SUMIFS('💰 Sales Log'!$E$8:$E$67,'💰 Sales Log'!$C$8:$C$67,$B14)) -> 0 | N14: =IF($B14="","",SUMIFS('💰 Sales Log'!$H$8:$H$67,'💰 Sales Log'!$C$8:$C$67,$B14)) -> 0 | O14: =IF($B14="","",SUMIFS('💰 Sales Log'!$M$8:$M$67,'💰 Sales Log'!$C$8:$C$67,$B14)) -> 0 | P14: =IF($N14="","",$N14-$K14-$O14) -> 0 | Q14: =IF($N14="","",IF($N14=0,"",$P14/$N14)) -> 0 | R14: =IF($B14="","",IFERROR(INDEX('💰 Sales Log'!$D$8:$D$67,MATCH(1,INDEX(('💰 Sales Log'!$C$8:$C$67=$B14)*('💰 Sales Log'!$L$8:$L$67=SUMPRODUCT(MAX(('💰 Sales Log'!$C$8:$C$67=$B14)*'💰 Sales Log'!$L$8:$L$67))),0),0)),"")) -> 0
A15: 8 | K15: =IF($B15="","",SUM($F15:$J15)) -> 0 | M15: =IF($B15="","",SUMIFS('💰 Sales Log'!$E$8:$E$67,'💰 Sales Log'!$C$8:$C$67,$B15)) -> 0 | N15: =IF($B15="","",SUMIFS('💰 Sales Log'!$H$8:$H$67,'💰 Sales Log'!$C$8:$C$67,$B15)) -> 0 | O15: =IF($B15="","",SUMIFS('💰 Sales Log'!$M$8:$M$67,'💰 Sales Log'!$C$8:$C$67,$B15)) -> 0 | P15: =IF($N15="","",$N15-$K15-$O15) -> 0 | Q15: =IF($N15="","",IF($N15=0,"",$P15/$N15)) -> 0 | R15: =IF($B15="","",IFERROR(INDEX('💰 Sales Log'!$D$8:$D$67,MATCH(1,INDEX(('💰 Sales Log'!$C$8:$C$67=$B15)*('💰 Sales Log'!$L$8:$L$67=SUMPRODUCT(MAX(('💰 Sales Log'!$C$8:$C$67=$B15)*'💰 Sales Log'!$L$8:$L$67))),0),0)),"")) -> 0
A16: 9 | K16: =IF($B16="","",SUM($F16:$J16)) -> 0 | M16: =IF($B16="","",SUMIFS('💰 Sales Log'!$E$8:$E$67,'💰 Sales Log'!$C$8:$C$67,$B16)) -> 0 | N16: =IF($B16="","",SUMIFS('💰 Sales Log'!$H$8:$H$67,'💰 Sales Log'!$C$8:$C$67,$B16)) -> 0 | O16: =IF($B16="","",SUMIFS('💰 Sales Log'!$M$8:$M$67,'💰 Sales Log'!$C$8:$C$67,$B16)) -> 0 | P16: =IF($N16="","",$N16-$K16-$O16) -> 0 | Q16: =IF($N16="","",IF($N16=0,"",$P16/$N16)) -> 0 | R16: =IF($B16="","",IFERROR(INDEX('💰 Sales Log'!$D$8:$D$67,MATCH(1,INDEX(('💰 Sales Log'!$C$8:$C$67=$B16)*('💰 Sales Log'!$L$8:$L$67=SUMPRODUCT(MAX(('💰 Sales Log'!$C$8:$C$67=$B16)*'💰 Sales Log'!$L$8:$L$67))),0),0)),"")) -> 0
A17: 10 | K17: =IF($B17="","",SUM($F17:$J17)) -> 0 | M17: =IF($B17="","",SUMIFS('💰 Sales Log'!$E$8:$E$67,'💰 Sales Log'!$C$8:$C$67,$B17)) -> 0 | N17: =IF($B17="","",SUMIFS('💰 Sales Log'!$H$8:$H$67,'💰 Sales Log'!$C$8:$C$67,$B17)) -> 0 | O17: =IF($B17="","",SUMIFS('💰 Sales Log'!$M$8:$M$67,'💰 Sales Log'!$C$8:$C$67,$B17)) -> 0 | P17: =IF($N17="","",$N17-$K17-$O17) -> 0 | Q17: =IF($N17="","",IF($N17=0,"",$P17/$N17)) -> 0 | R17: =IF($B17="","",IFERROR(INDEX('💰 Sales Log'!$D$8:$D$67,MATCH(1,INDEX(('💰 Sales Log'!$C$8:$C$67=$B17)*('💰 Sales Log'!$L$8:$L$67=SUMPRODUCT(MAX(('💰 Sales Log'!$C$8:$C$67=$B17)*'💰 Sales Log'!$L$8:$L$67))),0),0)),"")) -> 0
A18: 11 | K18: =IF($B18="","",SUM($F18:$J18)) -> 0 | M18: =IF($B18="","",SUMIFS('💰 Sales Log'!$E$8:$E$67,'💰 Sales Log'!$C$8:$C$67,$B18)) -> 0 | N18: =IF($B18="","",SUMIFS('💰 Sales Log'!$H$8:$H$67,'💰 Sales Log'!$C$8:$C$67,$B18)) -> 0 | O18: =IF($B18="","",SUMIFS('💰 Sales Log'!$M$8:$M$67,'💰 Sales Log'!$C$8:$C$67,$B18)) -> 0 | P18: =IF($N18="","",$N18-$K18-$O18) -> 0 | Q18: =IF($N18="","",IF($N18=0,"",$P18/$N18)) -> 0 | R18: =IF($B18="","",IFERROR(INDEX('💰 Sales Log'!$D$8:$D$67,MATCH(1,INDEX(('💰 Sales Log'!$C$8:$C$67=$B18)*('💰 Sales Log'!$L$8:$L$67=SUMPRODUCT(MAX(('💰 Sales Log'!$C$8:$C$67=$B18)*'💰 Sales Log'!$L$8:$L$67))),0),0)),"")) -> 0
A19: 12 | K19: =IF($B19="","",SUM($F19:$J19)) -> 0 | M19: =IF($B19="","",SUMIFS('💰 Sales Log'!$E$8:$E$67,'💰 Sales Log'!$C$8:$C$67,$B19)) -> 0 | N19: =IF($B19="","",SUMIFS('💰 Sales Log'!$H$8:$H$67,'💰 Sales Log'!$C$8:$C$67,$B19)) -> 0 | O19: =IF($B19="","",SUMIFS('💰 Sales Log'!$M$8:$M$67,'💰 Sales Log'!$C$8:$C$67,$B19)) -> 0 | P19: =IF($N19="","",$N19-$K19-$O19) -> 0 | Q19: =IF($N19="","",IF($N19=0,"",$P19/$N19)) -> 0 | R19: =IF($B19="","",IFERROR(INDEX('💰 Sales Log'!$D$8:$D$67,MATCH(1,INDEX(('💰 Sales Log'!$C$8:$C$67=$B19)*('💰 Sales Log'!$L$8:$L$67=SUMPRODUCT(MAX(('💰 Sales Log'!$C$8:$C$67=$B19)*'💰 Sales Log'!$L$8:$L$67))),0),0)),"")) -> 0
... A31: 24 | K31: =IF($B31="","",SUM($F31:$J31)) -> 0 | M31: =IF($B31="","",SUMIFS('💰 Sales Log'!$E$8:$E$67,'💰 Sales Log'!$C$8:$C$67,$B31)) -> 0 | N31: =IF($B31="","",SUMIFS('💰 Sales Log'!$H$8:$H$67,'💰 Sales Log'!$C$8:$C$67,$B31)) -> 0 | O31: =IF($B31="","",SUMIFS('💰 Sales Log'!$M$8:$M$67,'💰 Sales Log'!$C$8:$C$67,$B31)) -> 0 | P31: =IF($N31="","",$N31-$K31-$O31) -> 0 | Q31: =IF($N31="","",IF($N31=0,"",$P31/$N31)) -> 0 | R31: =IF($B31="","",IFERROR(INDEX('💰 Sales Log'!$D$8:$D$67,MATCH(1,INDEX(('💰 Sales Log'!$C$8:$C$67=$B31)*('💰 Sales Log'!$L$8:$L$67=SUMPRODUCT(MAX(('💰 Sales Log'!$C$8:$C$67=$B31)*'💰 Sales Log'!$L$8:$L$67))),0),0)),"")) -> 0
B32: TOTALS | K32: =SUM(K8:K31) -> 0 | N32: =SUM(N8:N31) -> 0 | P32: =SUM(P8:P31) -> 0
B34: 💡 Wondering "should I do this market again?" Sort by Net profit, or check the ranking on the 📊 Dashboard.
B36: Settings | D36: 🏠 Home | F36: Products | H36: ▶ Fairs | J36: Sales | L36: Pricing | N36: Help

Sheet 💰 Sales Log
B2: 💰 Sales Log
B3: Log each sale once - the fair totals, dashboard, monthly summary and best-sellers all read this page. | K3: 🏠 Dashboard
B5: ="💰 Takings: "&Currency&TEXT(SUM('💰 Sales Log'!$H$8:$H$67),"#,##0.00") -> Takings: $0.00 | F5: ="🧶 Units: "&'_Data'!$AI$8 -> Units: 0 | H5: ="🧾 Sales logged: "&'_Data'!$AI$9 -> Sales logged: 0 | K5: ="🏷️ Discounts: "&Currency&TEXT(SUM('💰 Sales Log'!$G$8:$G$67),"#,##0.00") -> Discounts: $0.00
A7: # | B7: Date | C7: Fair / event | D7: Product | E7: Qty | F7: Unit price | G7: Discount | H7: Sale total | I7: Payment method | J7: Txn / ref # | K7: Notes | L7: Pair units | M7: Cost of sale
A8: 1 | H8: =IF($D8="","",IF($E8="","",E8*F8)-IF($G8="",0,$G8)) -> 0 | L8: =IF($C8="","",SUMIFS($E$8:$E$67,$C$8:$C$67,$C8,$D$8:$D$67,$D8)) -> 0 | M8: =IF($D8="","",$E8*IFERROR(INDEX('🧶 Product Catalog'!$I$8:$I$31,MATCH($D8,'🧶 Product Catalog'!$C$8:$C$31,0)),0)) -> 0
A9: 2 | H9: =IF($D9="","",IF($E9="","",E9*F9)-IF($G9="",0,$G9)) -> 0 | L9: =IF($C9="","",SUMIFS($E$8:$E$67,$C$8:$C$67,$C9,$D$8:$D$67,$D9)) -> 0 | M9: =IF($D9="","",$E9*IFERROR(INDEX('🧶 Product Catalog'!$I$8:$I$31,MATCH($D9,'🧶 Product Catalog'!$C$8:$C$31,0)),0)) -> 0
A10: 3 | H10: =IF($D10="","",IF($E10="","",E10*F10)-IF($G10="",0,$G10)) -> 0 | L10: =IF($C10="","",SUMIFS($E$8:$E$67,$C$8:$C$67,$C10,$D$8:$D$67,$D10)) -> 0 | M10: =IF($D10="","",$E10*IFERROR(INDEX('🧶 Product Catalog'!$I$8:$I$31,MATCH($D10,'🧶 Product Catalog'!$C$8:$C$31,0)),0)) -> 0
A11: 4 | H11: =IF($D11="","",IF($E11="","",E11*F11)-IF($G11="",0,$G11)) -> 0 | L11: =IF($C11="","",SUMIFS($E$8:$E$67,$C$8:$C$67,$C11,$D$8:$D$67,$D11)) -> 0 | M11: =IF($D11="","",$E11*IFERROR(INDEX('🧶 Product Catalog'!$I$8:$I$31,MATCH($D11,'🧶 Product Catalog'!$C$8:$C$31,0)),0)) -> 0
A12: 5 | H12: =IF($D12="","",IF($E12="","",E12*F12)-IF($G12="",0,$G12)) -> 0 | L12: =IF($C12="","",SUMIFS($E$8:$E$67,$C$8:$C$67,$C12,$D$8:$D$67,$D12)) -> 0 | M12: =IF($D12="","",$E12*IFERROR(INDEX('🧶 Product Catalog'!$I$8:$I$31,MATCH($D12,'🧶 Product Catalog'!$C$8:$C$31,0)),0)) -> 0
