Workbook
Name Actions: '⚙️ Settings & Instructions'!$E$46:$E$47
Name BudgetMax: '⚙️ Settings & Instructions'!$C$16
Name BudgetMin: '⚙️ Settings & Instructions'!$C$15
Name CoupleRule: '🚫 Exclusions & Rules'!$C$8
Name Currency: '⚙️ Settings & Instructions'!$C$10
Name Diets: OFFSET('⚙️ Settings & Instructions'!$D$26,0,0,MAX(1,COUNTA('⚙️ Settings & Instructions'!$D$26:$D$41)),1)
Name DrawSeed: '⚙️ Settings & Instructions'!$C$19
Name DrawStatus: '⚙️ Settings & Instructions'!$C$21
Name GiftNums: OFFSET('🎲 White Elephant'!$D$8,0,0,MAX(1,COUNTA('🎲 White Elephant'!$D$8:$D$31)),1)
Name LastYearRule: '🚫 Exclusions & Rules'!$C$10
Name MaxSteals: '⚙️ Settings & Instructions'!$C$17
Name Message: '⚙️ Settings & Instructions'!$C$7
Name OnOff: '⚙️ Settings & Instructions'!$H$46:$H$47
Name ParticipantsList: OFFSET('👥 Participants'!$B$8,0,0,MAX(1,COUNTA('👥 Participants'!$B$8:$B$31)),1)
Name PartyDate: '⚙️ Settings & Instructions'!$C$12
Name PartyHost: '⚙️ Settings & Instructions'!$C$14
Name PartyLocation: '⚙️ Settings & Instructions'!$C$13
Name PartyName: '⚙️ Settings & Instructions'!$C$6
Name PartyYear: '⚙️ Settings & Instructions'!$C$11
Name Priorities: '⚙️ Settings & Instructions'!$F$46:$F$48
Name RSVP: '⚙️ Settings & Instructions'!$D$46:$D$48
Name StartPlayer: '⚙️ Settings & Instructions'!$C$18
Name Statuses: '⚙️ Settings & Instructions'!$C$46:$C$49
Name TeamRule: '🚫 Exclusions & Rules'!$C$9
Name Teams: OFFSET('⚙️ Settings & Instructions'!$C$26,0,0,MAX(1,COUNTA('⚙️ Settings & Instructions'!$C$26:$C$41)),1)
Name Tick: '⚙️ Settings & Instructions'!$G$46:$G$47
Name WESeed: '⚙️ Settings & Instructions'!$C$20

Sheet _Data
AH1: Metric | AI1: Value
AH2: participants | AI2: =COUNTA('👥 Participants'!$B$8:$B$31) -> 12
AH3: rsvp_yes | AI3: =COUNTIF('👥 Participants'!$E$8:$E$31,"Yes") -> 10
AH4: rsvp_pending | AI4: =COUNTIF('👥 Participants'!$E$8:$E$31,"Maybe") -> 1
AH5: assigned | AI5: =SUMPRODUCT(--('🎅 Secret Santa Draw'!$E$8:$E$31<>"")) -> 12
AH6: purchased | AI6: =COUNTIF('👥 Participants'!$H$8:$H$31,"Gift Purchased")+COUNTIF('👥 Participants'!$H$8:$H$31,"Wrapped")+COUNTIF('👥 Participants'!$H$8:$H$31,"Complete") -> 10
AH7: wrapped | AI7: =COUNTIF('👥 Participants'!$H$8:$H$31,"Wrapped")+COUNTIF('👥 Participants'!$H$8:$H$31,"Complete") -> 5
AH8: complete | AI8: =COUNTIF('👥 Participants'!$H$8:$H$31,"Complete") -> 2
AH9: total_budget | AI9: =$AI$2*BudgetMax -> 420
AH10: spent | AI10: =SUM('💰 Budget Tracker'!$E$8:$E$31) -> 318.8
AH11: avg_gift | AI11: =IFERROR($AI$10/$AI$6,0) -> 31.88
AH12: rules_count | AI12: =(CoupleRule="On")+(TeamRule="On")+(LastYearRule="On")+SUMPRODUCT(--('🚫 Exclusions & Rules'!$B$8:$B$23<>"")) -> 4
AH13: we_players | AI13: =COUNTA('🎲 White Elephant'!$C$8:$C$31) -> 10
AH14: gifts_in_play | AI14: =COUNTIF('🎲 White Elephant'!$I$8:$I$31,"🤲 Held")+COUNTIF('🎲 White Elephant'!$I$8:$I$31,"🔄 Stolen") -> 7
AH15: locked_gifts | AI15: =COUNTIF('🎲 White Elephant'!$I$8:$I$31,"🔒 Final") -> 1
AH16: completion | AI16: =IFERROR(($AI$6+$AI$7+$AI$8)/(3*$AI$2),0) -> 0.47222222
AH17: turns_done | AI17: =COUNT('🔄 Game History'!$B$8:$B$67) -> 14
AH18: current_turn | AI18: =IF($AI$13=0,"",MOD(StartPlayer-1+$AI$17,$AI$13)+1) -> 5
AH19: violations | AI19: =COUNTIF('🎅 Secret Santa Draw'!$F$8:$F$31,"?*")-COUNTIF('🎅 Secret Santa Draw'!$F$8:$F$31,"✅ OK") -> 0
AH20: over_budget | AI20: =COUNTIF('💰 Budget Tracker'!$F$8:$F$31,"🚨 Over budget") -> 1
AH21: diets | AI21: =COUNTA('👥 Participants'!$F$8:$F$31) -> 6
AH40: Not Started | AI40: =COUNTIF('👥 Participants'!$H$8:$H$31,"Not Started") -> 2
AH41: Gift Purchased | AI41: =COUNTIF('👥 Participants'!$H$8:$H$31,"Gift Purchased") -> 5
AH42: Wrapped | AI42: =COUNTIF('👥 Participants'!$H$8:$H$31,"Wrapped") -> 3
AH43: Complete | AI43: =COUNTIF('👥 Participants'!$H$8:$H$31,"Complete") -> 2
AH45: Yes | AI45: =COUNTIF('👥 Participants'!$E$8:$E$31,"Yes") -> 10
AH46: No | AI46: =COUNTIF('👥 Participants'!$E$8:$E$31,"No") -> 1
AH47: Maybe | AI47: =COUNTIF('👥 Participants'!$E$8:$E$31,"Maybe") -> 1

Sheet ⚙️ Settings & Instructions
B4: 🎉 THE PARTY
B6: Party name | C6: Your party name
B7: Dashboard message of the day | C7: Type a message for the dashboard banner
B9: 🎛️ RULES OF THE GAME
B10: Currency symbol | C10: $
B11: Party year (used everywhere) | C11: 2026
B12: Party date | C12: 46375
B13: Location | C13: Where is the party?
B14: Host | C14: Who is hosting?
B15: Minimum gift budget | C15: 20
B16: Maximum gift budget | C16: 35
B17: Max steals per gift (White Elephant) | C17: 2
B18: Starting player seat (White Elephant) | C18: 1
B19: Secret Santa draw seed (change = re-draw) | C19: 5
B20: White Elephant seat seed | C20: 7
B21: Draw status | C21: Draft — re-draw allowed
B25: 📝 YOUR LISTS - rename or add, every dropdown follows
C26: Studio | D26: Vegetarian
C27: Shop | D27: Vegan
C28: Online | D28: Gluten-free
C29: Friends | D29: Halal
C30: Family | D30: Nut allergy
B44: 🔒 BUILT-IN LISTS (part of the engine - do not edit)
C45: Statuses | D45: RSVP | E45: Actions | F45: Priorities | G45: Tick | H45: OnOff
C46: Not Started | D46: Yes | E46: Pick | F46: Must-love | G46: ✓ | H46: On
C47: Gift Purchased | D47: No | E47: Steal | F47: Nice to have | H47: Off
C48: Wrapped | D48: Maybe | E48: Pass | F48: Just an idea
C49: Complete
B52: 📖 HOW TO RUN THE PARTY
B53: Formula cells are locked so nobody breaks the maths. The sheet password is “premium” - unlock via Review → Unprotect Sheet if you ever need to change a seed or a formula. Re-draw the Secret Santa any time: unlock, change the draw seed on this tab, watch 🎅 Secret Santa Draw shuffle, then set Draw status to Final and re-protect. White Elephant: log every Pick / Steal / Pass on 🔄 Game History - the 🎲 White Elephant tab updates holders, steal counts, locks and final gifts by itself.
B58: 💡 Cream cells are yours to type in; white cells calculate. Dropdowns keep every column honest.
B60: ▶ Settings | D60: Dashboard | F60: People
B61: Draw | D61: Rules | F61: Budget
B62: Wishlists | D62: White Elephant | F62: History
B63: Cards | D63: Start Here

Sheet 🏠 Dashboard
B2: =IF(PartyName="","🎅 Secret Santa & White Elephant Command Centre","🎅 "&PartyName&" • Secret Santa & White Elephant Command Centre") -> 🎅 Novality Store Holiday Party • Secret Santa & White Elephant Command Centre
B3: =IF(PartyDate="","", "🎄 "&TEXT(PartyDate,"dddd, dd mmmm yyyy")&" • "&PartyLocation&" • hosted by "&PartyHost&" • "&MAX(0,PartyDate-TODAY())&" days to go!") -> 🎄 Saturday, 19 December 2026 • Novality Loft, 12 Market Street • hosted by The Novality Team • 92 days to go!
B4: ="👥 "&'_Data'!$AI$2&" guests • "&'_Data'!$AI$5&" in the draw • "&'_Data'!$AI$13&" white-elephant players • draw: "&DrawStatus -> 👥 12 guests • 12 in the draw • 10 white-elephant players • draw: Final — locked 🔒
B5: ="💬 "&Message -> 💬 19 Dec - bring a wrapped gift and a stealing face!
B7: 🎉 PARTY AT A GLANCE
B8: PARTICIPANTS | D8: SANTA ASSIGNED | F8: GIFTS PURCHASED | H8: TOTAL BUDGET | J8: ACTUAL SPEND | L8: AVG GIFT COST
B9: ='_Data'!$AI$2 -> 12 | D9: ='_Data'!$AI$5&" of "&'_Data'!$AI$2 -> 12 of 12 | F9: ='_Data'!$AI$6 -> 10 | H9: =Currency&TEXT('_Data'!$AI$9,"#,##0") -> 420 | J9: =Currency&TEXT('_Data'!$AI$10,"#,##0") -> 318.8 | L9: =Currency&TEXT('_Data'!$AI$11,"#,##0.00") -> 31.88
B10: EXCLUSION RULES | D10: W-E PLAYERS | F10: GIFTS IN PLAY | H10: LOCKED GIFTS | J10: RSVP YES | L10: COMPLETION
B11: ='_Data'!$AI$12 -> 4 | D11: ='_Data'!$AI$13 -> 10 | F11: ='_Data'!$AI$14 -> 7 | H11: ='_Data'!$AI$15 -> 1 | J11: ='_Data'!$AI$3&" / "&'_Data'!$AI$2 -> 10 / 12 | L11: =TEXT('_Data'!$AI$16,"0%") -> 47%
B12: Gift readiness | D12: =IFERROR(REPT("█",ROUND(MIN(1,IFERROR(('_Data'!$AI$6)/('_Data'!$AI$2),0))*34,0))&REPT("░",34-ROUND(MIN(1,IFERROR(('_Data'!$AI$6)/('_Data'!$AI$2),0))*34,0)),"░░░░░░░░░░░░░░░░░░░░░░░░░░░░░░░░░░") -> ████████████████████████████░░░░░░ | K12: =TEXT(IFERROR('_Data'!$AI$6/'_Data'!$AI$2,0),"0.0%") -> 83.3%
B13: RSVP confirmed | D13: =IFERROR(REPT("█",ROUND(MIN(1,IFERROR(('_Data'!$AI$3)/('_Data'!$AI$2),0))*34,0))&REPT("░",34-ROUND(MIN(1,IFERROR(('_Data'!$AI$3)/('_Data'!$AI$2),0))*34,0)),"░░░░░░░░░░░░░░░░░░░░░░░░░░░░░░░░░░") -> ████████████████████████████░░░░░░ | K13: =TEXT(IFERROR('_Data'!$AI$3/'_Data'!$AI$2,0),"0.0%") -> 83.3%
B64: 🎲 GAME STATE • ⚠️ PARTY ALERTS
B65: Turns logged | F65: ='_Data'!$AI$17 -> 14 | I65: RSVP still maybe | M65: ='_Data'!$AI$4 -> 1
B66: Now playing (seat) | F66: ='_Data'!$AI$18 -> 5 | I66: Over-budget gifts | M66: ='_Data'!$AI$20 -> 1
B67: Gifts still stealable | F67: ='_Data'!$AI$14 -> 7 | I67: Draw rule hits | M67: ='_Data'!$AI$19 -> 0
B68: Gifts locked 🔒 | F68: ='_Data'!$AI$15 -> 1 | I68: Dietary needs noted | M68: ='_Data'!$AI$21 -> 6
B74: 💬 Novality Store wishes you a loud, glorious, steal-happy party.
B76: Settings | D76: ▶ Dashboard | F76: People | H76: Draw | J76: Rules | L76: Budget
B77: Wishlists | D77: White Elephant | F77: History | H77: Cards | J77: Start Here

Sheet 👥 Participants
B2: 👥 Participants
B3: Everyone in the draw - RSVP, household and team feed the exclusion rules automatically. | H3: 🏠 Dashboard
B5: ="👥 In the draw: "&COUNTA($B$8:$B$31) -> In the draw: 12 | E5: ="✅ RSVP yes: "&COUNTIF($E$8:$E$31,"Yes") -> RSVP yes: 10 | H5: ="⏳ Awaiting: "&COUNTIF($E$8:$E$31,"Maybe")+COUNTIF($E$8:$E$31,"No") -> Awaiting: 1 | K5: ="🎁 Ready (wrapped+done): "&COUNTIF($H$8:$H$31,"Wrapped")+COUNTIF($H$8:$H$31,"Complete") -> Ready: 5
A7: # | B7: Participant | C7: Team / dept | D7: Household / couple | E7: RSVP | F7: Dietary needs | G7: Gave to last year | H7: Gift status | I7: Wishes | J7: Notes
A8: 1 | B8: Ava Novak | C8: Studio | D8: Novak home | E8: Yes | G8: Jack Byrne | H8: Complete | I8: =IF($B8="","",COUNTIF('🎁 Wishlists'!$B$8:$B$47,$B8)) -> 2 | J8: Hosting helper - arrives early
A9: 2 | B9: Ben Carter | C9: Shop | E9: Yes | F9: Vegetarian | G9: Ava Novak | H9: Gift Purchased | I9: =IF($B9="","",COUNTIF('🎁 Wishlists'!$B$8:$B$47,$B9)) -> 1 | J9: Owes Kia a bet from 2025
A10: 3 | B10: Chloe Diaz | C10: Online | E10: Yes | F10: Vegan | G10: Grace Liu | H10: Wrapped | I10: =IF($B10="","",COUNTIF('🎁 Wishlists'!$B$8:$B$47,$B10)) -> 2
A11: 4 | B11: Dan Novak | C11: Studio | D11: Novak home | E11: Yes | G11: Elena Petrov | H11: Gift Purchased | I11: =IF($B11="","",COUNTIF('🎁 Wishlists'!$B$8:$B$47,$B11)) -> 1 | J11: Ava's husband - couple rule applies
A12: 5 | B12: Elena Petrov | C12: Shop | E12: Maybe | F12: Gluten-free | G12: Farid Khan | H12: Not Started | I12: =IF($B12="","",COUNTIF('🎁 Wishlists'!$B$8:$B$47,$B12)) -> 1 | J12: Waiting on shift rota
A13: 6 | B13: Farid Khan | C13: Shop | E13: Yes | F13: Halal | G13: Chloe Diaz | H13: Wrapped | I13: =IF($B13="","",COUNTIF('🎁 Wishlists'!$B$8:$B$47,$B13)) -> 1
A14: 7 | B14: Grace Liu | C14: Online | D14: Flat 4B | E14: Yes | G14: Hugo Silva | H14: Complete | I14: =IF($B14="","",COUNTIF('🎁 Wishlists'!$B$8:$B$47,$B14)) -> 2 | J14: Flat 4B - couple rule applies too
A15: 8 | B15: Hugo Silva | C15: Online | D15: Flat 4B | E15: Yes | G15: Grace Liu | H15: Gift Purchased | I15: =IF($B15="","",COUNTIF('🎁 Wishlists'!$B$8:$B$47,$B15)) -> 1
A16: 9 | B16: Isla Moore | C16: Studio | E16: No | G16: Leo Fontaine | H16: Not Started | I16: =IF($B16="","",COUNTIF('🎁 Wishlists'!$B$8:$B$47,$B16)) -> 1 | J16: Away in December - sad face
A17: 10 | B17: Jack Byrne | C17: Shop | E17: Yes | F17: Nut allergy | G17: Ava Novak | H17: Gift Purchased | I17: =IF($B17="","",COUNTIF('🎁 Wishlists'!$B$8:$B$47,$B17)) -> 1 | J17: Espresso-machine feud with Leo
A18: 11 | B18: Kia Osei | C18: Online | E18: Yes | G18: Ben Carter | H18: Wrapped | I18: =IF($B18="","",COUNTIF('🎁 Wishlists'!$B$8:$B$47,$B18)) -> 1
A19: 12 | B19: Leo Fontaine | C19: Studio | E19: Yes | F19: Vegetarian | G19: Isla Moore | H19: Gift Purchased | I19: =IF($B19="","",COUNTIF('🎁 Wishlists'!$B$8:$B$47,$B19)) -> 2
A20: 13 | I20: =IF($B20="","",COUNTIF('🎁 Wishlists'!$B$8:$B$47,$B20))
A21: 14 | I21: =IF($B21="","",COUNTIF('🎁 Wishlists'!$B$8:$B$47,$B21))
A22: 15 | I22: =IF($B22="","",COUNTIF('🎁 Wishlists'!$B$8:$B$47,$B22))
A23: 16 | I23: =IF($B23="","",COUNTIF('🎁 Wishlists'!$B$8:$B$47,$B23))
A24: 17 | I24: =IF($B24="","",COUNTIF('🎁 Wishlists'!$B$8:$B$47,$B24))
A25: 18 | I25: =IF($B25="","",COUNTIF('🎁 Wishlists'!$B$8:$B$47,$B25))
A26: 19 | I26: =IF($B26="","",COUNTIF('🎁 Wishlists'!$B$8:$B$47,$B26))
A27: 20 | I27: =IF($B27="","",COUNTIF('🎁 Wishlists'!$B$8:$B$47,$B27))
A28: 21 | I28: =IF($B28="","",COUNTIF('🎁 Wishlists'!$B$8:$B$47,$B28))
A29: 22 | I29: =IF($B29="","",COUNTIF('🎁 Wishlists'!$B$8:$B$47,$B29))
A30: 23 | I30: =IF($B30="","",COUNTIF('🎁 Wishlists'!$B$8:$B$47,$B30))
A31: 24 | I31: =IF($B31="","",COUNTIF('🎁 Wishlists'!$B$8:$B$47,$B31))
B33: 💡 Cream cells are yours to type in; white cells calculate. Dropdowns keep every column honest.
B35: Settings | D35: Dashboard | F35: ▶ People | H35: Draw
B36: Rules | D36: Budget | F36: Wishlists | H36: White Elephant
B37: History | D37: Cards | F37: Start Here

Sheet 🎅 Secret Santa Draw
B2: 🎅 Secret Santa Draw
B3: Change the seed on ⚙️ Settings to shuffle the draw - nobody ever draws themselves. | E3: 🏠 Dashboard
B5: ="🎅 Assigned: "&SUMPRODUCT(--($E$8:$E$31<>""))&" of "&COUNTA('👥 Participants'!$B$8:$B$31) -> Assigned: 12 of 12 | F5: ="✅ Clean pairs: "&COUNTIF($F$8:$F$31,"✅ OK") -> Clean pairs: 12 | I5: ="⚠️ Rule hits: "&'_Data'!$AI$19 -> Rule hits: 0 | L5: ="🔒 Status: "&DrawStatus -> Status: Final — locked 🔒
A7: # | B7: Giver | C7: Drawn (auto) | D7: Manual override | E7: FINAL recipient | F7: Rules check | G7: Gift status
A8: 1 | B8: =IF('👥 Participants'!$B$8="","",'👥 Participants'!$B$8) -> Ava Novak | C8: =IF($B8="","",INDEX('👥 Participants'!$B$8:$B$31,MOD($A8-1+MOD(DrawSeed-1,MAX(1,COUNTA('👥 Participants'!$B$8:$B$31)-1)),COUNTA('👥 Participants'!$B$8:$B$31))+1)) -> Farid Khan | E8: =IF($B8="","",IF($D8<>"",$D8,$C8)) -> Farid Khan | F8: =IF($E8="","",IF(TRIM(IF($E8=$B8,"Self ","")&IF(AND(CoupleRule="On",IFERROR(INDEX('👥 Participants'!$D$8:$D$31,MATCH($B8,'👥 Participants'!$B$8:$B$31,0)),"")<>"",INDEX('👥 Participants'!$D$8:$D$31,MATCH($B8,'👥 Participants'!$B$8:$B$31,0))=INDEX('👥 Participants'!$D$8:$D$31,MATCH($E8,'👥 Participants'!$B$8:$B$31,0))),"Couple ","")&IF(AND(TeamRule="On",IFERROR(INDEX('👥 Participants'!$C$8:$C$31,MATCH($B8,'👥 Participants'!$B$8:$B$31,0)),"")<>"",INDEX('👥 Participants'!$C$8:$C$31,MATCH($B8,'👥 Participants'!$B$8:$B$31,0))=INDEX('👥 Participants'!$C$8:$C$31,MATCH($E8,'👥 Participants'!$B$8:$B$31,0))),"Team ","")&IF(AND(LastYearRule="On",IFERROR(INDEX('👥 Participants'!$G$8:$G$31,MATCH($B8,'👥 Participants'!$B$8:$B$31,0)),"")=$E8),"LastYear ","")&IF(COUNTIFS('🚫 Exclusions & Rules'!$B$8:$B$23,$B8,'🚫 Exclusions & Rules'!$C$8:$C$23,$E8)>0,"Custom ",""))="","✅ OK",TRIM(IF($E8=$B8,"Self ","")&IF(AND(CoupleRule="On",IFERROR(INDEX('👥 Participants'!$D$8:$D$31,MATCH($B8,'👥 Participants'!$B$8:$B$31,0)),"")<>"",INDEX('👥 Participants'!$D$8:$D$31,MATCH($B8,'👥 Participants'!$B$8:$B$31,0))=INDEX('👥 Participants'!$D$8:$D$31,MATCH($E8,'👥 Participants'!$B$8:$B$31,0))),"Couple ","")&IF(AND(TeamRule="On",IFERROR(INDEX('👥 Participants'!$C$8:$C$31,MATCH($B8,'👥 Participants'!$B$8:$B$31,0)),"")<>"",INDEX('👥 Participants'!$C$8:$C$31,MATCH($B8,'👥 Participants'!$B$8:$B$31,0))=INDEX('👥 Participants'!$C$8:$C$31,MATCH($E8,'👥 Participants'!$B$8:$B$31,0))),"Team ","")&IF(AND(LastYearRule="On",IFERROR(INDEX('👥 Participants'!$G$8:$G$31,MATCH($B8,'👥 Participants'!$B$8:$B$31,0)),"")=$E8),"LastYear ","")&IF(COUNTIFS('🚫 Exclusions & Rules'!$B$8:$B$23,$B8,'🚫 Exclusions & Rules'!$C$8:$C$23,$E8)>0,"Custom ","")))) -> ✅ OK | G8: =IF($B8="","",INDEX('👥 Participants'!$H$8:$H$31,MATCH($B8,'👥 Participants'!$B$8:$B$31,0))) -> Complete
A9: 2 | B9: =IF('👥 Participants'!$B$9="","",'👥 Participants'!$B$9) -> Ben Carter | C9: =IF($B9="","",INDEX('👥 Participants'!$B$8:$B$31,MOD($A9-1+MOD(DrawSeed-1,MAX(1,COUNTA('👥 Participants'!$B$8:$B$31)-1)),COUNTA('👥 Participants'!$B$8:$B$31))+1)) -> Grace Liu | E9: =IF($B9="","",IF($D9<>"",$D9,$C9)) -> Grace Liu | F9: =IF($E9="","",IF(TRIM(IF($E9=$B9,"Self ","")&IF(AND(CoupleRule="On",IFERROR(INDEX('👥 Participants'!$D$8:$D$31,MATCH($B9,'👥 Participants'!$B$8:$B$31,0)),"")<>"",INDEX('👥 Participants'!$D$8:$D$31,MATCH($B9,'👥 Participants'!$B$8:$B$31,0))=INDEX('👥 Participants'!$D$8:$D$31,MATCH($E9,'👥 Participants'!$B$8:$B$31,0))),"Couple ","")&IF(AND(TeamRule="On",IFERROR(INDEX('👥 Participants'!$C$8:$C$31,MATCH($B9,'👥 Participants'!$B$8:$B$31,0)),"")<>"",INDEX('👥 Participants'!$C$8:$C$31,MATCH($B9,'👥 Participants'!$B$8:$B$31,0))=INDEX('👥 Participants'!$C$8:$C$31,MATCH($E9,'👥 Participants'!$B$8:$B$31,0))),"Team ","")&IF(AND(LastYearRule="On",IFERROR(INDEX('👥 Participants'!$G$8:$G$31,MATCH($B9,'👥 Participants'!$B$8:$B$31,0)),"")=$E9),"LastYear ","")&IF(COUNTIFS('🚫 Exclusions & Rules'!$B$8:$B$23,$B9,'🚫 Exclusions & Rules'!$C$8:$C$23,$E9)>0,"Custom ",""))="","✅ OK",TRIM(IF($E9=$B9,"Self ","")&IF(AND(CoupleRule="On",IFERROR(INDEX('👥 Participants'!$D$8:$D$31,MATCH($B9,'👥 Participants'!$B$8:$B$31,0)),"")<>"",INDEX('👥 Participants'!$D$8:$D$31,MATCH($B9,'👥 Participants'!$B$8:$B$31,0))=INDEX('👥 Participants'!$D$8:$D$31,MATCH($E9,'👥 Participants'!$B$8:$B$31,0))),"Couple ","")&IF(AND(TeamRule="On",IFERROR(INDEX('👥 Participants'!$C$8:$C$31,MATCH($B9,'👥 Participants'!$B$8:$B$31,0)),"")<>"",INDEX('👥 Participants'!$C$8:$C$31,MATCH($B9,'👥 Participants'!$B$8:$B$31,0))=INDEX('👥 Participants'!$C$8:$C$31,MATCH($E9,'👥 Participants'!$B$8:$B$31,0))),"Team ","")&IF(AND(LastYearRule="On",IFERROR(INDEX('👥 Participants'!$G$8:$G$31,MATCH($B9,'👥 Participants'!$B$8:$B$31,0)),"")=$E9),"LastYear ","")&IF(COUNTIFS('🚫 Exclusions & Rules'!$B$8:$B$23,$B9,'🚫 Exclusions & Rules'!$C$8:$C$23,$E9)>0,"Custom ","")))) -> ✅ OK | G9: =IF($B9="","",INDEX('👥 Participants'!$H$8:$H$31,MATCH($B9,'👥 Participants'!$B$8:$B$31,0))) -> Gift Purchased
A10: 3 | B10: =IF('👥 Participants'!$B$10="","",'👥 Participants'!$B$10) -> Chloe Diaz | C10: =IF($B10="","",INDEX('👥 Participants'!$B$8:$B$31,MOD($A10-1+MOD(DrawSeed-1,MAX(1,COUNTA('👥 Participants'!$B$8:$B$31)-1)),COUNTA('👥 Participants'!$B$8:$B$31))+1)) -> Hugo Silva | E10: =IF($B10="","",IF($D10<>"",$D10,$C10)) -> Hugo Silva | F10: =IF($E10="","",IF(TRIM(IF($E10=$B10,"Self ","")&IF(AND(CoupleRule="On",IFERROR(INDEX('👥 Participants'!$D$8:$D$31,MATCH($B10,'👥 Participants'!$B$8:$B$31,0)),"")<>"",INDEX('👥 Participants'!$D$8:$D$31,MATCH($B10,'👥 Participants'!$B$8:$B$31,0))=INDEX('👥 Participants'!$D$8:$D$31,MATCH($E10,'👥 Participants'!$B$8:$B$31,0))),"Couple ","")&IF(AND(TeamRule="On",IFERROR(INDEX('👥 Participants'!$C$8:$C$31,MATCH($B10,'👥 Participants'!$B$8:$B$31,0)),"")<>"",INDEX('👥 Participants'!$C$8:$C$31,MATCH($B10,'👥 Participants'!$B$8:$B$31,0))=INDEX('👥 Participants'!$C$8:$C$31,MATCH($E10,'👥 Participants'!$B$8:$B$31,0))),"Team ","")&IF(AND(LastYearRule="On",IFERROR(INDEX('👥 Participants'!$G$8:$G$31,MATCH($B10,'👥 Participants'!$B$8:$B$31,0)),"")=$E10),"LastYear ","")&IF(COUNTIFS('🚫 Exclusions & Rules'!$B$8:$B$23,$B10,'🚫 Exclusions & Rules'!$C$8:$C$23,$E10)>0,"Custom ",""))="","✅ OK",TRIM(IF($E10=$B10,"Self ","")&IF(AND(CoupleRule="On",IFERROR(INDEX('👥 Participants'!$D$8:$D$31,MATCH($B10,'👥 Participants'!$B$8:$B$31,0)),"")<>"",INDEX('👥 Participants'!$D$8:$D$31,MATCH($B10,'👥 Participants'!$B$8:$B$31,0))=INDEX('👥 Participants'!$D$8:$D$31,MATCH($E10,'👥 Participants'!$B$8:$B$31,0))),"Couple ","")&IF(AND(TeamRule="On",IFERROR(INDEX('👥 Participants'!$C$8:$C$31,MATCH($B10,'👥 Participants'!$B$8:$B$31,0)),"")<>"",INDEX('👥 Participants'!$C$8:$C$31,MATCH($B10,'👥 Participants'!$B$8:$B$31,0))=INDEX('👥 Participants'!$C$8:$C$31,MATCH($E10,'👥 Participants'!$B$8:$B$31,0))),"Team ","")&IF(AND(LastYearRule="On",IFERROR(INDEX('👥 Participants'!$G$8:$G$31,MATCH($B10,'👥 Participants'!$B$8:$B$31,0)),"")=$E10),"LastYear ","")&IF(COUNTIFS('🚫 Exclusions & Rules'!$B$8:$B$23,$B10,'🚫 Exclusions & Rules'!$C$8:$C$23,$E10)>0,"Custom ","")))) -> ✅ OK | G10: =IF($B10="","",INDEX('👥 Participants'!$H$8:$H$31,MATCH($B10,'👥 Participants'!$B$8:$B$31,0))) -> Wrapped
A11: 4 | B11: =IF('👥 Participants'!$B$11="","",'👥 Participants'!$B$11) -> Dan Novak | C11: =IF($B11="","",INDEX('👥 Participants'!$B$8:$B$31,MOD($A11-1+MOD(DrawSeed-1,MAX(1,COUNTA('👥 Participants'!$B$8:$B$31)-1)),COUNTA('👥 Participants'!$B$8:$B$31))+1)) -> Isla Moore | E11: =IF($B11="","",IF($D11<>"",$D11,$C11)) -> Isla Moore | F11: =IF($E11="","",IF(TRIM(IF($E11=$B11,"Self ","")&IF(AND(CoupleRule="On",IFERROR(INDEX('👥 Participants'!$D$8:$D$31,MATCH($B11,'👥 Participants'!$B$8:$B$31,0)),"")<>"",INDEX('👥 Participants'!$D$8:$D$31,MATCH($B11,'👥 Participants'!$B$8:$B$31,0))=INDEX('👥 Participants'!$D$8:$D$31,MATCH($E11,'👥 Participants'!$B$8:$B$31,0))),"Couple ","")&IF(AND(TeamRule="On",IFERROR(INDEX('👥 Participants'!$C$8:$C$31,MATCH($B11,'👥 Participants'!$B$8:$B$31,0)),"")<>"",INDEX('👥 Participants'!$C$8:$C$31,MATCH($B11,'👥 Participants'!$B$8:$B$31,0))=INDEX('👥 Participants'!$C$8:$C$31,MATCH($E11,'👥 Participants'!$B$8:$B$31,0))),"Team ","")&IF(AND(LastYearRule="On",IFERROR(INDEX('👥 Participants'!$G$8:$G$31,MATCH($B11,'👥 Participants'!$B$8:$B$31,0)),"")=$E11),"LastYear ","")&IF(COUNTIFS('🚫 Exclusions & Rules'!$B$8:$B$23,$B11,'🚫 Exclusions & Rules'!$C$8:$C$23,$E11)>0,"Custom ",""))="","✅ OK",TRIM(IF($E11=$B11,"Self ","")&IF(AND(CoupleRule="On",IFERROR(INDEX('👥 Participants'!$D$8:$D$31,MATCH($B11,'👥 Participants'!$B$8:$B$31,0)),"")<>"",INDEX('👥 Participants'!$D$8:$D$31,MATCH($B11,'👥 Participants'!$B$8:$B$31,0))=INDEX('👥 Participants'!$D$8:$D$31,MATCH($E11,'👥 Participants'!$B$8:$B$31,0))),"Couple ","")&IF(AND(TeamRule="On",IFERROR(INDEX('👥 Participants'!$C$8:$C$31,MATCH($B11,'👥 Participants'!$B$8:$B$31,0)),"")<>"",INDEX('👥 Participants'!$C$8:$C$31,MATCH($B11,'👥 Participants'!$B$8:$B$31,0))=INDEX('👥 Participants'!$C$8:$C$31,MATCH($E11,'👥 Participants'!$B$8:$B$31,0))),"Team ","")&IF(AND(LastYearRule="On",IFERROR(INDEX('👥 Participants'!$G$8:$G$31,MATCH($B11,'👥 Participants'!$B$8:$B$31,0)),"")=$E11),"LastYear ","")&IF(COUNTIFS('🚫 Exclusions & Rules'!$B$8:$B$23,$B11,'🚫 Exclusions & Rules'!$C$8:$C$23,$E11)>0,"Custom ","")))) -> ✅ OK | G11: =IF($B11="","",INDEX('👥 Participants'!$H$8:$H$31,MATCH($B11,'👥 Participants'!$B$8:$B$31,0))) -> Gift Purchased
A12: 5 | B12: =IF('👥 Participants'!$B$12="","",'👥 Participants'!$B$12) -> Elena Petrov | C12: =IF($B12="","",INDEX('👥 Participants'!$B$8:$B$31,MOD($A12-1+MOD(DrawSeed-1,MAX(1,COUNTA('👥 Participants'!$B$8:$B$31)-1)),COUNTA('👥 Participants'!$B$8:$B$31))+1)) -> Jack Byrne | E12: =IF($B12="","",IF($D12<>"",$D12,$C12)) -> Jack Byrne | F12: =IF($E12="","",IF(TRIM(IF($E12=$B12,"Self ","")&IF(AND(CoupleRule="On",IFERROR(INDEX('👥 Participants'!$D$8:$D$31,MATCH($B12,'👥 Participants'!$B$8:$B$31,0)),"")<>"",INDEX('👥 Participants'!$D$8:$D$31,MATCH($B12,'👥 Participants'!$B$8:$B$31,0))=INDEX('👥 Participants'!$D$8:$D$31,MATCH($E12,'👥 Participants'!$B$8:$B$31,0))),"Couple ","")&IF(AND(TeamRule="On",IFERROR(INDEX('👥 Participants'!$C$8:$C$31,MATCH($B12,'👥 Participants'!$B$8:$B$31,0)),"")<>"",INDEX('👥 Participants'!$C$8:$C$31,MATCH($B12,'👥 Participants'!$B$8:$B$31,0))=INDEX('👥 Participants'!$C$8:$C$31,MATCH($E12,'👥 Participants'!$B$8:$B$31,0))),"Team ","")&IF(AND(LastYearRule="On",IFERROR(INDEX('👥 Participants'!$G$8:$G$31,MATCH($B12,'👥 Participants'!$B$8:$B$31,0)),"")=$E12),"LastYear ","")&IF(COUNTIFS('🚫 Exclusions & Rules'!$B$8:$B$23,$B12,'🚫 Exclusions & Rules'!$C$8:$C$23,$E12)>0,"Custom ",""))="","✅ OK",TRIM(IF($E12=$B12,"Self ","")&IF(AND(CoupleRule="On",IFERROR(INDEX('👥 Participants'!$D$8:$D$31,MATCH($B12,'👥 Participants'!$B$8:$B$31,0)),"")<>"",INDEX('👥 Participants'!$D$8:$D$31,MATCH($B12,'👥 Participants'!$B$8:$B$31,0))=INDEX('👥 Participants'!$D$8:$D$31,MATCH($E12,'👥 Participants'!$B$8:$B$31,0))),"Couple ","")&IF(AND(TeamRule="On",IFERROR(INDEX('👥 Participants'!$C$8:$C$31,MATCH($B12,'👥 Participants'!$B$8:$B$31,0)),"")<>"",INDEX('👥 Participants'!$C$8:$C$31,MATCH($B12,'👥 Participants'!$B$8:$B$31,0))=INDEX('👥 Participants'!$C$8:$C$31,MATCH($E12,'👥 Participants'!$B$8:$B$31,0))),"Team ","")&IF(AND(LastYearRule="On",IFERROR(INDEX('👥 Participants'!$G$8:$G$31,MATCH($B12,'👥 Participants'!$B$8:$B$31,0)),"")=$E12),"LastYear ","")&IF(COUNTIFS('🚫 Exclusions & Rules'!$B$8:$B$23,$B12,'🚫 Exclusions & Rules'!$C$8:$C$23,$E12)>0,"Custom ","")))) -> ✅ OK | G12: =IF($B12="","",INDEX('👥 Participants'!$H$8:$H$31,MATCH($B12,'👥 Participants'!$B$8:$B$31,0))) -> Not Started
A13: 6 | B13: =IF('👥 Participants'!$B$13="","",'👥 Participants'!$B$13) -> Farid Khan | C13: =IF($B13="","",INDEX('👥 Participants'!$B$8:$B$31,MOD($A13-1+MOD(DrawSeed-1,MAX(1,COUNTA('👥 Participants'!$B$8:$B$31)-1)),COUNTA('👥 Participants'!$B$8:$B$31))+1)) -> Kia Osei | E13: =IF($B13="","",IF($D13<>"",$D13,$C13)) -> Kia Osei | F13: =IF($E13="","",IF(TRIM(IF($E13=$B13,"Self ","")&IF(AND(CoupleRule="On",IFERROR(INDEX('👥 Participants'!$D$8:$D$31,MATCH($B13,'👥 Participants'!$B$8:$B$31,0)),"")<>"",INDEX('👥 Participants'!$D$8:$D$31,MATCH($B13,'👥 Participants'!$B$8:$B$31,0))=INDEX('👥 Participants'!$D$8:$D$31,MATCH($E13,'👥 Participants'!$B$8:$B$31,0))),"Couple ","")&IF(AND(TeamRule="On",IFERROR(INDEX('👥 Participants'!$C$8:$C$31,MATCH($B13,'👥 Participants'!$B$8:$B$31,0)),"")<>"",INDEX('👥 Participants'!$C$8:$C$31,MATCH($B13,'👥 Participants'!$B$8:$B$31,0))=INDEX('👥 Participants'!$C$8:$C$31,MATCH($E13,'👥 Participants'!$B$8:$B$31,0))),"Team ","")&IF(AND(LastYearRule="On",IFERROR(INDEX('👥 Participants'!$G$8:$G$31,MATCH($B13,'👥 Participants'!$B$8:$B$31,0)),"")=$E13),"LastYear ","")&IF(COUNTIFS('🚫 Exclusions & Rules'!$B$8:$B$23,$B13,'🚫 Exclusions & Rules'!$C$8:$C$23,$E13)>0,"Custom ",""))="","✅ OK",TRIM(IF($E13=$B13,"Self ","")&IF(AND(CoupleRule="On",IFERROR(INDEX('👥 Participants'!$D$8:$D$31,MATCH($B13,'👥 Participants'!$B$8:$B$31,0)),"")<>"",INDEX('👥 Participants'!$D$8:$D$31,MATCH($B13,'👥 Participants'!$B$8:$B$31,0))=INDEX('👥 Participants'!$D$8:$D$31,MATCH($E13,'👥 Participants'!$B$8:$B$31,0))),"Couple ","")&IF(AND(TeamRule="On",IFERROR(INDEX('👥 Participants'!$C$8:$C$31,MATCH($B13,'👥 Participants'!$B$8:$B$31,0)),"")<>"",INDEX('👥 Participants'!$C$8:$C$31,MATCH($B13,'👥 Participants'!$B$8:$B$31,0))=INDEX('👥 Participants'!$C$8:$C$31,MATCH($E13,'👥 Participants'!$B$8:$B$31,0))),"Team ","")&IF(AND(LastYearRule="On",IFERROR(INDEX('👥 Participants'!$G$8:$G$31,MATCH($B13,'👥 Participants'!$B$8:$B$31,0)),"")=$E13),"LastYear ","")&IF(COUNTIFS('🚫 Exclusions & Rules'!$B$8:$B$23,$B13,'🚫 Exclusions & Rules'!$C$8:$C$23,$E13)>0,"Custom ","")))) -> ✅ OK | G13: =IF($B13="","",INDEX('👥 Participants'!$H$8:$H$31,MATCH($B13,'👥 Participants'!$B$8:$B$31,0))) -> Wrapped
A14: 7 | B14: =IF('👥 Participants'!$B$14="","",'👥 Participants'!$B$14) -> Grace Liu | C14: =IF($B14="","",INDEX('👥 Participants'!$B$8:$B$31,MOD($A14-1+MOD(DrawSeed-1,MAX(1,COUNTA('👥 Participants'!$B$8:$B$31)-1)),COUNTA('👥 Participants'!$B$8:$B$31))+1)) -> Leo Fontaine | E14: =IF($B14="","",IF($D14<>"",$D14,$C14)) -> Leo Fontaine | F14: =IF($E14="","",IF(TRIM(IF($E14=$B14,"Self ","")&IF(AND(CoupleRule="On",IFERROR(INDEX('👥 Participants'!$D$8:$D$31,MATCH($B14,'👥 Participants'!$B$8:$B$31,0)),"")<>"",INDEX('👥 Participants'!$D$8:$D$31,MATCH($B14,'👥 Participants'!$B$8:$B$31,0))=INDEX('👥 Participants'!$D$8:$D$31,MATCH($E14,'👥 Participants'!$B$8:$B$31,0))),"Couple ","")&IF(AND(TeamRule="On",IFERROR(INDEX('👥 Participants'!$C$8:$C$31,MATCH($B14,'👥 Participants'!$B$8:$B$31,0)),"")<>"",INDEX('👥 Participants'!$C$8:$C$31,MATCH($B14,'👥 Participants'!$B$8:$B$31,0))=INDEX('👥 Participants'!$C$8:$C$31,MATCH($E14,'👥 Participants'!$B$8:$B$31,0))),"Team ","")&IF(AND(LastYearRule="On",IFERROR(INDEX('👥 Participants'!$G$8:$G$31,MATCH($B14,'👥 Participants'!$B$8:$B$31,0)),"")=$E14),"LastYear ","")&IF(COUNTIFS('🚫 Exclusions & Rules'!$B$8:$B$23,$B14,'🚫 Exclusions & Rules'!$C$8:$C$23,$E14)>0,"Custom ",""))="","✅ OK",TRIM(IF($E14=$B14,"Self ","")&IF(AND(CoupleRule="On",IFERROR(INDEX('👥 Participants'!$D$8:$D$31,MATCH($B14,'👥 Participants'!$B$8:$B$31,0)),"")<>"",INDEX('👥 Participants'!$D$8:$D$31,MATCH($B14,'👥 Participants'!$B$8:$B$31,0))=INDEX('👥 Participants'!$D$8:$D$31,MATCH($E14,'👥 Participants'!$B$8:$B$31,0))),"Couple ","")&IF(AND(TeamRule="On",IFERROR(INDEX('👥 Participants'!$C$8:$C$31,MATCH($B14,'👥 Participants'!$B$8:$B$31,0)),"")<>"",INDEX('👥 Participants'!$C$8:$C$31,MATCH($B14,'👥 Participants'!$B$8:$B$31,0))=INDEX('👥 Participants'!$C$8:$C$31,MATCH($E14,'👥 Participants'!$B$8:$B$31,0))),"Team ","")&IF(AND(LastYearRule="On",IFERROR(INDEX('👥 Participants'!$G$8:$G$31,MATCH($B14,'👥 Participants'!$B$8:$B$31,0)),"")=$E14),"LastYear ","")&IF(COUNTIFS('🚫 Exclusions & Rules'!$B$8:$B$23,$B14,'🚫 Exclusions & Rules'!$C$8:$C$23,$E14)>0,"Custom ","")))) -> ✅ OK | G14: =IF($B14="","",INDEX('👥 Participants'!$H$8:$H$31,MATCH($B14,'👥 Participants'!$B$8:$B$31,0))) -> Complete
A15: 8 | B15: =IF('👥 Participants'!$B$15="","",'👥 Participants'!$B$15) -> Hugo Silva | C15: =IF($B15="","",INDEX('👥 Participants'!$B$8:$B$31,MOD($A15-1+MOD(DrawSeed-1,MAX(1,COUNTA('👥 Participants'!$B$8:$B$31)-1)),COUNTA('👥 Participants'!$B$8:$B$31))+1)) -> Ava Novak | E15: =IF($B15="","",IF($D15<>"",$D15,$C15)) -> Ava Novak | F15: =IF($E15="","",IF(TRIM(IF($E15=$B15,"Self ","")&IF(AND(CoupleRule="On",IFERROR(INDEX('👥 Participants'!$D$8:$D$31,MATCH($B15,'👥 Participants'!$B$8:$B$31,0)),"")<>"",INDEX('👥 Participants'!$D$8:$D$31,MATCH($B15,'👥 Participants'!$B$8:$B$31,0))=INDEX('👥 Participants'!$D$8:$D$31,MATCH($E15,'👥 Participants'!$B$8:$B$31,0))),"Couple ","")&IF(AND(TeamRule="On",IFERROR(INDEX('👥 Participants'!$C$8:$C$31,MATCH($B15,'👥 Participants'!$B$8:$B$31,0)),"")<>"",INDEX('👥 Participants'!$C$8:$C$31,MATCH($B15,'👥 Participants'!$B$8:$B$31,0))=INDEX('👥 Participants'!$C$8:$C$31,MATCH($E15,'👥 Participants'!$B$8:$B$31,0))),"Team ","")&IF(AND(LastYearRule="On",IFERROR(INDEX('👥 Participants'!$G$8:$G$31,MATCH($B15,'👥 Participants'!$B$8:$B$31,0)),"")=$E15),"LastYear ","")&IF(COUNTIFS('🚫 Exclusions & Rules'!$B$8:$B$23,$B15,'🚫 Exclusions & Rules'!$C$8:$C$23,$E15)>0,"Custom ",""))="","✅ OK",TRIM(IF($E15=$B15,"Self ","")&IF(AND(CoupleRule="On",IFERROR(INDEX('👥 Participants'!$D$8:$D$31,MATCH($B15,'👥 Participants'!$B$8:$B$31,0)),"")<>"",INDEX('👥 Participants'!$D$8:$D$31,MATCH($B15,'👥 Participants'!$B$8:$B$31,0))=INDEX('👥 Participants'!$D$8:$D$31,MATCH($E15,'👥 Participants'!$B$8:$B$31,0))),"Couple ","")&IF(AND(TeamRule="On",IFERROR(INDEX('👥 Participants'!$C$8:$C$31,MATCH($B15,'👥 Participants'!$B$8:$B$31,0)),"")<>"",INDEX('👥 Participants'!$C$8:$C$31,MATCH($B15,'👥 Participants'!$B$8:$B$31,0))=INDEX('👥 Participants'!$C$8:$C$31,MATCH($E15,'👥 Participants'!$B$8:$B$31,0))),"Team ","")&IF(AND(LastYearRule="On",IFERROR(INDEX('👥 Participants'!$G$8:$G$31,MATCH($B15,'👥 Participants'!$B$8:$B$31,0)),"")=$E15),"LastYear ","")&IF(COUNTIFS('🚫 Exclusions & Rules'!$B$8:$B$23,$B15,'🚫 Exclusions & Rules'!$C$8:$C$23,$E15)>0,"Custom ","")))) -> ✅ OK | G15: =IF($B15="","",INDEX('👥 Participants'!$H$8:$H$31,MATCH($B15,'👥 Participants'!$B$8:$B$31,0))) -> Gift Purchased
A16: 9 | B16: =IF('👥 Participants'!$B$16="","",'👥 Participants'!$B$16) -> Isla Moore | C16: =IF($B16="","",INDEX('👥 Participants'!$B$8:$B$31,MOD($A16-1+MOD(DrawSeed-1,MAX(1,COUNTA('👥 Participants'!$B$8:$B$31)-1)),COUNTA('👥 Participants'!$B$8:$B$31))+1)) -> Ben Carter | E16: =IF($B16="","",IF($D16<>"",$D16,$C16)) -> Ben Carter | F16: =IF($E16="","",IF(TRIM(IF($E16=$B16,"Self ","")&IF(AND(CoupleRule="On",IFERROR(INDEX('👥 Participants'!$D$8:$D$31,MATCH($B16,'👥 Participants'!$B$8:$B$31,0)),"")<>"",INDEX('👥 Participants'!$D$8:$D$31,MATCH($B16,'👥 Participants'!$B$8:$B$31,0))=INDEX('👥 Participants'!$D$8:$D$31,MATCH($E16,'👥 Participants'!$B$8:$B$31,0))),"Couple ","")&IF(AND(TeamRule="On",IFERROR(INDEX('👥 Participants'!$C$8:$C$31,MATCH($B16,'👥 Participants'!$B$8:$B$31,0)),"")<>"",INDEX('👥 Participants'!$C$8:$C$31,MATCH($B16,'👥 Participants'!$B$8:$B$31,0))=INDEX('👥 Participants'!$C$8:$C$31,MATCH($E16,'👥 Participants'!$B$8:$B$31,0))),"Team ","")&IF(AND(LastYearRule="On",IFERROR(INDEX('👥 Participants'!$G$8:$G$31,MATCH($B16,'👥 Participants'!$B$8:$B$31,0)),"")=$E16),"LastYear ","")&IF(COUNTIFS('🚫 Exclusions & Rules'!$B$8:$B$23,$B16,'🚫 Exclusions & Rules'!$C$8:$C$23,$E16)>0,"Custom ",""))="","✅ OK",TRIM(IF($E16=$B16,"Self ","")&IF(AND(CoupleRule="On",IFERROR(INDEX('👥 Participants'!$D$8:$D$31,MATCH($B16,'👥 Participants'!$B$8:$B$31,0)),"")<>"",INDEX('👥 Participants'!$D$8:$D$31,MATCH($B16,'👥 Participants'!$B$8:$B$31,0))=INDEX('👥 Participants'!$D$8:$D$31,MATCH($E16,'👥 Participants'!$B$8:$B$31,0))),"Couple ","")&IF(AND(TeamRule="On",IFERROR(INDEX('👥 Participants'!$C$8:$C$31,MATCH($B16,'👥 Participants'!$B$8:$B$31,0)),"")<>"",INDEX('👥 Participants'!$C$8:$C$31,MATCH($B16,'👥 Participants'!$B$8:$B$31,0))=INDEX('👥 Participants'!$C$8:$C$31,MATCH($E16,'👥 Participants'!$B$8:$B$31,0))),"Team ","")&IF(AND(LastYearRule="On",IFERROR(INDEX('👥 Participants'!$G$8:$G$31,MATCH($B16,'👥 Participants'!$B$8:$B$31,0)),"")=$E16),"LastYear ","")&IF(COUNTIFS('🚫 Exclusions & Rules'!$B$8:$B$23,$B16,'🚫 Exclusions & Rules'!$C$8:$C$23,$E16)>0,"Custom ","")))) -> ✅ OK | G16: =IF($B16="","",INDEX('👥 Participants'!$H$8:$H$31,MATCH($B16,'👥 Participants'!$B$8:$B$31,0))) -> Not Started
A17: 10 | B17: =IF('👥 Participants'!$B$17="","",'👥 Participants'!$B$17) -> Jack Byrne | C17: =IF($B17="","",INDEX('👥 Participants'!$B$8:$B$31,MOD($A17-1+MOD(DrawSeed-1,MAX(1,COUNTA('👥 Participants'!$B$8:$B$31)-1)),COUNTA('👥 Participants'!$B$8:$B$31))+1)) -> Chloe Diaz | E17: =IF($B17="","",IF($D17<>"",$D17,$C17)) -> Chloe Diaz | F17: =IF($E17="","",IF(TRIM(IF($E17=$B17,"Self ","")&IF(AND(CoupleRule="On",IFERROR(INDEX('👥 Participants'!$D$8:$D$31,MATCH($B17,'👥 Participants'!$B$8:$B$31,0)),"")<>"",INDEX('👥 Participants'!$D$8:$D$31,MATCH($B17,'👥 Participants'!$B$8:$B$31,0))=INDEX('👥 Participants'!$D$8:$D$31,MATCH($E17,'👥 Participants'!$B$8:$B$31,0))),"Couple ","")&IF(AND(TeamRule="On",IFERROR(INDEX('👥 Participants'!$C$8:$C$31,MATCH($B17,'👥 Participants'!$B$8:$B$31,0)),"")<>"",INDEX('👥 Participants'!$C$8:$C$31,MATCH($B17,'👥 Participants'!$B$8:$B$31,0))=INDEX('👥 Participants'!$C$8:$C$31,MATCH($E17,'👥 Participants'!$B$8:$B$31,0))),"Team ","")&IF(AND(LastYearRule="On",IFERROR(INDEX('👥 Participants'!$G$8:$G$31,MATCH($B17,'👥 Participants'!$B$8:$B$31,0)),"")=$E17),"LastYear ","")&IF(COUNTIFS('🚫 Exclusions & Rules'!$B$8:$B$23,$B17,'🚫 Exclusions & Rules'!$C$8:$C$23,$E17)>0,"Custom ",""))="","✅ OK",TRIM(IF($E17=$B17,"Self ","")&IF(AND(CoupleRule="On",IFERROR(INDEX('👥 Participants'!$D$8:$D$31,MATCH($B17,'👥 Participants'!$B$8:$B$31,0)),"")<>"",INDEX('👥 Participants'!$D$8:$D$31,MATCH($B17,'👥 Participants'!$B$8:$B$31,0))=INDEX('👥 Participants'!$D$8:$D$31,MATCH($E17,'👥 Participants'!$B$8:$B$31,0))),"Couple ","")&IF(AND(TeamRule="On",IFERROR(INDEX('👥 Participants'!$C$8:$C$31,MATCH($B17,'👥 Participants'!$B$8:$B$31,0)),"")<>"",INDEX('👥 Participants'!$C$8:$C$31,MATCH($B17,'👥 Participants'!$B$8:$B$31,0))=INDEX('👥 Participants'!$C$8:$C$31,MATCH($E17,'👥 Participants'!$B$8:$B$31,0))),"Team ","")&IF(AND(LastYearRule="On",IFERROR(INDEX('👥 Participants'!$G$8:$G$31,MATCH($B17,'👥 Participants'!$B$8:$B$31,0)),"")=$E17),"LastYear ","")&IF(COUNTIFS('🚫 Exclusions & Rules'!$B$8:$B$23,$B17,'🚫 Exclusions & Rules'!$C$8:$C$23,$E17)>0,"Custom ","")))) -> ✅ OK | G17: =IF($B17="","",INDEX('👥 Participants'!$H$8:$H$31,MATCH($B17,'👥 Participants'!$B$8:$B$31,0))) -> Gift Purchased
A18: 11 | B18: =IF('👥 Participants'!$B$18="","",'👥 Participants'!$B$18) -> Kia Osei | C18: =IF($B18="","",INDEX('👥 Participants'!$B$8:$B$31,MOD($A18-1+MOD(DrawSeed-1,MAX(1,COUNTA('👥 Participants'!$B$8:$B$31)-1)),COUNTA('👥 Participants'!$B$8:$B$31))+1)) -> Dan Novak | E18: =IF($B18="","",IF($D18<>"",$D18,$C18)) -> Dan Novak | F18: =IF($E18="","",IF(TRIM(IF($E18=$B18,"Self ","")&IF(AND(CoupleRule="On",IFERROR(INDEX('👥 Participants'!$D$8:$D$31,MATCH($B18,'👥 Participants'!$B$8:$B$31,0)),"")<>"",INDEX('👥 Participants'!$D$8:$D$31,MATCH($B18,'👥 Participants'!$B$8:$B$31,0))=INDEX('👥 Participants'!$D$8:$D$31,MATCH($E18,'👥 Participants'!$B$8:$B$31,0))),"Couple ","")&IF(AND(TeamRule="On",IFERROR(INDEX('👥 Participants'!$C$8:$C$31,MATCH($B18,'👥 Participants'!$B$8:$B$31,0)),"")<>"",INDEX('👥 Participants'!$C$8:$C$31,MATCH($B18,'👥 Participants'!$B$8:$B$31,0))=INDEX('👥 Participants'!$C$8:$C$31,MATCH($E18,'👥 Participants'!$B$8:$B$31,0))),"Team ","")&IF(AND(LastYearRule="On",IFERROR(INDEX('👥 Participants'!$G$8:$G$31,MATCH($B18,'👥 Participants'!$B$8:$B$31,0)),"")=$E18),"LastYear ","")&IF(COUNTIFS('🚫 Exclusions & Rules'!$B$8:$B$23,$B18,'🚫 Exclusions & Rules'!$C$8:$C$23,$E18)>0,"Custom ",""))="","✅ OK",TRIM(IF($E18=$B18,"Self ","")&IF(AND(CoupleRule="On",IFERROR(INDEX('👥 Participants'!$D$8:$D$31,MATCH($B18,'👥 Participants'!$B$8:$B$31,0)),"")<>"",INDEX('👥 Participants'!$D$8:$D$31,MATCH($B18,'👥 Participants'!$B$8:$B$31,0))=INDEX('👥 Participants'!$D$8:$D$31,MATCH($E18,'👥 Participants'!$B$8:$B$31,0))),"Couple ","")&IF(AND(TeamRule="On",IFERROR(INDEX('👥 Participants'!$C$8:$C$31,MATCH($B18,'👥 Participants'!$B$8:$B$31,0)),"")<>"",INDEX('👥 Participants'!$C$8:$C$31,MATCH($B18,'👥 Participants'!$B$8:$B$31,0))=INDEX('👥 Participants'!$C$8:$C$31,MATCH($E18,'👥 Participants'!$B$8:$B$31,0))),"Team ","")&IF(AND(LastYearRule="On",IFERROR(INDEX('👥 Participants'!$G$8:$G$31,MATCH($B18,'👥 Participants'!$B$8:$B$31,0)),"")=$E18),"LastYear ","")&IF(COUNTIFS('🚫 Exclusions & Rules'!$B$8:$B$23,$B18,'🚫 Exclusions & Rules'!$C$8:$C$23,$E18)>0,"Custom ","")))) -> ✅ OK | G18: =IF($B18="","",INDEX('👥 Participants'!$H$8:$H$31,MATCH($B18,'👥 Participants'!$B$8:$B$31,0))) -> Wrapped
A19: 12 | B19: =IF('👥 Participants'!$B$19="","",'👥 Participants'!$B$19) -> Leo Fontaine | C19: =IF($B19="","",INDEX('👥 Participants'!$B$8:$B$31,MOD($A19-1+MOD(DrawSeed-1,MAX(1,COUNTA('👥 Participants'!$B$8:$B$31)-1)),COUNTA('👥 Participants'!$B$8:$B$31))+1)) -> Elena Petrov | E19: =IF($B19="","",IF($D19<>"",$D19,$C19)) -> Elena Petrov | F19: =IF($E19="","",IF(TRIM(IF($E19=$B19,"Self ","")&IF(AND(CoupleRule="On",IFERROR(INDEX('👥 Participants'!$D$8:$D$31,MATCH($B19,'👥 Participants'!$B$8:$B$31,0)),"")<>"",INDEX('👥 Participants'!$D$8:$D$31,MATCH($B19,'👥 Participants'!$B$8:$B$31,0))=INDEX('👥 Participants'!$D$8:$D$31,MATCH($E19,'👥 Participants'!$B$8:$B$31,0))),"Couple ","")&IF(AND(TeamRule="On",IFERROR(INDEX('👥 Participants'!$C$8:$C$31,MATCH($B19,'👥 Participants'!$B$8:$B$31,0)),"")<>"",INDEX('👥 Participants'!$C$8:$C$31,MATCH($B19,'👥 Participants'!$B$8:$B$31,0))=INDEX('👥 Participants'!$C$8:$C$31,MATCH($E19,'👥 Participants'!$B$8:$B$31,0))),"Team ","")&IF(AND(LastYearRule="On",IFERROR(INDEX('👥 Participants'!$G$8:$G$31,MATCH($B19,'👥 Participants'!$B$8:$B$31,0)),"")=$E19),"LastYear ","")&IF(COUNTIFS('🚫 Exclusions & Rules'!$B$8:$B$23,$B19,'🚫 Exclusions & Rules'!$C$8:$C$23,$E19)>0,"Custom ",""))="","✅ OK",TRIM(IF($E19=$B19,"Self ","")&IF(AND(CoupleRule="On",IFERROR(INDEX('👥 Participants'!$D$8:$D$31,MATCH($B19,'👥 Participants'!$B$8:$B$31,0)),"")<>"",INDEX('👥 Participants'!$D$8:$D$31,MATCH($B19,'👥 Participants'!$B$8:$B$31,0))=INDEX('👥 Participants'!$D$8:$D$31,MATCH($E19,'👥 Participants'!$B$8:$B$31,0))),"Couple ","")&IF(AND(TeamRule="On",IFERROR(INDEX('👥 Participants'!$C$8:$C$31,MATCH($B19,'👥 Participants'!$B$8:$B$31,0)),"")<>"",INDEX('👥 Participants'!$C$8:$C$31,MATCH($B19,'👥 Participants'!$B$8:$B$31,0))=INDEX('👥 Participants'!$C$8:$C$31,MATCH($E19,'👥 Participants'!$B$8:$B$31,0))),"Team ","")&IF(AND(LastYearRule="On",IFERROR(INDEX('👥 Participants'!$G$8:$G$31,MATCH($B19,'👥 Participants'!$B$8:$B$31,0)),"")=$E19),"LastYear ","")&IF(COUNTIFS('🚫 Exclusions & Rules'!$B$8:$B$23,$B19,'🚫 Exclusions & Rules'!$C$8:$C$23,$E19)>0,"Custom ","")))) -> ✅ OK | G19: =IF($B19="","",INDEX('👥 Participants'!$H$8:$H$31,MATCH($B19,'👥 Participants'!$B$8:$B$31,0))) -> Gift Purchased
A20: 13 | B20: =IF('👥 Participants'!$B$20="","",'👥 Participants'!$B$20) | C20: =IF($B20="","",INDEX('👥 Participants'!$B$8:$B$31,MOD($A20-1+MOD(DrawSeed-1,MAX(1,COUNTA('👥 Participants'!$B$8:$B$31)-1)),COUNTA('👥 Participants'!$B$8:$B$31))+1)) | E20: =IF($B20="","",IF($D20<>"",$D20,$C20)) | F20: =IF($E20="","",IF(TRIM(IF($E20=$B20,"Self ","")&IF(AND(CoupleRule="On",IFERROR(INDEX('👥 Participants'!$D$8:$D$31,MATCH($B20,'👥 Participants'!$B$8:$B$31,0)),"")<>"",INDEX('👥 Participants'!$D$8:$D$31,MATCH($B20,'👥 Participants'!$B$8:$B$31,0))=INDEX('👥 Participants'!$D$8:$D$31,MATCH($E20,'👥 Participants'!$B$8:$B$31,0))),"Couple ","")&IF(AND(TeamRule="On",IFERROR(INDEX('👥 Participants'!$C$8:$C$31,MATCH($B20,'👥 Participants'!$B$8:$B$31,0)),"")<>"",INDEX('👥 Participants'!$C$8:$C$31,MATCH($B20,'👥 Participants'!$B$8:$B$31,0))=INDEX('👥 Participants'!$C$8:$C$31,MATCH($E20,'👥 Participants'!$B$8:$B$31,0))),"Team ","")&IF(AND(LastYearRule="On",IFERROR(INDEX('👥 Participants'!$G$8:$G$31,MATCH($B20,'👥 Participants'!$B$8:$B$31,0)),"")=$E20),"LastYear ","")&IF(COUNTIFS('🚫 Exclusions & Rules'!$B$8:$B$23,$B20,'🚫 Exclusions & Rules'!$C$8:$C$23,$E20)>0,"Custom ",""))="","✅ OK",TRIM(IF($E20=$B20,"Self ","")&IF(AND(CoupleRule="On",IFERROR(INDEX('👥 Participants'!$D$8:$D$31,MATCH($B20,'👥 Participants'!$B$8:$B$31,0)),"")<>"",INDEX('👥 Participants'!$D$8:$D$31,MATCH($B20,'👥 Participants'!$B$8:$B$31,0))=INDEX('👥 Participants'!$D$8:$D$31,MATCH($E20,'👥 Participants'!$B$8:$B$31,0))),"Couple ","")&IF(AND(TeamRule="On",IFERROR(INDEX('👥 Participants'!$C$8:$C$31,MATCH($B20,'👥 Participants'!$B$8:$B$31,0)),"")<>"",INDEX('👥 Participants'!$C$8:$C$31,MATCH($B20,'👥 Participants'!$B$8:$B$31,0))=INDEX('👥 Participants'!$C$8:$C$31,MATCH($E20,'👥 Participants'!$B$8:$B$31,0))),"Team ","")&IF(AND(LastYearRule="On",IFERROR(INDEX('👥 Participants'!$G$8:$G$31,MATCH($B20,'👥 Participants'!$B$8:$B$31,0)),"")=$E20),"LastYear ","")&IF(COUNTIFS('🚫 Exclusions & Rules'!$B$8:$B$23,$B20,'🚫 Exclusions & Rules'!$C$8:$C$23,$E20)>0,"Custom ","")))) | G20: =IF($B20="","",INDEX('👥 Participants'!$H$8:$H$31,MATCH($B20,'👥 Participants'!$B$8:$B$31,0)))
A21: 14 | B21: =IF('👥 Participants'!$B$21="","",'👥 Participants'!$B$21) | C21: =IF($B21="","",INDEX('👥 Participants'!$B$8:$B$31,MOD($A21-1+MOD(DrawSeed-1,MAX(1,COUNTA('👥 Participants'!$B$8:$B$31)-1)),COUNTA('👥 Participants'!$B$8:$B$31))+1)) | E21: =IF($B21="","",IF($D21<>"",$D21,$C21)) | F21: =IF($E21="","",IF(TRIM(IF($E21=$B21,"Self ","")&IF(AND(CoupleRule="On",IFERROR(INDEX('👥 Participants'!$D$8:$D$31,MATCH($B21,'👥 Participants'!$B$8:$B$31,0)),"")<>"",INDEX('👥 Participants'!$D$8:$D$31,MATCH($B21,'👥 Participants'!$B$8:$B$31,0))=INDEX('👥 Participants'!$D$8:$D$31,MATCH($E21,'👥 Participants'!$B$8:$B$31,0))),"Couple ","")&IF(AND(TeamRule="On",IFERROR(INDEX('👥 Participants'!$C$8:$C$31,MATCH($B21,'👥 Participants'!$B$8:$B$31,0)),"")<>"",INDEX('👥 Participants'!$C$8:$C$31,MATCH($B21,'👥 Participants'!$B$8:$B$31,0))=INDEX('👥 Participants'!$C$8:$C$31,MATCH($E21,'👥 Participants'!$B$8:$B$31,0))),"Team ","")&IF(AND(LastYearRule="On",IFERROR(INDEX('👥 Participants'!$G$8:$G$31,MATCH($B21,'👥 Participants'!$B$8:$B$31,0)),"")=$E21),"LastYear ","")&IF(COUNTIFS('🚫 Exclusions & Rules'!$B$8:$B$23,$B21,'🚫 Exclusions & Rules'!$C$8:$C$23,$E21)>0,"Custom ",""))="","✅ OK",TRIM(IF($E21=$B21,"Self ","")&IF(AND(CoupleRule="On",IFERROR(INDEX('👥 Participants'!$D$8:$D$31,MATCH($B21,'👥 Participants'!$B$8:$B$31,0)),"")<>"",INDEX('👥 Participants'!$D$8:$D$31,MATCH($B21,'👥 Participants'!$B$8:$B$31,0))=INDEX('👥 Participants'!$D$8:$D$31,MATCH($E21,'👥 Participants'!$B$8:$B$31,0))),"Couple ","")&IF(AND(TeamRule="On",IFERROR(INDEX('👥 Participants'!$C$8:$C$31,MATCH($B21,'👥 Participants'!$B$8:$B$31,0)),"")<>"",INDEX('👥 Participants'!$C$8:$C$31,MATCH($B21,'👥 Participants'!$B$8:$B$31,0))=INDEX('👥 Participants'!$C$8:$C$31,MATCH($E21,'👥 Participants'!$B$8:$B$31,0))),"Team ","")&IF(AND(LastYearRule="On",IFERROR(INDEX('👥 Participants'!$G$8:$G$31,MATCH($B21,'👥 Participants'!$B$8:$B$31,0)),"")=$E21),"LastYear ","")&IF(COUNTIFS('🚫 Exclusions & Rules'!$B$8:$B$23,$B21,'🚫 Exclusions & Rules'!$C$8:$C$23,$E21)>0,"Custom ","")))) | G21: =IF($B21="","",INDEX('👥 Participants'!$H$8:$H$31,MATCH($B21,'👥 Participants'!$B$8:$B$31,0)))
A22: 15 | B22: =IF('👥 Participants'!$B$22="","",'👥 Participants'!$B$22) | C22: =IF($B22="","",INDEX('👥 Participants'!$B$8:$B$31,MOD($A22-1+MOD(DrawSeed-1,MAX(1,COUNTA('👥 Participants'!$B$8:$B$31)-1)),COUNTA('👥 Participants'!$B$8:$B$31))+1)) | E22: =IF($B22="","",IF($D22<>"",$D22,$C22)) | F22: =IF($E22="","",IF(TRIM(IF($E22=$B22,"Self ","")&IF(AND(CoupleRule="On",IFERROR(INDEX('👥 Participants'!$D$8:$D$31,MATCH($B22,'👥 Participants'!$B$8:$B$31,0)),"")<>"",INDEX('👥 Participants'!$D$8:$D$31,MATCH($B22,'👥 Participants'!$B$8:$B$31,0))=INDEX('👥 Participants'!$D$8:$D$31,MATCH($E22,'👥 Participants'!$B$8:$B$31,0))),"Couple ","")&IF(AND(TeamRule="On",IFERROR(INDEX('👥 Participants'!$C$8:$C$31,MATCH($B22,'👥 Participants'!$B$8:$B$31,0)),"")<>"",INDEX('👥 Participants'!$C$8:$C$31,MATCH($B22,'👥 Participants'!$B$8:$B$31,0))=INDEX('👥 Participants'!$C$8:$C$31,MATCH($E22,'👥 Participants'!$B$8:$B$31,0))),"Team ","")&IF(AND(LastYearRule="On",IFERROR(INDEX('👥 Participants'!$G$8:$G$31,MATCH($B22,'👥 Participants'!$B$8:$B$31,0)),"")=$E22),"LastYear ","")&IF(COUNTIFS('🚫 Exclusions & Rules'!$B$8:$B$23,$B22,'🚫 Exclusions & Rules'!$C$8:$C$23,$E22)>0,"Custom ",""))="","✅ OK",TRIM(IF($E22=$B22,"Self ","")&IF(AND(CoupleRule="On",IFERROR(INDEX('👥 Participants'!$D$8:$D$31,MATCH($B22,'👥 Participants'!$B$8:$B$31,0)),"")<>"",INDEX('👥 Participants'!$D$8:$D$31,MATCH($B22,'👥 Participants'!$B$8:$B$31,0))=INDEX('👥 Participants'!$D$8:$D$31,MATCH($E22,'👥 Participants'!$B$8:$B$31,0))),"Couple ","")&IF(AND(TeamRule="On",IFERROR(INDEX('👥 Participants'!$C$8:$C$31,MATCH($B22,'👥 Participants'!$B$8:$B$31,0)),"")<>"",INDEX('👥 Participants'!$C$8:$C$31,MATCH($B22,'👥 Participants'!$B$8:$B$31,0))=INDEX('👥 Participants'!$C$8:$C$31,MATCH($E22,'👥 Participants'!$B$8:$B$31,0))),"Team ","")&IF(AND(LastYearRule="On",IFERROR(INDEX('👥 Participants'!$G$8:$G$31,MATCH($B22,'👥 Participants'!$B$8:$B$31,0)),"")=$E22),"LastYear ","")&IF(COUNTIFS('🚫 Exclusions & Rules'!$B$8:$B$23,$B22,'🚫 Exclusions & Rules'!$C$8:$C$23,$E22)>0,"Custom ","")))) | G22: =IF($B22="","",INDEX('👥 Participants'!$H$8:$H$31,MATCH($B22,'👥 Participants'!$B$8:$B$31,0)))
A23: 16 | B23: =IF('👥 Participants'!$B$23="","",'👥 Participants'!$B$23) | C23: =IF($B23="","",INDEX('👥 Participants'!$B$8:$B$31,MOD($A23-1+MOD(DrawSeed-1,MAX(1,COUNTA('👥 Participants'!$B$8:$B$31)-1)),COUNTA('👥 Participants'!$B$8:$B$31))+1)) | E23: =IF($B23="","",IF($D23<>"",$D23,$C23)) | F23: =IF($E23="","",IF(TRIM(IF($E23=$B23,"Self ","")&IF(AND(CoupleRule="On",IFERROR(INDEX('👥 Participants'!$D$8:$D$31,MATCH($B23,'👥 Participants'!$B$8:$B$31,0)),"")<>"",INDEX('👥 Participants'!$D$8:$D$31,MATCH($B23,'👥 Participants'!$B$8:$B$31,0))=INDEX('👥 Participants'!$D$8:$D$31,MATCH($E23,'👥 Participants'!$B$8:$B$31,0))),"Couple ","")&IF(AND(TeamRule="On",IFERROR(INDEX('👥 Participants'!$C$8:$C$31,MATCH($B23,'👥 Participants'!$B$8:$B$31,0)),"")<>"",INDEX('👥 Participants'!$C$8:$C$31,MATCH($B23,'👥 Participants'!$B$8:$B$31,0))=INDEX('👥 Participants'!$C$8:$C$31,MATCH($E23,'👥 Participants'!$B$8:$B$31,0))),"Team ","")&IF(AND(LastYearRule="On",IFERROR(INDEX('👥 Participants'!$G$8:$G$31,MATCH($B23,'👥 Participants'!$B$8:$B$31,0)),"")=$E23),"LastYear ","")&IF(COUNTIFS('🚫 Exclusions & Rules'!$B$8:$B$23,$B23,'🚫 Exclusions & Rules'!$C$8:$C$23,$E23)>0,"Custom ",""))="","✅ OK",TRIM(IF($E23=$B23,"Self ","")&IF(AND(CoupleRule="On",IFERROR(INDEX('👥 Participants'!$D$8:$D$31,MATCH($B23,'👥 Participants'!$B$8:$B$31,0)),"")<>"",INDEX('👥 Participants'!$D$8:$D$31,MATCH($B23,'👥 Participants'!$B$8:$B$31,0))=INDEX('👥 Participants'!$D$8:$D$31,MATCH($E23,'👥 Participants'!$B$8:$B$31,0))),"Couple ","")&IF(AND(TeamRule="On",IFERROR(INDEX('👥 Participants'!$C$8:$C$31,MATCH($B23,'👥 Participants'!$B$8:$B$31,0)),"")<>"",INDEX('👥 Participants'!$C$8:$C$31,MATCH($B23,'👥 Participants'!$B$8:$B$31,0))=INDEX('👥 Participants'!$C$8:$C$31,MATCH($E23,'👥 Participants'!$B$8:$B$31,0))),"Team ","")&IF(AND(LastYearRule="On",IFERROR(INDEX('👥 Participants'!$G$8:$G$31,MATCH($B23,'👥 Participants'!$B$8:$B$31,0)),"")=$E23),"LastYear ","")&IF(COUNTIFS('🚫 Exclusions & Rules'!$B$8:$B$23,$B23,'🚫 Exclusions & Rules'!$C$8:$C$23,$E23)>0,"Custom ","")))) | G23: =IF($B23="","",INDEX('👥 Participants'!$H$8:$H$31,MATCH($B23,'👥 Participants'!$B$8:$B$31,0)))
A24: 17 | B24: =IF('👥 Participants'!$B$24="","",'👥 Participants'!$B$24) | C24: =IF($B24="","",INDEX('👥 Participants'!$B$8:$B$31,MOD($A24-1+MOD(DrawSeed-1,MAX(1,COUNTA('👥 Participants'!$B$8:$B$31)-1)),COUNTA('👥 Participants'!$B$8:$B$31))+1)) | E24: =IF($B24="","",IF($D24<>"",$D24,$C24)) | F24: =IF($E24="","",IF(TRIM(IF($E24=$B24,"Self ","")&IF(AND(CoupleRule="On",IFERROR(INDEX('👥 Participants'!$D$8:$D$31,MATCH($B24,'👥 Participants'!$B$8:$B$31,0)),"")<>"",INDEX('👥 Participants'!$D$8:$D$31,MATCH($B24,'👥 Participants'!$B$8:$B$31,0))=INDEX('👥 Participants'!$D$8:$D$31,MATCH($E24,'👥 Participants'!$B$8:$B$31,0))),"Couple ","")&IF(AND(TeamRule="On",IFERROR(INDEX('👥 Participants'!$C$8:$C$31,MATCH($B24,'👥 Participants'!$B$8:$B$31,0)),"")<>"",INDEX('👥 Participants'!$C$8:$C$31,MATCH($B24,'👥 Participants'!$B$8:$B$31,0))=INDEX('👥 Participants'!$C$8:$C$31,MATCH($E24,'👥 Participants'!$B$8:$B$31,0))),"Team ","")&IF(AND(LastYearRule="On",IFERROR(INDEX('👥 Participants'!$G$8:$G$31,MATCH($B24,'👥 Participants'!$B$8:$B$31,0)),"")=$E24),"LastYear ","")&IF(COUNTIFS('🚫 Exclusions & Rules'!$B$8:$B$23,$B24,'🚫 Exclusions & Rules'!$C$8:$C$23,$E24)>0,"Custom ",""))="","✅ OK",TRIM(IF($E24=$B24,"Self ","")&IF(AND(CoupleRule="On",IFERROR(INDEX('👥 Participants'!$D$8:$D$31,MATCH($B24,'👥 Participants'!$B$8:$B$31,0)),"")<>"",INDEX('👥 Participants'!$D$8:$D$31,MATCH($B24,'👥 Participants'!$B$8:$B$31,0))=INDEX('👥 Participants'!$D$8:$D$31,MATCH($E24,'👥 Participants'!$B$8:$B$31,0))),"Couple ","")&IF(AND(TeamRule="On",IFERROR(INDEX('👥 Participants'!$C$8:$C$31,MATCH($B24,'👥 Participants'!$B$8:$B$31,0)),"")<>"",INDEX('👥 Participants'!$C$8:$C$31,MATCH($B24,'👥 Participants'!$B$8:$B$31,0))=INDEX('👥 Participants'!$C$8:$C$31,MATCH($E24,'👥 Participants'!$B$8:$B$31,0))),"Team ","")&IF(AND(LastYearRule="On",IFERROR(INDEX('👥 Participants'!$G$8:$G$31,MATCH($B24,'👥 Participants'!$B$8:$B$31,0)),"")=$E24),"LastYear ","")&IF(COUNTIFS('🚫 Exclusions & Rules'!$B$8:$B$23,$B24,'🚫 Exclusions & Rules'!$C$8:$C$23,$E24)>0,"Custom ","")))) | G24: =IF($B24="","",INDEX('👥 Participants'!$H$8:$H$31,MATCH($B24,'👥 Participants'!$B$8:$B$31,0)))
A25: 18 | B25: =IF('👥 Participants'!$B$25="","",'👥 Participants'!$B$25) | C25: =IF($B25="","",INDEX('👥 Participants'!$B$8:$B$31,MOD($A25-1+MOD(DrawSeed-1,MAX(1,COUNTA('👥 Participants'!$B$8:$B$31)-1)),COUNTA('👥 Participants'!$B$8:$B$31))+1)) | E25: =IF($B25="","",IF($D25<>"",$D25,$C25)) | F25: =IF($E25="","",IF(TRIM(IF($E25=$B25,"Self ","")&IF(AND(CoupleRule="On",IFERROR(INDEX('👥 Participants'!$D$8:$D$31,MATCH($B25,'👥 Participants'!$B$8:$B$31,0)),"")<>"",INDEX('👥 Participants'!$D$8:$D$31,MATCH($B25,'👥 Participants'!$B$8:$B$31,0))=INDEX('👥 Participants'!$D$8:$D$31,MATCH($E25,'👥 Participants'!$B$8:$B$31,0))),"Couple ","")&IF(AND(TeamRule="On",IFERROR(INDEX('👥 Participants'!$C$8:$C$31,MATCH($B25,'👥 Participants'!$B$8:$B$31,0)),"")<>"",INDEX('👥 Participants'!$C$8:$C$31,MATCH($B25,'👥 Participants'!$B$8:$B$31,0))=INDEX('👥 Participants'!$C$8:$C$31,MATCH($E25,'👥 Participants'!$B$8:$B$31,0))),"Team ","")&IF(AND(LastYearRule="On",IFERROR(INDEX('👥 Participants'!$G$8:$G$31,MATCH($B25,'👥 Participants'!$B$8:$B$31,0)),"")=$E25),"LastYear ","")&IF(COUNTIFS('🚫 Exclusions & Rules'!$B$8:$B$23,$B25,'🚫 Exclusions & Rules'!$C$8:$C$23,$E25)>0,"Custom ",""))="","✅ OK",TRIM(IF($E25=$B25,"Self ","")&IF(AND(CoupleRule="On",IFERROR(INDEX('👥 Participants'!$D$8:$D$31,MATCH($B25,'👥 Participants'!$B$8:$B$31,0)),"")<>"",INDEX('👥 Participants'!$D$8:$D$31,MATCH($B25,'👥 Participants'!$B$8:$B$31,0))=INDEX('👥 Participants'!$D$8:$D$31,MATCH($E25,'👥 Participants'!$B$8:$B$31,0))),"Couple ","")&IF(AND(TeamRule="On",IFERROR(INDEX('👥 Participants'!$C$8:$C$31,MATCH($B25,'👥 Participants'!$B$8:$B$31,0)),"")<>"",INDEX('👥 Participants'!$C$8:$C$31,MATCH($B25,'👥 Participants'!$B$8:$B$31,0))=INDEX('👥 Participants'!$C$8:$C$31,MATCH($E25,'👥 Participants'!$B$8:$B$31,0))),"Team ","")&IF(AND(LastYearRule="On",IFERROR(INDEX('👥 Participants'!$G$8:$G$31,MATCH($B25,'👥 Participants'!$B$8:$B$31,0)),"")=$E25),"LastYear ","")&IF(COUNTIFS('🚫 Exclusions & Rules'!$B$8:$B$23,$B25,'🚫 Exclusions & Rules'!$C$8:$C$23,$E25)>0,"Custom ","")))) | G25: =IF($B25="","",INDEX('👥 Participants'!$H$8:$H$31,MATCH($B25,'👥 Participants'!$B$8:$B$31,0)))
A26: 19 | B26: =IF('👥 Participants'!$B$26="","",'👥 Participants'!$B$26) | C26: =IF($B26="","",INDEX('👥 Participants'!$B$8:$B$31,MOD($A26-1+MOD(DrawSeed-1,MAX(1,COUNTA('👥 Participants'!$B$8:$B$31)-1)),COUNTA('👥 Participants'!$B$8:$B$31))+1)) | E26: =IF($B26="","",IF($D26<>"",$D26,$C26)) | F26: =IF($E26="","",IF(TRIM(IF($E26=$B26,"Self ","")&IF(AND(CoupleRule="On",IFERROR(INDEX('👥 Participants'!$D$8:$D$31,MATCH($B26,'👥 Participants'!$B$8:$B$31,0)),"")<>"",INDEX('👥 Participants'!$D$8:$D$31,MATCH($B26,'👥 Participants'!$B$8:$B$31,0))=INDEX('👥 Participants'!$D$8:$D$31,MATCH($E26,'👥 Participants'!$B$8:$B$31,0))),"Couple ","")&IF(AND(TeamRule="On",IFERROR(INDEX('👥 Participants'!$C$8:$C$31,MATCH($B26,'👥 Participants'!$B$8:$B$31,0)),"")<>"",INDEX('👥 Participants'!$C$8:$C$31,MATCH($B26,'👥 Participants'!$B$8:$B$31,0))=INDEX('👥 Participants'!$C$8:$C$31,MATCH($E26,'👥 Participants'!$B$8:$B$31,0))),"Team ","")&IF(AND(LastYearRule="On",IFERROR(INDEX('👥 Participants'!$G$8:$G$31,MATCH($B26,'👥 Participants'!$B$8:$B$31,0)),"")=$E26),"LastYear ","")&IF(COUNTIFS('🚫 Exclusions & Rules'!$B$8:$B$23,$B26,'🚫 Exclusions & Rules'!$C$8:$C$23,$E26)>0,"Custom ",""))="","✅ OK",TRIM(IF($E26=$B26,"Self ","")&IF(AND(CoupleRule="On",IFERROR(INDEX('👥 Participants'!$D$8:$D$31,MATCH($B26,'👥 Participants'!$B$8:$B$31,0)),"")<>"",INDEX('👥 Participants'!$D$8:$D$31,MATCH($B26,'👥 Participants'!$B$8:$B$31,0))=INDEX('👥 Participants'!$D$8:$D$31,MATCH($E26,'👥 Participants'!$B$8:$B$31,0))),"Couple ","")&IF(AND(TeamRule="On",IFERROR(INDEX('👥 Participants'!$C$8:$C$31,MATCH($B26,'👥 Participants'!$B$8:$B$31,0)),"")<>"",INDEX('👥 Participants'!$C$8:$C$31,MATCH($B26,'👥 Participants'!$B$8:$B$31,0))=INDEX('👥 Participants'!$C$8:$C$31,MATCH($E26,'👥 Participants'!$B$8:$B$31,0))),"Team ","")&IF(AND(LastYearRule="On",IFERROR(INDEX('👥 Participants'!$G$8:$G$31,MATCH($B26,'👥 Participants'!$B$8:$B$31,0)),"")=$E26),"LastYear ","")&IF(COUNTIFS('🚫 Exclusions & Rules'!$B$8:$B$23,$B26,'🚫 Exclusions & Rules'!$C$8:$C$23,$E26)>0,"Custom ","")))) | G26: =IF($B26="","",INDEX('👥 Participants'!$H$8:$H$31,MATCH($B26,'👥 Participants'!$B$8:$B$31,0)))
A27: 20 | B27: =IF('👥 Participants'!$B$27="","",'👥 Participants'!$B$27) | C27: =IF($B27="","",INDEX('👥 Participants'!$B$8:$B$31,MOD($A27-1+MOD(DrawSeed-1,MAX(1,COUNTA('👥 Participants'!$B$8:$B$31)-1)),COUNTA('👥 Participants'!$B$8:$B$31))+1)) | E27: =IF($B27="","",IF($D27<>"",$D27,$C27)) | F27: =IF($E27="","",IF(TRIM(IF($E27=$B27,"Self ","")&IF(AND(CoupleRule="On",IFERROR(INDEX('👥 Participants'!$D$8:$D$31,MATCH($B27,'👥 Participants'!$B$8:$B$31,0)),"")<>"",INDEX('👥 Participants'!$D$8:$D$31,MATCH($B27,'👥 Participants'!$B$8:$B$31,0))=INDEX('👥 Participants'!$D$8:$D$31,MATCH($E27,'👥 Participants'!$B$8:$B$31,0))),"Couple ","")&IF(AND(TeamRule="On",IFERROR(INDEX('👥 Participants'!$C$8:$C$31,MATCH($B27,'👥 Participants'!$B$8:$B$31,0)),"")<>"",INDEX('👥 Participants'!$C$8:$C$31,MATCH($B27,'👥 Participants'!$B$8:$B$31,0))=INDEX('👥 Participants'!$C$8:$C$31,MATCH($E27,'👥 Participants'!$B$8:$B$31,0))),"Team ","")&IF(AND(LastYearRule="On",IFERROR(INDEX('👥 Participants'!$G$8:$G$31,MATCH($B27,'👥 Participants'!$B$8:$B$31,0)),"")=$E27),"LastYear ","")&IF(COUNTIFS('🚫 Exclusions & Rules'!$B$8:$B$23,$B27,'🚫 Exclusions & Rules'!$C$8:$C$23,$E27)>0,"Custom ",""))="","✅ OK",TRIM(IF($E27=$B27,"Self ","")&IF(AND(CoupleRule="On",IFERROR(INDEX('👥 Participants'!$D$8:$D$31,MATCH($B27,'👥 Participants'!$B$8:$B$31,0)),"")<>"",INDEX('👥 Participants'!$D$8:$D$31,MATCH($B27,'👥 Participants'!$B$8:$B$31,0))=INDEX('👥 Participants'!$D$8:$D$31,MATCH($E27,'👥 Participants'!$B$8:$B$31,0))),"Couple ","")&IF(AND(TeamRule="On",IFERROR(INDEX('👥 Participants'!$C$8:$C$31,MATCH($B27,'👥 Participants'!$B$8:$B$31,0)),"")<>"",INDEX('👥 Participants'!$C$8:$C$31,MATCH($B27,'👥 Participants'!$B$8:$B$31,0))=INDEX('👥 Participants'!$C$8:$C$31,MATCH($E27,'👥 Participants'!$B$8:$B$31,0))),"Team ","")&IF(AND(LastYearRule="On",IFERROR(INDEX('👥 Participants'!$G$8:$G$31,MATCH($B27,'👥 Participants'!$B$8:$B$31,0)),"")=$E27),"LastYear ","")&IF(COUNTIFS('🚫 Exclusions & Rules'!$B$8:$B$23,$B27,'🚫 Exclusions & Rules'!$C$8:$C$23,$E27)>0,"Custom ","")))) | G27: =IF($B27="","",INDEX('👥 Participants'!$H$8:$H$31,MATCH($B27,'👥 Participants'!$B$8:$B$31,0)))
A28: 21 | B28: =IF('👥 Participants'!$B$28="","",'👥 Participants'!$B$28) | C28: =IF($B28="","",INDEX('👥 Participants'!$B$8:$B$31,MOD($A28-1+MOD(DrawSeed-1,MAX(1,COUNTA('👥 Participants'!$B$8:$B$31)-1)),COUNTA('👥 Participants'!$B$8:$B$31))+1)) | E28: =IF($B28="","",IF($D28<>"",$D28,$C28)) | F28: =IF($E28="","",IF(TRIM(IF($E28=$B28,"Self ","")&IF(AND(CoupleRule="On",IFERROR(INDEX('👥 Participants'!$D$8:$D$31,MATCH($B28,'👥 Participants'!$B$8:$B$31,0)),"")<>"",INDEX('👥 Participants'!$D$8:$D$31,MATCH($B28,'👥 Participants'!$B$8:$B$31,0))=INDEX('👥 Participants'!$D$8:$D$31,MATCH($E28,'👥 Participants'!$B$8:$B$31,0))),"Couple ","")&IF(AND(TeamRule="On",IFERROR(INDEX('👥 Participants'!$C$8:$C$31,MATCH($B28,'👥 Participants'!$B$8:$B$31,0)),"")<>"",INDEX('👥 Participants'!$C$8:$C$31,MATCH($B28,'👥 Participants'!$B$8:$B$31,0))=INDEX('👥 Participants'!$C$8:$C$31,MATCH($E28,'👥 Participants'!$B$8:$B$31,0))),"Team ","")&IF(AND(LastYearRule="On",IFERROR(INDEX('👥 Participants'!$G$8:$G$31,MATCH($B28,'👥 Participants'!$B$8:$B$31,0)),"")=$E28),"LastYear ","")&IF(COUNTIFS('🚫 Exclusions & Rules'!$B$8:$B$23,$B28,'🚫 Exclusions & Rules'!$C$8:$C$23,$E28)>0,"Custom ",""))="","✅ OK",TRIM(IF($E28=$B28,"Self ","")&IF(AND(CoupleRule="On",IFERROR(INDEX('👥 Participants'!$D$8:$D$31,MATCH($B28,'👥 Participants'!$B$8:$B$31,0)),"")<>"",INDEX('👥 Participants'!$D$8:$D$31,MATCH($B28,'👥 Participants'!$B$8:$B$31,0))=INDEX('👥 Participants'!$D$8:$D$31,MATCH($E28,'👥 Participants'!$B$8:$B$31,0))),"Couple ","")&IF(AND(TeamRule="On",IFERROR(INDEX('👥 Participants'!$C$8:$C$31,MATCH($B28,'👥 Participants'!$B$8:$B$31,0)),"")<>"",INDEX('👥 Participants'!$C$8:$C$31,MATCH($B28,'👥 Participants'!$B$8:$B$31,0))=INDEX('👥 Participants'!$C$8:$C$31,MATCH($E28,'👥 Participants'!$B$8:$B$31,0))),"Team ","")&IF(AND(LastYearRule="On",IFERROR(INDEX('👥 Participants'!$G$8:$G$31,MATCH($B28,'👥 Participants'!$B$8:$B$31,0)),"")=$E28),"LastYear ","")&IF(COUNTIFS('🚫 Exclusions & Rules'!$B$8:$B$23,$B28,'🚫 Exclusions & Rules'!$C$8:$C$23,$E28)>0,"Custom ","")))) | G28: =IF($B28="","",INDEX('👥 Participants'!$H$8:$H$31,MATCH($B28,'👥 Participants'!$B$8:$B$31,0)))
