Workbook
Name AccessList: Lists!$A$35:$A$53
Name AnnualRevenueTarget: Settings!$D$66
Name AreaUnit: Settings!$D$23
Name AreaUnitList: Lists!$E$282:$E$291
Name AttendanceList: Lists!$G$156:$G$173
Name BillingCycleList: Lists!$I$80:$I$95
Name BizAddress: Settings!$D$10
Name BizArea: Settings!$D$12
Name BizEmail: Settings!$D$8
Name BizInsurance: Settings!$D$15
Name BizName: Settings!$D$6
Name BizOwner: Settings!$D$7
Name BizPayDetails: Settings!$D$62
Name BizPhone: Settings!$D$9
Name BizRegNo: Settings!$D$14
Name BizTagline: Settings!$D$13
Name BizWebsite: Settings!$D$11
Name CalloutFee: Settings!$D$38
Name CalStart: Calendar!$B$5
Name CertWarningDays: Settings!$D$79
Name CleanersPerJob: Settings!$D$21
Name ClientIDs: OFFSET(Clients!$A$5,0,0,MAX(1,COUNTIF(Clients!$A$5:$A$204,"?*")),1)
Name ClientNames: OFFSET(Clients!$B$5,0,0,MAX(1,COUNTIF(Clients!$B$5:$B$204,"?*")),1)
Name ClientPrefix: Settings!$D$84
Name ClientStatusList: Lists!$G$9:$G$25
Name ClientTypeList: Lists!$E$9:$E$31
Name ComplaintPrefix: Settings!$D$96
Name ComplaintStatusList: Lists!$E$233:$E$248
Name ComplaintTypeList: Lists!$C$233:$C$254
Name ConditionFactors: Lists!$B$337:$B$345
Name ConditionList: Lists!$G$35:$G$47
Name ConditionNames: Lists!$A$337:$A$345
Name ContractStatusList: Lists!$E$80:$E$97
Name ContractTermList: Lists!$G$80:$G$94
Name CostPerHour: Settings!$D$49
Name DashKey: Dashboard!$H$5
Name DashMonth: Dashboard!$F$5
Name DeepCleanUplift: Settings!$D$39
Name DepositPercent: Settings!$D$42
Name DistanceUnit: Settings!$D$24
Name DistanceUnitList: Lists!$G$282:$G$291
Name DocStatusList: Lists!$E$257:$E$270
Name EmployeeIDs: OFFSET(Employees!$A$5,0,0,MAX(1,COUNTIF(Employees!$A$5:$A$44,"?*")),1)
Name EmployeeNames: OFFSET(Employees!$B$5,0,0,MAX(1,COUNTIF(Employees!$B$5:$B$44,"?*")),1)
Name EmployeePrefix: Settings!$D$92
Name EmployeeRoleList: Lists!$I$126:$I$145
Name EmployeeStatusList: Lists!$C$156:$C$171
Name EmployerOncost: Settings!$D$48
Name EmploymentTypeList: Lists!$A$156:$A$171
Name EquipmentNames: OFFSET(Equipment!$B$5,0,0,MAX(1,COUNTIF(Equipment!$B$5:$B$84,"?*")),1)
Name EquipmentPrefix: Settings!$D$94
Name EquipmentStatusList: Lists!$I$176:$I$191
Name EquipmentTypeList: Lists!$G$176:$G$196
Name ExpenseCategoryList: Lists!$E$199:$E$230
Name ExpenseMonths: OFFSET(Expenses!$C$5,0,0,MAX(1,COUNTIF(Expenses!$C$5:$C$404,"?*")),1)
Name ExpensePrefix: Settings!$D$95
Name ExpenseTypeList: Lists!$G$199:$G$211
Name FpAvgHours: 'Financial Plan'!$D$9
Name FpAvgJob: 'Financial Plan'!$D$8
Name FpBreakEvenHours: 'Financial Plan'!$D$14

Sheet Start Here
A1: Cleaning Business CRM & Pricing Calculator | H1: Novality Store | v1.0.0
A2: A complete back office for a cleaning business - clients, quotes, jobs, staff, invoices and profit.
A3: > Start Here | C3: > Dashboard | E3: > Clients | G3: > Jobs | I3: > Calendar
A5: Welcome. This workbook replaces the diary, the quote pad, the invoice book and the shoebox of receipts. Everything is a formula you can read and change - no macros, no add-ins, no subscription.
A7: What is in the file
B8: Tab | C8: What it does | D8: Your job
B9: Business Settings | C9: Your name, rates, tax, targets and every reminder window | H9: Fill in once, revisit twice a year
B10: Dashboard | C10: Twelve live numbers, the jobs for the week and everything that needs doing | H10: Read it every morning
B11: Pricing & Quote Calculator | C11: Prices a clean four different ways and shows the margin on each | H11: Use it before you quote
B12: Client CRM | C12: Every client, what they are worth and whether they are drifting away | H12: Add clients
B13: Property & Site Database | C13: Addresses, access, keys, pets, parking and the hours each property needs | H13: Add properties
B14: Leads & Sales Pipeline | C14: Enquiries from first call to won or lost | H14: Log every enquiry
B15: Service Catalog | C15: What you offer, what it costs you and what it earns an hour | H15: Set up once
B16: Quotes & Estimates | C16: Quotes, their lines, follow-ups and acceptance | H16: Raise quotes
B17: Job Scheduler | C17: Every visit: who, where, when, how long, how much | H17: The heart of the workbook
B18: Calendar | C18: The month at a glance and the next thirty visits in order | H18: Read only
B19: Cleaning Checklists | C19: Room-by-room task templates, and the tasks ticked off on the day | H19: Build your own
B20: Employee Database | C20: Your team, their pay, skills, checks and performance | H20: Add staff
... B32: Settings & Dropdown Lists | C32: Every drop-down list in the workbook | H32: Edit to suit you
A34: Twenty minutes to set it up
B35: Step | C35: Where | D35: What to do
B36: 1 | C36: Business Settings | E36: Your business name, address, phone and email. They print on every quote and invoice.
B37: 2 | C37: Business Settings | E37: Your hourly rate, minimum charge and what a cleaner costs you an hour. Nothing else works until these are right.
B38: 3 | C38: Business Settings | E38: Tax rate and payment terms. Set the tax rate to 0 if you are not registered.
B39: 4 | C39: Service Catalog | E39: Edit the services to match what you actually sell. Delete the ones you do not offer.
B40: 5 | C40: Cleaning Checklists | E40: Adjust the task templates. These become the job sheets your cleaners carry.
B41: 6 | C41: Employee Database | E41: Add your team - even if the team is just you. Put your own pay rate in; it is what makes the profit figures real.
B42: 7 | C42: Client CRM and Property & Site Database | E42: Add your clients, then their properties. The property is where the hours and the access details live.
B43: 8 | C43: Job Scheduler | E43: Put next week's visits in. The price, the finish time and the invoice link all work themselves out.
B44: 9 | C44: Dashboard | E44: Open it every morning. If a number looks wrong, the tab it came from is named right beside it.
A46: The rhythm that keeps it accurate
B47: When | C47: What | D47: How long
B48: Every morning | C48: Open the Dashboard. Confirm tomorrow's visits. Assign anything with no cleaner. | I48: 2 minutes
B49: After each job | C49: Mark it Completed and put the actual hours in. | I49: 30 seconds
B50: Every Friday | C50: Approve timesheets, raise the week's invoices, log receipts. | I50: 20 minutes
B51: Every Monday | C51: Chase unpaid invoices and unanswered quotes. This is the hour that pays for itself. | I51: 30 minutes
B52: Monthly | C52: Count supplies, check equipment servicing, read the Reports tab. | I52: 1 hour
B53: Quarterly | C53: Review prices against the Job Costing tab. Any client under your margin floor needs a conversation. | I53: 1 hour
A55: What the workbook does by itself
B56: Prices a clean from the floor area, the room count, the service or your target margin - and shows all four.
...

Sheet Settings
A1: Business Settings | G1: Novality Store | v1.0.0
A2: Fill in the white cells once. Shaded cells are locked formulas. Every price, every invoice and every alert in the workbook reads these values.
A3: > Start Here | C3: > Dashboard | E3: > Clients | G3: > Jobs
A5: 1. Your business
B6: Business name | D6: Bright & Tidy Cleaning Co. | F6: Shown on every quote, invoice and printable page.
B7: Owner / manager | D7: Dana Whitfield
B8: Email | D8: hello@brightandtidy.co
B9: Phone | D9: (503) 555 0142
B10: Address | D10: 18 Juniper Way, Portland, OR 97214
B11: Website | D11: brightandtidy.co
B12: Area you cover | D12: Portland metro - 20 mile radius | F12: Used on quotes and to sanity check how far a job is.
B13: Tagline | D13: Reliable domestic and commercial cleaning since 2019
B14: Business / tax number | D14: BT-CLEAN-2019-0146
B15: Insurance policy | D15: Hartfield Commercial - policy HCX-884213 | F15: Clients ask for this more often than you think - keep it here so it is easy to quote.
A17: 2. Your working week
B18: Year | D18: 2026 | E18: The year the calendar, the planner and the reports open on.
B19: Week starts on | D19: Monday | E19: Used by the calendar grid, the staff rota and the week numbers.
B20: Billable hours in a working day | D20: 6 | E20: Hours one cleaner can actually charge for after travel, setup and breaks. The capacity and utilisation figures use this.
B21: Cleaners on a standard job | D21: 2 | E21: Two cleaners for three hours is six paid hours - the costing tab works that out for you.
B22: Travel allowance between jobs (minutes) | D22: 20 | E22: Added to each job when the scheduler checks whether two bookings clash.
B23: Area measured in | D23: sq ft | E23: Square feet or square metres - the price per unit below should match.
B24: Distance measured in | D24: miles
B25: Today | D25: =TODAY() -> 0 | E25: Every 'due', 'overdue' and 'coming up' flag in the workbook counts from this cell, so they all move on by themselves overnight.
B26: This month starts | D26: =DATE(YEAR(TodayDate),MONTH(TodayDate),1) -> 0
B27: This month ends | D27: =DATE(YEAR(TodayDate),MONTH(TodayDate)+1,1)-1 -> 0
B28: This week starts | D28: =TodayDate-WEEKDAY(TodayDate,IF(WeekStart="Sunday",1,2))+1 -> 0
A30: 3. What you charge
B31: These are the numbers the quote calculator multiplies. Set them once from your own costs and local market - the figures shipped with the workbook are a realistic starting point, not advice on what to charge.
B32: Standard hourly rate | D32: 45 | E32: What one cleaner's hour costs the client.
B33: Minimum charge for any job | D33: 90 | E33: No quote leaves below this, however small the job. It covers getting there and back.
B34: Price per sq ft | D34: 0.09 | E34: Used by the area based pricing method - common for offices and end of tenancy work.
B35: Price per bedroom | D35: 25
B36: Price per bathroom | D36: 30 | E36: Bathrooms and kitchens take the longest - price them higher than a bedroom.
B37: Price per other room | D37: 18
B38: Call out / travel fee | D38: 15
B39: Deep clean uplift | D39: 0.45 | E39: A deep clean takes far longer than a weekly visit. 45% means a $200 clean quotes at $290.
B40: Move in / move out uplift | D40: 0.35
B41: Pet surcharge | D41: 20 | E41: Hair and paw prints are real extra minutes. Set it to 0 if you would rather absorb it.
B42: Deposit to take up front | D42: 0.25 | E42: Shown on quotes and contracts for larger jobs.
B43: Price rounding | D43: Nearest 5 | E43: Quotes look more professional rounded. 'Nearest 5' turns 187.40 into 185.
...

Sheet Dashboard
A1: Business Dashboard | J1: Novality Store | v1.0.0
A2: Today, this week and the year so far - all worked out from the jobs, invoices and expenses you have already entered.
A3: > Start Here | C3: > Dashboard | E3: > Clients | G3: > Jobs | I3: > Calendar | K3: > Quotes
A5: Business | B5: =BizName -> 0 | E5: Month | F5: =TEXT(TodayDate,"mmmm yyyy") -> 0 | G5: Month key | H5: =TEXT(TodayDate,"yyyy-mm") -> 0 | I5: Today | K5: =TodayDate -> 0
A7: Revenue this month | D7: Invoiced this month | G7: Collected this month | J7: Owed to you right now
A8: =SUMIFS(Jobs!$AJ$5:$AJ$604,Jobs!$E$5:$E$604,DashKey,Jobs!$P$5:$P$604,"Completed")+SUMIFS(Jobs!$AJ$5:$AJ$604,Jobs!$E$5:$E$604,DashKey,Jobs!$P$5:$P$604,"Invoiced") -> 0 | D8: =SUMIFS(Invoices!$V$5:$V$404,Invoices!$C$5:$C$404,DashKey) -> 0 | G8: =SUMIFS(Payments!$G$5:$G$404,Payments!$C$5:$C$404,DashKey) -> 0 | J8: =SUM(Invoices!$X$5:$X$404) -> 0
A9: target $6,000 | D9: what you have billed | G9: money actually in | J9: every unpaid invoice
A11: Costs this month | D11: Profit this month | G11: Margin this month | J11: Average job value
A12: =SUMIFS(Expenses!$Q$5:$Q$404,Expenses!$C$5:$C$404,DashKey) -> 0 | D12: =SUMIFS(Jobs!$AJ$5:$AJ$604,Jobs!$E$5:$E$604,DashKey,Jobs!$P$5:$P$604,"Completed")+SUMIFS(Jobs!$AJ$5:$AJ$604,Jobs!$E$5:$E$604,DashKey,Jobs!$P$5:$P$604,"Invoiced")-SUMIFS(Expenses!$Q$5:$Q$404,Expenses!$C$5:$C$404,DashKey) -> 0 | G12: =IFERROR((SUMIFS(Jobs!$AJ$5:$AJ$604,Jobs!$E$5:$E$604,DashKey,Jobs!$P$5:$P$604,"Completed")+SUMIFS(Jobs!$AJ$5:$AJ$604,Jobs!$E$5:$E$604,DashKey,Jobs!$P$5:$P$604,"Invoiced")-SUMIFS(Expenses!$Q$5:$Q$404,Expenses!$C$5:$C$404,DashKey))/(SUMIFS(Jobs!$AJ$5:$AJ$604,Jobs!$E$5:$E$604,DashKey,Jobs!$P$5:$P$604,"Completed")+SUMIFS(Jobs!$AJ$5:$AJ$604,Jobs!$E$5:$E$604,DashKey,Jobs!$P$5:$P$604,"Invoiced")),"") -> 0 | J12: =IFERROR((SUMIFS(Jobs!$AJ$5:$AJ$604,Jobs!$E$5:$E$604,DashKey,Jobs!$P$5:$P$604,"Completed")+SUMIFS(Jobs!$AJ$5:$AJ$604,Jobs!$E$5:$E$604,DashKey,Jobs!$P$5:$P$604,"Invoiced"))/(COUNTIFS(Jobs!$E$5:$E$604,DashKey,Jobs!$P$5:$P$604,"Completed")+COUNTIFS(Jobs!$E$5:$E$604,DashKey,Jobs!$P$5:$P$604,"Invoiced")),"") -> 0
A13: budget $4,000 | D13: revenue less expenses | G13: after wages and overheads | J13: completed work this month
A15: Jobs this week | D15: Hours booked this week | G15: Quotes waiting | J15: Active clients
A16: =COUNTIFS(Jobs!$B$5:$B$604,">="&WeekStartDate,Jobs!$B$5:$B$604,"<="&WeekStartDate+6,Jobs!$P$5:$P$604,"<>Cancelled") -> 0 | D16: =SUMIFS(Jobs!$AF$5:$AF$604,Jobs!$B$5:$B$604,">="&WeekStartDate,Jobs!$B$5:$B$604,"<="&WeekStartDate+6,Jobs!$P$5:$P$604,"<>Cancelled") -> 0 | G16: =COUNTIFS(Quotes!$K$5:$K$204,"Sent")+COUNTIFS(Quotes!$K$5:$K$204,"Followed up") -> 0 | J16: =COUNTIFS(Clients!$H$5:$H$204,"Active")+COUNTIFS(Clients!$H$5:$H$204,"Regular") -> 0
A17: booked in the next seven days | D17: across the whole team | G17: worth chasing today | J17: on the books right now
A19: Needs your attention
A20: What | B20: How many | C20: What it means | D20: Where to fix it
A21: Jobs with no cleaner | B21: =COUNTIFS(Jobs!$R$5:$R$604,"",Jobs!$G$5:$G$604,"<>",Jobs!$B$5:$B$604,">="&TodayDate) -> 0 | C21: ="Booked work nobody is assigned to yet" -> 0 | K21: Jobs
A22: Visits to confirm | B22: =COUNTIF(Jobs!$AX$5:$AX$604,"Confirm*") -> 0 | C22: ="Coming up within "&ReminderDays&" days and not confirmed with the client" -> 0 | K22: Jobs
A23: Double bookings | B23: =COUNTIF(Jobs!$AR$5:$AR$604,"Clash") -> 0 | C23: ="The same cleaner booked twice at the same time" -> 0 | K23: Jobs
A24: Jobs done but not invoiced | B24: =COUNTIFS(Jobs!$P$5:$P$604,"Completed",Jobs!$AP$5:$AP$604,"") -> 0 | C24: ="Work you have done and not yet billed - worth "&TEXT(SUMIFS(Jobs!$AJ$5:$AJ$604,Jobs!$P$5:$P$604,"Completed",Jobs!$AP$5:$AP$604,""),"#,##0") -> 0 | K24: Invoices
A25: Overdue invoices | B25: =COUNTIF(Invoices!$AE$5:$AE$404,"Overdue*") -> 0 | C25: ="Past their due date, totalling "&TEXT(SUMIFS(Invoices!$X$5:$X$404,Invoices!$AB$5:$AB$404,"1-30 days")+SUMIFS(Invoices!$X$5:$X$404,Invoices!$AB$5:$AB$404,"31-60 days")+SUMIFS(Invoices!$X$5:$X$404,Invoices!$AB$5:$AB$404,"61-90 days")+SUMIFS(Invoices!$X$5:$X$404,Invoices!$AB$5:$AB$404,"90+ days"),"#,##0") -> 0 | K25: Invoices
A26: Quotes to chase | B26: =COUNTIF(Quotes!$AK$5:$AK$204,"Chase*") -> 0 | C26: ="Sent more than "&QuoteFollowupDays&" days ago with no answer - this is the fastest money in the workbook" -> 0 | K26: Quotes
A27: Leads with no quote | B27: =COUNTIF(Leads!$Z$5:$Z$154,"Action - no quote*") -> 0 | C27: ="Enquiries that have not been priced yet" -> 0 | K27: Leads
A28: Clients going quiet | B28: =COUNTIF(Clients!$AP$5:$AP$204,"At risk")+COUNTIF(Clients!$AP$5:$AP$204,"Slipping") -> 0 | C28: ="No visit booked, or nothing for "&InactiveClientDays&" days" -> 0 | K28: Client Retention
A29: Supplies to reorder | B29: =COUNTIF(Supplies!$Y$5:$Y$154,"Low stock")+COUNTIF(Supplies!$Y$5:$Y$154,"Out of stock") -> 0 | C29: ="Below the reorder level or less than "&LowStockDays&" days of cover" -> 0 | K29: Supplies
A30: Equipment due a service | B30: =COUNTIF(Equipment!$Z$5:$Z$84,"Overdue*")+COUNTIF(Equipment!$Z$5:$Z$84,"Due*") -> 0 | C30: ="A machine that dies mid-job costs you the day" -> 0 | K30: Equipment
A31: Certificates expiring | B31: =COUNTIF(Safety!$P$5:$P$84,"Due soon")+COUNTIF(Safety!$P$5:$P$84,"Expired") -> 0 | C31: ="Insurance, checks and training within "&CertWarningDays&" days of running out" -> 0 | K31: Safety
A32: Open complaints | B32: =COUNTIF(Complaints!$W$5:$W$84,"Yes") -> 0 | C32: ="Every day one of these stays open costs you a client" -> 0 | K32: Complaints
A33: Loss-making jobs | B33: =COUNTIF('Job Costing'!$AA$5:$AA$604,"Loss*") -> 0 | C33: ="Jobs that cost more than they earned" -> 0 | K33: Job Costing
A34: Timesheets to approve | B34: =COUNTIF(Timesheets!$Z$5:$Z$804,"Due - needs approving") -> 0 | C34: ="Hours entered but not signed off" -> 0 | K34: Timesheets
A36: The next seven days
A37: Day | B37: =TodayDate+0 -> 0 | C37: =TodayDate+1 -> 0 | D37: =TodayDate+2 -> 0 | E37: =TodayDate+3 -> 0 | F37: =TodayDate+4 -> 0 | G37: =TodayDate+5 -> 0 | H37: =TodayDate+6 -> 0 | I37: Week
A38: Jobs booked | B38: =COUNTIFS(Jobs!$B$5:$B$604,B$37,Jobs!$P$5:$P$604,"<>Cancelled") -> 0 | C38: =COUNTIFS(Jobs!$B$5:$B$604,C$37,Jobs!$P$5:$P$604,"<>Cancelled") -> 0 | D38: =COUNTIFS(Jobs!$B$5:$B$604,D$37,Jobs!$P$5:$P$604,"<>Cancelled") -> 0 | E38: =COUNTIFS(Jobs!$B$5:$B$604,E$37,Jobs!$P$5:$P$604,"<>Cancelled") -> 0 | F38: =COUNTIFS(Jobs!$B$5:$B$604,F$37,Jobs!$P$5:$P$604,"<>Cancelled") -> 0 | G38: =COUNTIFS(Jobs!$B$5:$B$604,G$37,Jobs!$P$5:$P$604,"<>Cancelled") -> 0 | H38: =COUNTIFS(Jobs!$B$5:$B$604,H$37,Jobs!$P$5:$P$604,"<>Cancelled") -> 0 | I38: =COUNTIFS(Jobs!$B$5:$B$604,">="&TodayDate,Jobs!$B$5:$B$604,"<="&TodayDate+6,Jobs!$P$5:$P$604,"<>Cancelled") -> 0
A39: Hours on site | B39: =SUMIFS(Jobs!$AF$5:$AF$604,Jobs!$B$5:$B$604,B$37,Jobs!$P$5:$P$604,"<>Cancelled") -> 0 | C39: =SUMIFS(Jobs!$AF$5:$AF$604,Jobs!$B$5:$B$604,C$37,Jobs!$P$5:$P$604,"<>Cancelled") -> 0 | D39: =SUMIFS(Jobs!$AF$5:$AF$604,Jobs!$B$5:$B$604,D$37,Jobs!$P$5:$P$604,"<>Cancelled") -> 0 | E39: =SUMIFS(Jobs!$AF$5:$AF$604,Jobs!$B$5:$B$604,E$37,Jobs!$P$5:$P$604,"<>Cancelled") -> 0 | F39: =SUMIFS(Jobs!$AF$5:$AF$604,Jobs!$B$5:$B$604,F$37,Jobs!$P$5:$P$604,"<>Cancelled") -> 0 | G39: =SUMIFS(Jobs!$AF$5:$AF$604,Jobs!$B$5:$B$604,G$37,Jobs!$P$5:$P$604,"<>Cancelled") -> 0 | H39: =SUMIFS(Jobs!$AF$5:$AF$604,Jobs!$B$5:$B$604,H$37,Jobs!$P$5:$P$604,"<>Cancelled") -> 0 | I39: =SUMIFS(Jobs!$AF$5:$AF$604,Jobs!$B$5:$B$604,">="&TodayDate,Jobs!$B$5:$B$604,"<="&TodayDate+6,Jobs!$P$5:$P$604,"<>Cancelled") -> 0
A40: Value | B40: =SUMIFS(Jobs!$AJ$5:$AJ$604,Jobs!$B$5:$B$604,B$37,Jobs!$P$5:$P$604,"<>Cancelled") -> 0 | C40: =SUMIFS(Jobs!$AJ$5:$AJ$604,Jobs!$B$5:$B$604,C$37,Jobs!$P$5:$P$604,"<>Cancelled") -> 0 | D40: =SUMIFS(Jobs!$AJ$5:$AJ$604,Jobs!$B$5:$B$604,D$37,Jobs!$P$5:$P$604,"<>Cancelled") -> 0 | E40: =SUMIFS(Jobs!$AJ$5:$AJ$604,Jobs!$B$5:$B$604,E$37,Jobs!$P$5:$P$604,"<>Cancelled") -> 0 | F40: =SUMIFS(Jobs!$AJ$5:$AJ$604,Jobs!$B$5:$B$604,F$37,Jobs!$P$5:$P$604,"<>Cancelled") -> 0 | G40: =SUMIFS(Jobs!$AJ$5:$AJ$604,Jobs!$B$5:$B$604,G$37,Jobs!$P$5:$P$604,"<>Cancelled") -> 0 | H40: =SUMIFS(Jobs!$AJ$5:$AJ$604,Jobs!$B$5:$B$604,H$37,Jobs!$P$5:$P$604,"<>Cancelled") -> 0 | I40: =SUMIFS(Jobs!$AJ$5:$AJ$604,Jobs!$B$5:$B$604,">="&TodayDate,Jobs!$B$5:$B$604,"<="&TodayDate+6,Jobs!$P$5:$P$604,"<>Cancelled") -> 0
A41: Cleaners needed | B41: =SUMIFS(Jobs!$AE$5:$AE$604,Jobs!$B$5:$B$604,B$37,Jobs!$P$5:$P$604,"<>Cancelled") -> 0 | C41: =SUMIFS(Jobs!$AE$5:$AE$604,Jobs!$B$5:$B$604,C$37,Jobs!$P$5:$P$604,"<>Cancelled") -> 0 | D41: =SUMIFS(Jobs!$AE$5:$AE$604,Jobs!$B$5:$B$604,D$37,Jobs!$P$5:$P$604,"<>Cancelled") -> 0 | E41: =SUMIFS(Jobs!$AE$5:$AE$604,Jobs!$B$5:$B$604,E$37,Jobs!$P$5:$P$604,"<>Cancelled") -> 0 | F41: =SUMIFS(Jobs!$AE$5:$AE$604,Jobs!$B$5:$B$604,F$37,Jobs!$P$5:$P$604,"<>Cancelled") -> 0 | G41: =SUMIFS(Jobs!$AE$5:$AE$604,Jobs!$B$5:$B$604,G$37,Jobs!$P$5:$P$604,"<>Cancelled") -> 0 | H41: =SUMIFS(Jobs!$AE$5:$AE$604,Jobs!$B$5:$B$604,H$37,Jobs!$P$5:$P$604,"<>Cancelled") -> 0 | I41: =SUMIFS(Jobs!$AE$5:$AE$604,Jobs!$B$5:$B$604,">="&TodayDate,Jobs!$B$5:$B$604,"<="&TodayDate+6,Jobs!$P$5:$P$604,"<>Cancelled") -> 0
A43: Nothing in a column means a free day - the best day to fit in a quote visit, a deep clean or some time off.
A45: Your five biggest clients
A46: Client | B46: Type | C46: Jobs done | D46: Invoiced | E46: Profit | F46: Margin | G46: Worth a year | H46: Last clean | I46: Standing
A47: =IFERROR(INDEX(Clients!$B$5:$B$204,MATCH(1,Clients!$AM$5:$AM$204,0)),"") -> 0 | B47: =IFERROR(INDEX(Clients!$C$5:$C$204,MATCH(1,Clients!$AM$5:$AM$204,0)),"") -> 0 | C47: =IFERROR(INDEX(Clients!$Y$5:$Y$204,MATCH(1,Clients!$AM$5:$AM$204,0)),"") -> 0 | D47: =IFERROR(INDEX(Clients!$AD$5:$AD$204,MATCH(1,Clients!$AM$5:$AM$204,0)),"") -> 0 | E47: =IFERROR(INDEX(Clients!$AH$5:$AH$204,MATCH(1,Clients!$AM$5:$AM$204,0)),"") -> 0 | F47: =IFERROR(INDEX(Clients!$AI$5:$AI$204,MATCH(1,Clients!$AM$5:$AM$204,0)),"") -> 0 | G47: =IFERROR(INDEX(Clients!$AJ$5:$AJ$204,MATCH(1,Clients!$AM$5:$AM$204,0)),"") -> 0 | H47: =IFERROR(INDEX(Clients!$AA$5:$AA$204,MATCH(1,Clients!$AM$5:$AM$204,0)),"") -> 0 | I47: =IFERROR(INDEX(Clients!$AP$5:$AP$204,MATCH(1,Clients!$AM$5:$AM$204,0)),"") -> 0
A48: =IFERROR(INDEX(Clients!$B$5:$B$204,MATCH(2,Clients!$AM$5:$AM$204,0)),"") -> 0 | B48: =IFERROR(INDEX(Clients!$C$5:$C$204,MATCH(2,Clients!$AM$5:$AM$204,0)),"") -> 0 | C48: =IFERROR(INDEX(Clients!$Y$5:$Y$204,MATCH(2,Clients!$AM$5:$AM$204,0)),"") -> 0 | D48: =IFERROR(INDEX(Clients!$AD$5:$AD$204,MATCH(2,Clients!$AM$5:$AM$204,0)),"") -> 0 | E48: =IFERROR(INDEX(Clients!$AH$5:$AH$204,MATCH(2,Clients!$AM$5:$AM$204,0)),"") -> 0 | F48: =IFERROR(INDEX(Clients!$AI$5:$AI$204,MATCH(2,Clients!$AM$5:$AM$204,0)),"") -> 0 | G48: =IFERROR(INDEX(Clients!$AJ$5:$AJ$204,MATCH(2,Clients!$AM$5:$AM$204,0)),"") -> 0 | H48: =IFERROR(INDEX(Clients!$AA$5:$AA$204,MATCH(2,Clients!$AM$5:$AM$204,0)),"") -> 0 | I48: =IFERROR(INDEX(Clients!$AP$5:$AP$204,MATCH(2,Clients!$AM$5:$AM$204,0)),"") -> 0
...

Sheet Quote Calculator
A1: Pricing & Quote Calculator | J1: Novality Store | v1.0.0
A2: Fill in the white cells. The price, the cost, the margin and the yearly value all work themselves out.
A3: > Start Here | C3: > Dashboard | E3: > Clients | G3: > Jobs | I3: > Calendar | K3: > Quotes
A5: 1. What are we cleaning?
B6: You can start from a property you already have on file, or just type the numbers in. Nothing here changes any of your saved data.
B7: Service | D7: Regular home clean | F7: From the Services tab. Its hours, price and uplift are used below.
B8: Client type | D8: Residential
B9: Floor area (sq ft) | D9: 1450 | E9: Leave at 0 if you do not know it - the room count will carry the estimate.
B10: Bedrooms | D10: 3
B11: Bathrooms | D11: 2 | E11: Bathrooms and kitchens are where the time really goes.
B12: Other rooms | D12: 4
B13: Condition | D13: Normal | F13: Be honest. This multiplies the hours - the factors are on the Lists tab.
B14: How often | D14: Weekly | F14: Regular work takes less time per visit, so it is priced lower.
B15: Pets at the property? | D15: Yes
B16: Distance one way (miles) | D16: 6
B17: Add the call-out fee? | D17: No | E17: Adds the $15 call-out fee from Settings.
B18: Cleaners on the job | D18: 2
B19: Hours (override the estimate) | D19: 0 | E19: Leave at 0 to let the calculator estimate. Type a number if you have walked the job.
B20: Hourly rate (override) | D20: 0 | E20: 0 uses the standard rate from Settings.
B21: Discount | D21: 0 | E21: A first-clean discount is the cheapest way to win recurring work - but watch the margin below.
A23: 2. Extras
B24: Add-ons priced straight from the Services tab. Ovens, interior windows, inside the fridge - the jobs that turn an average clean into a good one.
B25: Extra | C25: Qty | D25: Each | E25: Total | F25: Hours it adds
B26: Oven clean | C26: 1 | D26: =IF(B26="","",IFERROR(INDEX(Services!$P$5:$P$64,MATCH(B26,Services!$B$5:$B$64,0)),0)) -> 0 | E26: =IF(B26="","",IF(C26="",0,C26)*D26) -> 0 | F26: =IF(B26="","",IFERROR(INDEX(Services!$G$5:$G$64,MATCH(B26,Services!$B$5:$B$64,0)),0)*IF(C26="",0,C26)) -> 0
D27: =IF(B27="","",IFERROR(INDEX(Services!$P$5:$P$64,MATCH(B27,Services!$B$5:$B$64,0)),0)) -> 0 | E27: =IF(B27="","",IF(C27="",0,C27)*D27) -> 0 | F27: =IF(B27="","",IFERROR(INDEX(Services!$G$5:$G$64,MATCH(B27,Services!$B$5:$B$64,0)),0)*IF(C27="",0,C27)) -> 0
D28: =IF(B28="","",IFERROR(INDEX(Services!$P$5:$P$64,MATCH(B28,Services!$B$5:$B$64,0)),0)) -> 0 | E28: =IF(B28="","",IF(C28="",0,C28)*D28) -> 0 | F28: =IF(B28="","",IFERROR(INDEX(Services!$G$5:$G$64,MATCH(B28,Services!$B$5:$B$64,0)),0)*IF(C28="",0,C28)) -> 0
D29: =IF(B29="","",IFERROR(INDEX(Services!$P$5:$P$64,MATCH(B29,Services!$B$5:$B$64,0)),0)) -> 0 | E29: =IF(B29="","",IF(C29="",0,C29)*D29) -> 0 | F29: =IF(B29="","",IFERROR(INDEX(Services!$G$5:$G$64,MATCH(B29,Services!$B$5:$B$64,0)),0)*IF(C29="",0,C29)) -> 0
B30: Extras total | E30: =SUM($E$26:$E$29) -> 0 | F30: =SUM($F$26:$F$29) -> 0
A32: 3. How long it should take
B33: Hours from the room count | D33: =QcBeds*0.45+QcBaths*0.6+QcRooms*0.3 -> 0 | E33: Bedrooms at 27 minutes, bathrooms at 36, everything else at 18. Change the weights here if your own figures differ.
B34: Hours from the floor area | D34: =IF(QcArea=0,0,QcArea/IF(AreaUnit="sq m",60,650)) -> 0 | E34: One cleaner covers about 650 sq ft (60 sq m) an hour on a standard clean.
B35: Hours the service allows | D35: =IFERROR(INDEX(Services!$G$5:$G$64,MATCH(QcService,Services!$B$5:$B$64,0)),0) -> 0
B36: Base hours used | D36: =IF(QcHoursOverride>0,QcHoursOverride,IF(AND(IFERROR(INDEX(Services!$D$5:$D$64,MATCH(QcService,Services!$B$5:$B$64,0)),"")<>"Per hour",QcServiceHours>0),QcServiceHours,MAX(QcRoomHours,QcAreaHours))) -> 0 | E36: Your override if you gave one, the service time for a fixed-price job, otherwise the larger of the room and area estimates.
B37: Condition factor | D37: =IFERROR(INDEX(ConditionFactors,MATCH(QcCondition,ConditionNames,0)),1) -> 0
B38: Hours for this job | D38: =ROUND(QcBaseHours*QcConditionFactor+QcExtraHours,2) -> 0 | E38: Total cleaner-hours, including the extras.
B39: Time on site | D39: =ROUND(QcHours/MAX(1,QcCleaners),2) -> 0 | E39: How long the visit lasts with your crew on it. This is what you tell the client.
A41: 4. Four ways to price it
B42: The same job, priced four different ways. They rarely agree - that is the point. Pick the method that suits the client and sanity-check it against the others.
B43: Rate used | D43: =IF(QcRateOverride>0,QcRateOverride,HourlyRate) -> 0
B44: Service uplift | D44: =IFERROR(INDEX(Services!$H$5:$H$64,MATCH(QcService,Services!$B$5:$B$64,0)),0) -> 0 | E44: Deep cleans and end of tenancy work carry an uplift - it is set on the Services tab.
...

Sheet Clients
A1: Client Database | AQ1: Novality Store | v1.0.0
A2: Every customer, what they have spent, what they earn you and when you last saw them.
A3: > Start Here | C3: > Dashboard | E3: > Clients | G3: > Jobs | I3: > Calendar | K3: > Quotes | M3: > Invoices | O3: > Staff | Q3: > Help | S3: Add the client here first, then their address on the Properties tab, then book the work on the Jobs tab. Everything downstream keys off the client ID in column A.
A4: ID | B4: Client | C4: Type | D4: Main contact | E4: Phone | F4: Email | G4: Billing address | H4: Status | I4: Came from | J4: Client since | K4: Usual frequency | L4: Preferred day | M4: Preferred time | N4: Preferred cleaner | O4: Agreed hourly rate | P4: Payment terms (days) | Q4: Pays by | R4: Contract | S4: Contract ends | T4: VIP? | U4: Happy to be contacted? | V4: Notes | W4: Properties | X4: Jobs booked | Y4: Jobs done | Z4: Cancelled | AA4: Last clean | AB4: Days since | AC4: Next booking | AD4: Invoiced to date | AE4: Paid to date | AF4: Owing now | AG4: Average job | AH4: Profit to date | AI4: Margin | AJ4: Value a year | AK4: Average rating | AL4: Complaints | AM4: Rank | AN4: Rank | AO4: Rank | AP4: Standing | AQ4: Risk score | AR4: Risk order | AS4: Action
A5: =IF(B5="","",ClientPrefix&TEXT(ROW()-4,"0000")) -> 0 | B5: Harper Residence | C5: Residential | D5: Megan Harper | E5: (503) 555 0188 | F5: megan.harper@example.com | G5: 42 Larch Street, Portland OR 97215 | H5: Regular | I5: Google search | J5: 45553 | K5: Weekly | L5: Tuesday | M5: Morning (9-12) | N5: Marta Kovacs | O5: 45 | P5: 7 | R5: Rolling monthly | T5: No | U5: Yes | V5: Two cats. Hates the smell of bleach - use the eco spray. | W5: =IF(A5="","",COUNTIFS(Properties!$C$5:$C$254,A5)) -> 0 | X5: =IF(A5="","",COUNTIFS(Jobs!$G$5:$G$604,A5)) -> 0 | Y5: =IF(A5="","",COUNTIFS(Jobs!$G$5:$G$604,A5,Jobs!$P$5:$P$604,"Completed")+COUNTIFS(Jobs!$G$5:$G$604,A5,Jobs!$P$5:$P$604,"Invoiced")) -> 0 | Z5: =IF(A5="","",COUNTIFS(Jobs!$G$5:$G$604,A5,Jobs!$P$5:$P$604,"Cancelled")+COUNTIFS(Jobs!$G$5:$G$604,A5,Jobs!$P$5:$P$604,"No access")) -> 0 | AA5: =IF(A5="","",IF(SUMPRODUCT(MAX((Jobs!$G$5:$G$604=A5)*((Jobs!$P$5:$P$604="Completed")+(Jobs!$P$5:$P$604="Invoiced"))*Jobs!$B$5:$B$604))=0,"",SUMPRODUCT(MAX((Jobs!$G$5:$G$604=A5)*((Jobs!$P$5:$P$604="Completed")+(Jobs!$P$5:$P$604="Invoiced"))*Jobs!$B$5:$B$604)))) -> 0 | AB5: =IF(AA5="","",TodayDate-AA5) -> 0 | AC5: =IF(A5="","",IF(SUMPRODUCT(MIN((Jobs!$G$5:$G$604=A5)*(Jobs!$B$5:$B$604>=TodayDate)*(Jobs!$P$5:$P$604<>"Cancelled")*Jobs!$B$5:$B$604+(1-(Jobs!$G$5:$G$604=A5)*(Jobs!$B$5:$B$604>=TodayDate)*(Jobs!$P$5:$P$604<>"Cancelled"))*2958465))=2958465,"",SUMPRODUCT(MIN((Jobs!$G$5:$G$604=A5)*(Jobs!$B$5:$B$604>=TodayDate)*(Jobs!$P$5:$P$604<>"Cancelled")*Jobs!$B$5:$B$604+(1-(Jobs!$G$5:$G$604=A5)*(Jobs!$B$5:$B$604>=TodayDate)*(Jobs!$P$5:$P$604<>"Cancelled"))*2958465)))) -> 0 | AD5: =IF(A5="","",SUMIFS(Invoices!$V$5:$V$404,Invoices!$D$5:$D$404,A5)) -> 0 | AE5: =IF(A5="","",SUMIFS(Invoices!$W$5:$W$404,Invoices!$D$5:$D$404,A5)) -> 0 | AF5: =IF(A5="","",AD5-AE5) -> 0 | AG5: =IF(OR(A5="",Y5=0),"",AD5/Y5) -> 0 | AH5: =IF(A5="","",SUMIFS('Job Costing'!$U$5:$U$604,'Job Costing'!$D$5:$D$604,A5)) -> 0 | AI5: =IF(OR(A5="",AD5=0),"",AH5/AD5) -> 0 | AJ5: =IF(OR(A5="",K5="",AG5=""),"",AG5*IFERROR(INDEX(FreqPerYear,MATCH(K5,FreqNames,0)),1)) -> 0 | AK5: =IF(A5="","",IFERROR(AVERAGEIFS(Jobs!$AA$5:$AA$604,Jobs!$G$5:$G$604,A5,Jobs!$AA$5:$AA$604,">0"),"")) -> 0 | AL5: =IF(A5="","",COUNTIFS(Complaints!$D$5:$D$84,A5)) -> 0 | AM5: =IF(B5="","",COUNTIFS($AD$5:$AD$204,">"&AD5)+COUNTIFS($AD$5:AD5,AD5)) -> 0 | AN5: =IF(B5="","",COUNTIFS($AH$5:$AH$204,">"&AH5)+COUNTIFS($AH$5:AH5,AH5)) -> 0 | AO5: =IF(B5="","",COUNTIFS($AJ$5:$AJ$204,">"&AJ5)+COUNTIFS($AJ$5:AJ5,AJ5)) -> 0 | AP5: =IF(B5="","",IF(H5="Lost","Lost",IF(H5="Inactive","Dormant",IF(AA5="","Dormant",IF(AB5>InactiveClientDays*2,"Dormant",IF(AB5>InactiveClientDays,"At risk",IF(AC5="","Slipping",IF(Y5>=10,"Loyal","Steady")))))))) -> 0 | AQ5: =IF(OR(B5="",AP5="Lost",AP5="Dormant"),"",IF(OR(AP5="At risk",AP5="Slipping"),IF(AB5="",999,AB5),"")) -> 0 | AR5: =IF(AQ5="","",COUNTIFS($AQ$5:$AQ$204,">"&AQ5)+COUNTIFS($AQ$5:AQ5,AQ5)) -> 0 | AS5: =IF(B5="","",IF(AF5>0.5,"Chase - "&TEXT(AF5,"0")&" owing",IF(AND(H5<>"Lost",H5<>"Inactive",H5<>"Paused",AC5="",K5<>"One-off"),"Book - nothing in the diary",IF(AND(S5<>"",S5-TodayDate<=RenewalWarningDays,S5>=TodayDate),"Due - contract renews soon",IF(AP5="At risk","Call - going quiet",IF(AL5>=2,"Check - complaints logged",IF(AND(AI5<>"",AI5<MarginFloor,Y5>0),"Check - thin margin","OK"))))))) -> 0
A6: =IF(B6="","",ClientPrefix&TEXT(ROW()-4,"0000")) -> 0 | B6: Okafor Family | C6: Residential | D6: Tobi Okafor | E6: (503) 555 0231 | F6: tobi.okafor@example.com | G6: 9 Elmwood Court, Portland OR 97212 | H6: Regular | I6: Referral - client | J6: 45773 | K6: Fortnightly | L6: Thursday | M6: Afternoon (2-5) | N6: Jade Ellis | O6: 45 | P6: 7 | R6: Rolling monthly | T6: No | U6: Yes | V6: Twins under three - toys everywhere, allow extra tidy time. | W6: =IF(A6="","",COUNTIFS(Properties!$C$5:$C$254,A6)) -> 0 | X6: =IF(A6="","",COUNTIFS(Jobs!$G$5:$G$604,A6)) -> 0 | Y6: =IF(A6="","",COUNTIFS(Jobs!$G$5:$G$604,A6,Jobs!$P$5:$P$604,"Completed")+COUNTIFS(Jobs!$G$5:$G$604,A6,Jobs!$P$5:$P$604,"Invoiced")) -> 0 | Z6: =IF(A6="","",COUNTIFS(Jobs!$G$5:$G$604,A6,Jobs!$P$5:$P$604,"Cancelled")+COUNTIFS(Jobs!$G$5:$G$604,A6,Jobs!$P$5:$P$604,"No access")) -> 0 | AA6: =IF(A6="","",IF(SUMPRODUCT(MAX((Jobs!$G$5:$G$604=A6)*((Jobs!$P$5:$P$604="Completed")+(Jobs!$P$5:$P$604="Invoiced"))*Jobs!$B$5:$B$604))=0,"",SUMPRODUCT(MAX((Jobs!$G$5:$G$604=A6)*((Jobs!$P$5:$P$604="Completed")+(Jobs!$P$5:$P$604="Invoiced"))*Jobs!$B$5:$B$604)))) -> 0 | AB6: =IF(AA6="","",TodayDate-AA6) -> 0 | AC6: =IF(A6="","",IF(SUMPRODUCT(MIN((Jobs!$G$5:$G$604=A6)*(Jobs!$B$5:$B$604>=TodayDate)*(Jobs!$P$5:$P$604<>"Cancelled")*Jobs!$B$5:$B$604+(1-(Jobs!$G$5:$G$604=A6)*(Jobs!$B$5:$B$604>=TodayDate)*(Jobs!$P$5:$P$604<>"Cancelled"))*2958465))=2958465,"",SUMPRODUCT(MIN((Jobs!$G$5:$G$604=A6)*(Jobs!$B$5:$B$604>=TodayDate)*(Jobs!$P$5:$P$604<>"Cancelled")*Jobs!$B$5:$B$604+(1-(Jobs!$G$5:$G$604=A6)*(Jobs!$B$5:$B$604>=TodayDate)*(Jobs!$P$5:$P$604<>"Cancelled"))*2958465)))) -> 0 | AD6: =IF(A6="","",SUMIFS(Invoices!$V$5:$V$404,Invoices!$D$5:$D$404,A6)) -> 0 | AE6: =IF(A6="","",SUMIFS(Invoices!$W$5:$W$404,Invoices!$D$5:$D$404,A6)) -> 0 | AF6: =IF(A6="","",AD6-AE6) -> 0 | AG6: =IF(OR(A6="",Y6=0),"",AD6/Y6) -> 0 | AH6: =IF(A6="","",SUMIFS('Job Costing'!$U$5:$U$604,'Job Costing'!$D$5:$D$604,A6)) -> 0 | AI6: =IF(OR(A6="",AD6=0),"",AH6/AD6) -> 0 | AJ6: =IF(OR(A6="",K6="",AG6=""),"",AG6*IFERROR(INDEX(FreqPerYear,MATCH(K6,FreqNames,0)),1)) -> 0 | AK6: =IF(A6="","",IFERROR(AVERAGEIFS(Jobs!$AA$5:$AA$604,Jobs!$G$5:$G$604,A6,Jobs!$AA$5:$AA$604,">0"),"")) -> 0 | AL6: =IF(A6="","",COUNTIFS(Complaints!$D$5:$D$84,A6)) -> 0 | AM6: =IF(B6="","",COUNTIFS($AD$5:$AD$204,">"&AD6)+COUNTIFS($AD$5:AD6,AD6)) -> 0 | AN6: =IF(B6="","",COUNTIFS($AH$5:$AH$204,">"&AH6)+COUNTIFS($AH$5:AH6,AH6)) -> 0 | AO6: =IF(B6="","",COUNTIFS($AJ$5:$AJ$204,">"&AJ6)+COUNTIFS($AJ$5:AJ6,AJ6)) -> 0 | AP6: =IF(B6="","",IF(H6="Lost","Lost",IF(H6="Inactive","Dormant",IF(AA6="","Dormant",IF(AB6>InactiveClientDays*2,"Dormant",IF(AB6>InactiveClientDays,"At risk",IF(AC6="","Slipping",IF(Y6>=10,"Loyal","Steady")))))))) -> 0 | AQ6: =IF(OR(B6="",AP6="Lost",AP6="Dormant"),"",IF(OR(AP6="At risk",AP6="Slipping"),IF(AB6="",999,AB6),"")) -> 0 | AR6: =IF(AQ6="","",COUNTIFS($AQ$5:$AQ$204,">"&AQ6)+COUNTIFS($AQ$5:AQ6,AQ6)) -> 0 | AS6: =IF(B6="","",IF(AF6>0.5,"Chase - "&TEXT(AF6,"0")&" owing",IF(AND(H6<>"Lost",H6<>"Inactive",H6<>"Paused",AC6="",K6<>"One-off"),"Book - nothing in the diary",IF(AND(S6<>"",S6-TodayDate<=RenewalWarningDays,S6>=TodayDate),"Due - contract renews soon",IF(AP6="At risk","Call - going quiet",IF(AL6>=2,"Check - complaints logged",IF(AND(AI6<>"",AI6<MarginFloor,Y6>0),"Check - thin margin","OK"))))))) -> 0
A7: =IF(B7="","",ClientPrefix&TEXT(ROW()-4,"0000")) -> 0 | B7: Riverbend Dental | C7: Medical & dental | D7: Dr. Alan Reyes | E7: (503) 555 0410 | F7: practice@riverbenddental.example | G7: 118 Riverbend Plaza, Suite 3, Portland OR 97209 | H7: Active | I7: Directory listing | J7: 45883 | K7: Weekly | L7: Friday | M7: Late (5-8) | N7: Tomas Ruiz | O7: 52 | P7: 14 | R7: 12 months | T7: Yes | U7: Yes | V7: Clinical waste stays with the practice. Sign in at reception. | W7: =IF(A7="","",COUNTIFS(Properties!$C$5:$C$254,A7)) -> 0 | X7: =IF(A7="","",COUNTIFS(Jobs!$G$5:$G$604,A7)) -> 0 | Y7: =IF(A7="","",COUNTIFS(Jobs!$G$5:$G$604,A7,Jobs!$P$5:$P$604,"Completed")+COUNTIFS(Jobs!$G$5:$G$604,A7,Jobs!$P$5:$P$604,"Invoiced")) -> 0 | Z7: =IF(A7="","",COUNTIFS(Jobs!$G$5:$G$604,A7,Jobs!$P$5:$P$604,"Cancelled")+COUNTIFS(Jobs!$G$5:$G$604,A7,Jobs!$P$5:$P$604,"No access")) -> 0 | AA7: =IF(A7="","",IF(SUMPRODUCT(MAX((Jobs!$G$5:$G$604=A7)*((Jobs!$P$5:$P$604="Completed")+(Jobs!$P$5:$P$604="Invoiced"))*Jobs!$B$5:$B$604))=0,"",SUMPRODUCT(MAX((Jobs!$G$5:$G$604=A7)*((Jobs!$P$5:$P$604="Completed")+(Jobs!$P$5:$P$604="Invoiced"))*Jobs!$B$5:$B$604)))) -> 0 | AB7: =IF(AA7="","",TodayDate-AA7) -> 0 | AC7: =IF(A7="","",IF(SUMPRODUCT(MIN((Jobs!$G$5:$G$604=A7)*(Jobs!$B$5:$B$604>=TodayDate)*(Jobs!$P$5:$P$604<>"Cancelled")*Jobs!$B$5:$B$604+(1-(Jobs!$G$5:$G$604=A7)*(Jobs!$B$5:$B$604>=TodayDate)*(Jobs!$P$5:$P$604<>"Cancelled"))*2958465))=2958465,"",SUMPRODUCT(MIN((Jobs!$G$5:$G$604=A7)*(Jobs!$B$5:$B$604>=TodayDate)*(Jobs!$P$5:$P$604<>"Cancelled")*Jobs!$B$5:$B$604+(1-(Jobs!$G$5:$G$604=A7)*(Jobs!$B$5:$B$604>=TodayDate)*(Jobs!$P$5:$P$604<>"Cancelled"))*2958465)))) -> 0 | AD7: =IF(A7="","",SUMIFS(Invoices!$V$5:$V$404,Invoices!$D$5:$D$404,A7)) -> 0 | AE7: =IF(A7="","",SUMIFS(Invoices!$W$5:$W$404,Invoices!$D$5:$D$404,A7)) -> 0 | AF7: =IF(A7="","",AD7-AE7) -> 0 | AG7: =IF(OR(A7="",Y7=0),"",AD7/Y7) -> 0 | AH7: =IF(A7="","",SUMIFS('Job Costing'!$U$5:$U$604,'Job Costing'!$D$5:$D$604,A7)) -> 0 | AI7: =IF(OR(A7="",AD7=0),"",AH7/AD7) -> 0 | AJ7: =IF(OR(A7="",K7="",AG7=""),"",AG7*IFERROR(INDEX(FreqPerYear,MATCH(K7,FreqNames,0)),1)) -> 0 | AK7: =IF(A7="","",IFERROR(AVERAGEIFS(Jobs!$AA$5:$AA$604,Jobs!$G$5:$G$604,A7,Jobs!$AA$5:$AA$604,">0"),"")) -> 0 | AL7: =IF(A7="","",COUNTIFS(Complaints!$D$5:$D$84,A7)) -> 0 | AM7: =IF(B7="","",COUNTIFS($AD$5:$AD$204,">"&AD7)+COUNTIFS($AD$5:AD7,AD7)) -> 0 | AN7: =IF(B7="","",COUNTIFS($AH$5:$AH$204,">"&AH7)+COUNTIFS($AH$5:AH7,AH7)) -> 0 | AO7: =IF(B7="","",COUNTIFS($AJ$5:$AJ$204,">"&AJ7)+COUNTIFS($AJ$5:AJ7,AJ7)) -> 0 | AP7: =IF(B7="","",IF(H7="Lost","Lost",IF(H7="Inactive","Dormant",IF(AA7="","Dormant",IF(AB7>InactiveClientDays*2,"Dormant",IF(AB7>InactiveClientDays,"At risk",IF(AC7="","Slipping",IF(Y7>=10,"Loyal","Steady")))))))) -> 0 | AQ7: =IF(OR(B7="",AP7="Lost",AP7="Dormant"),"",IF(OR(AP7="At risk",AP7="Slipping"),IF(AB7="",999,AB7),"")) -> 0 | AR7: =IF(AQ7="","",COUNTIFS($AQ$5:$AQ$204,">"&AQ7)+COUNTIFS($AQ$5:AQ7,AQ7)) -> 0 | AS7: =IF(B7="","",IF(AF7>0.5,"Chase - "&TEXT(AF7,"0")&" owing",IF(AND(H7<>"Lost",H7<>"Inactive",H7<>"Paused",AC7="",K7<>"One-off"),"Book - nothing in the diary",IF(AND(S7<>"",S7-TodayDate<=RenewalWarningDays,S7>=TodayDate),"Due - contract renews soon",IF(AP7="At risk","Call - going quiet",IF(AL7>=2,"Check - complaints logged",IF(AND(AI7<>"",AI7<MarginFloor,Y7>0),"Check - thin margin","OK"))))))) -> 0
A8: =IF(B8="","",ClientPrefix&TEXT(ROW()-4,"0000")) -> 0 | B8: Cedar & Co Accountants | C8: Commercial office | D8: Priya Shah | E8: (503) 555 0366 | F8: priya@cedarandco.example | G8: 77 Cedar Avenue, Floor 2, Portland OR 97204 | H8: Regular | I8: Referral - client | J8: 45693 | K8: Twice a week | L8: Monday | M8: Late (5-8) | N8: Tomas Ruiz | O8: 50 | P8: 14 | R8: 12 months | T8: Yes | U8: Yes | V8: Out of hours only. Alarm code is on the Properties tab. | W8: =IF(A8="","",COUNTIFS(Properties!$C$5:$C$254,A8)) -> 0 | X8: =IF(A8="","",COUNTIFS(Jobs!$G$5:$G$604,A8)) -> 0 | Y8: =IF(A8="","",COUNTIFS(Jobs!$G$5:$G$604,A8,Jobs!$P$5:$P$604,"Completed")+COUNTIFS(Jobs!$G$5:$G$604,A8,Jobs!$P$5:$P$604,"Invoiced")) -> 0 | Z8: =IF(A8="","",COUNTIFS(Jobs!$G$5:$G$604,A8,Jobs!$P$5:$P$604,"Cancelled")+COUNTIFS(Jobs!$G$5:$G$604,A8,Jobs!$P$5:$P$604,"No access")) -> 0 | AA8: =IF(A8="","",IF(SUMPRODUCT(MAX((Jobs!$G$5:$G$604=A8)*((Jobs!$P$5:$P$604="Completed")+(Jobs!$P$5:$P$604="Invoiced"))*Jobs!$B$5:$B$604))=0,"",SUMPRODUCT(MAX((Jobs!$G$5:$G$604=A8)*((Jobs!$P$5:$P$604="Completed")+(Jobs!$P$5:$P$604="Invoiced"))*Jobs!$B$5:$B$604)))) -> 0 | AB8: =IF(AA8="","",TodayDate-AA8) -> 0 | AC8: =IF(A8="","",IF(SUMPRODUCT(MIN((Jobs!$G$5:$G$604=A8)*(Jobs!$B$5:$B$604>=TodayDate)*(Jobs!$P$5:$P$604<>"Cancelled")*Jobs!$B$5:$B$604+(1-(Jobs!$G$5:$G$604=A8)*(Jobs!$B$5:$B$604>=TodayDate)*(Jobs!$P$5:$P$604<>"Cancelled"))*2958465))=2958465,"",SUMPRODUCT(MIN((Jobs!$G$5:$G$604=A8)*(Jobs!$B$5:$B$604>=TodayDate)*(Jobs!$P$5:$P$604<>"Cancelled")*Jobs!$B$5:$B$604+(1-(Jobs!$G$5:$G$604=A8)*(Jobs!$B$5:$B$604>=TodayDate)*(Jobs!$P$5:$P$604<>"Cancelled"))*2958465)))) -> 0 | AD8: =IF(A8="","",SUMIFS(Invoices!$V$5:$V$404,Invoices!$D$5:$D$404,A8)) -> 0 | AE8: =IF(A8="","",SUMIFS(Invoices!$W$5:$W$404,Invoices!$D$5:$D$404,A8)) -> 0 | AF8: =IF(A8="","",AD8-AE8) -> 0 | AG8: =IF(OR(A8="",Y8=0),"",AD8/Y8) -> 0 | AH8: =IF(A8="","",SUMIFS('Job Costing'!$U$5:$U$604,'Job Costing'!$D$5:$D$604,A8)) -> 0 | AI8: =IF(OR(A8="",AD8=0),"",AH8/AD8) -> 0 | AJ8: =IF(OR(A8="",K8="",AG8=""),"",AG8*IFERROR(INDEX(FreqPerYear,MATCH(K8,FreqNames,0)),1)) -> 0 | AK8: =IF(A8="","",IFERROR(AVERAGEIFS(Jobs!$AA$5:$AA$604,Jobs!$G$5:$G$604,A8,Jobs!$AA$5:$AA$604,">0"),"")) -> 0 | AL8: =IF(A8="","",COUNTIFS(Complaints!$D$5:$D$84,A8)) -> 0 | AM8: =IF(B8="","",COUNTIFS($AD$5:$AD$204,">"&AD8)+COUNTIFS($AD$5:AD8,AD8)) -> 0 | AN8: =IF(B8="","",COUNTIFS($AH$5:$AH$204,">"&AH8)+COUNTIFS($AH$5:AH8,AH8)) -> 0 | AO8: =IF(B8="","",COUNTIFS($AJ$5:$AJ$204,">"&AJ8)+COUNTIFS($AJ$5:AJ8,AJ8)) -> 0 | AP8: =IF(B8="","",IF(H8="Lost","Lost",IF(H8="Inactive","Dormant",IF(AA8="","Dormant",IF(AB8>InactiveClientDays*2,"Dormant",IF(AB8>InactiveClientDays,"At risk",IF(AC8="","Slipping",IF(Y8>=10,"Loyal","Steady")))))))) -> 0 | AQ8: =IF(OR(B8="",AP8="Lost",AP8="Dormant"),"",IF(OR(AP8="At risk",AP8="Slipping"),IF(AB8="",999,AB8),"")) -> 0 | AR8: =IF(AQ8="","",COUNTIFS($AQ$5:$AQ$204,">"&AQ8)+COUNTIFS($AQ$5:AQ8,AQ8)) -> 0 | AS8: =IF(B8="","",IF(AF8>0.5,"Chase - "&TEXT(AF8,"0")&" owing",IF(AND(H8<>"Lost",H8<>"Inactive",H8<>"Paused",AC8="",K8<>"One-off"),"Book - nothing in the diary",IF(AND(S8<>"",S8-TodayDate<=RenewalWarningDays,S8>=TodayDate),"Due - contract renews soon",IF(AP8="At risk","Call - going quiet",IF(AL8>=2,"Check - complaints logged",IF(AND(AI8<>"",AI8<MarginFloor,Y8>0),"Check - thin margin","OK"))))))) -> 0
A9: =IF(B9="","",ClientPrefix&TEXT(ROW()-4,"0000")) -> 0 | B9: Lakeview Lettings | C9: Letting agent | D9: Sam Whitlock | E9: (503) 555 0177 | F9: sam@lakeviewlettings.example | G9: 3 Lakeview Road, Portland OR 97202 | H9: Active | I9: Letting agent | J9: 46283 | K9: One-off | L9: Flexible | M9: Flexible | N9: Priya Raman | O9: 48 | P9: 21 | R9: No contract | T9: No | U9: Yes | V9: End of tenancy work. Always wants photos and a receipt. | W9: =IF(A9="","",COUNTIFS(Properties!$C$5:$C$254,A9)) -> 0 | X9: =IF(A9="","",COUNTIFS(Jobs!$G$5:$G$604,A9)) -> 0 | Y9: =IF(A9="","",COUNTIFS(Jobs!$G$5:$G$604,A9,Jobs!$P$5:$P$604,"Completed")+COUNTIFS(Jobs!$G$5:$G$604,A9,Jobs!$P$5:$P$604,"Invoiced")) -> 0 | Z9: =IF(A9="","",COUNTIFS(Jobs!$G$5:$G$604,A9,Jobs!$P$5:$P$604,"Cancelled")+COUNTIFS(Jobs!$G$5:$G$604,A9,Jobs!$P$5:$P$604,"No access")) -> 0 | AA9: =IF(A9="","",IF(SUMPRODUCT(MAX((Jobs!$G$5:$G$604=A9)*((Jobs!$P$5:$P$604="Completed")+(Jobs!$P$5:$P$604="Invoiced"))*Jobs!$B$5:$B$604))=0,"",SUMPRODUCT(MAX((Jobs!$G$5:$G$604=A9)*((Jobs!$P$5:$P$604="Completed")+(Jobs!$P$5:$P$604="Invoiced"))*Jobs!$B$5:$B$604)))) -> 0 | AB9: =IF(AA9="","",TodayDate-AA9) -> 0 | AC9: =IF(A9="","",IF(SUMPRODUCT(MIN((Jobs!$G$5:$G$604=A9)*(Jobs!$B$5:$B$604>=TodayDate)*(Jobs!$P$5:$P$604<>"Cancelled")*Jobs!$B$5:$B$604+(1-(Jobs!$G$5:$G$604=A9)*(Jobs!$B$5:$B$604>=TodayDate)*(Jobs!$P$5:$P$604<>"Cancelled"))*2958465))=2958465,"",SUMPRODUCT(MIN((Jobs!$G$5:$G$604=A9)*(Jobs!$B$5:$B$604>=TodayDate)*(Jobs!$P$5:$P$604<>"Cancelled")*Jobs!$B$5:$B$604+(1-(Jobs!$G$5:$G$604=A9)*(Jobs!$B$5:$B$604>=TodayDate)*(Jobs!$P$5:$P$604<>"Cancelled"))*2958465)))) -> 0 | AD9: =IF(A9="","",SUMIFS(Invoices!$V$5:$V$404,Invoices!$D$5:$D$404,A9)) -> 0 | AE9: =IF(A9="","",SUMIFS(Invoices!$W$5:$W$404,Invoices!$D$5:$D$404,A9)) -> 0 | AF9: =IF(A9="","",AD9-AE9) -> 0 | AG9: =IF(OR(A9="",Y9=0),"",AD9/Y9) -> 0 | AH9: =IF(A9="","",SUMIFS('Job Costing'!$U$5:$U$604,'Job Costing'!$D$5:$D$604,A9)) -> 0 | AI9: =IF(OR(A9="",AD9=0),"",AH9/AD9) -> 0 | AJ9: =IF(OR(A9="",K9="",AG9=""),"",AG9*IFERROR(INDEX(FreqPerYear,MATCH(K9,FreqNames,0)),1)) -> 0 | AK9: =IF(A9="","",IFERROR(AVERAGEIFS(Jobs!$AA$5:$AA$604,Jobs!$G$5:$G$604,A9,Jobs!$AA$5:$AA$604,">0"),"")) -> 0 | AL9: =IF(A9="","",COUNTIFS(Complaints!$D$5:$D$84,A9)) -> 0 | AM9: =IF(B9="","",COUNTIFS($AD$5:$AD$204,">"&AD9)+COUNTIFS($AD$5:AD9,AD9)) -> 0 | AN9: =IF(B9="","",COUNTIFS($AH$5:$AH$204,">"&AH9)+COUNTIFS($AH$5:AH9,AH9)) -> 0 | AO9: =IF(B9="","",COUNTIFS($AJ$5:$AJ$204,">"&AJ9)+COUNTIFS($AJ$5:AJ9,AJ9)) -> 0 | AP9: =IF(B9="","",IF(H9="Lost","Lost",IF(H9="Inactive","Dormant",IF(AA9="","Dormant",IF(AB9>InactiveClientDays*2,"Dormant",IF(AB9>InactiveClientDays,"At risk",IF(AC9="","Slipping",IF(Y9>=10,"Loyal","Steady")))))))) -> 0 | AQ9: =IF(OR(B9="",AP9="Lost",AP9="Dormant"),"",IF(OR(AP9="At risk",AP9="Slipping"),IF(AB9="",999,AB9),"")) -> 0 | AR9: =IF(AQ9="","",COUNTIFS($AQ$5:$AQ$204,">"&AQ9)+COUNTIFS($AQ$5:AQ9,AQ9)) -> 0 | AS9: =IF(B9="","",IF(AF9>0.5,"Chase - "&TEXT(AF9,"0")&" owing",IF(AND(H9<>"Lost",H9<>"Inactive",H9<>"Paused",AC9="",K9<>"One-off"),"Book - nothing in the diary",IF(AND(S9<>"",S9-TodayDate<=RenewalWarningDays,S9>=TodayDate),"Due - contract renews soon",IF(AP9="At risk","Call - going quiet",IF(AL9>=2,"Check - complaints logged",IF(AND(AI9<>"",AI9<MarginFloor,Y9>0),"Check - thin margin","OK"))))))) -> 0
A10: =IF(B10="","",ClientPrefix&TEXT(ROW()-4,"0000")) -> 0 | B10: The Maple Cafe | C10: Restaurant & cafe | D10: Gio Bellini | E10: (503) 555 0145 | F10: gio@maplecafe.example | G10: 210 Maple Street, Portland OR 97214 | H10: Active | I10: Word of mouth | J10: 46013 | K10: Weekly | L10: Sunday | M10: Early (7-9) | N10: Amara Diallo | O10: 55 | P10: 7 | R10: 6 months | T10: No | U10: Yes | V10: Before opening. Kitchen deep clean quarterly, billed separately. | W10: =IF(A10="","",COUNTIFS(Properties!$C$5:$C$254,A10)) -> 0 | X10: =IF(A10="","",COUNTIFS(Jobs!$G$5:$G$604,A10)) -> 0 | Y10: =IF(A10="","",COUNTIFS(Jobs!$G$5:$G$604,A10,Jobs!$P$5:$P$604,"Completed")+COUNTIFS(Jobs!$G$5:$G$604,A10,Jobs!$P$5:$P$604,"Invoiced")) -> 0 | Z10: =IF(A10="","",COUNTIFS(Jobs!$G$5:$G$604,A10,Jobs!$P$5:$P$604,"Cancelled")+COUNTIFS(Jobs!$G$5:$G$604,A10,Jobs!$P$5:$P$604,"No access")) -> 0 | AA10: =IF(A10="","",IF(SUMPRODUCT(MAX((Jobs!$G$5:$G$604=A10)*((Jobs!$P$5:$P$604="Completed")+(Jobs!$P$5:$P$604="Invoiced"))*Jobs!$B$5:$B$604))=0,"",SUMPRODUCT(MAX((Jobs!$G$5:$G$604=A10)*((Jobs!$P$5:$P$604="Completed")+(Jobs!$P$5:$P$604="Invoiced"))*Jobs!$B$5:$B$604)))) -> 0 | AB10: =IF(AA10="","",TodayDate-AA10) -> 0 | AC10: =IF(A10="","",IF(SUMPRODUCT(MIN((Jobs!$G$5:$G$604=A10)*(Jobs!$B$5:$B$604>=TodayDate)*(Jobs!$P$5:$P$604<>"Cancelled")*Jobs!$B$5:$B$604+(1-(Jobs!$G$5:$G$604=A10)*(Jobs!$B$5:$B$604>=TodayDate)*(Jobs!$P$5:$P$604<>"Cancelled"))*2958465))=2958465,"",SUMPRODUCT(MIN((Jobs!$G$5:$G$604=A10)*(Jobs!$B$5:$B$604>=TodayDate)*(Jobs!$P$5:$P$604<>"Cancelled")*Jobs!$B$5:$B$604+(1-(Jobs!$G$5:$G$604=A10)*(Jobs!$B$5:$B$604>=TodayDate)*(Jobs!$P$5:$P$604<>"Cancelled"))*2958465)))) -> 0 | AD10: =IF(A10="","",SUMIFS(Invoices!$V$5:$V$404,Invoices!$D$5:$D$404,A10)) -> 0 | AE10: =IF(A10="","",SUMIFS(Invoices!$W$5:$W$404,Invoices!$D$5:$D$404,A10)) -> 0 | AF10: =IF(A10="","",AD10-AE10) -> 0 | AG10: =IF(OR(A10="",Y10=0),"",AD10/Y10) -> 0 | AH10: =IF(A10="","",SUMIFS('Job Costing'!$U$5:$U$604,'Job Costing'!$D$5:$D$604,A10)) -> 0 | AI10: =IF(OR(A10="",AD10=0),"",AH10/AD10) -> 0 | AJ10: =IF(OR(A10="",K10="",AG10=""),"",AG10*IFERROR(INDEX(FreqPerYear,MATCH(K10,FreqNames,0)),1)) -> 0 | AK10: =IF(A10="","",IFERROR(AVERAGEIFS(Jobs!$AA$5:$AA$604,Jobs!$G$5:$G$604,A10,Jobs!$AA$5:$AA$604,">0"),"")) -> 0 | AL10: =IF(A10="","",COUNTIFS(Complaints!$D$5:$D$84,A10)) -> 0 | AM10: =IF(B10="","",COUNTIFS($AD$5:$AD$204,">"&AD10)+COUNTIFS($AD$5:AD10,AD10)) -> 0 | AN10: =IF(B10="","",COUNTIFS($AH$5:$AH$204,">"&AH10)+COUNTIFS($AH$5:AH10,AH10)) -> 0 | AO10: =IF(B10="","",COUNTIFS($AJ$5:$AJ$204,">"&AJ10)+COUNTIFS($AJ$5:AJ10,AJ10)) -> 0 | AP10: =IF(B10="","",IF(H10="Lost","Lost",IF(H10="Inactive","Dormant",IF(AA10="","Dormant",IF(AB10>InactiveClientDays*2,"Dormant",IF(AB10>InactiveClientDays,"At risk",IF(AC10="","Slipping",IF(Y10>=10,"Loyal","Steady")))))))) -> 0 | AQ10: =IF(OR(B10="",AP10="Lost",AP10="Dormant"),"",IF(OR(AP10="At risk",AP10="Slipping"),IF(AB10="",999,AB10),"")) -> 0 | AR10: =IF(AQ10="","",COUNTIFS($AQ$5:$AQ$204,">"&AQ10)+COUNTIFS($AQ$5:AQ10,AQ10)) -> 0 | AS10: =IF(B10="","",IF(AF10>0.5,"Chase - "&TEXT(AF10,"0")&" owing",IF(AND(H10<>"Lost",H10<>"Inactive",H10<>"Paused",AC10="",K10<>"One-off"),"Book - nothing in the diary",IF(AND(S10<>"",S10-TodayDate<=RenewalWarningDays,S10>=TodayDate),"Due - contract renews soon",IF(AP10="At risk","Call - going quiet",IF(AL10>=2,"Check - complaints logged",IF(AND(AI10<>"",AI10<MarginFloor,Y10>0),"Check - thin margin","OK"))))))) -> 0
A11: =IF(B11="","",ClientPrefix&TEXT(ROW()-4,"0000")) -> 0 | B11: Bright Start Nursery | C11: School & nursery | D11: Carla Jensen | E11: (503) 555 0122 | F11: carla@brightstart.example | G11: 15 Juniper Lane, Portland OR 97213 | H11: Regular | I11: Google search | J11: 45903 | K11: Weekly | L11: Friday | M11: Late (5-8) | N11: Amara Diallo | O11: 50 | P11: 14 | R11: 12 months | T11: Yes | U11: Yes | V11: Background checks required for everyone on site. No harsh chemicals in the baby room. | W11: =IF(A11="","",COUNTIFS(Properties!$C$5:$C$254,A11)) -> 0 | X11: =IF(A11="","",COUNTIFS(Jobs!$G$5:$G$604,A11)) -> 0 | Y11: =IF(A11="","",COUNTIFS(Jobs!$G$5:$G$604,A11,Jobs!$P$5:$P$604,"Completed")+COUNTIFS(Jobs!$G$5:$G$604,A11,Jobs!$P$5:$P$604,"Invoiced")) -> 0 | Z11: =IF(A11="","",COUNTIFS(Jobs!$G$5:$G$604,A11,Jobs!$P$5:$P$604,"Cancelled")+COUNTIFS(Jobs!$G$5:$G$604,A11,Jobs!$P$5:$P$604,"No access")) -> 0 | AA11: =IF(A11="","",IF(SUMPRODUCT(MAX((Jobs!$G$5:$G$604=A11)*((Jobs!$P$5:$P$604="Completed")+(Jobs!$P$5:$P$604="Invoiced"))*Jobs!$B$5:$B$604))=0,"",SUMPRODUCT(MAX((Jobs!$G$5:$G$604=A11)*((Jobs!$P$5:$P$604="Completed")+(Jobs!$P$5:$P$604="Invoiced"))*Jobs!$B$5:$B$604)))) -> 0 | AB11: =IF(AA11="","",TodayDate-AA11) -> 0 | AC11: =IF(A11="","",IF(SUMPRODUCT(MIN((Jobs!$G$5:$G$604=A11)*(Jobs!$B$5:$B$604>=TodayDate)*(Jobs!$P$5:$P$604<>"Cancelled")*Jobs!$B$5:$B$604+(1-(Jobs!$G$5:$G$604=A11)*(Jobs!$B$5:$B$604>=TodayDate)*(Jobs!$P$5:$P$604<>"Cancelled"))*2958465))=2958465,"",SUMPRODUCT(MIN((Jobs!$G$5:$G$604=A11)*(Jobs!$B$5:$B$604>=TodayDate)*(Jobs!$P$5:$P$604<>"Cancelled")*Jobs!$B$5:$B$604+(1-(Jobs!$G$5:$G$604=A11)*(Jobs!$B$5:$B$604>=TodayDate)*(Jobs!$P$5:$P$604<>"Cancelled"))*2958465)))) -> 0 | AD11: =IF(A11="","",SUMIFS(Invoices!$V$5:$V$404,Invoices!$D$5:$D$404,A11)) -> 0 | AE11: =IF(A11="","",SUMIFS(Invoices!$W$5:$W$404,Invoices!$D$5:$D$404,A11)) -> 0 | AF11: =IF(A11="","",AD11-AE11) -> 0 | AG11: =IF(OR(A11="",Y11=0),"",AD11/Y11) -> 0 | AH11: =IF(A11="","",SUMIFS('Job Costing'!$U$5:$U$604,'Job Costing'!$D$5:$D$604,A11)) -> 0 | AI11: =IF(OR(A11="",AD11=0),"",AH11/AD11) -> 0 | AJ11: =IF(OR(A11="",K11="",AG11=""),"",AG11*IFERROR(INDEX(FreqPerYear,MATCH(K11,FreqNames,0)),1)) -> 0 | AK11: =IF(A11="","",IFERROR(AVERAGEIFS(Jobs!$AA$5:$AA$604,Jobs!$G$5:$G$604,A11,Jobs!$AA$5:$AA$604,">0"),"")) -> 0 | AL11: =IF(A11="","",COUNTIFS(Complaints!$D$5:$D$84,A11)) -> 0 | AM11: =IF(B11="","",COUNTIFS($AD$5:$AD$204,">"&AD11)+COUNTIFS($AD$5:AD11,AD11)) -> 0 | AN11: =IF(B11="","",COUNTIFS($AH$5:$AH$204,">"&AH11)+COUNTIFS($AH$5:AH11,AH11)) -> 0 | AO11: =IF(B11="","",COUNTIFS($AJ$5:$AJ$204,">"&AJ11)+COUNTIFS($AJ$5:AJ11,AJ11)) -> 0 | AP11: =IF(B11="","",IF(H11="Lost","Lost",IF(H11="Inactive","Dormant",IF(AA11="","Dormant",IF(AB11>InactiveClientDays*2,"Dormant",IF(AB11>InactiveClientDays,"At risk",IF(AC11="","Slipping",IF(Y11>=10,"Loyal","Steady")))))))) -> 0 | AQ11: =IF(OR(B11="",AP11="Lost",AP11="Dormant"),"",IF(OR(AP11="At risk",AP11="Slipping"),IF(AB11="",999,AB11),"")) -> 0 | AR11: =IF(AQ11="","",COUNTIFS($AQ$5:$AQ$204,">"&AQ11)+COUNTIFS($AQ$5:AQ11,AQ11)) -> 0 | AS11: =IF(B11="","",IF(AF11>0.5,"Chase - "&TEXT(AF11,"0")&" owing",IF(AND(H11<>"Lost",H11<>"Inactive",H11<>"Paused",AC11="",K11<>"One-off"),"Book - nothing in the diary",IF(AND(S11<>"",S11-TodayDate<=RenewalWarningDays,S11>=TodayDate),"Due - contract renews soon",IF(AP11="At risk","Call - going quiet",IF(AL11>=2,"Check - complaints logged",IF(AND(AI11<>"",AI11<MarginFloor,Y11>0),"Check - thin margin","OK"))))))) -> 0
A12: =IF(B12="","",ClientPrefix&TEXT(ROW()-4,"0000")) -> 0 | B12: Nguyen Household | C12: Residential | D12: Lien Nguyen | E12: (503) 555 0259 | F12: lien.nguyen@example.com | G12: 88 Alder Way, Portland OR 97211 | H12: Active | I12: Facebook | J12: 46103 | K12: Monthly | L12: Wednesday | M12: Morning (9-12) | N12: Jade Ellis | O12: 45 | P12: 7 | R12: Rolling monthly | T12: No | U12: Yes | V12: Shoes off at the door. Key is in the lockbox. | W12: =IF(A12="","",COUNTIFS(Properties!$C$5:$C$254,A12)) -> 0 | X12: =IF(A12="","",COUNTIFS(Jobs!$G$5:$G$604,A12)) -> 0 | Y12: =IF(A12="","",COUNTIFS(Jobs!$G$5:$G$604,A12,Jobs!$P$5:$P$604,"Completed")+COUNTIFS(Jobs!$G$5:$G$604,A12,Jobs!$P$5:$P$604,"Invoiced")) -> 0 | Z12: =IF(A12="","",COUNTIFS(Jobs!$G$5:$G$604,A12,Jobs!$P$5:$P$604,"Cancelled")+COUNTIFS(Jobs!$G$5:$G$604,A12,Jobs!$P$5:$P$604,"No access")) -> 0 | AA12: =IF(A12="","",IF(SUMPRODUCT(MAX((Jobs!$G$5:$G$604=A12)*((Jobs!$P$5:$P$604="Completed")+(Jobs!$P$5:$P$604="Invoiced"))*Jobs!$B$5:$B$604))=0,"",SUMPRODUCT(MAX((Jobs!$G$5:$G$604=A12)*((Jobs!$P$5:$P$604="Completed")+(Jobs!$P$5:$P$604="Invoiced"))*Jobs!$B$5:$B$604)))) -> 0 | AB12: =IF(AA12="","",TodayDate-AA12) -> 0 | AC12: =IF(A12="","",IF(SUMPRODUCT(MIN((Jobs!$G$5:$G$604=A12)*(Jobs!$B$5:$B$604>=TodayDate)*(Jobs!$P$5:$P$604<>"Cancelled")*Jobs!$B$5:$B$604+(1-(Jobs!$G$5:$G$604=A12)*(Jobs!$B$5:$B$604>=TodayDate)*(Jobs!$P$5:$P$604<>"Cancelled"))*2958465))=2958465,"",SUMPRODUCT(MIN((Jobs!$G$5:$G$604=A12)*(Jobs!$B$5:$B$604>=TodayDate)*(Jobs!$P$5:$P$604<>"Cancelled")*Jobs!$B$5:$B$604+(1-(Jobs!$G$5:$G$604=A12)*(Jobs!$B$5:$B$604>=TodayDate)*(Jobs!$P$5:$P$604<>"Cancelled"))*2958465)))) -> 0 | AD12: =IF(A12="","",SUMIFS(Invoices!$V$5:$V$404,Invoices!$D$5:$D$404,A12)) -> 0 | AE12: =IF(A12="","",SUMIFS(Invoices!$W$5:$W$404,Invoices!$D$5:$D$404,A12)) -> 0 | AF12: =IF(A12="","",AD12-AE12) -> 0 | AG12: =IF(OR(A12="",Y12=0),"",AD12/Y12) -> 0 | AH12: =IF(A12="","",SUMIFS('Job Costing'!$U$5:$U$604,'Job Costing'!$D$5:$D$604,A12)) -> 0 | AI12: =IF(OR(A12="",AD12=0),"",AH12/AD12) -> 0 | AJ12: =IF(OR(A12="",K12="",AG12=""),"",AG12*IFERROR(INDEX(FreqPerYear,MATCH(K12,FreqNames,0)),1)) -> 0 | AK12: =IF(A12="","",IFERROR(AVERAGEIFS(Jobs!$AA$5:$AA$604,Jobs!$G$5:$G$604,A12,Jobs!$AA$5:$AA$604,">0"),"")) -> 0 | AL12: =IF(A12="","",COUNTIFS(Complaints!$D$5:$D$84,A12)) -> 0 | AM12: =IF(B12="","",COUNTIFS($AD$5:$AD$204,">"&AD12)+COUNTIFS($AD$5:AD12,AD12)) -> 0 | AN12: =IF(B12="","",COUNTIFS($AH$5:$AH$204,">"&AH12)+COUNTIFS($AH$5:AH12,AH12)) -> 0 | AO12: =IF(B12="","",COUNTIFS($AJ$5:$AJ$204,">"&AJ12)+COUNTIFS($AJ$5:AJ12,AJ12)) -> 0 | AP12: =IF(B12="","",IF(H12="Lost","Lost",IF(H12="Inactive","Dormant",IF(AA12="","Dormant",IF(AB12>InactiveClientDays*2,"Dormant",IF(AB12>InactiveClientDays,"At risk",IF(AC12="","Slipping",IF(Y12>=10,"Loyal","Steady")))))))) -> 0 | AQ12: =IF(OR(B12="",AP12="Lost",AP12="Dormant"),"",IF(OR(AP12="At risk",AP12="Slipping"),IF(AB12="",999,AB12),"")) -> 0 | AR12: =IF(AQ12="","",COUNTIFS($AQ$5:$AQ$204,">"&AQ12)+COUNTIFS($AQ$5:AQ12,AQ12)) -> 0 | AS12: =IF(B12="","",IF(AF12>0.5,"Chase - "&TEXT(AF12,"0")&" owing",IF(AND(H12<>"Lost",H12<>"Inactive",H12<>"Paused",AC12="",K12<>"One-off"),"Book - nothing in the diary",IF(AND(S12<>"",S12-TodayDate<=RenewalWarningDays,S12>=TodayDate),"Due - contract renews soon",IF(AP12="At risk","Call - going quiet",IF(AL12>=2,"Check - complaints logged",IF(AND(AI12<>"",AI12<MarginFloor,Y12>0),"Check - thin margin","OK"))))))) -> 0
A13: =IF(B13="","",ClientPrefix&TEXT(ROW()-4,"0000")) -> 0 | B13: Summit Fitness Studio | C13: Gym & studio | D13: Dev Patel | E13: (503) 555 0333 | F13: dev@summitfitness.example | G13: 501 Summit Drive, Portland OR 97201 | H13: Active | I13: Instagram | J13: 46133 | K13: Twice a week | L13: Monday | M13: Early (7-9) | N13: Luke Bennett | O13: 52 | P13: 14 | R13: 6 months | T13: No | U13: Yes | V13: Mirrors and mats matter more than floors here. | W13: =IF(A13="","",COUNTIFS(Properties!$C$5:$C$254,A13)) -> 0 | X13: =IF(A13="","",COUNTIFS(Jobs!$G$5:$G$604,A13)) -> 0 | Y13: =IF(A13="","",COUNTIFS(Jobs!$G$5:$G$604,A13,Jobs!$P$5:$P$604,"Completed")+COUNTIFS(Jobs!$G$5:$G$604,A13,Jobs!$P$5:$P$604,"Invoiced")) -> 0 | Z13: =IF(A13="","",COUNTIFS(Jobs!$G$5:$G$604,A13,Jobs!$P$5:$P$604,"Cancelled")+COUNTIFS(Jobs!$G$5:$G$604,A13,Jobs!$P$5:$P$604,"No access")) -> 0 | AA13: =IF(A13="","",IF(SUMPRODUCT(MAX((Jobs!$G$5:$G$604=A13)*((Jobs!$P$5:$P$604="Completed")+(Jobs!$P$5:$P$604="Invoiced"))*Jobs!$B$5:$B$604))=0,"",SUMPRODUCT(MAX((Jobs!$G$5:$G$604=A13)*((Jobs!$P$5:$P$604="Completed")+(Jobs!$P$5:$P$604="Invoiced"))*Jobs!$B$5:$B$604)))) -> 0 | AB13: =IF(AA13="","",TodayDate-AA13) -> 0 | AC13: =IF(A13="","",IF(SUMPRODUCT(MIN((Jobs!$G$5:$G$604=A13)*(Jobs!$B$5:$B$604>=TodayDate)*(Jobs!$P$5:$P$604<>"Cancelled")*Jobs!$B$5:$B$604+(1-(Jobs!$G$5:$G$604=A13)*(Jobs!$B$5:$B$604>=TodayDate)*(Jobs!$P$5:$P$604<>"Cancelled"))*2958465))=2958465,"",SUMPRODUCT(MIN((Jobs!$G$5:$G$604=A13)*(Jobs!$B$5:$B$604>=TodayDate)*(Jobs!$P$5:$P$604<>"Cancelled")*Jobs!$B$5:$B$604+(1-(Jobs!$G$5:$G$604=A13)*(Jobs!$B$5:$B$604>=TodayDate)*(Jobs!$P$5:$P$604<>"Cancelled"))*2958465)))) -> 0 | AD13: =IF(A13="","",SUMIFS(Invoices!$V$5:$V$404,Invoices!$D$5:$D$404,A13)) -> 0 | AE13: =IF(A13="","",SUMIFS(Invoices!$W$5:$W$404,Invoices!$D$5:$D$404,A13)) -> 0 | AF13: =IF(A13="","",AD13-AE13) -> 0 | AG13: =IF(OR(A13="",Y13=0),"",AD13/Y13) -> 0 | AH13: =IF(A13="","",SUMIFS('Job Costing'!$U$5:$U$604,'Job Costing'!$D$5:$D$604,A13)) -> 0 | AI13: =IF(OR(A13="",AD13=0),"",AH13/AD13) -> 0 | AJ13: =IF(OR(A13="",K13="",AG13=""),"",AG13*IFERROR(INDEX(FreqPerYear,MATCH(K13,FreqNames,0)),1)) -> 0 | AK13: =IF(A13="","",IFERROR(AVERAGEIFS(Jobs!$AA$5:$AA$604,Jobs!$G$5:$G$604,A13,Jobs!$AA$5:$AA$604,">0"),"")) -> 0 | AL13: =IF(A13="","",COUNTIFS(Complaints!$D$5:$D$84,A13)) -> 0 | AM13: =IF(B13="","",COUNTIFS($AD$5:$AD$204,">"&AD13)+COUNTIFS($AD$5:AD13,AD13)) -> 0 | AN13: =IF(B13="","",COUNTIFS($AH$5:$AH$204,">"&AH13)+COUNTIFS($AH$5:AH13,AH13)) -> 0 | AO13: =IF(B13="","",COUNTIFS($AJ$5:$AJ$204,">"&AJ13)+COUNTIFS($AJ$5:AJ13,AJ13)) -> 0 | AP13: =IF(B13="","",IF(H13="Lost","Lost",IF(H13="Inactive","Dormant",IF(AA13="","Dormant",IF(AB13>InactiveClientDays*2,"Dormant",IF(AB13>InactiveClientDays,"At risk",IF(AC13="","Slipping",IF(Y13>=10,"Loyal","Steady")))))))) -> 0 | AQ13: =IF(OR(B13="",AP13="Lost",AP13="Dormant"),"",IF(OR(AP13="At risk",AP13="Slipping"),IF(AB13="",999,AB13),"")) -> 0 | AR13: =IF(AQ13="","",COUNTIFS($AQ$5:$AQ$204,">"&AQ13)+COUNTIFS($AQ$5:AQ13,AQ13)) -> 0 | AS13: =IF(B13="","",IF(AF13>0.5,"Chase - "&TEXT(AF13,"0")&" owing",IF(AND(H13<>"Lost",H13<>"Inactive",H13<>"Paused",AC13="",K13<>"One-off"),"Book - nothing in the diary",IF(AND(S13<>"",S13-TodayDate<=RenewalWarningDays,S13>=TodayDate),"Due - contract renews soon",IF(AP13="At risk","Call - going quiet",IF(AL13>=2,"Check - complaints logged",IF(AND(AI13<>"",AI13<MarginFloor,Y13>0),"Check - thin margin","OK"))))))) -> 0
