Workbook
Name AllocationList: Lists!$C$122:$C$134
Name BatchIDs: OFFSET(Batches!$A$5,0,0,MAX(1,COUNTIF(Batches!$A$5:$A$204,"?*")),1)
Name BatchPrefix: Settings!$D$98
Name BatchStatusList: Lists!$A$146:$A$162
Name BeCm: 'Profit & Break-Even'!$C$21
Name BeContribution: 'Profit & Break-Even'!$C$20
Name BeFeeFixed: 'Profit & Break-Even'!$D$12
Name BeFeePct: 'Profit & Break-Even'!$D$11
Name BeFees: 'Profit & Break-Even'!$C$18
Name BeFixed: 'Profit & Break-Even'!$D$7
Name BeFixedTotal: 'Profit & Break-Even'!$C$16
Name BeP: 'Profit & Break-Even'!$C$17
Name BePrice: 'Profit & Break-Even'!$D$9
Name BeProduct: 'Profit & Break-Even'!$D$6
Name BeVar: 'Profit & Break-Even'!$C$19
Name BeVariable: 'Profit & Break-Even'!$D$10
Name BeWage: 'Profit & Break-Even'!$D$8
Name BundleIDs: OFFSET(Bundles!$A$5,0,0,MAX(1,COUNTIF(Bundles!$A$5:$A$64,"?*")),1)
Name BundlePrefix: Settings!$D$96
Name BundleTypeList: Lists!$C$265:$C$280
Name CandlePrefix: Settings!$D$107
Name CategoryList: Lists!$E$9:$E$31
Name ChannelList: Lists!$I$9:$I$23
Name ChannelNames: OFFSET(Channels!$A$5,0,0,MAX(1,COUNTIF(Channels!$A$5:$A$18,"?*")),1)
Name ClothingPrefix: Settings!$D$108
Name ContractorRate: Settings!$D$30
Name CrochetPrefix: Settings!$D$105
Name CurrencyFee: Settings!$D$65
Name CustomerIDs: OFFSET('Wholesale Customers'!$A$5,0,0,MAX(1,COUNTIF('Wholesale Customers'!$A$5:$A$64,"?*")),1)
Name CustomerNames: OFFSET('Wholesale Customers'!$B$5,0,0,MAX(1,COUNTIF('Wholesale Customers'!$B$5:$B$64,"?*")),1)
Name CustomerPrefix: Settings!$D$100
Name CustomerTypeList: Lists!$I$146:$I$164
Name DashKey: Dashboard!$H$5
Name DefaultBatchSize: Settings!$D$35
Name DefaultChannel: Settings!$D$71
Name DefaultDefect: Settings!$D$41
Name DefaultDiscount: Settings!$D$80
Name DefaultMarkup: Settings!$D$76
Name DefaultPackaging: Settings!$D$45
Name DefaultShipping: Settings!$D$46
Name DefaultWaste: Settings!$D$40
Name DevPrefix: Settings!$D$102
Name DevStageList: Lists!$A$192:$A$207
Name DifficultyList: Lists!$A$65:$A$77
Name DiffNames: Lists!$A$320:$A$328
Name DiffPriceFactors: Lists!$C$320:$C$328
Name DiffTimeFactors: Lists!$B$320:$B$328
Name DigitalPrefix: Settings!$D$110
Name DigitalTypeList: Lists!$G$241:$G$260
Name EmployeeRate: Settings!$D$29
Name EventNames: OFFSET(Events!$A$5,0,0,MAX(1,COUNTIF(Events!$A$5:$A$44,"?*")),1)
Name EventPrefix: Settings!$D$103
Name EventTypeList: Lists!$G$146:$G$163
Name FabricList: Lists!$I$215:$I$238
Name FeeReviewDays: Settings!$D$69
Name FeesOnShipping: Settings!$D$66
Name FeesOnTax: Settings!$D$67
Name FeesReviewed: Settings!$D$68
Name FeesStale: Settings!$D$70
Name FeeTypeList: Lists!$E$122:$E$136

Sheet Start Here
A1: Handmade Product Pricing & Profit Calculator | H1: Novality Store | v1.0.0
A2: Materials, labour, packaging, fees and overhead - turned into a price that pays you.
A3: > Start Here | C3: > Dashboard | E3: > Products | G3: > Materials | I3: > Labour
A5: Most handmade pricing advice stops at 'materials times two'. That is why so many makers work for nothing. This workbook counts the yarn, the hours, the box, the postage, the Etsy fees and the studio rent, then solves for the price that leaves the margin you actually want.
A7: Five minutes to your first honest price
B8: Step | C8: Where | D8: What to do
B9: 1 | C9: Settings | D9: Put your hourly rate in. That one number changes more than anything else here.
B10: 2 | C10: Materials | D10: Add the three or four materials the product uses, with what you paid and how much came in the pack.
B11: 3 | C11: Material Usage | D11: List how much of each goes into one piece.
B12: 4 | C12: Labor | D12: Put the minutes in - all of them, including finishing and packing.
B13: 5 | C13: Products | D13: Add the product. Cost, suggested price, margin and your hourly wage appear.
B14: 6 | C14: Retail Calculator | D14: Check the price, try the ladder, and decide.
A16: The formula everything is built on
B17: Marketplace fees are charged on the price - the price you have not worked out yet. That is why you cannot just add 20% to your costs: the fee is charged on the fee. Solving it properly looks like this.
B18: Cost | C18: C = materials + labour + packaging + postage + overhead | G18: What one piece costs you.
B19: Labour | C19: L = minutes / 60 x your hourly rate | G19: Every minute, not just the fun ones.
B20: Price | C20: Price = (C + fixed fees) / (1 - target margin - fee rate) | G20: The price that leaves the margin you asked for, after the percentage fees.
B21: Margin | C21: Margin = profit / price x 100 | G21: The share of the price you keep.
B22: Markup | C22: Markup = profit / cost x 100 | G22: The share of the cost you added. Not the same thing.
B23: Break-even | C23: Units = fixed costs / contribution a unit | G23: Rounded up, because you cannot sell two thirds of a candle.
B25: Worked example. A beanie costs $8.40 in yarn and labour, $1.85 to package and post, and carries $1.20 of overhead - $11.45. Etsy takes about 9.5% plus $0.45. You want a 55% margin. The price is (11.45 + 0.45) / (1 - 0.55 - 0.095) = $33.52, rounded to $33.99. Adding 55% to the cost would have given $17.75 and a real margin of 25%.
A27: What is in the file
B28: Tab | C28: What it does | D28: Your job
B29: Settings | C29: Your rates, targets, fee rates, rounding rule and every default | H29: Fill in once, review twice a year
B30: Dashboard | C30: Your margins, your month and everything that needs fixing | H30: Read it weekly
B31: Products | C31: The catalog: cost, price, margin, hourly wage and what sold | H31: The heart of the workbook
B32: Materials | C32: Every yarn, bead, wax and board, with the cost per gram worked out | H32: Add as you buy
B33: Material Usage | C33: How much of each material goes into each product | H33: The bill of materials
B34: Labor | C34: Minutes per stage, per item or per batch | H34: Be honest about the time
B35: Packaging / Shipping | C35: Boxes, tissue, labels, postage services and what you absorb | H35: Set up once
B36: Overhead | C36: Studio, insurance, subscriptions - shared across what you make | H36: Add your bills
B37: Channels | C37: Etsy, Shopify, markets, wholesale - every fee, fully editable | H37: Check twice a year
B38: Retail Calculator | C38: The price, the ladder and the sanity check | H38: Use before you list
B39: Wholesale Calculator | C39: What a stockist leaves you and what retail price supports it | H39: Use before you say yes
B40: Profit & Break-Even | C40: Contribution, break-even units, margin against markup | H40: Use when you are planning
... B51: Lists / Help | C51: Every drop-down, every factor table, and the troubleshooting | H51: Edit the lists
A53: A rhythm that keeps it accurate
B54: As you buy | C54: Add new materials with the pack price and pack size. Nothing else is needed. | I54: 1 minute
B55: As you make | C55: Log batches with the real hours. Two runs and your estimates become facts. | I55: 2 minutes
B56: Every week | C56: Enter the week's sales with the real fees and postage. | I56: 15 minutes
...

Sheet Settings
A1: Business Settings | G1: Novality Store | v1.0.0
A2: Fill in the white cells once. Shaded cells are locked formulas. Every price, every margin and every warning in the workbook reads these values.
A3: > Start Here | C3: > Dashboard | E3: > Products | G3: > Materials
A5: 1. Your shop
B6: Business name | D6: Willow & Thread Handmade | F6: Shown on every quote, order form and printable page.
B7: Maker / owner | D7: Maya Albright
B8: Brand name | D8: Willow & Thread | F8: If you trade under a shorter name than the business one.
B9: Email | D9: hello@willowandthread.co
B10: Phone | D10: (828) 555 0176
B11: Address | D11: 42 Larkspur Lane, Asheville, NC 28801
B12: Website | D12: willowandthread.co
B13: Marketplace shop name | D13: WillowAndThreadCo | F13: Your Etsy / Amazon Handmade / Folksy shop name, for the order forms.
B14: Social handle | D14: @willowandthread
B15: Tagline | D15: Small batch crochet, candles and keepsakes since 2021
B16: Business / tax number | D16: NC-HM-2021-4471
A18: 2. Dates
B19: Year | D19: 2026 | E19: The year the reports and the sales summaries open on.
B20: Today | D20: =TODAY() -> 0 | E20: Every 'due', 'stale price' and 'review the fees' flag counts from this cell, so they all move on by themselves overnight.
B21: This month starts | D21: =DATE(YEAR(TodayDate),MONTH(TodayDate),1) -> 0
B22: This month ends | D22: =DATE(YEAR(TodayDate),MONTH(TodayDate)+1,1)-1 -> 0
B23: This year starts | D23: =DATE(PlanYear,1,1) -> 0
A25: 3. What your time is worth
B26: The single number most handmade sellers get wrong. If your products do not pay you for the hours you spend making them, you do not have a business, you have an expensive hobby. Pay yourself a real wage here and let the prices follow.
B27: What you pay yourself an hour | D27: 25 | E27: What one hour of your making time costs. Not what is left over - what you are worth.
B28: Local minimum wage (for the warning) | D28: 15 | E28: The workbook flags any product whose price pays you less than this an hour.
B29: Employee hourly rate | D29: 18
B30: Contractor / outsourced hourly rate | D30: 32 | E30: Used when a labour line says somebody else made it.
B31: On-costs on paid labour | D31: 0.12 | E31: Employer tax, insurance and holiday pay. Added to employee and contractor hours.
B32: Your hour, with on-costs | D32: =ROUND(HourlyRate*(1+PayrollBurden),2) -> 0 | E32: This is the rate the labour calculator multiplies your minutes by.
B33: Hours a month you actually make things | D33: 70 | E33: Bench hours only - not admin, not photos, not scrolling. Overhead per hour is divided by this.
B34: Items a month you usually finish | D34: 24 | E34: Used when overhead is spread per item instead of per hour.
B35: Default batch size | D35: 10
B36: Consumables an hour | D36: 0.6 | E36: Glue, needles, sandpaper, thread - the small things nobody itemises. Added per labour hour.
A38: 4. Materials and waste
B39: Measurement system | D39: Metric | E39: Metric weighs in grams, imperial in ounces. The unit table on Lists converts either way.
B40: Default waste allowance | D40: 0.05 | E40: Offcuts, frogged rows, the last inch of a board. Added to every material line that does not set its own.
B41: Default defect / seconds rate | D41: 0.03 | E41: The share of a batch that never makes it to the shop. The batch tab spreads its cost over the pieces that do.
B42: Days of stock that counts as low | D42: 21
A44: 5. Packaging and shipping
B45: Fallback packaging cost | D45: 1.85 | E45: Used for a product that has not picked a packaging profile on the Packaging tab.
...

Sheet Dashboard
A1: Pricing Dashboard | L1: Novality Store | v1.0.0
A2: Your range, your margins and your month - worked out from the products, costs and sales you have already entered.
A3: > Start Here | C3: > Dashboard | E3: > Products | G3: > Materials | I3: > Labour | K3: > Retail Price | M3: > Wholesale
A5: Shop | B5: =ShopName -> 0 | E5: Month | F5: =TEXT(TodayDate,"mmmm yyyy") -> 0 | G5: Month key | H5: =TEXT(TodayDate,"yyyy-mm") -> 0 | I5: Today | K5: =TodayDate -> 0
A7: Products priced | D7: Average margin | G7: Average you earn an hour | J7: Products below target
A8: =COUNTIF(Products!$B$5:$B$304,"<>") -> 0 | D8: =IFERROR(AVERAGE(Products!$AW$5:$AW$304),"") -> 0 | G8: =IFERROR(AVERAGE(Products!$AZ$5:$AZ$304),"") -> 0 | J8: =COUNTIFS(Products!$AW$5:$AW$304,"<"&MarginWarning,Products!$B$5:$B$304,"<>") -> 0
A9: in the catalog | D9: target 30% | G9: your rate is $25.00 | J9: margin under your warning level
A11: Revenue this month | D11: Profit this month | G11: Margin this month | J11: Items sold this month
A12: =ROUND(SUMIFS(Sales!$V$5:$V$804,Sales!$R$5:$R$804,DashKey),2) -> 0 | D12: =ROUND(SUMIFS(Sales!$AG$5:$AG$804,Sales!$R$5:$R$804,DashKey),2) -> 0 | G12: =IFERROR(SUMIFS(Sales!$AG$5:$AG$804,Sales!$R$5:$R$804,DashKey)/SUMIFS(Sales!$V$5:$V$804,Sales!$R$5:$R$804,DashKey),"") -> 0 | J12: =SUMIFS(Sales!$D$5:$D$804,Sales!$R$5:$R$804,DashKey) -> 0
A13: target $2,400 | D13: after fees and postage | G13: what you actually kept | J13: across every channel
A15: Overhead a month | D15: Covered by this month | G15: Value of your materials | J15: Hours of work sold
A16: =ROUND(OverheadMonthly,2) -> 0 | D16: =IFERROR(SUMIFS(Sales!$AG$5:$AG$804,Sales!$R$5:$R$804,DashKey)/MAX(0.01,OverheadMonthly),"") -> 0 | G16: =ROUND(SUM(Materials!$Y$5:$Y$254),2) -> 0 | J16: =ROUND(SUMIFS(Sales!$AK$5:$AK$804,Sales!$R$5:$R$804,DashKey),1) -> 0
A17: studio, insurance, software | D17: 100% means the studio has paid for itself | G17: money sitting on the shelf | J17: this month
A19: Needs your attention
A20: What | B20: How many | C20: What it means | D20: Where to fix it
A21: Products with no price | B21: =COUNTIFS(Products!$B$5:$B$304,"<>",Products!$AR$5:$AR$304,"") -> 0 | C21: ="Listed in the catalog with nothing to sell them at" -> 0 | M21: Products
A22: Products that lose money | B22: =COUNTIF(Products!$BS$5:$BS$304,"Loss*") -> 0 | C22: ="The price does not cover the cost and the fees" -> 0 | M22: Products
A23: Products below minimum wage | B23: =COUNTIF(Products!$BS$5:$BS$304,"Below*") -> 0 | C23: ="You would earn less than "&TEXT(MinimumWage,"0.00")&" an hour making these" -> 0 | M23: Products
A24: Products under your margin warning | B24: =COUNTIFS(Products!$AW$5:$AW$304,"<"&MarginWarning,Products!$B$5:$B$304,"<>") -> 0 | C24: ="Thinner than "&TEXT(MarginWarning,"0%")&" - one bad month away from nothing" -> 0 | M24: Retail Calculator
A25: Products with no costs entered | B25: =COUNTIF(Products!$BS$5:$BS$304,"Add - no costs*") -> 0 | C25: ="Nothing on the Material Usage or Labor tabs for these" -> 0 | M25: Material Usage
A26: Materials with no price | B26: =COUNTIF(Materials!$AG$5:$AG$254,"Add*") -> 0 | C26: ="Every product using them is under-costed" -> 0 | M26: Materials
A27: Materials running low | B27: =COUNTIF(Materials!$AE$5:$AE$254,"Low stock")+COUNTIF(Materials!$AE$5:$AE$254,"Out of stock") -> 0 | C27: ="Below the reorder level or less than "&LowStockDays&" days of cover" -> 0 | M27: Materials
A28: Prices going stale | B28: =COUNTIF(Products!$BS$5:$BS$304,"Review*") -> 0 | C28: ="Not changed in "&PriceReviewDays&" days, while your costs moved" -> 0 | M28: Price History
A29: Fee settings to check | B29: =IF(FeesStale="Yes",1,0) -> 0 | C29: ="Marketplace fees change. Yours were last reviewed "&TEXT(FeesReviewed,"d mmm yyyy") -> 0 | M29: Channels
A30: Orders that lost money | B30: =COUNTIFS(Sales!$AG$5:$AG$804,"<0") -> 0 | C30: ="Real orders where the money went the wrong way" -> 0 | M30: Sales
A31: Batches costing more than the estimate | B31: =COUNTIF(Batches!$AE$5:$AE$204,"Check - costing*") -> 0 | C31: ="The catalog is optimistic about these" -> 0 | M31: Batches
A32: Wholesale orders below target margin | B32: =COUNTIF('Wholesale Orders'!$AD$5:$AD$204,"Low margin*") -> 0 | C32: ="The discount is deeper than the product can carry" -> 0 | M32: Wholesale Orders
A33: Unpaid wholesale invoices | B33: =ROUND(SUMIFS('Wholesale Orders'!$V$5:$V$204,'Wholesale Orders'!$M$5:$M$204,"No"),0) -> 0 | C33: ="Money shops owe you right now" -> 0 | M33: Wholesale Customers
A34: Avoidable waste this year | B34: =ROUND(SUMIFS('Waste Log'!$L$5:$L$204,'Waste Log'!$G$5:$G$204,"Yes"),0) -> 0 | C34: ="Material you paid for and did not sell" -> 0 | M34: Waste Log
A36: What is working
A37: Most profit a sale | B37: Profit | C37: Best margin | D37: Margin | E37: Best paid an hour | F37: An hour | G37: Most sold | H37: Sold
A38: =IFERROR(INDEX(Products!$B$5:$B$304,MATCH(1,Products!$BO$5:$BO$304,0)),"") -> 0 | B38: =IFERROR(INDEX(Products!$AV$5:$AV$304,MATCH(1,Products!$BO$5:$BO$304,0)),"") -> 0 | C38: =IFERROR(INDEX(Products!$B$5:$B$304,MATCH(1,Products!$BP$5:$BP$304,0)),"") -> 0 | D38: =IFERROR(INDEX(Products!$AW$5:$AW$304,MATCH(1,Products!$BP$5:$BP$304,0)),"") -> 0 | E38: =IFERROR(INDEX(Products!$B$5:$B$304,MATCH(1,Products!$BR$5:$BR$304,0)),"") -> 0 | F38: =IFERROR(INDEX(Products!$AY$5:$AY$304,MATCH(1,Products!$BR$5:$BR$304,0)),"") -> 0 | G38: =IFERROR(INDEX(Products!$B$5:$B$304,MATCH(1,Products!$BQ$5:$BQ$304,0)),"") -> 0 | H38: =IFERROR(INDEX(Products!$BH$5:$BH$304,MATCH(1,Products!$BQ$5:$BQ$304,0)),"") -> 0
A39: =IFERROR(INDEX(Products!$B$5:$B$304,MATCH(2,Products!$BO$5:$BO$304,0)),"") -> 0 | B39: =IFERROR(INDEX(Products!$AV$5:$AV$304,MATCH(2,Products!$BO$5:$BO$304,0)),"") -> 0 | C39: =IFERROR(INDEX(Products!$B$5:$B$304,MATCH(2,Products!$BP$5:$BP$304,0)),"") -> 0 | D39: =IFERROR(INDEX(Products!$AW$5:$AW$304,MATCH(2,Products!$BP$5:$BP$304,0)),"") -> 0 | E39: =IFERROR(INDEX(Products!$B$5:$B$304,MATCH(2,Products!$BR$5:$BR$304,0)),"") -> 0 | F39: =IFERROR(INDEX(Products!$AY$5:$AY$304,MATCH(2,Products!$BR$5:$BR$304,0)),"") -> 0 | G39: =IFERROR(INDEX(Products!$B$5:$B$304,MATCH(2,Products!$BQ$5:$BQ$304,0)),"") -> 0 | H39: =IFERROR(INDEX(Products!$BH$5:$BH$304,MATCH(2,Products!$BQ$5:$BQ$304,0)),"") -> 0
A40: =IFERROR(INDEX(Products!$B$5:$B$304,MATCH(3,Products!$BO$5:$BO$304,0)),"") -> 0 | B40: =IFERROR(INDEX(Products!$AV$5:$AV$304,MATCH(3,Products!$BO$5:$BO$304,0)),"") -> 0 | C40: =IFERROR(INDEX(Products!$B$5:$B$304,MATCH(3,Products!$BP$5:$BP$304,0)),"") -> 0 | D40: =IFERROR(INDEX(Products!$AW$5:$AW$304,MATCH(3,Products!$BP$5:$BP$304,0)),"") -> 0 | E40: =IFERROR(INDEX(Products!$B$5:$B$304,MATCH(3,Products!$BR$5:$BR$304,0)),"") -> 0 | F40: =IFERROR(INDEX(Products!$AY$5:$AY$304,MATCH(3,Products!$BR$5:$BR$304,0)),"") -> 0 | G40: =IFERROR(INDEX(Products!$B$5:$B$304,MATCH(3,Products!$BQ$5:$BQ$304,0)),"") -> 0 | H40: =IFERROR(INDEX(Products!$BH$5:$BH$304,MATCH(3,Products!$BQ$5:$BQ$304,0)),"") -> 0
A41: =IFERROR(INDEX(Products!$B$5:$B$304,MATCH(4,Products!$BO$5:$BO$304,0)),"") -> 0 | B41: =IFERROR(INDEX(Products!$AV$5:$AV$304,MATCH(4,Products!$BO$5:$BO$304,0)),"") -> 0 | C41: =IFERROR(INDEX(Products!$B$5:$B$304,MATCH(4,Products!$BP$5:$BP$304,0)),"") -> 0 | D41: =IFERROR(INDEX(Products!$AW$5:$AW$304,MATCH(4,Products!$BP$5:$BP$304,0)),"") -> 0 | E41: =IFERROR(INDEX(Products!$B$5:$B$304,MATCH(4,Products!$BR$5:$BR$304,0)),"") -> 0 | F41: =IFERROR(INDEX(Products!$AY$5:$AY$304,MATCH(4,Products!$BR$5:$BR$304,0)),"") -> 0 | G41: =IFERROR(INDEX(Products!$B$5:$B$304,MATCH(4,Products!$BQ$5:$BQ$304,0)),"") -> 0 | H41: =IFERROR(INDEX(Products!$BH$5:$BH$304,MATCH(4,Products!$BQ$5:$BQ$304,0)),"") -> 0
A42: =IFERROR(INDEX(Products!$B$5:$B$304,MATCH(5,Products!$BO$5:$BO$304,0)),"") -> 0 | B42: =IFERROR(INDEX(Products!$AV$5:$AV$304,MATCH(5,Products!$BO$5:$BO$304,0)),"") -> 0 | C42: =IFERROR(INDEX(Products!$B$5:$B$304,MATCH(5,Products!$BP$5:$BP$304,0)),"") -> 0 | D42: =IFERROR(INDEX(Products!$AW$5:$AW$304,MATCH(5,Products!$BP$5:$BP$304,0)),"") -> 0 | E42: =IFERROR(INDEX(Products!$B$5:$B$304,MATCH(5,Products!$BR$5:$BR$304,0)),"") -> 0 | F42: =IFERROR(INDEX(Products!$AY$5:$AY$304,MATCH(5,Products!$BR$5:$BR$304,0)),"") -> 0 | G42: =IFERROR(INDEX(Products!$B$5:$B$304,MATCH(5,Products!$BQ$5:$BQ$304,0)),"") -> 0 | H42: =IFERROR(INDEX(Products!$BH$5:$BH$304,MATCH(5,Products!$BQ$5:$BQ$304,0)),"") -> 0
A43: =IFERROR(INDEX(Products!$B$5:$B$304,MATCH(6,Products!$BO$5:$BO$304,0)),"") -> 0 | B43: =IFERROR(INDEX(Products!$AV$5:$AV$304,MATCH(6,Products!$BO$5:$BO$304,0)),"") -> 0 | C43: =IFERROR(INDEX(Products!$B$5:$B$304,MATCH(6,Products!$BP$5:$BP$304,0)),"") -> 0 | D43: =IFERROR(INDEX(Products!$AW$5:$AW$304,MATCH(6,Products!$BP$5:$BP$304,0)),"") -> 0 | E43: =IFERROR(INDEX(Products!$B$5:$B$304,MATCH(6,Products!$BR$5:$BR$304,0)),"") -> 0 | F43: =IFERROR(INDEX(Products!$AY$5:$AY$304,MATCH(6,Products!$BR$5:$BR$304,0)),"") -> 0 | G43: =IFERROR(INDEX(Products!$B$5:$B$304,MATCH(6,Products!$BQ$5:$BQ$304,0)),"") -> 0 | H43: =IFERROR(INDEX(Products!$BH$5:$BH$304,MATCH(6,Products!$BQ$5:$BQ$304,0)),"") -> 0
A44: =IFERROR(INDEX(Products!$B$5:$B$304,MATCH(7,Products!$BO$5:$BO$304,0)),"") -> 0 | B44: =IFERROR(INDEX(Products!$AV$5:$AV$304,MATCH(7,Products!$BO$5:$BO$304,0)),"") -> 0 | C44: =IFERROR(INDEX(Products!$B$5:$B$304,MATCH(7,Products!$BP$5:$BP$304,0)),"") -> 0 | D44: =IFERROR(INDEX(Products!$AW$5:$AW$304,MATCH(7,Products!$BP$5:$BP$304,0)),"") -> 0 | E44: =IFERROR(INDEX(Products!$B$5:$B$304,MATCH(7,Products!$BR$5:$BR$304,0)),"") -> 0 | F44: =IFERROR(INDEX(Products!$AY$5:$AY$304,MATCH(7,Products!$BR$5:$BR$304,0)),"") -> 0 | G44: =IFERROR(INDEX(Products!$B$5:$B$304,MATCH(7,Products!$BQ$5:$BQ$304,0)),"") -> 0 | H44: =IFERROR(INDEX(Products!$BH$5:$BH$304,MATCH(7,Products!$BQ$5:$BQ$304,0)),"") -> 0
A45: =IFERROR(INDEX(Products!$B$5:$B$304,MATCH(8,Products!$BO$5:$BO$304,0)),"") -> 0 | B45: =IFERROR(INDEX(Products!$AV$5:$AV$304,MATCH(8,Products!$BO$5:$BO$304,0)),"") -> 0 | C45: =IFERROR(INDEX(Products!$B$5:$B$304,MATCH(8,Products!$BP$5:$BP$304,0)),"") -> 0 | D45: =IFERROR(INDEX(Products!$AW$5:$AW$304,MATCH(8,Products!$BP$5:$BP$304,0)),"") -> 0 | E45: =IFERROR(INDEX(Products!$B$5:$B$304,MATCH(8,Products!$BR$5:$BR$304,0)),"") -> 0 | F45: =IFERROR(INDEX(Products!$AY$5:$AY$304,MATCH(8,Products!$BR$5:$BR$304,0)),"") -> 0 | G45: =IFERROR(INDEX(Products!$B$5:$B$304,MATCH(8,Products!$BQ$5:$BQ$304,0)),"") -> 0 | H45: =IFERROR(INDEX(Products!$BH$5:$BH$304,MATCH(8,Products!$BQ$5:$BQ$304,0)),"") -> 0
A47: The four columns rarely agree. The piece that makes the most profit is often not the one that pays best per hour - and the hourly column is the one that decides what you should be making more of.
...

Sheet Products
A1: Product Catalog | BQ1: Novality Store | v1.0.0
A2: Every product, every cost, the price the maths asks for and the margin you actually make.
A3: > Start Here | C3: > Dashboard | E3: > Products | G3: > Materials | I3: > Labour | K3: > Retail Price | M3: > Wholesale | O3: > Sales | Q3: > Help | S3: Give a product a name, a category, a packaging profile and a channel. Cost it on the Materials and Labor tabs (or a specialist tab) and the price appears here.
A4: ID | B4: Product | C4: SKU override | D4: Category | E4: Status | F4: Season | G4: Difficulty | H4: Main channel | I4: Packaging | J4: Shipping option | K4: Item weight (g) | L4: In stock | M4: Your price | N4: Target margin | O4: Made so far | P4: Listed on | Q4: Listing link | R4: Notes | S4: SKU | T4: Materials | U4: Labour | V4: Minutes logged | W4: Difficulty factor | X4: Minutes | Y4: Hours | Z4: Labour at difficulty | AA4: Consumables | AB4: Packaging | AC4: Packaging weight | AD4: Postage costs | AE4: Postage charged | AF4: Weight band | AG4: Postage you absorb | AH4: Cost before overhead | AI4: Fee rate | AJ4: Fees on postage? | AK4: Fixed fees | AL4: Overhead rate | AM4: Overhead in cost | AN4: Target margin used | AO4: Pricing denominator | AP4: Suggested, unrounded | AQ4: Suggested price | AR4: Price used | AS4: Overhead | AT4: Total cost | AU4: Channel fees | AV4: Profit | AW4: Margin | AX4: Markup | AY4: Profit an hour | AZ4: You earn an hour | BA4: Never sell below | BB4: Keystone (x2) | BC4: Wholesale price | BD4: Wholesale profit | BE4: Wholesale margin | BF4: Competitors average | BG4: Versus the market | BH4: Units sold | BI4: Revenue | BJ4: Actual profit | BK4: Actual margin | BL4: Last sold | BM4: Price changed | BN4: Days since review | BO4: Profit rank | BP4: Margin rank | BQ4: Revenue rank | BR4: Hourly rank | BS4: Action
A5: =IF(B5="","",ProductPrefix&TEXT(ROW()-4,"0000")) -> 0 | B5: Willow cable beanie | D5: Crochet & knitting | E5: Active | F5: Autumn | G5: Moderate | H5: Etsy | I5: Standard | J5: First class - Domestic to 250g | K5: 140 | L5: 9 | M5: 78 | O5: 46305 | P5: 45917 | Q5: willowandthread.co/beanie | R5: Costed on the Crochet tab, not the bill of materials. | S5: =IF(B5="","",IF(C5<>"",C5,UPPER(LEFT(IF(D5="","GEN",D5),3))&"-"&TEXT(ROW()-4,"000"))) -> 0 | T5: =IF(B5="","",ROUND(SUMIFS('Material Usage'!$M$5:$M$904,'Material Usage'!$A$5:$A$904,A5)+SUMIFS(Crochet!$AD$5:$AD$84,Crochet!$A$5:$A$84,A5)+SUMIFS(Jewelry!$AF$5:$AF$84,Jewelry!$A$5:$A$84,A5)+SUMIFS(Candles!$AF$5:$AF$84,Candles!$A$5:$A$84,A5)+SUMIFS(Clothing!$AB$5:$AB$84,Clothing!$A$5:$A$84,A5)+SUMIFS(Woodworking!$AC$5:$AC$84,Woodworking!$A$5:$A$84,A5)+SUMIFS(Digital!$X$5:$X$84,Digital!$A$5:$A$84,A5),2)) -> 0 | U5: =IF(B5="","",ROUND(SUMIFS(Labor!$O$5:$O$304,Labor!$A$5:$A$304,A5)+SUMIFS(Crochet!$AG$5:$AG$84,Crochet!$A$5:$A$84,A5)+SUMIFS(Jewelry!$AI$5:$AI$84,Jewelry!$A$5:$A$84,A5)+SUMIFS(Candles!$AI$5:$AI$84,Candles!$A$5:$A$84,A5)+SUMIFS(Clothing!$AE$5:$AE$84,Clothing!$A$5:$A$84,A5)+SUMIFS(Woodworking!$AF$5:$AF$84,Woodworking!$A$5:$A$84,A5)+SUMIFS(Digital!$Z$5:$Z$84,Digital!$A$5:$A$84,A5),2)) -> 0 | V5: =IF(B5="","",ROUND(SUMIFS(Labor!$P$5:$P$304,Labor!$A$5:$A$304,A5)+SUMIFS(Crochet!$AE$5:$AE$84,Crochet!$A$5:$A$84,A5)+SUMIFS(Jewelry!$AG$5:$AG$84,Jewelry!$A$5:$A$84,A5)+SUMIFS(Candles!$AG$5:$AG$84,Candles!$A$5:$A$84,A5)+SUMIFS(Clothing!$AC$5:$AC$84,Clothing!$A$5:$A$84,A5)+SUMIFS(Woodworking!$AD$5:$AD$84,Woodworking!$A$5:$A$84,A5)+SUMIFS(Digital!$Y$5:$Y$84,Digital!$A$5:$A$84,A5),1)) -> 0 | W5: =IF(B5="","",IFERROR(INDEX(DiffTimeFactors,MATCH(G5,DiffNames,0)),1)) -> 0 | X5: =IF(B5="","",ROUND(V5*W5,1)) -> 0 | Y5: =IF(B5="","",ROUND(X5/60,3)) -> 0 | Z5: =IF(B5="","",ROUND(U5*W5,2)) -> 0 | AA5: =IF(B5="","",ROUND(SUMIFS(Labor!$Q$5:$Q$304,Labor!$A$5:$A$304,A5)+SUMIFS(Crochet!$AH$5:$AH$84,Crochet!$A$5:$A$84,A5)+SUMIFS(Jewelry!$AJ$5:$AJ$84,Jewelry!$A$5:$A$84,A5)+SUMIFS(Candles!$AJ$5:$AJ$84,Candles!$A$5:$A$84,A5)+SUMIFS(Clothing!$AF$5:$AF$84,Clothing!$A$5:$A$84,A5)+SUMIFS(Woodworking!$AH$5:$AH$84,Woodworking!$A$5:$A$84,A5)+SUMIFS(Digital!$AA$5:$AA$84,Digital!$A$5:$A$84,A5),2)) -> 0 | AB5: =IF(B5="","",ROUND(IF(I5="Budget",PackBudget,IF(I5="Standard",PackStandard,IF(I5="Gift",PackGift,IF(I5="Premium",PackPremium,DefaultPackaging)))),2)) -> 0 | AC5: =IF(B5="","",IF(I5="Budget",PackWeightBudget,IF(I5="Standard",PackWeightStandard,IF(I5="Gift",PackWeightGift,IF(I5="Premium",PackWeightPremium,0))))) -> 0 | AD5: =IF(B5="","",IFERROR(INDEX(Shipping!$M$5:$M$64,MATCH(J5,Shipping!$L$5:$L$64,0)),DefaultShipping)) -> 0 | AE5: =IF(B5="","",IFERROR(INDEX(Shipping!$F$5:$F$64,MATCH(J5,Shipping!$L$5:$L$64,0)),0)) -> 0 | AF5: =IF(B5="","",IFERROR(INDEX(Shipping!$C$5:$C$64,MATCH(J5,Shipping!$L$5:$L$64,0)),"")) -> 0 | AG5: =IF(B5="","",ROUND(MAX(0,AD5-AE5),2)) -> 0 | AH5: =IF(B5="","",ROUND(T5+Z5+AA5+AB5+AG5,2)) -> 0 | AI5: =IF(B5="","",IFERROR(INDEX(Channels!$S$5:$S$18,MATCH(IF(H5="",DefaultChannel,H5),Channels!$A$5:$A$18,0)),0)) -> 0 | AJ5: =IF(B5="","",IFERROR(INDEX(Channels!$O$5:$O$18,MATCH(IF(H5="",DefaultChannel,H5),Channels!$A$5:$A$18,0)),"No")) -> 0 | AK5: =IF(B5="","",ROUND(IFERROR(INDEX(Channels!$T$5:$T$18,MATCH(IF(H5="",DefaultChannel,H5),Channels!$A$5:$A$18,0)),0)+IF(AJ5="Yes",AE5*AI5,0),4)) -> 0 | AL5: =IF(B5="","",IF(OverheadMethod="Share of revenue",IF(RevenueTargetMonth<=0,0,OverheadMonthly/RevenueTargetMonth),0)) -> 0 | AM5: =IF(B5="","",IF(OverheadMethod="Per hour worked",ROUND(OverheadPerHour*Y5,2),IF(OR(OverheadMethod="Per unit made",OverheadMethod="Per order"),OverheadPerUnit,0))) -> 0 | AN5: =IF(B5="","",IF(N5<>"",N5,TargetRetailMargin)) -> 0 | AO5: =IF(B5="","",1-AN5-AI5-AL5) -> 0 | AP5: =IF(B5="","",IF(AO5<=0,"",(AH5+AM5+AK5)/AO5)) -> 0 | AQ5: =IF(B5="","",IF(AP5="","Check the settings",ROUND(IF(RoundingRule="None",AP5,IF(RoundingRule="Nearest 0.99",MAX(0.99,CEILING(AP5,1)-0.01),IF(RoundingRule="Nearest 0.95",MAX(0.95,CEILING(AP5,1)-0.05),IF(RoundingRule="Nearest 0.50",CEILING(AP5,0.5),IF(RoundingRule="Nearest 1",CEILING(AP5,1),IF(RoundingRule="Nearest 5",CEILING(AP5,5),IF(RoundingRule="Up to whole 1",CEILING(AP5,1),IF(RoundingRule="Up to whole 5",CEILING(AP5,5),ROUND(AP5,2))))))))),2))) -> 0 | AR5: =IF(B5="","",IF(M5<>"",M5,IF(ISNUMBER(AQ5),AQ5,""))) -> 0 | AS5: =IF(B5="","",IF(AR5="","",ROUND(AM5+AR5*AL5,2))) -> 0 | AT5: =IF(B5="","",IF(AR5="","",ROUND(AH5+AS5,2))) -> 0 | AU5: =IF(B5="","",IF(AR5="","",ROUND(AR5*AI5+AK5,2))) -> 0 | AV5: =IF(B5="","",IF(AR5="","",ROUND(AR5-AT5-AU5,2))) -> 0 | AW5: =IF(B5="","",IF(OR(AR5="",AR5=0),"",AV5/AR5)) -> 0 | AX5: =IF(B5="","",IF(OR(AT5="",AT5=0),"",AV5/AT5)) -> 0 | AY5: =IF(B5="","",IF(OR(Y5="",Y5=0,AV5=""),"",ROUND(AV5/Y5,2))) -> 0 | AZ5: =IF(B5="","",IF(OR(Y5="",Y5=0,AV5=""),"",ROUND((AV5+Z5)/Y5,2))) -> 0 | BA5: =IF(B5="","",IF(1-AI5-AL5<=0,"",ROUND((AH5+AM5+AK5)/(1-AI5-AL5),2))) -> 0 | BB5: =IF(B5="","",IF(AT5="","",ROUND(AT5*2,2))) -> 0 | BC5: =IF(B5="","",IF(AR5="","",ROUND(AR5*(1-WholesaleDiscount),2))) -> 0 | BD5: =IF(B5="","",IF(BC5="","",ROUND(BC5-AH5-AM5,2))) -> 0 | BE5: =IF(B5="","",IF(OR(BC5="",BC5=0),"",BD5/BC5)) -> 0 | BF5: =IF(B5="","",IFERROR(ROUND(AVERAGEIFS(Competitors!$F$5:$F$154,Competitors!$A$5:$A$154,A5),2),"")) -> 0 | BG5: =IF(B5="","",IF(OR(BF5="",BF5=0,AR5=""),"",AR5/BF5-1)) -> 0 | BH5: =IF(B5="","",SUMIFS(Sales!$D$5:$D$804,Sales!$C$5:$C$804,A5)) -> 0 | BI5: =IF(B5="","",ROUND(SUMIFS(Sales!$V$5:$V$804,Sales!$C$5:$C$804,A5),2)) -> 0 | BJ5: =IF(B5="","",ROUND(SUMIFS(Sales!$AG$5:$AG$804,Sales!$C$5:$C$804,A5),2)) -> 0 | BK5: =IF(B5="","",IF(OR(BI5="",BI5=0),"",BJ5/BI5)) -> 0 | BL5: =IF(B5="","",IF(SUMPRODUCT(MAX((Sales!$C$5:$C$804=A5)*Sales!$B$5:$B$804))=0,"",SUMPRODUCT(MAX((Sales!$C$5:$C$804=A5)*Sales!$B$5:$B$804)))) -> 0 | BM5: =IF(B5="","",IF(SUMPRODUCT(MAX(('Price History'!$B$5:$B$304=A5)*'Price History'!$A$5:$A$304))=0,IF(P5="","",P5),SUMPRODUCT(MAX(('Price History'!$B$5:$B$304=A5)*'Price History'!$A$5:$A$304)))) -> 0 | BN5: =IF(B5="","",IF(BM5="","",TodayDate-BM5)) -> 0 | BO5: =IF(B5="","",COUNTIFS($AV$5:$AV$304,">"&AV5)+COUNTIFS($AV$5:AV5,AV5)) -> 0 | BP5: =IF(B5="","",COUNTIFS($AW$5:$AW$304,">"&AW5)+COUNTIFS($AW$5:AW5,AW5)) -> 0 | BQ5: =IF(B5="","",COUNTIFS($BI$5:$BI$304,">"&BI5)+COUNTIFS($BI$5:BI5,BI5)) -> 0 | BR5: =IF(B5="","",COUNTIFS($AY$5:$AY$304,">"&AY5)+COUNTIFS($AY$5:AY5,AY5)) -> 0 | BS5: =IF(B5="","",IF(AH5=0,"Add - no costs entered yet",IF(AR5="","Check - no price yet",IF(AV5<0,"Loss - every sale costs you money",IF(AND(AZ5<>"",AZ5<MinimumWage),"Below - pays under minimum wage",IF(AW5<MarginWarning,"Low margin - re-price it",IF(AND(AF5<>"",K5<>"",K5+AC5>AF5),"Check - too heavy for that postage band",IF(AND(BN5<>"",BN5>PriceReviewDays),"Due - price has not been reviewed",IF(AND(BG5<>"",BG5>0.5),"Check - well above the market","OK")))))))) ) -> 0
A6: =IF(B6="","",ProductPrefix&TEXT(ROW()-4,"0000")) -> 0 | B6: Chunky market bag | D6: Bags & leather | E6: Active | F6: All year | G6: Simple | H6: Etsy | I6: Budget | J6: First class - Domestic to 500g | K6: 320 | L6: 6 | M6: 75 | O6: 46297 | P6: 45797 | S6: =IF(B6="","",IF(C6<>"",C6,UPPER(LEFT(IF(D6="","GEN",D6),3))&"-"&TEXT(ROW()-4,"000"))) -> 0 | T6: =IF(B6="","",ROUND(SUMIFS('Material Usage'!$M$5:$M$904,'Material Usage'!$A$5:$A$904,A6)+SUMIFS(Crochet!$AD$5:$AD$84,Crochet!$A$5:$A$84,A6)+SUMIFS(Jewelry!$AF$5:$AF$84,Jewelry!$A$5:$A$84,A6)+SUMIFS(Candles!$AF$5:$AF$84,Candles!$A$5:$A$84,A6)+SUMIFS(Clothing!$AB$5:$AB$84,Clothing!$A$5:$A$84,A6)+SUMIFS(Woodworking!$AC$5:$AC$84,Woodworking!$A$5:$A$84,A6)+SUMIFS(Digital!$X$5:$X$84,Digital!$A$5:$A$84,A6),2)) -> 0 | U6: =IF(B6="","",ROUND(SUMIFS(Labor!$O$5:$O$304,Labor!$A$5:$A$304,A6)+SUMIFS(Crochet!$AG$5:$AG$84,Crochet!$A$5:$A$84,A6)+SUMIFS(Jewelry!$AI$5:$AI$84,Jewelry!$A$5:$A$84,A6)+SUMIFS(Candles!$AI$5:$AI$84,Candles!$A$5:$A$84,A6)+SUMIFS(Clothing!$AE$5:$AE$84,Clothing!$A$5:$A$84,A6)+SUMIFS(Woodworking!$AF$5:$AF$84,Woodworking!$A$5:$A$84,A6)+SUMIFS(Digital!$Z$5:$Z$84,Digital!$A$5:$A$84,A6),2)) -> 0 | V6: =IF(B6="","",ROUND(SUMIFS(Labor!$P$5:$P$304,Labor!$A$5:$A$304,A6)+SUMIFS(Crochet!$AE$5:$AE$84,Crochet!$A$5:$A$84,A6)+SUMIFS(Jewelry!$AG$5:$AG$84,Jewelry!$A$5:$A$84,A6)+SUMIFS(Candles!$AG$5:$AG$84,Candles!$A$5:$A$84,A6)+SUMIFS(Clothing!$AC$5:$AC$84,Clothing!$A$5:$A$84,A6)+SUMIFS(Woodworking!$AD$5:$AD$84,Woodworking!$A$5:$A$84,A6)+SUMIFS(Digital!$Y$5:$Y$84,Digital!$A$5:$A$84,A6),1)) -> 0 | W6: =IF(B6="","",IFERROR(INDEX(DiffTimeFactors,MATCH(G6,DiffNames,0)),1)) -> 0 | X6: =IF(B6="","",ROUND(V6*W6,1)) -> 0 | Y6: =IF(B6="","",ROUND(X6/60,3)) -> 0 | Z6: =IF(B6="","",ROUND(U6*W6,2)) -> 0 | AA6: =IF(B6="","",ROUND(SUMIFS(Labor!$Q$5:$Q$304,Labor!$A$5:$A$304,A6)+SUMIFS(Crochet!$AH$5:$AH$84,Crochet!$A$5:$A$84,A6)+SUMIFS(Jewelry!$AJ$5:$AJ$84,Jewelry!$A$5:$A$84,A6)+SUMIFS(Candles!$AJ$5:$AJ$84,Candles!$A$5:$A$84,A6)+SUMIFS(Clothing!$AF$5:$AF$84,Clothing!$A$5:$A$84,A6)+SUMIFS(Woodworking!$AH$5:$AH$84,Woodworking!$A$5:$A$84,A6)+SUMIFS(Digital!$AA$5:$AA$84,Digital!$A$5:$A$84,A6),2)) -> 0 | AB6: =IF(B6="","",ROUND(IF(I6="Budget",PackBudget,IF(I6="Standard",PackStandard,IF(I6="Gift",PackGift,IF(I6="Premium",PackPremium,DefaultPackaging)))),2)) -> 0 | AC6: =IF(B6="","",IF(I6="Budget",PackWeightBudget,IF(I6="Standard",PackWeightStandard,IF(I6="Gift",PackWeightGift,IF(I6="Premium",PackWeightPremium,0))))) -> 0 | AD6: =IF(B6="","",IFERROR(INDEX(Shipping!$M$5:$M$64,MATCH(J6,Shipping!$L$5:$L$64,0)),DefaultShipping)) -> 0 | AE6: =IF(B6="","",IFERROR(INDEX(Shipping!$F$5:$F$64,MATCH(J6,Shipping!$L$5:$L$64,0)),0)) -> 0 | AF6: =IF(B6="","",IFERROR(INDEX(Shipping!$C$5:$C$64,MATCH(J6,Shipping!$L$5:$L$64,0)),"")) -> 0 | AG6: =IF(B6="","",ROUND(MAX(0,AD6-AE6),2)) -> 0 | AH6: =IF(B6="","",ROUND(T6+Z6+AA6+AB6+AG6,2)) -> 0 | AI6: =IF(B6="","",IFERROR(INDEX(Channels!$S$5:$S$18,MATCH(IF(H6="",DefaultChannel,H6),Channels!$A$5:$A$18,0)),0)) -> 0 | AJ6: =IF(B6="","",IFERROR(INDEX(Channels!$O$5:$O$18,MATCH(IF(H6="",DefaultChannel,H6),Channels!$A$5:$A$18,0)),"No")) -> 0 | AK6: =IF(B6="","",ROUND(IFERROR(INDEX(Channels!$T$5:$T$18,MATCH(IF(H6="",DefaultChannel,H6),Channels!$A$5:$A$18,0)),0)+IF(AJ6="Yes",AE6*AI6,0),4)) -> 0 | AL6: =IF(B6="","",IF(OverheadMethod="Share of revenue",IF(RevenueTargetMonth<=0,0,OverheadMonthly/RevenueTargetMonth),0)) -> 0 | AM6: =IF(B6="","",IF(OverheadMethod="Per hour worked",ROUND(OverheadPerHour*Y6,2),IF(OR(OverheadMethod="Per unit made",OverheadMethod="Per order"),OverheadPerUnit,0))) -> 0 | AN6: =IF(B6="","",IF(N6<>"",N6,TargetRetailMargin)) -> 0 | AO6: =IF(B6="","",1-AN6-AI6-AL6) -> 0 | AP6: =IF(B6="","",IF(AO6<=0,"",(AH6+AM6+AK6)/AO6)) -> 0 | AQ6: =IF(B6="","",IF(AP6="","Check the settings",ROUND(IF(RoundingRule="None",AP6,IF(RoundingRule="Nearest 0.99",MAX(0.99,CEILING(AP6,1)-0.01),IF(RoundingRule="Nearest 0.95",MAX(0.95,CEILING(AP6,1)-0.05),IF(RoundingRule="Nearest 0.50",CEILING(AP6,0.5),IF(RoundingRule="Nearest 1",CEILING(AP6,1),IF(RoundingRule="Nearest 5",CEILING(AP6,5),IF(RoundingRule="Up to whole 1",CEILING(AP6,1),IF(RoundingRule="Up to whole 5",CEILING(AP6,5),ROUND(AP6,2))))))))),2))) -> 0 | AR6: =IF(B6="","",IF(M6<>"",M6,IF(ISNUMBER(AQ6),AQ6,""))) -> 0 | AS6: =IF(B6="","",IF(AR6="","",ROUND(AM6+AR6*AL6,2))) -> 0 | AT6: =IF(B6="","",IF(AR6="","",ROUND(AH6+AS6,2))) -> 0 | AU6: =IF(B6="","",IF(AR6="","",ROUND(AR6*AI6+AK6,2))) -> 0 | AV6: =IF(B6="","",IF(AR6="","",ROUND(AR6-AT6-AU6,2))) -> 0 | AW6: =IF(B6="","",IF(OR(AR6="",AR6=0),"",AV6/AR6)) -> 0 | AX6: =IF(B6="","",IF(OR(AT6="",AT6=0),"",AV6/AT6)) -> 0 | AY6: =IF(B6="","",IF(OR(Y6="",Y6=0,AV6=""),"",ROUND(AV6/Y6,2))) -> 0 | AZ6: =IF(B6="","",IF(OR(Y6="",Y6=0,AV6=""),"",ROUND((AV6+Z6)/Y6,2))) -> 0 | BA6: =IF(B6="","",IF(1-AI6-AL6<=0,"",ROUND((AH6+AM6+AK6)/(1-AI6-AL6),2))) -> 0 | BB6: =IF(B6="","",IF(AT6="","",ROUND(AT6*2,2))) -> 0 | BC6: =IF(B6="","",IF(AR6="","",ROUND(AR6*(1-WholesaleDiscount),2))) -> 0 | BD6: =IF(B6="","",IF(BC6="","",ROUND(BC6-AH6-AM6,2))) -> 0 | BE6: =IF(B6="","",IF(OR(BC6="",BC6=0),"",BD6/BC6)) -> 0 | BF6: =IF(B6="","",IFERROR(ROUND(AVERAGEIFS(Competitors!$F$5:$F$154,Competitors!$A$5:$A$154,A6),2),"")) -> 0 | BG6: =IF(B6="","",IF(OR(BF6="",BF6=0,AR6=""),"",AR6/BF6-1)) -> 0 | BH6: =IF(B6="","",SUMIFS(Sales!$D$5:$D$804,Sales!$C$5:$C$804,A6)) -> 0 | BI6: =IF(B6="","",ROUND(SUMIFS(Sales!$V$5:$V$804,Sales!$C$5:$C$804,A6),2)) -> 0 | BJ6: =IF(B6="","",ROUND(SUMIFS(Sales!$AG$5:$AG$804,Sales!$C$5:$C$804,A6),2)) -> 0 | BK6: =IF(B6="","",IF(OR(BI6="",BI6=0),"",BJ6/BI6)) -> 0 | BL6: =IF(B6="","",IF(SUMPRODUCT(MAX((Sales!$C$5:$C$804=A6)*Sales!$B$5:$B$804))=0,"",SUMPRODUCT(MAX((Sales!$C$5:$C$804=A6)*Sales!$B$5:$B$804)))) -> 0 | BM6: =IF(B6="","",IF(SUMPRODUCT(MAX(('Price History'!$B$5:$B$304=A6)*'Price History'!$A$5:$A$304))=0,IF(P6="","",P6),SUMPRODUCT(MAX(('Price History'!$B$5:$B$304=A6)*'Price History'!$A$5:$A$304)))) -> 0 | BN6: =IF(B6="","",IF(BM6="","",TodayDate-BM6)) -> 0 | BO6: =IF(B6="","",COUNTIFS($AV$5:$AV$304,">"&AV6)+COUNTIFS($AV$5:AV6,AV6)) -> 0 | BP6: =IF(B6="","",COUNTIFS($AW$5:$AW$304,">"&AW6)+COUNTIFS($AW$5:AW6,AW6)) -> 0 | BQ6: =IF(B6="","",COUNTIFS($BI$5:$BI$304,">"&BI6)+COUNTIFS($BI$5:BI6,BI6)) -> 0 | BR6: =IF(B6="","",COUNTIFS($AY$5:$AY$304,">"&AY6)+COUNTIFS($AY$5:AY6,AY6)) -> 0 | BS6: =IF(B6="","",IF(AH6=0,"Add - no costs entered yet",IF(AR6="","Check - no price yet",IF(AV6<0,"Loss - every sale costs you money",IF(AND(AZ6<>"",AZ6<MinimumWage),"Below - pays under minimum wage",IF(AW6<MarginWarning,"Low margin - re-price it",IF(AND(AF6<>"",K6<>"",K6+AC6>AF6),"Check - too heavy for that postage band",IF(AND(BN6<>"",BN6>PriceReviewDays),"Due - price has not been reviewed",IF(AND(BG6<>"",BG6>0.5),"Check - well above the market","OK")))))))) ) -> 0
A7: =IF(B7="","",ProductPrefix&TEXT(ROW()-4,"0000")) -> 0 | B7: Woodland fox amigurumi | D7: Toys & amigurumi | E7: Active | F7: Christmas | G7: Moderate | H7: Etsy | I7: Gift | J7: First class - Domestic to 500g | K7: 180 | L7: 4 | M7: 78 | O7: 46310 | P7: 46017 | S7: =IF(B7="","",IF(C7<>"",C7,UPPER(LEFT(IF(D7="","GEN",D7),3))&"-"&TEXT(ROW()-4,"000"))) -> 0 | T7: =IF(B7="","",ROUND(SUMIFS('Material Usage'!$M$5:$M$904,'Material Usage'!$A$5:$A$904,A7)+SUMIFS(Crochet!$AD$5:$AD$84,Crochet!$A$5:$A$84,A7)+SUMIFS(Jewelry!$AF$5:$AF$84,Jewelry!$A$5:$A$84,A7)+SUMIFS(Candles!$AF$5:$AF$84,Candles!$A$5:$A$84,A7)+SUMIFS(Clothing!$AB$5:$AB$84,Clothing!$A$5:$A$84,A7)+SUMIFS(Woodworking!$AC$5:$AC$84,Woodworking!$A$5:$A$84,A7)+SUMIFS(Digital!$X$5:$X$84,Digital!$A$5:$A$84,A7),2)) -> 0 | U7: =IF(B7="","",ROUND(SUMIFS(Labor!$O$5:$O$304,Labor!$A$5:$A$304,A7)+SUMIFS(Crochet!$AG$5:$AG$84,Crochet!$A$5:$A$84,A7)+SUMIFS(Jewelry!$AI$5:$AI$84,Jewelry!$A$5:$A$84,A7)+SUMIFS(Candles!$AI$5:$AI$84,Candles!$A$5:$A$84,A7)+SUMIFS(Clothing!$AE$5:$AE$84,Clothing!$A$5:$A$84,A7)+SUMIFS(Woodworking!$AF$5:$AF$84,Woodworking!$A$5:$A$84,A7)+SUMIFS(Digital!$Z$5:$Z$84,Digital!$A$5:$A$84,A7),2)) -> 0 | V7: =IF(B7="","",ROUND(SUMIFS(Labor!$P$5:$P$304,Labor!$A$5:$A$304,A7)+SUMIFS(Crochet!$AE$5:$AE$84,Crochet!$A$5:$A$84,A7)+SUMIFS(Jewelry!$AG$5:$AG$84,Jewelry!$A$5:$A$84,A7)+SUMIFS(Candles!$AG$5:$AG$84,Candles!$A$5:$A$84,A7)+SUMIFS(Clothing!$AC$5:$AC$84,Clothing!$A$5:$A$84,A7)+SUMIFS(Woodworking!$AD$5:$AD$84,Woodworking!$A$5:$A$84,A7)+SUMIFS(Digital!$Y$5:$Y$84,Digital!$A$5:$A$84,A7),1)) -> 0 | W7: =IF(B7="","",IFERROR(INDEX(DiffTimeFactors,MATCH(G7,DiffNames,0)),1)) -> 0 | X7: =IF(B7="","",ROUND(V7*W7,1)) -> 0 | Y7: =IF(B7="","",ROUND(X7/60,3)) -> 0 | Z7: =IF(B7="","",ROUND(U7*W7,2)) -> 0 | AA7: =IF(B7="","",ROUND(SUMIFS(Labor!$Q$5:$Q$304,Labor!$A$5:$A$304,A7)+SUMIFS(Crochet!$AH$5:$AH$84,Crochet!$A$5:$A$84,A7)+SUMIFS(Jewelry!$AJ$5:$AJ$84,Jewelry!$A$5:$A$84,A7)+SUMIFS(Candles!$AJ$5:$AJ$84,Candles!$A$5:$A$84,A7)+SUMIFS(Clothing!$AF$5:$AF$84,Clothing!$A$5:$A$84,A7)+SUMIFS(Woodworking!$AH$5:$AH$84,Woodworking!$A$5:$A$84,A7)+SUMIFS(Digital!$AA$5:$AA$84,Digital!$A$5:$A$84,A7),2)) -> 0 | AB7: =IF(B7="","",ROUND(IF(I7="Budget",PackBudget,IF(I7="Standard",PackStandard,IF(I7="Gift",PackGift,IF(I7="Premium",PackPremium,DefaultPackaging)))),2)) -> 0 | AC7: =IF(B7="","",IF(I7="Budget",PackWeightBudget,IF(I7="Standard",PackWeightStandard,IF(I7="Gift",PackWeightGift,IF(I7="Premium",PackWeightPremium,0))))) -> 0 | AD7: =IF(B7="","",IFERROR(INDEX(Shipping!$M$5:$M$64,MATCH(J7,Shipping!$L$5:$L$64,0)),DefaultShipping)) -> 0 | AE7: =IF(B7="","",IFERROR(INDEX(Shipping!$F$5:$F$64,MATCH(J7,Shipping!$L$5:$L$64,0)),0)) -> 0 | AF7: =IF(B7="","",IFERROR(INDEX(Shipping!$C$5:$C$64,MATCH(J7,Shipping!$L$5:$L$64,0)),"")) -> 0 | AG7: =IF(B7="","",ROUND(MAX(0,AD7-AE7),2)) -> 0 | AH7: =IF(B7="","",ROUND(T7+Z7+AA7+AB7+AG7,2)) -> 0 | AI7: =IF(B7="","",IFERROR(INDEX(Channels!$S$5:$S$18,MATCH(IF(H7="",DefaultChannel,H7),Channels!$A$5:$A$18,0)),0)) -> 0 | AJ7: =IF(B7="","",IFERROR(INDEX(Channels!$O$5:$O$18,MATCH(IF(H7="",DefaultChannel,H7),Channels!$A$5:$A$18,0)),"No")) -> 0 | AK7: =IF(B7="","",ROUND(IFERROR(INDEX(Channels!$T$5:$T$18,MATCH(IF(H7="",DefaultChannel,H7),Channels!$A$5:$A$18,0)),0)+IF(AJ7="Yes",AE7*AI7,0),4)) -> 0 | AL7: =IF(B7="","",IF(OverheadMethod="Share of revenue",IF(RevenueTargetMonth<=0,0,OverheadMonthly/RevenueTargetMonth),0)) -> 0 | AM7: =IF(B7="","",IF(OverheadMethod="Per hour worked",ROUND(OverheadPerHour*Y7,2),IF(OR(OverheadMethod="Per unit made",OverheadMethod="Per order"),OverheadPerUnit,0))) -> 0 | AN7: =IF(B7="","",IF(N7<>"",N7,TargetRetailMargin)) -> 0 | AO7: =IF(B7="","",1-AN7-AI7-AL7) -> 0 | AP7: =IF(B7="","",IF(AO7<=0,"",(AH7+AM7+AK7)/AO7)) -> 0 | AQ7: =IF(B7="","",IF(AP7="","Check the settings",ROUND(IF(RoundingRule="None",AP7,IF(RoundingRule="Nearest 0.99",MAX(0.99,CEILING(AP7,1)-0.01),IF(RoundingRule="Nearest 0.95",MAX(0.95,CEILING(AP7,1)-0.05),IF(RoundingRule="Nearest 0.50",CEILING(AP7,0.5),IF(RoundingRule="Nearest 1",CEILING(AP7,1),IF(RoundingRule="Nearest 5",CEILING(AP7,5),IF(RoundingRule="Up to whole 1",CEILING(AP7,1),IF(RoundingRule="Up to whole 5",CEILING(AP7,5),ROUND(AP7,2))))))))),2))) -> 0 | AR7: =IF(B7="","",IF(M7<>"",M7,IF(ISNUMBER(AQ7),AQ7,""))) -> 0 | AS7: =IF(B7="","",IF(AR7="","",ROUND(AM7+AR7*AL7,2))) -> 0 | AT7: =IF(B7="","",IF(AR7="","",ROUND(AH7+AS7,2))) -> 0 | AU7: =IF(B7="","",IF(AR7="","",ROUND(AR7*AI7+AK7,2))) -> 0 | AV7: =IF(B7="","",IF(AR7="","",ROUND(AR7-AT7-AU7,2))) -> 0 | AW7: =IF(B7="","",IF(OR(AR7="",AR7=0),"",AV7/AR7)) -> 0 | AX7: =IF(B7="","",IF(OR(AT7="",AT7=0),"",AV7/AT7)) -> 0 | AY7: =IF(B7="","",IF(OR(Y7="",Y7=0,AV7=""),"",ROUND(AV7/Y7,2))) -> 0 | AZ7: =IF(B7="","",IF(OR(Y7="",Y7=0,AV7=""),"",ROUND((AV7+Z7)/Y7,2))) -> 0 | BA7: =IF(B7="","",IF(1-AI7-AL7<=0,"",ROUND((AH7+AM7+AK7)/(1-AI7-AL7),2))) -> 0 | BB7: =IF(B7="","",IF(AT7="","",ROUND(AT7*2,2))) -> 0 | BC7: =IF(B7="","",IF(AR7="","",ROUND(AR7*(1-WholesaleDiscount),2))) -> 0 | BD7: =IF(B7="","",IF(BC7="","",ROUND(BC7-AH7-AM7,2))) -> 0 | BE7: =IF(B7="","",IF(OR(BC7="",BC7=0),"",BD7/BC7)) -> 0 | BF7: =IF(B7="","",IFERROR(ROUND(AVERAGEIFS(Competitors!$F$5:$F$154,Competitors!$A$5:$A$154,A7),2),"")) -> 0 | BG7: =IF(B7="","",IF(OR(BF7="",BF7=0,AR7=""),"",AR7/BF7-1)) -> 0 | BH7: =IF(B7="","",SUMIFS(Sales!$D$5:$D$804,Sales!$C$5:$C$804,A7)) -> 0 | BI7: =IF(B7="","",ROUND(SUMIFS(Sales!$V$5:$V$804,Sales!$C$5:$C$804,A7),2)) -> 0 | BJ7: =IF(B7="","",ROUND(SUMIFS(Sales!$AG$5:$AG$804,Sales!$C$5:$C$804,A7),2)) -> 0 | BK7: =IF(B7="","",IF(OR(BI7="",BI7=0),"",BJ7/BI7)) -> 0 | BL7: =IF(B7="","",IF(SUMPRODUCT(MAX((Sales!$C$5:$C$804=A7)*Sales!$B$5:$B$804))=0,"",SUMPRODUCT(MAX((Sales!$C$5:$C$804=A7)*Sales!$B$5:$B$804)))) -> 0 | BM7: =IF(B7="","",IF(SUMPRODUCT(MAX(('Price History'!$B$5:$B$304=A7)*'Price History'!$A$5:$A$304))=0,IF(P7="","",P7),SUMPRODUCT(MAX(('Price History'!$B$5:$B$304=A7)*'Price History'!$A$5:$A$304)))) -> 0 | BN7: =IF(B7="","",IF(BM7="","",TodayDate-BM7)) -> 0 | BO7: =IF(B7="","",COUNTIFS($AV$5:$AV$304,">"&AV7)+COUNTIFS($AV$5:AV7,AV7)) -> 0 | BP7: =IF(B7="","",COUNTIFS($AW$5:$AW$304,">"&AW7)+COUNTIFS($AW$5:AW7,AW7)) -> 0 | BQ7: =IF(B7="","",COUNTIFS($BI$5:$BI$304,">"&BI7)+COUNTIFS($BI$5:BI7,BI7)) -> 0 | BR7: =IF(B7="","",COUNTIFS($AY$5:$AY$304,">"&AY7)+COUNTIFS($AY$5:AY7,AY7)) -> 0 | BS7: =IF(B7="","",IF(AH7=0,"Add - no costs entered yet",IF(AR7="","Check - no price yet",IF(AV7<0,"Loss - every sale costs you money",IF(AND(AZ7<>"",AZ7<MinimumWage),"Below - pays under minimum wage",IF(AW7<MarginWarning,"Low margin - re-price it",IF(AND(AF7<>"",K7<>"",K7+AC7>AF7),"Check - too heavy for that postage band",IF(AND(BN7<>"",BN7>PriceReviewDays),"Due - price has not been reviewed",IF(AND(BG7<>"",BG7>0.5),"Check - well above the market","OK")))))))) ) -> 0
A8: =IF(B8="","",ProductPrefix&TEXT(ROW()-4,"0000")) -> 0 | B8: Hammered silver stacking ring | D8: Jewelry | E8: Active | F8: All year | G8: Moderate | H8: Etsy | I8: Gift | J8: First class - Domestic to 100g | K8: 25 | L8: 14 | M8: 58 | O8: 46308 | P8: 45697 | S8: =IF(B8="","",IF(C8<>"",C8,UPPER(LEFT(IF(D8="","GEN",D8),3))&"-"&TEXT(ROW()-4,"000"))) -> 0 | T8: =IF(B8="","",ROUND(SUMIFS('Material Usage'!$M$5:$M$904,'Material Usage'!$A$5:$A$904,A8)+SUMIFS(Crochet!$AD$5:$AD$84,Crochet!$A$5:$A$84,A8)+SUMIFS(Jewelry!$AF$5:$AF$84,Jewelry!$A$5:$A$84,A8)+SUMIFS(Candles!$AF$5:$AF$84,Candles!$A$5:$A$84,A8)+SUMIFS(Clothing!$AB$5:$AB$84,Clothing!$A$5:$A$84,A8)+SUMIFS(Woodworking!$AC$5:$AC$84,Woodworking!$A$5:$A$84,A8)+SUMIFS(Digital!$X$5:$X$84,Digital!$A$5:$A$84,A8),2)) -> 0 | U8: =IF(B8="","",ROUND(SUMIFS(Labor!$O$5:$O$304,Labor!$A$5:$A$304,A8)+SUMIFS(Crochet!$AG$5:$AG$84,Crochet!$A$5:$A$84,A8)+SUMIFS(Jewelry!$AI$5:$AI$84,Jewelry!$A$5:$A$84,A8)+SUMIFS(Candles!$AI$5:$AI$84,Candles!$A$5:$A$84,A8)+SUMIFS(Clothing!$AE$5:$AE$84,Clothing!$A$5:$A$84,A8)+SUMIFS(Woodworking!$AF$5:$AF$84,Woodworking!$A$5:$A$84,A8)+SUMIFS(Digital!$Z$5:$Z$84,Digital!$A$5:$A$84,A8),2)) -> 0 | V8: =IF(B8="","",ROUND(SUMIFS(Labor!$P$5:$P$304,Labor!$A$5:$A$304,A8)+SUMIFS(Crochet!$AE$5:$AE$84,Crochet!$A$5:$A$84,A8)+SUMIFS(Jewelry!$AG$5:$AG$84,Jewelry!$A$5:$A$84,A8)+SUMIFS(Candles!$AG$5:$AG$84,Candles!$A$5:$A$84,A8)+SUMIFS(Clothing!$AC$5:$AC$84,Clothing!$A$5:$A$84,A8)+SUMIFS(Woodworking!$AD$5:$AD$84,Woodworking!$A$5:$A$84,A8)+SUMIFS(Digital!$Y$5:$Y$84,Digital!$A$5:$A$84,A8),1)) -> 0 | W8: =IF(B8="","",IFERROR(INDEX(DiffTimeFactors,MATCH(G8,DiffNames,0)),1)) -> 0 | X8: =IF(B8="","",ROUND(V8*W8,1)) -> 0 | Y8: =IF(B8="","",ROUND(X8/60,3)) -> 0 | Z8: =IF(B8="","",ROUND(U8*W8,2)) -> 0 | AA8: =IF(B8="","",ROUND(SUMIFS(Labor!$Q$5:$Q$304,Labor!$A$5:$A$304,A8)+SUMIFS(Crochet!$AH$5:$AH$84,Crochet!$A$5:$A$84,A8)+SUMIFS(Jewelry!$AJ$5:$AJ$84,Jewelry!$A$5:$A$84,A8)+SUMIFS(Candles!$AJ$5:$AJ$84,Candles!$A$5:$A$84,A8)+SUMIFS(Clothing!$AF$5:$AF$84,Clothing!$A$5:$A$84,A8)+SUMIFS(Woodworking!$AH$5:$AH$84,Woodworking!$A$5:$A$84,A8)+SUMIFS(Digital!$AA$5:$AA$84,Digital!$A$5:$A$84,A8),2)) -> 0 | AB8: =IF(B8="","",ROUND(IF(I8="Budget",PackBudget,IF(I8="Standard",PackStandard,IF(I8="Gift",PackGift,IF(I8="Premium",PackPremium,DefaultPackaging)))),2)) -> 0 | AC8: =IF(B8="","",IF(I8="Budget",PackWeightBudget,IF(I8="Standard",PackWeightStandard,IF(I8="Gift",PackWeightGift,IF(I8="Premium",PackWeightPremium,0))))) -> 0 | AD8: =IF(B8="","",IFERROR(INDEX(Shipping!$M$5:$M$64,MATCH(J8,Shipping!$L$5:$L$64,0)),DefaultShipping)) -> 0 | AE8: =IF(B8="","",IFERROR(INDEX(Shipping!$F$5:$F$64,MATCH(J8,Shipping!$L$5:$L$64,0)),0)) -> 0 | AF8: =IF(B8="","",IFERROR(INDEX(Shipping!$C$5:$C$64,MATCH(J8,Shipping!$L$5:$L$64,0)),"")) -> 0 | AG8: =IF(B8="","",ROUND(MAX(0,AD8-AE8),2)) -> 0 | AH8: =IF(B8="","",ROUND(T8+Z8+AA8+AB8+AG8,2)) -> 0 | AI8: =IF(B8="","",IFERROR(INDEX(Channels!$S$5:$S$18,MATCH(IF(H8="",DefaultChannel,H8),Channels!$A$5:$A$18,0)),0)) -> 0 | AJ8: =IF(B8="","",IFERROR(INDEX(Channels!$O$5:$O$18,MATCH(IF(H8="",DefaultChannel,H8),Channels!$A$5:$A$18,0)),"No")) -> 0 | AK8: =IF(B8="","",ROUND(IFERROR(INDEX(Channels!$T$5:$T$18,MATCH(IF(H8="",DefaultChannel,H8),Channels!$A$5:$A$18,0)),0)+IF(AJ8="Yes",AE8*AI8,0),4)) -> 0 | AL8: =IF(B8="","",IF(OverheadMethod="Share of revenue",IF(RevenueTargetMonth<=0,0,OverheadMonthly/RevenueTargetMonth),0)) -> 0 | AM8: =IF(B8="","",IF(OverheadMethod="Per hour worked",ROUND(OverheadPerHour*Y8,2),IF(OR(OverheadMethod="Per unit made",OverheadMethod="Per order"),OverheadPerUnit,0))) -> 0 | AN8: =IF(B8="","",IF(N8<>"",N8,TargetRetailMargin)) -> 0 | AO8: =IF(B8="","",1-AN8-AI8-AL8) -> 0 | AP8: =IF(B8="","",IF(AO8<=0,"",(AH8+AM8+AK8)/AO8)) -> 0 | AQ8: =IF(B8="","",IF(AP8="","Check the settings",ROUND(IF(RoundingRule="None",AP8,IF(RoundingRule="Nearest 0.99",MAX(0.99,CEILING(AP8,1)-0.01),IF(RoundingRule="Nearest 0.95",MAX(0.95,CEILING(AP8,1)-0.05),IF(RoundingRule="Nearest 0.50",CEILING(AP8,0.5),IF(RoundingRule="Nearest 1",CEILING(AP8,1),IF(RoundingRule="Nearest 5",CEILING(AP8,5),IF(RoundingRule="Up to whole 1",CEILING(AP8,1),IF(RoundingRule="Up to whole 5",CEILING(AP8,5),ROUND(AP8,2))))))))),2))) -> 0 | AR8: =IF(B8="","",IF(M8<>"",M8,IF(ISNUMBER(AQ8),AQ8,""))) -> 0 | AS8: =IF(B8="","",IF(AR8="","",ROUND(AM8+AR8*AL8,2))) -> 0 | AT8: =IF(B8="","",IF(AR8="","",ROUND(AH8+AS8,2))) -> 0 | AU8: =IF(B8="","",IF(AR8="","",ROUND(AR8*AI8+AK8,2))) -> 0 | AV8: =IF(B8="","",IF(AR8="","",ROUND(AR8-AT8-AU8,2))) -> 0 | AW8: =IF(B8="","",IF(OR(AR8="",AR8=0),"",AV8/AR8)) -> 0 | AX8: =IF(B8="","",IF(OR(AT8="",AT8=0),"",AV8/AT8)) -> 0 | AY8: =IF(B8="","",IF(OR(Y8="",Y8=0,AV8=""),"",ROUND(AV8/Y8,2))) -> 0 | AZ8: =IF(B8="","",IF(OR(Y8="",Y8=0,AV8=""),"",ROUND((AV8+Z8)/Y8,2))) -> 0 | BA8: =IF(B8="","",IF(1-AI8-AL8<=0,"",ROUND((AH8+AM8+AK8)/(1-AI8-AL8),2))) -> 0 | BB8: =IF(B8="","",IF(AT8="","",ROUND(AT8*2,2))) -> 0 | BC8: =IF(B8="","",IF(AR8="","",ROUND(AR8*(1-WholesaleDiscount),2))) -> 0 | BD8: =IF(B8="","",IF(BC8="","",ROUND(BC8-AH8-AM8,2))) -> 0 | BE8: =IF(B8="","",IF(OR(BC8="",BC8=0),"",BD8/BC8)) -> 0 | BF8: =IF(B8="","",IFERROR(ROUND(AVERAGEIFS(Competitors!$F$5:$F$154,Competitors!$A$5:$A$154,A8),2),"")) -> 0 | BG8: =IF(B8="","",IF(OR(BF8="",BF8=0,AR8=""),"",AR8/BF8-1)) -> 0 | BH8: =IF(B8="","",SUMIFS(Sales!$D$5:$D$804,Sales!$C$5:$C$804,A8)) -> 0 | BI8: =IF(B8="","",ROUND(SUMIFS(Sales!$V$5:$V$804,Sales!$C$5:$C$804,A8),2)) -> 0 | BJ8: =IF(B8="","",ROUND(SUMIFS(Sales!$AG$5:$AG$804,Sales!$C$5:$C$804,A8),2)) -> 0 | BK8: =IF(B8="","",IF(OR(BI8="",BI8=0),"",BJ8/BI8)) -> 0 | BL8: =IF(B8="","",IF(SUMPRODUCT(MAX((Sales!$C$5:$C$804=A8)*Sales!$B$5:$B$804))=0,"",SUMPRODUCT(MAX((Sales!$C$5:$C$804=A8)*Sales!$B$5:$B$804)))) -> 0 | BM8: =IF(B8="","",IF(SUMPRODUCT(MAX(('Price History'!$B$5:$B$304=A8)*'Price History'!$A$5:$A$304))=0,IF(P8="","",P8),SUMPRODUCT(MAX(('Price History'!$B$5:$B$304=A8)*'Price History'!$A$5:$A$304)))) -> 0 | BN8: =IF(B8="","",IF(BM8="","",TodayDate-BM8)) -> 0 | BO8: =IF(B8="","",COUNTIFS($AV$5:$AV$304,">"&AV8)+COUNTIFS($AV$5:AV8,AV8)) -> 0 | BP8: =IF(B8="","",COUNTIFS($AW$5:$AW$304,">"&AW8)+COUNTIFS($AW$5:AW8,AW8)) -> 0 | BQ8: =IF(B8="","",COUNTIFS($BI$5:$BI$304,">"&BI8)+COUNTIFS($BI$5:BI8,BI8)) -> 0 | BR8: =IF(B8="","",COUNTIFS($AY$5:$AY$304,">"&AY8)+COUNTIFS($AY$5:AY8,AY8)) -> 0 | BS8: =IF(B8="","",IF(AH8=0,"Add - no costs entered yet",IF(AR8="","Check - no price yet",IF(AV8<0,"Loss - every sale costs you money",IF(AND(AZ8<>"",AZ8<MinimumWage),"Below - pays under minimum wage",IF(AW8<MarginWarning,"Low margin - re-price it",IF(AND(AF8<>"",K8<>"",K8+AC8>AF8),"Check - too heavy for that postage band",IF(AND(BN8<>"",BN8>PriceReviewDays),"Due - price has not been reviewed",IF(AND(BG8<>"",BG8>0.5),"Check - well above the market","OK")))))))) ) -> 0
A9: =IF(B9="","",ProductPrefix&TEXT(ROW()-4,"0000")) -> 0 | B9: Sea glass pendant | D9: Jewelry | E9: Active | F9: Summer | G9: Simple | H9: Etsy | I9: Gift | J9: First class - Domestic to 100g | K9: 30 | L9: 11 | M9: 52 | O9: 46302 | P9: 45897 | S9: =IF(B9="","",IF(C9<>"",C9,UPPER(LEFT(IF(D9="","GEN",D9),3))&"-"&TEXT(ROW()-4,"000"))) -> 0 | T9: =IF(B9="","",ROUND(SUMIFS('Material Usage'!$M$5:$M$904,'Material Usage'!$A$5:$A$904,A9)+SUMIFS(Crochet!$AD$5:$AD$84,Crochet!$A$5:$A$84,A9)+SUMIFS(Jewelry!$AF$5:$AF$84,Jewelry!$A$5:$A$84,A9)+SUMIFS(Candles!$AF$5:$AF$84,Candles!$A$5:$A$84,A9)+SUMIFS(Clothing!$AB$5:$AB$84,Clothing!$A$5:$A$84,A9)+SUMIFS(Woodworking!$AC$5:$AC$84,Woodworking!$A$5:$A$84,A9)+SUMIFS(Digital!$X$5:$X$84,Digital!$A$5:$A$84,A9),2)) -> 0 | U9: =IF(B9="","",ROUND(SUMIFS(Labor!$O$5:$O$304,Labor!$A$5:$A$304,A9)+SUMIFS(Crochet!$AG$5:$AG$84,Crochet!$A$5:$A$84,A9)+SUMIFS(Jewelry!$AI$5:$AI$84,Jewelry!$A$5:$A$84,A9)+SUMIFS(Candles!$AI$5:$AI$84,Candles!$A$5:$A$84,A9)+SUMIFS(Clothing!$AE$5:$AE$84,Clothing!$A$5:$A$84,A9)+SUMIFS(Woodworking!$AF$5:$AF$84,Woodworking!$A$5:$A$84,A9)+SUMIFS(Digital!$Z$5:$Z$84,Digital!$A$5:$A$84,A9),2)) -> 0 | V9: =IF(B9="","",ROUND(SUMIFS(Labor!$P$5:$P$304,Labor!$A$5:$A$304,A9)+SUMIFS(Crochet!$AE$5:$AE$84,Crochet!$A$5:$A$84,A9)+SUMIFS(Jewelry!$AG$5:$AG$84,Jewelry!$A$5:$A$84,A9)+SUMIFS(Candles!$AG$5:$AG$84,Candles!$A$5:$A$84,A9)+SUMIFS(Clothing!$AC$5:$AC$84,Clothing!$A$5:$A$84,A9)+SUMIFS(Woodworking!$AD$5:$AD$84,Woodworking!$A$5:$A$84,A9)+SUMIFS(Digital!$Y$5:$Y$84,Digital!$A$5:$A$84,A9),1)) -> 0 | W9: =IF(B9="","",IFERROR(INDEX(DiffTimeFactors,MATCH(G9,DiffNames,0)),1)) -> 0 | X9: =IF(B9="","",ROUND(V9*W9,1)) -> 0 | Y9: =IF(B9="","",ROUND(X9/60,3)) -> 0 | Z9: =IF(B9="","",ROUND(U9*W9,2)) -> 0 | AA9: =IF(B9="","",ROUND(SUMIFS(Labor!$Q$5:$Q$304,Labor!$A$5:$A$304,A9)+SUMIFS(Crochet!$AH$5:$AH$84,Crochet!$A$5:$A$84,A9)+SUMIFS(Jewelry!$AJ$5:$AJ$84,Jewelry!$A$5:$A$84,A9)+SUMIFS(Candles!$AJ$5:$AJ$84,Candles!$A$5:$A$84,A9)+SUMIFS(Clothing!$AF$5:$AF$84,Clothing!$A$5:$A$84,A9)+SUMIFS(Woodworking!$AH$5:$AH$84,Woodworking!$A$5:$A$84,A9)+SUMIFS(Digital!$AA$5:$AA$84,Digital!$A$5:$A$84,A9),2)) -> 0 | AB9: =IF(B9="","",ROUND(IF(I9="Budget",PackBudget,IF(I9="Standard",PackStandard,IF(I9="Gift",PackGift,IF(I9="Premium",PackPremium,DefaultPackaging)))),2)) -> 0 | AC9: =IF(B9="","",IF(I9="Budget",PackWeightBudget,IF(I9="Standard",PackWeightStandard,IF(I9="Gift",PackWeightGift,IF(I9="Premium",PackWeightPremium,0))))) -> 0 | AD9: =IF(B9="","",IFERROR(INDEX(Shipping!$M$5:$M$64,MATCH(J9,Shipping!$L$5:$L$64,0)),DefaultShipping)) -> 0 | AE9: =IF(B9="","",IFERROR(INDEX(Shipping!$F$5:$F$64,MATCH(J9,Shipping!$L$5:$L$64,0)),0)) -> 0 | AF9: =IF(B9="","",IFERROR(INDEX(Shipping!$C$5:$C$64,MATCH(J9,Shipping!$L$5:$L$64,0)),"")) -> 0 | AG9: =IF(B9="","",ROUND(MAX(0,AD9-AE9),2)) -> 0 | AH9: =IF(B9="","",ROUND(T9+Z9+AA9+AB9+AG9,2)) -> 0 | AI9: =IF(B9="","",IFERROR(INDEX(Channels!$S$5:$S$18,MATCH(IF(H9="",DefaultChannel,H9),Channels!$A$5:$A$18,0)),0)) -> 0 | AJ9: =IF(B9="","",IFERROR(INDEX(Channels!$O$5:$O$18,MATCH(IF(H9="",DefaultChannel,H9),Channels!$A$5:$A$18,0)),"No")) -> 0 | AK9: =IF(B9="","",ROUND(IFERROR(INDEX(Channels!$T$5:$T$18,MATCH(IF(H9="",DefaultChannel,H9),Channels!$A$5:$A$18,0)),0)+IF(AJ9="Yes",AE9*AI9,0),4)) -> 0 | AL9: =IF(B9="","",IF(OverheadMethod="Share of revenue",IF(RevenueTargetMonth<=0,0,OverheadMonthly/RevenueTargetMonth),0)) -> 0 | AM9: =IF(B9="","",IF(OverheadMethod="Per hour worked",ROUND(OverheadPerHour*Y9,2),IF(OR(OverheadMethod="Per unit made",OverheadMethod="Per order"),OverheadPerUnit,0))) -> 0 | AN9: =IF(B9="","",IF(N9<>"",N9,TargetRetailMargin)) -> 0 | AO9: =IF(B9="","",1-AN9-AI9-AL9) -> 0 | AP9: =IF(B9="","",IF(AO9<=0,"",(AH9+AM9+AK9)/AO9)) -> 0 | AQ9: =IF(B9="","",IF(AP9="","Check the settings",ROUND(IF(RoundingRule="None",AP9,IF(RoundingRule="Nearest 0.99",MAX(0.99,CEILING(AP9,1)-0.01),IF(RoundingRule="Nearest 0.95",MAX(0.95,CEILING(AP9,1)-0.05),IF(RoundingRule="Nearest 0.50",CEILING(AP9,0.5),IF(RoundingRule="Nearest 1",CEILING(AP9,1),IF(RoundingRule="Nearest 5",CEILING(AP9,5),IF(RoundingRule="Up to whole 1",CEILING(AP9,1),IF(RoundingRule="Up to whole 5",CEILING(AP9,5),ROUND(AP9,2))))))))),2))) -> 0 | AR9: =IF(B9="","",IF(M9<>"",M9,IF(ISNUMBER(AQ9),AQ9,""))) -> 0 | AS9: =IF(B9="","",IF(AR9="","",ROUND(AM9+AR9*AL9,2))) -> 0 | AT9: =IF(B9="","",IF(AR9="","",ROUND(AH9+AS9,2))) -> 0 | AU9: =IF(B9="","",IF(AR9="","",ROUND(AR9*AI9+AK9,2))) -> 0 | AV9: =IF(B9="","",IF(AR9="","",ROUND(AR9-AT9-AU9,2))) -> 0 | AW9: =IF(B9="","",IF(OR(AR9="",AR9=0),"",AV9/AR9)) -> 0 | AX9: =IF(B9="","",IF(OR(AT9="",AT9=0),"",AV9/AT9)) -> 0 | AY9: =IF(B9="","",IF(OR(Y9="",Y9=0,AV9=""),"",ROUND(AV9/Y9,2))) -> 0 | AZ9: =IF(B9="","",IF(OR(Y9="",Y9=0,AV9=""),"",ROUND((AV9+Z9)/Y9,2))) -> 0 | BA9: =IF(B9="","",IF(1-AI9-AL9<=0,"",ROUND((AH9+AM9+AK9)/(1-AI9-AL9),2))) -> 0 | BB9: =IF(B9="","",IF(AT9="","",ROUND(AT9*2,2))) -> 0 | BC9: =IF(B9="","",IF(AR9="","",ROUND(AR9*(1-WholesaleDiscount),2))) -> 0 | BD9: =IF(B9="","",IF(BC9="","",ROUND(BC9-AH9-AM9,2))) -> 0 | BE9: =IF(B9="","",IF(OR(BC9="",BC9=0),"",BD9/BC9)) -> 0 | BF9: =IF(B9="","",IFERROR(ROUND(AVERAGEIFS(Competitors!$F$5:$F$154,Competitors!$A$5:$A$154,A9),2),"")) -> 0 | BG9: =IF(B9="","",IF(OR(BF9="",BF9=0,AR9=""),"",AR9/BF9-1)) -> 0 | BH9: =IF(B9="","",SUMIFS(Sales!$D$5:$D$804,Sales!$C$5:$C$804,A9)) -> 0 | BI9: =IF(B9="","",ROUND(SUMIFS(Sales!$V$5:$V$804,Sales!$C$5:$C$804,A9),2)) -> 0 | BJ9: =IF(B9="","",ROUND(SUMIFS(Sales!$AG$5:$AG$804,Sales!$C$5:$C$804,A9),2)) -> 0 | BK9: =IF(B9="","",IF(OR(BI9="",BI9=0),"",BJ9/BI9)) -> 0 | BL9: =IF(B9="","",IF(SUMPRODUCT(MAX((Sales!$C$5:$C$804=A9)*Sales!$B$5:$B$804))=0,"",SUMPRODUCT(MAX((Sales!$C$5:$C$804=A9)*Sales!$B$5:$B$804)))) -> 0 | BM9: =IF(B9="","",IF(SUMPRODUCT(MAX(('Price History'!$B$5:$B$304=A9)*'Price History'!$A$5:$A$304))=0,IF(P9="","",P9),SUMPRODUCT(MAX(('Price History'!$B$5:$B$304=A9)*'Price History'!$A$5:$A$304)))) -> 0 | BN9: =IF(B9="","",IF(BM9="","",TodayDate-BM9)) -> 0 | BO9: =IF(B9="","",COUNTIFS($AV$5:$AV$304,">"&AV9)+COUNTIFS($AV$5:AV9,AV9)) -> 0 | BP9: =IF(B9="","",COUNTIFS($AW$5:$AW$304,">"&AW9)+COUNTIFS($AW$5:AW9,AW9)) -> 0 | BQ9: =IF(B9="","",COUNTIFS($BI$5:$BI$304,">"&BI9)+COUNTIFS($BI$5:BI9,BI9)) -> 0 | BR9: =IF(B9="","",COUNTIFS($AY$5:$AY$304,">"&AY9)+COUNTIFS($AY$5:AY9,AY9)) -> 0 | BS9: =IF(B9="","",IF(AH9=0,"Add - no costs entered yet",IF(AR9="","Check - no price yet",IF(AV9<0,"Loss - every sale costs you money",IF(AND(AZ9<>"",AZ9<MinimumWage),"Below - pays under minimum wage",IF(AW9<MarginWarning,"Low margin - re-price it",IF(AND(AF9<>"",K9<>"",K9+AC9>AF9),"Check - too heavy for that postage band",IF(AND(BN9<>"",BN9>PriceReviewDays),"Due - price has not been reviewed",IF(AND(BG9<>"",BG9>0.5),"Check - well above the market","OK")))))))) ) -> 0
