Workbook
Name ActiveList: Lists!$G$174:$G$185
Name AgeGroupList: Lists!$I$174:$I$187
Name AisleList: Lists!$G$59:$G$82
Name AllergenList: Lists!$C$59:$C$81
Name AnnualBudget: Settings!$D$29
Name BoughtLunch: 'Recipe Costs'!$D$11
Name BudgetLineList: Lists!$A$190:$A$206
Name CalorieTarget: Settings!$D$35
Name CarbTarget: Settings!$D$37
Name CardFactor: 'Print Recipe'!$H$6
Name CardPeople: 'Print Recipe'!$D$5
Name CardRecipe: 'Print Recipe'!$B$5
Name ContainerList: Lists!$A$85:$A$101
Name CookingMethodList: Lists!$C$31:$C$50
Name CuisineList: Lists!$A$31:$A$56
Name DashKey: Dashboard!$F$5
Name DashMonth: Dashboard!$D$5
Name DashWeek: Dashboard!$B$5
Name DefaultServings: Settings!$D$21
Name DietList: Lists!$A$59:$A$81
Name DifficultyList: Lists!$E$31:$E$41
Name DirectionList: Lists!$C$210:$C$219
Name DisposalList: Lists!$E$210:$E$222
Name EatingOutBudget: Settings!$D$30
Name EventNames: OFFSET(Events!$B$5,0,0,MAX(1,COUNTIF(Events!$B$5:$B$44,"?*")),1)
Name EventPrefix: Settings!$D$67
Name EventStatusList: Lists!$A$210:$A$223
Name EventTypeList: Lists!$C$107:$C$126
Name ExpiryWarningDays: Settings!$D$45
Name FatTarget: Settings!$D$38
Name FibreTarget: Settings!$D$39
Name FilterAllergen: 'Dietary Filters'!$D$11
Name FilterCategory: 'Dietary Filters'!$D$7
Name FilterCost: 'Dietary Filters'!$D$10
Name FilterDiet: 'Dietary Filters'!$D$6
Name FilterMethod: 'Dietary Filters'!$D$8
Name FilterTime: 'Dietary Filters'!$D$9
Name FreezerDays: Settings!$D$47
Name FrequencyList: Lists!$I$129:$I$142
Name GoalCategoryList: Lists!$E$129:$E$143
Name GoalNames: OFFSET(Goals!$B$5,0,0,MAX(1,COUNTIF(Goals!$B$5:$B$44,"?*")),1)
Name GoalStatusList: Lists!$G$129:$G$142
Name GroceryCategoryList: Lists!$E$59:$E$80
Name GroceryPrefix: Settings!$D$65
Name HomeCookedTarget: Settings!$D$53
Name HouseCook: Settings!$D$7
Name HouseEmail: Settings!$D$8
Name HouseMembers: Settings!$D$10
Name HouseName: Settings!$D$6
Name HouseNotes: Settings!$D$12
Name HouseTown: Settings!$D$9
Name IngredientIDs: OFFSET(Ingredients!$A$5,0,0,MAX(1,COUNTIF(Ingredients!$A$5:$A$304,"?*")),1)
Name IngredientNames: OFFSET(Ingredients!$B$5,0,0,MAX(1,COUNTIF(Ingredients!$B$5:$B$304,"?*")),1)
Name IngredientPrefix: Settings!$D$62
Name LeftoverDays: Settings!$D$46
Name LeftoverItems: OFFSET(Leftovers!$B$5,0,0,MAX(1,COUNTIF(Leftovers!$B$5:$B$124,"?*")),1)
Name LeftoverPrefix: Settings!$D$66
Name LeftoverStatusList: Lists!$E$107:$E$121
Name LowStockDays: Settings!$D$48
Name MainStore: Settings!$D$11

Sheet Start Here
A1: Automated Meal Planner & Grocery List Spreadsheet | J1: Novality Store | v1.0.0
A2: Plan the week, price it before you shop, and stop buying things you already own.
A3: > Start Here | C3: > Dashboard | E3: > Recipes | G3: > Week | I3: > Month | K3: > Grocery
B5: Everything in this workbook is linked. Type something once - a recipe, a price, a meal - and it turns up everywhere it is needed: the planner, the shopping list, the budget, the nutrition tracker and the alerts. Cream cells are yours to fill in; grey cells are formulas and are locked so they cannot be broken by accident.
A7: Six steps to set it up
B8: Step | C8: Where | D8: What to do
B9: 1 | C9: Settings | D9: Your household, how many you feed, the weekly budget, your shopping day and your nutrition targets. Ten minutes, and it feeds every other tab.
B10: 2 | C10: Household | D10: One row per person: portion size, diet, allergies, what they will not touch and which meals they are in for.
B11: 3 | C11: Ingredients | D11: The price book. Pack size and pack price for the thirty things you buy most. This is what prices every recipe and every shopping list, so it is the tab worth the effort.
B12: 4 | C12: Recipes + Recipe Ingredients | D12: Add a recipe, then list its ingredients one line each with a quantity and a unit. The cost, the calories and the allergens are worked out for you.
B13: 5 | C13: Pantry | D13: What is already in the cupboard, the fridge and the freezer. This is what stops the grocery list buying things you own.
B14: 6 | C14: Meal Plan | D14: Plan the week: date, meal, recipe, how many you are feeding. The Weekly Planner shows it as a week and the Grocery List builds itself.
A16: How the automatic grocery list works
B17: 1. The Meal Plan says you are cooking recipe R-0002 on Tuesday for 4 people.
B18: 2. The recipe serves 6, so everything in it is multiplied by 0.67 - that is the scaling, done for you.
B19: 3. Each ingredient line is converted to a base unit: 2 tbsp of oil becomes 30 ml, 1 kg of mince becomes 1000 g.
B20: 4. Every meal in the shopping window is added up by ingredient, so three recipes using onions make one line.
B21: 5. Whatever the Pantry says you already own is taken off.
B22: 6. What is left is rounded up to whole packs and priced from the Ingredients tab - that is your list, with a total, before you leave the house.
A24: The weekly rhythm
B25: FRIDAY (10 minutes) - look at the Pantry 'Use soon' list and the Leftovers tab, then plan next week on the Meal Plan tab.
B26: SATURDAY MORNING - open the Grocery List, tick off anything you already have, print it or take the laptop, and shop.
B27: AFTER THE SHOP (2 minutes) - log the total on the Grocery Spending tab and update the Pantry for the big items.
B28: PREP DAY - work through the Meal Prep tab: two or three jobs, not ten.
B29: DURING THE WEEK - mark meals 'Eaten' as you go and log leftovers while you are putting them in the fridge.
B30: END OF THE MONTH - read the Dashboard and the Food Waste tab, and change one thing.
A32: What is in the workbook
B33: Tab | C33: What it is for
B34: Dashboard | C34: This week at a glance - cost, meals, alerts
B35: Weekly Planner | C35: Seven days on one page, ready to print
B36: Monthly Planner | C36: The month as a calendar grid
B37: Settings | C37: Household, budget, targets, shopping window
B38: Lists | C38: Every drop-down, plus the unit conversion table
B39: Household | C39: Who eats here, portions, diets and allergies
B40: Recipes | C40: THE RECIPE BOOK - cost and nutrition worked out
B41: Recipe Ingredients | C41: What goes in each recipe. The engine room
B42: Ingredients | C42: The price book: pack sizes, prices, nutrition
B43: Meal Plan | C43: THE MAIN TAB - one row per planned meal
B44: Grocery List | C44: Builds itself from the plan, minus the pantry
... B55: Help | C55: Every question answered, including the honest limits
...

Sheet Dashboard
A1: Dashboard | J1: Novality Store | v1.0.0
A2: This week, this month and the year so far - all from the numbers you have already entered.
A3: > Start Here | C3: > Dashboard | E3: > Recipes | G3: > Week | I3: > Month | K3: > Grocery
A5: Week of | B5: =WeekPick -> 0 | C5: Month | D5: =TEXT(TODAY(),"mmmm yyyy") -> 0 | E5: Month key | F5: =TEXT(TODAY(),"yyyy-mm") -> 0 | G5: Household | H5: =HouseMembers -> 0 | I5: Updated | K5: =TODAY() -> 0
A7: Meals planned this week | D7: Planned cost this week | G7: This week's shopping list | J7: Left in the weekly budget
A8: =COUNTIFS('Meal Plan'!$B$5:$B$504,">="&DashWeek,'Meal Plan'!$B$5:$B$504,"<="&DashWeek+6) -> 0 | D8: =SUMIFS('Meal Plan'!$T$5:$T$504,'Meal Plan'!$B$5:$B$504,">="&DashWeek,'Meal Plan'!$B$5:$B$504,"<="&DashWeek+6) -> 0 | G8: =SUM('Grocery List'!$O$5:$O$304) -> 0 | J8: =WeeklyBudget-SUM('Grocery List'!$O$5:$O$304) -> 0
A9: every slot with something in it | D9: at price book prices | G9: what the list adds up to | J9: green is money left
A11: Spent this month | D11: Pantry value | G11: Food wasted this month | J11: Cooked at home this week
A12: =SUMIFS('Grocery Spending'!$K$5:$K$404,'Grocery Spending'!$E$5:$E$404,DashKey) -> 0 | D12: =SUM(Pantry!$P$5:$P$304) -> 0 | G12: =SUMIFS('Food Waste'!$L$5:$L$154,'Food Waste'!$D$5:$D$154,DashKey) -> 0 | J12: =COUNTIFS('Meal Plan'!$B$5:$B$504,">="&DashWeek,'Meal Plan'!$B$5:$B$504,"<="&DashWeek+6,'Meal Plan'!$AD$5:$AD$504,"Yes") -> 0
A13: every shop, takeaway and meal out | D13: what is sitting in the cupboards | G13: target under $15 | J13: target 18 a week
A15: Needs your attention
A16: What | B16: How many | C16: What it means | D16: Where to fix it
A17: Food about to go off | B17: =COUNTIF(Pantry!$W$5:$W$304,"Use soon") -> 0 | C17: ="Use these within 5 days or they are money in the bin" -> 0 | K17: Pantry
A18: Already expired | B18: =COUNTIF(Pantry!$W$5:$W$304,"Expired") -> 0 | C18: ="Past their date - check, then bin and log them" -> 0 | K18: Pantry
A19: Leftovers waiting | B19: =SUMIFS(Leftovers!$F$5:$F$124,Leftovers!$Q$5:$Q$124,"<>Eaten",Leftovers!$Q$5:$Q$124,"<>Binned") -> 0 | C19: ="Portions in the fridge or freezer worth "&TEXT(SUMIFS(Leftovers!$M$5:$M$124,Leftovers!$Q$5:$Q$124,"<>Eaten",Leftovers!$Q$5:$Q$124,"<>Binned"),"0.00") -> 0 | K19: Leftovers
A20: Staples below par | B20: =COUNTIF(Staples!$Q$5:$Q$104,"Low stock")+COUNTIF(Staples!$Q$5:$Q$104,"Out of stock") -> 0 | C20: ="Things you said you never want to run out of" -> 0 | K20: Staples
A21: Ingredients with no price | B21: =COUNTIFS(Ingredients!$B$5:$B$304,"<>",Ingredients!$I$5:$I$304,"") -> 0 | C21: ="Until these have a price, recipes using them are under-costed" -> 0 | K21: Ingredients
A22: Recipe lines to fix | B22: =COUNTIF('Recipe Ingredients'!$AB$5:$AB$1204,"Missing*")+COUNTIF('Recipe Ingredients'!$AB$5:$AB$1204,"Check - *") -> 0 | C22: ="Unit mismatches or ingredients not in the price book - they are left out of the shopping list" -> 0 | K22: Recipe Ingredients
A23: Days with nothing planned | B23: =(COUNTIFS('Meal Plan'!$B$5:$B$504,DashWeek+0,'Meal Plan'!$F$5:$F$504,"Dinner")=0)*1+(COUNTIFS('Meal Plan'!$B$5:$B$504,DashWeek+1,'Meal Plan'!$F$5:$F$504,"Dinner")=0)*1+(COUNTIFS('Meal Plan'!$B$5:$B$504,DashWeek+2,'Meal Plan'!$F$5:$F$504,"Dinner")=0)*1+(COUNTIFS('Meal Plan'!$B$5:$B$504,DashWeek+3,'Meal Plan'!$F$5:$F$504,"Dinner")=0)*1+(COUNTIFS('Meal Plan'!$B$5:$B$504,DashWeek+4,'Meal Plan'!$F$5:$F$504,"Dinner")=0)*1+(COUNTIFS('Meal Plan'!$B$5:$B$504,DashWeek+5,'Meal Plan'!$F$5:$F$504,"Dinner")=0)*1+(COUNTIFS('Meal Plan'!$B$5:$B$504,DashWeek+6,'Meal Plan'!$F$5:$F$504,"Dinner")=0)*1 -> 0 | C23: ="Dinner slots still empty in the week you are looking at" -> 0 | K23: Meal Plan
A24: Prep jobs outstanding | B24: =COUNTIFS('Meal Prep'!$W$5:$W$124,"<>Done",'Meal Prep'!$B$5:$B$124,"<>") -> 0 | C24: ="Batch cooking you planned but have not made yet" -> 0 | K24: Meal Prep
A25: Goals behind target | B25: =COUNTIF(Goals!$K$5:$K$44,"No") -> 0 | C25: ="Worth five minutes with a cup of tea" -> 0 | K25: Goals
A27: This week's dinners
A28: Day | B28: =DashWeek+0 -> 0 | C28: =DashWeek+1 -> 0 | D28: =DashWeek+2 -> 0 | E28: =DashWeek+3 -> 0 | F28: =DashWeek+4 -> 0 | G28: =DashWeek+5 -> 0 | H28: =DashWeek+6 -> 0 | I28: Week
A29: Dinner | B29: =IFERROR(INDEX('Meal Plan'!$H$5:$H$504,MATCH(TEXT(B$28,"yyyy-mm-dd")&"|Dinner",'Meal Plan'!$AE$5:$AE$504,0)),"-") -> 0 | C29: =IFERROR(INDEX('Meal Plan'!$H$5:$H$504,MATCH(TEXT(C$28,"yyyy-mm-dd")&"|Dinner",'Meal Plan'!$AE$5:$AE$504,0)),"-") -> 0 | D29: =IFERROR(INDEX('Meal Plan'!$H$5:$H$504,MATCH(TEXT(D$28,"yyyy-mm-dd")&"|Dinner",'Meal Plan'!$AE$5:$AE$504,0)),"-") -> 0 | E29: =IFERROR(INDEX('Meal Plan'!$H$5:$H$504,MATCH(TEXT(E$28,"yyyy-mm-dd")&"|Dinner",'Meal Plan'!$AE$5:$AE$504,0)),"-") -> 0 | F29: =IFERROR(INDEX('Meal Plan'!$H$5:$H$504,MATCH(TEXT(F$28,"yyyy-mm-dd")&"|Dinner",'Meal Plan'!$AE$5:$AE$504,0)),"-") -> 0 | G29: =IFERROR(INDEX('Meal Plan'!$H$5:$H$504,MATCH(TEXT(G$28,"yyyy-mm-dd")&"|Dinner",'Meal Plan'!$AE$5:$AE$504,0)),"-") -> 0 | H29: =IFERROR(INDEX('Meal Plan'!$H$5:$H$504,MATCH(TEXT(H$28,"yyyy-mm-dd")&"|Dinner",'Meal Plan'!$AE$5:$AE$504,0)),"-") -> 0 | I29: =COUNTIFS('Meal Plan'!$B$5:$B$504,">="&DashWeek,'Meal Plan'!$B$5:$B$504,"<="&DashWeek+6,'Meal Plan'!$F$5:$F$504,"Dinner") -> 0
A30: Cost | B30: =IF(B$28="","",SUMIFS('Meal Plan'!$T$5:$T$504,'Meal Plan'!$B$5:$B$504,B$28)) -> 0 | C30: =IF(C$28="","",SUMIFS('Meal Plan'!$T$5:$T$504,'Meal Plan'!$B$5:$B$504,C$28)) -> 0 | D30: =IF(D$28="","",SUMIFS('Meal Plan'!$T$5:$T$504,'Meal Plan'!$B$5:$B$504,D$28)) -> 0 | E30: =IF(E$28="","",SUMIFS('Meal Plan'!$T$5:$T$504,'Meal Plan'!$B$5:$B$504,E$28)) -> 0 | F30: =IF(F$28="","",SUMIFS('Meal Plan'!$T$5:$T$504,'Meal Plan'!$B$5:$B$504,F$28)) -> 0 | G30: =IF(G$28="","",SUMIFS('Meal Plan'!$T$5:$T$504,'Meal Plan'!$B$5:$B$504,G$28)) -> 0 | H30: =IF(H$28="","",SUMIFS('Meal Plan'!$T$5:$T$504,'Meal Plan'!$B$5:$B$504,H$28)) -> 0 | I30: =SUMIFS('Meal Plan'!$T$5:$T$504,'Meal Plan'!$B$5:$B$504,">="&DashWeek,'Meal Plan'!$B$5:$B$504,"<="&DashWeek+6) -> 0
A32: The year so far
A33: Month | B33: Grocery spend | C33: Budget | D33: Difference | E33: Eating out | F33: Food waste | G33: Meals cooked at home | H33: Trend
A34: =TEXT(DATE(PlanYear,1,1),"mmm") -> 0 | B34: =SUMIFS('Grocery Spending'!$K$5:$K$404,'Grocery Spending'!$E$5:$E$404,TEXT(DATE(PlanYear,1,1),"yyyy-mm")) -> 0 | C34: =MonthlyBudget -> 0 | D34: =MonthlyBudget-SUMIFS('Grocery Spending'!$K$5:$K$404,'Grocery Spending'!$E$5:$E$404,TEXT(DATE(PlanYear,1,1),"yyyy-mm")) -> 0 | E34: =SUMIFS('Grocery Spending'!$K$5:$K$404,'Grocery Spending'!$E$5:$E$404,TEXT(DATE(PlanYear,1,1),"yyyy-mm"),'Grocery Spending'!$G$5:$G$404,"Eating out")+SUMIFS('Grocery Spending'!$K$5:$K$404,'Grocery Spending'!$E$5:$E$404,TEXT(DATE(PlanYear,1,1),"yyyy-mm"),'Grocery Spending'!$G$5:$G$404,"Takeaway") -> 0 | F34: =SUMIFS('Food Waste'!$L$5:$L$154,'Food Waste'!$D$5:$D$154,TEXT(DATE(PlanYear,1,1),"yyyy-mm")) -> 0 | G34: =COUNTIFS('Meal Plan'!$E$5:$E$504,TEXT(DATE(PlanYear,1,1),"yyyy-mm"),'Meal Plan'!$AD$5:$AD$504,"Yes") -> 0
A35: =TEXT(DATE(PlanYear,2,1),"mmm") -> 0 | B35: =SUMIFS('Grocery Spending'!$K$5:$K$404,'Grocery Spending'!$E$5:$E$404,TEXT(DATE(PlanYear,2,1),"yyyy-mm")) -> 0 | C35: =MonthlyBudget -> 0 | D35: =MonthlyBudget-SUMIFS('Grocery Spending'!$K$5:$K$404,'Grocery Spending'!$E$5:$E$404,TEXT(DATE(PlanYear,2,1),"yyyy-mm")) -> 0 | E35: =SUMIFS('Grocery Spending'!$K$5:$K$404,'Grocery Spending'!$E$5:$E$404,TEXT(DATE(PlanYear,2,1),"yyyy-mm"),'Grocery Spending'!$G$5:$G$404,"Eating out")+SUMIFS('Grocery Spending'!$K$5:$K$404,'Grocery Spending'!$E$5:$E$404,TEXT(DATE(PlanYear,2,1),"yyyy-mm"),'Grocery Spending'!$G$5:$G$404,"Takeaway") -> 0 | F35: =SUMIFS('Food Waste'!$L$5:$L$154,'Food Waste'!$D$5:$D$154,TEXT(DATE(PlanYear,2,1),"yyyy-mm")) -> 0 | G35: =COUNTIFS('Meal Plan'!$E$5:$E$504,TEXT(DATE(PlanYear,2,1),"yyyy-mm"),'Meal Plan'!$AD$5:$AD$504,"Yes") -> 0
A36: =TEXT(DATE(PlanYear,3,1),"mmm") -> 0 | B36: =SUMIFS('Grocery Spending'!$K$5:$K$404,'Grocery Spending'!$E$5:$E$404,TEXT(DATE(PlanYear,3,1),"yyyy-mm")) -> 0 | C36: =MonthlyBudget -> 0 | D36: =MonthlyBudget-SUMIFS('Grocery Spending'!$K$5:$K$404,'Grocery Spending'!$E$5:$E$404,TEXT(DATE(PlanYear,3,1),"yyyy-mm")) -> 0 | E36: =SUMIFS('Grocery Spending'!$K$5:$K$404,'Grocery Spending'!$E$5:$E$404,TEXT(DATE(PlanYear,3,1),"yyyy-mm"),'Grocery Spending'!$G$5:$G$404,"Eating out")+SUMIFS('Grocery Spending'!$K$5:$K$404,'Grocery Spending'!$E$5:$E$404,TEXT(DATE(PlanYear,3,1),"yyyy-mm"),'Grocery Spending'!$G$5:$G$404,"Takeaway") -> 0 | F36: =SUMIFS('Food Waste'!$L$5:$L$154,'Food Waste'!$D$5:$D$154,TEXT(DATE(PlanYear,3,1),"yyyy-mm")) -> 0 | G36: =COUNTIFS('Meal Plan'!$E$5:$E$504,TEXT(DATE(PlanYear,3,1),"yyyy-mm"),'Meal Plan'!$AD$5:$AD$504,"Yes") -> 0
A37: =TEXT(DATE(PlanYear,4,1),"mmm") -> 0 | B37: =SUMIFS('Grocery Spending'!$K$5:$K$404,'Grocery Spending'!$E$5:$E$404,TEXT(DATE(PlanYear,4,1),"yyyy-mm")) -> 0 | C37: =MonthlyBudget -> 0 | D37: =MonthlyBudget-SUMIFS('Grocery Spending'!$K$5:$K$404,'Grocery Spending'!$E$5:$E$404,TEXT(DATE(PlanYear,4,1),"yyyy-mm")) -> 0 | E37: =SUMIFS('Grocery Spending'!$K$5:$K$404,'Grocery Spending'!$E$5:$E$404,TEXT(DATE(PlanYear,4,1),"yyyy-mm"),'Grocery Spending'!$G$5:$G$404,"Eating out")+SUMIFS('Grocery Spending'!$K$5:$K$404,'Grocery Spending'!$E$5:$E$404,TEXT(DATE(PlanYear,4,1),"yyyy-mm"),'Grocery Spending'!$G$5:$G$404,"Takeaway") -> 0 | F37: =SUMIFS('Food Waste'!$L$5:$L$154,'Food Waste'!$D$5:$D$154,TEXT(DATE(PlanYear,4,1),"yyyy-mm")) -> 0 | G37: =COUNTIFS('Meal Plan'!$E$5:$E$504,TEXT(DATE(PlanYear,4,1),"yyyy-mm"),'Meal Plan'!$AD$5:$AD$504,"Yes") -> 0
A38: =TEXT(DATE(PlanYear,5,1),"mmm") -> 0 | B38: =SUMIFS('Grocery Spending'!$K$5:$K$404,'Grocery Spending'!$E$5:$E$404,TEXT(DATE(PlanYear,5,1),"yyyy-mm")) -> 0 | C38: =MonthlyBudget -> 0 | D38: =MonthlyBudget-SUMIFS('Grocery Spending'!$K$5:$K$404,'Grocery Spending'!$E$5:$E$404,TEXT(DATE(PlanYear,5,1),"yyyy-mm")) -> 0 | E38: =SUMIFS('Grocery Spending'!$K$5:$K$404,'Grocery Spending'!$E$5:$E$404,TEXT(DATE(PlanYear,5,1),"yyyy-mm"),'Grocery Spending'!$G$5:$G$404,"Eating out")+SUMIFS('Grocery Spending'!$K$5:$K$404,'Grocery Spending'!$E$5:$E$404,TEXT(DATE(PlanYear,5,1),"yyyy-mm"),'Grocery Spending'!$G$5:$G$404,"Takeaway") -> 0 | F38: =SUMIFS('Food Waste'!$L$5:$L$154,'Food Waste'!$D$5:$D$154,TEXT(DATE(PlanYear,5,1),"yyyy-mm")) -> 0 | G38: =COUNTIFS('Meal Plan'!$E$5:$E$504,TEXT(DATE(PlanYear,5,1),"yyyy-mm"),'Meal Plan'!$AD$5:$AD$504,"Yes") -> 0
A39: =TEXT(DATE(PlanYear,6,1),"mmm") -> 0 | B39: =SUMIFS('Grocery Spending'!$K$5:$K$404,'Grocery Spending'!$E$5:$E$404,TEXT(DATE(PlanYear,6,1),"yyyy-mm")) -> 0 | C39: =MonthlyBudget -> 0 | D39: =MonthlyBudget-SUMIFS('Grocery Spending'!$K$5:$K$404,'Grocery Spending'!$E$5:$E$404,TEXT(DATE(PlanYear,6,1),"yyyy-mm")) -> 0 | E39: =SUMIFS('Grocery Spending'!$K$5:$K$404,'Grocery Spending'!$E$5:$E$404,TEXT(DATE(PlanYear,6,1),"yyyy-mm"),'Grocery Spending'!$G$5:$G$404,"Eating out")+SUMIFS('Grocery Spending'!$K$5:$K$404,'Grocery Spending'!$E$5:$E$404,TEXT(DATE(PlanYear,6,1),"yyyy-mm"),'Grocery Spending'!$G$5:$G$404,"Takeaway") -> 0 | F39: =SUMIFS('Food Waste'!$L$5:$L$154,'Food Waste'!$D$5:$D$154,TEXT(DATE(PlanYear,6,1),"yyyy-mm")) -> 0 | G39: =COUNTIFS('Meal Plan'!$E$5:$E$504,TEXT(DATE(PlanYear,6,1),"yyyy-mm"),'Meal Plan'!$AD$5:$AD$504,"Yes") -> 0
A40: =TEXT(DATE(PlanYear,7,1),"mmm") -> 0 | B40: =SUMIFS('Grocery Spending'!$K$5:$K$404,'Grocery Spending'!$E$5:$E$404,TEXT(DATE(PlanYear,7,1),"yyyy-mm")) -> 0 | C40: =MonthlyBudget -> 0 | D40: =MonthlyBudget-SUMIFS('Grocery Spending'!$K$5:$K$404,'Grocery Spending'!$E$5:$E$404,TEXT(DATE(PlanYear,7,1),"yyyy-mm")) -> 0 | E40: =SUMIFS('Grocery Spending'!$K$5:$K$404,'Grocery Spending'!$E$5:$E$404,TEXT(DATE(PlanYear,7,1),"yyyy-mm"),'Grocery Spending'!$G$5:$G$404,"Eating out")+SUMIFS('Grocery Spending'!$K$5:$K$404,'Grocery Spending'!$E$5:$E$404,TEXT(DATE(PlanYear,7,1),"yyyy-mm"),'Grocery Spending'!$G$5:$G$404,"Takeaway") -> 0 | F40: =SUMIFS('Food Waste'!$L$5:$L$154,'Food Waste'!$D$5:$D$154,TEXT(DATE(PlanYear,7,1),"yyyy-mm")) -> 0 | G40: =COUNTIFS('Meal Plan'!$E$5:$E$504,TEXT(DATE(PlanYear,7,1),"yyyy-mm"),'Meal Plan'!$AD$5:$AD$504,"Yes") -> 0
A41: =TEXT(DATE(PlanYear,8,1),"mmm") -> 0 | B41: =SUMIFS('Grocery Spending'!$K$5:$K$404,'Grocery Spending'!$E$5:$E$404,TEXT(DATE(PlanYear,8,1),"yyyy-mm")) -> 0 | C41: =MonthlyBudget -> 0 | D41: =MonthlyBudget-SUMIFS('Grocery Spending'!$K$5:$K$404,'Grocery Spending'!$E$5:$E$404,TEXT(DATE(PlanYear,8,1),"yyyy-mm")) -> 0 | E41: =SUMIFS('Grocery Spending'!$K$5:$K$404,'Grocery Spending'!$E$5:$E$404,TEXT(DATE(PlanYear,8,1),"yyyy-mm"),'Grocery Spending'!$G$5:$G$404,"Eating out")+SUMIFS('Grocery Spending'!$K$5:$K$404,'Grocery Spending'!$E$5:$E$404,TEXT(DATE(PlanYear,8,1),"yyyy-mm"),'Grocery Spending'!$G$5:$G$404,"Takeaway") -> 0 | F41: =SUMIFS('Food Waste'!$L$5:$L$154,'Food Waste'!$D$5:$D$154,TEXT(DATE(PlanYear,8,1),"yyyy-mm")) -> 0 | G41: =COUNTIFS('Meal Plan'!$E$5:$E$504,TEXT(DATE(PlanYear,8,1),"yyyy-mm"),'Meal Plan'!$AD$5:$AD$504,"Yes") -> 0
A42: =TEXT(DATE(PlanYear,9,1),"mmm") -> 0 | B42: =SUMIFS('Grocery Spending'!$K$5:$K$404,'Grocery Spending'!$E$5:$E$404,TEXT(DATE(PlanYear,9,1),"yyyy-mm")) -> 0 | C42: =MonthlyBudget -> 0 | D42: =MonthlyBudget-SUMIFS('Grocery Spending'!$K$5:$K$404,'Grocery Spending'!$E$5:$E$404,TEXT(DATE(PlanYear,9,1),"yyyy-mm")) -> 0 | E42: =SUMIFS('Grocery Spending'!$K$5:$K$404,'Grocery Spending'!$E$5:$E$404,TEXT(DATE(PlanYear,9,1),"yyyy-mm"),'Grocery Spending'!$G$5:$G$404,"Eating out")+SUMIFS('Grocery Spending'!$K$5:$K$404,'Grocery Spending'!$E$5:$E$404,TEXT(DATE(PlanYear,9,1),"yyyy-mm"),'Grocery Spending'!$G$5:$G$404,"Takeaway") -> 0 | F42: =SUMIFS('Food Waste'!$L$5:$L$154,'Food Waste'!$D$5:$D$154,TEXT(DATE(PlanYear,9,1),"yyyy-mm")) -> 0 | G42: =COUNTIFS('Meal Plan'!$E$5:$E$504,TEXT(DATE(PlanYear,9,1),"yyyy-mm"),'Meal Plan'!$AD$5:$AD$504,"Yes") -> 0
A43: =TEXT(DATE(PlanYear,10,1),"mmm") -> 0 | B43: =SUMIFS('Grocery Spending'!$K$5:$K$404,'Grocery Spending'!$E$5:$E$404,TEXT(DATE(PlanYear,10,1),"yyyy-mm")) -> 0 | C43: =MonthlyBudget -> 0 | D43: =MonthlyBudget-SUMIFS('Grocery Spending'!$K$5:$K$404,'Grocery Spending'!$E$5:$E$404,TEXT(DATE(PlanYear,10,1),"yyyy-mm")) -> 0 | E43: =SUMIFS('Grocery Spending'!$K$5:$K$404,'Grocery Spending'!$E$5:$E$404,TEXT(DATE(PlanYear,10,1),"yyyy-mm"),'Grocery Spending'!$G$5:$G$404,"Eating out")+SUMIFS('Grocery Spending'!$K$5:$K$404,'Grocery Spending'!$E$5:$E$404,TEXT(DATE(PlanYear,10,1),"yyyy-mm"),'Grocery Spending'!$G$5:$G$404,"Takeaway") -> 0 | F43: =SUMIFS('Food Waste'!$L$5:$L$154,'Food Waste'!$D$5:$D$154,TEXT(DATE(PlanYear,10,1),"yyyy-mm")) -> 0 | G43: =COUNTIFS('Meal Plan'!$E$5:$E$504,TEXT(DATE(PlanYear,10,1),"yyyy-mm"),'Meal Plan'!$AD$5:$AD$504,"Yes") -> 0
A44: =TEXT(DATE(PlanYear,11,1),"mmm") -> 0 | B44: =SUMIFS('Grocery Spending'!$K$5:$K$404,'Grocery Spending'!$E$5:$E$404,TEXT(DATE(PlanYear,11,1),"yyyy-mm")) -> 0 | C44: =MonthlyBudget -> 0 | D44: =MonthlyBudget-SUMIFS('Grocery Spending'!$K$5:$K$404,'Grocery Spending'!$E$5:$E$404,TEXT(DATE(PlanYear,11,1),"yyyy-mm")) -> 0 | E44: =SUMIFS('Grocery Spending'!$K$5:$K$404,'Grocery Spending'!$E$5:$E$404,TEXT(DATE(PlanYear,11,1),"yyyy-mm"),'Grocery Spending'!$G$5:$G$404,"Eating out")+SUMIFS('Grocery Spending'!$K$5:$K$404,'Grocery Spending'!$E$5:$E$404,TEXT(DATE(PlanYear,11,1),"yyyy-mm"),'Grocery Spending'!$G$5:$G$404,"Takeaway") -> 0 | F44: =SUMIFS('Food Waste'!$L$5:$L$154,'Food Waste'!$D$5:$D$154,TEXT(DATE(PlanYear,11,1),"yyyy-mm")) -> 0 | G44: =COUNTIFS('Meal Plan'!$E$5:$E$504,TEXT(DATE(PlanYear,11,1),"yyyy-mm"),'Meal Plan'!$AD$5:$AD$504,"Yes") -> 0
A45: =TEXT(DATE(PlanYear,12,1),"mmm") -> 0 | B45: =SUMIFS('Grocery Spending'!$K$5:$K$404,'Grocery Spending'!$E$5:$E$404,TEXT(DATE(PlanYear,12,1),"yyyy-mm")) -> 0 | C45: =MonthlyBudget -> 0 | D45: =MonthlyBudget-SUMIFS('Grocery Spending'!$K$5:$K$404,'Grocery Spending'!$E$5:$E$404,TEXT(DATE(PlanYear,12,1),"yyyy-mm")) -> 0 | E45: =SUMIFS('Grocery Spending'!$K$5:$K$404,'Grocery Spending'!$E$5:$E$404,TEXT(DATE(PlanYear,12,1),"yyyy-mm"),'Grocery Spending'!$G$5:$G$404,"Eating out")+SUMIFS('Grocery Spending'!$K$5:$K$404,'Grocery Spending'!$E$5:$E$404,TEXT(DATE(PlanYear,12,1),"yyyy-mm"),'Grocery Spending'!$G$5:$G$404,"Takeaway") -> 0 | F45: =SUMIFS('Food Waste'!$L$5:$L$154,'Food Waste'!$D$5:$D$154,TEXT(DATE(PlanYear,12,1),"yyyy-mm")) -> 0 | G45: =COUNTIFS('Meal Plan'!$E$5:$E$504,TEXT(DATE(PlanYear,12,1),"yyyy-mm"),'Meal Plan'!$AD$5:$AD$504,"Yes") -> 0
A47: Spend, waste and home cooking by month. The little charts on the right are, top to bottom: grocery spend, food waste, meals cooked at home.
...

Sheet Weekly Planner
A1: Weekly Meal Planner | G1: Novality Store | v1.0.0
A2: One week at a glance - what you are eating, what it costs and what still needs cooking.
A3: > Start Here | C3: > Dashboard | E3: > Recipes | G3: > Week
A5: Week starting | B5: 46300 | C5: Week number | D5: =WEEKNUM(WeekPick,IF(WeekStart="Sunday",1,2)) -> 0 | E5: People | F5: =DefaultServings -> 0 | G5: Weekly budget | H5: =WeeklyBudget -> 0
A6: Change the date above to any Monday - every box on the page follows it. Meals themselves are added on the Meal Plan tab; this page is the view, not the entry form.
A7: Meal | B7: =WeekPick+0 -> 0 | C7: =WeekPick+1 -> 0 | D7: =WeekPick+2 -> 0 | E7: =WeekPick+3 -> 0 | F7: =WeekPick+4 -> 0 | G7: =WeekPick+5 -> 0 | H7: =WeekPick+6 -> 0 | I7: Week total
A8: Breakfast | B8: =IF(B$7="","",IFERROR(INDEX('Meal Plan'!$H$5:$H$504,MATCH(TEXT(B$7,"yyyy-mm-dd")&"|"&"Breakfast",'Meal Plan'!$AE$5:$AE$504,0)),"")) -> 0 | C8: =IF(C$7="","",IFERROR(INDEX('Meal Plan'!$H$5:$H$504,MATCH(TEXT(C$7,"yyyy-mm-dd")&"|"&"Breakfast",'Meal Plan'!$AE$5:$AE$504,0)),"")) -> 0 | D8: =IF(D$7="","",IFERROR(INDEX('Meal Plan'!$H$5:$H$504,MATCH(TEXT(D$7,"yyyy-mm-dd")&"|"&"Breakfast",'Meal Plan'!$AE$5:$AE$504,0)),"")) -> 0 | E8: =IF(E$7="","",IFERROR(INDEX('Meal Plan'!$H$5:$H$504,MATCH(TEXT(E$7,"yyyy-mm-dd")&"|"&"Breakfast",'Meal Plan'!$AE$5:$AE$504,0)),"")) -> 0 | F8: =IF(F$7="","",IFERROR(INDEX('Meal Plan'!$H$5:$H$504,MATCH(TEXT(F$7,"yyyy-mm-dd")&"|"&"Breakfast",'Meal Plan'!$AE$5:$AE$504,0)),"")) -> 0 | G8: =IF(G$7="","",IFERROR(INDEX('Meal Plan'!$H$5:$H$504,MATCH(TEXT(G$7,"yyyy-mm-dd")&"|"&"Breakfast",'Meal Plan'!$AE$5:$AE$504,0)),"")) -> 0 | H8: =IF(H$7="","",IFERROR(INDEX('Meal Plan'!$H$5:$H$504,MATCH(TEXT(H$7,"yyyy-mm-dd")&"|"&"Breakfast",'Meal Plan'!$AE$5:$AE$504,0)),"")) -> 0 | I8: =COUNTIFS('Meal Plan'!$B$5:$B$504,">="&WeekPick,'Meal Plan'!$B$5:$B$504,"<="&WeekPick+6,'Meal Plan'!$F$5:$F$504,"Breakfast") -> 0
A9: Morning snack | B9: =IF(B$7="","",IFERROR(INDEX('Meal Plan'!$H$5:$H$504,MATCH(TEXT(B$7,"yyyy-mm-dd")&"|"&"Morning snack",'Meal Plan'!$AE$5:$AE$504,0)),"")) -> 0 | C9: =IF(C$7="","",IFERROR(INDEX('Meal Plan'!$H$5:$H$504,MATCH(TEXT(C$7,"yyyy-mm-dd")&"|"&"Morning snack",'Meal Plan'!$AE$5:$AE$504,0)),"")) -> 0 | D9: =IF(D$7="","",IFERROR(INDEX('Meal Plan'!$H$5:$H$504,MATCH(TEXT(D$7,"yyyy-mm-dd")&"|"&"Morning snack",'Meal Plan'!$AE$5:$AE$504,0)),"")) -> 0 | E9: =IF(E$7="","",IFERROR(INDEX('Meal Plan'!$H$5:$H$504,MATCH(TEXT(E$7,"yyyy-mm-dd")&"|"&"Morning snack",'Meal Plan'!$AE$5:$AE$504,0)),"")) -> 0 | F9: =IF(F$7="","",IFERROR(INDEX('Meal Plan'!$H$5:$H$504,MATCH(TEXT(F$7,"yyyy-mm-dd")&"|"&"Morning snack",'Meal Plan'!$AE$5:$AE$504,0)),"")) -> 0 | G9: =IF(G$7="","",IFERROR(INDEX('Meal Plan'!$H$5:$H$504,MATCH(TEXT(G$7,"yyyy-mm-dd")&"|"&"Morning snack",'Meal Plan'!$AE$5:$AE$504,0)),"")) -> 0 | H9: =IF(H$7="","",IFERROR(INDEX('Meal Plan'!$H$5:$H$504,MATCH(TEXT(H$7,"yyyy-mm-dd")&"|"&"Morning snack",'Meal Plan'!$AE$5:$AE$504,0)),"")) -> 0 | I9: =COUNTIFS('Meal Plan'!$B$5:$B$504,">="&WeekPick,'Meal Plan'!$B$5:$B$504,"<="&WeekPick+6,'Meal Plan'!$F$5:$F$504,"Morning snack") -> 0
A10: Lunch | B10: =IF(B$7="","",IFERROR(INDEX('Meal Plan'!$H$5:$H$504,MATCH(TEXT(B$7,"yyyy-mm-dd")&"|"&"Lunch",'Meal Plan'!$AE$5:$AE$504,0)),"")) -> 0 | C10: =IF(C$7="","",IFERROR(INDEX('Meal Plan'!$H$5:$H$504,MATCH(TEXT(C$7,"yyyy-mm-dd")&"|"&"Lunch",'Meal Plan'!$AE$5:$AE$504,0)),"")) -> 0 | D10: =IF(D$7="","",IFERROR(INDEX('Meal Plan'!$H$5:$H$504,MATCH(TEXT(D$7,"yyyy-mm-dd")&"|"&"Lunch",'Meal Plan'!$AE$5:$AE$504,0)),"")) -> 0 | E10: =IF(E$7="","",IFERROR(INDEX('Meal Plan'!$H$5:$H$504,MATCH(TEXT(E$7,"yyyy-mm-dd")&"|"&"Lunch",'Meal Plan'!$AE$5:$AE$504,0)),"")) -> 0 | F10: =IF(F$7="","",IFERROR(INDEX('Meal Plan'!$H$5:$H$504,MATCH(TEXT(F$7,"yyyy-mm-dd")&"|"&"Lunch",'Meal Plan'!$AE$5:$AE$504,0)),"")) -> 0 | G10: =IF(G$7="","",IFERROR(INDEX('Meal Plan'!$H$5:$H$504,MATCH(TEXT(G$7,"yyyy-mm-dd")&"|"&"Lunch",'Meal Plan'!$AE$5:$AE$504,0)),"")) -> 0 | H10: =IF(H$7="","",IFERROR(INDEX('Meal Plan'!$H$5:$H$504,MATCH(TEXT(H$7,"yyyy-mm-dd")&"|"&"Lunch",'Meal Plan'!$AE$5:$AE$504,0)),"")) -> 0 | I10: =COUNTIFS('Meal Plan'!$B$5:$B$504,">="&WeekPick,'Meal Plan'!$B$5:$B$504,"<="&WeekPick+6,'Meal Plan'!$F$5:$F$504,"Lunch") -> 0
A11: Afternoon snack | B11: =IF(B$7="","",IFERROR(INDEX('Meal Plan'!$H$5:$H$504,MATCH(TEXT(B$7,"yyyy-mm-dd")&"|"&"Afternoon snack",'Meal Plan'!$AE$5:$AE$504,0)),"")) -> 0 | C11: =IF(C$7="","",IFERROR(INDEX('Meal Plan'!$H$5:$H$504,MATCH(TEXT(C$7,"yyyy-mm-dd")&"|"&"Afternoon snack",'Meal Plan'!$AE$5:$AE$504,0)),"")) -> 0 | D11: =IF(D$7="","",IFERROR(INDEX('Meal Plan'!$H$5:$H$504,MATCH(TEXT(D$7,"yyyy-mm-dd")&"|"&"Afternoon snack",'Meal Plan'!$AE$5:$AE$504,0)),"")) -> 0 | E11: =IF(E$7="","",IFERROR(INDEX('Meal Plan'!$H$5:$H$504,MATCH(TEXT(E$7,"yyyy-mm-dd")&"|"&"Afternoon snack",'Meal Plan'!$AE$5:$AE$504,0)),"")) -> 0 | F11: =IF(F$7="","",IFERROR(INDEX('Meal Plan'!$H$5:$H$504,MATCH(TEXT(F$7,"yyyy-mm-dd")&"|"&"Afternoon snack",'Meal Plan'!$AE$5:$AE$504,0)),"")) -> 0 | G11: =IF(G$7="","",IFERROR(INDEX('Meal Plan'!$H$5:$H$504,MATCH(TEXT(G$7,"yyyy-mm-dd")&"|"&"Afternoon snack",'Meal Plan'!$AE$5:$AE$504,0)),"")) -> 0 | H11: =IF(H$7="","",IFERROR(INDEX('Meal Plan'!$H$5:$H$504,MATCH(TEXT(H$7,"yyyy-mm-dd")&"|"&"Afternoon snack",'Meal Plan'!$AE$5:$AE$504,0)),"")) -> 0 | I11: =COUNTIFS('Meal Plan'!$B$5:$B$504,">="&WeekPick,'Meal Plan'!$B$5:$B$504,"<="&WeekPick+6,'Meal Plan'!$F$5:$F$504,"Afternoon snack") -> 0
A12: Dinner | B12: =IF(B$7="","",IFERROR(INDEX('Meal Plan'!$H$5:$H$504,MATCH(TEXT(B$7,"yyyy-mm-dd")&"|"&"Dinner",'Meal Plan'!$AE$5:$AE$504,0)),"")) -> 0 | C12: =IF(C$7="","",IFERROR(INDEX('Meal Plan'!$H$5:$H$504,MATCH(TEXT(C$7,"yyyy-mm-dd")&"|"&"Dinner",'Meal Plan'!$AE$5:$AE$504,0)),"")) -> 0 | D12: =IF(D$7="","",IFERROR(INDEX('Meal Plan'!$H$5:$H$504,MATCH(TEXT(D$7,"yyyy-mm-dd")&"|"&"Dinner",'Meal Plan'!$AE$5:$AE$504,0)),"")) -> 0 | E12: =IF(E$7="","",IFERROR(INDEX('Meal Plan'!$H$5:$H$504,MATCH(TEXT(E$7,"yyyy-mm-dd")&"|"&"Dinner",'Meal Plan'!$AE$5:$AE$504,0)),"")) -> 0 | F12: =IF(F$7="","",IFERROR(INDEX('Meal Plan'!$H$5:$H$504,MATCH(TEXT(F$7,"yyyy-mm-dd")&"|"&"Dinner",'Meal Plan'!$AE$5:$AE$504,0)),"")) -> 0 | G12: =IF(G$7="","",IFERROR(INDEX('Meal Plan'!$H$5:$H$504,MATCH(TEXT(G$7,"yyyy-mm-dd")&"|"&"Dinner",'Meal Plan'!$AE$5:$AE$504,0)),"")) -> 0 | H12: =IF(H$7="","",IFERROR(INDEX('Meal Plan'!$H$5:$H$504,MATCH(TEXT(H$7,"yyyy-mm-dd")&"|"&"Dinner",'Meal Plan'!$AE$5:$AE$504,0)),"")) -> 0 | I12: =COUNTIFS('Meal Plan'!$B$5:$B$504,">="&WeekPick,'Meal Plan'!$B$5:$B$504,"<="&WeekPick+6,'Meal Plan'!$F$5:$F$504,"Dinner") -> 0
A13: Evening snack | B13: =IF(B$7="","",IFERROR(INDEX('Meal Plan'!$H$5:$H$504,MATCH(TEXT(B$7,"yyyy-mm-dd")&"|"&"Evening snack",'Meal Plan'!$AE$5:$AE$504,0)),"")) -> 0 | C13: =IF(C$7="","",IFERROR(INDEX('Meal Plan'!$H$5:$H$504,MATCH(TEXT(C$7,"yyyy-mm-dd")&"|"&"Evening snack",'Meal Plan'!$AE$5:$AE$504,0)),"")) -> 0 | D13: =IF(D$7="","",IFERROR(INDEX('Meal Plan'!$H$5:$H$504,MATCH(TEXT(D$7,"yyyy-mm-dd")&"|"&"Evening snack",'Meal Plan'!$AE$5:$AE$504,0)),"")) -> 0 | E13: =IF(E$7="","",IFERROR(INDEX('Meal Plan'!$H$5:$H$504,MATCH(TEXT(E$7,"yyyy-mm-dd")&"|"&"Evening snack",'Meal Plan'!$AE$5:$AE$504,0)),"")) -> 0 | F13: =IF(F$7="","",IFERROR(INDEX('Meal Plan'!$H$5:$H$504,MATCH(TEXT(F$7,"yyyy-mm-dd")&"|"&"Evening snack",'Meal Plan'!$AE$5:$AE$504,0)),"")) -> 0 | G13: =IF(G$7="","",IFERROR(INDEX('Meal Plan'!$H$5:$H$504,MATCH(TEXT(G$7,"yyyy-mm-dd")&"|"&"Evening snack",'Meal Plan'!$AE$5:$AE$504,0)),"")) -> 0 | H13: =IF(H$7="","",IFERROR(INDEX('Meal Plan'!$H$5:$H$504,MATCH(TEXT(H$7,"yyyy-mm-dd")&"|"&"Evening snack",'Meal Plan'!$AE$5:$AE$504,0)),"")) -> 0 | I13: =COUNTIFS('Meal Plan'!$B$5:$B$504,">="&WeekPick,'Meal Plan'!$B$5:$B$504,"<="&WeekPick+6,'Meal Plan'!$F$5:$F$504,"Evening snack") -> 0
A14: Dessert | B14: =IF(B$7="","",IFERROR(INDEX('Meal Plan'!$H$5:$H$504,MATCH(TEXT(B$7,"yyyy-mm-dd")&"|"&"Dessert",'Meal Plan'!$AE$5:$AE$504,0)),"")) -> 0 | C14: =IF(C$7="","",IFERROR(INDEX('Meal Plan'!$H$5:$H$504,MATCH(TEXT(C$7,"yyyy-mm-dd")&"|"&"Dessert",'Meal Plan'!$AE$5:$AE$504,0)),"")) -> 0 | D14: =IF(D$7="","",IFERROR(INDEX('Meal Plan'!$H$5:$H$504,MATCH(TEXT(D$7,"yyyy-mm-dd")&"|"&"Dessert",'Meal Plan'!$AE$5:$AE$504,0)),"")) -> 0 | E14: =IF(E$7="","",IFERROR(INDEX('Meal Plan'!$H$5:$H$504,MATCH(TEXT(E$7,"yyyy-mm-dd")&"|"&"Dessert",'Meal Plan'!$AE$5:$AE$504,0)),"")) -> 0 | F14: =IF(F$7="","",IFERROR(INDEX('Meal Plan'!$H$5:$H$504,MATCH(TEXT(F$7,"yyyy-mm-dd")&"|"&"Dessert",'Meal Plan'!$AE$5:$AE$504,0)),"")) -> 0 | G14: =IF(G$7="","",IFERROR(INDEX('Meal Plan'!$H$5:$H$504,MATCH(TEXT(G$7,"yyyy-mm-dd")&"|"&"Dessert",'Meal Plan'!$AE$5:$AE$504,0)),"")) -> 0 | H14: =IF(H$7="","",IFERROR(INDEX('Meal Plan'!$H$5:$H$504,MATCH(TEXT(H$7,"yyyy-mm-dd")&"|"&"Dessert",'Meal Plan'!$AE$5:$AE$504,0)),"")) -> 0 | I14: =COUNTIFS('Meal Plan'!$B$5:$B$504,">="&WeekPick,'Meal Plan'!$B$5:$B$504,"<="&WeekPick+6,'Meal Plan'!$F$5:$F$504,"Dessert") -> 0
A15: Cost of the day | B15: =IF(B$7="","",SUMIFS('Meal Plan'!$T$5:$T$504,'Meal Plan'!$B$5:$B$504,B$7)) -> 0 | C15: =IF(C$7="","",SUMIFS('Meal Plan'!$T$5:$T$504,'Meal Plan'!$B$5:$B$504,C$7)) -> 0 | D15: =IF(D$7="","",SUMIFS('Meal Plan'!$T$5:$T$504,'Meal Plan'!$B$5:$B$504,D$7)) -> 0 | E15: =IF(E$7="","",SUMIFS('Meal Plan'!$T$5:$T$504,'Meal Plan'!$B$5:$B$504,E$7)) -> 0 | F15: =IF(F$7="","",SUMIFS('Meal Plan'!$T$5:$T$504,'Meal Plan'!$B$5:$B$504,F$7)) -> 0 | G15: =IF(G$7="","",SUMIFS('Meal Plan'!$T$5:$T$504,'Meal Plan'!$B$5:$B$504,G$7)) -> 0 | H15: =IF(H$7="","",SUMIFS('Meal Plan'!$T$5:$T$504,'Meal Plan'!$B$5:$B$504,H$7)) -> 0 | I15: =SUMIFS('Meal Plan'!$T$5:$T$504,'Meal Plan'!$B$5:$B$504,">="&WeekPick,'Meal Plan'!$B$5:$B$504,"<="&WeekPick+6) -> 0
A16: Calories a head | B16: =IF(B$7="","",IFERROR(SUMIFS('Meal Plan'!$AA$5:$AA$504,'Meal Plan'!$B$5:$B$504,B$7)/DefaultServings,"")) -> 0 | C16: =IF(C$7="","",IFERROR(SUMIFS('Meal Plan'!$AA$5:$AA$504,'Meal Plan'!$B$5:$B$504,C$7)/DefaultServings,"")) -> 0 | D16: =IF(D$7="","",IFERROR(SUMIFS('Meal Plan'!$AA$5:$AA$504,'Meal Plan'!$B$5:$B$504,D$7)/DefaultServings,"")) -> 0 | E16: =IF(E$7="","",IFERROR(SUMIFS('Meal Plan'!$AA$5:$AA$504,'Meal Plan'!$B$5:$B$504,E$7)/DefaultServings,"")) -> 0 | F16: =IF(F$7="","",IFERROR(SUMIFS('Meal Plan'!$AA$5:$AA$504,'Meal Plan'!$B$5:$B$504,F$7)/DefaultServings,"")) -> 0 | G16: =IF(G$7="","",IFERROR(SUMIFS('Meal Plan'!$AA$5:$AA$504,'Meal Plan'!$B$5:$B$504,G$7)/DefaultServings,"")) -> 0 | H16: =IF(H$7="","",IFERROR(SUMIFS('Meal Plan'!$AA$5:$AA$504,'Meal Plan'!$B$5:$B$504,H$7)/DefaultServings,"")) -> 0 | I16: =IFERROR(SUMIFS('Meal Plan'!$AA$5:$AA$504,'Meal Plan'!$B$5:$B$504,">="&WeekPick,'Meal Plan'!$B$5:$B$504,"<="&WeekPick+6)/(DefaultServings*7),"") -> 0
A17: Who is cooking | B17: =IF(B$7="","",IFERROR(INDEX('Meal Plan'!$O$5:$O$504,MATCH(TEXT(B$7,"yyyy-mm-dd")&"|"&"Dinner",'Meal Plan'!$AE$5:$AE$504,0)),"")) -> 0 | C17: =IF(C$7="","",IFERROR(INDEX('Meal Plan'!$O$5:$O$504,MATCH(TEXT(C$7,"yyyy-mm-dd")&"|"&"Dinner",'Meal Plan'!$AE$5:$AE$504,0)),"")) -> 0 | D17: =IF(D$7="","",IFERROR(INDEX('Meal Plan'!$O$5:$O$504,MATCH(TEXT(D$7,"yyyy-mm-dd")&"|"&"Dinner",'Meal Plan'!$AE$5:$AE$504,0)),"")) -> 0 | E17: =IF(E$7="","",IFERROR(INDEX('Meal Plan'!$O$5:$O$504,MATCH(TEXT(E$7,"yyyy-mm-dd")&"|"&"Dinner",'Meal Plan'!$AE$5:$AE$504,0)),"")) -> 0 | F17: =IF(F$7="","",IFERROR(INDEX('Meal Plan'!$O$5:$O$504,MATCH(TEXT(F$7,"yyyy-mm-dd")&"|"&"Dinner",'Meal Plan'!$AE$5:$AE$504,0)),"")) -> 0 | G17: =IF(G$7="","",IFERROR(INDEX('Meal Plan'!$O$5:$O$504,MATCH(TEXT(G$7,"yyyy-mm-dd")&"|"&"Dinner",'Meal Plan'!$AE$5:$AE$504,0)),"")) -> 0 | H17: =IF(H$7="","",IFERROR(INDEX('Meal Plan'!$O$5:$O$504,MATCH(TEXT(H$7,"yyyy-mm-dd")&"|"&"Dinner",'Meal Plan'!$AE$5:$AE$504,0)),"")) -> 0 | I17: =COUNTIFS('Meal Plan'!$B$5:$B$504,">="&WeekPick,'Meal Plan'!$B$5:$B$504,"<="&WeekPick+6,'Meal Plan'!$O$5:$O$504,"<>") -> 0
A19: This week in numbers
A20: Meals planned | C20: Planned food cost | E20: Against the budget | G20: Cooked at home
A21: =COUNTIFS('Meal Plan'!$B$5:$B$504,">="&WeekPick,'Meal Plan'!$B$5:$B$504,"<="&WeekPick+6) -> 0 | C21: =SUMIFS('Meal Plan'!$T$5:$T$504,'Meal Plan'!$B$5:$B$504,">="&WeekPick,'Meal Plan'!$B$5:$B$504,"<="&WeekPick+6) -> 0 | E21: =WeeklyBudget-SUMIFS('Meal Plan'!$T$5:$T$504,'Meal Plan'!$B$5:$B$504,">="&WeekPick,'Meal Plan'!$B$5:$B$504,"<="&WeekPick+6) -> 0 | G21: =COUNTIFS('Meal Plan'!$B$5:$B$504,">="&WeekPick,'Meal Plan'!$B$5:$B$504,"<="&WeekPick+6,'Meal Plan'!$AD$5:$AD$504,"Yes") -> 0
A22: every slot with something in it | C22: recipes only - the shop may differ | E22: green is money left | G22: target 18 a week
A24: Before the week starts
A25: Job | B25: Where it stands | C25: Detail
A26: Shopping list built | B26: =IF(COUNTIF('Grocery List'!$B$5:$B$304,"<>")=0,"Nothing on it","Ready") -> 0 | C26: ="The list covers "&TEXT(ShopFrom,"d mmm")&" to "&TEXT(ShopTo,"d mmm")&" - "&COUNTIF('Grocery List'!$B$5:$B$304,"<>")&" items, about "&TEXT(SUM('Grocery List'!$O$5:$O$304),"0.00") -> 0
A27: Shopping done | B27: =IF(COUNTIF('Grocery List'!$V$5:$V$304,"Yes")=0,"Not started",IF(COUNTIFS('Grocery List'!$I$5:$I$304,">0",'Grocery List'!$V$5:$V$304,"<>Yes")=0,"Done","In progress")) -> 0 | C27: =COUNTIF('Grocery List'!$V$5:$V$304,"Yes")&" of "&COUNTIFS('Grocery List'!$I$5:$I$304,">0")&" items ticked off" -> 0
A28: Prep jobs for this week | B28: =IF(COUNTIFS('Meal Prep'!$C$5:$C$124,">="&WeekPick,'Meal Prep'!$C$5:$C$124,"<="&WeekPick+6)=0,"None planned",IF(COUNTIFS('Meal Prep'!$C$5:$C$124,">="&WeekPick,'Meal Prep'!$C$5:$C$124,"<="&WeekPick+6,'Meal Prep'!$W$5:$W$124,"<>Done")=0,"Done","To do")) -> 0 | C28: =COUNTIFS('Meal Prep'!$C$5:$C$124,">="&WeekPick,'Meal Prep'!$C$5:$C$124,"<="&WeekPick+6)&" job(s) on the prep day" -> 0
A29: Leftovers to eat first | B29: =IF(COUNTIFS(Leftovers!$Q$5:$Q$124,"<>Eaten",Leftovers!$Q$5:$Q$124,"<>Binned")=0,"None","Use soon") -> 0 | C29: =SUMIFS(Leftovers!$F$5:$F$124,Leftovers!$Q$5:$Q$124,"<>Eaten",Leftovers!$Q$5:$Q$124,"<>Binned")&" portion(s) in the fridge or freezer" -> 0
A30: Food about to go off | B30: =IF(COUNTIF(Pantry!$W$5:$W$304,"Use soon")=0,"All good","Use soon") -> 0 | C30: =COUNTIF(Pantry!$W$5:$W$304,"Use soon")&" pantry item(s) within "&ExpiryWarningDays&" days of their date" -> 0
A32: Printing: this page is set to one page wide. Print it on a Sunday, stick it on the fridge and the week looks after itself.

Sheet Monthly Planner
A1: Monthly Meal Planner | E1: Novality Store | v1.0.0
A2: The whole month on one page - dinners, lunches and what each day costs. Print it and pin it up.
A3: > Start Here | C3: > Dashboard | E3: > Recipes
A5: Month | B5: October | C5: First day | D5: =DATE(PlanYear,MAX(1,IFERROR(MATCH(PlanMonthName,MonthList,0),MONTH(TODAY()))),1) -> 0 | E5: Meals planned | F5: =COUNTIFS('Meal Plan'!$B$5:$B$504,">="&PlanMonthStart,'Meal Plan'!$B$5:$B$504,"<="&EOMONTH(PlanMonthStart,0)) -> 0 | G5: =SUMIFS('Meal Plan'!$T$5:$T$504,'Meal Plan'!$B$5:$B$504,">="&PlanMonthStart,'Meal Plan'!$B$5:$B$504,"<="&EOMONTH(PlanMonthStart,0)) -> 0
A6: Each box shows the dinner in bold type, then the lunch, then what the day costs. Empty boxes are days with nothing planned - the gaps are the point.
A7: =TEXT(PlanMonthStart-MOD(WEEKDAY(PlanMonthStart,IF(WeekStart="Sunday",1,2))-1,7)+0,"dddd") -> 0 | B7: =TEXT(PlanMonthStart-MOD(WEEKDAY(PlanMonthStart,IF(WeekStart="Sunday",1,2))-1,7)+1,"dddd") -> 0 | C7: =TEXT(PlanMonthStart-MOD(WEEKDAY(PlanMonthStart,IF(WeekStart="Sunday",1,2))-1,7)+2,"dddd") -> 0 | D7: =TEXT(PlanMonthStart-MOD(WEEKDAY(PlanMonthStart,IF(WeekStart="Sunday",1,2))-1,7)+3,"dddd") -> 0 | E7: =TEXT(PlanMonthStart-MOD(WEEKDAY(PlanMonthStart,IF(WeekStart="Sunday",1,2))-1,7)+4,"dddd") -> 0 | F7: =TEXT(PlanMonthStart-MOD(WEEKDAY(PlanMonthStart,IF(WeekStart="Sunday",1,2))-1,7)+5,"dddd") -> 0 | G7: =TEXT(PlanMonthStart-MOD(WEEKDAY(PlanMonthStart,IF(WeekStart="Sunday",1,2))-1,7)+6,"dddd") -> 0
A8: =PlanMonthStart-MOD(WEEKDAY(PlanMonthStart,IF(WeekStart="Sunday",1,2))-1,7)+0 -> 0 | B8: =PlanMonthStart-MOD(WEEKDAY(PlanMonthStart,IF(WeekStart="Sunday",1,2))-1,7)+1 -> 0 | C8: =PlanMonthStart-MOD(WEEKDAY(PlanMonthStart,IF(WeekStart="Sunday",1,2))-1,7)+2 -> 0 | D8: =PlanMonthStart-MOD(WEEKDAY(PlanMonthStart,IF(WeekStart="Sunday",1,2))-1,7)+3 -> 0 | E8: =PlanMonthStart-MOD(WEEKDAY(PlanMonthStart,IF(WeekStart="Sunday",1,2))-1,7)+4 -> 0 | F8: =PlanMonthStart-MOD(WEEKDAY(PlanMonthStart,IF(WeekStart="Sunday",1,2))-1,7)+5 -> 0 | G8: =PlanMonthStart-MOD(WEEKDAY(PlanMonthStart,IF(WeekStart="Sunday",1,2))-1,7)+6 -> 0
A9: =IF(A$8="","",IFERROR(INDEX('Meal Plan'!$H$5:$H$504,MATCH(TEXT(A$8,"yyyy-mm-dd")&"|"&"Dinner",'Meal Plan'!$AE$5:$AE$504,0)),"")) -> 0 | B9: =IF(B$8="","",IFERROR(INDEX('Meal Plan'!$H$5:$H$504,MATCH(TEXT(B$8,"yyyy-mm-dd")&"|"&"Dinner",'Meal Plan'!$AE$5:$AE$504,0)),"")) -> 0 | C9: =IF(C$8="","",IFERROR(INDEX('Meal Plan'!$H$5:$H$504,MATCH(TEXT(C$8,"yyyy-mm-dd")&"|"&"Dinner",'Meal Plan'!$AE$5:$AE$504,0)),"")) -> 0 | D9: =IF(D$8="","",IFERROR(INDEX('Meal Plan'!$H$5:$H$504,MATCH(TEXT(D$8,"yyyy-mm-dd")&"|"&"Dinner",'Meal Plan'!$AE$5:$AE$504,0)),"")) -> 0 | E9: =IF(E$8="","",IFERROR(INDEX('Meal Plan'!$H$5:$H$504,MATCH(TEXT(E$8,"yyyy-mm-dd")&"|"&"Dinner",'Meal Plan'!$AE$5:$AE$504,0)),"")) -> 0 | F9: =IF(F$8="","",IFERROR(INDEX('Meal Plan'!$H$5:$H$504,MATCH(TEXT(F$8,"yyyy-mm-dd")&"|"&"Dinner",'Meal Plan'!$AE$5:$AE$504,0)),"")) -> 0 | G9: =IF(G$8="","",IFERROR(INDEX('Meal Plan'!$H$5:$H$504,MATCH(TEXT(G$8,"yyyy-mm-dd")&"|"&"Dinner",'Meal Plan'!$AE$5:$AE$504,0)),"")) -> 0
A10: =IF(A$8="","",IFERROR(INDEX('Meal Plan'!$H$5:$H$504,MATCH(TEXT(A$8,"yyyy-mm-dd")&"|"&"Lunch",'Meal Plan'!$AE$5:$AE$504,0)),"")) -> 0 | B10: =IF(B$8="","",IFERROR(INDEX('Meal Plan'!$H$5:$H$504,MATCH(TEXT(B$8,"yyyy-mm-dd")&"|"&"Lunch",'Meal Plan'!$AE$5:$AE$504,0)),"")) -> 0 | C10: =IF(C$8="","",IFERROR(INDEX('Meal Plan'!$H$5:$H$504,MATCH(TEXT(C$8,"yyyy-mm-dd")&"|"&"Lunch",'Meal Plan'!$AE$5:$AE$504,0)),"")) -> 0 | D10: =IF(D$8="","",IFERROR(INDEX('Meal Plan'!$H$5:$H$504,MATCH(TEXT(D$8,"yyyy-mm-dd")&"|"&"Lunch",'Meal Plan'!$AE$5:$AE$504,0)),"")) -> 0 | E10: =IF(E$8="","",IFERROR(INDEX('Meal Plan'!$H$5:$H$504,MATCH(TEXT(E$8,"yyyy-mm-dd")&"|"&"Lunch",'Meal Plan'!$AE$5:$AE$504,0)),"")) -> 0 | F10: =IF(F$8="","",IFERROR(INDEX('Meal Plan'!$H$5:$H$504,MATCH(TEXT(F$8,"yyyy-mm-dd")&"|"&"Lunch",'Meal Plan'!$AE$5:$AE$504,0)),"")) -> 0 | G10: =IF(G$8="","",IFERROR(INDEX('Meal Plan'!$H$5:$H$504,MATCH(TEXT(G$8,"yyyy-mm-dd")&"|"&"Lunch",'Meal Plan'!$AE$5:$AE$504,0)),"")) -> 0
A11: =IF(A$8="","",IF(SUMIFS('Meal Plan'!$T$5:$T$504,'Meal Plan'!$B$5:$B$504,A$8)=0,"",SUMIFS('Meal Plan'!$T$5:$T$504,'Meal Plan'!$B$5:$B$504,A$8))) -> 0 | B11: =IF(B$8="","",IF(SUMIFS('Meal Plan'!$T$5:$T$504,'Meal Plan'!$B$5:$B$504,B$8)=0,"",SUMIFS('Meal Plan'!$T$5:$T$504,'Meal Plan'!$B$5:$B$504,B$8))) -> 0 | C11: =IF(C$8="","",IF(SUMIFS('Meal Plan'!$T$5:$T$504,'Meal Plan'!$B$5:$B$504,C$8)=0,"",SUMIFS('Meal Plan'!$T$5:$T$504,'Meal Plan'!$B$5:$B$504,C$8))) -> 0 | D11: =IF(D$8="","",IF(SUMIFS('Meal Plan'!$T$5:$T$504,'Meal Plan'!$B$5:$B$504,D$8)=0,"",SUMIFS('Meal Plan'!$T$5:$T$504,'Meal Plan'!$B$5:$B$504,D$8))) -> 0 | E11: =IF(E$8="","",IF(SUMIFS('Meal Plan'!$T$5:$T$504,'Meal Plan'!$B$5:$B$504,E$8)=0,"",SUMIFS('Meal Plan'!$T$5:$T$504,'Meal Plan'!$B$5:$B$504,E$8))) -> 0 | F11: =IF(F$8="","",IF(SUMIFS('Meal Plan'!$T$5:$T$504,'Meal Plan'!$B$5:$B$504,F$8)=0,"",SUMIFS('Meal Plan'!$T$5:$T$504,'Meal Plan'!$B$5:$B$504,F$8))) -> 0 | G11: =IF(G$8="","",IF(SUMIFS('Meal Plan'!$T$5:$T$504,'Meal Plan'!$B$5:$B$504,G$8)=0,"",SUMIFS('Meal Plan'!$T$5:$T$504,'Meal Plan'!$B$5:$B$504,G$8))) -> 0
A12: =PlanMonthStart-MOD(WEEKDAY(PlanMonthStart,IF(WeekStart="Sunday",1,2))-1,7)+7 -> 0 | B12: =PlanMonthStart-MOD(WEEKDAY(PlanMonthStart,IF(WeekStart="Sunday",1,2))-1,7)+8 -> 0 | C12: =PlanMonthStart-MOD(WEEKDAY(PlanMonthStart,IF(WeekStart="Sunday",1,2))-1,7)+9 -> 0 | D12: =PlanMonthStart-MOD(WEEKDAY(PlanMonthStart,IF(WeekStart="Sunday",1,2))-1,7)+10 -> 0 | E12: =PlanMonthStart-MOD(WEEKDAY(PlanMonthStart,IF(WeekStart="Sunday",1,2))-1,7)+11 -> 0 | F12: =PlanMonthStart-MOD(WEEKDAY(PlanMonthStart,IF(WeekStart="Sunday",1,2))-1,7)+12 -> 0 | G12: =PlanMonthStart-MOD(WEEKDAY(PlanMonthStart,IF(WeekStart="Sunday",1,2))-1,7)+13 -> 0
A13: =IF(A$12="","",IFERROR(INDEX('Meal Plan'!$H$5:$H$504,MATCH(TEXT(A$12,"yyyy-mm-dd")&"|"&"Dinner",'Meal Plan'!$AE$5:$AE$504,0)),"")) -> 0 | B13: =IF(B$12="","",IFERROR(INDEX('Meal Plan'!$H$5:$H$504,MATCH(TEXT(B$12,"yyyy-mm-dd")&"|"&"Dinner",'Meal Plan'!$AE$5:$AE$504,0)),"")) -> 0 | C13: =IF(C$12="","",IFERROR(INDEX('Meal Plan'!$H$5:$H$504,MATCH(TEXT(C$12,"yyyy-mm-dd")&"|"&"Dinner",'Meal Plan'!$AE$5:$AE$504,0)),"")) -> 0 | D13: =IF(D$12="","",IFERROR(INDEX('Meal Plan'!$H$5:$H$504,MATCH(TEXT(D$12,"yyyy-mm-dd")&"|"&"Dinner",'Meal Plan'!$AE$5:$AE$504,0)),"")) -> 0 | E13: =IF(E$12="","",IFERROR(INDEX('Meal Plan'!$H$5:$H$504,MATCH(TEXT(E$12,"yyyy-mm-dd")&"|"&"Dinner",'Meal Plan'!$AE$5:$AE$504,0)),"")) -> 0 | F13: =IF(F$12="","",IFERROR(INDEX('Meal Plan'!$H$5:$H$504,MATCH(TEXT(F$12,"yyyy-mm-dd")&"|"&"Dinner",'Meal Plan'!$AE$5:$AE$504,0)),"")) -> 0 | G13: =IF(G$12="","",IFERROR(INDEX('Meal Plan'!$H$5:$H$504,MATCH(TEXT(G$12,"yyyy-mm-dd")&"|"&"Dinner",'Meal Plan'!$AE$5:$AE$504,0)),"")) -> 0
A14: =IF(A$12="","",IFERROR(INDEX('Meal Plan'!$H$5:$H$504,MATCH(TEXT(A$12,"yyyy-mm-dd")&"|"&"Lunch",'Meal Plan'!$AE$5:$AE$504,0)),"")) -> 0 | B14: =IF(B$12="","",IFERROR(INDEX('Meal Plan'!$H$5:$H$504,MATCH(TEXT(B$12,"yyyy-mm-dd")&"|"&"Lunch",'Meal Plan'!$AE$5:$AE$504,0)),"")) -> 0 | C14: =IF(C$12="","",IFERROR(INDEX('Meal Plan'!$H$5:$H$504,MATCH(TEXT(C$12,"yyyy-mm-dd")&"|"&"Lunch",'Meal Plan'!$AE$5:$AE$504,0)),"")) -> 0 | D14: =IF(D$12="","",IFERROR(INDEX('Meal Plan'!$H$5:$H$504,MATCH(TEXT(D$12,"yyyy-mm-dd")&"|"&"Lunch",'Meal Plan'!$AE$5:$AE$504,0)),"")) -> 0 | E14: =IF(E$12="","",IFERROR(INDEX('Meal Plan'!$H$5:$H$504,MATCH(TEXT(E$12,"yyyy-mm-dd")&"|"&"Lunch",'Meal Plan'!$AE$5:$AE$504,0)),"")) -> 0 | F14: =IF(F$12="","",IFERROR(INDEX('Meal Plan'!$H$5:$H$504,MATCH(TEXT(F$12,"yyyy-mm-dd")&"|"&"Lunch",'Meal Plan'!$AE$5:$AE$504,0)),"")) -> 0 | G14: =IF(G$12="","",IFERROR(INDEX('Meal Plan'!$H$5:$H$504,MATCH(TEXT(G$12,"yyyy-mm-dd")&"|"&"Lunch",'Meal Plan'!$AE$5:$AE$504,0)),"")) -> 0
A15: =IF(A$12="","",IF(SUMIFS('Meal Plan'!$T$5:$T$504,'Meal Plan'!$B$5:$B$504,A$12)=0,"",SUMIFS('Meal Plan'!$T$5:$T$504,'Meal Plan'!$B$5:$B$504,A$12))) -> 0 | B15: =IF(B$12="","",IF(SUMIFS('Meal Plan'!$T$5:$T$504,'Meal Plan'!$B$5:$B$504,B$12)=0,"",SUMIFS('Meal Plan'!$T$5:$T$504,'Meal Plan'!$B$5:$B$504,B$12))) -> 0 | C15: =IF(C$12="","",IF(SUMIFS('Meal Plan'!$T$5:$T$504,'Meal Plan'!$B$5:$B$504,C$12)=0,"",SUMIFS('Meal Plan'!$T$5:$T$504,'Meal Plan'!$B$5:$B$504,C$12))) -> 0 | D15: =IF(D$12="","",IF(SUMIFS('Meal Plan'!$T$5:$T$504,'Meal Plan'!$B$5:$B$504,D$12)=0,"",SUMIFS('Meal Plan'!$T$5:$T$504,'Meal Plan'!$B$5:$B$504,D$12))) -> 0 | E15: =IF(E$12="","",IF(SUMIFS('Meal Plan'!$T$5:$T$504,'Meal Plan'!$B$5:$B$504,E$12)=0,"",SUMIFS('Meal Plan'!$T$5:$T$504,'Meal Plan'!$B$5:$B$504,E$12))) -> 0 | F15: =IF(F$12="","",IF(SUMIFS('Meal Plan'!$T$5:$T$504,'Meal Plan'!$B$5:$B$504,F$12)=0,"",SUMIFS('Meal Plan'!$T$5:$T$504,'Meal Plan'!$B$5:$B$504,F$12))) -> 0 | G15: =IF(G$12="","",IF(SUMIFS('Meal Plan'!$T$5:$T$504,'Meal Plan'!$B$5:$B$504,G$12)=0,"",SUMIFS('Meal Plan'!$T$5:$T$504,'Meal Plan'!$B$5:$B$504,G$12))) -> 0
A16: =PlanMonthStart-MOD(WEEKDAY(PlanMonthStart,IF(WeekStart="Sunday",1,2))-1,7)+14 -> 0 | B16: =PlanMonthStart-MOD(WEEKDAY(PlanMonthStart,IF(WeekStart="Sunday",1,2))-1,7)+15 -> 0 | C16: =PlanMonthStart-MOD(WEEKDAY(PlanMonthStart,IF(WeekStart="Sunday",1,2))-1,7)+16 -> 0 | D16: =PlanMonthStart-MOD(WEEKDAY(PlanMonthStart,IF(WeekStart="Sunday",1,2))-1,7)+17 -> 0 | E16: =PlanMonthStart-MOD(WEEKDAY(PlanMonthStart,IF(WeekStart="Sunday",1,2))-1,7)+18 -> 0 | F16: =PlanMonthStart-MOD(WEEKDAY(PlanMonthStart,IF(WeekStart="Sunday",1,2))-1,7)+19 -> 0 | G16: =PlanMonthStart-MOD(WEEKDAY(PlanMonthStart,IF(WeekStart="Sunday",1,2))-1,7)+20 -> 0
A17: =IF(A$16="","",IFERROR(INDEX('Meal Plan'!$H$5:$H$504,MATCH(TEXT(A$16,"yyyy-mm-dd")&"|"&"Dinner",'Meal Plan'!$AE$5:$AE$504,0)),"")) -> 0 | B17: =IF(B$16="","",IFERROR(INDEX('Meal Plan'!$H$5:$H$504,MATCH(TEXT(B$16,"yyyy-mm-dd")&"|"&"Dinner",'Meal Plan'!$AE$5:$AE$504,0)),"")) -> 0 | C17: =IF(C$16="","",IFERROR(INDEX('Meal Plan'!$H$5:$H$504,MATCH(TEXT(C$16,"yyyy-mm-dd")&"|"&"Dinner",'Meal Plan'!$AE$5:$AE$504,0)),"")) -> 0 | D17: =IF(D$16="","",IFERROR(INDEX('Meal Plan'!$H$5:$H$504,MATCH(TEXT(D$16,"yyyy-mm-dd")&"|"&"Dinner",'Meal Plan'!$AE$5:$AE$504,0)),"")) -> 0 | E17: =IF(E$16="","",IFERROR(INDEX('Meal Plan'!$H$5:$H$504,MATCH(TEXT(E$16,"yyyy-mm-dd")&"|"&"Dinner",'Meal Plan'!$AE$5:$AE$504,0)),"")) -> 0 | F17: =IF(F$16="","",IFERROR(INDEX('Meal Plan'!$H$5:$H$504,MATCH(TEXT(F$16,"yyyy-mm-dd")&"|"&"Dinner",'Meal Plan'!$AE$5:$AE$504,0)),"")) -> 0 | G17: =IF(G$16="","",IFERROR(INDEX('Meal Plan'!$H$5:$H$504,MATCH(TEXT(G$16,"yyyy-mm-dd")&"|"&"Dinner",'Meal Plan'!$AE$5:$AE$504,0)),"")) -> 0
A18: =IF(A$16="","",IFERROR(INDEX('Meal Plan'!$H$5:$H$504,MATCH(TEXT(A$16,"yyyy-mm-dd")&"|"&"Lunch",'Meal Plan'!$AE$5:$AE$504,0)),"")) -> 0 | B18: =IF(B$16="","",IFERROR(INDEX('Meal Plan'!$H$5:$H$504,MATCH(TEXT(B$16,"yyyy-mm-dd")&"|"&"Lunch",'Meal Plan'!$AE$5:$AE$504,0)),"")) -> 0 | C18: =IF(C$16="","",IFERROR(INDEX('Meal Plan'!$H$5:$H$504,MATCH(TEXT(C$16,"yyyy-mm-dd")&"|"&"Lunch",'Meal Plan'!$AE$5:$AE$504,0)),"")) -> 0 | D18: =IF(D$16="","",IFERROR(INDEX('Meal Plan'!$H$5:$H$504,MATCH(TEXT(D$16,"yyyy-mm-dd")&"|"&"Lunch",'Meal Plan'!$AE$5:$AE$504,0)),"")) -> 0 | E18: =IF(E$16="","",IFERROR(INDEX('Meal Plan'!$H$5:$H$504,MATCH(TEXT(E$16,"yyyy-mm-dd")&"|"&"Lunch",'Meal Plan'!$AE$5:$AE$504,0)),"")) -> 0 | F18: =IF(F$16="","",IFERROR(INDEX('Meal Plan'!$H$5:$H$504,MATCH(TEXT(F$16,"yyyy-mm-dd")&"|"&"Lunch",'Meal Plan'!$AE$5:$AE$504,0)),"")) -> 0 | G18: =IF(G$16="","",IFERROR(INDEX('Meal Plan'!$H$5:$H$504,MATCH(TEXT(G$16,"yyyy-mm-dd")&"|"&"Lunch",'Meal Plan'!$AE$5:$AE$504,0)),"")) -> 0
A19: =IF(A$16="","",IF(SUMIFS('Meal Plan'!$T$5:$T$504,'Meal Plan'!$B$5:$B$504,A$16)=0,"",SUMIFS('Meal Plan'!$T$5:$T$504,'Meal Plan'!$B$5:$B$504,A$16))) -> 0 | B19: =IF(B$16="","",IF(SUMIFS('Meal Plan'!$T$5:$T$504,'Meal Plan'!$B$5:$B$504,B$16)=0,"",SUMIFS('Meal Plan'!$T$5:$T$504,'Meal Plan'!$B$5:$B$504,B$16))) -> 0 | C19: =IF(C$16="","",IF(SUMIFS('Meal Plan'!$T$5:$T$504,'Meal Plan'!$B$5:$B$504,C$16)=0,"",SUMIFS('Meal Plan'!$T$5:$T$504,'Meal Plan'!$B$5:$B$504,C$16))) -> 0 | D19: =IF(D$16="","",IF(SUMIFS('Meal Plan'!$T$5:$T$504,'Meal Plan'!$B$5:$B$504,D$16)=0,"",SUMIFS('Meal Plan'!$T$5:$T$504,'Meal Plan'!$B$5:$B$504,D$16))) -> 0 | E19: =IF(E$16="","",IF(SUMIFS('Meal Plan'!$T$5:$T$504,'Meal Plan'!$B$5:$B$504,E$16)=0,"",SUMIFS('Meal Plan'!$T$5:$T$504,'Meal Plan'!$B$5:$B$504,E$16))) -> 0 | F19: =IF(F$16="","",IF(SUMIFS('Meal Plan'!$T$5:$T$504,'Meal Plan'!$B$5:$B$504,F$16)=0,"",SUMIFS('Meal Plan'!$T$5:$T$504,'Meal Plan'!$B$5:$B$504,F$16))) -> 0 | G19: =IF(G$16="","",IF(SUMIFS('Meal Plan'!$T$5:$T$504,'Meal Plan'!$B$5:$B$504,G$16)=0,"",SUMIFS('Meal Plan'!$T$5:$T$504,'Meal Plan'!$B$5:$B$504,G$16))) -> 0
A20: =PlanMonthStart-MOD(WEEKDAY(PlanMonthStart,IF(WeekStart="Sunday",1,2))-1,7)+21 -> 0 | B20: =PlanMonthStart-MOD(WEEKDAY(PlanMonthStart,IF(WeekStart="Sunday",1,2))-1,7)+22 -> 0 | C20: =PlanMonthStart-MOD(WEEKDAY(PlanMonthStart,IF(WeekStart="Sunday",1,2))-1,7)+23 -> 0 | D20: =PlanMonthStart-MOD(WEEKDAY(PlanMonthStart,IF(WeekStart="Sunday",1,2))-1,7)+24 -> 0 | E20: =PlanMonthStart-MOD(WEEKDAY(PlanMonthStart,IF(WeekStart="Sunday",1,2))-1,7)+25 -> 0 | F20: =PlanMonthStart-MOD(WEEKDAY(PlanMonthStart,IF(WeekStart="Sunday",1,2))-1,7)+26 -> 0 | G20: =PlanMonthStart-MOD(WEEKDAY(PlanMonthStart,IF(WeekStart="Sunday",1,2))-1,7)+27 -> 0
A21: =IF(A$20="","",IFERROR(INDEX('Meal Plan'!$H$5:$H$504,MATCH(TEXT(A$20,"yyyy-mm-dd")&"|"&"Dinner",'Meal Plan'!$AE$5:$AE$504,0)),"")) -> 0 | B21: =IF(B$20="","",IFERROR(INDEX('Meal Plan'!$H$5:$H$504,MATCH(TEXT(B$20,"yyyy-mm-dd")&"|"&"Dinner",'Meal Plan'!$AE$5:$AE$504,0)),"")) -> 0 | C21: =IF(C$20="","",IFERROR(INDEX('Meal Plan'!$H$5:$H$504,MATCH(TEXT(C$20,"yyyy-mm-dd")&"|"&"Dinner",'Meal Plan'!$AE$5:$AE$504,0)),"")) -> 0 | D21: =IF(D$20="","",IFERROR(INDEX('Meal Plan'!$H$5:$H$504,MATCH(TEXT(D$20,"yyyy-mm-dd")&"|"&"Dinner",'Meal Plan'!$AE$5:$AE$504,0)),"")) -> 0 | E21: =IF(E$20="","",IFERROR(INDEX('Meal Plan'!$H$5:$H$504,MATCH(TEXT(E$20,"yyyy-mm-dd")&"|"&"Dinner",'Meal Plan'!$AE$5:$AE$504,0)),"")) -> 0 | F21: =IF(F$20="","",IFERROR(INDEX('Meal Plan'!$H$5:$H$504,MATCH(TEXT(F$20,"yyyy-mm-dd")&"|"&"Dinner",'Meal Plan'!$AE$5:$AE$504,0)),"")) -> 0 | G21: =IF(G$20="","",IFERROR(INDEX('Meal Plan'!$H$5:$H$504,MATCH(TEXT(G$20,"yyyy-mm-dd")&"|"&"Dinner",'Meal Plan'!$AE$5:$AE$504,0)),"")) -> 0
A22: =IF(A$20="","",IFERROR(INDEX('Meal Plan'!$H$5:$H$504,MATCH(TEXT(A$20,"yyyy-mm-dd")&"|"&"Lunch",'Meal Plan'!$AE$5:$AE$504,0)),"")) -> 0 | B22: =IF(B$20="","",IFERROR(INDEX('Meal Plan'!$H$5:$H$504,MATCH(TEXT(B$20,"yyyy-mm-dd")&"|"&"Lunch",'Meal Plan'!$AE$5:$AE$504,0)),"")) -> 0 | C22: =IF(C$20="","",IFERROR(INDEX('Meal Plan'!$H$5:$H$504,MATCH(TEXT(C$20,"yyyy-mm-dd")&"|"&"Lunch",'Meal Plan'!$AE$5:$AE$504,0)),"")) -> 0 | D22: =IF(D$20="","",IFERROR(INDEX('Meal Plan'!$H$5:$H$504,MATCH(TEXT(D$20,"yyyy-mm-dd")&"|"&"Lunch",'Meal Plan'!$AE$5:$AE$504,0)),"")) -> 0 | E22: =IF(E$20="","",IFERROR(INDEX('Meal Plan'!$H$5:$H$504,MATCH(TEXT(E$20,"yyyy-mm-dd")&"|"&"Lunch",'Meal Plan'!$AE$5:$AE$504,0)),"")) -> 0 | F22: =IF(F$20="","",IFERROR(INDEX('Meal Plan'!$H$5:$H$504,MATCH(TEXT(F$20,"yyyy-mm-dd")&"|"&"Lunch",'Meal Plan'!$AE$5:$AE$504,0)),"")) -> 0 | G22: =IF(G$20="","",IFERROR(INDEX('Meal Plan'!$H$5:$H$504,MATCH(TEXT(G$20,"yyyy-mm-dd")&"|"&"Lunch",'Meal Plan'!$AE$5:$AE$504,0)),"")) -> 0
A23: =IF(A$20="","",IF(SUMIFS('Meal Plan'!$T$5:$T$504,'Meal Plan'!$B$5:$B$504,A$20)=0,"",SUMIFS('Meal Plan'!$T$5:$T$504,'Meal Plan'!$B$5:$B$504,A$20))) -> 0 | B23: =IF(B$20="","",IF(SUMIFS('Meal Plan'!$T$5:$T$504,'Meal Plan'!$B$5:$B$504,B$20)=0,"",SUMIFS('Meal Plan'!$T$5:$T$504,'Meal Plan'!$B$5:$B$504,B$20))) -> 0 | C23: =IF(C$20="","",IF(SUMIFS('Meal Plan'!$T$5:$T$504,'Meal Plan'!$B$5:$B$504,C$20)=0,"",SUMIFS('Meal Plan'!$T$5:$T$504,'Meal Plan'!$B$5:$B$504,C$20))) -> 0 | D23: =IF(D$20="","",IF(SUMIFS('Meal Plan'!$T$5:$T$504,'Meal Plan'!$B$5:$B$504,D$20)=0,"",SUMIFS('Meal Plan'!$T$5:$T$504,'Meal Plan'!$B$5:$B$504,D$20))) -> 0 | E23: =IF(E$20="","",IF(SUMIFS('Meal Plan'!$T$5:$T$504,'Meal Plan'!$B$5:$B$504,E$20)=0,"",SUMIFS('Meal Plan'!$T$5:$T$504,'Meal Plan'!$B$5:$B$504,E$20))) -> 0 | F23: =IF(F$20="","",IF(SUMIFS('Meal Plan'!$T$5:$T$504,'Meal Plan'!$B$5:$B$504,F$20)=0,"",SUMIFS('Meal Plan'!$T$5:$T$504,'Meal Plan'!$B$5:$B$504,F$20))) -> 0 | G23: =IF(G$20="","",IF(SUMIFS('Meal Plan'!$T$5:$T$504,'Meal Plan'!$B$5:$B$504,G$20)=0,"",SUMIFS('Meal Plan'!$T$5:$T$504,'Meal Plan'!$B$5:$B$504,G$20))) -> 0
A24: =PlanMonthStart-MOD(WEEKDAY(PlanMonthStart,IF(WeekStart="Sunday",1,2))-1,7)+28 -> 0 | B24: =PlanMonthStart-MOD(WEEKDAY(PlanMonthStart,IF(WeekStart="Sunday",1,2))-1,7)+29 -> 0 | C24: =PlanMonthStart-MOD(WEEKDAY(PlanMonthStart,IF(WeekStart="Sunday",1,2))-1,7)+30 -> 0 | D24: =PlanMonthStart-MOD(WEEKDAY(PlanMonthStart,IF(WeekStart="Sunday",1,2))-1,7)+31 -> 0 | E24: =PlanMonthStart-MOD(WEEKDAY(PlanMonthStart,IF(WeekStart="Sunday",1,2))-1,7)+32 -> 0 | F24: =PlanMonthStart-MOD(WEEKDAY(PlanMonthStart,IF(WeekStart="Sunday",1,2))-1,7)+33 -> 0 | G24: =PlanMonthStart-MOD(WEEKDAY(PlanMonthStart,IF(WeekStart="Sunday",1,2))-1,7)+34 -> 0
A25: =IF(A$24="","",IFERROR(INDEX('Meal Plan'!$H$5:$H$504,MATCH(TEXT(A$24,"yyyy-mm-dd")&"|"&"Dinner",'Meal Plan'!$AE$5:$AE$504,0)),"")) -> 0 | B25: =IF(B$24="","",IFERROR(INDEX('Meal Plan'!$H$5:$H$504,MATCH(TEXT(B$24,"yyyy-mm-dd")&"|"&"Dinner",'Meal Plan'!$AE$5:$AE$504,0)),"")) -> 0 | C25: =IF(C$24="","",IFERROR(INDEX('Meal Plan'!$H$5:$H$504,MATCH(TEXT(C$24,"yyyy-mm-dd")&"|"&"Dinner",'Meal Plan'!$AE$5:$AE$504,0)),"")) -> 0 | D25: =IF(D$24="","",IFERROR(INDEX('Meal Plan'!$H$5:$H$504,MATCH(TEXT(D$24,"yyyy-mm-dd")&"|"&"Dinner",'Meal Plan'!$AE$5:$AE$504,0)),"")) -> 0 | E25: =IF(E$24="","",IFERROR(INDEX('Meal Plan'!$H$5:$H$504,MATCH(TEXT(E$24,"yyyy-mm-dd")&"|"&"Dinner",'Meal Plan'!$AE$5:$AE$504,0)),"")) -> 0 | F25: =IF(F$24="","",IFERROR(INDEX('Meal Plan'!$H$5:$H$504,MATCH(TEXT(F$24,"yyyy-mm-dd")&"|"&"Dinner",'Meal Plan'!$AE$5:$AE$504,0)),"")) -> 0 | G25: =IF(G$24="","",IFERROR(INDEX('Meal Plan'!$H$5:$H$504,MATCH(TEXT(G$24,"yyyy-mm-dd")&"|"&"Dinner",'Meal Plan'!$AE$5:$AE$504,0)),"")) -> 0
A26: =IF(A$24="","",IFERROR(INDEX('Meal Plan'!$H$5:$H$504,MATCH(TEXT(A$24,"yyyy-mm-dd")&"|"&"Lunch",'Meal Plan'!$AE$5:$AE$504,0)),"")) -> 0 | B26: =IF(B$24="","",IFERROR(INDEX('Meal Plan'!$H$5:$H$504,MATCH(TEXT(B$24,"yyyy-mm-dd")&"|"&"Lunch",'Meal Plan'!$AE$5:$AE$504,0)),"")) -> 0 | C26: =IF(C$24="","",IFERROR(INDEX('Meal Plan'!$H$5:$H$504,MATCH(TEXT(C$24,"yyyy-mm-dd")&"|"&"Lunch",'Meal Plan'!$AE$5:$AE$504,0)),"")) -> 0 | D26: =IF(D$24="","",IFERROR(INDEX('Meal Plan'!$H$5:$H$504,MATCH(TEXT(D$24,"yyyy-mm-dd")&"|"&"Lunch",'Meal Plan'!$AE$5:$AE$504,0)),"")) -> 0 | E26: =IF(E$24="","",IFERROR(INDEX('Meal Plan'!$H$5:$H$504,MATCH(TEXT(E$24,"yyyy-mm-dd")&"|"&"Lunch",'Meal Plan'!$AE$5:$AE$504,0)),"")) -> 0 | F26: =IF(F$24="","",IFERROR(INDEX('Meal Plan'!$H$5:$H$504,MATCH(TEXT(F$24,"yyyy-mm-dd")&"|"&"Lunch",'Meal Plan'!$AE$5:$AE$504,0)),"")) -> 0 | G26: =IF(G$24="","",IFERROR(INDEX('Meal Plan'!$H$5:$H$504,MATCH(TEXT(G$24,"yyyy-mm-dd")&"|"&"Lunch",'Meal Plan'!$AE$5:$AE$504,0)),"")) -> 0
A27: =IF(A$24="","",IF(SUMIFS('Meal Plan'!$T$5:$T$504,'Meal Plan'!$B$5:$B$504,A$24)=0,"",SUMIFS('Meal Plan'!$T$5:$T$504,'Meal Plan'!$B$5:$B$504,A$24))) -> 0 | B27: =IF(B$24="","",IF(SUMIFS('Meal Plan'!$T$5:$T$504,'Meal Plan'!$B$5:$B$504,B$24)=0,"",SUMIFS('Meal Plan'!$T$5:$T$504,'Meal Plan'!$B$5:$B$504,B$24))) -> 0 | C27: =IF(C$24="","",IF(SUMIFS('Meal Plan'!$T$5:$T$504,'Meal Plan'!$B$5:$B$504,C$24)=0,"",SUMIFS('Meal Plan'!$T$5:$T$504,'Meal Plan'!$B$5:$B$504,C$24))) -> 0 | D27: =IF(D$24="","",IF(SUMIFS('Meal Plan'!$T$5:$T$504,'Meal Plan'!$B$5:$B$504,D$24)=0,"",SUMIFS('Meal Plan'!$T$5:$T$504,'Meal Plan'!$B$5:$B$504,D$24))) -> 0 | E27: =IF(E$24="","",IF(SUMIFS('Meal Plan'!$T$5:$T$504,'Meal Plan'!$B$5:$B$504,E$24)=0,"",SUMIFS('Meal Plan'!$T$5:$T$504,'Meal Plan'!$B$5:$B$504,E$24))) -> 0 | F27: =IF(F$24="","",IF(SUMIFS('Meal Plan'!$T$5:$T$504,'Meal Plan'!$B$5:$B$504,F$24)=0,"",SUMIFS('Meal Plan'!$T$5:$T$504,'Meal Plan'!$B$5:$B$504,F$24))) -> 0 | G27: =IF(G$24="","",IF(SUMIFS('Meal Plan'!$T$5:$T$504,'Meal Plan'!$B$5:$B$504,G$24)=0,"",SUMIFS('Meal Plan'!$T$5:$T$504,'Meal Plan'!$B$5:$B$504,G$24))) -> 0
A28: =PlanMonthStart-MOD(WEEKDAY(PlanMonthStart,IF(WeekStart="Sunday",1,2))-1,7)+35 -> 0 | B28: =PlanMonthStart-MOD(WEEKDAY(PlanMonthStart,IF(WeekStart="Sunday",1,2))-1,7)+36 -> 0 | C28: =PlanMonthStart-MOD(WEEKDAY(PlanMonthStart,IF(WeekStart="Sunday",1,2))-1,7)+37 -> 0 | D28: =PlanMonthStart-MOD(WEEKDAY(PlanMonthStart,IF(WeekStart="Sunday",1,2))-1,7)+38 -> 0 | E28: =PlanMonthStart-MOD(WEEKDAY(PlanMonthStart,IF(WeekStart="Sunday",1,2))-1,7)+39 -> 0 | F28: =PlanMonthStart-MOD(WEEKDAY(PlanMonthStart,IF(WeekStart="Sunday",1,2))-1,7)+40 -> 0 | G28: =PlanMonthStart-MOD(WEEKDAY(PlanMonthStart,IF(WeekStart="Sunday",1,2))-1,7)+41 -> 0
A29: =IF(A$28="","",IFERROR(INDEX('Meal Plan'!$H$5:$H$504,MATCH(TEXT(A$28,"yyyy-mm-dd")&"|"&"Dinner",'Meal Plan'!$AE$5:$AE$504,0)),"")) -> 0 | B29: =IF(B$28="","",IFERROR(INDEX('Meal Plan'!$H$5:$H$504,MATCH(TEXT(B$28,"yyyy-mm-dd")&"|"&"Dinner",'Meal Plan'!$AE$5:$AE$504,0)),"")) -> 0 | C29: =IF(C$28="","",IFERROR(INDEX('Meal Plan'!$H$5:$H$504,MATCH(TEXT(C$28,"yyyy-mm-dd")&"|"&"Dinner",'Meal Plan'!$AE$5:$AE$504,0)),"")) -> 0 | D29: =IF(D$28="","",IFERROR(INDEX('Meal Plan'!$H$5:$H$504,MATCH(TEXT(D$28,"yyyy-mm-dd")&"|"&"Dinner",'Meal Plan'!$AE$5:$AE$504,0)),"")) -> 0 | E29: =IF(E$28="","",IFERROR(INDEX('Meal Plan'!$H$5:$H$504,MATCH(TEXT(E$28,"yyyy-mm-dd")&"|"&"Dinner",'Meal Plan'!$AE$5:$AE$504,0)),"")) -> 0 | F29: =IF(F$28="","",IFERROR(INDEX('Meal Plan'!$H$5:$H$504,MATCH(TEXT(F$28,"yyyy-mm-dd")&"|"&"Dinner",'Meal Plan'!$AE$5:$AE$504,0)),"")) -> 0 | G29: =IF(G$28="","",IFERROR(INDEX('Meal Plan'!$H$5:$H$504,MATCH(TEXT(G$28,"yyyy-mm-dd")&"|"&"Dinner",'Meal Plan'!$AE$5:$AE$504,0)),"")) -> 0
A30: =IF(A$28="","",IFERROR(INDEX('Meal Plan'!$H$5:$H$504,MATCH(TEXT(A$28,"yyyy-mm-dd")&"|"&"Lunch",'Meal Plan'!$AE$5:$AE$504,0)),"")) -> 0 | B30: =IF(B$28="","",IFERROR(INDEX('Meal Plan'!$H$5:$H$504,MATCH(TEXT(B$28,"yyyy-mm-dd")&"|"&"Lunch",'Meal Plan'!$AE$5:$AE$504,0)),"")) -> 0 | C30: =IF(C$28="","",IFERROR(INDEX('Meal Plan'!$H$5:$H$504,MATCH(TEXT(C$28,"yyyy-mm-dd")&"|"&"Lunch",'Meal Plan'!$AE$5:$AE$504,0)),"")) -> 0 | D30: =IF(D$28="","",IFERROR(INDEX('Meal Plan'!$H$5:$H$504,MATCH(TEXT(D$28,"yyyy-mm-dd")&"|"&"Lunch",'Meal Plan'!$AE$5:$AE$504,0)),"")) -> 0 | E30: =IF(E$28="","",IFERROR(INDEX('Meal Plan'!$H$5:$H$504,MATCH(TEXT(E$28,"yyyy-mm-dd")&"|"&"Lunch",'Meal Plan'!$AE$5:$AE$504,0)),"")) -> 0 | F30: =IF(F$28="","",IFERROR(INDEX('Meal Plan'!$H$5:$H$504,MATCH(TEXT(F$28,"yyyy-mm-dd")&"|"&"Lunch",'Meal Plan'!$AE$5:$AE$504,0)),"")) -> 0 | G30: =IF(G$28="","",IFERROR(INDEX('Meal Plan'!$H$5:$H$504,MATCH(TEXT(G$28,"yyyy-mm-dd")&"|"&"Lunch",'Meal Plan'!$AE$5:$AE$504,0)),"")) -> 0
