Workbook
Name AppetiteList: OFFSET(Lists!$T$5,0,0,MAX(1,COUNTIF(Lists!$T$5:$T$44,"?*")),1)
Name BillingUnitList: OFFSET(Lists!$M$5,0,0,MAX(1,COUNTIF(Lists!$M$5:$M$44,"?*")),1)
Name Biz_Address: Settings!$D$11
Name Biz_Bank: Settings!$D$17
Name Biz_City: Settings!$D$12
Name Biz_Country: Settings!$D$15
Name Biz_Email: Settings!$D$9
Name Biz_InsuranceRenewal: Settings!$D$20
Name Biz_Insurer: Settings!$D$18
Name Biz_Licence: Settings!$D$21
Name Biz_LicenceRenewal: Settings!$D$22
Name Biz_Name: Settings!$D$6
Name Biz_Owner: Settings!$D$7
Name Biz_Phone: Settings!$D$8
Name Biz_Policy: Settings!$D$19
Name Biz_Post: Settings!$D$14
Name Biz_State: Settings!$D$13
Name Biz_TaxID: Settings!$D$16
Name Biz_Web: Settings!$D$10
Name BookingIDs: OFFSET(Bookings!$A$5,0,0,MAX(1,COUNTIF(Bookings!$A$5:$A$404,"?*")),1)
Name BookingPrefix: Settings!$D$54
Name BookingStatusList: OFFSET(Lists!$N$5,0,0,MAX(1,COUNTIF(Lists!$N$5:$N$44,"?*")),1)
Name BusinessPersonalList: OFFSET(Lists!$AI$5,0,0,MAX(1,COUNTIF(Lists!$AI$5:$AI$44,"?*")),1)
Name CancelReasonList: OFFSET(Lists!$Q$5,0,0,MAX(1,COUNTIF(Lists!$Q$5:$Q$44,"?*")),1)
Name ChannelList: OFFSET(Lists!$AB$5,0,0,MAX(1,COUNTIF(Lists!$AB$5:$AB$44,"?*")),1)
Name ClientIDs: OFFSET(Clients!$A$5,0,0,MAX(1,COUNTIF(Clients!$A$5:$A$254,"?*")),1)
Name ClientNames: OFFSET(Clients!$B$5,0,0,MAX(1,COUNTIF(Clients!$B$5:$B$254,"?*")),1)
Name ClientPrefix: Settings!$D$52
Name ClientStatusList: OFFSET(Lists!$C$5,0,0,MAX(1,COUNTIF(Lists!$C$5:$C$44,"?*")),1)
Name ContactMethodList: OFFSET(Lists!$D$5,0,0,MAX(1,COUNTIF(Lists!$D$5:$D$44,"?*")),1)
Name ContractStatusList: OFFSET(Lists!$F$5,0,0,MAX(1,COUNTIF(Lists!$F$5:$F$44,"?*")),1)
Name CurrencyCode: Settings!$D$33
Name CurrencySymbol: Settings!$D$32
Name Dash_Expenses: Dashboard!$M$10
Name Dash_MonthName: Dashboard!$F$6
Name Dash_Profit: Dashboard!$P$10
Name Dash_Revenue: Dashboard!$A$10
Name Dash_Year: Dashboard!$C$6
Name DayEnd: Settings!$D$80
Name DayStart: Settings!$D$79
Name DefaultVisitMins: Settings!$D$78
Name DepositPct: Settings!$D$50
Name DirectionList: OFFSET(Lists!$AC$5,0,0,MAX(1,COUNTIF(Lists!$AC$5:$AC$44,"?*")),1)
Name DiscountTypeList: OFFSET(Lists!$P$5,0,0,MAX(1,COUNTIF(Lists!$P$5:$P$44,"?*")),1)
Name DistanceUnit: Settings!$D$36
Name EmergencyFee: Settings!$D$60
Name EmploymentTypeList: OFFSET(Lists!$AM$5,0,0,MAX(1,COUNTIF(Lists!$AM$5:$AM$44,"?*")),1)
Name ExpenseApprovalList: OFFSET(Lists!$AH$5,0,0,MAX(1,COUNTIF(Lists!$AH$5:$AH$44,"?*")),1)
Name ExpenseCategoryList: OFFSET(Lists!$AG$5,0,0,MAX(1,COUNTIF(Lists!$AG$5:$AG$44,"?*")),1)
Name ExpiryAlertDays: Settings!$D$77
Name ExtraPetFeeDefault: Settings!$D$57
Name FixedCosts: Budget!$B$10
Name FollowUpDays: Settings!$D$76
Name FreeTravelDistance: Settings!$D$69
Name FY_Start: Settings!$D$37
Name GrowthRate: Budget!$B$14
Name HealthRecordTypeList: OFFSET(Lists!$V$5,0,0,MAX(1,COUNTIF(Lists!$V$5:$V$44,"?*")),1)
Name HolidayDates: Settings!$B$85:$B$114
Name HolidaySurcharge: Settings!$D$58
Name InactiveDays: Settings!$D$75

Sheet Start Here
A1: Pet Sitting & Dog Walking Business Spreadsheet | H1: Novality Store - v1.0.0
A2: Client Booking, Pet Care Log, Invoices, Payments, Mileage & Profit Tracker
A4: ="Welcome "&Biz_Owner&" - this workbook is set up for "&Biz_Name&". Cream cells are yours to type in, grey cells are locked formulas that do the maths for you." -> 0
A6: Quick start - ten minutes to a working workbook
B7: 1. Open the Settings tab and enter your business details, currency, tax rate and mileage rate.
B8: 2. Edit the Services tab so the names and prices match what you actually sell.
B9: 3. Add your clients, then their pets (choose the owner from the drop down so they link up).
B10: 4. Add your team on the Staff tab - even if that is only you.
B11: 5. Take a booking: pick the client, pet and service and the price calculates itself.
B12: 6. After each visit, add a row to the Visit Log and tick off the care you gave.
B13: 7. Raise an invoice, link the booking, and record the payment when it lands.
B14: 8. Log expenses and trips as you go - future you will thank you at tax time.
B15: 9. Check the Reminders tab every morning and the Dashboard every week.
B16: 10. Print the reports you need at month end and save a dated backup.
A18: Where everything lives
B19: Tab | C19: What it does
B20: Settings | C20: Your business details, rates, tax, surcharges and reminder windows - set this up first.
B21: Lists | C21: Every drop down list in the workbook. Rename anything to match the way you talk about your services.
B22: Services | C22: Your price list. Billing unit, rate, extra pet fee and profit per service.
B23: Clients | C23: Client database with keys, contracts, lifetime revenue and follow-up flags.
B24: Pets | C24: Pet profiles: feeding, medication, vet, vaccinations, temperament and safety warnings.
B25: Bookings | C25: The schedule. Prices itself from the Services tab and warns you about double bookings.
B26: Visit Log | C26: Proof of every walk and visit: times, care given, mood, health notes and client updates.
B27: Health Log | C27: Medication administration, vaccinations and vet appointments.
B28: Incidents | C28: Emergency contacts and incident reports.
B29: Messages | C29: Client communication, feedback, ratings and complaints.
B30: Invoices | C30: Automatic invoice numbers, due dates, tax, balances and ageing.
... B44: Help | C44: Instructions, formula notes, troubleshooting and version history.
A46: Getting started checklist
B47: Step | C47: What to do | H47: Done?
B48: Step 1 | C48: Business details added on the Settings tab | H48: No
B49: Step 2 | C49: Currency, tax rate and payment terms checked | H49: No
B50: Step 3 | C50: Mileage rate and travel fees set | H50: No
B51: Step 4 | C51: Service names and prices updated | H51: No
B52: Step 5 | C52: Drop down lists adjusted to suit my business | H52: No
B53: Step 6 | C53: Public holidays added for this year | H53: No
B54: Step 7 | C54: First clients entered | H54: No
B55: Step 8 | C55: Pets added and linked to their owners | H55: No
B56: Step 9 | C56: Staff or contractors added | H56: No
B57: Step 10 | C57: Sample data deleted (rows 5 onwards on each tab) | H57: No
...

Sheet Dashboard
A1: Business Dashboard | P1: Novality Store | v1.0.0
A2: Pick a period, then read the business at a glance. Every number is live - it updates as you fill in the other tabs.
A3: > Start Here | C3: > Dashboard | E3: > Clients | G3: > Pets | I3: > Bookings | K3: > Visit Log | M3: > Invoices | O3: > Reminders | Q3: > Help
A5: Reporting period
A6: Year | C6: 2026 | D6: Month | F6: All year | H6: Period start | J6: =IF(Dash_MonthName="All year",DATE(Dash_Year,1,1),DATE(Dash_Year,MAX(1,MATCH(Dash_MonthName,MonthList,0)-1),1)) -> 0 | L6: Period end | N6: =IF(Dash_MonthName="All year",DATE(Dash_Year,12,31),EOMONTH(PeriodStart,0)) -> 0 | P6: Today | R6: =TODAY() -> 0
A8: Money
A9: Revenue collected | D9: Invoiced | G9: Outstanding | J9: Overdue | M9: Expenses | P9: Net profit
A10: =SUMIFS(Payments!$L$5:$L$304,Payments!$B$5:$B$304,">="&PeriodStart,Payments!$B$5:$B$304,"<="&PeriodEnd) -> 0 | D10: =SUMIFS(Invoices!$O$5:$O$304,Invoices!$B$5:$B$304,">="&PeriodStart,Invoices!$B$5:$B$304,"<="&PeriodEnd,Invoices!$T$5:$T$304,"<>Cancelled") -> 0 | G10: =SUMIFS(Invoices!$S$5:$S$304,Invoices!$T$5:$T$304,"<>Cancelled") -> 0 | J10: =SUMIFS(Invoices!$S$5:$S$304,Invoices!$U$5:$U$304,"Overdue")+SUMIFS(Invoices!$S$5:$S$304,Invoices!$U$5:$U$304,"Overdue - part paid") -> 0 | M10: =SUMIFS(Expenses!$F$5:$F$304,Expenses!$B$5:$B$304,">="&PeriodStart,Expenses!$B$5:$B$304,"<="&PeriodEnd,Expenses!$J$5:$J$304,"<>Personal") -> 0 | P10: =Dash_Revenue-Dash_Expenses -> 0
A11: Payments received in the period | D11: Value of invoices raised | G11: Unpaid balance, all invoices | J11: Past the due date - chase today | M11: Business costs in the period | P11: Revenue collected less expenses
A12: Profit margin | D12: Average booking value | G12: Revenue per active client | J12: Mileage claim | M12: Tax to set aside | P12: Cash collected per visit
A13: =IFERROR(Dash_Profit/Dash_Revenue,0) -> 0 | D13: =IFERROR(SUMIFS(Bookings!$AK$5:$AK$404,Bookings!$I$5:$I$404,">="&PeriodStart,Bookings!$I$5:$I$404,"<="&PeriodEnd,Bookings!$AM$5:$AM$404,"<>Cancelled")/COUNTIFS(Bookings!$I$5:$I$404,">="&PeriodStart,Bookings!$I$5:$I$404,"<="&PeriodEnd,Bookings!$AM$5:$AM$404,"<>Cancelled"),0) -> 0 | G13: =IFERROR(Dash_Revenue/COUNTIF(Clients!$M$5:$M$254,"Active"),0) -> 0 | J13: =SUMIFS(Mileage!$U$5:$U$304,Mileage!$B$5:$B$304,">="&PeriodStart,Mileage!$B$5:$B$304,"<="&PeriodEnd) -> 0 | M13: =MAX(0,Dash_Profit)*TaxReservePct -> 0 | P13: =IFERROR(Dash_Revenue/COUNTIFS('Visit Log'!$C$5:$C$404,">="&PeriodStart,'Visit Log'!$C$5:$C$404,"<="&PeriodEnd,'Visit Log'!$AE$5:$AE$404,"Completed"),0) -> 0
A14: Net profit as a share of revenue | D14: Booked value per job | G14: Period revenue / active clients | J14: Travel you can claim back | M14: Profit x tax reserve % from Settings | P14: Revenue / completed visits
A16: Bookings, visits & clients
A17: Bookings in period | D17: Completed | G17: Cancelled | J17: Upcoming (7 days) | M17: Visits completed | P17: Missed visits
A18: =COUNTIFS(Bookings!$I$5:$I$404,">="&PeriodStart,Bookings!$I$5:$I$404,"<="&PeriodEnd,Bookings!$AM$5:$AM$404,"<>Cancelled") -> 0 | D18: =COUNTIFS(Bookings!$I$5:$I$404,">="&PeriodStart,Bookings!$I$5:$I$404,"<="&PeriodEnd,Bookings!$AM$5:$AM$404,"Completed") -> 0 | G18: =COUNTIFS(Bookings!$I$5:$I$404,">="&PeriodStart,Bookings!$I$5:$I$404,"<="&PeriodEnd,Bookings!$AM$5:$AM$404,"Cancelled") -> 0 | J18: =COUNTIFS(Bookings!$I$5:$I$404,">="&TODAY(),Bookings!$I$5:$I$404,"<="&TODAY()+7,Bookings!$AM$5:$AM$404,"<>Cancelled") -> 0 | M18: =COUNTIFS('Visit Log'!$C$5:$C$404,">="&PeriodStart,'Visit Log'!$C$5:$C$404,"<="&PeriodEnd,'Visit Log'!$AE$5:$AE$404,"Completed") -> 0 | P18: =COUNTIFS('Visit Log'!$C$5:$C$404,">="&PeriodStart,'Visit Log'!$C$5:$C$404,"<="&PeriodEnd,'Visit Log'!$AE$5:$AE$404,"Missed") -> 0
A19: Excludes cancellations | D19: Jobs delivered | G19: Watch the cancellation rate | J19: Next seven days | M19: Logged in the Visit Log | P19: Investigate every one
A20: Active clients | D20: Pets on the books | G20: New clients | J20: Repeat clients | M20: Unconfirmed bookings | P20: Average rating
A21: =COUNTIF(Clients!$M$5:$M$254,"Active") -> 0 | D21: =COUNTIF(Pets!$B$5:$B$254,"?*") -> 0 | G21: =COUNTIFS(Clients!$L$5:$L$254,">="&PeriodStart,Clients!$L$5:$L$254,"<="&PeriodEnd) -> 0 | J21: =COUNTIF(Clients!$Z$5:$Z$254,">1") -> 0 | M21: =COUNTIFS(Bookings!$I$5:$I$404,">="&TODAY(),Bookings!$AN$5:$AN$404,"<>Yes",Bookings!$AM$5:$AM$404,"<>Cancelled") -> 0 | P21: =IFERROR(AVERAGEIFS(Messages!$I$5:$I$204,Messages!$B$5:$B$204,">="&PeriodStart,Messages!$B$5:$B$204,"<="&PeriodEnd),"-") -> 0
A22: Clients marked Active | D22: All registered pets | G22: Registered in the period | J22: More than one booking | M22: Send a confirmation | P22: Client satisfaction, 1 to 5
A24: Monthly performance - trends for the selected year
A25: Month | B25: Revenue | C25: Invoiced | D25: Expenses | E25: Profit | F25: Margin | G25: Bookings | H25: Completed | I25: Cancelled | J25: Visits | K25: New clients | L25: Distance | M25: Last year | N25: Change
A26: =Calc!$U$5 -> 0 | B26: =Calc!$V$5 -> 0 | C26: =Calc!$W$5 -> 0 | D26: =Calc!$X$5 -> 0 | E26: =Calc!$Y$5 -> 0 | F26: =IFERROR(Calc!$Y$5/Calc!$V$5,"") -> 0 | G26: =Calc!$Z$5 -> 0 | H26: =Calc!$AA$5 -> 0 | I26: =Calc!$AB$5 -> 0 | J26: =Calc!$AC$5 -> 0 | K26: =Calc!$AD$5 -> 0 | L26: =Calc!$AE$5 -> 0 | M26: =Calc!$AF$5 -> 0 | N26: =IFERROR(Calc!$V$5/Calc!$AF$5-1,"") -> 0
A27: =Calc!$U$6 -> 0 | B27: =Calc!$V$6 -> 0 | C27: =Calc!$W$6 -> 0 | D27: =Calc!$X$6 -> 0 | E27: =Calc!$Y$6 -> 0 | F27: =IFERROR(Calc!$Y$6/Calc!$V$6,"") -> 0 | G27: =Calc!$Z$6 -> 0 | H27: =Calc!$AA$6 -> 0 | I27: =Calc!$AB$6 -> 0 | J27: =Calc!$AC$6 -> 0 | K27: =Calc!$AD$6 -> 0 | L27: =Calc!$AE$6 -> 0 | M27: =Calc!$AF$6 -> 0 | N27: =IFERROR(Calc!$V$6/Calc!$AF$6-1,"") -> 0
A28: =Calc!$U$7 -> 0 | B28: =Calc!$V$7 -> 0 | C28: =Calc!$W$7 -> 0 | D28: =Calc!$X$7 -> 0 | E28: =Calc!$Y$7 -> 0 | F28: =IFERROR(Calc!$Y$7/Calc!$V$7,"") -> 0 | G28: =Calc!$Z$7 -> 0 | H28: =Calc!$AA$7 -> 0 | I28: =Calc!$AB$7 -> 0 | J28: =Calc!$AC$7 -> 0 | K28: =Calc!$AD$7 -> 0 | L28: =Calc!$AE$7 -> 0 | M28: =Calc!$AF$7 -> 0 | N28: =IFERROR(Calc!$V$7/Calc!$AF$7-1,"") -> 0
A29: =Calc!$U$8 -> 0 | B29: =Calc!$V$8 -> 0 | C29: =Calc!$W$8 -> 0 | D29: =Calc!$X$8 -> 0 | E29: =Calc!$Y$8 -> 0 | F29: =IFERROR(Calc!$Y$8/Calc!$V$8,"") -> 0 | G29: =Calc!$Z$8 -> 0 | H29: =Calc!$AA$8 -> 0 | I29: =Calc!$AB$8 -> 0 | J29: =Calc!$AC$8 -> 0 | K29: =Calc!$AD$8 -> 0 | L29: =Calc!$AE$8 -> 0 | M29: =Calc!$AF$8 -> 0 | N29: =IFERROR(Calc!$V$8/Calc!$AF$8-1,"") -> 0
A30: =Calc!$U$9 -> 0 | B30: =Calc!$V$9 -> 0 | C30: =Calc!$W$9 -> 0 | D30: =Calc!$X$9 -> 0 | E30: =Calc!$Y$9 -> 0 | F30: =IFERROR(Calc!$Y$9/Calc!$V$9,"") -> 0 | G30: =Calc!$Z$9 -> 0 | H30: =Calc!$AA$9 -> 0 | I30: =Calc!$AB$9 -> 0 | J30: =Calc!$AC$9 -> 0 | K30: =Calc!$AD$9 -> 0 | L30: =Calc!$AE$9 -> 0 | M30: =Calc!$AF$9 -> 0 | N30: =IFERROR(Calc!$V$9/Calc!$AF$9-1,"") -> 0
A31: =Calc!$U$10 -> 0 | B31: =Calc!$V$10 -> 0 | C31: =Calc!$W$10 -> 0 | D31: =Calc!$X$10 -> 0 | E31: =Calc!$Y$10 -> 0 | F31: =IFERROR(Calc!$Y$10/Calc!$V$10,"") -> 0 | G31: =Calc!$Z$10 -> 0 | H31: =Calc!$AA$10 -> 0 | I31: =Calc!$AB$10 -> 0 | J31: =Calc!$AC$10 -> 0 | K31: =Calc!$AD$10 -> 0 | L31: =Calc!$AE$10 -> 0 | M31: =Calc!$AF$10 -> 0 | N31: =IFERROR(Calc!$V$10/Calc!$AF$10-1,"") -> 0
A32: =Calc!$U$11 -> 0 | B32: =Calc!$V$11 -> 0 | C32: =Calc!$W$11 -> 0 | D32: =Calc!$X$11 -> 0 | E32: =Calc!$Y$11 -> 0 | F32: =IFERROR(Calc!$Y$11/Calc!$V$11,"") -> 0 | G32: =Calc!$Z$11 -> 0 | H32: =Calc!$AA$11 -> 0 | I32: =Calc!$AB$11 -> 0 | J32: =Calc!$AC$11 -> 0 | K32: =Calc!$AD$11 -> 0 | L32: =Calc!$AE$11 -> 0 | M32: =Calc!$AF$11 -> 0 | N32: =IFERROR(Calc!$V$11/Calc!$AF$11-1,"") -> 0
A33: =Calc!$U$12 -> 0 | B33: =Calc!$V$12 -> 0 | C33: =Calc!$W$12 -> 0 | D33: =Calc!$X$12 -> 0 | E33: =Calc!$Y$12 -> 0 | F33: =IFERROR(Calc!$Y$12/Calc!$V$12,"") -> 0 | G33: =Calc!$Z$12 -> 0 | H33: =Calc!$AA$12 -> 0 | I33: =Calc!$AB$12 -> 0 | J33: =Calc!$AC$12 -> 0 | K33: =Calc!$AD$12 -> 0 | L33: =Calc!$AE$12 -> 0 | M33: =Calc!$AF$12 -> 0 | N33: =IFERROR(Calc!$V$12/Calc!$AF$12-1,"") -> 0
A34: =Calc!$U$13 -> 0 | B34: =Calc!$V$13 -> 0 | C34: =Calc!$W$13 -> 0 | D34: =Calc!$X$13 -> 0 | E34: =Calc!$Y$13 -> 0 | F34: =IFERROR(Calc!$Y$13/Calc!$V$13,"") -> 0 | G34: =Calc!$Z$13 -> 0 | H34: =Calc!$AA$13 -> 0 | I34: =Calc!$AB$13 -> 0 | J34: =Calc!$AC$13 -> 0 | K34: =Calc!$AD$13 -> 0 | L34: =Calc!$AE$13 -> 0 | M34: =Calc!$AF$13 -> 0 | N34: =IFERROR(Calc!$V$13/Calc!$AF$13-1,"") -> 0
A35: =Calc!$U$14 -> 0 | B35: =Calc!$V$14 -> 0 | C35: =Calc!$W$14 -> 0 | D35: =Calc!$X$14 -> 0 | E35: =Calc!$Y$14 -> 0 | F35: =IFERROR(Calc!$Y$14/Calc!$V$14,"") -> 0 | G35: =Calc!$Z$14 -> 0 | H35: =Calc!$AA$14 -> 0 | I35: =Calc!$AB$14 -> 0 | J35: =Calc!$AC$14 -> 0 | K35: =Calc!$AD$14 -> 0 | L35: =Calc!$AE$14 -> 0 | M35: =Calc!$AF$14 -> 0 | N35: =IFERROR(Calc!$V$14/Calc!$AF$14-1,"") -> 0
A36: =Calc!$U$15 -> 0 | B36: =Calc!$V$15 -> 0 | C36: =Calc!$W$15 -> 0 | D36: =Calc!$X$15 -> 0 | E36: =Calc!$Y$15 -> 0 | F36: =IFERROR(Calc!$Y$15/Calc!$V$15,"") -> 0 | G36: =Calc!$Z$15 -> 0 | H36: =Calc!$AA$15 -> 0 | I36: =Calc!$AB$15 -> 0 | J36: =Calc!$AC$15 -> 0 | K36: =Calc!$AD$15 -> 0 | L36: =Calc!$AE$15 -> 0 | M36: =Calc!$AF$15 -> 0 | N36: =IFERROR(Calc!$V$15/Calc!$AF$15-1,"") -> 0
A37: =Calc!$U$16 -> 0 | B37: =Calc!$V$16 -> 0 | C37: =Calc!$W$16 -> 0 | D37: =Calc!$X$16 -> 0 | E37: =Calc!$Y$16 -> 0 | F37: =IFERROR(Calc!$Y$16/Calc!$V$16,"") -> 0 | G37: =Calc!$Z$16 -> 0 | H37: =Calc!$AA$16 -> 0 | I37: =Calc!$AB$16 -> 0 | J37: =Calc!$AC$16 -> 0 | K37: =Calc!$AD$16 -> 0 | L37: =Calc!$AE$16 -> 0 | M37: =Calc!$AF$16 -> 0 | N37: =IFERROR(Calc!$V$16/Calc!$AF$16-1,"") -> 0
A38: Year total | B38: =SUM(B26:B37) -> 0 | C38: =SUM(C26:C37) -> 0 | D38: =SUM(D26:D37) -> 0 | E38: =SUM(E26:E37) -> 0 | F38: =IFERROR(E38/B38,"") -> 0 | G38: =SUM(G26:G37) -> 0 | H38: =SUM(H26:H37) -> 0 | I38: =SUM(I26:I37) -> 0 | J38: =SUM(J26:J37) -> 0 | K38: =SUM(K26:K37) -> 0 | L38: =SUM(L26:L37) -> 0 | M38: =SUM(M26:M37) -> 0 | N38: =IFERROR(B38/M38-1,"") -> 0
A39: Trend
A41: Where the money comes from - and where it goes
A42: Revenue by service (selected period) | H42: Expenses by category (selected period)
A43: Service | B43: Bookings | C43: Revenue | D43: Share | H43: Category | I43: Spend | J43: Share
A44: =IF(Calc!$I$5="","",Calc!$I$5) -> 0 | B44: =IF(Calc!$I$5="","",Calc!$K$5) -> 0 | C44: =IF(Calc!$I$5="","",Calc!$J$5) -> 0 | D44: =IFERROR(Calc!$J$5/SUM(Calc!$J$5:$J$254),"") -> 0 | H44: =IF(Calc!$P$5="","",Calc!$P$5) -> 0 | I44: =IF(Calc!$P$5="","",Calc!$Q$5) -> 0 | J44: =IFERROR(Calc!$Q$5/SUM(Calc!$Q$5:$Q$254),"") -> 0
A45: =IF(Calc!$I$6="","",Calc!$I$6) -> 0 | B45: =IF(Calc!$I$6="","",Calc!$K$6) -> 0 | C45: =IF(Calc!$I$6="","",Calc!$J$6) -> 0 | D45: =IFERROR(Calc!$J$6/SUM(Calc!$J$5:$J$254),"") -> 0 | H45: =IF(Calc!$P$6="","",Calc!$P$6) -> 0 | I45: =IF(Calc!$P$6="","",Calc!$Q$6) -> 0 | J45: =IFERROR(Calc!$Q$6/SUM(Calc!$Q$5:$Q$254),"") -> 0
...

Sheet Settings
A1: Business Setup & Settings | G1: Novality Store | v1.0.0
A2: Fill in the cream cells once. Grey cells are locked formulas. Everything else in the workbook reads these values.
A3: > Start Here | C3: > Dashboard | E3: > Clients | G3: > Pets
A5: 1. Business details (used on invoices and printables)
B6: Business name | D6: Happy Paws Pet Care | F6: Shown on every printable form and invoice.
B7: Owner / main contact | D7: Alex Morgan
B8: Phone | D8: +1 (555) 014 2200
B9: Email | D9: hello@happypawspetcare.com
B10: Website / social | D10: www.happypawspetcare.com
B11: Street address | D11: 28 Brookfield Lane
B12: City / suburb | D12: Springfield
B13: State / region | D13: IL
B14: Post / ZIP code | D14: 62704
B15: Country | D15: United States
B16: Business / tax number | D16: TAX-884 221 905
B17: Payment details for invoices | D17: Happy Paws Pet Care - Acct 1023 4455 - Routing 021000021 | F17: Bank account, payment link or app handle.
B18: Insurance provider | D18: PetGuard Business Insurance
B19: Insurance policy number | D19: PG-7741920
B20: Insurance renewal date | D20: 46426 | E20: Feeds the renewal reminder on the Reminders tab.
B21: Licence / permit | D21: City Pet Care Operator Licence
B22: Licence renewal date | D22: 46516
A24: 2. Logo & branding
B25: To add your logo: unprotect the sheet (Review > Unprotect Sheet, password 'premium'), click Insert > Pictures, place the image in the box below, then protect the sheet again. The printable forms have their own logo placeholders.
B26: LOGO PLACEHOLDER - insert your image here
A31: 3. Currency, date & time formats
B32: Currency symbol | D32: $ | E32: Display only. To change the cell formatting use Format Cells > Currency on the money columns.
B33: Currency code | D33: USD
B34: Date format in use | D34: DD-MMM-YYYY | E34: Select a date column and use Format Cells to switch to your local style.
B35: Time format in use | D35: h:mm AM/PM | E35: 24 hour clock: format as hh:mm.
B36: Distance unit | D36: km
B37: Financial year starts | D37: 46023
A39: 4. Tax settings
B40: Tax name | D40: Sales Tax | E40: GST, VAT, Sales Tax ...
B41: Registered for tax? | D41: Yes | E41: No = tax is never added to bookings or invoices.
B42: Tax rate | D42: 0.08 | E42: Enter as a percentage, e.g. 10%.
B43: Prices already include tax? | D43: No | E43: Yes = tax is extracted from the price. No = tax is added on top.
B44: Tax reserve to set aside | D44: 0.25 | E44: Used by the Budget tab to estimate money to park for the tax bill.
A46: 5. Invoicing & payments
B47: Invoice prefix | D47: INV-
B48: First invoice number | D48: 1001
...

Sheet Lists
A1: Customisable Drop Down Lists | AR1: Novality Store | v1.0.0
A2: Edit, add or delete options below - every drop down in the workbook updates automatically. Keep each list in one unbroken block, starting in row 5.
A3: > Start Here | C3: > Dashboard | E3: > Clients | G3: > Pets | I3: > Bookings | K3: > Visit Log | M3: > Invoices | O3: > Reminders | Q3: > Help | S3: TIP: lists grow automatically (up to row 44). Deleting an option does not change records that already use it.
A4: Yes / No | B4: Yes / No / N/A | C4: Client status | D4: Preferred contact | E4: Referral source | F4: Contract status | G4: Key / access status | H4: Pet type | I4: Pet gender | J4: Temperament | K4: Risk flag | L4: Service category | M4: Billing unit | N4: Booking status | O4: Recurring pattern | P4: Discount type | Q4: Cancellation reason | R4: Visit status | S4: Pet mood | T4: Appetite / intake | U4: Potty / litter | V4: Health record type | W4: Medication status | X4: Incident type | Y4: Severity | Z4: Incident status | AA4: Message type | AB4: Channel | AC4: Direction | AD4: Resolution status | AE4: Invoice status | AF4: Payment method | AG4: Expense category | AH4: Approval status | AI4: Business / personal | AJ4: Recurring expense | AK4: Trip purpose | AL4: Staff role | AM4: Employment type | AN4: Pay type | AO4: Staff status | AP4: Inventory category | AQ4: Priority | AR4: Task status | AS4: Satisfaction rating | AT4: Dashboard period
A5: Yes | B5: Yes | C5: Active | D5: Phone call | E5: Google search | F5: Not sent | G5: Not held | H5: Dog | I5: Male | J5: Friendly | K5: None | L5: Dog walking | M5: Per visit | N5: Enquiry | O5: None | P5: None | Q5: Client cancelled | R5: Scheduled | S5: Happy | T5: Normal | U5: Pee only | V5: Medication | W5: Scheduled | X5: Bite / nip | Y5: Low | Z5: Open | AA5: Booking confirmation | AB5: Phone call | AC5: Outgoing | AD5: Not required | AE5: Draft | AF5: Cash | AG5: Fuel | AH5: Pending | AI5: Business | AJ5: No | AK5: Client visit | AL5: Owner | AM5: Employee - full time | AN5: Hourly | AO5: Active | AP5: Pet food | AQ5: Low | AR5: Not started | AS5: 1 | AT5: All year
A6: No | B6: No | C6: Prospective | D6: SMS | E6: Facebook | F6: Sent | G6: Key held | H6: Cat | I6: Male (neutered) | J6: Calm | K6: Bite risk | L6: Drop-in visit | M6: Per hour | N6: Pending | O6: Daily | P6: Loyalty | Q6: Client away | R6: Completed | S6: Calm | T6: Reduced | U6: Poo only | V6: Vaccination | W6: Given | X6: Escape | Y6: Medium | Z6: In progress | AA6: Booking reminder | AB6: SMS | AC6: Incoming | AD6: Open | AE6: Sent | AF6: Bank transfer | AG6: Vehicle maintenance | AH6: Approved | AI6: Personal | AJ6: Weekly | AK6: Dog walk | AL6: Dog walker | AM6: Employee - part time | AN6: Per visit | AO6: On leave | AP6: Treats | AQ6: Medium | AR6: In progress | AS6: 2 | AT6: January
B7: N/A | C7: On hold | D7: Email | E7: Instagram | F7: Signed | G7: Key returned | H7: Bird | I7: Female | J7: Playful | K7: Escape artist | L7: Pet sitting | M7: Per night | N7: Confirmed | O7: Weekdays | P7: Promotional | Q7: Pet unwell | R7: Partially completed | S7: Playful | T7: None | U7: Both | V7: Vet visit | W7: Missed | X7: Injury | Y7: High | Z7: Resolved | AA7: Visit update | AB7: Email | AD7: In progress | AE7: Paid | AF7: Card - in person | AG7: Parking & tolls | AH7: Rejected | AI7: Mixed | AJ7: Fortnightly | AK7: Supplies run | AL7: Pet sitter | AM7: Casual | AN7: Salary | AO7: Inactive | AP7: Medication | AQ7: High | AR7: Waiting | AS7: 3 | AT7: February
C8: Inactive | D8: WhatsApp | E8: Word of mouth | F8: Expired | G8: Lockbox code | H8: Rabbit | I8: Female (spayed) | J8: Energetic | K8: Door dasher | L8: Overnight stay | M8: Per walk | N8: In progress | O8: Weekly | P8: Package | Q8: Weather | R8: Missed | S8: Sleepy | T8: Increased | U8: None | V8: Health observation | W8: Refused | X8: Illness | Y8: Critical | Z8: Closed | AA8: Payment reminder | AB8: WhatsApp | AD8: Resolved | AE8: Partially paid | AF8: Card - online | AG8: Pet supplies | AH8: Reimbursed | AJ8: Monthly | AK8: Vet trip | AL8: Assistant | AM8: Contractor | AN8: Commission % | AP8: First aid | AQ8: Urgent | AR8: Done | AS8: 4 | AT8: March
C9: Lost | D9: App message | E9: Client referral | F9: Renewal due | G9: Smart lock code | H9: Guinea pig | I9: Unknown | J9: Shy | K9: Pulls on lead | L9: House sitting | M9: Per day | N9: Completed | O9: Fortnightly | P9: Multi-pet | Q9: Staff unavailable | R9: Cancelled | S9: Anxious | T9: Not offered | U9: Litter cleaned | V9: Treatment | W9: Not required | X9: Property damage | AA9: Follow-up | AB9: In person | AE9: Cancelled | AF9: Digital wallet | AG9: Pet food & treats | AJ9: Quarterly | AK9: Admin / bank | AL9: Admin | AM9: Volunteer | AP9: Cleaning | AR9: Cancelled | AS9: 5 | AT9: April
E10: Vet clinic | G10: Owner home | H10: Small animal | J10: Anxious | K10: Not dog friendly | L10: Feeding visit | M10: Flat fee | N10: Cancelled | O10: Monthly | P10: Goodwill | Q10: Double booked | S10: Lethargic | U10: Accident indoors | V10: Grooming | X10: Lost key | AA10: Thank you | AB10: App message | AE10: Refunded | AF10: Direct debit | AG10: Cleaning supplies | AJ10: Annually | AK10: Marketing | AL10: Contractor | AP10: Waste bags | AT10: May
E11: Flyer / poster | H11: Reptile | J11: Reactive | K11: Not cat friendly | L11: Puppy care | N11: No show | P11: Custom | Q11: Payment issue | S11: Unwell | V11: Other | X11: Vehicle incident | AA11: Referral thank-you | AB11: Social media | AF11: Cheque | AG11: Equipment | AK11: Training | AL11: Trainee | AP11: Leads & harnesses | AT11: June
E12: Local directory | H12: Fish | J12: Protective | K12: Resource guarding | L12: Senior pet care | Q12: Rescheduled | S12: Aggressive | X12: Aggression | AA12: Birthday / anniversary | AF12: Other | AG12: Marketing & advertising | AK12: Personal | AP12: Toys | AT12: July
E13: Repeat client | H13: Other | J13: Needs slow introduction | K13: Needs muzzle | L13: Medication visit | Q13: No reason given | X13: Theft | AA13: Complaint | AG13: Software & subscriptions | AP13: Equipment | AT13: August
E14: Other | K14: Medical risk | L14: Pet transport | Q14: Other | X14: Other | AA14: Review request | AG14: Insurance | AP14: Office | AT14: September
K15: Other | L15: Add-on | AA15: Win-back offer | AG15: Licences & permits | AP15: Other | AT15: October
AA16: Other | AG16: Staff wages | AT16: November
AG17: Contractor payments | AT17: December
AG18: Training & certification
AG19: Phone & internet
AG20: Office & admin
AG21: Vet & emergency supplies
AG22: Bank & merchant fees
AG23: Other

Sheet Services
A1: Services & Price List | R1: Novality Store | v1.0.0
A2: Add every service you sell. Bookings pull the billing unit, rate, additional pet fee and surcharges straight from this table.
A3: > Start Here | C3: > Dashboard | E3: > Clients | G3: > Pets | I3: > Bookings | K3: > Visit Log | M3: > Invoices | O3: > Reminders | Q3: > Help
A4: ID | B4: Service name | C4: Category | D4: What is included | E4: Billing unit | F4: Standard length (mins) | G4: Base rate | H4: Additional pet fee | I4: Holiday surcharge | J4: Weekend surcharge | K4: Travel fee applies? | L4: Staff cost per unit | M4: Gross profit per unit | N4: Margin % | O4: Times booked | P4: Revenue to date | Q4: Average value | R4: Estimated profit | S4: Active? | T4: Notes
A5: =IF(B5="","","SV-"&TEXT(ROW()-4,"000")) -> 0 | M5: =IF(G5="","",G5-IF(L5="",0,L5)) -> 0 | N5: =IF(OR(G5="",G5=0),"",M5/G5) -> 0 | O5: =IF(B5="","",COUNTIFS(Bookings!$H$5:$H$404,B5,Bookings!$AM$5:$AM$404,"<>Cancelled")) -> 0 | P5: =IF(B5="","",SUMIFS(Bookings!$AK$5:$AK$404,Bookings!$H$5:$H$404,B5,Bookings!$AM$5:$AM$404,"<>Cancelled")) -> 0 | Q5: =IF(OR(O5="",O5=0),"",P5/O5) -> 0 | R5: =IF(OR(O5="",M5=""),"",O5*M5) -> 0
A6: =IF(B6="","","SV-"&TEXT(ROW()-4,"000")) -> 0 | M6: =IF(G6="","",G6-IF(L6="",0,L6)) -> 0 | N6: =IF(OR(G6="",G6=0),"",M6/G6) -> 0 | O6: =IF(B6="","",COUNTIFS(Bookings!$H$5:$H$404,B6,Bookings!$AM$5:$AM$404,"<>Cancelled")) -> 0 | P6: =IF(B6="","",SUMIFS(Bookings!$AK$5:$AK$404,Bookings!$H$5:$H$404,B6,Bookings!$AM$5:$AM$404,"<>Cancelled")) -> 0 | Q6: =IF(OR(O6="",O6=0),"",P6/O6) -> 0 | R6: =IF(OR(O6="",M6=""),"",O6*M6) -> 0
A7: =IF(B7="","","SV-"&TEXT(ROW()-4,"000")) -> 0 | M7: =IF(G7="","",G7-IF(L7="",0,L7)) -> 0 | N7: =IF(OR(G7="",G7=0),"",M7/G7) -> 0 | O7: =IF(B7="","",COUNTIFS(Bookings!$H$5:$H$404,B7,Bookings!$AM$5:$AM$404,"<>Cancelled")) -> 0 | P7: =IF(B7="","",SUMIFS(Bookings!$AK$5:$AK$404,Bookings!$H$5:$H$404,B7,Bookings!$AM$5:$AM$404,"<>Cancelled")) -> 0 | Q7: =IF(OR(O7="",O7=0),"",P7/O7) -> 0 | R7: =IF(OR(O7="",M7=""),"",O7*M7) -> 0
A8: =IF(B8="","","SV-"&TEXT(ROW()-4,"000")) -> 0 | M8: =IF(G8="","",G8-IF(L8="",0,L8)) -> 0 | N8: =IF(OR(G8="",G8=0),"",M8/G8) -> 0 | O8: =IF(B8="","",COUNTIFS(Bookings!$H$5:$H$404,B8,Bookings!$AM$5:$AM$404,"<>Cancelled")) -> 0 | P8: =IF(B8="","",SUMIFS(Bookings!$AK$5:$AK$404,Bookings!$H$5:$H$404,B8,Bookings!$AM$5:$AM$404,"<>Cancelled")) -> 0 | Q8: =IF(OR(O8="",O8=0),"",P8/O8) -> 0 | R8: =IF(OR(O8="",M8=""),"",O8*M8) -> 0
A9: =IF(B9="","","SV-"&TEXT(ROW()-4,"000")) -> 0 | M9: =IF(G9="","",G9-IF(L9="",0,L9)) -> 0 | N9: =IF(OR(G9="",G9=0),"",M9/G9) -> 0 | O9: =IF(B9="","",COUNTIFS(Bookings!$H$5:$H$404,B9,Bookings!$AM$5:$AM$404,"<>Cancelled")) -> 0 | P9: =IF(B9="","",SUMIFS(Bookings!$AK$5:$AK$404,Bookings!$H$5:$H$404,B9,Bookings!$AM$5:$AM$404,"<>Cancelled")) -> 0 | Q9: =IF(OR(O9="",O9=0),"",P9/O9) -> 0 | R9: =IF(OR(O9="",M9=""),"",O9*M9) -> 0
A10: =IF(B10="","","SV-"&TEXT(ROW()-4,"000")) -> 0 | M10: =IF(G10="","",G10-IF(L10="",0,L10)) -> 0 | N10: =IF(OR(G10="",G10=0),"",M10/G10) -> 0 | O10: =IF(B10="","",COUNTIFS(Bookings!$H$5:$H$404,B10,Bookings!$AM$5:$AM$404,"<>Cancelled")) -> 0 | P10: =IF(B10="","",SUMIFS(Bookings!$AK$5:$AK$404,Bookings!$H$5:$H$404,B10,Bookings!$AM$5:$AM$404,"<>Cancelled")) -> 0 | Q10: =IF(OR(O10="",O10=0),"",P10/O10) -> 0 | R10: =IF(OR(O10="",M10=""),"",O10*M10) -> 0
A11: =IF(B11="","","SV-"&TEXT(ROW()-4,"000")) -> 0 | M11: =IF(G11="","",G11-IF(L11="",0,L11)) -> 0 | N11: =IF(OR(G11="",G11=0),"",M11/G11) -> 0 | O11: =IF(B11="","",COUNTIFS(Bookings!$H$5:$H$404,B11,Bookings!$AM$5:$AM$404,"<>Cancelled")) -> 0 | P11: =IF(B11="","",SUMIFS(Bookings!$AK$5:$AK$404,Bookings!$H$5:$H$404,B11,Bookings!$AM$5:$AM$404,"<>Cancelled")) -> 0 | Q11: =IF(OR(O11="",O11=0),"",P11/O11) -> 0 | R11: =IF(OR(O11="",M11=""),"",O11*M11) -> 0
A12: =IF(B12="","","SV-"&TEXT(ROW()-4,"000")) -> 0 | M12: =IF(G12="","",G12-IF(L12="",0,L12)) -> 0 | N12: =IF(OR(G12="",G12=0),"",M12/G12) -> 0 | O12: =IF(B12="","",COUNTIFS(Bookings!$H$5:$H$404,B12,Bookings!$AM$5:$AM$404,"<>Cancelled")) -> 0 | P12: =IF(B12="","",SUMIFS(Bookings!$AK$5:$AK$404,Bookings!$H$5:$H$404,B12,Bookings!$AM$5:$AM$404,"<>Cancelled")) -> 0 | Q12: =IF(OR(O12="",O12=0),"",P12/O12) -> 0 | R12: =IF(OR(O12="",M12=""),"",O12*M12) -> 0
A13: =IF(B13="","","SV-"&TEXT(ROW()-4,"000")) -> 0 | M13: =IF(G13="","",G13-IF(L13="",0,L13)) -> 0 | N13: =IF(OR(G13="",G13=0),"",M13/G13) -> 0 | O13: =IF(B13="","",COUNTIFS(Bookings!$H$5:$H$404,B13,Bookings!$AM$5:$AM$404,"<>Cancelled")) -> 0 | P13: =IF(B13="","",SUMIFS(Bookings!$AK$5:$AK$404,Bookings!$H$5:$H$404,B13,Bookings!$AM$5:$AM$404,"<>Cancelled")) -> 0 | Q13: =IF(OR(O13="",O13=0),"",P13/O13) -> 0 | R13: =IF(OR(O13="",M13=""),"",O13*M13) -> 0
A14: =IF(B14="","","SV-"&TEXT(ROW()-4,"000")) -> 0 | M14: =IF(G14="","",G14-IF(L14="",0,L14)) -> 0 | N14: =IF(OR(G14="",G14=0),"",M14/G14) -> 0 | O14: =IF(B14="","",COUNTIFS(Bookings!$H$5:$H$404,B14,Bookings!$AM$5:$AM$404,"<>Cancelled")) -> 0 | P14: =IF(B14="","",SUMIFS(Bookings!$AK$5:$AK$404,Bookings!$H$5:$H$404,B14,Bookings!$AM$5:$AM$404,"<>Cancelled")) -> 0 | Q14: =IF(OR(O14="",O14=0),"",P14/O14) -> 0 | R14: =IF(OR(O14="",M14=""),"",O14*M14) -> 0
A15: =IF(B15="","","SV-"&TEXT(ROW()-4,"000")) -> 0 | M15: =IF(G15="","",G15-IF(L15="",0,L15)) -> 0 | N15: =IF(OR(G15="",G15=0),"",M15/G15) -> 0 | O15: =IF(B15="","",COUNTIFS(Bookings!$H$5:$H$404,B15,Bookings!$AM$5:$AM$404,"<>Cancelled")) -> 0 | P15: =IF(B15="","",SUMIFS(Bookings!$AK$5:$AK$404,Bookings!$H$5:$H$404,B15,Bookings!$AM$5:$AM$404,"<>Cancelled")) -> 0 | Q15: =IF(OR(O15="",O15=0),"",P15/O15) -> 0 | R15: =IF(OR(O15="",M15=""),"",O15*M15) -> 0
A16: =IF(B16="","","SV-"&TEXT(ROW()-4,"000")) -> 0 | M16: =IF(G16="","",G16-IF(L16="",0,L16)) -> 0 | N16: =IF(OR(G16="",G16=0),"",M16/G16) -> 0 | O16: =IF(B16="","",COUNTIFS(Bookings!$H$5:$H$404,B16,Bookings!$AM$5:$AM$404,"<>Cancelled")) -> 0 | P16: =IF(B16="","",SUMIFS(Bookings!$AK$5:$AK$404,Bookings!$H$5:$H$404,B16,Bookings!$AM$5:$AM$404,"<>Cancelled")) -> 0 | Q16: =IF(OR(O16="",O16=0),"",P16/O16) -> 0 | R16: =IF(OR(O16="",M16=""),"",O16*M16) -> 0
... A54: =IF(B54="","","SV-"&TEXT(ROW()-4,"000")) -> 0 | M54: =IF(G54="","",G54-IF(L54="",0,L54)) -> 0 | N54: =IF(OR(G54="",G54=0),"",M54/G54) -> 0 | O54: =IF(B54="","",COUNTIFS(Bookings!$H$5:$H$404,B54,Bookings!$AM$5:$AM$404,"<>Cancelled")) -> 0 | P54: =IF(B54="","",SUMIFS(Bookings!$AK$5:$AK$404,Bookings!$H$5:$H$404,B54,Bookings!$AM$5:$AM$404,"<>Cancelled")) -> 0 | Q54: =IF(OR(O54="",O54=0),"",P54/O54) -> 0 | R54: =IF(OR(O54="",M54=""),"",O54*M54) -> 0

Sheet Clients
A1: Client Database | AJ1: Novality Store | v1.0.0
A2: One row per client. Grey columns calculate pets, visits, lifetime revenue, outstanding balances and follow-up actions for you.
A3: > Start Here | C3: > Dashboard | E3: > Clients | G3: > Pets | I3: > Bookings | K3: > Visit Log | M3: > Invoices | O3: > Reminders | Q3: > Help | S3: Type the client name first - the Client ID appears automatically. Use the filter arrows in the header row to search; avoid re-sorting rows so IDs stay stable.
A4: ID | B4: Client name | C4: Phone | D4: Email | E4: Street address | F4: City / suburb | G4: Post code | H4: Emergency contact | I4: Emergency phone | J4: Preferred contact | K4: Referral source | L4: Registered on | M4: Status | N4: Key / access | O4: Key tag / ref | P4: Key returned on | Q4: Home access instructions | R4: Alarm / gate code | S4: Contract status | T4: Agreement signed | U4: Emergency vet consent | V4: Vet spend authority | W4: Preferences & special instructions | X4: Notes & communication history | Y4: Pets | Z4: Bookings | AA4: Visits done | AB4: Last service | AC4: Days since | AD4: Next booking | AE4: Lifetime revenue | AF4: Invoiced to date | AG4: Outstanding | AH4: Average booking | AI4: Loyalty status | AJ4: Duplicate check | AK4: Missing information | AL4: Action needed
A5: =IF(B5="","",ClientPrefix&TEXT(ROW()-4,"0000")) -> 0 | Y5: =IF(B5="","",COUNTIF(Pets!$C$5:$C$254,B5)) -> 0 | Z5: =IF(B5="","",COUNTIFS(Bookings!$C$5:$C$404,B5)) -> 0 | AA5: =IF(B5="","",COUNTIFS('Visit Log'!$D$5:$D$404,B5,'Visit Log'!$AE$5:$AE$404,"Completed")) -> 0 | AB5: =IF(B5="","",IF(SUMPRODUCT(MAX((Bookings!$C$5:$C$404=B5)*(Bookings!$AM$5:$AM$404="Completed")*Bookings!$I$5:$I$404))=0,"",SUMPRODUCT(MAX((Bookings!$C$5:$C$404=B5)*(Bookings!$AM$5:$AM$404="Completed")*Bookings!$I$5:$I$404)))) -> 0 | AC5: =IF(AB5="","",TODAY()-AB5) -> 0 | AD5: =IF(B5="","",IF(COUNTIFS(Bookings!$C$5:$C$404,B5,Bookings!$I$5:$I$404,">="&TODAY(),Bookings!$AM$5:$AM$404,"<>Cancelled")=0,"",SUMPRODUCT(MIN(((Bookings!$C$5:$C$404=B5)*(Bookings!$I$5:$I$404>=TODAY())*(Bookings!$AM$5:$AM$404<>"Cancelled"))*Bookings!$I$5:$I$404+(1-((Bookings!$C$5:$C$404=B5)*(Bookings!$I$5:$I$404>=TODAY())*(Bookings!$AM$5:$AM$404<>"Cancelled")))*2958465)))) -> 0 | AE5: =IF(B5="","",SUMIFS(Payments!$L$5:$L$304,Payments!$C$5:$C$304,B5)) -> 0 | AF5: =IF(B5="","",SUMIFS(Invoices!$O$5:$O$304,Invoices!$D$5:$D$304,B5,Invoices!$T$5:$T$304,"<>Draft")) -> 0 | AG5: =IF(B5="","",SUMIFS(Invoices!$S$5:$S$304,Invoices!$D$5:$D$304,B5,Invoices!$T$5:$T$304,"<>Cancelled")) -> 0 | AH5: =IF(OR(Z5="",Z5=0),"",SUMIFS(Bookings!$AK$5:$AK$404,Bookings!$C$5:$C$404,B5,Bookings!$AM$5:$AM$404,"<>Cancelled")/Z5) -> 0 | AI5: =IF(B5="","",IF(Z5>=LoyaltyThreshold,"Loyalty discount","Standard")) -> 0 | AJ5: =IF(B5="","",IF(COUNTIF(Clients!$B$5:$B$254,B5)>1,"Duplicate name",IF(AND(C5<>"",COUNTIF(Clients!$C$5:$C$254,C5)>1),"Duplicate phone","OK"))) -> 0 | AK5: =IF(B5="","",IF(AND(C5<>"",D5<>"",L5<>"",M5<>""),"OK","Add: "&IF(C5="","phone ","")&IF(D5="","email ","")&IF(L5="","date ","")&IF(M5="","status",""))) -> 0 | AL5: =IF(B5="","",IF(AG5>0.5,"Overdue - chase payment",IF(AND(M5="Active",ISNUMBER(AC5),AC5>InactiveDays),"Inactive - win back",IF(AND(M5="Active",S5<>"Signed"),"Action - contract not signed",IF(AND(M5="Prospective",AD5=""),"Action - follow up quote","OK"))))) -> 0
A6: =IF(B6="","",ClientPrefix&TEXT(ROW()-4,"0000")) -> 0 | Y6: =IF(B6="","",COUNTIF(Pets!$C$5:$C$254,B6)) -> 0 | Z6: =IF(B6="","",COUNTIFS(Bookings!$C$5:$C$404,B6)) -> 0 | AA6: =IF(B6="","",COUNTIFS('Visit Log'!$D$5:$D$404,B6,'Visit Log'!$AE$5:$AE$404,"Completed")) -> 0 | AB6: =IF(B6="","",IF(SUMPRODUCT(MAX((Bookings!$C$5:$C$404=B6)*(Bookings!$AM$5:$AM$404="Completed")*Bookings!$I$5:$I$404))=0,"",SUMPRODUCT(MAX((Bookings!$C$5:$C$404=B6)*(Bookings!$AM$5:$AM$404="Completed")*Bookings!$I$5:$I$404)))) -> 0 | AC6: =IF(AB6="","",TODAY()-AB6) -> 0 | AD6: =IF(B6="","",IF(COUNTIFS(Bookings!$C$5:$C$404,B6,Bookings!$I$5:$I$404,">="&TODAY(),Bookings!$AM$5:$AM$404,"<>Cancelled")=0,"",SUMPRODUCT(MIN(((Bookings!$C$5:$C$404=B6)*(Bookings!$I$5:$I$404>=TODAY())*(Bookings!$AM$5:$AM$404<>"Cancelled"))*Bookings!$I$5:$I$404+(1-((Bookings!$C$5:$C$404=B6)*(Bookings!$I$5:$I$404>=TODAY())*(Bookings!$AM$5:$AM$404<>"Cancelled")))*2958465)))) -> 0 | AE6: =IF(B6="","",SUMIFS(Payments!$L$5:$L$304,Payments!$C$5:$C$304,B6)) -> 0 | AF6: =IF(B6="","",SUMIFS(Invoices!$O$5:$O$304,Invoices!$D$5:$D$304,B6,Invoices!$T$5:$T$304,"<>Draft")) -> 0 | AG6: =IF(B6="","",SUMIFS(Invoices!$S$5:$S$304,Invoices!$D$5:$D$304,B6,Invoices!$T$5:$T$304,"<>Cancelled")) -> 0 | AH6: =IF(OR(Z6="",Z6=0),"",SUMIFS(Bookings!$AK$5:$AK$404,Bookings!$C$5:$C$404,B6,Bookings!$AM$5:$AM$404,"<>Cancelled")/Z6) -> 0 | AI6: =IF(B6="","",IF(Z6>=LoyaltyThreshold,"Loyalty discount","Standard")) -> 0 | AJ6: =IF(B6="","",IF(COUNTIF(Clients!$B$5:$B$254,B6)>1,"Duplicate name",IF(AND(C6<>"",COUNTIF(Clients!$C$5:$C$254,C6)>1),"Duplicate phone","OK"))) -> 0 | AK6: =IF(B6="","",IF(AND(C6<>"",D6<>"",L6<>"",M6<>""),"OK","Add: "&IF(C6="","phone ","")&IF(D6="","email ","")&IF(L6="","date ","")&IF(M6="","status",""))) -> 0 | AL6: =IF(B6="","",IF(AG6>0.5,"Overdue - chase payment",IF(AND(M6="Active",ISNUMBER(AC6),AC6>InactiveDays),"Inactive - win back",IF(AND(M6="Active",S6<>"Signed"),"Action - contract not signed",IF(AND(M6="Prospective",AD6=""),"Action - follow up quote","OK"))))) -> 0
A7: =IF(B7="","",ClientPrefix&TEXT(ROW()-4,"0000")) -> 0 | Y7: =IF(B7="","",COUNTIF(Pets!$C$5:$C$254,B7)) -> 0 | Z7: =IF(B7="","",COUNTIFS(Bookings!$C$5:$C$404,B7)) -> 0 | AA7: =IF(B7="","",COUNTIFS('Visit Log'!$D$5:$D$404,B7,'Visit Log'!$AE$5:$AE$404,"Completed")) -> 0 | AB7: =IF(B7="","",IF(SUMPRODUCT(MAX((Bookings!$C$5:$C$404=B7)*(Bookings!$AM$5:$AM$404="Completed")*Bookings!$I$5:$I$404))=0,"",SUMPRODUCT(MAX((Bookings!$C$5:$C$404=B7)*(Bookings!$AM$5:$AM$404="Completed")*Bookings!$I$5:$I$404)))) -> 0 | AC7: =IF(AB7="","",TODAY()-AB7) -> 0 | AD7: =IF(B7="","",IF(COUNTIFS(Bookings!$C$5:$C$404,B7,Bookings!$I$5:$I$404,">="&TODAY(),Bookings!$AM$5:$AM$404,"<>Cancelled")=0,"",SUMPRODUCT(MIN(((Bookings!$C$5:$C$404=B7)*(Bookings!$I$5:$I$404>=TODAY())*(Bookings!$AM$5:$AM$404<>"Cancelled"))*Bookings!$I$5:$I$404+(1-((Bookings!$C$5:$C$404=B7)*(Bookings!$I$5:$I$404>=TODAY())*(Bookings!$AM$5:$AM$404<>"Cancelled")))*2958465)))) -> 0 | AE7: =IF(B7="","",SUMIFS(Payments!$L$5:$L$304,Payments!$C$5:$C$304,B7)) -> 0 | AF7: =IF(B7="","",SUMIFS(Invoices!$O$5:$O$304,Invoices!$D$5:$D$304,B7,Invoices!$T$5:$T$304,"<>Draft")) -> 0 | AG7: =IF(B7="","",SUMIFS(Invoices!$S$5:$S$304,Invoices!$D$5:$D$304,B7,Invoices!$T$5:$T$304,"<>Cancelled")) -> 0 | AH7: =IF(OR(Z7="",Z7=0),"",SUMIFS(Bookings!$AK$5:$AK$404,Bookings!$C$5:$C$404,B7,Bookings!$AM$5:$AM$404,"<>Cancelled")/Z7) -> 0 | AI7: =IF(B7="","",IF(Z7>=LoyaltyThreshold,"Loyalty discount","Standard")) -> 0 | AJ7: =IF(B7="","",IF(COUNTIF(Clients!$B$5:$B$254,B7)>1,"Duplicate name",IF(AND(C7<>"",COUNTIF(Clients!$C$5:$C$254,C7)>1),"Duplicate phone","OK"))) -> 0 | AK7: =IF(B7="","",IF(AND(C7<>"",D7<>"",L7<>"",M7<>""),"OK","Add: "&IF(C7="","phone ","")&IF(D7="","email ","")&IF(L7="","date ","")&IF(M7="","status",""))) -> 0 | AL7: =IF(B7="","",IF(AG7>0.5,"Overdue - chase payment",IF(AND(M7="Active",ISNUMBER(AC7),AC7>InactiveDays),"Inactive - win back",IF(AND(M7="Active",S7<>"Signed"),"Action - contract not signed",IF(AND(M7="Prospective",AD7=""),"Action - follow up quote","OK"))))) -> 0
A8: =IF(B8="","",ClientPrefix&TEXT(ROW()-4,"0000")) -> 0 | Y8: =IF(B8="","",COUNTIF(Pets!$C$5:$C$254,B8)) -> 0 | Z8: =IF(B8="","",COUNTIFS(Bookings!$C$5:$C$404,B8)) -> 0 | AA8: =IF(B8="","",COUNTIFS('Visit Log'!$D$5:$D$404,B8,'Visit Log'!$AE$5:$AE$404,"Completed")) -> 0 | AB8: =IF(B8="","",IF(SUMPRODUCT(MAX((Bookings!$C$5:$C$404=B8)*(Bookings!$AM$5:$AM$404="Completed")*Bookings!$I$5:$I$404))=0,"",SUMPRODUCT(MAX((Bookings!$C$5:$C$404=B8)*(Bookings!$AM$5:$AM$404="Completed")*Bookings!$I$5:$I$404)))) -> 0 | AC8: =IF(AB8="","",TODAY()-AB8) -> 0 | AD8: =IF(B8="","",IF(COUNTIFS(Bookings!$C$5:$C$404,B8,Bookings!$I$5:$I$404,">="&TODAY(),Bookings!$AM$5:$AM$404,"<>Cancelled")=0,"",SUMPRODUCT(MIN(((Bookings!$C$5:$C$404=B8)*(Bookings!$I$5:$I$404>=TODAY())*(Bookings!$AM$5:$AM$404<>"Cancelled"))*Bookings!$I$5:$I$404+(1-((Bookings!$C$5:$C$404=B8)*(Bookings!$I$5:$I$404>=TODAY())*(Bookings!$AM$5:$AM$404<>"Cancelled")))*2958465)))) -> 0 | AE8: =IF(B8="","",SUMIFS(Payments!$L$5:$L$304,Payments!$C$5:$C$304,B8)) -> 0 | AF8: =IF(B8="","",SUMIFS(Invoices!$O$5:$O$304,Invoices!$D$5:$D$304,B8,Invoices!$T$5:$T$304,"<>Draft")) -> 0 | AG8: =IF(B8="","",SUMIFS(Invoices!$S$5:$S$304,Invoices!$D$5:$D$304,B8,Invoices!$T$5:$T$304,"<>Cancelled")) -> 0 | AH8: =IF(OR(Z8="",Z8=0),"",SUMIFS(Bookings!$AK$5:$AK$404,Bookings!$C$5:$C$404,B8,Bookings!$AM$5:$AM$404,"<>Cancelled")/Z8) -> 0 | AI8: =IF(B8="","",IF(Z8>=LoyaltyThreshold,"Loyalty discount","Standard")) -> 0 | AJ8: =IF(B8="","",IF(COUNTIF(Clients!$B$5:$B$254,B8)>1,"Duplicate name",IF(AND(C8<>"",COUNTIF(Clients!$C$5:$C$254,C8)>1),"Duplicate phone","OK"))) -> 0 | AK8: =IF(B8="","",IF(AND(C8<>"",D8<>"",L8<>"",M8<>""),"OK","Add: "&IF(C8="","phone ","")&IF(D8="","email ","")&IF(L8="","date ","")&IF(M8="","status",""))) -> 0 | AL8: =IF(B8="","",IF(AG8>0.5,"Overdue - chase payment",IF(AND(M8="Active",ISNUMBER(AC8),AC8>InactiveDays),"Inactive - win back",IF(AND(M8="Active",S8<>"Signed"),"Action - contract not signed",IF(AND(M8="Prospective",AD8=""),"Action - follow up quote","OK"))))) -> 0
A9: =IF(B9="","",ClientPrefix&TEXT(ROW()-4,"0000")) -> 0 | Y9: =IF(B9="","",COUNTIF(Pets!$C$5:$C$254,B9)) -> 0 | Z9: =IF(B9="","",COUNTIFS(Bookings!$C$5:$C$404,B9)) -> 0 | AA9: =IF(B9="","",COUNTIFS('Visit Log'!$D$5:$D$404,B9,'Visit Log'!$AE$5:$AE$404,"Completed")) -> 0 | AB9: =IF(B9="","",IF(SUMPRODUCT(MAX((Bookings!$C$5:$C$404=B9)*(Bookings!$AM$5:$AM$404="Completed")*Bookings!$I$5:$I$404))=0,"",SUMPRODUCT(MAX((Bookings!$C$5:$C$404=B9)*(Bookings!$AM$5:$AM$404="Completed")*Bookings!$I$5:$I$404)))) -> 0 | AC9: =IF(AB9="","",TODAY()-AB9) -> 0 | AD9: =IF(B9="","",IF(COUNTIFS(Bookings!$C$5:$C$404,B9,Bookings!$I$5:$I$404,">="&TODAY(),Bookings!$AM$5:$AM$404,"<>Cancelled")=0,"",SUMPRODUCT(MIN(((Bookings!$C$5:$C$404=B9)*(Bookings!$I$5:$I$404>=TODAY())*(Bookings!$AM$5:$AM$404<>"Cancelled"))*Bookings!$I$5:$I$404+(1-((Bookings!$C$5:$C$404=B9)*(Bookings!$I$5:$I$404>=TODAY())*(Bookings!$AM$5:$AM$404<>"Cancelled")))*2958465)))) -> 0 | AE9: =IF(B9="","",SUMIFS(Payments!$L$5:$L$304,Payments!$C$5:$C$304,B9)) -> 0 | AF9: =IF(B9="","",SUMIFS(Invoices!$O$5:$O$304,Invoices!$D$5:$D$304,B9,Invoices!$T$5:$T$304,"<>Draft")) -> 0 | AG9: =IF(B9="","",SUMIFS(Invoices!$S$5:$S$304,Invoices!$D$5:$D$304,B9,Invoices!$T$5:$T$304,"<>Cancelled")) -> 0 | AH9: =IF(OR(Z9="",Z9=0),"",SUMIFS(Bookings!$AK$5:$AK$404,Bookings!$C$5:$C$404,B9,Bookings!$AM$5:$AM$404,"<>Cancelled")/Z9) -> 0 | AI9: =IF(B9="","",IF(Z9>=LoyaltyThreshold,"Loyalty discount","Standard")) -> 0 | AJ9: =IF(B9="","",IF(COUNTIF(Clients!$B$5:$B$254,B9)>1,"Duplicate name",IF(AND(C9<>"",COUNTIF(Clients!$C$5:$C$254,C9)>1),"Duplicate phone","OK"))) -> 0 | AK9: =IF(B9="","",IF(AND(C9<>"",D9<>"",L9<>"",M9<>""),"OK","Add: "&IF(C9="","phone ","")&IF(D9="","email ","")&IF(L9="","date ","")&IF(M9="","status",""))) -> 0 | AL9: =IF(B9="","",IF(AG9>0.5,"Overdue - chase payment",IF(AND(M9="Active",ISNUMBER(AC9),AC9>InactiveDays),"Inactive - win back",IF(AND(M9="Active",S9<>"Signed"),"Action - contract not signed",IF(AND(M9="Prospective",AD9=""),"Action - follow up quote","OK"))))) -> 0
A10: =IF(B10="","",ClientPrefix&TEXT(ROW()-4,"0000")) -> 0 | Y10: =IF(B10="","",COUNTIF(Pets!$C$5:$C$254,B10)) -> 0 | Z10: =IF(B10="","",COUNTIFS(Bookings!$C$5:$C$404,B10)) -> 0 | AA10: =IF(B10="","",COUNTIFS('Visit Log'!$D$5:$D$404,B10,'Visit Log'!$AE$5:$AE$404,"Completed")) -> 0 | AB10: =IF(B10="","",IF(SUMPRODUCT(MAX((Bookings!$C$5:$C$404=B10)*(Bookings!$AM$5:$AM$404="Completed")*Bookings!$I$5:$I$404))=0,"",SUMPRODUCT(MAX((Bookings!$C$5:$C$404=B10)*(Bookings!$AM$5:$AM$404="Completed")*Bookings!$I$5:$I$404)))) -> 0 | AC10: =IF(AB10="","",TODAY()-AB10) -> 0 | AD10: =IF(B10="","",IF(COUNTIFS(Bookings!$C$5:$C$404,B10,Bookings!$I$5:$I$404,">="&TODAY(),Bookings!$AM$5:$AM$404,"<>Cancelled")=0,"",SUMPRODUCT(MIN(((Bookings!$C$5:$C$404=B10)*(Bookings!$I$5:$I$404>=TODAY())*(Bookings!$AM$5:$AM$404<>"Cancelled"))*Bookings!$I$5:$I$404+(1-((Bookings!$C$5:$C$404=B10)*(Bookings!$I$5:$I$404>=TODAY())*(Bookings!$AM$5:$AM$404<>"Cancelled")))*2958465)))) -> 0 | AE10: =IF(B10="","",SUMIFS(Payments!$L$5:$L$304,Payments!$C$5:$C$304,B10)) -> 0 | AF10: =IF(B10="","",SUMIFS(Invoices!$O$5:$O$304,Invoices!$D$5:$D$304,B10,Invoices!$T$5:$T$304,"<>Draft")) -> 0 | AG10: =IF(B10="","",SUMIFS(Invoices!$S$5:$S$304,Invoices!$D$5:$D$304,B10,Invoices!$T$5:$T$304,"<>Cancelled")) -> 0 | AH10: =IF(OR(Z10="",Z10=0),"",SUMIFS(Bookings!$AK$5:$AK$404,Bookings!$C$5:$C$404,B10,Bookings!$AM$5:$AM$404,"<>Cancelled")/Z10) -> 0 | AI10: =IF(B10="","",IF(Z10>=LoyaltyThreshold,"Loyalty discount","Standard")) -> 0 | AJ10: =IF(B10="","",IF(COUNTIF(Clients!$B$5:$B$254,B10)>1,"Duplicate name",IF(AND(C10<>"",COUNTIF(Clients!$C$5:$C$254,C10)>1),"Duplicate phone","OK"))) -> 0 | AK10: =IF(B10="","",IF(AND(C10<>"",D10<>"",L10<>"",M10<>""),"OK","Add: "&IF(C10="","phone ","")&IF(D10="","email ","")&IF(L10="","date ","")&IF(M10="","status",""))) -> 0 | AL10: =IF(B10="","",IF(AG10>0.5,"Overdue - chase payment",IF(AND(M10="Active",ISNUMBER(AC10),AC10>InactiveDays),"Inactive - win back",IF(AND(M10="Active",S10<>"Signed"),"Action - contract not signed",IF(AND(M10="Prospective",AD10=""),"Action - follow up quote","OK"))))) -> 0
A11: =IF(B11="","",ClientPrefix&TEXT(ROW()-4,"0000")) -> 0 | Y11: =IF(B11="","",COUNTIF(Pets!$C$5:$C$254,B11)) -> 0 | Z11: =IF(B11="","",COUNTIFS(Bookings!$C$5:$C$404,B11)) -> 0 | AA11: =IF(B11="","",COUNTIFS('Visit Log'!$D$5:$D$404,B11,'Visit Log'!$AE$5:$AE$404,"Completed")) -> 0 | AB11: =IF(B11="","",IF(SUMPRODUCT(MAX((Bookings!$C$5:$C$404=B11)*(Bookings!$AM$5:$AM$404="Completed")*Bookings!$I$5:$I$404))=0,"",SUMPRODUCT(MAX((Bookings!$C$5:$C$404=B11)*(Bookings!$AM$5:$AM$404="Completed")*Bookings!$I$5:$I$404)))) -> 0 | AC11: =IF(AB11="","",TODAY()-AB11) -> 0 | AD11: =IF(B11="","",IF(COUNTIFS(Bookings!$C$5:$C$404,B11,Bookings!$I$5:$I$404,">="&TODAY(),Bookings!$AM$5:$AM$404,"<>Cancelled")=0,"",SUMPRODUCT(MIN(((Bookings!$C$5:$C$404=B11)*(Bookings!$I$5:$I$404>=TODAY())*(Bookings!$AM$5:$AM$404<>"Cancelled"))*Bookings!$I$5:$I$404+(1-((Bookings!$C$5:$C$404=B11)*(Bookings!$I$5:$I$404>=TODAY())*(Bookings!$AM$5:$AM$404<>"Cancelled")))*2958465)))) -> 0 | AE11: =IF(B11="","",SUMIFS(Payments!$L$5:$L$304,Payments!$C$5:$C$304,B11)) -> 0 | AF11: =IF(B11="","",SUMIFS(Invoices!$O$5:$O$304,Invoices!$D$5:$D$304,B11,Invoices!$T$5:$T$304,"<>Draft")) -> 0 | AG11: =IF(B11="","",SUMIFS(Invoices!$S$5:$S$304,Invoices!$D$5:$D$304,B11,Invoices!$T$5:$T$304,"<>Cancelled")) -> 0 | AH11: =IF(OR(Z11="",Z11=0),"",SUMIFS(Bookings!$AK$5:$AK$404,Bookings!$C$5:$C$404,B11,Bookings!$AM$5:$AM$404,"<>Cancelled")/Z11) -> 0 | AI11: =IF(B11="","",IF(Z11>=LoyaltyThreshold,"Loyalty discount","Standard")) -> 0 | AJ11: =IF(B11="","",IF(COUNTIF(Clients!$B$5:$B$254,B11)>1,"Duplicate name",IF(AND(C11<>"",COUNTIF(Clients!$C$5:$C$254,C11)>1),"Duplicate phone","OK"))) -> 0 | AK11: =IF(B11="","",IF(AND(C11<>"",D11<>"",L11<>"",M11<>""),"OK","Add: "&IF(C11="","phone ","")&IF(D11="","email ","")&IF(L11="","date ","")&IF(M11="","status",""))) -> 0 | AL11: =IF(B11="","",IF(AG11>0.5,"Overdue - chase payment",IF(AND(M11="Active",ISNUMBER(AC11),AC11>InactiveDays),"Inactive - win back",IF(AND(M11="Active",S11<>"Signed"),"Action - contract not signed",IF(AND(M11="Prospective",AD11=""),"Action - follow up quote","OK"))))) -> 0
A12: =IF(B12="","",ClientPrefix&TEXT(ROW()-4,"0000")) -> 0 | Y12: =IF(B12="","",COUNTIF(Pets!$C$5:$C$254,B12)) -> 0 | Z12: =IF(B12="","",COUNTIFS(Bookings!$C$5:$C$404,B12)) -> 0 | AA12: =IF(B12="","",COUNTIFS('Visit Log'!$D$5:$D$404,B12,'Visit Log'!$AE$5:$AE$404,"Completed")) -> 0 | AB12: =IF(B12="","",IF(SUMPRODUCT(MAX((Bookings!$C$5:$C$404=B12)*(Bookings!$AM$5:$AM$404="Completed")*Bookings!$I$5:$I$404))=0,"",SUMPRODUCT(MAX((Bookings!$C$5:$C$404=B12)*(Bookings!$AM$5:$AM$404="Completed")*Bookings!$I$5:$I$404)))) -> 0 | AC12: =IF(AB12="","",TODAY()-AB12) -> 0 | AD12: =IF(B12="","",IF(COUNTIFS(Bookings!$C$5:$C$404,B12,Bookings!$I$5:$I$404,">="&TODAY(),Bookings!$AM$5:$AM$404,"<>Cancelled")=0,"",SUMPRODUCT(MIN(((Bookings!$C$5:$C$404=B12)*(Bookings!$I$5:$I$404>=TODAY())*(Bookings!$AM$5:$AM$404<>"Cancelled"))*Bookings!$I$5:$I$404+(1-((Bookings!$C$5:$C$404=B12)*(Bookings!$I$5:$I$404>=TODAY())*(Bookings!$AM$5:$AM$404<>"Cancelled")))*2958465)))) -> 0 | AE12: =IF(B12="","",SUMIFS(Payments!$L$5:$L$304,Payments!$C$5:$C$304,B12)) -> 0 | AF12: =IF(B12="","",SUMIFS(Invoices!$O$5:$O$304,Invoices!$D$5:$D$304,B12,Invoices!$T$5:$T$304,"<>Draft")) -> 0 | AG12: =IF(B12="","",SUMIFS(Invoices!$S$5:$S$304,Invoices!$D$5:$D$304,B12,Invoices!$T$5:$T$304,"<>Cancelled")) -> 0 | AH12: =IF(OR(Z12="",Z12=0),"",SUMIFS(Bookings!$AK$5:$AK$404,Bookings!$C$5:$C$404,B12,Bookings!$AM$5:$AM$404,"<>Cancelled")/Z12) -> 0 | AI12: =IF(B12="","",IF(Z12>=LoyaltyThreshold,"Loyalty discount","Standard")) -> 0 | AJ12: =IF(B12="","",IF(COUNTIF(Clients!$B$5:$B$254,B12)>1,"Duplicate name",IF(AND(C12<>"",COUNTIF(Clients!$C$5:$C$254,C12)>1),"Duplicate phone","OK"))) -> 0 | AK12: =IF(B12="","",IF(AND(C12<>"",D12<>"",L12<>"",M12<>""),"OK","Add: "&IF(C12="","phone ","")&IF(D12="","email ","")&IF(L12="","date ","")&IF(M12="","status",""))) -> 0 | AL12: =IF(B12="","",IF(AG12>0.5,"Overdue - chase payment",IF(AND(M12="Active",ISNUMBER(AC12),AC12>InactiveDays),"Inactive - win back",IF(AND(M12="Active",S12<>"Signed"),"Action - contract not signed",IF(AND(M12="Prospective",AD12=""),"Action - follow up quote","OK"))))) -> 0
A13: =IF(B13="","",ClientPrefix&TEXT(ROW()-4,"0000")) -> 0 | Y13: =IF(B13="","",COUNTIF(Pets!$C$5:$C$254,B13)) -> 0 | Z13: =IF(B13="","",COUNTIFS(Bookings!$C$5:$C$404,B13)) -> 0 | AA13: =IF(B13="","",COUNTIFS('Visit Log'!$D$5:$D$404,B13,'Visit Log'!$AE$5:$AE$404,"Completed")) -> 0 | AB13: =IF(B13="","",IF(SUMPRODUCT(MAX((Bookings!$C$5:$C$404=B13)*(Bookings!$AM$5:$AM$404="Completed")*Bookings!$I$5:$I$404))=0,"",SUMPRODUCT(MAX((Bookings!$C$5:$C$404=B13)*(Bookings!$AM$5:$AM$404="Completed")*Bookings!$I$5:$I$404)))) -> 0 | AC13: =IF(AB13="","",TODAY()-AB13) -> 0 | AD13: =IF(B13="","",IF(COUNTIFS(Bookings!$C$5:$C$404,B13,Bookings!$I$5:$I$404,">="&TODAY(),Bookings!$AM$5:$AM$404,"<>Cancelled")=0,"",SUMPRODUCT(MIN(((Bookings!$C$5:$C$404=B13)*(Bookings!$I$5:$I$404>=TODAY())*(Bookings!$AM$5:$AM$404<>"Cancelled"))*Bookings!$I$5:$I$404+(1-((Bookings!$C$5:$C$404=B13)*(Bookings!$I$5:$I$404>=TODAY())*(Bookings!$AM$5:$AM$404<>"Cancelled")))*2958465)))) -> 0 | AE13: =IF(B13="","",SUMIFS(Payments!$L$5:$L$304,Payments!$C$5:$C$304,B13)) -> 0 | AF13: =IF(B13="","",SUMIFS(Invoices!$O$5:$O$304,Invoices!$D$5:$D$304,B13,Invoices!$T$5:$T$304,"<>Draft")) -> 0 | AG13: =IF(B13="","",SUMIFS(Invoices!$S$5:$S$304,Invoices!$D$5:$D$304,B13,Invoices!$T$5:$T$304,"<>Cancelled")) -> 0 | AH13: =IF(OR(Z13="",Z13=0),"",SUMIFS(Bookings!$AK$5:$AK$404,Bookings!$C$5:$C$404,B13,Bookings!$AM$5:$AM$404,"<>Cancelled")/Z13) -> 0 | AI13: =IF(B13="","",IF(Z13>=LoyaltyThreshold,"Loyalty discount","Standard")) -> 0 | AJ13: =IF(B13="","",IF(COUNTIF(Clients!$B$5:$B$254,B13)>1,"Duplicate name",IF(AND(C13<>"",COUNTIF(Clients!$C$5:$C$254,C13)>1),"Duplicate phone","OK"))) -> 0 | AK13: =IF(B13="","",IF(AND(C13<>"",D13<>"",L13<>"",M13<>""),"OK","Add: "&IF(C13="","phone ","")&IF(D13="","email ","")&IF(L13="","date ","")&IF(M13="","status",""))) -> 0 | AL13: =IF(B13="","",IF(AG13>0.5,"Overdue - chase payment",IF(AND(M13="Active",ISNUMBER(AC13),AC13>InactiveDays),"Inactive - win back",IF(AND(M13="Active",S13<>"Signed"),"Action - contract not signed",IF(AND(M13="Prospective",AD13=""),"Action - follow up quote","OK"))))) -> 0
A14: =IF(B14="","",ClientPrefix&TEXT(ROW()-4,"0000")) -> 0 | Y14: =IF(B14="","",COUNTIF(Pets!$C$5:$C$254,B14)) -> 0 | Z14: =IF(B14="","",COUNTIFS(Bookings!$C$5:$C$404,B14)) -> 0 | AA14: =IF(B14="","",COUNTIFS('Visit Log'!$D$5:$D$404,B14,'Visit Log'!$AE$5:$AE$404,"Completed")) -> 0 | AB14: =IF(B14="","",IF(SUMPRODUCT(MAX((Bookings!$C$5:$C$404=B14)*(Bookings!$AM$5:$AM$404="Completed")*Bookings!$I$5:$I$404))=0,"",SUMPRODUCT(MAX((Bookings!$C$5:$C$404=B14)*(Bookings!$AM$5:$AM$404="Completed")*Bookings!$I$5:$I$404)))) -> 0 | AC14: =IF(AB14="","",TODAY()-AB14) -> 0 | AD14: =IF(B14="","",IF(COUNTIFS(Bookings!$C$5:$C$404,B14,Bookings!$I$5:$I$404,">="&TODAY(),Bookings!$AM$5:$AM$404,"<>Cancelled")=0,"",SUMPRODUCT(MIN(((Bookings!$C$5:$C$404=B14)*(Bookings!$I$5:$I$404>=TODAY())*(Bookings!$AM$5:$AM$404<>"Cancelled"))*Bookings!$I$5:$I$404+(1-((Bookings!$C$5:$C$404=B14)*(Bookings!$I$5:$I$404>=TODAY())*(Bookings!$AM$5:$AM$404<>"Cancelled")))*2958465)))) -> 0 | AE14: =IF(B14="","",SUMIFS(Payments!$L$5:$L$304,Payments!$C$5:$C$304,B14)) -> 0 | AF14: =IF(B14="","",SUMIFS(Invoices!$O$5:$O$304,Invoices!$D$5:$D$304,B14,Invoices!$T$5:$T$304,"<>Draft")) -> 0 | AG14: =IF(B14="","",SUMIFS(Invoices!$S$5:$S$304,Invoices!$D$5:$D$304,B14,Invoices!$T$5:$T$304,"<>Cancelled")) -> 0 | AH14: =IF(OR(Z14="",Z14=0),"",SUMIFS(Bookings!$AK$5:$AK$404,Bookings!$C$5:$C$404,B14,Bookings!$AM$5:$AM$404,"<>Cancelled")/Z14) -> 0 | AI14: =IF(B14="","",IF(Z14>=LoyaltyThreshold,"Loyalty discount","Standard")) -> 0 | AJ14: =IF(B14="","",IF(COUNTIF(Clients!$B$5:$B$254,B14)>1,"Duplicate name",IF(AND(C14<>"",COUNTIF(Clients!$C$5:$C$254,C14)>1),"Duplicate phone","OK"))) -> 0 | AK14: =IF(B14="","",IF(AND(C14<>"",D14<>"",L14<>"",M14<>""),"OK","Add: "&IF(C14="","phone ","")&IF(D14="","email ","")&IF(L14="","date ","")&IF(M14="","status",""))) -> 0 | AL14: =IF(B14="","",IF(AG14>0.5,"Overdue - chase payment",IF(AND(M14="Active",ISNUMBER(AC14),AC14>InactiveDays),"Inactive - win back",IF(AND(M14="Active",S14<>"Signed"),"Action - contract not signed",IF(AND(M14="Prospective",AD14=""),"Action - follow up quote","OK"))))) -> 0
A15: =IF(B15="","",ClientPrefix&TEXT(ROW()-4,"0000")) -> 0 | Y15: =IF(B15="","",COUNTIF(Pets!$C$5:$C$254,B15)) -> 0 | Z15: =IF(B15="","",COUNTIFS(Bookings!$C$5:$C$404,B15)) -> 0 | AA15: =IF(B15="","",COUNTIFS('Visit Log'!$D$5:$D$404,B15,'Visit Log'!$AE$5:$AE$404,"Completed")) -> 0 | AB15: =IF(B15="","",IF(SUMPRODUCT(MAX((Bookings!$C$5:$C$404=B15)*(Bookings!$AM$5:$AM$404="Completed")*Bookings!$I$5:$I$404))=0,"",SUMPRODUCT(MAX((Bookings!$C$5:$C$404=B15)*(Bookings!$AM$5:$AM$404="Completed")*Bookings!$I$5:$I$404)))) -> 0 | AC15: =IF(AB15="","",TODAY()-AB15) -> 0 | AD15: =IF(B15="","",IF(COUNTIFS(Bookings!$C$5:$C$404,B15,Bookings!$I$5:$I$404,">="&TODAY(),Bookings!$AM$5:$AM$404,"<>Cancelled")=0,"",SUMPRODUCT(MIN(((Bookings!$C$5:$C$404=B15)*(Bookings!$I$5:$I$404>=TODAY())*(Bookings!$AM$5:$AM$404<>"Cancelled"))*Bookings!$I$5:$I$404+(1-((Bookings!$C$5:$C$404=B15)*(Bookings!$I$5:$I$404>=TODAY())*(Bookings!$AM$5:$AM$404<>"Cancelled")))*2958465)))) -> 0 | AE15: =IF(B15="","",SUMIFS(Payments!$L$5:$L$304,Payments!$C$5:$C$304,B15)) -> 0 | AF15: =IF(B15="","",SUMIFS(Invoices!$O$5:$O$304,Invoices!$D$5:$D$304,B15,Invoices!$T$5:$T$304,"<>Draft")) -> 0 | AG15: =IF(B15="","",SUMIFS(Invoices!$S$5:$S$304,Invoices!$D$5:$D$304,B15,Invoices!$T$5:$T$304,"<>Cancelled")) -> 0 | AH15: =IF(OR(Z15="",Z15=0),"",SUMIFS(Bookings!$AK$5:$AK$404,Bookings!$C$5:$C$404,B15,Bookings!$AM$5:$AM$404,"<>Cancelled")/Z15) -> 0 | AI15: =IF(B15="","",IF(Z15>=LoyaltyThreshold,"Loyalty discount","Standard")) -> 0 | AJ15: =IF(B15="","",IF(COUNTIF(Clients!$B$5:$B$254,B15)>1,"Duplicate name",IF(AND(C15<>"",COUNTIF(Clients!$C$5:$C$254,C15)>1),"Duplicate phone","OK"))) -> 0 | AK15: =IF(B15="","",IF(AND(C15<>"",D15<>"",L15<>"",M15<>""),"OK","Add: "&IF(C15="","phone ","")&IF(D15="","email ","")&IF(L15="","date ","")&IF(M15="","status",""))) -> 0 | AL15: =IF(B15="","",IF(AG15>0.5,"Overdue - chase payment",IF(AND(M15="Active",ISNUMBER(AC15),AC15>InactiveDays),"Inactive - win back",IF(AND(M15="Active",S15<>"Signed"),"Action - contract not signed",IF(AND(M15="Prospective",AD15=""),"Action - follow up quote","OK"))))) -> 0
A16: =IF(B16="","",ClientPrefix&TEXT(ROW()-4,"0000")) -> 0 | Y16: =IF(B16="","",COUNTIF(Pets!$C$5:$C$254,B16)) -> 0 | Z16: =IF(B16="","",COUNTIFS(Bookings!$C$5:$C$404,B16)) -> 0 | AA16: =IF(B16="","",COUNTIFS('Visit Log'!$D$5:$D$404,B16,'Visit Log'!$AE$5:$AE$404,"Completed")) -> 0 | AB16: =IF(B16="","",IF(SUMPRODUCT(MAX((Bookings!$C$5:$C$404=B16)*(Bookings!$AM$5:$AM$404="Completed")*Bookings!$I$5:$I$404))=0,"",SUMPRODUCT(MAX((Bookings!$C$5:$C$404=B16)*(Bookings!$AM$5:$AM$404="Completed")*Bookings!$I$5:$I$404)))) -> 0 | AC16: =IF(AB16="","",TODAY()-AB16) -> 0 | AD16: =IF(B16="","",IF(COUNTIFS(Bookings!$C$5:$C$404,B16,Bookings!$I$5:$I$404,">="&TODAY(),Bookings!$AM$5:$AM$404,"<>Cancelled")=0,"",SUMPRODUCT(MIN(((Bookings!$C$5:$C$404=B16)*(Bookings!$I$5:$I$404>=TODAY())*(Bookings!$AM$5:$AM$404<>"Cancelled"))*Bookings!$I$5:$I$404+(1-((Bookings!$C$5:$C$404=B16)*(Bookings!$I$5:$I$404>=TODAY())*(Bookings!$AM$5:$AM$404<>"Cancelled")))*2958465)))) -> 0 | AE16: =IF(B16="","",SUMIFS(Payments!$L$5:$L$304,Payments!$C$5:$C$304,B16)) -> 0 | AF16: =IF(B16="","",SUMIFS(Invoices!$O$5:$O$304,Invoices!$D$5:$D$304,B16,Invoices!$T$5:$T$304,"<>Draft")) -> 0 | AG16: =IF(B16="","",SUMIFS(Invoices!$S$5:$S$304,Invoices!$D$5:$D$304,B16,Invoices!$T$5:$T$304,"<>Cancelled")) -> 0 | AH16: =IF(OR(Z16="",Z16=0),"",SUMIFS(Bookings!$AK$5:$AK$404,Bookings!$C$5:$C$404,B16,Bookings!$AM$5:$AM$404,"<>Cancelled")/Z16) -> 0 | AI16: =IF(B16="","",IF(Z16>=LoyaltyThreshold,"Loyalty discount","Standard")) -> 0 | AJ16: =IF(B16="","",IF(COUNTIF(Clients!$B$5:$B$254,B16)>1,"Duplicate name",IF(AND(C16<>"",COUNTIF(Clients!$C$5:$C$254,C16)>1),"Duplicate phone","OK"))) -> 0 | AK16: =IF(B16="","",IF(AND(C16<>"",D16<>"",L16<>"",M16<>""),"OK","Add: "&IF(C16="","phone ","")&IF(D16="","email ","")&IF(L16="","date ","")&IF(M16="","status",""))) -> 0 | AL16: =IF(B16="","",IF(AG16>0.5,"Overdue - chase payment",IF(AND(M16="Active",ISNUMBER(AC16),AC16>InactiveDays),"Inactive - win back",IF(AND(M16="Active",S16<>"Signed"),"Action - contract not signed",IF(AND(M16="Prospective",AD16=""),"Action - follow up quote","OK"))))) -> 0
