Workbook
Name AppointmentDates: OFFSET(Appointments!$B$5,0,0,MAX(1,COUNTIF(Appointments!$B$5:$B$1204,"?*")),1)
Name AppointmentIDs: OFFSET(Appointments!$A$5,0,0,MAX(1,COUNTIF(Appointments!$A$5:$A$1204,"?*")),1)
Name AppointmentPrefix: Settings!$C$106
Name AppointmentStatus: OFFSET(Appointments!$M$5,0,0,MAX(1,COUNTIF(Appointments!$M$5:$M$1204,"?*")),1)
Name AppointmentStatusList: Settings!$A$148:$A$161
Name ApprenticeCommission: Settings!$D$55
Name BudgetAmount: 'Goals & Budget'!$C$45:$C$64
Name BudgetCategory: 'Goals & Budget'!$B$45:$B$64
Name BudgetMonthlyTotal: 'Goals & Budget'!$C$65
Name CampaignPrefix: Settings!$G$107
Name CampaignStatusList: Settings!$D$232:$D$242
Name CancellationHours: Settings!$D$44
Name CancelReasonList: Settings!$G$148:$G$163
Name CardFeeFixed: Settings!$D$41
Name CardFeePercent: Settings!$D$40
Name ChairHoursWeek: Settings!$D$31
Name ChairRentWeek: Settings!$D$59
Name Chairs: Settings!$D$30
Name ClientCount: Settings!$D$117
Name ClientList: OFFSET(Clients!$A$5,0,0,MAX(1,COUNTIF(Clients!$A$5:$A$504,"?*")),1)
Name ClientNames: OFFSET(Clients!$B$5,0,0,MAX(1,COUNTIF(Clients!$B$5:$B$504,"?*")),1)
Name ClientPrefix: Settings!$C$103
Name ClientSegments: OFFSET(Clients!$AM$5,0,0,MAX(1,COUNTIF(Clients!$AM$5:$AM$504,"?*")),1)
Name ClientStatusList: Settings!$A$169:$A$181
Name ClientTargetYear: 'Goals & Budget'!$D$20
Name CloseHour: Settings!$D$28
Name CommissionMethodList: Settings!$G$185:$G$198
Name CommissionOn: Settings!$D$58
Name CommissionPrefix: Settings!$C$109
Name ContactList: Settings!$J$148:$J$159
Name CurrencySign: Settings!$D$19
Name DashKey: Dashboard!$H$5
Name DashPrevKey: Dashboard!$K$5
Name DefaultHourly: Settings!$D$56
Name DepositPercent: Settings!$D$42
Name DepositThreshold: Settings!$D$43
Name ExpenseAmounts: OFFSET(Expenses!$F$5,0,0,MAX(1,COUNTIF(Expenses!$F$5:$F$604,"?*")),1)
Name ExpenseCategoriesCol: OFFSET(Expenses!$C$5,0,0,MAX(1,COUNTIF(Expenses!$C$5:$C$604,"?*")),1)
Name ExpenseCategoryList: Settings!$A$201:$A$229
Name ExpenseMonths: OFFSET(Expenses!$P$5,0,0,MAX(1,COUNTIF(Expenses!$P$5:$P$604,"?*")),1)
Name ExpensePrefix: Settings!$G$104
Name FrequencyList: Settings!$D$201:$D$214
Name InactiveDays: Settings!$D$93
Name LapsingDays: Settings!$D$92
Name LoyaltyPrefix: Settings!$G$108
Name LoyaltyRewardList: Settings!$G$232:$G$245
Name MarketingChannelList: Settings!$A$232:$A$252
Name MonthCostOfSales: Dashboard!$B$80
Name MonthExpenses: Dashboard!$E$80
Name MonthKeyList: Settings!$A$259:$A$283
Name MonthKeys: OFFSET(Settings!$A$259,0,0,MAX(1,COUNTIF(Settings!$A$259:$A$283,"?*")),1)
Name MonthNetSales: Dashboard!$A$80
Name MonthWages: Dashboard!$D$80
Name NetSalesAll: Settings!$D$116
Name NewClientTargetYear: 'Goals & Budget'!$D$21
Name NoShowFee: Settings!$D$45
Name OpenDays: Settings!$D$29
Name OpenHour: Settings!$D$27
Name OwnerName: Settings!$D$9
Name PatchTestDays: Settings!$D$94

Sheet Start Here
A1: Salon Business Management Spreadsheet | H1: Novality Store | v1.0.0
A2: A complete salon business system in one spreadsheet - diary, clients, prices, takings, staff pay, stock and profit.
A3: > Start Here | C3: > Dashboard | E3: > Diary | G3: > Clients | I3: > Services
A5: Everything in this workbook is worked out from four tabs you fill in as you go: the diary, the till, the expenses and the pay runs. Fill those honestly and the dashboard, the profit and loss and the reports look after themselves.
A7: Setting up, in six steps
B8: 1. Settings first | C8: Open the Settings tab and work down it: salon name, currency, tax rate and what tax applies to, deposit rule, rounding, the commission defaults and your targets. Ten minutes here saves every other tab from guessing.
B9: 2. Put your menu in | C9: On the Services tab, type each treatment with its price, how many minutes it takes and what the product costs you. The minutes matter as much as the price - that is what turns a price list into a profit list.
B10: 3. Add the team | C10: On the Staff tab, add everyone and pick their commission method. Nothing is assumed: commission only, hourly, a flat amount per service, tiered, a chair renter who pays you rent, or none at all.
B11: 4. Bring the clients across | C11: Paste or type your client list - name, phone, email and the 'found you by' column. Everything else fills itself in as you start logging visits.
B12: 5. Work the diary and the till | C12: Log appointments as you book them and sales as you ring them up. A deposit goes on the Payments tab against the booking; it is applied to the bill when the client comes in, so it can never be counted as revenue twice.
B13: 6. Once a month | C13: Add a commission row per stylist, run the payroll rows, log the bills on Expenses, count the stock, and read the Profit & Loss. Twenty minutes, and you know exactly how the month went.
A15: What is on each tab
B16: Tab | C16: What it is for | D16: You
B17: Dashboard | C17: The month at a glance: takings against target, average ticket, utilisation, rebooking, and the jobs that need doing today. | J17: Read it
B18: Appointments | C18: The diary. Date, time, client, service, stylist and status - with a double-booking alarm. | J18: Type here
B19: Clients | C19: The client book: contact details, formula, patch test, spend, last visit, and who is drifting away. | J19: Type here
B20: Services | C20: Your menu, with the minutes, the product cost and what each treatment earns an hour. | J20: Type here
B21: Sales | C21: The till. One row per thing sold - gross, discount, refund, net, tax and profit. | J21: Type here
B22: Payments | C22: Money in and out: deposits, balances, tips, refunds and the card fees. | J22: Type here
B23: Staff | C23: The team, their pay basis and what each chair brings in an hour. | J23: Type here
B24: Commissions | C24: One row per stylist per month. Eight methods supported - you choose, per person. | J24: Type here
B25: Payroll | C25: Pay runs: hours, commission released, tips passed on and the employer costs on top. | J25: Type here
B26: Expenses | C26: Every cost, categorised the way a profit and loss wants it, with the recurring ones spread. | J26: Type here
B27: Profit & Loss | C27: Twelve months of income, cost of sales, staff cost, overheads and operating profit. | J27: Read it
B28: Inventory | C28: Retail and backbar stock: what is left, what it is worth, what to order. | J28: Type here
... B35: Settings | C35: Your salon, your tax rules, your pay model, your lists. Set these first. | J35: Set it up
A37: Seven rules that keep it working
B38: - Blue cells are yours. Grey cells are formulas - they are locked so a stray paste cannot break the workbook.
B39: - Every sheet is protected with the password 'premium'. Review > Unprotect Sheet if you want to change the structure.
B40: - IDs number themselves from the row. Filter and sort freely, but do not cut and paste rows around - copy the values instead.
B41: - Type dates as real dates. 14/03 or 3/14 depending on where you are, not '14 march'.
B42: - Status is the engine: Completed, Cancelled and No show are the three final answers an appointment can have. Everything else is still open and is left out of the completion and cancellation rates.
B43: - Never type over a formula to make a number look right. Find the row that is wrong instead - the alert columns are there to point at it.
B44: - Add rows by typing in the first empty row of a tab. Every tab has hundreds already formatted and waiting.
A46: What this workbook does not do
B47: - It does not send confirmations, reminders, texts or emails, and it does not sync with any booking platform, till or card reader. Everything in here is typed in or pasted in by you.
B48: - It is not accounting, payroll or tax software, and nothing in it is accounting, payroll or tax advice. It organises your business so that the conversation with your accountant is a short one.
B49: - It does not calculate income tax, national insurance or social security on wages. It shows what a pay run costs the salon.
B50: - It does not take payments or store card details.
B51: - Sales tax is whatever you set it to be. There is no country baked in, and the two switches let you tax retail, services, both or neither.
...

Sheet Dashboard
A1: Salon Dashboard | K1: Novality Store | v1.0.0
A2: Takings, bookings, clients and chairs - worked out from the diary, the till and the payroll you have already filled in.
A3: > Start Here | C3: > Dashboard | E3: > Diary | G3: > Clients | I3: > Services | K3: > Sales
A5: Salon | B5: =SalonName -> 0 | E5: Month | F5: =TEXT(TodayDate,"mmmm yyyy") -> 0 | G5: Month key | H5: =TEXT(TodayDate,"yyyy-mm") -> 0 | I5: Last month | K5: =TEXT(DATE(YEAR(TodayDate),MONTH(TodayDate)-1,1),"yyyy-mm") -> 0 | L5: Today | M5: =TodayDate -> 0
A7: Net sales this month | D7: Against target | G7: Operating profit, month | J7: Profit margin
A8: =ROUND(SUMIFS(Sales!$Y$5:$Y$1204,Sales!$R$5:$R$1204,DashKey),2) -> 0 | D8: =IFERROR(SUMIFS(Sales!$Y$5:$Y$1204,Sales!$R$5:$R$1204,DashKey)/MAX(0.01,RevenueTargetMonth),"") -> 0 | G8: =ROUND(MonthNetSales-MonthCostOfSales-MonthWages-MonthExpenses,2) -> 0 | J8: =IF(MonthNetSales<=0,"",(MonthNetSales-MonthCostOfSales-MonthWages-MonthExpenses)/MonthNetSales) -> 0
A9: target $28,000 | D9: 100% means the month is made | G9: net sales less stock, wages and costs | J9: what is left of every dollar
A11: Clients served, month | D11: Average ticket | G11: Retail share | J11: Tips passed on
A12: =COUNTIFS(Appointments!$S$5:$S$1204,DashKey,Appointments!$M$5:$M$1204,"Completed") -> 0 | D12: =IFERROR(SUMIFS(Sales!$Y$5:$Y$1204,Sales!$R$5:$R$1204,DashKey)/MAX(1,COUNTIFS(Appointments!$S$5:$S$1204,DashKey,Appointments!$M$5:$M$1204,"Completed")),"") -> 0 | G12: =IFERROR(SUMIFS(Sales!$Y$5:$Y$1204,Sales!$R$5:$R$1204,DashKey,Sales!$H$5:$H$1204,"Retail")/MAX(0.01,SUMIFS(Sales!$Y$5:$Y$1204,Sales!$R$5:$R$1204,DashKey)),"") -> 0 | J12: =ROUND(SUMIFS(Payments!$G$5:$G$1204,Payments!$O$5:$O$1204,DashKey,Payments!$E$5:$E$1204,"Tip"),2) -> 0
A13: completed appointments | D13: target $78 | G13: target 12% | J13: the team's money, not the salon's
A15: Completion rate | D15: Cancellation rate | G15: No-show rate | J15: Chair utilisation
A16: =IFERROR(COUNTIFS(Appointments!$S$5:$S$1204,DashKey,Appointments!$M$5:$M$1204,"Completed")/MAX(1,COUNTIFS(Appointments!$S$5:$S$1204,DashKey,Appointments!$AC$5:$AC$1204,"Yes")),"") -> 0 | D16: =IFERROR(COUNTIFS(Appointments!$S$5:$S$1204,DashKey,Appointments!$M$5:$M$1204,"Cancelled")/MAX(1,COUNTIFS(Appointments!$S$5:$S$1204,DashKey,Appointments!$AC$5:$AC$1204,"Yes")),"") -> 0 | G16: =IFERROR(COUNTIFS(Appointments!$S$5:$S$1204,DashKey,Appointments!$M$5:$M$1204,"No show")/MAX(1,COUNTIFS(Appointments!$S$5:$S$1204,DashKey,Appointments!$AC$5:$AC$1204,"Yes")),"") -> 0 | J16: =IFERROR(SUMIFS(Appointments!$X$5:$X$1204,Appointments!$S$5:$S$1204,DashKey,Appointments!$M$5:$M$1204,"Completed")/MAX(1,ChairHoursWeek*4.33),"") -> 0
A17: of bookings that reached a final answer | D17: cancelled, not no-showed | G17: the most expensive hour in the salon | J17: target 75% of sellable hours
A19: Rebooking rate | D19: Repeat client rate | G19: Owed to you | J19: Stock on the shelf
A20: =IFERROR(COUNTIFS(Appointments!$S$5:$S$1204,DashKey,Appointments!$AF$5:$AF$1204,"Yes")/MAX(1,COUNTIFS(Appointments!$S$5:$S$1204,DashKey,Appointments!$M$5:$M$1204,"Completed")),"") -> 0 | D20: =IFERROR(COUNTIFS(Clients!$AN$5:$AN$504,"Yes")/MAX(1,COUNTIFS(Clients!$T$5:$T$504,">0")),"") -> 0 | G20: =ROUND(SUMIFS(Sales!$AH$5:$AH$1204,Sales!$AH$5:$AH$1204,">0.004"),2) -> 0 | J20: =ROUND(SUM(Inventory!$AB$5:$AB$304),2) -> 0
A21: target 60% leaving with the next one booked | D21: clients served who came back at least twice | G21: unpaid balances across every client | J21: at cost, retail and backbar
A23: Needs doing today
A24: What | B24: How many | C24: What it means | D24: Where to fix it
A25: Clashes in the diary | B25: =COUNTIF(Appointments!$AG$5:$AG$1204,"Clash") -> 0 | C25: ="Two bookings for the same stylist at the same time" -> 0 | L25: Appointments
A26: Bookings to confirm | B26: =COUNTIF(Appointments!$AH$5:$AH$1204,"Confirm*") -> 0 | C26: ="Coming up in the next two days and not confirmed" -> 0 | L26: Appointments
A27: Deposits not taken | B27: =COUNTIF(Appointments!$AH$5:$AH$1204,"Due - deposit*") -> 0 | C27: ="Bookings over "&TEXT(DepositThreshold,"0")&" with no deposit against them" -> 0 | L27: Appointments
A28: Visits with nothing rung up | B28: =COUNTIF(Appointments!$AH$5:$AH$1204,"Unpaid*") -> 0 | C28: ="Marked completed but no sale was logged" -> 0 | L28: Sales
A29: Unpaid balances | B29: =COUNTIFS(Sales!$AH$5:$AH$1204,">0.004") -> 0 | C29: ="Sales where money is still owed" -> 0 | L29: Payments
A30: Clients lapsing | B30: =COUNTIF(Clients!$AM$5:$AM$504,"Lapsing") -> 0 | C30: ="Not in for "&LapsingDays&" days. Call them before they become inactive" -> 0 | L30: Clients
A31: Clients due a rebook | B31: =COUNTIF(Clients!$AQ$5:$AQ$504,"Rebook*") -> 0 | C31: ="Past their usual gap with nothing in the book" -> 0 | L31: Clients
A32: Patch tests out of date | B32: =COUNTIF(Clients!$AQ$5:$AQ$504,"Due - patch*") -> 0 | C32: ="Colour clients whose patch test is older than "&PatchTestDays&" days" -> 0 | L32: Clients
A33: Products out of stock | B33: =COUNTIF(Inventory!$Z$5:$Z$304,"Out of stock") -> 0 | C33: ="Nothing left on the shelf to sell or use" -> 0 | L33: Inventory
A34: Products to reorder | B34: =COUNTIF(Inventory!$Z$5:$Z$304,"Low stock") -> 0 | C34: ="Below the reorder point or under "&StockWarningWeeks&" weeks of cover" -> 0 | L34: Inventory
A35: Deliveries late | B35: =COUNTIF(Purchases!$Y$5:$Y$304,"Late*") -> 0 | C35: ="Ordered, expected, still not here" -> 0 | L35: Purchases
A36: Bills overdue | B36: =COUNTIF(Expenses!$V$5:$V$604,"Overdue") -> 0 | C36: ="Past the due date and not marked paid" -> 0 | L36: Expenses
A37: Commission to approve | B37: =COUNTIFS(Commissions!$H$5:$H$244,"<>Yes",Commissions!$B$5:$B$244,"<>") -> 0 | C37: ="Calculated and waiting for your sign-off" -> 0 | L37: Commissions
A38: Pay runs not paid | B38: =COUNTIFS(Payroll!$M$5:$M$364,"<>Yes",Payroll!$B$5:$B$364,"<>") -> 0 | C38: ="Payroll rows still open" -> 0 | L38: Payroll
A39: Loyalty rewards ready | B39: =COUNTIF(Loyalty!$X$5:$X$504,"Action - reward*") -> 0 | C39: ="Clients who have earned something. Tell them" -> 0 | L39: Loyalty
A40: Services below your chair rate | B40: =SUMPRODUCT((IFERROR(Services!$V$5:$V$204*1,0)>0)*(IFERROR(Services!$V$5:$V$204*1,0)<TargetChairRate)) -> 0 | C40: ="Earning less than "&TEXT(TargetChairRate,"0")&" an hour before commission" -> 0 | L40: Services
A42: Who is earning what
A43: Stylist | B43: Sales this month | C43: Against target | D43: Completed | E43: Average ticket | F43: Retail share | G43: Utilisation | H43: Rebook rate | I43: Commission | J43: Pay this month | K43: Leaves behind
A44: =IFERROR(INDEX(Staff!$B$5:$B$44,MATCH(1,Staff!$AN$5:$AN$44,0)),"") -> 0 | B44: =IFERROR(INDEX(Staff!$AD$5:$AD$44,MATCH(1,Staff!$AN$5:$AN$44,0)),"") -> 0 | C44: =IFERROR(INDEX(Staff!$AE$5:$AE$44,MATCH(1,Staff!$AN$5:$AN$44,0)),"") -> 0 | D44: =IFERROR(INDEX(Staff!$U$5:$U$44,MATCH(1,Staff!$AN$5:$AN$44,0)),"") -> 0 | E44: =IFERROR(INDEX(Staff!$AF$5:$AF$44,MATCH(1,Staff!$AN$5:$AN$44,0)),"") -> 0 | F44: =IFERROR(INDEX(Staff!$AG$5:$AG$44,MATCH(1,Staff!$AN$5:$AN$44,0)),"") -> 0 | G44: =IFERROR(INDEX(Staff!$Z$5:$Z$44,MATCH(1,Staff!$AN$5:$AN$44,0)),"") -> 0 | H44: =IFERROR(INDEX(Staff!$AI$5:$AI$44,MATCH(1,Staff!$AN$5:$AN$44,0)),"") -> 0 | I44: =IFERROR(INDEX(Staff!$AK$5:$AK$44,MATCH(1,Staff!$AN$5:$AN$44,0)),"") -> 0 | J44: =IFERROR(INDEX(Staff!$AL$5:$AL$44,MATCH(1,Staff!$AN$5:$AN$44,0)),"") -> 0 | K44: =IFERROR(INDEX(Staff!$AM$5:$AM$44,MATCH(1,Staff!$AN$5:$AN$44,0)),"") -> 0
A45: =IFERROR(INDEX(Staff!$B$5:$B$44,MATCH(2,Staff!$AN$5:$AN$44,0)),"") -> 0 | B45: =IFERROR(INDEX(Staff!$AD$5:$AD$44,MATCH(2,Staff!$AN$5:$AN$44,0)),"") -> 0 | C45: =IFERROR(INDEX(Staff!$AE$5:$AE$44,MATCH(2,Staff!$AN$5:$AN$44,0)),"") -> 0 | D45: =IFERROR(INDEX(Staff!$U$5:$U$44,MATCH(2,Staff!$AN$5:$AN$44,0)),"") -> 0 | E45: =IFERROR(INDEX(Staff!$AF$5:$AF$44,MATCH(2,Staff!$AN$5:$AN$44,0)),"") -> 0 | F45: =IFERROR(INDEX(Staff!$AG$5:$AG$44,MATCH(2,Staff!$AN$5:$AN$44,0)),"") -> 0 | G45: =IFERROR(INDEX(Staff!$Z$5:$Z$44,MATCH(2,Staff!$AN$5:$AN$44,0)),"") -> 0 | H45: =IFERROR(INDEX(Staff!$AI$5:$AI$44,MATCH(2,Staff!$AN$5:$AN$44,0)),"") -> 0 | I45: =IFERROR(INDEX(Staff!$AK$5:$AK$44,MATCH(2,Staff!$AN$5:$AN$44,0)),"") -> 0 | J45: =IFERROR(INDEX(Staff!$AL$5:$AL$44,MATCH(2,Staff!$AN$5:$AN$44,0)),"") -> 0 | K45: =IFERROR(INDEX(Staff!$AM$5:$AM$44,MATCH(2,Staff!$AN$5:$AN$44,0)),"") -> 0
A46: =IFERROR(INDEX(Staff!$B$5:$B$44,MATCH(3,Staff!$AN$5:$AN$44,0)),"") -> 0 | B46: =IFERROR(INDEX(Staff!$AD$5:$AD$44,MATCH(3,Staff!$AN$5:$AN$44,0)),"") -> 0 | C46: =IFERROR(INDEX(Staff!$AE$5:$AE$44,MATCH(3,Staff!$AN$5:$AN$44,0)),"") -> 0 | D46: =IFERROR(INDEX(Staff!$U$5:$U$44,MATCH(3,Staff!$AN$5:$AN$44,0)),"") -> 0 | E46: =IFERROR(INDEX(Staff!$AF$5:$AF$44,MATCH(3,Staff!$AN$5:$AN$44,0)),"") -> 0 | F46: =IFERROR(INDEX(Staff!$AG$5:$AG$44,MATCH(3,Staff!$AN$5:$AN$44,0)),"") -> 0 | G46: =IFERROR(INDEX(Staff!$Z$5:$Z$44,MATCH(3,Staff!$AN$5:$AN$44,0)),"") -> 0 | H46: =IFERROR(INDEX(Staff!$AI$5:$AI$44,MATCH(3,Staff!$AN$5:$AN$44,0)),"") -> 0 | I46: =IFERROR(INDEX(Staff!$AK$5:$AK$44,MATCH(3,Staff!$AN$5:$AN$44,0)),"") -> 0 | J46: =IFERROR(INDEX(Staff!$AL$5:$AL$44,MATCH(3,Staff!$AN$5:$AN$44,0)),"") -> 0 | K46: =IFERROR(INDEX(Staff!$AM$5:$AM$44,MATCH(3,Staff!$AN$5:$AN$44,0)),"") -> 0
A47: =IFERROR(INDEX(Staff!$B$5:$B$44,MATCH(4,Staff!$AN$5:$AN$44,0)),"") -> 0 | B47: =IFERROR(INDEX(Staff!$AD$5:$AD$44,MATCH(4,Staff!$AN$5:$AN$44,0)),"") -> 0 | C47: =IFERROR(INDEX(Staff!$AE$5:$AE$44,MATCH(4,Staff!$AN$5:$AN$44,0)),"") -> 0 | D47: =IFERROR(INDEX(Staff!$U$5:$U$44,MATCH(4,Staff!$AN$5:$AN$44,0)),"") -> 0 | E47: =IFERROR(INDEX(Staff!$AF$5:$AF$44,MATCH(4,Staff!$AN$5:$AN$44,0)),"") -> 0 | F47: =IFERROR(INDEX(Staff!$AG$5:$AG$44,MATCH(4,Staff!$AN$5:$AN$44,0)),"") -> 0 | G47: =IFERROR(INDEX(Staff!$Z$5:$Z$44,MATCH(4,Staff!$AN$5:$AN$44,0)),"") -> 0 | H47: =IFERROR(INDEX(Staff!$AI$5:$AI$44,MATCH(4,Staff!$AN$5:$AN$44,0)),"") -> 0 | I47: =IFERROR(INDEX(Staff!$AK$5:$AK$44,MATCH(4,Staff!$AN$5:$AN$44,0)),"") -> 0 | J47: =IFERROR(INDEX(Staff!$AL$5:$AL$44,MATCH(4,Staff!$AN$5:$AN$44,0)),"") -> 0 | K47: =IFERROR(INDEX(Staff!$AM$5:$AM$44,MATCH(4,Staff!$AN$5:$AN$44,0)),"") -> 0
...

Sheet Appointments
A1: Appointment Planner | AF1: Novality Store | v1.0.0
A2: The diary: who, with whom, how long, how much - and a double-booking alarm that checks every row.
A3: > Start Here | C3: > Dashboard | E3: > Diary | G3: > Clients | I3: > Services | K3: > Sales | M3: > Staff | O3: > Profit | Q3: > Settings | S3: Date, start time, client, service, stylist, status. The finish time, the price and the clash check look after themselves.
A4: ID | B4: Date | C4: Day | D4: Start | E4: Client ID | F4: Client | G4: Service ID | H4: Service | I4: Stylist ID | J4: Stylist | K4: Minutes | L4: Price | M4: Status | N4: Booked via | O4: Deposit asked | P4: Notes | Q4: If cancelled, why | R4: Late fee charged | S4: Month | T4: Week | U4: Minutes used | V4: Finishes | W4: Hour | X4: Chair hours | Y4: Price charged | Z4: Deposit wanted | AA4: Deposit paid | AB4: Billed | AC4: Final? | AD4: Booked ahead | AE4: Booked on | AF4: Rebooked? | AG4: Clash? | AH4: Action
A5: =IF(B5="","",AppointmentPrefix&TEXT(ROW()-4,"0000")) -> 0 | C5: =IF(B5="","",TEXT(B5,"ddd")) -> 0 | F5: =IF(E5="","",IFERROR(INDEX(Clients!$B$5:$B$504,MATCH(E5,Clients!$A$5:$A$504,0)),"Walk-in")) -> 0 | H5: =IF(G5="","",IFERROR(INDEX(Services!$B$5:$B$204,MATCH(G5,Services!$A$5:$A$204,0)),"Not in Services")) -> 0 | J5: =IF(I5="","",IFERROR(INDEX(Staff!$B$5:$B$44,MATCH(I5,Staff!$A$5:$A$44,0)),"Unassigned")) -> 0 | S5: =IF(B5="","",TEXT(B5,"yyyy-mm")) -> 0 | T5: =IF(B5="","",WEEKNUM(B5,2)) -> 0 | U5: =IF(B5="","",IF(K5<>"",K5,IFERROR(INDEX(Services!$E$5:$E$204,MATCH(G5,Services!$A$5:$A$204,0))*1,0)+IFERROR(INDEX(Services!$F$5:$F$204,MATCH(G5,Services!$A$5:$A$204,0))*1,0))) -> 0 | V5: =IF(B5="","",IF(D5="","",D5+U5/1440)) -> 0 | W5: =IF(B5="","",IF(D5="","",HOUR(D5))) -> 0 | X5: =IF(B5="","",ROUND(U5/60,2)) -> 0 | Y5: =IF(B5="","",IF(L5<>"",L5,IFERROR(INDEX(Services!$G$5:$G$204,MATCH(G5,Services!$A$5:$A$204,0))*1,0))) -> 0 | Z5: =IF(B5="","",IF(O5<>"",O5,IF(Y5>=DepositThreshold,ROUND(Y5*DepositPercent,2),0))) -> 0 | AA5: =IF(B5="","",ROUND(SUMIFS(Payments!$G$5:$G$1204,Payments!$I$5:$I$1204,A5,Payments!$E$5:$E$1204,"Deposit"),2)) -> 0 | AB5: =IF(B5="","",ROUND(SUMIFS(Sales!$Y$5:$Y$1204,Sales!$C$5:$C$1204,A5),2)) -> 0 | AC5: =IF(B5="","",IF(M5="Completed","Yes",IF(M5="Cancelled","Yes",IF(M5="No show","Yes","No")))) -> 0 | AD5: =IF(B5="","",IF(AE5="","",B5-AE5)) -> 0 | AF5: =IF(B5="","",IF(M5<>"Completed","",IF(E5="","No",IF(COUNTIFS(Appointments!$E$5:$E$1204,E5,Appointments!$B$5:$B$1204,">"&B5,Appointments!$M$5:$M$1204,"<>Cancelled")>0,"Yes","No")))) -> 0 | AG5: =IF(B5="","",IF(I5="","",IF(D5="","",IF(COUNTIFS($I$5:$I$1204,I5,$B$5:$B$1204,B5,$D$5:$D$1204,"<"&V5,$V$5:$V$1204,">"&D5,$M$5:$M$1204,"<>Cancelled")>1,"Clash","")))) -> 0 | AH5: =IF(B5="","",IF(AG5="Clash","Clash - stylist double booked",IF(I5="","Assign - no stylist yet",IF(G5="","Add - no service chosen",IF(M5="No show","No show - charge the fee?",IF(M5="Cancelled","",IF(IF(M5="Completed",AB5<Y5-0.004,FALSE),"Unpaid - nothing rung up for this visit",IF(IF(B5<TodayDate,M5="Booked",FALSE),"Overdue - past date, still only Booked",IF(IF(B5=TodayDate,TRUE,FALSE),"Today",IF(IF(Z5>0,AA5<Z5-0.004,FALSE),"Due - deposit not taken",IF(IF(B5>TodayDate,B5<=TodayDate+2,FALSE),"Confirm - coming up","OK"))))))))))) -> 0
A6: =IF(B6="","",AppointmentPrefix&TEXT(ROW()-4,"0000")) -> 0 | C6: =IF(B6="","",TEXT(B6,"ddd")) -> 0 | F6: =IF(E6="","",IFERROR(INDEX(Clients!$B$5:$B$504,MATCH(E6,Clients!$A$5:$A$504,0)),"Walk-in")) -> 0 | H6: =IF(G6="","",IFERROR(INDEX(Services!$B$5:$B$204,MATCH(G6,Services!$A$5:$A$204,0)),"Not in Services")) -> 0 | J6: =IF(I6="","",IFERROR(INDEX(Staff!$B$5:$B$44,MATCH(I6,Staff!$A$5:$A$44,0)),"Unassigned")) -> 0 | S6: =IF(B6="","",TEXT(B6,"yyyy-mm")) -> 0 | T6: =IF(B6="","",WEEKNUM(B6,2)) -> 0 | U6: =IF(B6="","",IF(K6<>"",K6,IFERROR(INDEX(Services!$E$5:$E$204,MATCH(G6,Services!$A$5:$A$204,0))*1,0)+IFERROR(INDEX(Services!$F$5:$F$204,MATCH(G6,Services!$A$5:$A$204,0))*1,0))) -> 0 | V6: =IF(B6="","",IF(D6="","",D6+U6/1440)) -> 0 | W6: =IF(B6="","",IF(D6="","",HOUR(D6))) -> 0 | X6: =IF(B6="","",ROUND(U6/60,2)) -> 0 | Y6: =IF(B6="","",IF(L6<>"",L6,IFERROR(INDEX(Services!$G$5:$G$204,MATCH(G6,Services!$A$5:$A$204,0))*1,0))) -> 0 | Z6: =IF(B6="","",IF(O6<>"",O6,IF(Y6>=DepositThreshold,ROUND(Y6*DepositPercent,2),0))) -> 0 | AA6: =IF(B6="","",ROUND(SUMIFS(Payments!$G$5:$G$1204,Payments!$I$5:$I$1204,A6,Payments!$E$5:$E$1204,"Deposit"),2)) -> 0 | AB6: =IF(B6="","",ROUND(SUMIFS(Sales!$Y$5:$Y$1204,Sales!$C$5:$C$1204,A6),2)) -> 0 | AC6: =IF(B6="","",IF(M6="Completed","Yes",IF(M6="Cancelled","Yes",IF(M6="No show","Yes","No")))) -> 0 | AD6: =IF(B6="","",IF(AE6="","",B6-AE6)) -> 0 | AF6: =IF(B6="","",IF(M6<>"Completed","",IF(E6="","No",IF(COUNTIFS(Appointments!$E$5:$E$1204,E6,Appointments!$B$5:$B$1204,">"&B6,Appointments!$M$5:$M$1204,"<>Cancelled")>0,"Yes","No")))) -> 0 | AG6: =IF(B6="","",IF(I6="","",IF(D6="","",IF(COUNTIFS($I$5:$I$1204,I6,$B$5:$B$1204,B6,$D$5:$D$1204,"<"&V6,$V$5:$V$1204,">"&D6,$M$5:$M$1204,"<>Cancelled")>1,"Clash","")))) -> 0 | AH6: =IF(B6="","",IF(AG6="Clash","Clash - stylist double booked",IF(I6="","Assign - no stylist yet",IF(G6="","Add - no service chosen",IF(M6="No show","No show - charge the fee?",IF(M6="Cancelled","",IF(IF(M6="Completed",AB6<Y6-0.004,FALSE),"Unpaid - nothing rung up for this visit",IF(IF(B6<TodayDate,M6="Booked",FALSE),"Overdue - past date, still only Booked",IF(IF(B6=TodayDate,TRUE,FALSE),"Today",IF(IF(Z6>0,AA6<Z6-0.004,FALSE),"Due - deposit not taken",IF(IF(B6>TodayDate,B6<=TodayDate+2,FALSE),"Confirm - coming up","OK"))))))))))) -> 0
A7: =IF(B7="","",AppointmentPrefix&TEXT(ROW()-4,"0000")) -> 0 | C7: =IF(B7="","",TEXT(B7,"ddd")) -> 0 | F7: =IF(E7="","",IFERROR(INDEX(Clients!$B$5:$B$504,MATCH(E7,Clients!$A$5:$A$504,0)),"Walk-in")) -> 0 | H7: =IF(G7="","",IFERROR(INDEX(Services!$B$5:$B$204,MATCH(G7,Services!$A$5:$A$204,0)),"Not in Services")) -> 0 | J7: =IF(I7="","",IFERROR(INDEX(Staff!$B$5:$B$44,MATCH(I7,Staff!$A$5:$A$44,0)),"Unassigned")) -> 0 | S7: =IF(B7="","",TEXT(B7,"yyyy-mm")) -> 0 | T7: =IF(B7="","",WEEKNUM(B7,2)) -> 0 | U7: =IF(B7="","",IF(K7<>"",K7,IFERROR(INDEX(Services!$E$5:$E$204,MATCH(G7,Services!$A$5:$A$204,0))*1,0)+IFERROR(INDEX(Services!$F$5:$F$204,MATCH(G7,Services!$A$5:$A$204,0))*1,0))) -> 0 | V7: =IF(B7="","",IF(D7="","",D7+U7/1440)) -> 0 | W7: =IF(B7="","",IF(D7="","",HOUR(D7))) -> 0 | X7: =IF(B7="","",ROUND(U7/60,2)) -> 0 | Y7: =IF(B7="","",IF(L7<>"",L7,IFERROR(INDEX(Services!$G$5:$G$204,MATCH(G7,Services!$A$5:$A$204,0))*1,0))) -> 0 | Z7: =IF(B7="","",IF(O7<>"",O7,IF(Y7>=DepositThreshold,ROUND(Y7*DepositPercent,2),0))) -> 0 | AA7: =IF(B7="","",ROUND(SUMIFS(Payments!$G$5:$G$1204,Payments!$I$5:$I$1204,A7,Payments!$E$5:$E$1204,"Deposit"),2)) -> 0 | AB7: =IF(B7="","",ROUND(SUMIFS(Sales!$Y$5:$Y$1204,Sales!$C$5:$C$1204,A7),2)) -> 0 | AC7: =IF(B7="","",IF(M7="Completed","Yes",IF(M7="Cancelled","Yes",IF(M7="No show","Yes","No")))) -> 0 | AD7: =IF(B7="","",IF(AE7="","",B7-AE7)) -> 0 | AF7: =IF(B7="","",IF(M7<>"Completed","",IF(E7="","No",IF(COUNTIFS(Appointments!$E$5:$E$1204,E7,Appointments!$B$5:$B$1204,">"&B7,Appointments!$M$5:$M$1204,"<>Cancelled")>0,"Yes","No")))) -> 0 | AG7: =IF(B7="","",IF(I7="","",IF(D7="","",IF(COUNTIFS($I$5:$I$1204,I7,$B$5:$B$1204,B7,$D$5:$D$1204,"<"&V7,$V$5:$V$1204,">"&D7,$M$5:$M$1204,"<>Cancelled")>1,"Clash","")))) -> 0 | AH7: =IF(B7="","",IF(AG7="Clash","Clash - stylist double booked",IF(I7="","Assign - no stylist yet",IF(G7="","Add - no service chosen",IF(M7="No show","No show - charge the fee?",IF(M7="Cancelled","",IF(IF(M7="Completed",AB7<Y7-0.004,FALSE),"Unpaid - nothing rung up for this visit",IF(IF(B7<TodayDate,M7="Booked",FALSE),"Overdue - past date, still only Booked",IF(IF(B7=TodayDate,TRUE,FALSE),"Today",IF(IF(Z7>0,AA7<Z7-0.004,FALSE),"Due - deposit not taken",IF(IF(B7>TodayDate,B7<=TodayDate+2,FALSE),"Confirm - coming up","OK"))))))))))) -> 0
A8: =IF(B8="","",AppointmentPrefix&TEXT(ROW()-4,"0000")) -> 0 | C8: =IF(B8="","",TEXT(B8,"ddd")) -> 0 | F8: =IF(E8="","",IFERROR(INDEX(Clients!$B$5:$B$504,MATCH(E8,Clients!$A$5:$A$504,0)),"Walk-in")) -> 0 | H8: =IF(G8="","",IFERROR(INDEX(Services!$B$5:$B$204,MATCH(G8,Services!$A$5:$A$204,0)),"Not in Services")) -> 0 | J8: =IF(I8="","",IFERROR(INDEX(Staff!$B$5:$B$44,MATCH(I8,Staff!$A$5:$A$44,0)),"Unassigned")) -> 0 | S8: =IF(B8="","",TEXT(B8,"yyyy-mm")) -> 0 | T8: =IF(B8="","",WEEKNUM(B8,2)) -> 0 | U8: =IF(B8="","",IF(K8<>"",K8,IFERROR(INDEX(Services!$E$5:$E$204,MATCH(G8,Services!$A$5:$A$204,0))*1,0)+IFERROR(INDEX(Services!$F$5:$F$204,MATCH(G8,Services!$A$5:$A$204,0))*1,0))) -> 0 | V8: =IF(B8="","",IF(D8="","",D8+U8/1440)) -> 0 | W8: =IF(B8="","",IF(D8="","",HOUR(D8))) -> 0 | X8: =IF(B8="","",ROUND(U8/60,2)) -> 0 | Y8: =IF(B8="","",IF(L8<>"",L8,IFERROR(INDEX(Services!$G$5:$G$204,MATCH(G8,Services!$A$5:$A$204,0))*1,0))) -> 0 | Z8: =IF(B8="","",IF(O8<>"",O8,IF(Y8>=DepositThreshold,ROUND(Y8*DepositPercent,2),0))) -> 0 | AA8: =IF(B8="","",ROUND(SUMIFS(Payments!$G$5:$G$1204,Payments!$I$5:$I$1204,A8,Payments!$E$5:$E$1204,"Deposit"),2)) -> 0 | AB8: =IF(B8="","",ROUND(SUMIFS(Sales!$Y$5:$Y$1204,Sales!$C$5:$C$1204,A8),2)) -> 0 | AC8: =IF(B8="","",IF(M8="Completed","Yes",IF(M8="Cancelled","Yes",IF(M8="No show","Yes","No")))) -> 0 | AD8: =IF(B8="","",IF(AE8="","",B8-AE8)) -> 0 | AF8: =IF(B8="","",IF(M8<>"Completed","",IF(E8="","No",IF(COUNTIFS(Appointments!$E$5:$E$1204,E8,Appointments!$B$5:$B$1204,">"&B8,Appointments!$M$5:$M$1204,"<>Cancelled")>0,"Yes","No")))) -> 0 | AG8: =IF(B8="","",IF(I8="","",IF(D8="","",IF(COUNTIFS($I$5:$I$1204,I8,$B$5:$B$1204,B8,$D$5:$D$1204,"<"&V8,$V$5:$V$1204,">"&D8,$M$5:$M$1204,"<>Cancelled")>1,"Clash","")))) -> 0 | AH8: =IF(B8="","",IF(AG8="Clash","Clash - stylist double booked",IF(I8="","Assign - no stylist yet",IF(G8="","Add - no service chosen",IF(M8="No show","No show - charge the fee?",IF(M8="Cancelled","",IF(IF(M8="Completed",AB8<Y8-0.004,FALSE),"Unpaid - nothing rung up for this visit",IF(IF(B8<TodayDate,M8="Booked",FALSE),"Overdue - past date, still only Booked",IF(IF(B8=TodayDate,TRUE,FALSE),"Today",IF(IF(Z8>0,AA8<Z8-0.004,FALSE),"Due - deposit not taken",IF(IF(B8>TodayDate,B8<=TodayDate+2,FALSE),"Confirm - coming up","OK"))))))))))) -> 0
A9: =IF(B9="","",AppointmentPrefix&TEXT(ROW()-4,"0000")) -> 0 | C9: =IF(B9="","",TEXT(B9,"ddd")) -> 0 | F9: =IF(E9="","",IFERROR(INDEX(Clients!$B$5:$B$504,MATCH(E9,Clients!$A$5:$A$504,0)),"Walk-in")) -> 0 | H9: =IF(G9="","",IFERROR(INDEX(Services!$B$5:$B$204,MATCH(G9,Services!$A$5:$A$204,0)),"Not in Services")) -> 0 | J9: =IF(I9="","",IFERROR(INDEX(Staff!$B$5:$B$44,MATCH(I9,Staff!$A$5:$A$44,0)),"Unassigned")) -> 0 | S9: =IF(B9="","",TEXT(B9,"yyyy-mm")) -> 0 | T9: =IF(B9="","",WEEKNUM(B9,2)) -> 0 | U9: =IF(B9="","",IF(K9<>"",K9,IFERROR(INDEX(Services!$E$5:$E$204,MATCH(G9,Services!$A$5:$A$204,0))*1,0)+IFERROR(INDEX(Services!$F$5:$F$204,MATCH(G9,Services!$A$5:$A$204,0))*1,0))) -> 0 | V9: =IF(B9="","",IF(D9="","",D9+U9/1440)) -> 0 | W9: =IF(B9="","",IF(D9="","",HOUR(D9))) -> 0 | X9: =IF(B9="","",ROUND(U9/60,2)) -> 0 | Y9: =IF(B9="","",IF(L9<>"",L9,IFERROR(INDEX(Services!$G$5:$G$204,MATCH(G9,Services!$A$5:$A$204,0))*1,0))) -> 0 | Z9: =IF(B9="","",IF(O9<>"",O9,IF(Y9>=DepositThreshold,ROUND(Y9*DepositPercent,2),0))) -> 0 | AA9: =IF(B9="","",ROUND(SUMIFS(Payments!$G$5:$G$1204,Payments!$I$5:$I$1204,A9,Payments!$E$5:$E$1204,"Deposit"),2)) -> 0 | AB9: =IF(B9="","",ROUND(SUMIFS(Sales!$Y$5:$Y$1204,Sales!$C$5:$C$1204,A9),2)) -> 0 | AC9: =IF(B9="","",IF(M9="Completed","Yes",IF(M9="Cancelled","Yes",IF(M9="No show","Yes","No")))) -> 0 | AD9: =IF(B9="","",IF(AE9="","",B9-AE9)) -> 0 | AF9: =IF(B9="","",IF(M9<>"Completed","",IF(E9="","No",IF(COUNTIFS(Appointments!$E$5:$E$1204,E9,Appointments!$B$5:$B$1204,">"&B9,Appointments!$M$5:$M$1204,"<>Cancelled")>0,"Yes","No")))) -> 0 | AG9: =IF(B9="","",IF(I9="","",IF(D9="","",IF(COUNTIFS($I$5:$I$1204,I9,$B$5:$B$1204,B9,$D$5:$D$1204,"<"&V9,$V$5:$V$1204,">"&D9,$M$5:$M$1204,"<>Cancelled")>1,"Clash","")))) -> 0 | AH9: =IF(B9="","",IF(AG9="Clash","Clash - stylist double booked",IF(I9="","Assign - no stylist yet",IF(G9="","Add - no service chosen",IF(M9="No show","No show - charge the fee?",IF(M9="Cancelled","",IF(IF(M9="Completed",AB9<Y9-0.004,FALSE),"Unpaid - nothing rung up for this visit",IF(IF(B9<TodayDate,M9="Booked",FALSE),"Overdue - past date, still only Booked",IF(IF(B9=TodayDate,TRUE,FALSE),"Today",IF(IF(Z9>0,AA9<Z9-0.004,FALSE),"Due - deposit not taken",IF(IF(B9>TodayDate,B9<=TodayDate+2,FALSE),"Confirm - coming up","OK"))))))))))) -> 0
A10: =IF(B10="","",AppointmentPrefix&TEXT(ROW()-4,"0000")) -> 0 | C10: =IF(B10="","",TEXT(B10,"ddd")) -> 0 | F10: =IF(E10="","",IFERROR(INDEX(Clients!$B$5:$B$504,MATCH(E10,Clients!$A$5:$A$504,0)),"Walk-in")) -> 0 | H10: =IF(G10="","",IFERROR(INDEX(Services!$B$5:$B$204,MATCH(G10,Services!$A$5:$A$204,0)),"Not in Services")) -> 0 | J10: =IF(I10="","",IFERROR(INDEX(Staff!$B$5:$B$44,MATCH(I10,Staff!$A$5:$A$44,0)),"Unassigned")) -> 0 | S10: =IF(B10="","",TEXT(B10,"yyyy-mm")) -> 0 | T10: =IF(B10="","",WEEKNUM(B10,2)) -> 0 | U10: =IF(B10="","",IF(K10<>"",K10,IFERROR(INDEX(Services!$E$5:$E$204,MATCH(G10,Services!$A$5:$A$204,0))*1,0)+IFERROR(INDEX(Services!$F$5:$F$204,MATCH(G10,Services!$A$5:$A$204,0))*1,0))) -> 0 | V10: =IF(B10="","",IF(D10="","",D10+U10/1440)) -> 0 | W10: =IF(B10="","",IF(D10="","",HOUR(D10))) -> 0 | X10: =IF(B10="","",ROUND(U10/60,2)) -> 0 | Y10: =IF(B10="","",IF(L10<>"",L10,IFERROR(INDEX(Services!$G$5:$G$204,MATCH(G10,Services!$A$5:$A$204,0))*1,0))) -> 0 | Z10: =IF(B10="","",IF(O10<>"",O10,IF(Y10>=DepositThreshold,ROUND(Y10*DepositPercent,2),0))) -> 0 | AA10: =IF(B10="","",ROUND(SUMIFS(Payments!$G$5:$G$1204,Payments!$I$5:$I$1204,A10,Payments!$E$5:$E$1204,"Deposit"),2)) -> 0 | AB10: =IF(B10="","",ROUND(SUMIFS(Sales!$Y$5:$Y$1204,Sales!$C$5:$C$1204,A10),2)) -> 0 | AC10: =IF(B10="","",IF(M10="Completed","Yes",IF(M10="Cancelled","Yes",IF(M10="No show","Yes","No")))) -> 0 | AD10: =IF(B10="","",IF(AE10="","",B10-AE10)) -> 0 | AF10: =IF(B10="","",IF(M10<>"Completed","",IF(E10="","No",IF(COUNTIFS(Appointments!$E$5:$E$1204,E10,Appointments!$B$5:$B$1204,">"&B10,Appointments!$M$5:$M$1204,"<>Cancelled")>0,"Yes","No")))) -> 0 | AG10: =IF(B10="","",IF(I10="","",IF(D10="","",IF(COUNTIFS($I$5:$I$1204,I10,$B$5:$B$1204,B10,$D$5:$D$1204,"<"&V10,$V$5:$V$1204,">"&D10,$M$5:$M$1204,"<>Cancelled")>1,"Clash","")))) -> 0 | AH10: =IF(B10="","",IF(AG10="Clash","Clash - stylist double booked",IF(I10="","Assign - no stylist yet",IF(G10="","Add - no service chosen",IF(M10="No show","No show - charge the fee?",IF(M10="Cancelled","",IF(IF(M10="Completed",AB10<Y10-0.004,FALSE),"Unpaid - nothing rung up for this visit",IF(IF(B10<TodayDate,M10="Booked",FALSE),"Overdue - past date, still only Booked",IF(IF(B10=TodayDate,TRUE,FALSE),"Today",IF(IF(Z10>0,AA10<Z10-0.004,FALSE),"Due - deposit not taken",IF(IF(B10>TodayDate,B10<=TodayDate+2,FALSE),"Confirm - coming up","OK"))))))))))) -> 0
A11: =IF(B11="","",AppointmentPrefix&TEXT(ROW()-4,"0000")) -> 0 | C11: =IF(B11="","",TEXT(B11,"ddd")) -> 0 | F11: =IF(E11="","",IFERROR(INDEX(Clients!$B$5:$B$504,MATCH(E11,Clients!$A$5:$A$504,0)),"Walk-in")) -> 0 | H11: =IF(G11="","",IFERROR(INDEX(Services!$B$5:$B$204,MATCH(G11,Services!$A$5:$A$204,0)),"Not in Services")) -> 0 | J11: =IF(I11="","",IFERROR(INDEX(Staff!$B$5:$B$44,MATCH(I11,Staff!$A$5:$A$44,0)),"Unassigned")) -> 0 | S11: =IF(B11="","",TEXT(B11,"yyyy-mm")) -> 0 | T11: =IF(B11="","",WEEKNUM(B11,2)) -> 0 | U11: =IF(B11="","",IF(K11<>"",K11,IFERROR(INDEX(Services!$E$5:$E$204,MATCH(G11,Services!$A$5:$A$204,0))*1,0)+IFERROR(INDEX(Services!$F$5:$F$204,MATCH(G11,Services!$A$5:$A$204,0))*1,0))) -> 0 | V11: =IF(B11="","",IF(D11="","",D11+U11/1440)) -> 0 | W11: =IF(B11="","",IF(D11="","",HOUR(D11))) -> 0 | X11: =IF(B11="","",ROUND(U11/60,2)) -> 0 | Y11: =IF(B11="","",IF(L11<>"",L11,IFERROR(INDEX(Services!$G$5:$G$204,MATCH(G11,Services!$A$5:$A$204,0))*1,0))) -> 0 | Z11: =IF(B11="","",IF(O11<>"",O11,IF(Y11>=DepositThreshold,ROUND(Y11*DepositPercent,2),0))) -> 0 | AA11: =IF(B11="","",ROUND(SUMIFS(Payments!$G$5:$G$1204,Payments!$I$5:$I$1204,A11,Payments!$E$5:$E$1204,"Deposit"),2)) -> 0 | AB11: =IF(B11="","",ROUND(SUMIFS(Sales!$Y$5:$Y$1204,Sales!$C$5:$C$1204,A11),2)) -> 0 | AC11: =IF(B11="","",IF(M11="Completed","Yes",IF(M11="Cancelled","Yes",IF(M11="No show","Yes","No")))) -> 0 | AD11: =IF(B11="","",IF(AE11="","",B11-AE11)) -> 0 | AF11: =IF(B11="","",IF(M11<>"Completed","",IF(E11="","No",IF(COUNTIFS(Appointments!$E$5:$E$1204,E11,Appointments!$B$5:$B$1204,">"&B11,Appointments!$M$5:$M$1204,"<>Cancelled")>0,"Yes","No")))) -> 0 | AG11: =IF(B11="","",IF(I11="","",IF(D11="","",IF(COUNTIFS($I$5:$I$1204,I11,$B$5:$B$1204,B11,$D$5:$D$1204,"<"&V11,$V$5:$V$1204,">"&D11,$M$5:$M$1204,"<>Cancelled")>1,"Clash","")))) -> 0 | AH11: =IF(B11="","",IF(AG11="Clash","Clash - stylist double booked",IF(I11="","Assign - no stylist yet",IF(G11="","Add - no service chosen",IF(M11="No show","No show - charge the fee?",IF(M11="Cancelled","",IF(IF(M11="Completed",AB11<Y11-0.004,FALSE),"Unpaid - nothing rung up for this visit",IF(IF(B11<TodayDate,M11="Booked",FALSE),"Overdue - past date, still only Booked",IF(IF(B11=TodayDate,TRUE,FALSE),"Today",IF(IF(Z11>0,AA11<Z11-0.004,FALSE),"Due - deposit not taken",IF(IF(B11>TodayDate,B11<=TodayDate+2,FALSE),"Confirm - coming up","OK"))))))))))) -> 0
A12: =IF(B12="","",AppointmentPrefix&TEXT(ROW()-4,"0000")) -> 0 | C12: =IF(B12="","",TEXT(B12,"ddd")) -> 0 | F12: =IF(E12="","",IFERROR(INDEX(Clients!$B$5:$B$504,MATCH(E12,Clients!$A$5:$A$504,0)),"Walk-in")) -> 0 | H12: =IF(G12="","",IFERROR(INDEX(Services!$B$5:$B$204,MATCH(G12,Services!$A$5:$A$204,0)),"Not in Services")) -> 0 | J12: =IF(I12="","",IFERROR(INDEX(Staff!$B$5:$B$44,MATCH(I12,Staff!$A$5:$A$44,0)),"Unassigned")) -> 0 | S12: =IF(B12="","",TEXT(B12,"yyyy-mm")) -> 0 | T12: =IF(B12="","",WEEKNUM(B12,2)) -> 0 | U12: =IF(B12="","",IF(K12<>"",K12,IFERROR(INDEX(Services!$E$5:$E$204,MATCH(G12,Services!$A$5:$A$204,0))*1,0)+IFERROR(INDEX(Services!$F$5:$F$204,MATCH(G12,Services!$A$5:$A$204,0))*1,0))) -> 0 | V12: =IF(B12="","",IF(D12="","",D12+U12/1440)) -> 0 | W12: =IF(B12="","",IF(D12="","",HOUR(D12))) -> 0 | X12: =IF(B12="","",ROUND(U12/60,2)) -> 0 | Y12: =IF(B12="","",IF(L12<>"",L12,IFERROR(INDEX(Services!$G$5:$G$204,MATCH(G12,Services!$A$5:$A$204,0))*1,0))) -> 0 | Z12: =IF(B12="","",IF(O12<>"",O12,IF(Y12>=DepositThreshold,ROUND(Y12*DepositPercent,2),0))) -> 0 | AA12: =IF(B12="","",ROUND(SUMIFS(Payments!$G$5:$G$1204,Payments!$I$5:$I$1204,A12,Payments!$E$5:$E$1204,"Deposit"),2)) -> 0 | AB12: =IF(B12="","",ROUND(SUMIFS(Sales!$Y$5:$Y$1204,Sales!$C$5:$C$1204,A12),2)) -> 0 | AC12: =IF(B12="","",IF(M12="Completed","Yes",IF(M12="Cancelled","Yes",IF(M12="No show","Yes","No")))) -> 0 | AD12: =IF(B12="","",IF(AE12="","",B12-AE12)) -> 0 | AF12: =IF(B12="","",IF(M12<>"Completed","",IF(E12="","No",IF(COUNTIFS(Appointments!$E$5:$E$1204,E12,Appointments!$B$5:$B$1204,">"&B12,Appointments!$M$5:$M$1204,"<>Cancelled")>0,"Yes","No")))) -> 0 | AG12: =IF(B12="","",IF(I12="","",IF(D12="","",IF(COUNTIFS($I$5:$I$1204,I12,$B$5:$B$1204,B12,$D$5:$D$1204,"<"&V12,$V$5:$V$1204,">"&D12,$M$5:$M$1204,"<>Cancelled")>1,"Clash","")))) -> 0 | AH12: =IF(B12="","",IF(AG12="Clash","Clash - stylist double booked",IF(I12="","Assign - no stylist yet",IF(G12="","Add - no service chosen",IF(M12="No show","No show - charge the fee?",IF(M12="Cancelled","",IF(IF(M12="Completed",AB12<Y12-0.004,FALSE),"Unpaid - nothing rung up for this visit",IF(IF(B12<TodayDate,M12="Booked",FALSE),"Overdue - past date, still only Booked",IF(IF(B12=TodayDate,TRUE,FALSE),"Today",IF(IF(Z12>0,AA12<Z12-0.004,FALSE),"Due - deposit not taken",IF(IF(B12>TodayDate,B12<=TodayDate+2,FALSE),"Confirm - coming up","OK"))))))))))) -> 0
A13: =IF(B13="","",AppointmentPrefix&TEXT(ROW()-4,"0000")) -> 0 | C13: =IF(B13="","",TEXT(B13,"ddd")) -> 0 | F13: =IF(E13="","",IFERROR(INDEX(Clients!$B$5:$B$504,MATCH(E13,Clients!$A$5:$A$504,0)),"Walk-in")) -> 0 | H13: =IF(G13="","",IFERROR(INDEX(Services!$B$5:$B$204,MATCH(G13,Services!$A$5:$A$204,0)),"Not in Services")) -> 0 | J13: =IF(I13="","",IFERROR(INDEX(Staff!$B$5:$B$44,MATCH(I13,Staff!$A$5:$A$44,0)),"Unassigned")) -> 0 | S13: =IF(B13="","",TEXT(B13,"yyyy-mm")) -> 0 | T13: =IF(B13="","",WEEKNUM(B13,2)) -> 0 | U13: =IF(B13="","",IF(K13<>"",K13,IFERROR(INDEX(Services!$E$5:$E$204,MATCH(G13,Services!$A$5:$A$204,0))*1,0)+IFERROR(INDEX(Services!$F$5:$F$204,MATCH(G13,Services!$A$5:$A$204,0))*1,0))) -> 0 | V13: =IF(B13="","",IF(D13="","",D13+U13/1440)) -> 0 | W13: =IF(B13="","",IF(D13="","",HOUR(D13))) -> 0 | X13: =IF(B13="","",ROUND(U13/60,2)) -> 0 | Y13: =IF(B13="","",IF(L13<>"",L13,IFERROR(INDEX(Services!$G$5:$G$204,MATCH(G13,Services!$A$5:$A$204,0))*1,0))) -> 0 | Z13: =IF(B13="","",IF(O13<>"",O13,IF(Y13>=DepositThreshold,ROUND(Y13*DepositPercent,2),0))) -> 0 | AA13: =IF(B13="","",ROUND(SUMIFS(Payments!$G$5:$G$1204,Payments!$I$5:$I$1204,A13,Payments!$E$5:$E$1204,"Deposit"),2)) -> 0 | AB13: =IF(B13="","",ROUND(SUMIFS(Sales!$Y$5:$Y$1204,Sales!$C$5:$C$1204,A13),2)) -> 0 | AC13: =IF(B13="","",IF(M13="Completed","Yes",IF(M13="Cancelled","Yes",IF(M13="No show","Yes","No")))) -> 0 | AD13: =IF(B13="","",IF(AE13="","",B13-AE13)) -> 0 | AF13: =IF(B13="","",IF(M13<>"Completed","",IF(E13="","No",IF(COUNTIFS(Appointments!$E$5:$E$1204,E13,Appointments!$B$5:$B$1204,">"&B13,Appointments!$M$5:$M$1204,"<>Cancelled")>0,"Yes","No")))) -> 0 | AG13: =IF(B13="","",IF(I13="","",IF(D13="","",IF(COUNTIFS($I$5:$I$1204,I13,$B$5:$B$1204,B13,$D$5:$D$1204,"<"&V13,$V$5:$V$1204,">"&D13,$M$5:$M$1204,"<>Cancelled")>1,"Clash","")))) -> 0 | AH13: =IF(B13="","",IF(AG13="Clash","Clash - stylist double booked",IF(I13="","Assign - no stylist yet",IF(G13="","Add - no service chosen",IF(M13="No show","No show - charge the fee?",IF(M13="Cancelled","",IF(IF(M13="Completed",AB13<Y13-0.004,FALSE),"Unpaid - nothing rung up for this visit",IF(IF(B13<TodayDate,M13="Booked",FALSE),"Overdue - past date, still only Booked",IF(IF(B13=TodayDate,TRUE,FALSE),"Today",IF(IF(Z13>0,AA13<Z13-0.004,FALSE),"Due - deposit not taken",IF(IF(B13>TodayDate,B13<=TodayDate+2,FALSE),"Confirm - coming up","OK"))))))))))) -> 0
A14: =IF(B14="","",AppointmentPrefix&TEXT(ROW()-4,"0000")) -> 0 | C14: =IF(B14="","",TEXT(B14,"ddd")) -> 0 | F14: =IF(E14="","",IFERROR(INDEX(Clients!$B$5:$B$504,MATCH(E14,Clients!$A$5:$A$504,0)),"Walk-in")) -> 0 | H14: =IF(G14="","",IFERROR(INDEX(Services!$B$5:$B$204,MATCH(G14,Services!$A$5:$A$204,0)),"Not in Services")) -> 0 | J14: =IF(I14="","",IFERROR(INDEX(Staff!$B$5:$B$44,MATCH(I14,Staff!$A$5:$A$44,0)),"Unassigned")) -> 0 | S14: =IF(B14="","",TEXT(B14,"yyyy-mm")) -> 0 | T14: =IF(B14="","",WEEKNUM(B14,2)) -> 0 | U14: =IF(B14="","",IF(K14<>"",K14,IFERROR(INDEX(Services!$E$5:$E$204,MATCH(G14,Services!$A$5:$A$204,0))*1,0)+IFERROR(INDEX(Services!$F$5:$F$204,MATCH(G14,Services!$A$5:$A$204,0))*1,0))) -> 0 | V14: =IF(B14="","",IF(D14="","",D14+U14/1440)) -> 0 | W14: =IF(B14="","",IF(D14="","",HOUR(D14))) -> 0 | X14: =IF(B14="","",ROUND(U14/60,2)) -> 0 | Y14: =IF(B14="","",IF(L14<>"",L14,IFERROR(INDEX(Services!$G$5:$G$204,MATCH(G14,Services!$A$5:$A$204,0))*1,0))) -> 0 | Z14: =IF(B14="","",IF(O14<>"",O14,IF(Y14>=DepositThreshold,ROUND(Y14*DepositPercent,2),0))) -> 0 | AA14: =IF(B14="","",ROUND(SUMIFS(Payments!$G$5:$G$1204,Payments!$I$5:$I$1204,A14,Payments!$E$5:$E$1204,"Deposit"),2)) -> 0 | AB14: =IF(B14="","",ROUND(SUMIFS(Sales!$Y$5:$Y$1204,Sales!$C$5:$C$1204,A14),2)) -> 0 | AC14: =IF(B14="","",IF(M14="Completed","Yes",IF(M14="Cancelled","Yes",IF(M14="No show","Yes","No")))) -> 0 | AD14: =IF(B14="","",IF(AE14="","",B14-AE14)) -> 0 | AF14: =IF(B14="","",IF(M14<>"Completed","",IF(E14="","No",IF(COUNTIFS(Appointments!$E$5:$E$1204,E14,Appointments!$B$5:$B$1204,">"&B14,Appointments!$M$5:$M$1204,"<>Cancelled")>0,"Yes","No")))) -> 0 | AG14: =IF(B14="","",IF(I14="","",IF(D14="","",IF(COUNTIFS($I$5:$I$1204,I14,$B$5:$B$1204,B14,$D$5:$D$1204,"<"&V14,$V$5:$V$1204,">"&D14,$M$5:$M$1204,"<>Cancelled")>1,"Clash","")))) -> 0 | AH14: =IF(B14="","",IF(AG14="Clash","Clash - stylist double booked",IF(I14="","Assign - no stylist yet",IF(G14="","Add - no service chosen",IF(M14="No show","No show - charge the fee?",IF(M14="Cancelled","",IF(IF(M14="Completed",AB14<Y14-0.004,FALSE),"Unpaid - nothing rung up for this visit",IF(IF(B14<TodayDate,M14="Booked",FALSE),"Overdue - past date, still only Booked",IF(IF(B14=TodayDate,TRUE,FALSE),"Today",IF(IF(Z14>0,AA14<Z14-0.004,FALSE),"Due - deposit not taken",IF(IF(B14>TodayDate,B14<=TodayDate+2,FALSE),"Confirm - coming up","OK"))))))))))) -> 0
A15: =IF(B15="","",AppointmentPrefix&TEXT(ROW()-4,"0000")) -> 0 | C15: =IF(B15="","",TEXT(B15,"ddd")) -> 0 | F15: =IF(E15="","",IFERROR(INDEX(Clients!$B$5:$B$504,MATCH(E15,Clients!$A$5:$A$504,0)),"Walk-in")) -> 0 | H15: =IF(G15="","",IFERROR(INDEX(Services!$B$5:$B$204,MATCH(G15,Services!$A$5:$A$204,0)),"Not in Services")) -> 0 | J15: =IF(I15="","",IFERROR(INDEX(Staff!$B$5:$B$44,MATCH(I15,Staff!$A$5:$A$44,0)),"Unassigned")) -> 0 | S15: =IF(B15="","",TEXT(B15,"yyyy-mm")) -> 0 | T15: =IF(B15="","",WEEKNUM(B15,2)) -> 0 | U15: =IF(B15="","",IF(K15<>"",K15,IFERROR(INDEX(Services!$E$5:$E$204,MATCH(G15,Services!$A$5:$A$204,0))*1,0)+IFERROR(INDEX(Services!$F$5:$F$204,MATCH(G15,Services!$A$5:$A$204,0))*1,0))) -> 0 | V15: =IF(B15="","",IF(D15="","",D15+U15/1440)) -> 0 | W15: =IF(B15="","",IF(D15="","",HOUR(D15))) -> 0 | X15: =IF(B15="","",ROUND(U15/60,2)) -> 0 | Y15: =IF(B15="","",IF(L15<>"",L15,IFERROR(INDEX(Services!$G$5:$G$204,MATCH(G15,Services!$A$5:$A$204,0))*1,0))) -> 0 | Z15: =IF(B15="","",IF(O15<>"",O15,IF(Y15>=DepositThreshold,ROUND(Y15*DepositPercent,2),0))) -> 0 | AA15: =IF(B15="","",ROUND(SUMIFS(Payments!$G$5:$G$1204,Payments!$I$5:$I$1204,A15,Payments!$E$5:$E$1204,"Deposit"),2)) -> 0 | AB15: =IF(B15="","",ROUND(SUMIFS(Sales!$Y$5:$Y$1204,Sales!$C$5:$C$1204,A15),2)) -> 0 | AC15: =IF(B15="","",IF(M15="Completed","Yes",IF(M15="Cancelled","Yes",IF(M15="No show","Yes","No")))) -> 0 | AD15: =IF(B15="","",IF(AE15="","",B15-AE15)) -> 0 | AF15: =IF(B15="","",IF(M15<>"Completed","",IF(E15="","No",IF(COUNTIFS(Appointments!$E$5:$E$1204,E15,Appointments!$B$5:$B$1204,">"&B15,Appointments!$M$5:$M$1204,"<>Cancelled")>0,"Yes","No")))) -> 0 | AG15: =IF(B15="","",IF(I15="","",IF(D15="","",IF(COUNTIFS($I$5:$I$1204,I15,$B$5:$B$1204,B15,$D$5:$D$1204,"<"&V15,$V$5:$V$1204,">"&D15,$M$5:$M$1204,"<>Cancelled")>1,"Clash","")))) -> 0 | AH15: =IF(B15="","",IF(AG15="Clash","Clash - stylist double booked",IF(I15="","Assign - no stylist yet",IF(G15="","Add - no service chosen",IF(M15="No show","No show - charge the fee?",IF(M15="Cancelled","",IF(IF(M15="Completed",AB15<Y15-0.004,FALSE),"Unpaid - nothing rung up for this visit",IF(IF(B15<TodayDate,M15="Booked",FALSE),"Overdue - past date, still only Booked",IF(IF(B15=TodayDate,TRUE,FALSE),"Today",IF(IF(Z15>0,AA15<Z15-0.004,FALSE),"Due - deposit not taken",IF(IF(B15>TodayDate,B15<=TodayDate+2,FALSE),"Confirm - coming up","OK"))))))))))) -> 0
A16: =IF(B16="","",AppointmentPrefix&TEXT(ROW()-4,"0000")) -> 0 | C16: =IF(B16="","",TEXT(B16,"ddd")) -> 0 | F16: =IF(E16="","",IFERROR(INDEX(Clients!$B$5:$B$504,MATCH(E16,Clients!$A$5:$A$504,0)),"Walk-in")) -> 0 | H16: =IF(G16="","",IFERROR(INDEX(Services!$B$5:$B$204,MATCH(G16,Services!$A$5:$A$204,0)),"Not in Services")) -> 0 | J16: =IF(I16="","",IFERROR(INDEX(Staff!$B$5:$B$44,MATCH(I16,Staff!$A$5:$A$44,0)),"Unassigned")) -> 0 | S16: =IF(B16="","",TEXT(B16,"yyyy-mm")) -> 0 | T16: =IF(B16="","",WEEKNUM(B16,2)) -> 0 | U16: =IF(B16="","",IF(K16<>"",K16,IFERROR(INDEX(Services!$E$5:$E$204,MATCH(G16,Services!$A$5:$A$204,0))*1,0)+IFERROR(INDEX(Services!$F$5:$F$204,MATCH(G16,Services!$A$5:$A$204,0))*1,0))) -> 0 | V16: =IF(B16="","",IF(D16="","",D16+U16/1440)) -> 0 | W16: =IF(B16="","",IF(D16="","",HOUR(D16))) -> 0 | X16: =IF(B16="","",ROUND(U16/60,2)) -> 0 | Y16: =IF(B16="","",IF(L16<>"",L16,IFERROR(INDEX(Services!$G$5:$G$204,MATCH(G16,Services!$A$5:$A$204,0))*1,0))) -> 0 | Z16: =IF(B16="","",IF(O16<>"",O16,IF(Y16>=DepositThreshold,ROUND(Y16*DepositPercent,2),0))) -> 0 | AA16: =IF(B16="","",ROUND(SUMIFS(Payments!$G$5:$G$1204,Payments!$I$5:$I$1204,A16,Payments!$E$5:$E$1204,"Deposit"),2)) -> 0 | AB16: =IF(B16="","",ROUND(SUMIFS(Sales!$Y$5:$Y$1204,Sales!$C$5:$C$1204,A16),2)) -> 0 | AC16: =IF(B16="","",IF(M16="Completed","Yes",IF(M16="Cancelled","Yes",IF(M16="No show","Yes","No")))) -> 0 | AD16: =IF(B16="","",IF(AE16="","",B16-AE16)) -> 0 | AF16: =IF(B16="","",IF(M16<>"Completed","",IF(E16="","No",IF(COUNTIFS(Appointments!$E$5:$E$1204,E16,Appointments!$B$5:$B$1204,">"&B16,Appointments!$M$5:$M$1204,"<>Cancelled")>0,"Yes","No")))) -> 0 | AG16: =IF(B16="","",IF(I16="","",IF(D16="","",IF(COUNTIFS($I$5:$I$1204,I16,$B$5:$B$1204,B16,$D$5:$D$1204,"<"&V16,$V$5:$V$1204,">"&D16,$M$5:$M$1204,"<>Cancelled")>1,"Clash","")))) -> 0 | AH16: =IF(B16="","",IF(AG16="Clash","Clash - stylist double booked",IF(I16="","Assign - no stylist yet",IF(G16="","Add - no service chosen",IF(M16="No show","No show - charge the fee?",IF(M16="Cancelled","",IF(IF(M16="Completed",AB16<Y16-0.004,FALSE),"Unpaid - nothing rung up for this visit",IF(IF(B16<TodayDate,M16="Booked",FALSE),"Overdue - past date, still only Booked",IF(IF(B16=TodayDate,TRUE,FALSE),"Today",IF(IF(Z16>0,AA16<Z16-0.004,FALSE),"Due - deposit not taken",IF(IF(B16>TodayDate,B16<=TodayDate+2,FALSE),"Confirm - coming up","OK"))))))))))) -> 0
... A1204: =IF(B1204="","",AppointmentPrefix&TEXT(ROW()-4,"0000")) -> 0 | C1204: =IF(B1204="","",TEXT(B1204,"ddd")) -> 0 | F1204: =IF(E1204="","",IFERROR(INDEX(Clients!$B$5:$B$504,MATCH(E1204,Clients!$A$5:$A$504,0)),"Walk-in")) -> 0 | H1204: =IF(G1204="","",IFERROR(INDEX(Services!$B$5:$B$204,MATCH(G1204,Services!$A$5:$A$204,0)),"Not in Services")) -> 0 | J1204: =IF(I1204="","",IFERROR(INDEX(Staff!$B$5:$B$44,MATCH(I1204,Staff!$A$5:$A$44,0)),"Unassigned")) -> 0 | S1204: =IF(B1204="","",TEXT(B1204,"yyyy-mm")) -> 0 | T1204: =IF(B1204="","",WEEKNUM(B1204,2)) -> 0 | U1204: =IF(B1204="","",IF(K1204<>"",K1204,IFERROR(INDEX(Services!$E$5:$E$204,MATCH(G1204,Services!$A$5:$A$204,0))*1,0)+IFERROR(INDEX(Services!$F$5:$F$204,MATCH(G1204,Services!$A$5:$A$204,0))*1,0))) -> 0 | V1204: =IF(B1204="","",IF(D1204="","",D1204+U1204/1440)) -> 0 | W1204: =IF(B1204="","",IF(D1204="","",HOUR(D1204))) -> 0 | X1204: =IF(B1204="","",ROUND(U1204/60,2)) -> 0 | Y1204: =IF(B1204="","",IF(L1204<>"",L1204,IFERROR(INDEX(Services!$G$5:$G$204,MATCH(G1204,Services!$A$5:$A$204,0))*1,0))) -> 0 | Z1204: =IF(B1204="","",IF(O1204<>"",O1204,IF(Y1204>=DepositThreshold,ROUND(Y1204*DepositPercent,2),0))) -> 0 | AA1204: =IF(B1204="","",ROUND(SUMIFS(Payments!$G$5:$G$1204,Payments!$I$5:$I$1204,A1204,Payments!$E$5:$E$1204,"Deposit"),2)) -> 0 | AB1204: =IF(B1204="","",ROUND(SUMIFS(Sales!$Y$5:$Y$1204,Sales!$C$5:$C$1204,A1204),2)) -> 0 | AC1204: =IF(B1204="","",IF(M1204="Completed","Yes",IF(M1204="Cancelled","Yes",IF(M1204="No show","Yes","No")))) -> 0 | AD1204: =IF(B1204="","",IF(AE1204="","",B1204-AE1204)) -> 0 | AF1204: =IF(B1204="","",IF(M1204<>"Completed","",IF(E1204="","No",IF(COUNTIFS(Appointments!$E$5:$E$1204,E1204,Appointments!$B$5:$B$1204,">"&B1204,Appointments!$M$5:$M$1204,"<>Cancelled")>0,"Yes","No")))) -> 0 | AG1204: =IF(B1204="","",IF(I1204="","",IF(D1204="","",IF(COUNTIFS($I$5:$I$1204,I1204,$B$5:$B$1204,B1204,$D$5:$D$1204,"<"&V1204,$V$5:$V$1204,">"&D1204,$M$5:$M$1204,"<>Cancelled")>1,"Clash","")))) -> 0 | AH1204: =IF(B1204="","",IF(AG1204="Clash","Clash - stylist double booked",IF(I1204="","Assign - no stylist yet",IF(G1204="","Add - no service chosen",IF(M1204="No show","No show - charge the fee?",IF(M1204="Cancelled","",IF(IF(M1204="Completed",AB1204<Y1204-0.004,FALSE),"Unpaid - nothing rung up for this visit",IF(IF(B1204<TodayDate,M1204="Booked",FALSE),"Overdue - past date, still only Booked",IF(IF(B1204=TodayDate,TRUE,FALSE),"Today",IF(IF(Z1204>0,AA1204<Z1204-0.004,FALSE),"Due - deposit not taken",IF(IF(B1204>TodayDate,B1204<=TodayDate+2,FALSE),"Confirm - coming up","OK"))))))))))) -> 0
A1206: The diary in numbers
A1207: Appointments logged | B1207: Completed | C1207: Cancelled | D1207: No shows | E1207: Completion rate | F1207: Cancellation rate | G1207: No-show rate | H1207: Booked value, completed | I1207: Chair hours, completed | J1207: Clashes to fix
A1208: =COUNTIF(Appointments!$B$5:$B$1204,"<>") -> 0 | B1208: =COUNTIFS(Appointments!$M$5:$M$1204,"Completed") -> 0 | C1208: =COUNTIFS(Appointments!$M$5:$M$1204,"Cancelled") -> 0 | D1208: =COUNTIFS(Appointments!$M$5:$M$1204,"No show") -> 0 | E1208: =IFERROR(COUNTIFS(Appointments!$M$5:$M$1204,"Completed")/MAX(1,COUNTIFS(Appointments!$AC$5:$AC$1204,"Yes")),0) -> 0 | F1208: =IFERROR(COUNTIFS(Appointments!$M$5:$M$1204,"Cancelled")/MAX(1,COUNTIFS(Appointments!$AC$5:$AC$1204,"Yes")),0) -> 0 | G1208: =IFERROR(COUNTIFS(Appointments!$M$5:$M$1204,"No show")/MAX(1,COUNTIFS(Appointments!$AC$5:$AC$1204,"Yes")),0) -> 0 | H1208: =ROUND(SUMIFS(Appointments!$Y$5:$Y$1204,Appointments!$M$5:$M$1204,"Completed"),2) -> 0 | I1208: =ROUND(SUMIFS(Appointments!$X$5:$X$1204,Appointments!$M$5:$M$1204,"Completed"),1) -> 0 | J1208: =COUNTIFS(Appointments!$AG$5:$AG$1204,"Clash") -> 0

Sheet Clients
A1: Client CRM | AO1: Novality Store | v1.0.0
A2: Who they are, what they have spent, when they were last in - and which of them you are about to lose.
A3: > Start Here | C3: > Dashboard | E3: > Diary | G3: > Clients | I3: > Services | K3: > Sales | M3: > Staff | O3: > Profit | Q3: > Settings | S3: Type the name and the contact details. Visits, spend, last visit and the chase list all build themselves from the appointments and sales tabs.
A4: ID | B4: Client | C4: Phone | D4: Email | E4: Contact by | F4: First seen | G4: Found you by | H4: Referred by | I4: Usual stylist | J4: Stylist | K4: Birthday | L4: Formula & preferences | M4: Allergies & notes | N4: Patch test | O4: Marketing OK? | P4: Photos OK? | Q4: Tags | R4: Status | S4: Notes | T4: Visits | U4: Visits, 12m | V4: Cancelled | W4: No shows | X4: First visit | Y4: Last visit | Z4: Days since | AA4: Next raw | AB4: Next booked | AC4: Usual gap | AD4: Rebook by | AE4: Lifetime spend | AF4: On services | AG4: On retail | AH4: Spend, 12m | AI4: Average ticket | AJ4: A year is worth | AK4: Balance owed | AL4: Loyalty points | AM4: Segment | AN4: Came back? | AO4: Spend rank | AP4: Visit rank | AQ4: Action
A5: =IF(B5="","",ClientPrefix&TEXT(ROW()-4,"0000")) -> 0 | J5: =IF(I5="","",IFERROR(INDEX(Staff!$B$5:$B$44,MATCH(I5,Staff!$A$5:$A$44,0)),"Not in Staff")) -> 0 | T5: =IF(B5="","",COUNTIFS(Appointments!$E$5:$E$1204,A5,Appointments!$M$5:$M$1204,"Completed")) -> 0 | U5: =IF(B5="","",COUNTIFS(Appointments!$E$5:$E$1204,A5,Appointments!$M$5:$M$1204,"Completed",Appointments!$B$5:$B$1204,">="&TodayDate-365)) -> 0 | V5: =IF(B5="","",COUNTIFS(Appointments!$E$5:$E$1204,A5,Appointments!$M$5:$M$1204,"Cancelled")) -> 0 | W5: =IF(B5="","",COUNTIFS(Appointments!$E$5:$E$1204,A5,Appointments!$M$5:$M$1204,"No show")) -> 0 | X5: =IF(B5="","",IF(F5<>"",F5,IF(T5=0,"",SUMPRODUCT(MIN((Appointments!$E$5:$E$1204=A5)*(Appointments!$M$5:$M$1204="Completed")*Appointments!$B$5:$B$1204+(1-(Appointments!$E$5:$E$1204=A5)*(Appointments!$M$5:$M$1204="Completed"))*2958465))))) -> 0 | Y5: =IF(B5="","",IF(T5=0,"",SUMPRODUCT(MAX((Appointments!$E$5:$E$1204=A5)*(Appointments!$M$5:$M$1204="Completed")*Appointments!$B$5:$B$1204)))) -> 0 | Z5: =IF(B5="","",IF(Y5="","",TodayDate-Y5)) -> 0 | AA5: =IF(B5="","",SUMPRODUCT(MIN((Appointments!$E$5:$E$1204=A5)*(Appointments!$M$5:$M$1204<>"Cancelled")*(Appointments!$M$5:$M$1204<>"Completed")*(Appointments!$M$5:$M$1204<>"No show")*(Appointments!$B$5:$B$1204>=TodayDate)*Appointments!$B$5:$B$1204+(1-(Appointments!$E$5:$E$1204=A5)*(Appointments!$M$5:$M$1204<>"Cancelled")*(Appointments!$M$5:$M$1204<>"Completed")*(Appointments!$M$5:$M$1204<>"No show")*(Appointments!$B$5:$B$1204>=TodayDate))*2958465))) -> 0 | AB5: =IF(B5="","",IF(AA5>=2958465,"",AA5)) -> 0 | AC5: =IF(B5="","",IF(T5<2,"",ROUND((Y5-X5)/MAX(1,T5-1),0))) -> 0 | AD5: =IF(B5="","",IF(Y5="","",Y5+IF(AC5="",RebookWeeks*7,MAX(14,AC5)))) -> 0 | AE5: =IF(B5="","",ROUND(SUMIFS(Sales!$Y$5:$Y$1204,Sales!$D$5:$D$1204,A5),2)) -> 0 | AF5: =IF(B5="","",ROUND(SUMIFS(Sales!$Y$5:$Y$1204,Sales!$D$5:$D$1204,A5,Sales!$H$5:$H$1204,"Service"),2)) -> 0 | AG5: =IF(B5="","",ROUND(SUMIFS(Sales!$Y$5:$Y$1204,Sales!$D$5:$D$1204,A5,Sales!$H$5:$H$1204,"Retail"),2)) -> 0 | AH5: =IF(B5="","",ROUND(SUMIFS(Sales!$Y$5:$Y$1204,Sales!$D$5:$D$1204,A5,Sales!$B$5:$B$1204,">="&TodayDate-365),2)) -> 0 | AI5: =IF(B5="","",IF(T5=0,"",ROUND(AE5/T5,2))) -> 0 | AJ5: =IF(B5="","",IF(AI5="","",IF(AC5="","",ROUND(AI5*(365/MAX(14,AC5)),2)))) -> 0 | AK5: =IF(B5="","",ROUND(SUMIFS(Sales!$AH$5:$AH$1204,Sales!$D$5:$D$1204,A5),2)) -> 0 | AL5: =IF(B5="","",IFERROR(INDEX(Loyalty!$P$5:$P$504,MATCH(A5,Loyalty!$B$5:$B$504,0))*1,0)) -> 0 | AM5: =IF(B5="","",IF(R5="Archived","Archived",IF(T5=0,"Not been yet",IF(Z5>=InactiveDays,"Inactive",IF(Z5>=LapsingDays,"Lapsing",IF(T5=1,"New",IF(AH5>=VipSpend,"VIP",IF(U5>=4,"Regular","Active")))))))) -> 0 | AN5: =IF(B5="","",IF(T5>=2,"Yes","No")) -> 0 | AO5: =IF(B5="","",COUNTIFS($AE$5:$AE$504,">"&AE5)+COUNTIFS($AE$5:AE5,AE5)) -> 0 | AP5: =IF(B5="","",COUNTIFS($T$5:$T$504,">"&T5)+COUNTIFS($T$5:T5,T5)) -> 0 | AQ5: =IF(B5="","",IF(COUNTIF($B$5:$B$504,B5)>1,"Duplicate - same name twice",IF(R5="Archived","",IF(AK5>0.004,"Chase - balance outstanding",IF(AM5="Inactive","Gone - win-back offer",IF(AM5="Lapsing","Chase - lapsing, call them",IF(IF(N5="",FALSE,TodayDate-N5>PatchTestDays),"Due - patch test out of date",IF(IF(AD5="",FALSE,IF(AB5<>"",FALSE,AD5<=TodayDate+14)),"Rebook - due and nothing booked",IF(IF(K5="",FALSE,ABS(DATE(YEAR(TodayDate),MONTH(K5),DAY(K5))-TodayDate)<=7),"Birthday - send the treat","OK"))))))))) -> 0
A6: =IF(B6="","",ClientPrefix&TEXT(ROW()-4,"0000")) -> 0 | J6: =IF(I6="","",IFERROR(INDEX(Staff!$B$5:$B$44,MATCH(I6,Staff!$A$5:$A$44,0)),"Not in Staff")) -> 0 | T6: =IF(B6="","",COUNTIFS(Appointments!$E$5:$E$1204,A6,Appointments!$M$5:$M$1204,"Completed")) -> 0 | U6: =IF(B6="","",COUNTIFS(Appointments!$E$5:$E$1204,A6,Appointments!$M$5:$M$1204,"Completed",Appointments!$B$5:$B$1204,">="&TodayDate-365)) -> 0 | V6: =IF(B6="","",COUNTIFS(Appointments!$E$5:$E$1204,A6,Appointments!$M$5:$M$1204,"Cancelled")) -> 0 | W6: =IF(B6="","",COUNTIFS(Appointments!$E$5:$E$1204,A6,Appointments!$M$5:$M$1204,"No show")) -> 0 | X6: =IF(B6="","",IF(F6<>"",F6,IF(T6=0,"",SUMPRODUCT(MIN((Appointments!$E$5:$E$1204=A6)*(Appointments!$M$5:$M$1204="Completed")*Appointments!$B$5:$B$1204+(1-(Appointments!$E$5:$E$1204=A6)*(Appointments!$M$5:$M$1204="Completed"))*2958465))))) -> 0 | Y6: =IF(B6="","",IF(T6=0,"",SUMPRODUCT(MAX((Appointments!$E$5:$E$1204=A6)*(Appointments!$M$5:$M$1204="Completed")*Appointments!$B$5:$B$1204)))) -> 0 | Z6: =IF(B6="","",IF(Y6="","",TodayDate-Y6)) -> 0 | AA6: =IF(B6="","",SUMPRODUCT(MIN((Appointments!$E$5:$E$1204=A6)*(Appointments!$M$5:$M$1204<>"Cancelled")*(Appointments!$M$5:$M$1204<>"Completed")*(Appointments!$M$5:$M$1204<>"No show")*(Appointments!$B$5:$B$1204>=TodayDate)*Appointments!$B$5:$B$1204+(1-(Appointments!$E$5:$E$1204=A6)*(Appointments!$M$5:$M$1204<>"Cancelled")*(Appointments!$M$5:$M$1204<>"Completed")*(Appointments!$M$5:$M$1204<>"No show")*(Appointments!$B$5:$B$1204>=TodayDate))*2958465))) -> 0 | AB6: =IF(B6="","",IF(AA6>=2958465,"",AA6)) -> 0 | AC6: =IF(B6="","",IF(T6<2,"",ROUND((Y6-X6)/MAX(1,T6-1),0))) -> 0 | AD6: =IF(B6="","",IF(Y6="","",Y6+IF(AC6="",RebookWeeks*7,MAX(14,AC6)))) -> 0 | AE6: =IF(B6="","",ROUND(SUMIFS(Sales!$Y$5:$Y$1204,Sales!$D$5:$D$1204,A6),2)) -> 0 | AF6: =IF(B6="","",ROUND(SUMIFS(Sales!$Y$5:$Y$1204,Sales!$D$5:$D$1204,A6,Sales!$H$5:$H$1204,"Service"),2)) -> 0 | AG6: =IF(B6="","",ROUND(SUMIFS(Sales!$Y$5:$Y$1204,Sales!$D$5:$D$1204,A6,Sales!$H$5:$H$1204,"Retail"),2)) -> 0 | AH6: =IF(B6="","",ROUND(SUMIFS(Sales!$Y$5:$Y$1204,Sales!$D$5:$D$1204,A6,Sales!$B$5:$B$1204,">="&TodayDate-365),2)) -> 0 | AI6: =IF(B6="","",IF(T6=0,"",ROUND(AE6/T6,2))) -> 0 | AJ6: =IF(B6="","",IF(AI6="","",IF(AC6="","",ROUND(AI6*(365/MAX(14,AC6)),2)))) -> 0 | AK6: =IF(B6="","",ROUND(SUMIFS(Sales!$AH$5:$AH$1204,Sales!$D$5:$D$1204,A6),2)) -> 0 | AL6: =IF(B6="","",IFERROR(INDEX(Loyalty!$P$5:$P$504,MATCH(A6,Loyalty!$B$5:$B$504,0))*1,0)) -> 0 | AM6: =IF(B6="","",IF(R6="Archived","Archived",IF(T6=0,"Not been yet",IF(Z6>=InactiveDays,"Inactive",IF(Z6>=LapsingDays,"Lapsing",IF(T6=1,"New",IF(AH6>=VipSpend,"VIP",IF(U6>=4,"Regular","Active")))))))) -> 0 | AN6: =IF(B6="","",IF(T6>=2,"Yes","No")) -> 0 | AO6: =IF(B6="","",COUNTIFS($AE$5:$AE$504,">"&AE6)+COUNTIFS($AE$5:AE6,AE6)) -> 0 | AP6: =IF(B6="","",COUNTIFS($T$5:$T$504,">"&T6)+COUNTIFS($T$5:T6,T6)) -> 0 | AQ6: =IF(B6="","",IF(COUNTIF($B$5:$B$504,B6)>1,"Duplicate - same name twice",IF(R6="Archived","",IF(AK6>0.004,"Chase - balance outstanding",IF(AM6="Inactive","Gone - win-back offer",IF(AM6="Lapsing","Chase - lapsing, call them",IF(IF(N6="",FALSE,TodayDate-N6>PatchTestDays),"Due - patch test out of date",IF(IF(AD6="",FALSE,IF(AB6<>"",FALSE,AD6<=TodayDate+14)),"Rebook - due and nothing booked",IF(IF(K6="",FALSE,ABS(DATE(YEAR(TodayDate),MONTH(K6),DAY(K6))-TodayDate)<=7),"Birthday - send the treat","OK"))))))))) -> 0
