Workbook
Name AccountNames: OFFSET(Accounts!$C$5,0,0,MAX(1,COUNTIF(Accounts!$C$5:$C$34,"?*")),1)
Name AccountTypeList: OFFSET(Lists!$D$5,0,0,MAX(1,COUNTIF(Lists!$D$5:$D$44,"?*")),1)
Name AdObjectiveList: OFFSET(Lists!$AF$5,0,0,MAX(1,COUNTIF(Lists!$AF$5:$AF$44,"?*")),1)
Name AnnualBudget: Settings!$D$44
Name ApprovalDays: Settings!$D$50
Name ApprovalStatusList: OFFSET(Lists!$V$5,0,0,MAX(1,COUNTIF(Lists!$V$5:$V$44,"?*")),1)
Name AssetIDs: OFFSET(Assets!$A$5,0,0,MAX(1,COUNTIF(Assets!$A$5:$A$254,"?*")),1)
Name AssetPrefix: Settings!$D$62
Name AssetReviewDays: Settings!$D$53
Name AssetTypeList: OFFSET(Lists!$T$5,0,0,MAX(1,COUNTIF(Lists!$T$5:$T$44,"?*")),1)
Name BrandAudience: Settings!$D$14
Name BrandEmail: Settings!$D$8
Name BrandFolder: Settings!$D$22
Name BrandFonts: Settings!$D$21
Name BrandGoal: Settings!$D$15
Name BrandHashtag: Settings!$D$16
Name BrandIndustry: Settings!$D$12
Name BrandLogo: Settings!$D$19
Name BrandName: Settings!$D$6
Name BrandNiche: Settings!$D$13
Name BrandOwner: Settings!$D$7
Name BrandPalette: Settings!$D$20
Name BrandPhone: Settings!$D$9
Name BrandShop: Settings!$D$11
Name BrandTimeZone: Settings!$D$27
Name BrandWeb: Settings!$D$10
Name BriefID: 'Print Brief'!$C$1
Name CampaignNames: OFFSET(Campaigns!$B$5,0,0,MAX(1,COUNTIF(Campaigns!$B$5:$B$64,"?*")),1)
Name CampaignPrefix: Settings!$D$61
Name CampaignStatusList: OFFSET(Lists!$P$5,0,0,MAX(1,COUNTIF(Lists!$P$5:$P$44,"?*")),1)
Name CaptionIDs: OFFSET('Caption Bank'!$A$5,0,0,MAX(1,COUNTIF('Caption Bank'!$A$5:$A$204,"?*")),1)
Name CaptionPrefix: Settings!$D$59
Name CaptionTitles: OFFSET('Caption Bank'!$B$5,0,0,MAX(1,COUNTIF('Caption Bank'!$B$5:$B$204,"?*")),1)
Name ClickGoal: Settings!$D$37
Name CollabTypeList: OFFSET(Lists!$W$5,0,0,MAX(1,COUNTIF(Lists!$W$5:$W$44,"?*")),1)
Name CompetitorNames: OFFSET(Competitors!$B$5,0,0,MAX(1,COUNTIF(Competitors!$B$5:$B$44,"?*")),1)
Name ComplianceStatusList: OFFSET(Lists!$AM$5,0,0,MAX(1,COUNTIF(Lists!$AM$5:$AM$44,"?*")),1)
Name ContentIDs: OFFSET('Content Calendar'!$A$5,0,0,MAX(1,COUNTIF('Content Calendar'!$A$5:$A$604,"?*")),1)
Name ContentPrefix: Settings!$D$57
Name ContentStatusList: OFFSET(Lists!$F$5,0,0,MAX(1,COUNTIF(Lists!$F$5:$F$44,"?*")),1)
Name ContentTitles: OFFSET('Content Calendar'!$H$5,0,0,MAX(1,COUNTIF('Content Calendar'!$H$5:$H$604,"?*")),1)
Name ConversionGoal: Settings!$D$39
Name CostCategoryList: OFFSET(Lists!$AE$5,0,0,MAX(1,COUNTIF(Lists!$AE$5:$AE$44,"?*")),1)
Name CplTarget: Settings!$D$46
Name CTAList: OFFSET(Lists!$I$5,0,0,MAX(1,COUNTIF(Lists!$I$5:$I$44,"?*")),1)
Name CurrencyCode: Settings!$D$28
Name Dash_Engagements: Dashboard!$G$15
Name Dash_Published: Dashboard!$D$10
Name Dash_Reach: Dashboard!$A$15
Name Dash_Revenue: Dashboard!$P$20
Name Dash_Spend: Dashboard!$A$25
Name DashEnd: Dashboard!$K$6
Name DashKey: Dashboard!$O$6
Name DashMonthName: Dashboard!$C$6
Name DashStart: Dashboard!$G$6
Name DifficultyList: OFFSET(Lists!$S$5,0,0,MAX(1,COUNTIF(Lists!$S$5:$S$44,"?*")),1)
Name FiscalStartMonth: Settings!$D$29
Name FollowerGoal: Settings!$D$35
Name FormatList: OFFSET(Lists!$E$5,0,0,MAX(1,COUNTIF(Lists!$E$5:$E$44,"?*")),1)
Name FrequencyList: OFFSET(Lists!$AK$5,0,0,MAX(1,COUNTIF(Lists!$AK$5:$AK$44,"?*")),1)

Sheet Start Here
A1: Social Media Content Calendar & Analytics Planner | J1: Novality Store | v1.0.0
A2: Plan a year of content, keep every caption and hashtag in one place, and see what actually worked.
A3: > Start Here | C3: > Dashboard | E3: > Calendar | G3: > Ideas | I3: > Captions | K3: > Hashtags
B5: Everything in this workbook is linked. Type something once - a post, a caption, a number from Instagram - and it appears wherever it is needed: the dashboards, the reports, the printable brief and the alerts. Cream cells are yours to fill in; grey cells are formulas and are locked so they cannot be broken by accident.
A7: Six steps to set it up
B8: Step | C8: Where | D8: What to do
B9: 1 | C9: Settings | D9: Put your brand name, handles, plan year, targets and budget in. Ten minutes, and it feeds every other tab.
B10: 2 | C10: Accounts & Brand Voice | D10: List every profile you post to, then write down how the brand sounds so captions stay consistent.
B11: 3 | C11: Personas & Content Pillars | D11: Decide who you are talking to and the five or six themes you post about. The pillars become drop downs everywhere else.
B12: 4 | C12: Idea Bank, Captions & Hashtags | D12: Dump every idea in, write captions you can reuse and build hashtag groups of 20-30 tags.
B13: 5 | C13: Content Calendar | D13: Plan the year. One row per post: date, platform, title, pillar, caption, hashtag group, asset, owner, status.
B14: 6 | C14: Analytics & Performance | D14: On the first of each month enter the account numbers, and after each post record how it did. The dashboards do the rest.
A16: The weekly rhythm
B17: MONDAY - clear the overdue list on the Dashboard, then look at the next posts due on the Workflow tab.
B18: ONE BATCH DAY - make the week's content in one sitting. It is always faster than making it one post at a time.
B19: BEFORE YOU POST - check the caption, the hashtag group, the asset and the link. The calendar flags anything missing.
B20: AFTER YOU POST - paste the link into the calendar. Two days later, add the numbers on the Performance tab.
B21: FIRST OF THE MONTH - fill in the Analytics tab (ten minutes), update your Goals, then read the Monthly Dashboard.
A23: What is in the workbook
B24: Tab | C24: What it is for
B25: Dashboard | C25: This month at a glance, with alerts and the queue
B26: Annual Dashboard | C26: The whole year, quarter by quarter
B27: Settings | C27: Your brand, targets, budget and reminder windows
B28: Lists | C28: Every drop down list - edit these to suit your business
B29: Brand Voice | C29: How the brand sounds, looks and behaves
B30: Audience Personas | C30: Who you are talking to
B31: Accounts | C31: Every profile, with a six point optimisation check
B32: Content Pillars | C32: Your themes and the mix you planned
B33: Content Calendar | C33: THE MAIN TAB - one row per post, all year
B34: Month View | C34: The same calendar laid out as a printable grid
B35: Workflow | C35: The production pipeline: what is where, what is late
... B61: Help | C61: Every question answered, including the honest limits
A63: Good to know
B64: PROTECTION - every sheet is protected so the formulas cannot be edited by accident. The password is 'premium'. Review > Unprotect Sheet if you want to change something.
B65: ADDING ROWS - every register has spare rows ready to use. Right click a row inside the list and choose Insert to add more; the formulas copy down.
B66: SORTING - use the filter arrows in the header row rather than re-sorting the sheet, so the content IDs keep matching the other tabs.
B67: DROP DOWNS - every list lives on the Lists tab. Edit it there and the drop downs follow.
B68: GOOGLE SHEETS - File > Import works, and everything except the sparklines and the sheet protection carries over.
B69: YOUR CURRENCY - set the symbol on the Settings tab, or rebuild the workbook with a different currency.
A71: What a spreadsheet can and cannot do
...

Sheet Dashboard
A1: Monthly Dashboard | P1: Novality Store | v1.0.0
A2: Pick a month, then read your whole social media presence at a glance. Every number is live - it updates as you fill in the calendar and the Analytics tab.
A3: > Start Here | C3: > Dashboard | E3: > Calendar | G3: > Ideas | I3: > Captions | K3: > Hashtags | M3: > Analytics | O3: > Reports | Q3: > Help
A5: Which month are you looking at?
A6: Month | C6: October | E6: Period start | G6: =IF(DashMonthName="All year",DATE(PlanYear,1,1),DATE(PlanYear,MAX(1,MATCH(DashMonthName,MonthList,0)-1),1)) -> 0 | I6: Period end | K6: =IF(DashMonthName="All year",DATE(PlanYear,12,31),EOMONTH(DashStart,0)) -> 0 | M6: Month key | O6: =TEXT(DashStart,"yyyy-mm") -> 0 | Q6: Today | R6: =TODAY() -> 0
A8: What you published
A9: Posts planned | D9: Published | G9: Still to come | J9: Target for the month | M9: Against target | P9: Needing attention
A10: =COUNTIFS('Content Calendar'!$B$5:$B$604,">="&DashStart,'Content Calendar'!$B$5:$B$604,"<="&DashEnd) -> 0 | D10: =COUNTIFS('Content Calendar'!$B$5:$B$604,">="&DashStart,'Content Calendar'!$B$5:$B$604,"<="&DashEnd,'Content Calendar'!$X$5:$X$604,"Published") -> 0 | G10: =COUNTIFS('Content Calendar'!$B$5:$B$604,">="&DashStart,'Content Calendar'!$B$5:$B$604,"<="&DashEnd,'Content Calendar'!$X$5:$X$604,"Scheduled")+COUNTIFS('Content Calendar'!$B$5:$B$604,">="&DashStart,'Content Calendar'!$B$5:$B$604,"<="&DashEnd,'Content Calendar'!$X$5:$X$604,"Approved") -> 0 | J10: =IF(DashMonthName="All year",MonthlyPostTarget*12,MonthlyPostTarget) -> 0 | M10: =IFERROR(Dash_Published/IF(DashMonthName="All year",MonthlyPostTarget*12,MonthlyPostTarget),0) -> 0 | P10: =COUNTIFS('Content Calendar'!$AM$5:$AM$604,"<>OK",'Content Calendar'!$H$5:$H$604,"<>") -> 0
A11: Everything on the calendar in this period | D11: Actually went out | G11: Approved or scheduled, not yet live | J11: From the Settings tab | M11: Published divided by your target | P11: Rows with an action in the last column
A13: How it performed
A14: Reach | D14: Impressions | G14: Engagements | J14: Engagement rate | M14: Target rate | P14: Reach per post
A15: =SUMIFS(Analytics!$J$5:$J$154,Analytics!$B$5:$B$154,">="&DashStart,Analytics!$B$5:$B$154,"<="&DashEnd) -> 0 | D15: =SUMIFS(Analytics!$K$5:$K$154,Analytics!$B$5:$B$154,">="&DashStart,Analytics!$B$5:$B$154,"<="&DashEnd) -> 0 | G15: =SUMIFS(Analytics!$L$5:$L$154,Analytics!$B$5:$B$154,">="&DashStart,Analytics!$B$5:$B$154,"<="&DashEnd) -> 0 | J15: =IFERROR(Dash_Engagements/Dash_Reach,0) -> 0 | M15: =TargetEngagement -> 0 | P15: =IFERROR(Dash_Reach/Dash_Published,0) -> 0
A16: People reached across every account | D16: Times your content was shown | G16: Likes, comments, shares and saves | J16: Engagements divided by reach | M16: Your goal, set on the Settings tab | P16: How far the average post travelled
A18: Audience & results
A19: Followers | D19: Follower growth | G19: Link clicks | J19: Leads | M19: Sales | P19: Revenue
A20: =SUMIFS(Analytics!$G$5:$G$154,Analytics!$B$5:$B$154,">="&DashStart,Analytics!$B$5:$B$154,"<="&DashEnd) -> 0 | D20: =SUMIFS(Analytics!$X$5:$X$154,Analytics!$B$5:$B$154,">="&DashStart,Analytics!$B$5:$B$154,"<="&DashEnd) -> 0 | G20: =SUMIFS(Analytics!$R$5:$R$154,Analytics!$B$5:$B$154,">="&DashStart,Analytics!$B$5:$B$154,"<="&DashEnd) -> 0 | J20: =SUMIFS(Analytics!$S$5:$S$154,Analytics!$B$5:$B$154,">="&DashStart,Analytics!$B$5:$B$154,"<="&DashEnd) -> 0 | M20: =SUMIFS(Analytics!$T$5:$T$154,Analytics!$B$5:$B$154,">="&DashStart,Analytics!$B$5:$B$154,"<="&DashEnd) -> 0 | P20: =SUMIFS(Analytics!$U$5:$U$154,Analytics!$B$5:$B$154,">="&DashStart,Analytics!$B$5:$B$154,"<="&DashEnd) -> 0
A21: Total across every account at the end of the period | D21: New followers less unfollows | G21: Traffic you sent out | J21: Sign-ups, enquiries, waitlist joins | M21: Orders you can trace back to social | P21: Money attributed to social
A23: What it cost
A24: Spend | D24: Budget | G24: Left to spend | J24: Return on spend | M24: Cost per lead | P24: Revenue per post
A25: =SUMIFS(Budget!$H$5:$H$64,Budget!$B$5:$B$64,">="&DashStart,Budget!$B$5:$B$64,"<="&DashEnd) -> 0 | D25: =IF(DashMonthName="All year",AnnualBudget,MonthlyBudget) -> 0 | G25: =IF(DashMonthName="All year",AnnualBudget,MonthlyBudget)-Dash_Spend -> 0 | J25: =IFERROR(Dash_Revenue/Dash_Spend,0) -> 0 | M25: =IFERROR(Dash_Spend/SUMIFS(Analytics!$S$5:$S$154,Analytics!$B$5:$B$154,">="&DashStart,Analytics!$B$5:$B$154,"<="&DashEnd),0) -> 0 | P25: =IFERROR(Dash_Revenue/Dash_Published,0) -> 0
A26: Everything on the Budget tab for this period | D26: From the Settings tab | G26: Budget less actual spend | J26: Revenue divided by spend | M26: Spend divided by leads | P26: Money per published post
A28: The whole of 2026 month by month
A29: Month | B29: Published | C29: Reach | D29: Engagements | E29: Eng. rate | F29: Followers | G29: Growth | H29: Clicks | I29: Leads | J29: Sales | K29: Revenue | L29: Spend | M29: Net
A30: =Calc!$D$5 -> 0 | B30: =Calc!$F$5 -> 0 | C30: =Calc!$G$5 -> 0 | D30: =Calc!$I$5 -> 0 | E30: =Calc!$J$5 -> 0 | F30: =Calc!$K$5 -> 0 | G30: =Calc!$L$5 -> 0 | H30: =Calc!$M$5 -> 0 | I30: =Calc!$N$5 -> 0 | J30: =Calc!$O$5 -> 0 | K30: =Calc!$P$5 -> 0 | L30: =Calc!$Q$5 -> 0 | M30: =Calc!$R$5 -> 0
A31: =Calc!$D$6 -> 0 | B31: =Calc!$F$6 -> 0 | C31: =Calc!$G$6 -> 0 | D31: =Calc!$I$6 -> 0 | E31: =Calc!$J$6 -> 0 | F31: =Calc!$K$6 -> 0 | G31: =Calc!$L$6 -> 0 | H31: =Calc!$M$6 -> 0 | I31: =Calc!$N$6 -> 0 | J31: =Calc!$O$6 -> 0 | K31: =Calc!$P$6 -> 0 | L31: =Calc!$Q$6 -> 0 | M31: =Calc!$R$6 -> 0
A32: =Calc!$D$7 -> 0 | B32: =Calc!$F$7 -> 0 | C32: =Calc!$G$7 -> 0 | D32: =Calc!$I$7 -> 0 | E32: =Calc!$J$7 -> 0 | F32: =Calc!$K$7 -> 0 | G32: =Calc!$L$7 -> 0 | H32: =Calc!$M$7 -> 0 | I32: =Calc!$N$7 -> 0 | J32: =Calc!$O$7 -> 0 | K32: =Calc!$P$7 -> 0 | L32: =Calc!$Q$7 -> 0 | M32: =Calc!$R$7 -> 0
A33: =Calc!$D$8 -> 0 | B33: =Calc!$F$8 -> 0 | C33: =Calc!$G$8 -> 0 | D33: =Calc!$I$8 -> 0 | E33: =Calc!$J$8 -> 0 | F33: =Calc!$K$8 -> 0 | G33: =Calc!$L$8 -> 0 | H33: =Calc!$M$8 -> 0 | I33: =Calc!$N$8 -> 0 | J33: =Calc!$O$8 -> 0 | K33: =Calc!$P$8 -> 0 | L33: =Calc!$Q$8 -> 0 | M33: =Calc!$R$8 -> 0
A34: =Calc!$D$9 -> 0 | B34: =Calc!$F$9 -> 0 | C34: =Calc!$G$9 -> 0 | D34: =Calc!$I$9 -> 0 | E34: =Calc!$J$9 -> 0 | F34: =Calc!$K$9 -> 0 | G34: =Calc!$L$9 -> 0 | H34: =Calc!$M$9 -> 0 | I34: =Calc!$N$9 -> 0 | J34: =Calc!$O$9 -> 0 | K34: =Calc!$P$9 -> 0 | L34: =Calc!$Q$9 -> 0 | M34: =Calc!$R$9 -> 0
A35: =Calc!$D$10 -> 0 | B35: =Calc!$F$10 -> 0 | C35: =Calc!$G$10 -> 0 | D35: =Calc!$I$10 -> 0 | E35: =Calc!$J$10 -> 0 | F35: =Calc!$K$10 -> 0 | G35: =Calc!$L$10 -> 0 | H35: =Calc!$M$10 -> 0 | I35: =Calc!$N$10 -> 0 | J35: =Calc!$O$10 -> 0 | K35: =Calc!$P$10 -> 0 | L35: =Calc!$Q$10 -> 0 | M35: =Calc!$R$10 -> 0
A36: =Calc!$D$11 -> 0 | B36: =Calc!$F$11 -> 0 | C36: =Calc!$G$11 -> 0 | D36: =Calc!$I$11 -> 0 | E36: =Calc!$J$11 -> 0 | F36: =Calc!$K$11 -> 0 | G36: =Calc!$L$11 -> 0 | H36: =Calc!$M$11 -> 0 | I36: =Calc!$N$11 -> 0 | J36: =Calc!$O$11 -> 0 | K36: =Calc!$P$11 -> 0 | L36: =Calc!$Q$11 -> 0 | M36: =Calc!$R$11 -> 0
A37: =Calc!$D$12 -> 0 | B37: =Calc!$F$12 -> 0 | C37: =Calc!$G$12 -> 0 | D37: =Calc!$I$12 -> 0 | E37: =Calc!$J$12 -> 0 | F37: =Calc!$K$12 -> 0 | G37: =Calc!$L$12 -> 0 | H37: =Calc!$M$12 -> 0 | I37: =Calc!$N$12 -> 0 | J37: =Calc!$O$12 -> 0 | K37: =Calc!$P$12 -> 0 | L37: =Calc!$Q$12 -> 0 | M37: =Calc!$R$12 -> 0
A38: =Calc!$D$13 -> 0 | B38: =Calc!$F$13 -> 0 | C38: =Calc!$G$13 -> 0 | D38: =Calc!$I$13 -> 0 | E38: =Calc!$J$13 -> 0 | F38: =Calc!$K$13 -> 0 | G38: =Calc!$L$13 -> 0 | H38: =Calc!$M$13 -> 0 | I38: =Calc!$N$13 -> 0 | J38: =Calc!$O$13 -> 0 | K38: =Calc!$P$13 -> 0 | L38: =Calc!$Q$13 -> 0 | M38: =Calc!$R$13 -> 0
A39: =Calc!$D$14 -> 0 | B39: =Calc!$F$14 -> 0 | C39: =Calc!$G$14 -> 0 | D39: =Calc!$I$14 -> 0 | E39: =Calc!$J$14 -> 0 | F39: =Calc!$K$14 -> 0 | G39: =Calc!$L$14 -> 0 | H39: =Calc!$M$14 -> 0 | I39: =Calc!$N$14 -> 0 | J39: =Calc!$O$14 -> 0 | K39: =Calc!$P$14 -> 0 | L39: =Calc!$Q$14 -> 0 | M39: =Calc!$R$14 -> 0
A40: =Calc!$D$15 -> 0 | B40: =Calc!$F$15 -> 0 | C40: =Calc!$G$15 -> 0 | D40: =Calc!$I$15 -> 0 | E40: =Calc!$J$15 -> 0 | F40: =Calc!$K$15 -> 0 | G40: =Calc!$L$15 -> 0 | H40: =Calc!$M$15 -> 0 | I40: =Calc!$N$15 -> 0 | J40: =Calc!$O$15 -> 0 | K40: =Calc!$P$15 -> 0 | L40: =Calc!$Q$15 -> 0 | M40: =Calc!$R$15 -> 0
A41: =Calc!$D$16 -> 0 | B41: =Calc!$F$16 -> 0 | C41: =Calc!$G$16 -> 0 | D41: =Calc!$I$16 -> 0 | E41: =Calc!$J$16 -> 0 | F41: =Calc!$K$16 -> 0 | G41: =Calc!$L$16 -> 0 | H41: =Calc!$M$16 -> 0 | I41: =Calc!$N$16 -> 0 | J41: =Calc!$O$16 -> 0 | K41: =Calc!$P$16 -> 0 | L41: =Calc!$Q$16 -> 0 | M41: =Calc!$R$16 -> 0
A42: Trend
A44: Platform by platform (selected period) | K44: Content pillars (this year)
A45: Platform | B45: Posts | C45: Reach | D45: Engagements | E45: Eng. rate | F45: Followers | G45: Growth | H45: Clicks | I45: Revenue | K45: Pillar | L45: Posts | M45: Reach | N45: Engagements | O45: Eng. rate | P45: Share
A46: =IF(Calc!$T$5="","",Calc!$T$5) -> 0 | B46: =IF(Calc!$T$5="","",Calc!$V$5) -> 0 | C46: =IF(Calc!$T$5="","",Calc!$W$5) -> 0 | D46: =IF(Calc!$T$5="","",Calc!$X$5) -> 0 | E46: =IF(Calc!$T$5="","",Calc!$Y$5) -> 0 | F46: =IF(Calc!$T$5="","",Calc!$Z$5) -> 0 | G46: =IF(Calc!$T$5="","",Calc!$AA$5) -> 0 | H46: =IF(Calc!$T$5="","",Calc!$AB$5) -> 0 | I46: =IF(Calc!$T$5="","",Calc!$AC$5) -> 0 | K46: =IF(Calc!$AJ$5="","",Calc!$AJ$5) -> 0 | L46: =IF(Calc!$AJ$5="","",Calc!$AK$5) -> 0 | M46: =IF(Calc!$AJ$5="","",Calc!$AL$5) -> 0 | N46: =IF(Calc!$AJ$5="","",Calc!$AM$5) -> 0 | O46: =IF(Calc!$AJ$5="","",Calc!$AN$5) -> 0 | P46: =IFERROR(Calc!$AK$5/SUM(Calc!$AK$5:$AK$604),"") -> 0
A47: =IF(Calc!$T$6="","",Calc!$T$6) -> 0 | B47: =IF(Calc!$T$6="","",Calc!$V$6) -> 0 | C47: =IF(Calc!$T$6="","",Calc!$W$6) -> 0 | D47: =IF(Calc!$T$6="","",Calc!$X$6) -> 0 | E47: =IF(Calc!$T$6="","",Calc!$Y$6) -> 0 | F47: =IF(Calc!$T$6="","",Calc!$Z$6) -> 0 | G47: =IF(Calc!$T$6="","",Calc!$AA$6) -> 0 | H47: =IF(Calc!$T$6="","",Calc!$AB$6) -> 0 | I47: =IF(Calc!$T$6="","",Calc!$AC$6) -> 0 | K47: =IF(Calc!$AJ$6="","",Calc!$AJ$6) -> 0 | L47: =IF(Calc!$AJ$6="","",Calc!$AK$6) -> 0 | M47: =IF(Calc!$AJ$6="","",Calc!$AL$6) -> 0 | N47: =IF(Calc!$AJ$6="","",Calc!$AM$6) -> 0 | O47: =IF(Calc!$AJ$6="","",Calc!$AN$6) -> 0 | P47: =IFERROR(Calc!$AK$6/SUM(Calc!$AK$5:$AK$604),"") -> 0
...

Sheet Annual Dashboard
A1: Annual Dashboard | P1: Novality Store | v1.0.0
A2: Everything you planned and published in 2026, quarter by quarter and month by month.
A3: > Start Here | C3: > Dashboard | E3: > Calendar | G3: > Ideas | I3: > Captions | K3: > Hashtags | M3: > Analytics | O3: > Reports | Q3: > Help
A5: 2026 in numbers
A6: Posts planned | D6: Published | G6: Reach | J6: Engagements | M6: Engagement rate | P6: Follower growth
A7: =COUNTIFS('Content Calendar'!$B$5:$B$604,">="&DATE(PlanYear,1,1),'Content Calendar'!$B$5:$B$604,"<="&DATE(PlanYear,12,31)) -> 0 | D7: =COUNTIFS('Content Calendar'!$B$5:$B$604,">="&DATE(PlanYear,1,1),'Content Calendar'!$B$5:$B$604,"<="&DATE(PlanYear,12,31),'Content Calendar'!$X$5:$X$604,"Published") -> 0 | G7: =SUM(Calc!$G$5:$G$604) -> 0 | J7: =SUM(Calc!$I$5:$I$604) -> 0 | M7: =IFERROR(Year_Eng/Year_Reach,0) -> 0 | P7: =SUM(Calc!$L$5:$L$604) -> 0
A8: Every row on the calendar this year | D8: Actually went out | G8: Across every account and month | J8: Likes, comments, shares, saves | M8: The year's average | P8: New followers less unfollows
A10: Clicks | D10: Leads | G10: Sales | J10: Revenue | M10: Spend | P10: Return on spend
A11: =SUM(Calc!$M$5:$M$604) -> 0 | D11: =SUM(Calc!$N$5:$N$604) -> 0 | G11: =SUM(Calc!$O$5:$O$604) -> 0 | J11: =SUM(Calc!$P$5:$P$604) -> 0 | M11: =SUM(Calc!$Q$5:$Q$604) -> 0 | P11: =IFERROR(Year_Revenue/Year_Spend,0) -> 0
A12: Traffic sent out | D12: Enquiries and sign-ups | G12: Orders traced back to social | J12: Money attributed to social | M12: Everything on the Budget tab | P12: Revenue divided by spend
A14: Posts a week | D14: Reach per post | G14: Revenue per post | J14: Best month | M14: Best platform | P14: Best day to post
A15: =IFERROR(Year_Published/52,0) -> 0 | D15: =IFERROR(Year_Reach/Year_Published,0) -> 0 | G15: =IFERROR(Year_Revenue/Year_Published,0) -> 0 | J15: =IFERROR(INDEX(Calc!$D$5:$D$604,MATCH(MAX(Calc!$G$5:$G$604),Calc!$G$5:$G$604,0)),"") -> 0 | M15: =IFERROR(INDEX(Calc!$T$5:$T$604,MATCH(MAX(Calc!$AI$5:$AI$604),Calc!$AI$5:$AI$604,0)),"") -> 0 | P15: =IFERROR(INDEX(Calc!$AV$5:$AV$604,MATCH(MAX(Calc!$BA$5:$BA$604),Calc!$BA$5:$BA$604,0)),"") -> 0
A16: Your real publishing rhythm | D16: How far the average post travelled | G16: Money per published post | J16: By reach | M16: By reach this year | P16: Highest average engagement rate
A18: Quarter by quarter
A19: Quarter | B19: Published | C19: Reach | D19: Engagements | E19: Eng. rate | F19: Followers gained | G19: Clicks | H19: Leads | I19: Sales | J19: Revenue | K19: Spend | L19: Net
A20: Q1 | B20: =N(Calc!$F$5)+N(Calc!$F$6)+N(Calc!$F$7) -> 0 | C20: =N(Calc!$G$5)+N(Calc!$G$6)+N(Calc!$G$7) -> 0 | D20: =N(Calc!$I$5)+N(Calc!$I$6)+N(Calc!$I$7) -> 0 | E20: =IFERROR(D20/C20,"") -> 0 | F20: =N(Calc!$L$5)+N(Calc!$L$6)+N(Calc!$L$7) -> 0 | G20: =N(Calc!$M$5)+N(Calc!$M$6)+N(Calc!$M$7) -> 0 | H20: =N(Calc!$N$5)+N(Calc!$N$6)+N(Calc!$N$7) -> 0 | I20: =N(Calc!$O$5)+N(Calc!$O$6)+N(Calc!$O$7) -> 0 | J20: =N(Calc!$P$5)+N(Calc!$P$6)+N(Calc!$P$7) -> 0 | K20: =N(Calc!$Q$5)+N(Calc!$Q$6)+N(Calc!$Q$7) -> 0 | L20: =J20-K20 -> 0
A21: Q2 | B21: =N(Calc!$F$8)+N(Calc!$F$9)+N(Calc!$F$10) -> 0 | C21: =N(Calc!$G$8)+N(Calc!$G$9)+N(Calc!$G$10) -> 0 | D21: =N(Calc!$I$8)+N(Calc!$I$9)+N(Calc!$I$10) -> 0 | E21: =IFERROR(D21/C21,"") -> 0 | F21: =N(Calc!$L$8)+N(Calc!$L$9)+N(Calc!$L$10) -> 0 | G21: =N(Calc!$M$8)+N(Calc!$M$9)+N(Calc!$M$10) -> 0 | H21: =N(Calc!$N$8)+N(Calc!$N$9)+N(Calc!$N$10) -> 0 | I21: =N(Calc!$O$8)+N(Calc!$O$9)+N(Calc!$O$10) -> 0 | J21: =N(Calc!$P$8)+N(Calc!$P$9)+N(Calc!$P$10) -> 0 | K21: =N(Calc!$Q$8)+N(Calc!$Q$9)+N(Calc!$Q$10) -> 0 | L21: =J21-K21 -> 0
A22: Q3 | B22: =N(Calc!$F$11)+N(Calc!$F$12)+N(Calc!$F$13) -> 0 | C22: =N(Calc!$G$11)+N(Calc!$G$12)+N(Calc!$G$13) -> 0 | D22: =N(Calc!$I$11)+N(Calc!$I$12)+N(Calc!$I$13) -> 0 | E22: =IFERROR(D22/C22,"") -> 0 | F22: =N(Calc!$L$11)+N(Calc!$L$12)+N(Calc!$L$13) -> 0 | G22: =N(Calc!$M$11)+N(Calc!$M$12)+N(Calc!$M$13) -> 0 | H22: =N(Calc!$N$11)+N(Calc!$N$12)+N(Calc!$N$13) -> 0 | I22: =N(Calc!$O$11)+N(Calc!$O$12)+N(Calc!$O$13) -> 0 | J22: =N(Calc!$P$11)+N(Calc!$P$12)+N(Calc!$P$13) -> 0 | K22: =N(Calc!$Q$11)+N(Calc!$Q$12)+N(Calc!$Q$13) -> 0 | L22: =J22-K22 -> 0
A23: Q4 | B23: =N(Calc!$F$14)+N(Calc!$F$15)+N(Calc!$F$16) -> 0 | C23: =N(Calc!$G$14)+N(Calc!$G$15)+N(Calc!$G$16) -> 0 | D23: =N(Calc!$I$14)+N(Calc!$I$15)+N(Calc!$I$16) -> 0 | E23: =IFERROR(D23/C23,"") -> 0 | F23: =N(Calc!$L$14)+N(Calc!$L$15)+N(Calc!$L$16) -> 0 | G23: =N(Calc!$M$14)+N(Calc!$M$15)+N(Calc!$M$16) -> 0 | H23: =N(Calc!$N$14)+N(Calc!$N$15)+N(Calc!$N$16) -> 0 | I23: =N(Calc!$O$14)+N(Calc!$O$15)+N(Calc!$O$16) -> 0 | J23: =N(Calc!$P$14)+N(Calc!$P$15)+N(Calc!$P$16) -> 0 | K23: =N(Calc!$Q$14)+N(Calc!$Q$15)+N(Calc!$Q$16) -> 0 | L23: =J23-K23 -> 0
A25: Every month in detail
A26: Month | B26: Planned | C26: Published | D26: On target? | E26: Reach | F26: Impressions | G26: Engagements | H26: Eng. rate | I26: Followers | J26: Growth | K26: Clicks | L26: Leads | M26: Sales | N26: Revenue | O26: Spend | P26: Net | Q26: Return
A27: =Calc!$D$5 -> 0 | B27: =Calc!$E$5 -> 0 | C27: =Calc!$F$5 -> 0 | D27: =IFERROR(Calc!$F$5/Calc!$S$5,"") -> 0 | E27: =Calc!$G$5 -> 0 | F27: =Calc!$H$5 -> 0 | G27: =Calc!$I$5 -> 0 | H27: =Calc!$J$5 -> 0 | I27: =Calc!$K$5 -> 0 | J27: =Calc!$L$5 -> 0 | K27: =Calc!$M$5 -> 0 | L27: =Calc!$N$5 -> 0 | M27: =Calc!$O$5 -> 0 | N27: =Calc!$P$5 -> 0 | O27: =Calc!$Q$5 -> 0 | P27: =N27-O27 -> 0 | Q27: =IFERROR(N27/O27,"") -> 0
A28: =Calc!$D$6 -> 0 | B28: =Calc!$E$6 -> 0 | C28: =Calc!$F$6 -> 0 | D28: =IFERROR(Calc!$F$6/Calc!$S$6,"") -> 0 | E28: =Calc!$G$6 -> 0 | F28: =Calc!$H$6 -> 0 | G28: =Calc!$I$6 -> 0 | H28: =Calc!$J$6 -> 0 | I28: =Calc!$K$6 -> 0 | J28: =Calc!$L$6 -> 0 | K28: =Calc!$M$6 -> 0 | L28: =Calc!$N$6 -> 0 | M28: =Calc!$O$6 -> 0 | N28: =Calc!$P$6 -> 0 | O28: =Calc!$Q$6 -> 0 | P28: =N28-O28 -> 0 | Q28: =IFERROR(N28/O28,"") -> 0
A29: =Calc!$D$7 -> 0 | B29: =Calc!$E$7 -> 0 | C29: =Calc!$F$7 -> 0 | D29: =IFERROR(Calc!$F$7/Calc!$S$7,"") -> 0 | E29: =Calc!$G$7 -> 0 | F29: =Calc!$H$7 -> 0 | G29: =Calc!$I$7 -> 0 | H29: =Calc!$J$7 -> 0 | I29: =Calc!$K$7 -> 0 | J29: =Calc!$L$7 -> 0 | K29: =Calc!$M$7 -> 0 | L29: =Calc!$N$7 -> 0 | M29: =Calc!$O$7 -> 0 | N29: =Calc!$P$7 -> 0 | O29: =Calc!$Q$7 -> 0 | P29: =N29-O29 -> 0 | Q29: =IFERROR(N29/O29,"") -> 0
A30: =Calc!$D$8 -> 0 | B30: =Calc!$E$8 -> 0 | C30: =Calc!$F$8 -> 0 | D30: =IFERROR(Calc!$F$8/Calc!$S$8,"") -> 0 | E30: =Calc!$G$8 -> 0 | F30: =Calc!$H$8 -> 0 | G30: =Calc!$I$8 -> 0 | H30: =Calc!$J$8 -> 0 | I30: =Calc!$K$8 -> 0 | J30: =Calc!$L$8 -> 0 | K30: =Calc!$M$8 -> 0 | L30: =Calc!$N$8 -> 0 | M30: =Calc!$O$8 -> 0 | N30: =Calc!$P$8 -> 0 | O30: =Calc!$Q$8 -> 0 | P30: =N30-O30 -> 0 | Q30: =IFERROR(N30/O30,"") -> 0
A31: =Calc!$D$9 -> 0 | B31: =Calc!$E$9 -> 0 | C31: =Calc!$F$9 -> 0 | D31: =IFERROR(Calc!$F$9/Calc!$S$9,"") -> 0 | E31: =Calc!$G$9 -> 0 | F31: =Calc!$H$9 -> 0 | G31: =Calc!$I$9 -> 0 | H31: =Calc!$J$9 -> 0 | I31: =Calc!$K$9 -> 0 | J31: =Calc!$L$9 -> 0 | K31: =Calc!$M$9 -> 0 | L31: =Calc!$N$9 -> 0 | M31: =Calc!$O$9 -> 0 | N31: =Calc!$P$9 -> 0 | O31: =Calc!$Q$9 -> 0 | P31: =N31-O31 -> 0 | Q31: =IFERROR(N31/O31,"") -> 0
A32: =Calc!$D$10 -> 0 | B32: =Calc!$E$10 -> 0 | C32: =Calc!$F$10 -> 0 | D32: =IFERROR(Calc!$F$10/Calc!$S$10,"") -> 0 | E32: =Calc!$G$10 -> 0 | F32: =Calc!$H$10 -> 0 | G32: =Calc!$I$10 -> 0 | H32: =Calc!$J$10 -> 0 | I32: =Calc!$K$10 -> 0 | J32: =Calc!$L$10 -> 0 | K32: =Calc!$M$10 -> 0 | L32: =Calc!$N$10 -> 0 | M32: =Calc!$O$10 -> 0 | N32: =Calc!$P$10 -> 0 | O32: =Calc!$Q$10 -> 0 | P32: =N32-O32 -> 0 | Q32: =IFERROR(N32/O32,"") -> 0
A33: =Calc!$D$11 -> 0 | B33: =Calc!$E$11 -> 0 | C33: =Calc!$F$11 -> 0 | D33: =IFERROR(Calc!$F$11/Calc!$S$11,"") -> 0 | E33: =Calc!$G$11 -> 0 | F33: =Calc!$H$11 -> 0 | G33: =Calc!$I$11 -> 0 | H33: =Calc!$J$11 -> 0 | I33: =Calc!$K$11 -> 0 | J33: =Calc!$L$11 -> 0 | K33: =Calc!$M$11 -> 0 | L33: =Calc!$N$11 -> 0 | M33: =Calc!$O$11 -> 0 | N33: =Calc!$P$11 -> 0 | O33: =Calc!$Q$11 -> 0 | P33: =N33-O33 -> 0 | Q33: =IFERROR(N33/O33,"") -> 0
A34: =Calc!$D$12 -> 0 | B34: =Calc!$E$12 -> 0 | C34: =Calc!$F$12 -> 0 | D34: =IFERROR(Calc!$F$12/Calc!$S$12,"") -> 0 | E34: =Calc!$G$12 -> 0 | F34: =Calc!$H$12 -> 0 | G34: =Calc!$I$12 -> 0 | H34: =Calc!$J$12 -> 0 | I34: =Calc!$K$12 -> 0 | J34: =Calc!$L$12 -> 0 | K34: =Calc!$M$12 -> 0 | L34: =Calc!$N$12 -> 0 | M34: =Calc!$O$12 -> 0 | N34: =Calc!$P$12 -> 0 | O34: =Calc!$Q$12 -> 0 | P34: =N34-O34 -> 0 | Q34: =IFERROR(N34/O34,"") -> 0
A35: =Calc!$D$13 -> 0 | B35: =Calc!$E$13 -> 0 | C35: =Calc!$F$13 -> 0 | D35: =IFERROR(Calc!$F$13/Calc!$S$13,"") -> 0 | E35: =Calc!$G$13 -> 0 | F35: =Calc!$H$13 -> 0 | G35: =Calc!$I$13 -> 0 | H35: =Calc!$J$13 -> 0 | I35: =Calc!$K$13 -> 0 | J35: =Calc!$L$13 -> 0 | K35: =Calc!$M$13 -> 0 | L35: =Calc!$N$13 -> 0 | M35: =Calc!$O$13 -> 0 | N35: =Calc!$P$13 -> 0 | O35: =Calc!$Q$13 -> 0 | P35: =N35-O35 -> 0 | Q35: =IFERROR(N35/O35,"") -> 0
A36: =Calc!$D$14 -> 0 | B36: =Calc!$E$14 -> 0 | C36: =Calc!$F$14 -> 0 | D36: =IFERROR(Calc!$F$14/Calc!$S$14,"") -> 0 | E36: =Calc!$G$14 -> 0 | F36: =Calc!$H$14 -> 0 | G36: =Calc!$I$14 -> 0 | H36: =Calc!$J$14 -> 0 | I36: =Calc!$K$14 -> 0 | J36: =Calc!$L$14 -> 0 | K36: =Calc!$M$14 -> 0 | L36: =Calc!$N$14 -> 0 | M36: =Calc!$O$14 -> 0 | N36: =Calc!$P$14 -> 0 | O36: =Calc!$Q$14 -> 0 | P36: =N36-O36 -> 0 | Q36: =IFERROR(N36/O36,"") -> 0
A37: =Calc!$D$15 -> 0 | B37: =Calc!$E$15 -> 0 | C37: =Calc!$F$15 -> 0 | D37: =IFERROR(Calc!$F$15/Calc!$S$15,"") -> 0 | E37: =Calc!$G$15 -> 0 | F37: =Calc!$H$15 -> 0 | G37: =Calc!$I$15 -> 0 | H37: =Calc!$J$15 -> 0 | I37: =Calc!$K$15 -> 0 | J37: =Calc!$L$15 -> 0 | K37: =Calc!$M$15 -> 0 | L37: =Calc!$N$15 -> 0 | M37: =Calc!$O$15 -> 0 | N37: =Calc!$P$15 -> 0 | O37: =Calc!$Q$15 -> 0 | P37: =N37-O37 -> 0 | Q37: =IFERROR(N37/O37,"") -> 0
A38: =Calc!$D$16 -> 0 | B38: =Calc!$E$16 -> 0 | C38: =Calc!$F$16 -> 0 | D38: =IFERROR(Calc!$F$16/Calc!$S$16,"") -> 0 | E38: =Calc!$G$16 -> 0 | F38: =Calc!$H$16 -> 0 | G38: =Calc!$I$16 -> 0 | H38: =Calc!$J$16 -> 0 | I38: =Calc!$K$16 -> 0 | J38: =Calc!$L$16 -> 0 | K38: =Calc!$M$16 -> 0 | L38: =Calc!$N$16 -> 0 | M38: =Calc!$O$16 -> 0 | N38: =Calc!$P$16 -> 0 | O38: =Calc!$Q$16 -> 0 | P38: =N38-O38 -> 0 | Q38: =IFERROR(N38/O38,"") -> 0
A39: Trend
A41: Platforms, formats and goals
A42: Platform totals for the year | I42: Goals
A43: Platform | B43: Posts | C43: Reach | D43: Engagements | E43: Eng. rate | F43: Growth | G43: Share of reach | I43: Goal | J43: Target | K43: Now | L43: Progress | M43: On track? | N43: By when
A44: =IF(Calc!$T$5="","",Calc!$T$5) -> 0 | B44: =IF(Calc!$T$5="","",Calc!$AD$5) -> 0 | C44: =IF(Calc!$T$5="","",Calc!$AE$5) -> 0 | D44: =IF(Calc!$T$5="","",Calc!$AF$5) -> 0 | E44: =IF(Calc!$T$5="","",Calc!$AG$5) -> 0 | F44: =IF(Calc!$T$5="","",Calc!$AH$5) -> 0 | G44: =IFERROR(Calc!$AE$5/SUM(Calc!$AE$5:$AE$604),"") -> 0 | I44: =IF(Goals!$B$5="","",Goals!$B$5) -> 0 | J44: =IF(Goals!$B$5="","",Goals!$K$5) -> 0 | K44: =IF(Goals!$B$5="","",Goals!$J$5) -> 0 | L44: =IF(Goals!$B$5="","",Goals!$R$5) -> 0 | M44: =IF(Goals!$B$5="","",Goals!$V$5) -> 0 | N44: =IF(Goals!$B$5="","",Goals!$L$5) -> 0
A45: =IF(Calc!$T$6="","",Calc!$T$6) -> 0 | B45: =IF(Calc!$T$6="","",Calc!$AD$6) -> 0 | C45: =IF(Calc!$T$6="","",Calc!$AE$6) -> 0 | D45: =IF(Calc!$T$6="","",Calc!$AF$6) -> 0 | E45: =IF(Calc!$T$6="","",Calc!$AG$6) -> 0 | F45: =IF(Calc!$T$6="","",Calc!$AH$6) -> 0 | G45: =IFERROR(Calc!$AE$6/SUM(Calc!$AE$5:$AE$604),"") -> 0 | I45: =IF(Goals!$B$6="","",Goals!$B$6) -> 0 | J45: =IF(Goals!$B$6="","",Goals!$K$6) -> 0 | K45: =IF(Goals!$B$6="","",Goals!$J$6) -> 0 | L45: =IF(Goals!$B$6="","",Goals!$R$6) -> 0 | M45: =IF(Goals!$B$6="","",Goals!$V$6) -> 0 | N45: =IF(Goals!$B$6="","",Goals!$L$6) -> 0
A46: =IF(Calc!$T$7="","",Calc!$T$7) -> 0 | B46: =IF(Calc!$T$7="","",Calc!$AD$7) -> 0 | C46: =IF(Calc!$T$7="","",Calc!$AE$7) -> 0 | D46: =IF(Calc!$T$7="","",Calc!$AF$7) -> 0 | E46: =IF(Calc!$T$7="","",Calc!$AG$7) -> 0 | F46: =IF(Calc!$T$7="","",Calc!$AH$7) -> 0 | G46: =IFERROR(Calc!$AE$7/SUM(Calc!$AE$5:$AE$604),"") -> 0 | I46: =IF(Goals!$B$7="","",Goals!$B$7) -> 0 | J46: =IF(Goals!$B$7="","",Goals!$K$7) -> 0 | K46: =IF(Goals!$B$7="","",Goals!$J$7) -> 0 | L46: =IF(Goals!$B$7="","",Goals!$R$7) -> 0 | M46: =IF(Goals!$B$7="","",Goals!$V$7) -> 0 | N46: =IF(Goals!$B$7="","",Goals!$L$7) -> 0
...

Sheet Settings
A1: Business Setup & Settings | G1: Novality Store | v1.0.0
A2: Fill in the cream cells once. Grey cells are locked formulas. Everything else in the workbook reads these values.
A3: > Start Here | C3: > Dashboard | E3: > Calendar | G3: > Ideas
A5: 1. Brand details
B6: Business or brand name | D6: Wildflower Studio | F6: Shown on every printable page and report.
B7: Owner / main contact | D7: Jordan Avery
B8: Email | D8: hello@wildflowerstudio.com
B9: Phone | D9: +1 (555) 017 4410
B10: Website | D10: www.wildflowerstudio.com
B11: Shop / booking link | D11: shop.wildflowerstudio.com | F11: The link you send people to - used in the campaign and launch planners.
B12: Industry | D12: Handmade home & lifestyle
B13: Niche / speciality | D13: Sustainable ceramics and home styling
B14: Target audience | D14: Women 28-45 who love slow living, handmade homeware and styling their first home | F14: One sentence. The Audience Personas tab breaks this down properly.
B15: Main marketing goal | D15: Grow to 25,000 followers and 1,200 shop visits a month
B16: Branded hashtag | D16: #wildflowerstudio
A18: 2. Visual identity reference
B19: Logo file / link | D19: brand-assets/wildflower-logo.png | F19: Paste a cloud link. Spreadsheets cannot preview an external image, so keep the link handy.
B20: Brand colour palette | D20: #3B2A6B indigo, #F2665E coral, #F4EFE6 oat
B21: Fonts / typography | D21: Headings: Canela. Body: Inter.
B22: Brand asset folder | D22: brand-assets/
A24: 3. Calendar & time settings
B25: Planning year | D25: 2026 | E25: The year the dashboards and the 12 month calendar open on.
B26: Week starts on | D26: Monday | E26: Used by the week numbers on the calendar.
B27: Time zone | D27: GMT-05:00 Eastern Time | F27: Posting times on the calendar are in this zone.
B28: Currency code | D28: USD | E28: Budget and revenue columns use the currency symbol set when the workbook was built.
B29: Fiscal year starts in month | D29: 1 | E29: 1 = January. Used by the quarterly report.
A31: 4. Targets (the dashboards measure against these)
B32: Posts per week target | D32: 3
B33: Posts per month target | D33: 13 | E33: Actual against planned is on the dashboard.
B34: Engagement rate target | D34: 0.045 | E34: Posts at or above this rate turn green.
B35: Follower goal (end of year) | D35: 25000
B36: Reach goal (per month) | D36: 120000
B37: Website click goal (per month) | D37: 1800
B38: Lead goal (per month) | D38: 240
B39: Conversion goal (per month) | D39: 90
B40: Revenue goal (per year) | D40: 36000
A42: 5. Budget & return
B43: Marketing budget per month | D43: 900
B44: Marketing budget per year | D44: 10800
B45: Return on ad spend target | D45: 4 | E45: 4 means every 1 spent should bring back 4.
...

Sheet Lists
A1: Customisable Drop Down Lists | AN1: Novality Store | v1.0.0
A2: Edit, add or delete options below - every drop down in the workbook updates automatically. Keep each list in one unbroken block, starting in row 5.
A3: > Start Here | C3: > Dashboard | E3: > Calendar | G3: > Ideas | I3: > Captions | K3: > Hashtags | M3: > Analytics | O3: > Reports | Q3: > Help | S3: TIP: lists grow automatically (up to row 44). Deleting an option does not change posts that already use it.
A4: Yes / No | B4: Yes / No / N/A | C4: Platform | D4: Account type | E4: Content format | F4: Content status | G4: Objective | H4: Funnel stage | I4: Call to action | J4: Hook type | K4: Tone of voice | L4: Priority | M4: Idea status | N4: Idea source | O4: Seasonal event type | P4: Campaign status | Q4: Hashtag type | R4: Search intent | S4: Keyword difficulty | T4: Asset type | U4: Usage rights | V4: Approval status | W4: Collaboration type | X4: Outreach status | Y4: UGC permission | Z4: UGC source | AA4: Team role | AB4: Task status | AC4: Goal category | AD4: Goal status | AE4: Cost category | AF4: Ad objective | AG4: Test variable | AH4: Test status | AI4: Trend type | AJ4: Repurpose status | AK4: Frequency | AL4: Posting slot | AM4: Compliance status | AN4: Month | AO4: Quarter | AP4: Week starts on
A5: Yes | B5: Yes | C5: Instagram | D5: Business account | E5: Feed post | F5: Idea | G5: Awareness | H5: Awareness | I5: Follow for more | J5: Question | K5: Friendly | L5: High | M5: New | N5: Own idea | O5: Public holiday | P5: Planned | Q5: Broad reach | R5: Informational | S5: Low | T5: Photo | U5: Owned | V5: Not started | W5: Gifted product | X5: Not contacted | Y5: Not requested | Z5: Tagged post | AA5: Owner | AB5: Not started | AC5: Followers | AD5: Not started | AE5: Paid advertising | AF5: Awareness | AG5: Hook | AH5: Planned | AI5: Audio | AJ5: Planned | AK5: Daily | AL5: Early morning | AM5: Not checked | AN5: All year | AO5: All year | AP5: Monday
A6: No | B6: No | C6: TikTok | D6: Creator account | E6: Carousel | F6: Brief | G6: Engagement | H6: Consideration | I6: Save this | J6: Bold statement | K6: Playful | L6: Medium | M6: Shortlisted | N6: Customer question | O6: Awareness day | P6: Running | Q6: Niche | R6: Inspirational | S6: Medium | T6: Video clip | U6: Licensed | V6: Awaiting review | W6: Paid post | X6: Contacted | Y6: Requested | Z6: Story mention | AA6: Social media manager | AB6: In progress | AC6: Engagement | AD6: On track | AE6: Influencer fees | AF6: Traffic | AG6: Caption length | AH6: Running | AI6: Format | AJ6: In progress | AK6: 3 x week | AL6: Morning | AM6: Checked | AN6: January | AO6: Q1 | AP6: Sunday
B7: N/A | C7: Pinterest | D7: Personal profile | E7: Reel | F7: In production | G7: Traffic | H7: Conversion | I7: Share with a friend | J7: Statistic | K7: Inspiring | L7: Low | M7: Scheduled | N7: Comment | O7: Industry event | P7: Paused | Q7: Community | R7: Commercial | S7: High | T7: Graphic | U7: Royalty free | V7: Approved | W7: Affiliate | X7: Replied | Y7: Granted | Z7: Product review | AA7: Content creator | AB7: Blocked | AC7: Reach | AD7: At risk | AE7: Content production | AF7: Engagement | AG7: Thumbnail | AH7: Complete | AI7: Topic | AJ7: Published | AK7: Weekly | AL7: Lunchtime | AM7: Not required | AN7: February | AO7: Q2
C8: YouTube | D8: Page | E8: Story | F8: Draft | G8: Leads | H8: Retention | I8: Comment below | J8: Story | K8: Educational | M8: Used | N8: Direct message | O8: Seasonal sale | P8: Complete | Q8: Branded | R8: Navigational | T8: Canva template | U8: UGC with permission | V8: Revision needed | W8: Brand ambassador | X8: Negotiating | Y8: Refused | Z8: Email | AA8: Copywriter | AB8: Complete | AC8: Website traffic | AD8: Behind | AE8: Design & editing | AF8: Video views | AG8: Posting time | AH8: Inconclusive | AI8: Challenge | AJ8: Not suitable | AK8: Fortnightly | AL8: Afternoon | AM8: Issue found | AN8: March | AO8: Q3
C9: Facebook | D9: Group | E9: Short video | F9: Awaiting review | G9: Sales | I9: Link in bio | J9: Problem | K9: Professional | M9: On hold | N9: Product review | O9: Product launch | P9: Cancelled | Q9: Campaign | R9: Transactional | T9: Reel cover | U9: Influencer content | V9: Rejected | W9: Giveaway | X9: Agreed | Y9: Expired | Z9: Direct message | AA9: Designer | AC9: Leads | AD9: Achieved | AE9: Software & subscriptions | AF9: Lead generation | AG9: Format | AI9: Meme | AK9: Monthly | AL9: Evening | AM9: Fixed | AN9: April | AO9: Q4
C10: LinkedIn | D10: Channel | E10: Long video | F10: Revision needed | G10: Community | I10: Shop now | J10: Myth bust | K10: Warm | M10: Archived | N10: Competitor post | O10: Local event | Q10: Product | T10: Thumbnail | U10: Stock library | W10: Account takeover | X10: Declined | Z10: Hashtag | AA10: Video editor | AC10: Sales | AD10: Missed | AE10: Contractor fees | AF10: Sales | AG10: Call to action | AI10: Hashtag | AK10: Quarterly | AL10: Night | AN10: May
C11: X (Twitter) | D11: Shop | E11: Live | F11: Approved | G11: Retention | I11: Sign up | J11: How-to | K11: Bold | N11: Trend | O11: Cultural moment | Q11: Location | T11: Carousel set | U11: Expired | W11: Guest content | X11: Complete | Z11: Competition entry | AA11: Photographer | AC11: Revenue | AE11: Props & samples | AF11: Retargeting | AG11: Hashtag set | AI11: Platform feature | AK11: Ad hoc | AN11: June
C12: Threads | E12: Photo | F12: Scheduled | G12: Brand authority | I12: Download the guide | J12: Listicle | K12: Calm | N12: Keyword research | Q12: Seasonal | T12: Audio | W12: Event | Z12: Influencer content | AA12: Virtual assistant | AC12: Content output | AE12: Training | AF12: App installs | AG12: Cover image | AN12: July
C13: Blog | E13: Graphic | F13: Published | G13: Launch support | I13: Book a call | J13: Before and after | K13: Witty | N13: Analytics | Q13: Trending | T13: Font | AA13: Contractor | AC13: Email list | AE13: Stock media | AG13: Audio | AN13: August
C14: Email newsletter | E14: Infographic | F14: Archived | I14: Watch to the end | J14: POV | K14: Honest | N14: Team suggestion | T14: Logo | AA14: Agency | AC14: Community | AE14: Printing | AG14: Offer | AN14: September
C15: Other | E15: Text post | F15: Cancelled | I15: Reply to this | J15: Tutorial | N15: Newsletter | T15: Mockup | AE15: Other | AG15: First comment | AN15: October
E16: Poll | I16: Tag a friend | J16: Behind the scenes | N16: Repurposed | T16: UGC clip | AN16: November
E17: Standard Pin | I17: None | T17: Product shot | AN17: December
E18: Video Pin
E19: Idea Pin
E20: Blog post
E21: Newsletter
E22: Podcast
E23: UGC repost

Sheet Brand Voice
A1: Brand Voice & Identity | H1: Novality Store | v1.0.0
A2: Fill this in once. Every caption you write, every reply you send and anyone you hire should match what is on this page.
A3: > Start Here | C3: > Dashboard | E3: > Calendar | G3: > Ideas | I3: > Captions
A5: Who you are
B6: Mission - why the business exists | D6: We make everyday objects worth keeping.
B7: Vision - where it is going | D7: A handmade piece on every table, not in every cabinet.
B8: Brand promise - what people can count on | D8: Made slowly, built to be used, replaced if it fails.
B9: Brand story in one paragraph | D9: Started at a night class, kept going because people kept asking. Everything is thrown, glazed and packed by hand.
B10: What makes you different | D10: Small batches, named glazes, and the maker answers the messages.
A12: How you sound
B13: Three words that describe your voice | D13: Warm, honest, playful
B14: Three words you are not | D14: Corporate, pushy, precious
B15: Reading age / tone | D15: Chatty but clear - write like you talk
B16: Point of view | D16: First person: I made this, we packed this
B17: Humour | D17: Dry and self-deprecating, never at anyone's expense
B18: Emoji use | D18: One or two, never a wall
B19: Exclamation marks | D19: One per post at most
A21: Words
B22: Words and phrases you use | D22: handmade, small batch, slow made, everyday, kiln, glaze
B23: Words and phrases you avoid | D23: cheap, luxury, must-have, hurry, limited time only
B24: How you describe the product | D24: Stoneware made in small batches, dishwasher and microwave safe.
B25: How you describe the customer | D25: People who use the good stuff on a Tuesday.
B26: Your sign-off / signature line | D26: Made slowly, used daily.
A28: Rules
B29: Always do | D29: Reply to every comment in the first hour
B30: Never do | D30: Argue in the comments, or repost without asking
B31: How you handle a complaint | D31: Reply once publicly, move it to messages, fix it, follow up
B32: How you handle a troll | D32: Hide, do not engage, block if repeated
B33: How you handle a mistake | D33: Say it plainly, say what you are doing about it
A35: How you look
B36: Logo file / link | D36: drive/wildflower/logo
B37: Colour palette | D37: Clay #C8734A, Sand #EAE0D2, Ink #241B38
B38: Fonts | D38: Headlines: Fraunces. Body: Inter.
B39: Photo style | D39: Daylight, linen, slight mess - real tables, not studios
B40: Video style | D40: Hands, process, no voiceover, captions always
B41: Grid / feed style | D41: Alternating product, process, person
B42: Template files | D42: canva.com/wildflower-templates
A44: Profile copy
B45: Bio - short (150 characters) | D45: Handmade stoneware for everyday use. Made slowly in the studio. Shop below.
B46: Bio - long | D46: Hand-thrown ceramics made in small batches. Dishwasher safe, built to be used, shipped carefully. New glazes monthly.
...

Sheet Accounts
A1: Social Media Accounts | AB1: Novality Store | v1.0.0
A2: One row per account. The grey columns count your posts, pull the reach and engagement from the Analytics tab and tell you when a profile needs attention.
A3: > Start Here | C3: > Dashboard | E3: > Calendar | G3: > Ideas | I3: > Captions | K3: > Hashtags | M3: > Analytics | O3: > Reports | Q3: > Help | S3: Add every account you post to - the dashboards compare them side by side. Mark the six profile checks Yes once you have optimised each profile.
A4: ID | B4: Platform | C4: Account / profile name | D4: Username / handle | E4: Profile URL | F4: Account type | G4: Account owner | H4: What this account is for | I4: Primary audience | J4: Followers today | K4: Account started | L4: Posts per week target | M4: Bio / description checked | N4: Profile picture on brand | O4: Cover image current | P4: Website link works | Q4: Contact details correct | R4: Platform branding done | S4: Profile score | T4: Access & responsibility notes | U4: Posts this year | V4: Published | W4: Reach this year | X4: Engagements | Y4: Engagement rate | Z4: Follower growth | AA4: Last published | AB4: Days since | AC4: Action needed | AD4: Notes
A5: =IF(C5="","","ACC-"&TEXT(ROW()-4,"000")) -> 0 | B5: Instagram | C5: Wildflower Studio | D5: @wildflower.studio | E5: instagram.com/wildflower.studio | F5: Business account | G5: Jordan Avery | H5: Main shop window - product, styling and community | I5: Home lovers 28-45 | J5: 8420 | K5: 45586 | L5: 5 | M5: Yes | N5: Yes | O5: Yes | P5: Yes | Q5: Yes | R5: Yes | S5: =IF(C5="","",(((M5="Yes")*1)+((N5="Yes")*1)+((O5="Yes")*1)+((P5="Yes")*1)+((Q5="Yes")*1)+((R5="Yes")*1))/6) -> 0 | T5: Owner + manager, 2FA on | U5: =IF(B5="","",COUNTIFS('Content Calendar'!$G$5:$G$604,B5,'Content Calendar'!$B$5:$B$604,">="&DATE(PlanYear,1,1),'Content Calendar'!$B$5:$B$604,"<="&DATE(PlanYear,12,31))) -> 0 | V5: =IF(B5="","",COUNTIFS('Content Calendar'!$G$5:$G$604,B5,'Content Calendar'!$X$5:$X$604,"Published",'Content Calendar'!$B$5:$B$604,">="&DATE(PlanYear,1,1),'Content Calendar'!$B$5:$B$604,"<="&DATE(PlanYear,12,31))) -> 0 | W5: =IF(C5="","",SUMIFS(Analytics!$J$5:$J$154,Analytics!$E$5:$E$154,C5,Analytics!$D$5:$D$154,B5)) -> 0 | X5: =IF(C5="","",SUMIFS(Analytics!$L$5:$L$154,Analytics!$E$5:$E$154,C5,Analytics!$D$5:$D$154,B5)) -> 0 | Y5: =IF(OR(W5="",W5=0),"",X5/W5) -> 0 | Z5: =IF(C5="","",SUMIFS(Analytics!$G$5:$G$154,Analytics!$E$5:$E$154,C5)-SUMIFS(Analytics!$F$5:$F$154,Analytics!$E$5:$E$154,C5)) -> 0 | AA5: =IF(B5="","",IF(SUMPRODUCT(MAX(('Content Calendar'!$G$5:$G$604=B5)*('Content Calendar'!$X$5:$X$604="Published")*'Content Calendar'!$B$5:$B$604))=0,"",SUMPRODUCT(MAX(('Content Calendar'!$G$5:$G$604=B5)*('Content Calendar'!$X$5:$X$604="Published")*'Content Calendar'!$B$5:$B$604)))) -> 0 | AB5: =IF(AA5="","",TODAY()-AA5) -> 0 | AC5: =IF(C5="","",IF(S5<1,"Action - finish the profile checklist",IF(AND(ISNUMBER(AB5),AB5>QuietAccountDays),"Check - account has gone quiet",IF(AND(Y5<>"",Y5<TargetEngagement),"Check - engagement below target","OK")))) -> 0 | AD5: Link in bio points at the shop
A6: =IF(C6="","","ACC-"&TEXT(ROW()-4,"000")) -> 0 | B6: TikTok | C6: Wildflower Studio | D6: @wildflowerstudio | E6: tiktok.com/@wildflowerstudio | F6: Creator account | G6: Priya Nair | H6: Reach new people with process and personality | I6: Home lovers 28-45 | J6: 5260 | K6: 45676 | L6: 4 | M6: Yes | N6: Yes | O6: No | P6: Yes | Q6: Yes | R6: Yes | S6: =IF(C6="","",(((M6="Yes")*1)+((N6="Yes")*1)+((O6="Yes")*1)+((P6="Yes")*1)+((Q6="Yes")*1)+((R6="Yes")*1))/6) -> 0 | T6: Owner + manager, 2FA on | U6: =IF(B6="","",COUNTIFS('Content Calendar'!$G$5:$G$604,B6,'Content Calendar'!$B$5:$B$604,">="&DATE(PlanYear,1,1),'Content Calendar'!$B$5:$B$604,"<="&DATE(PlanYear,12,31))) -> 0 | V6: =IF(B6="","",COUNTIFS('Content Calendar'!$G$5:$G$604,B6,'Content Calendar'!$X$5:$X$604,"Published",'Content Calendar'!$B$5:$B$604,">="&DATE(PlanYear,1,1),'Content Calendar'!$B$5:$B$604,"<="&DATE(PlanYear,12,31))) -> 0 | W6: =IF(C6="","",SUMIFS(Analytics!$J$5:$J$154,Analytics!$E$5:$E$154,C6,Analytics!$D$5:$D$154,B6)) -> 0 | X6: =IF(C6="","",SUMIFS(Analytics!$L$5:$L$154,Analytics!$E$5:$E$154,C6,Analytics!$D$5:$D$154,B6)) -> 0 | Y6: =IF(OR(W6="",W6=0),"",X6/W6) -> 0 | Z6: =IF(C6="","",SUMIFS(Analytics!$G$5:$G$154,Analytics!$E$5:$E$154,C6)-SUMIFS(Analytics!$F$5:$F$154,Analytics!$E$5:$E$154,C6)) -> 0 | AA6: =IF(B6="","",IF(SUMPRODUCT(MAX(('Content Calendar'!$G$5:$G$604=B6)*('Content Calendar'!$X$5:$X$604="Published")*'Content Calendar'!$B$5:$B$604))=0,"",SUMPRODUCT(MAX(('Content Calendar'!$G$5:$G$604=B6)*('Content Calendar'!$X$5:$X$604="Published")*'Content Calendar'!$B$5:$B$604)))) -> 0 | AB6: =IF(AA6="","",TODAY()-AA6) -> 0 | AC6: =IF(C6="","",IF(S6<1,"Action - finish the profile checklist",IF(AND(ISNUMBER(AB6),AB6>QuietAccountDays),"Check - account has gone quiet",IF(AND(Y6<>"",Y6<TargetEngagement),"Check - engagement below target","OK")))) -> 0
A7: =IF(C7="","","ACC-"&TEXT(ROW()-4,"000")) -> 0 | B7: Pinterest | C7: Wildflower Studio | D7: wildflowerstudio | E7: pinterest.com/wildflowerstudio | F7: Business account | G7: Sam Okonkwo | H7: Evergreen search traffic to the shop | I7: Home lovers 28-45 | J7: 3180 | K7: 45766 | L7: 3 | M7: Yes | N7: Yes | O7: Yes | P7: Yes | Q7: Yes | R7: Yes | S7: =IF(C7="","",(((M7="Yes")*1)+((N7="Yes")*1)+((O7="Yes")*1)+((P7="Yes")*1)+((Q7="Yes")*1)+((R7="Yes")*1))/6) -> 0 | T7: Owner + manager, 2FA on | U7: =IF(B7="","",COUNTIFS('Content Calendar'!$G$5:$G$604,B7,'Content Calendar'!$B$5:$B$604,">="&DATE(PlanYear,1,1),'Content Calendar'!$B$5:$B$604,"<="&DATE(PlanYear,12,31))) -> 0 | V7: =IF(B7="","",COUNTIFS('Content Calendar'!$G$5:$G$604,B7,'Content Calendar'!$X$5:$X$604,"Published",'Content Calendar'!$B$5:$B$604,">="&DATE(PlanYear,1,1),'Content Calendar'!$B$5:$B$604,"<="&DATE(PlanYear,12,31))) -> 0 | W7: =IF(C7="","",SUMIFS(Analytics!$J$5:$J$154,Analytics!$E$5:$E$154,C7,Analytics!$D$5:$D$154,B7)) -> 0 | X7: =IF(C7="","",SUMIFS(Analytics!$L$5:$L$154,Analytics!$E$5:$E$154,C7,Analytics!$D$5:$D$154,B7)) -> 0 | Y7: =IF(OR(W7="",W7=0),"",X7/W7) -> 0 | Z7: =IF(C7="","",SUMIFS(Analytics!$G$5:$G$154,Analytics!$E$5:$E$154,C7)-SUMIFS(Analytics!$F$5:$F$154,Analytics!$E$5:$E$154,C7)) -> 0 | AA7: =IF(B7="","",IF(SUMPRODUCT(MAX(('Content Calendar'!$G$5:$G$604=B7)*('Content Calendar'!$X$5:$X$604="Published")*'Content Calendar'!$B$5:$B$604))=0,"",SUMPRODUCT(MAX(('Content Calendar'!$G$5:$G$604=B7)*('Content Calendar'!$X$5:$X$604="Published")*'Content Calendar'!$B$5:$B$604)))) -> 0 | AB7: =IF(AA7="","",TODAY()-AA7) -> 0 | AC7: =IF(C7="","",IF(S7<1,"Action - finish the profile checklist",IF(AND(ISNUMBER(AB7),AB7>QuietAccountDays),"Check - account has gone quiet",IF(AND(Y7<>"",Y7<TargetEngagement),"Check - engagement below target","OK")))) -> 0
A8: =IF(C8="","","ACC-"&TEXT(ROW()-4,"000")) -> 0 | B8: YouTube | C8: Wildflower Studio | D8: @wildflowerstudio | E8: youtube.com/@wildflowerstudio | F8: Channel | G8: Elena Dias | H8: Long form studio films and buying guides | I8: Makers and buyers | J8: 1240 | K8: 45856 | L8: 1 | M8: Yes | N8: Yes | O8: Yes | P8: Yes | Q8: No | R8: Yes | S8: =IF(C8="","",(((M8="Yes")*1)+((N8="Yes")*1)+((O8="Yes")*1)+((P8="Yes")*1)+((Q8="Yes")*1)+((R8="Yes")*1))/6) -> 0 | T8: Owner + manager, 2FA on | U8: =IF(B8="","",COUNTIFS('Content Calendar'!$G$5:$G$604,B8,'Content Calendar'!$B$5:$B$604,">="&DATE(PlanYear,1,1),'Content Calendar'!$B$5:$B$604,"<="&DATE(PlanYear,12,31))) -> 0 | V8: =IF(B8="","",COUNTIFS('Content Calendar'!$G$5:$G$604,B8,'Content Calendar'!$X$5:$X$604,"Published",'Content Calendar'!$B$5:$B$604,">="&DATE(PlanYear,1,1),'Content Calendar'!$B$5:$B$604,"<="&DATE(PlanYear,12,31))) -> 0 | W8: =IF(C8="","",SUMIFS(Analytics!$J$5:$J$154,Analytics!$E$5:$E$154,C8,Analytics!$D$5:$D$154,B8)) -> 0 | X8: =IF(C8="","",SUMIFS(Analytics!$L$5:$L$154,Analytics!$E$5:$E$154,C8,Analytics!$D$5:$D$154,B8)) -> 0 | Y8: =IF(OR(W8="",W8=0),"",X8/W8) -> 0 | Z8: =IF(C8="","",SUMIFS(Analytics!$G$5:$G$154,Analytics!$E$5:$E$154,C8)-SUMIFS(Analytics!$F$5:$F$154,Analytics!$E$5:$E$154,C8)) -> 0 | AA8: =IF(B8="","",IF(SUMPRODUCT(MAX(('Content Calendar'!$G$5:$G$604=B8)*('Content Calendar'!$X$5:$X$604="Published")*'Content Calendar'!$B$5:$B$604))=0,"",SUMPRODUCT(MAX(('Content Calendar'!$G$5:$G$604=B8)*('Content Calendar'!$X$5:$X$604="Published")*'Content Calendar'!$B$5:$B$604)))) -> 0 | AB8: =IF(AA8="","",TODAY()-AA8) -> 0 | AC8: =IF(C8="","",IF(S8<1,"Action - finish the profile checklist",IF(AND(ISNUMBER(AB8),AB8>QuietAccountDays),"Check - account has gone quiet",IF(AND(Y8<>"",Y8<TargetEngagement),"Check - engagement below target","OK")))) -> 0
A9: =IF(C9="","","ACC-"&TEXT(ROW()-4,"000")) -> 0 | B9: Facebook | C9: Wildflower Studio | D9: wildflowerstudiohome | E9: facebook.com/wildflowerstudiohome | F9: Page | G9: Jordan Avery | H9: Local customers, markets and events | I9: Home lovers 28-45 | J9: 2640 | K9: 45946 | L9: 2 | M9: Yes | N9: Yes | O9: Yes | P9: Yes | Q9: Yes | R9: Yes | S9: =IF(C9="","",(((M9="Yes")*1)+((N9="Yes")*1)+((O9="Yes")*1)+((P9="Yes")*1)+((Q9="Yes")*1)+((R9="Yes")*1))/6) -> 0 | T9: Owner + manager, 2FA on | U9: =IF(B9="","",COUNTIFS('Content Calendar'!$G$5:$G$604,B9,'Content Calendar'!$B$5:$B$604,">="&DATE(PlanYear,1,1),'Content Calendar'!$B$5:$B$604,"<="&DATE(PlanYear,12,31))) -> 0 | V9: =IF(B9="","",COUNTIFS('Content Calendar'!$G$5:$G$604,B9,'Content Calendar'!$X$5:$X$604,"Published",'Content Calendar'!$B$5:$B$604,">="&DATE(PlanYear,1,1),'Content Calendar'!$B$5:$B$604,"<="&DATE(PlanYear,12,31))) -> 0 | W9: =IF(C9="","",SUMIFS(Analytics!$J$5:$J$154,Analytics!$E$5:$E$154,C9,Analytics!$D$5:$D$154,B9)) -> 0 | X9: =IF(C9="","",SUMIFS(Analytics!$L$5:$L$154,Analytics!$E$5:$E$154,C9,Analytics!$D$5:$D$154,B9)) -> 0 | Y9: =IF(OR(W9="",W9=0),"",X9/W9) -> 0 | Z9: =IF(C9="","",SUMIFS(Analytics!$G$5:$G$154,Analytics!$E$5:$E$154,C9)-SUMIFS(Analytics!$F$5:$F$154,Analytics!$E$5:$E$154,C9)) -> 0 | AA9: =IF(B9="","",IF(SUMPRODUCT(MAX(('Content Calendar'!$G$5:$G$604=B9)*('Content Calendar'!$X$5:$X$604="Published")*'Content Calendar'!$B$5:$B$604))=0,"",SUMPRODUCT(MAX(('Content Calendar'!$G$5:$G$604=B9)*('Content Calendar'!$X$5:$X$604="Published")*'Content Calendar'!$B$5:$B$604)))) -> 0 | AB9: =IF(AA9="","",TODAY()-AA9) -> 0 | AC9: =IF(C9="","",IF(S9<1,"Action - finish the profile checklist",IF(AND(ISNUMBER(AB9),AB9>QuietAccountDays),"Check - account has gone quiet",IF(AND(Y9<>"",Y9<TargetEngagement),"Check - engagement below target","OK")))) -> 0
A10: =IF(C10="","","ACC-"&TEXT(ROW()-4,"000")) -> 0 | S10: =IF(C10="","",(((M10="Yes")*1)+((N10="Yes")*1)+((O10="Yes")*1)+((P10="Yes")*1)+((Q10="Yes")*1)+((R10="Yes")*1))/6) -> 0 | U10: =IF(B10="","",COUNTIFS('Content Calendar'!$G$5:$G$604,B10,'Content Calendar'!$B$5:$B$604,">="&DATE(PlanYear,1,1),'Content Calendar'!$B$5:$B$604,"<="&DATE(PlanYear,12,31))) -> 0 | V10: =IF(B10="","",COUNTIFS('Content Calendar'!$G$5:$G$604,B10,'Content Calendar'!$X$5:$X$604,"Published",'Content Calendar'!$B$5:$B$604,">="&DATE(PlanYear,1,1),'Content Calendar'!$B$5:$B$604,"<="&DATE(PlanYear,12,31))) -> 0 | W10: =IF(C10="","",SUMIFS(Analytics!$J$5:$J$154,Analytics!$E$5:$E$154,C10,Analytics!$D$5:$D$154,B10)) -> 0 | X10: =IF(C10="","",SUMIFS(Analytics!$L$5:$L$154,Analytics!$E$5:$E$154,C10,Analytics!$D$5:$D$154,B10)) -> 0 | Y10: =IF(OR(W10="",W10=0),"",X10/W10) -> 0 | Z10: =IF(C10="","",SUMIFS(Analytics!$G$5:$G$154,Analytics!$E$5:$E$154,C10)-SUMIFS(Analytics!$F$5:$F$154,Analytics!$E$5:$E$154,C10)) -> 0 | AA10: =IF(B10="","",IF(SUMPRODUCT(MAX(('Content Calendar'!$G$5:$G$604=B10)*('Content Calendar'!$X$5:$X$604="Published")*'Content Calendar'!$B$5:$B$604))=0,"",SUMPRODUCT(MAX(('Content Calendar'!$G$5:$G$604=B10)*('Content Calendar'!$X$5:$X$604="Published")*'Content Calendar'!$B$5:$B$604)))) -> 0 | AB10: =IF(AA10="","",TODAY()-AA10) -> 0 | AC10: =IF(C10="","",IF(S10<1,"Action - finish the profile checklist",IF(AND(ISNUMBER(AB10),AB10>QuietAccountDays),"Check - account has gone quiet",IF(AND(Y10<>"",Y10<TargetEngagement),"Check - engagement below target","OK")))) -> 0
A11: =IF(C11="","","ACC-"&TEXT(ROW()-4,"000")) -> 0 | S11: =IF(C11="","",(((M11="Yes")*1)+((N11="Yes")*1)+((O11="Yes")*1)+((P11="Yes")*1)+((Q11="Yes")*1)+((R11="Yes")*1))/6) -> 0 | U11: =IF(B11="","",COUNTIFS('Content Calendar'!$G$5:$G$604,B11,'Content Calendar'!$B$5:$B$604,">="&DATE(PlanYear,1,1),'Content Calendar'!$B$5:$B$604,"<="&DATE(PlanYear,12,31))) -> 0 | V11: =IF(B11="","",COUNTIFS('Content Calendar'!$G$5:$G$604,B11,'Content Calendar'!$X$5:$X$604,"Published",'Content Calendar'!$B$5:$B$604,">="&DATE(PlanYear,1,1),'Content Calendar'!$B$5:$B$604,"<="&DATE(PlanYear,12,31))) -> 0 | W11: =IF(C11="","",SUMIFS(Analytics!$J$5:$J$154,Analytics!$E$5:$E$154,C11,Analytics!$D$5:$D$154,B11)) -> 0 | X11: =IF(C11="","",SUMIFS(Analytics!$L$5:$L$154,Analytics!$E$5:$E$154,C11,Analytics!$D$5:$D$154,B11)) -> 0 | Y11: =IF(OR(W11="",W11=0),"",X11/W11) -> 0 | Z11: =IF(C11="","",SUMIFS(Analytics!$G$5:$G$154,Analytics!$E$5:$E$154,C11)-SUMIFS(Analytics!$F$5:$F$154,Analytics!$E$5:$E$154,C11)) -> 0 | AA11: =IF(B11="","",IF(SUMPRODUCT(MAX(('Content Calendar'!$G$5:$G$604=B11)*('Content Calendar'!$X$5:$X$604="Published")*'Content Calendar'!$B$5:$B$604))=0,"",SUMPRODUCT(MAX(('Content Calendar'!$G$5:$G$604=B11)*('Content Calendar'!$X$5:$X$604="Published")*'Content Calendar'!$B$5:$B$604)))) -> 0 | AB11: =IF(AA11="","",TODAY()-AA11) -> 0 | AC11: =IF(C11="","",IF(S11<1,"Action - finish the profile checklist",IF(AND(ISNUMBER(AB11),AB11>QuietAccountDays),"Check - account has gone quiet",IF(AND(Y11<>"",Y11<TargetEngagement),"Check - engagement below target","OK")))) -> 0
A12: =IF(C12="","","ACC-"&TEXT(ROW()-4,"000")) -> 0 | S12: =IF(C12="","",(((M12="Yes")*1)+((N12="Yes")*1)+((O12="Yes")*1)+((P12="Yes")*1)+((Q12="Yes")*1)+((R12="Yes")*1))/6) -> 0 | U12: =IF(B12="","",COUNTIFS('Content Calendar'!$G$5:$G$604,B12,'Content Calendar'!$B$5:$B$604,">="&DATE(PlanYear,1,1),'Content Calendar'!$B$5:$B$604,"<="&DATE(PlanYear,12,31))) -> 0 | V12: =IF(B12="","",COUNTIFS('Content Calendar'!$G$5:$G$604,B12,'Content Calendar'!$X$5:$X$604,"Published",'Content Calendar'!$B$5:$B$604,">="&DATE(PlanYear,1,1),'Content Calendar'!$B$5:$B$604,"<="&DATE(PlanYear,12,31))) -> 0 | W12: =IF(C12="","",SUMIFS(Analytics!$J$5:$J$154,Analytics!$E$5:$E$154,C12,Analytics!$D$5:$D$154,B12)) -> 0 | X12: =IF(C12="","",SUMIFS(Analytics!$L$5:$L$154,Analytics!$E$5:$E$154,C12,Analytics!$D$5:$D$154,B12)) -> 0 | Y12: =IF(OR(W12="",W12=0),"",X12/W12) -> 0 | Z12: =IF(C12="","",SUMIFS(Analytics!$G$5:$G$154,Analytics!$E$5:$E$154,C12)-SUMIFS(Analytics!$F$5:$F$154,Analytics!$E$5:$E$154,C12)) -> 0 | AA12: =IF(B12="","",IF(SUMPRODUCT(MAX(('Content Calendar'!$G$5:$G$604=B12)*('Content Calendar'!$X$5:$X$604="Published")*'Content Calendar'!$B$5:$B$604))=0,"",SUMPRODUCT(MAX(('Content Calendar'!$G$5:$G$604=B12)*('Content Calendar'!$X$5:$X$604="Published")*'Content Calendar'!$B$5:$B$604)))) -> 0 | AB12: =IF(AA12="","",TODAY()-AA12) -> 0 | AC12: =IF(C12="","",IF(S12<1,"Action - finish the profile checklist",IF(AND(ISNUMBER(AB12),AB12>QuietAccountDays),"Check - account has gone quiet",IF(AND(Y12<>"",Y12<TargetEngagement),"Check - engagement below target","OK")))) -> 0
A13: =IF(C13="","","ACC-"&TEXT(ROW()-4,"000")) -> 0 | S13: =IF(C13="","",(((M13="Yes")*1)+((N13="Yes")*1)+((O13="Yes")*1)+((P13="Yes")*1)+((Q13="Yes")*1)+((R13="Yes")*1))/6) -> 0 | U13: =IF(B13="","",COUNTIFS('Content Calendar'!$G$5:$G$604,B13,'Content Calendar'!$B$5:$B$604,">="&DATE(PlanYear,1,1),'Content Calendar'!$B$5:$B$604,"<="&DATE(PlanYear,12,31))) -> 0 | V13: =IF(B13="","",COUNTIFS('Content Calendar'!$G$5:$G$604,B13,'Content Calendar'!$X$5:$X$604,"Published",'Content Calendar'!$B$5:$B$604,">="&DATE(PlanYear,1,1),'Content Calendar'!$B$5:$B$604,"<="&DATE(PlanYear,12,31))) -> 0 | W13: =IF(C13="","",SUMIFS(Analytics!$J$5:$J$154,Analytics!$E$5:$E$154,C13,Analytics!$D$5:$D$154,B13)) -> 0 | X13: =IF(C13="","",SUMIFS(Analytics!$L$5:$L$154,Analytics!$E$5:$E$154,C13,Analytics!$D$5:$D$154,B13)) -> 0 | Y13: =IF(OR(W13="",W13=0),"",X13/W13) -> 0 | Z13: =IF(C13="","",SUMIFS(Analytics!$G$5:$G$154,Analytics!$E$5:$E$154,C13)-SUMIFS(Analytics!$F$5:$F$154,Analytics!$E$5:$E$154,C13)) -> 0 | AA13: =IF(B13="","",IF(SUMPRODUCT(MAX(('Content Calendar'!$G$5:$G$604=B13)*('Content Calendar'!$X$5:$X$604="Published")*'Content Calendar'!$B$5:$B$604))=0,"",SUMPRODUCT(MAX(('Content Calendar'!$G$5:$G$604=B13)*('Content Calendar'!$X$5:$X$604="Published")*'Content Calendar'!$B$5:$B$604)))) -> 0 | AB13: =IF(AA13="","",TODAY()-AA13) -> 0 | AC13: =IF(C13="","",IF(S13<1,"Action - finish the profile checklist",IF(AND(ISNUMBER(AB13),AB13>QuietAccountDays),"Check - account has gone quiet",IF(AND(Y13<>"",Y13<TargetEngagement),"Check - engagement below target","OK")))) -> 0
